[META]
version=2.0
spawnOnBlockType=2,3,12
spawnSunlight=True
spawnDarkness=True
spawnWater=False
spawnLava=False
spawnAboveGround=False
spawnUnderGround=False
underFill=False
randomRotation=True
dig=True
tree=False
branch=False
needsFoundation=True
rarity=10
collisionPercentage=10
collisionBlockType=All
spawnElevationMin=0
spawnElevationMax=140
spawnInBiome=OttaJungle
groupId=
branch=false
diggingBranch=false
branchLimit=6
groupFrequencyMin=1
groupFrequencyMax=5
groupSeperationMin=0
groupSeperationMax=5
[DATA]
-4,-5,0:17.3
-3,-4,0:17.3
-2,-3,0:17.3
-2,-1,0:17.3
-2,0,0:17.3
-2,1,0:17.3
-1,1,0:17.3
0,1,0:17.3
1,1,0:17.3
1,0,0:17.3
1,-1,0:17.3
0,-1,0:17.3
-1,-1,0:17.3
-1,0,0:17.3
0,0,0:17.3
2,-1,0:17.3
2,0,0:17.3
2,1,0:17.3
2,2,0:17.3
1,2,0:17.3
0,2,0:17.3
-1,2,0:17.3
-2,2,0:17.3
-2,-2,0:17.3
-1,-2,0:17.3
0,-2,0:17.3
1,-2,0:17.3
2,-2,0:17.3
-3,-3,0:17.3
-3,-2,0:17.3
0,-3,0:17.3
1,-3,0:17.3
0,-4,0:17.3
0,-5,0:17.3
1,-6,0:17.3
2,-3,0:17.3
3,-2,0:17.3
3,-3,0:17.3
4,-4,0:17.3
4,-3,0:17.3
5,-4,0:17.3
-4,-4,0:17.3
-5,-6,0:17.3
-4,-6,0:17.3
0,-6,0:17.3
1,-7,0:17.3
3,0,0:17.3
3,1,0:17.3
4,1,0:17.3
5,0,0:17.3
6,0,0:17.3
4,0,0:17.3
2,3,0:17.3
3,2,0:17.3
3,3,0:17.3
3,4,0:17.3
4,4,0:17.3
4,5,0:17.3
0,3,0:17.3
0,4,0:17.3
0,5,0:17.3
-2,3,0:17.3
-3,2,0:17.3
-3,3,0:17.3
-4,3,0:17.3
-4,4,0:17.3
-4,5,0:17.3
-5,5,0:17.3
-6,6,0:17.3
-6,5,0:17.3
-3,0,0:17.3
-4,0,0:17.3
-5,0,0:17.3
-5,-1,0:17.3
-6,-1,0:17.3
-5,1,0:17.3
-6,2,0:17.3
-7,-1,0:17.3
-6,1,0:17.3
-5,-7,0:17.3
5,5,0:17.3
5,6,0:17.3
-1,5,0:17.3
0,6,0:17.3
1,6,0:17.3
5,-5,0:17.3
-7,1,0:31.1
-4,6,0:31.1
-4,-3,0:31.1
2,-6,0:31.1
6,-4,0:31.1
5,4,0:31.1
0,7,0:31.1
-4,-5,1:17.3
-4,-4,1:17.3
-3,-4,1:17.3
-3,-3,1:17.3
-3,-2,1:17.3
-2,-3,1:17.3
-2,-2,1:17.3
-1,-2,1:17.3
-2,-1,1:17.3
-1,-1,1:17.3
-1,0,1:17.3
-1,1,1:17.3
0,1,1:17.3
0,0,1:17.3
0,-1,1:17.3
1,-1,1:17.3
1,0,1:17.3
1,1,1:17.3
1,2,1:17.3
2,1,1:17.3
2,-1,1:17.3
1,-2,1:17.3
2,-2,1:17.3
3,-3,1:17.3
0,-3,1:17.3
0,-2,1:17.3
0,-4,1:17.3
0,-5,1:17.3
2,0,1:17.3
3,0,1:17.3
4,0,1:17.3
2,2,1:17.3
3,2,1:17.3
2,3,1:17.3
3,3,1:17.3
3,4,1:17.3
3,1,1:17.3
-2,1,1:17.3
-1,2,1:17.3
0,2,1:17.3
0,3,1:17.3
0,4,1:17.3
-2,2,1:17.3
-3,2,1:17.3
-2,3,1:17.3
-3,3,1:17.3
-4,3,1:17.3
-4,4,1:17.3
-4,0,1:17.3
-3,0,1:17.3
-2,0,1:17.3
-5,0,1:17.3
-5,1,1:17.3
4,-3,1:17.3
3,-2,1:17.3
5,0,1:17.3
-3,-3,2:17.3
-2,-3,2:17.3
-2,-2,2:17.3
-2,-1,2:17.3
-1,-1,2:17.3
-1,0,2:17.3
0,0,2:17.3
0,-1,2:17.3
1,-1,2:17.3
1,0,2:17.3
1,1,2:17.3
0,1,2:17.3
-1,1,2:17.3
-2,2,2:17.3
-2,3,2:17.3
-3,3,2:17.3
-2,0,2:17.3
-3,0,2:17.3
-4,0,2:17.3
0,-4,2:17.3
0,-3,2:17.3
0,-2,2:17.3
2,-1,2:17.3
2,-2,2:17.3
3,-2,2:17.3
2,1,2:17.3
2,2,2:17.3
3,2,2:17.3
3,3,2:17.3
0,2,2:17.3
0,3,2:17.3
-2,0,3:17.3
-1,0,3:17.3
0,0,3:17.3
1,0,3:17.3
0,-2,3:17.3
0,-1,3:17.3
0,1,3:17.3
0,2,3:17.3
-1,1,3:17.3
-1,-1,3:17.3
1,-1,3:17.3
1,1,3:17.3
2,-1,3:17.3
2,1,3:17.3
-3,0,3:17.3
-2,-2,3:17.3
0,-3,3:17.3
2,-2,3:17.3
2,2,3:17.3
-2,2,3:17.3
-1,-1,4:17.3
-1,0,4:17.3
-1,1,4:17.3
0,1,4:17.3
1,1,4:17.3
1,0,4:17.3
0,0,4:17.3
0,-1,4:17.3
1,-1,4:17.3
-2,0,4:17.3
0,-2,4:17.3
2,-1,4:17.3
2,1,4:17.3
0,2,4:17.3
-1,-1,5:17.3
-1,0,5:17.3
-1,1,5:17.3
0,1,5:17.3
1,1,5:17.3
1,0,5:17.3
1,-1,5:17.3
0,-1,5:17.3
0,0,5:17.3
0,2,5:17.3
2,-1,5:17.3
0,-2,5:17.3
-2,0,5:17.3
-1,-1,6:17.3
-1,0,6:17.3
-1,1,6:17.3
0,1,6:17.3
1,1,6:17.3
1,0,6:17.3
1,-1,6:17.3
0,-1,6:17.3
0,0,6:17.3
-2,0,6:17.3
0,2,6:17.3
0,-2,6:17.3
2,-1,6:17.3
-5,0,6:106.2
-1,-1,7:17.3
-1,0,7:17.3
-1,1,7:17.3
0,1,7:17.3
1,1,7:17.3
1,0,7:17.3
1,-1,7:17.3
0,-1,7:17.3
0,0,7:17.3
-2,0,7:17.3
0,-2,7:17.3
2,-1,7:17.3
0,2,7:17.3
3,2,7:106.1
-5,0,7:106.2
-1,-1,8:17.3
-1,0,8:17.3
-1,1,8:17.3
0,1,8:17.3
1,1,8:17.3
1,0,8:17.3
1,-1,8:17.3
0,-1,8:17.3
0,0,8:17.3
-2,0,8:17.3
0,2,8:17.3
0,-2,8:17.3
2,-1,8:17.3
2,0,8:18.3
2,-2,8:18.3
-3,1,8:18.3
3,2,8:106.1
-5,0,8:106.2
-1,-1,9:17.3
-1,0,9:17.3
-1,1,9:17.3
0,1,9:17.3
1,1,9:17.3
1,0,9:17.3
1,-1,9:17.3
0,-1,9:17.3
0,0,9:17.3
0,-2,9:17.3
0,2,9:17.3
-4,3,9:106.1
3,2,9:106.1
5,-2,9:106.8
-5,0,9:106.2
-1,-1,10:17.3
-1,0,10:17.3
-1,1,10:17.3
0,1,10:17.3
1,1,10:17.3
1,0,10:17.3
1,-1,10:17.3
0,-1,10:17.3
0,0,10:17.3
-2,-3,10:18.3
-1,-3,10:18.3
0,4,10:106.1
-4,3,10:106.1
3,2,10:106.1
5,-2,10:106.8
-7,-2,10:106.2
-5,0,10:106.2
-1,-1,11:17.3
-1,0,11:17.3
-1,1,11:17.3
0,1,11:17.3
1,1,11:17.3
1,0,11:17.3
1,-1,11:17.3
0,-1,11:17.3
0,0,11:17.3
-1,-2,11:17.3
-1,-3,11:17.3
-2,-3,11:17.3
-2,-4,11:18.3
-3,-3,11:18.3
-2,-2,11:18.3
-1,-4,11:18.3
0,-3,11:18.3
3,2,11:106.1
0,4,11:106.1
-4,3,11:106.1
5,-2,11:106.8
-7,-2,11:106.2
-5,0,11:106.2
-1,-1,12:17.3
-1,0,12:17.3
-1,1,12:17.3
0,1,12:17.3
1,1,12:17.3
1,0,12:17.3
1,-1,12:17.3
0,-1,12:17.3
0,0,12:17.3
-2,-4,12:18.3
-3,-3,12:18.3
-2,-3,12:18.3
-2,-2,12:18.3
-1,-3,12:18.3
-4,3,12:106.1
0,4,12:106.1
3,2,12:106.1
5,-2,12:106.8
-5,0,12:106.2
-7,-2,12:106.2
-1,-1,13:17.3
-1,0,13:17.3
-1,1,13:17.3
0,1,13:17.3
1,1,13:17.3
1,0,13:17.3
1,-1,13:17.3
0,-1,13:17.3
0,0,13:17.3
0,2,13:18.3
0,3,13:18.3
-4,3,13:106.1
0,4,13:106.1
3,2,13:106.1
5,-2,13:106.8
-5,0,13:106.2
-7,-2,13:106.2
-1,-1,14:17.3
-1,0,14:17.3
-1,1,14:17.3
0,1,14:17.3
1,1,14:17.3
1,0,14:17.3
1,-1,14:17.3
0,-1,14:17.3
0,0,14:17.3
0,2,14:17.3
0,3,14:17.3
0,4,14:106.1
-1,3,14:18.3
1,3,14:18.3
-4,3,14:106.1
3,2,14:106.1
5,-2,14:106.8
-5,0,14:106.2
-7,-2,14:106.2
-4,-3,-1:2
2,-6,-1:2
-4,6,-1:2
5,4,-1:2
0,7,-1:2
6,-4,-1:2
-7,1,-1:2
-1,-1,15:17.3
-1,0,15:17.3
-1,1,15:17.3
0,1,15:17.3
1,1,15:17.3
1,0,15:17.3
1,-1,15:17.3
0,-1,15:17.3
0,0,15:17.3
-1,3,15:18.3
0,4,15:106.1
1,3,15:18.3
0,3,15:18.3
0,2,15:18.3
-4,3,15:106.1
3,2,15:106.1
3,-5,15:106.4
5,-2,15:106.8
-5,0,15:106.2
-7,-2,15:106.2
-1,-1,16:17.3
-1,0,16:17.3
-1,1,16:17.3
0,1,16:17.3
1,1,16:17.3
1,0,16:17.3
1,-1,16:17.3
0,-1,16:17.3
0,0,16:17.3
0,4,16:106.1
-4,3,16:106.1
3,2,16:106.1
3,-5,16:106.4
5,-2,16:106.8
-5,0,16:106.2
-7,-2,16:106.2
-1,-1,17:17.3
-1,0,17:17.3
-1,1,17:17.3
0,1,17:17.3
1,1,17:17.3
1,0,17:17.3
1,-1,17:17.3
0,-1,17:17.3
0,0,17:17.3
-4,3,17:106.1
0,4,17:106.1
3,2,17:106.1
3,-5,17:106.4
-2,-6,17:106.4
5,-2,17:106.8
-5,0,17:106.2
-7,-2,17:106.2
-1,-1,18:17.3
-1,0,18:17.3
-1,1,18:17.3
0,1,18:17.3
1,1,18:17.3
1,0,18:17.3
1,-1,18:17.3
0,-1,18:17.3
0,0,18:17.3
-4,3,18:106.1
0,4,18:106.1
3,2,18:106.1
-3,-3,18:106.4
-2,-6,18:106.4
3,-5,18:106.4
5,-2,18:106.8
-7,-2,18:106.2
-5,0,18:106.2
-1,-1,19:17.3
-1,0,19:17.3
-1,1,19:17.3
0,1,19:17.3
1,1,19:17.3
1,0,19:17.3
1,-1,19:17.3
0,-1,19:17.3
0,0,19:17.3
-4,3,19:106.1
0,4,19:106.1
3,2,19:106.1
-3,-3,19:106.4
-2,-6,19:106.4
3,-5,19:106.4
5,-2,19:106.8
-7,-2,19:106.2
-5,0,19:106.2
-1,-1,20:17.3
-1,0,20:17.3
-1,1,20:17.3
0,1,20:17.3
1,1,20:17.3
1,0,20:17.3
1,-1,20:17.3
0,-1,20:17.3
0,0,20:17.3
2,0,20:18.3
-1,-2,20:18.3
-4,3,20:106.1
0,4,20:106.1
3,2,20:106.1
-3,-3,20:106.4
-2,-6,20:106.4
3,-5,20:106.4
5,-2,20:106.8
-7,-2,20:106.2
-5,0,20:106.2
-1,0,21:17.3
-1,-1,21:17.3
-1,1,21:17.3
0,1,21:17.3
1,1,21:17.3
1,0,21:17.3
1,-1,21:17.3
0,-1,21:17.3
0,0,21:17.3
-1,-2,21:17.3
-1,-3,21:17.3
-2,-3,21:17.3
-2,-4,21:17.3
2,-1,21:17.3
2,-2,21:17.3
3,-2,21:17.3
3,-3,21:17.3
2,1,21:17.3
2,2,21:17.3
2,3,21:17.3
3,3,21:17.3
0,2,21:17.3
0,3,21:17.3
-1,3,21:17.3
-2,3,21:17.3
-2,4,21:17.3
-2,0,21:17.3
-3,0,21:17.3
-3,1,21:17.3
-4,1,21:17.3
-5,1,21:17.3
4,3,21:17.3
0,4,21:18.3
0,-3,21:18.3
3,1,21:18.3
-4,2,21:18.3
-4,3,21:106.1
3,2,21:106.1
-2,-6,21:106.4
-3,-3,21:106.4
3,-5,21:106.4
5,-2,21:106.8
-7,-2,21:106.2
-5,0,21:106.2
-1,-1,22:17.3
-1,0,22:17.3
-1,1,22:17.3
0,1,22:17.3
1,1,22:17.3
1,0,22:17.3
1,-1,22:17.3
0,-1,22:17.3
0,0,22:17.3
-1,-2,22:17.3
-1,-3,22:17.3
-2,-3,22:17.3
-2,-4,22:17.3
-2,0,22:17.3
-3,0,22:17.3
-3,1,22:17.3
-4,1,22:17.3
-5,1,22:17.3
0,2,22:17.3
0,3,22:17.3
-1,3,22:17.3
-2,3,22:17.3
-2,4,22:17.3
-2,5,22:17.3
-6,1,22:17.3
-2,-5,22:17.3
4,-4,22:17.3
3,-4,22:17.3
3,-3,22:17.3
3,-2,22:17.3
2,-2,22:17.3
2,-1,22:17.3
2,1,22:17.3
2,2,22:17.3
2,3,22:17.3
3,3,22:17.3
4,3,22:17.3
5,3,22:17.3
-3,-1,22:18.3
3,-5,22:18.3
5,4,22:18.3
-3,-5,22:18.3
3,2,22:106.1
-4,3,22:106.1
-3,-3,22:106.4
-2,-6,22:106.4
5,-2,22:106.8
-5,0,22:106.2
-7,-2,22:106.2
-1,-1,23:17.3
-1,0,23:17.3
-1,1,23:17.3
0,1,23:17.3
1,1,23:17.3
1,0,23:17.3
1,-1,23:17.3
0,-1,23:17.3
0,0,23:17.3
-5,1,23:17.3
-6,1,23:17.3
-2,4,23:17.3
-2,5,23:17.3
-2,-5,23:17.3
-2,-4,23:17.3
3,-4,23:17.3
4,-4,23:17.3
4,3,23:17.3
5,3,23:17.3
-2,6,23:17.3
-7,1,23:17.3
-2,-6,23:17.3
5,-4,23:17.3
3,-5,23:17.3
4,4,23:17.3
-3,5,23:17.3
-4,5,23:17.3
-6,0,23:17.3
-6,-1,23:17.3
-7,-2,23:17.3
-6,-2,23:17.3
-3,-5,23:17.3
-4,-5,23:17.3
-4,-6,23:17.3
-1,-6,23:17.3
0,-6,23:17.3
0,-7,23:17.3
-1,6,23:17.3
0,6,23:17.3
0,7,23:17.3
5,2,23:17.3
5,1,23:17.3
6,1,23:17.3
5,-3,23:17.3
3,-6,23:17.3
0,5,23:18.3
1,6,23:18.3
-6,2,23:18.3
-5,-1,23:18.3
-5,-2,23:18.3
-4,-4,23:18.3
-2,-7,23:18.3
1,-7,23:18.3
4,-6,23:18.3
6,-3,23:18.3
2,-4,23:18.3
0,-2,23:18.3
-8,-2,23:18.3
-5,-6,23:18.3
-4,4,23:18.3
-5,5,23:18.3
-2,7,23:18.3
0,8,23:18.3
-2,3,23:18.3
4,5,23:18.3
6,3,23:18.3
5,0,23:18.3
7,1,23:18.3
4,2,23:18.3
2,-6,23:18.3
1,2,23:18.3
-8,1,23:18.3
-4,3,23:106.1
3,2,23:106.1
-3,-3,23:106.4
5,-2,23:106.8
-5,0,23:106.2
-3,0,23:31.1
0,3,23:31.1
3,-2,23:31.1
-4,-6,24:17.3
0,-7,24:17.3
-2,-4,24:17.3
-7,-2,24:17.3
-5,1,24:17.3
-7,1,24:17.3
-4,5,24:17.3
-2,4,24:17.3
-2,6,24:17.3
0,7,24:17.3
4,4,24:17.3
5,2,24:17.3
6,1,24:17.3
6,0,24:17.3
5,-3,24:17.3
3,-4,24:17.3
3,-6,24:17.3
3,-7,24:17.3
4,-7,24:17.3
0,-8,24:17.3
-1,-8,24:17.3
-5,-6,24:17.3
-5,-7,24:17.3
-7,-3,24:17.3
-8,-3,24:17.3
-7,2,24:17.3
-7,3,24:17.3
-4,4,24:17.3
-2,7,24:17.3
-3,7,24:17.3
1,7,24:17.3
1,8,24:17.3
-2,3,24:17.3
-1,3,24:17.3
-2,-3,24:17.3
-1,-3,24:17.3
5,-2,24:17.3
4,-2,24:17.3
7,0,24:17.3
4,5,24:17.3
3,5,24:17.3
5,5,24:17.3
5,6,24:17.3
-8,3,24:17.3
0,0,24:17.3
-4,3,24:106.1
3,2,24:106.1
-3,-3,24:106.4
-5,0,24:106.2
-8,-3,25:17.3
-5,1,25:17.3
-7,1,25:17.3
-8,3,25:17.3
-4,4,25:17.3
-3,7,25:17.3
1,8,25:17.3
-1,3,25:17.3
-5,-7,25:17.3
-2,-4,25:17.3
-1,-3,25:17.3
-4,-6,25:17.3
-3,-6,25:17.3
-5,-8,25:17.3
-3,-4,25:17.3
-1,-2,25:17.3
-1,-8,25:17.3
0,-7,25:17.3
1,-7,25:17.3
-1,-9,25:17.3
4,-7,25:17.3
3,-6,25:17.3
4,-8,25:17.3
3,-4,25:17.3
2,-4,25:17.3
5,-3,25:17.3
5,-4,25:17.3
6,-4,25:17.3
7,0,25:17.3
7,-1,25:17.3
5,2,25:17.3
4,2,25:17.3
4,-2,25:17.3
3,-2,25:17.3
3,-1,25:17.3
-1,2,25:17.3
-5,0,25:17.3
-8,-4,25:17.3
-8,4,25:17.3
-3,8,25:17.3
2,8,25:17.3
0,7,25:17.3
0,6,25:17.3
0,5,25:17.3
3,5,25:17.3
3,6,25:17.3
5,6,25:17.3
6,6,25:17.3
7,6,25:17.3
0,0,25:17.3
1,0,25:17.3
-4,3,25:106.1
3,2,25:106.1
-3,-3,25:106.4
-4,5,25:31.1
-7,-2,25:31.1
0,-8,25:31.1
5,-2,25:31.1
4,5,25:31.1
1,7,25:31.1
-7,3,25:31.1
-2,-3,25:31.1
-2,3,25:31.1
-8,-4,26:17.3
-8,4,26:17.3
-7,1,26:17.3
-5,0,26:17.3
-3,8,26:17.3
-4,4,26:17.3
-1,2,26:17.3
2,8,26:17.3
0,5,26:17.3
3,5,26:17.3
7,6,26:17.3
5,2,26:17.3
7,-1,26:17.3
6,-4,26:17.3
4,-2,26:17.3
4,-8,26:17.3
3,-6,26:17.3
2,-4,26:17.3
-1,-2,26:17.3
-3,-4,26:17.3
-3,-6,26:17.3
-5,-8,26:17.3
-1,-9,26:17.3
1,-7,26:17.3
0,0,26:17.3
-1,0,26:17.3
3,2,26:106.1
-4,3,26:106.1
-3,-3,26:106.4
-8,-4,27:17.3
-7,1,27:17.3
-8,4,27:17.3
-5,0,27:17.3
-3,-4,27:17.3
-3,-6,27:17.3
-5,-8,27:17.3
-1,-9,27:17.3
1,-7,27:17.3
4,-8,27:17.3
3,-6,27:17.3
2,-4,27:17.3
4,-2,27:17.3
6,-4,27:17.3
7,-1,27:17.3
-1,-2,27:17.3
-1,2,27:17.3
5,2,27:17.3
0,5,27:17.3
3,5,27:17.3
2,8,27:17.3
7,6,27:17.3
-3,8,27:17.3
0,0,27:17.3
3,2,27:106.1
-4,3,27:106.1
-3,-3,27:106.4
-1,0,27:31.1
-4,4,27:31.1
0,0,28:17.3
1,0,28:17.3
1,1,28:17.3
-1,2,28:17.3
0,5,28:17.3
-3,8,28:17.3
2,8,28:17.3
3,5,28:17.3
7,6,28:17.3
5,2,28:17.3
7,-1,28:17.3
6,-4,28:17.3
4,-2,28:17.3
2,-4,28:17.3
3,-6,28:17.3
4,-8,28:17.3
1,-7,28:17.3
-1,-9,28:17.3
-3,-6,28:17.3
-5,-8,28:17.3
-8,-4,28:17.3
-5,0,28:17.3
-7,1,28:17.3
-8,4,28:17.3
-8,3,28:17.3
-8,5,28:17.3
-7,0,28:17.3
-5,1,28:17.3
-5,-1,28:17.3
-7,-4,28:17.3
-9,-4,28:17.3
-6,-8,28:17.3
-4,-8,28:17.3
-3,-5,28:17.3
-1,-8,28:17.3
-1,-10,28:17.3
1,-8,28:17.3
4,-6,28:17.3
4,-9,28:17.3
6,-5,28:17.3
6,-3,28:17.3
6,-1,28:17.3
8,-1,28:17.3
3,-2,28:17.3
2,1,28:17.3
-2,2,28:17.3
-1,5,28:17.3
1,5,28:17.3
2,7,28:17.3
2,9,28:17.3
-2,8,28:17.3
-4,8,28:17.3
-7,4,28:17.3
7,5,28:17.3
7,7,28:17.3
4,5,28:17.3
6,2,28:17.3
6,3,28:17.3
-9,-5,28:18.3
-10,-5,28:18.3
-10,-4,28:18.3
-10,-3,28:18.3
-9,-3,28:18.3
-6,-9,28:18.3
-5,-9,28:18.3
-7,-8,28:18.3
-2,-10,28:18.3
-2,-11,28:18.3
-1,-11,28:18.3
-1,-12,28:18.3
0,-12,28:18.3
0,-11,28:18.3
0,-10,28:18.3
3,-9,28:18.3
3,-10,28:18.3
4,-10,28:18.3
5,-10,28:18.3
5,-9,28:18.3
1,-9,28:18.3
5,-7,28:18.3
5,-6,28:18.3
6,-6,28:18.3
7,-6,28:18.3
7,-5,28:18.3
8,-2,28:18.3
9,-2,28:18.3
9,-1,28:18.3
10,-1,28:18.3
10,0,28:18.3
9,0,28:18.3
6,1,28:18.3
7,1,28:18.3
7,2,28:18.3
8,5,28:18.3
8,6,28:18.3
8,7,28:18.3
8,8,28:18.3
7,8,28:18.3
6,8,28:18.3
5,4,28:18.3
5,5,28:18.3
5,6,28:18.3
3,7,28:18.3
3,8,28:18.3
3,9,28:18.3
3,10,28:18.3
1,9,28:18.3
1,10,28:18.3
2,10,28:18.3
-1,8,28:18.3
-1,9,28:18.3
-2,9,28:18.3
-3,9,28:18.3
-4,9,28:18.3
-5,9,28:18.3
-5,8,28:18.3
-9,2,28:18.3
-9,3,28:18.3
-9,4,28:18.3
-9,5,28:18.3
-9,6,28:18.3
-8,6,28:18.3
-8,1,28:18.3
-8,0,28:18.3
-8,-1,28:18.3
-8,-2,28:18.3
-7,-2,28:18.3
-7,-1,28:18.3
-4,-6,28:18.3
-2,-5,28:18.3
1,-4,28:18.3
2,-6,28:18.3
2,-2,28:18.3
4,-1,28:18.3
-2,1,28:18.3
-4,1,28:18.3
-3,7,28:18.3
-2,5,28:18.3
-1,7,28:18.3
0,4,28:18.3
3,4,28:18.3
-3,-4,28:18.3
-2,-8,28:18.3
-1,-2,28:18.3
-1,-1,28:18.3
0,-1,28:18.3
-4,3,28:106.1
3,2,28:106.1
-3,-3,28:106.4
-9,-4,29:17.3
-7,-4,29:17.3
-7,1,29:17.3
-5,-1,29:17.3
-5,0,29:17.3
-5,1,29:17.3
-8,3,29:17.3
-8,6,29:17.3
-8,5,29:17.3
-4,8,29:17.3
-2,8,29:17.3
-1,5,29:17.3
1,5,29:17.3
2,7,29:17.3
2,9,29:17.3
4,5,29:17.3
7,7,29:17.3
7,5,29:17.3
5,2,29:17.3
6,3,29:17.3
6,-1,29:17.3
8,-1,29:17.3
6,-3,29:17.3
6,-5,29:17.3
4,-2,29:17.3
2,1,29:17.3
-2,2,29:17.3
0,0,29:17.3
2,-4,29:17.3
3,-6,29:17.3
4,-9,29:17.3
1,-8,29:17.3
-1,-10,29:17.3
-1,-8,29:17.3
-4,-8,29:17.3
-6,-8,29:17.3
-3,-5,29:17.3
-6,-9,29:18.3
-7,-9,29:18.3
-7,-8,29:18.3
-7,-7,29:18.3
-6,-7,29:18.3
-5,-9,29:18.3
-4,-9,29:18.3
-3,-9,29:18.3
-3,-8,29:18.3
-4,-5,29:18.3
-4,-4,29:18.3
-3,-4,29:18.3
-2,-4,29:18.3
-2,-5,29:18.3
-8,-5,29:18.3
-9,-5,29:18.3
-10,-5,29:18.3
-10,-4,29:18.3
-10,-3,29:18.3
-9,-3,29:18.3
-8,-3,29:18.3
-8,0,29:18.3
-8,1,29:18.3
-8,2,29:18.3
-7,2,29:18.3
-7,0,29:18.3
-9,2,29:18.3
-9,3,29:18.3
-9,4,29:18.3
-9,5,29:18.3
-9,6,29:18.3
-9,7,29:18.3
-8,7,29:18.3
-7,6,29:18.3
-5,7,29:18.3
-5,8,29:18.3
-5,9,29:18.3
-4,9,29:18.3
-3,9,29:18.3
-2,9,29:18.3
-1,9,29:18.3
-1,8,29:18.3
-3,7,29:18.3
1,8,29:18.3
1,9,29:18.3
1,10,29:18.3
2,10,29:18.3
3,10,29:18.3
3,9,29:18.3
3,8,29:18.3
6,6,29:18.3
6,7,29:18.3
6,8,29:18.3
7,8,29:18.3
8,8,29:18.3
8,7,29:18.3
8,6,29:18.3
8,5,29:18.3
8,4,29:18.3
7,4,29:18.3
5,1,29:18.3
6,1,29:18.3
6,2,29:18.3
7,2,29:18.3
7,3,29:18.3
7,-2,29:18.3
7,-1,29:18.3
7,0,29:18.3
8,0,29:18.3
9,0,29:18.3
9,-1,29:18.3
9,-2,29:18.3
8,-2,29:18.3
7,-3,29:18.3
6,-4,29:18.3
7,-4,29:18.3
7,-5,29:18.3
7,-6,29:18.3
6,-6,29:18.3
5,-6,29:18.3
4,-6,29:18.3
4,-8,29:18.3
5,-8,29:18.3
5,-9,29:18.3
5,-10,29:18.3
4,-10,29:18.3
3,-10,29:18.3
3,-9,29:18.3
3,-8,29:18.3
-1,-9,29:18.3
0,-9,29:18.3
0,-10,29:18.3
0,-11,29:18.3
-1,-11,29:18.3
-2,-11,29:18.3
-2,-10,29:18.3
-2,-9,29:18.3
1,-9,29:18.3
1,-7,29:18.3
2,-8,29:18.3
-5,-8,29:18.3
-5,-10,29:18.3
-6,-10,29:18.3
-1,-12,29:18.3
4,-11,29:18.3
7,-7,29:18.3
10,-2,29:18.3
9,-3,29:18.3
3,-3,29:18.3
3,-2,29:18.3
3,-1,29:18.3
4,-1,29:18.3
4,-3,29:18.3
1,-5,29:18.3
1,-4,29:18.3
1,-3,29:18.3
2,-3,29:18.3
-3,-6,29:18.3
-6,-2,29:18.3
-6,-1,29:18.3
-6,0,29:18.3
-5,-2,29:18.3
-4,-2,29:18.3
-4,-1,29:18.3
-3,-1,29:18.3
-3,0,29:18.3
-5,2,29:18.3
-4,2,29:18.3
-4,1,29:18.3
-3,2,29:18.3
-3,3,29:18.3
-2,3,29:18.3
-1,3,29:18.3
0,3,29:18.3
-1,2,29:18.3
-1,1,29:18.3
1,1,29:18.3
1,0,29:18.3
0,-1,29:18.3
3,1,29:18.3
1,4,29:18.3
0,4,29:18.3
0,5,29:18.3
2,6,29:18.3
2,5,29:18.3
3,5,29:18.3
3,6,29:18.3
5,5,29:18.3
-7,4,29:18.3
-6,4,29:18.3
-6,5,29:18.3
-3,4,29:18.3
-4,4,29:18.3
-5,-5,29:18.3
-1,-7,29:18.3
0,-3,29:18.3
0,-4,29:18.3
-1,-1,29:18.3
4,0,29:18.3
3,4,29:18.3
-1,6,29:18.3
-2,6,29:18.3
-10,6,29:18.3
-10,5,29:18.3
-4,10,29:18.3
2,11,29:18.3
9,6,29:18.3
-10,-6,29:18.3
-11,-3,29:18.3
-8,-9,29:18.3
-4,3,29:106.1
3,2,29:106.1
-3,-3,29:106.4
2,8,29:31.1
-3,8,29:31.1
-8,4,29:31.1
-8,-4,29:31.1
-6,-8,30:17.3
-7,-4,30:17.3
-9,-4,30:17.3
-5,-1,30:17.3
-5,1,30:17.3
-7,1,30:17.3
-8,3,30:17.3
-8,6,30:17.3
-4,8,30:17.3
-2,8,30:17.3
-1,5,30:17.3
1,5,30:17.3
-2,2,30:17.3
2,7,30:17.3
2,9,30:17.3
4,5,30:17.3
7,5,30:17.3
7,7,30:17.3
6,3,30:17.3
5,2,30:17.3
0,0,30:17.3
2,1,30:17.3
2,-4,30:17.3
4,-2,30:17.3
6,-1,30:17.3
6,-3,30:17.3
8,-1,30:17.3
6,-5,30:17.3
4,-6,30:17.3
3,-6,30:17.3
4,-9,30:17.3
1,-8,30:17.3
-1,-8,30:17.3
-1,-10,30:17.3
-4,-8,30:17.3
-3,-5,30:17.3
-7,3,30:18.3
-7,4,30:18.3
-8,4,30:18.3
-8,5,30:18.3
-9,4,30:18.3
-9,3,30:18.3
-9,2,30:18.3
-8,2,30:18.3
-7,2,30:18.3
-6,2,30:18.3
-6,1,30:18.3
-6,0,30:18.3
-7,0,30:18.3
-8,0,30:18.3
-8,1,30:18.3
-6,-1,30:18.3
-6,-2,30:18.3
-5,-2,30:18.3
-4,-2,30:18.3
-4,-1,30:18.3
-4,0,30:18.3
-5,0,30:18.3
-4,1,30:18.3
-4,2,30:18.3
-5,2,30:18.3
-7,5,30:18.3
-7,6,30:18.3
-7,7,30:18.3
-8,7,30:18.3
-9,7,30:18.3
-9,6,30:18.3
-9,5,30:18.3
-10,-5,30:18.3
-10,-4,30:18.3
-9,-3,30:18.3
-8,-3,30:18.3
-7,-3,30:18.3
-7,-5,30:18.3
-8,-5,30:18.3
-9,-5,30:18.3
-6,-5,30:18.3
-6,-4,30:18.3
-6,-3,30:18.3
-8,-4,30:18.3
-10,-3,30:18.3
-5,-8,30:18.3
-5,-7,30:18.3
-6,-7,30:18.3
-7,-7,30:18.3
-7,-8,30:18.3
-7,-9,30:18.3
-6,-9,30:18.3
-5,-9,30:18.3
-4,-9,30:18.3
-3,-9,30:18.3
-3,-8,30:18.3
-4,-7,30:18.3
-3,-7,30:18.3
-3,-6,30:18.3
-4,-6,30:18.3
-4,-5,30:18.3
-4,-4,30:18.3
-3,-4,30:18.3
-2,-4,30:18.3
-2,-5,30:18.3
-2,-6,30:18.3
-2,-9,30:18.3
-1,-9,30:18.3
0,-9,30:18.3
0,-8,30:18.3
0,-7,30:18.3
-1,-7,30:18.3
-2,-7,30:18.3
-2,-8,30:18.3
-2,-10,30:18.3
-2,-11,30:18.3
-1,-11,30:18.3
0,-11,30:18.3
0,-10,30:18.3
1,-10,30:18.3
1,-9,30:18.3
2,-9,30:18.3
3,-9,30:18.3
3,-10,30:18.3
4,-10,30:18.3
5,-10,30:18.3
5,-9,30:18.3
5,-8,30:18.3
4,-8,30:18.3
3,-8,30:18.3
2,-8,30:18.3
2,-7,30:18.3
1,-7,30:18.3
3,-7,30:18.3
4,-7,30:18.3
5,-7,30:18.3
5,-6,30:18.3
5,-5,30:18.3
6,-6,30:18.3
7,-6,30:18.3
7,-5,30:18.3
7,-4,30:18.3
6,-4,30:18.3
5,-4,30:18.3
4,-4,30:18.3
4,-5,30:18.3
3,-5,30:18.3
2,-5,30:18.3
2,-6,30:18.3
1,-5,30:18.3
1,-4,30:18.3
1,-3,30:18.3
2,-3,30:18.3
3,-3,30:18.3
3,-4,30:18.3
4,-3,30:18.3
5,-3,30:18.3
5,-2,30:18.3
5,-1,30:18.3
4,-1,30:18.3
3,-1,30:18.3
3,-2,30:18.3
6,-2,30:18.3
7,-2,30:18.3
8,-2,30:18.3
9,-2,30:18.3
9,-1,30:18.3
9,0,30:18.3
8,0,30:18.3
7,0,30:18.3
6,0,30:18.3
5,0,30:18.3
7,-1,30:18.3
7,-3,30:18.3
0,-1,30:18.3
1,-1,30:18.3
1,0,30:18.3
2,0,30:18.3
3,0,30:18.3
3,1,30:18.3
3,2,30:18.3
2,2,30:18.3
1,2,30:18.3
1,1,30:18.3
0,1,30:18.3
-1,1,30:18.3
-1,0,30:18.3
-3,1,30:18.3
-2,1,30:18.3
-3,2,30:18.3
-3,3,30:18.3
-2,3,30:18.3
-1,3,30:18.3
-1,2,30:18.3
-1,-1,30:18.3
-2,4,30:18.3
-2,5,30:18.3
-2,6,30:18.3
-2,7,30:18.3
-4,7,30:18.3
-3,7,30:18.3
-5,7,30:18.3
-5,8,30:18.3
-5,9,30:18.3
-5,10,30:18.3
-4,10,30:18.3
-3,10,30:18.3
-2,10,30:18.3
-1,10,30:18.3
-1,9,30:18.3
-1,8,30:18.3
-1,7,30:18.3
-4,9,30:18.3
-3,9,30:18.3
-2,9,30:18.3
-3,8,30:18.3
-1,6,30:18.3
0,6,30:18.3
1,6,30:18.3
2,6,30:18.3
3,6,30:18.3
4,6,30:18.3
5,6,30:18.3
6,6,30:18.3
7,6,30:18.3
8,6,30:18.3
8,5,30:18.3
8,4,30:18.3
7,4,30:18.3
6,4,30:18.3
5,4,30:18.3
4,4,30:18.3
3,4,30:18.3
2,4,30:18.3
1,4,30:18.3
0,4,30:18.3
-1,4,30:18.3
0,5,30:18.3
0,7,30:18.3
2,5,30:18.3
3,5,30:18.3
4,3,30:18.3
4,2,30:18.3
4,1,30:18.3
5,3,30:18.3
5,1,30:18.3
6,1,30:18.3
6,2,30:18.3
7,2,30:18.3
7,3,30:18.3
6,5,30:18.3
5,5,30:18.3
3,7,30:18.3
4,7,30:18.3
5,7,30:18.3
6,7,30:18.3
8,7,30:18.3
8,8,30:18.3
7,8,30:18.3
6,8,30:18.3
5,8,30:18.3
3,8,30:18.3
3,9,30:18.3
3,10,30:18.3
2,10,30:18.3
1,10,30:18.3
1,9,30:18.3
1,8,30:18.3
1,7,30:18.3
2,8,30:18.3
-10,3,30:18.3
-10,4,30:18.3
-10,5,30:18.3
-10,6,30:18.3
-6,4,30:18.3
-6,5,30:18.3
-6,8,30:18.3
2,11,30:18.3
6,9,30:18.3
7,9,30:18.3
9,6,30:18.3
9,7,30:18.3
10,-1,30:18.3
8,-5,30:18.3
6,-9,30:18.3
4,-11,30:18.3
-1,-12,30:18.3
-6,-10,30:18.3
-5,-10,30:18.3
-8,-8,30:18.3
-9,-6,30:18.3
-11,-4,30:18.3
-9,-2,30:18.3
-11,4,30:18.3
-3,-3,30:18.3
-1,-2,30:18.3
-4,4,30:18.3
-4,3,30:106.1
-8,6,31:18.3
-4,8,31:18.3
-8,3,31:18.3
-7,1,31:18.3
-9,-4,31:18.3
-7,-4,31:18.3
-6,-8,31:18.3
-4,-8,31:18.3
-3,-5,31:18.3
-5,-1,31:18.3
-5,1,31:18.3
-2,2,31:18.3
-1,5,31:18.3
-2,8,31:18.3
2,9,31:18.3
2,7,31:18.3
1,5,31:18.3
0,0,31:18.3
2,-4,31:18.3
1,-8,31:18.3
-1,-8,31:18.3
-1,-10,31:18.3
3,-6,31:18.3
4,-6,31:18.3
4,-9,31:18.3
4,-2,31:18.3
6,-3,31:18.3
6,-5,31:18.3
6,-1,31:18.3
8,-1,31:18.3
5,2,31:18.3
2,1,31:18.3
6,3,31:18.3
4,5,31:18.3
7,5,31:18.3
7,7,31:18.3
-4,3,31:18.3
