[META]
version=2.0
spawnOnBlockType=12
spawnSunlight=True
spawnDarkness=False
spawnWater=True
spawnLava=False
underFill=True
randomRotation=True
dig=True
tree=False
branch=False
needsFoundation=True
rarity=10
collisionPercentage=2
spawnElevationMin=0
spawnElevationMax=128
spawnInBiome=OttaAtollBeach
[DATA]
0,-5,0:1
0,-4,0:1
0,-3,0:1
0,-2,0:1
0,-1,0:1
0,0,0:1
0,1,0:1
0,2,0:1
0,3,0:1
0,4,0:1
0,5,0:1
1,3,0:1
1,2,0:1
1,1,0:1
1,0,0:1
1,-1,0:1
1,-2,0:1
1,-3,0:1
2,-1,0:1
2,0,0:1
2,1,0:1
2,2,0:1
-1,3,0:1
-1,2,0:1
-1,1,0:1
-1,0,0:1
-1,-1,0:1
-1,-2,0:1
-1,-3,0:1
-2,-2,0:1
-2,-1,0:1
-2,0,0:1
-2,1,0:1
-2,2,0:1
3,-1,0:12
3,0,0:12
3,1,0:12
3,2,0:12
2,3,0:12
1,4,0:12
1,5,0:12
0,6,0:12
-1,5,0:12
-1,4,0:12
-2,3,0:12
-3,2,0:12
-3,1,0:12
-3,0,0:12
-3,-1,0:12
-3,-2,0:12
-2,-3,0:12
2,-2,0:12
2,-3,0:12
1,-4,0:12
1,-5,0:12
0,-6,0:12
-1,-5,0:12
-1,-4,0:12
0,-5,-1:1
0,-4,-1:1
0,-3,-1:1
0,-2,-1:1
0,-1,-1:1
0,0,-1:1
0,1,-1:1
0,2,-1:1
0,3,-1:1
0,4,-1:1
0,5,-1:1
1,3,-1:1
1,2,-1:1
1,1,-1:1
1,0,-1:1
1,-1,-1:1
1,-2,-1:1
1,-3,-1:1
2,-1,-1:1
2,0,-1:1
2,1,-1:1
2,2,-1:1
-1,3,-1:1
-1,2,-1:1
-1,1,-1:1
-1,0,-1:1
-1,-1,-1:1
-1,-2,-1:1
-1,-3,-1:1
-2,-2,-1:1
-2,-1,-1:1
-2,0,-1:1
-2,1,-1:1
-2,2,-1:1
1,-5,-1:12
1,-4,-1:12
2,-3,-1:12
2,-2,-1:12
3,-1,-1:12
3,0,-1:12
3,1,-1:12
3,2,-1:12
2,3,-1:12
1,4,-1:12
1,5,-1:12
0,6,-1:12
-1,5,-1:12
-1,4,-1:12
-2,3,-1:12
-3,2,-1:12
-3,1,-1:12
-3,0,-1:12
-3,-1,-1:12
-3,-2,-1:12
-2,-3,-1:12
-1,-4,-1:12
-1,-5,-1:12
0,-6,-1:12
2,-1,-2:1
2,0,-2:1
2,1,-2:1
2,2,-2:1
1,3,-2:1
1,2,-2:1
1,1,-2:1
1,0,-2:1
0,0,-2:1
0,-1,-2:1
0,-2,-2:1
1,-2,-2:1
1,-3,-2:1
0,-3,-2:1
-1,-3,-2:1
-1,-2,-2:1
-1,-1,-2:1
-1,0,-2:1
-1,1,-2:1
-1,2,-2:1
-1,3,-2:1
0,3,-2:1
0,2,-2:1
0,1,-2:1
1,-1,-2:1
0,4,-2:1
0,5,-2:1
0,-4,-2:1
0,-5,-2:1
-2,-2,-2:1
-2,-1,-2:1
-2,0,-2:1
-2,1,-2:1
-2,2,-2:1
2,-2,-2:12
2,-3,-2:12
1,-5,-2:12
1,-4,-2:12
3,-1,-2:12
3,0,-2:12
3,1,-2:12
3,2,-2:12
2,3,-2:12
1,4,-2:12
1,5,-2:12
0,6,-2:12
-1,5,-2:12
-1,4,-2:12
-2,3,-2:12
-3,2,-2:12
-3,1,-2:12
-3,0,-2:12
-3,-1,-2:12
-3,-2,-2:12
-2,-3,-2:12
-1,-4,-2:12
-1,-5,-2:12
0,-6,-2:12
0,-5,-3:1
0,-4,-3:1
0,4,-3:1
0,5,-3:1
1,3,-3:1
1,2,-3:1
1,1,-3:1
1,-3,-3:1
1,-2,-3:1
1,-1,-3:1
1,0,-3:1
-1,-3,-3:1
-1,-2,-3:1
-1,-1,-3:1
-1,0,-3:1
-1,1,-3:1
-1,2,-3:1
-1,3,-3:1
2,-1,-3:1
2,0,-3:1
2,1,-3:1
2,2,-3:1
-2,-2,-3:1
-2,-1,-3:1
-2,0,-3:1
-2,1,-3:1
-2,2,-3:1
0,-3,-3:1
0,-2,-3:1
0,-1,-3:1
0,0,-3:1
0,1,-3:1
0,2,-3:1
0,3,-3:1
3,-1,-3:12
3,0,-3:12
3,1,-3:12
3,2,-3:12
2,-2,-3:12
2,-3,-3:12
1,-4,-3:12
1,-5,-3:12
0,-6,-3:12
-1,-4,-3:12
-1,-5,-3:12
-2,-3,-3:12
-3,-2,-3:12
-3,-1,-3:12
-3,0,-3:12
-3,1,-3:12
-3,2,-3:12
-2,3,-3:12
-1,4,-3:12
-1,5,-3:12
0,6,-3:12
1,5,-3:12
1,4,-3:12
2,3,-3:12
0,-4,1:1
0,-3,1:1
0,-2,1:1
0,-1,1:1
0,0,1:1
0,1,1:1
0,2,1:1
0,3,1:1
0,4,1:1
1,2,1:1
1,1,1:1
1,0,1:1
1,-1,1:1
1,-2,1:1
2,0,1:1
2,1,1:1
-1,2,1:1
-1,1,1:1
-1,0,1:1
-1,-1,1:1
-1,-2,1:1
-2,-1,1:1
-2,0,1:1
-2,1,1:1
-3,0,1:12
-3,1,1:12
3,0,1:12
0,-3,2:1
0,-2,2:1
0,-1,2:1
0,0,2:1
0,1,2:1
0,2,2:1
0,3,2:1
1,-1,2:1
1,0,2:1
1,1,2:1
2,0,2:1
-1,-1,2:1
-1,0,2:1
-1,1,2:1
-2,0,2:1
0,-4,2:1
-1,-2,2:1
1,2,2:1
-2,1,2:1
-3,0,2:12
0,-3,3:1
0,-2,3:1
0,-1,3:1
0,0,3:1
0,1,3:1
0,2,3:1
0,3,3:1
1,-1,3:1
1,0,3:1
1,1,3:1
-1,-1,3:1
-1,0,3:1
-1,1,3:1
0,-2,4:1
0,-1,4:1
0,0,4:1
0,1,4:1
0,2,4:1
1,0,4:1
-1,0,4:1
-1,1,4:1
0,3,4:1
0,-1,5:1
0,0,5:1
0,1,5:1
1,0,5:1
-1,0,5:1
0,2,5:1
0,0,6:1
0,1,6:1
