[META]
version=2.0
spawnOnBlockType=2
spawnSunlight=True
spawnDarkness=False
spawnWater=False
spawnLava=False
underFill=True
randomRotation=True
dig=True
tree=True
branch=False
needsFoundation=True
rarity=10
collisionPercentage=20
spawnElevationMin=0
spawnElevationMax=128
spawnInBiome=OttaFlatPlainsLakeBirchBorder
[DATA]
0,0,0:17.2
0,0,1:17.2
0,0,2:17.2
0,1,2:18.2
-1,1,2:18.2
-1,2,2:18.2
-1,1,3:17.2
-1,2,3:17.2
0,1,3:17.2
0,0,3:17.2
-1,3,3:18.2
0,2,3:18.2
-2,1,3:18.2
-2,2,3:18.2
0,-1,4:18.2
0,0,4:17.2
-1,1,4:18.2
-1,2,4:18.2
-2,2,4:18.2
0,2,4:18.2
0,1,4:18.2
-1,0,4:18.2
-1,-1,4:18.2
-2,-2,5:18.2
-1,-2,5:17.2
0,-2,5:18.2
-1,-1,5:17.2
0,-1,5:17.2
-1,0,5:18.2
0,0,5:17.2
0,1,5:18.2
-1,1,5:18.2
-1,-3,5:18.2
-2,-1,5:18.2
1,-1,5:18.2
1,0,5:18.2
-1,-1,6:18.2
0,0,6:17.2
1,0,6:17.2
2,0,6:18.2
-1,1,6:18.2
0,1,6:18.2
-2,-2,6:18.2
-1,-2,6:18.2
0,-1,6:18.2
1,1,6:18.2
1,-1,6:18.2
-1,0,6:18.2
0,0,7:17.2
1,0,7:18.2
1,1,7:18.2
0,-1,7:18.2
-1,0,7:18.2
0,1,7:18.2
0,0,8:18.2
0,1,8:18.2
1,0,8:18.2
0,0,9:18.2
