[META]
version=2.0
spawnOnBlockType=2
spawnSunlight=True
spawnDarkness=False
spawnWater=False
spawnLava=False
underFill=True
randomRotation=True
dig=True
tree=True
branch=False
needsFoundation=True
rarity=10
collisionPercentage=2
spawnElevationMin=0
spawnElevationMax=128
spawnInBiome=OttaToskana,OttaToskanaHill
[DATA]
-2,2,0:17.0
-2,2,1:17
-2,2,2:17
-2,2,3:17
-2,0,4:17
-2,1,4:17
-2,2,4:17
-1,-2,5:17
-3,-1,5:18
-1,-1,5:17
-2,0,5:17.0
-1,0,5:17
-3,2,5:17
-2,2,5:17
-3,3,5:17
-5,4,5:18
-3,4,5:17
-5,5,5:18
-3,5,5:18
-2,5,5:18
-2,6,5:18
-1,6,5:18
-2,-3,6:18
-1,-3,6:18
0,-3,6:18
-3,-2,6:18
-1,-2,6:17.0
0,-2,6:18
-3,-1,6:18
-2,-1,6:18
-1,-1,6:18
1,-1,6:18
-3,0,6:18
-2,0,6:18
-1,0,6:18
0,0,6:18
-2,1,6:18
-1,1,6:18
-5,2,6:18
-4,2,6:18
-3,2,6:18
-2,2,6:17
-5,3,6:18
-4,3,6:18
-3,3,6:18
-5,4,6:18
-4,4,6:17
-3,4,6:17.0
0,4,6:18
-4,5,6:18
-3,5,6:18
-2,5,6:18
-1,5,6:18
-2,6,6:18
-1,6,6:18
-1,7,6:18
-1,-4,7:18
-3,-3,7:18
-2,-3,7:18
-1,-3,7:18
0,-3,7:18
-3,-2,7:18
-2,-2,7:18
-1,-2,7:17
0,-2,7:18
1,-2,7:18
-5,-1,7:18
-4,-1,7:18
-3,-1,7:18
-1,-1,7:18
1,-1,7:18
-4,0,7:18
-3,0,7:18
-2,0,7:18
0,0,7:18
-4,1,7:18
-3,1,7:17
-2,1,7:18
-1,1,7:18
0,1,7:18
-5,2,7:18
-4,2,7:18
-3,2,7:17
-2,2,7:17.0
-1,2,7:17
0,2,7:17
1,2,7:18
-5,3,7:18
-4,3,7:18
-3,3,7:18
-2,3,7:18
0,3,7:17
1,3,7:18
-5,4,7:18
-4,4,7:18
-3,4,7:18
-2,4,7:18
-1,4,7:18
0,4,7:18
1,4,7:18
-4,5,7:18
-3,5,7:18
-2,5,7:17
-1,5,7:18
0,5,7:18
-4,6,7:18
-3,6,7:18
-2,6,7:18
-1,6,7:18
0,6,7:18
-2,7,7:18
-1,7,7:18
-1,-4,8:18
-3,-3,8:18
-2,-3,8:18
-1,-3,8:18
-4,-2,8:18
-3,-2,8:18
-2,-2,8:18
-1,-2,8:18
0,-2,8:18
-6,-1,8:18
-5,-1,8:18
-4,-1,8:18
-3,-1,8:18
-2,-1,8:18
-1,-1,8:18
0,-1,8:18
-5,0,8:18
-4,0,8:17
-3,0,8:18
-2,0,8:18
-1,0,8:18
0,0,8:18
-5,1,8:18
-4,1,8:17
-3,1,8:17.0
-2,1,8:18
-1,1,8:18
0,1,8:18
-4,2,8:18
-3,2,8:18
-2,2,8:18
-1,2,8:18
0,2,8:18
1,2,8:18
-4,3,8:18
-3,3,8:18
-1,3,8:18
0,3,8:17
1,3,8:18
2,3,8:18
-4,4,8:18
-3,4,8:18
-2,4,8:18
-1,4,8:18
0,4,8:18
1,4,8:18
2,4,8:18
-4,5,8:18
-3,5,8:18
-2,5,8:18
-1,5,8:18
1,5,8:18
-3,6,8:18
-2,6,8:18
-1,6,8:18
0,6,8:18
-3,-2,9:18
-2,-2,9:18
-1,-2,9:18
-4,-1,9:18
-3,-1,9:18
-2,-1,9:18
-1,-1,9:18
-5,0,9:18
-4,0,9:18
-3,0,9:18
-4,1,9:18
-3,1,9:18
-2,1,9:18
-1,1,9:18
-2,2,9:18
-1,2,9:18
0,2,9:18
-4,3,9:18
-3,3,9:18
-2,3,9:18
-1,3,9:18
0,3,9:18
1,3,9:18
-4,4,9:18
-3,4,9:18
-2,4,9:18
-1,4,9:18
0,4,9:18
1,4,9:18
-2,5,9:18
-1,5,9:18
