[META]
version=2.0
spawnOnBlockType=2
spawnSunlight=True
spawnDarkness=False
spawnWater=False
spawnLava=False
underFill=True
randomRotation=True
dig=True
tree=True
branch=False
needsFoundation=True
rarity=10
collisionPercentage=2
spawnElevationMin=0
spawnElevationMax=128
spawnInBiome=OttaToskana,OttaToskanaHill
[DATA]
0,-2,0:17
2,-2,0:17
0,-1,0:17
1,-1,0:17
-1,0,0:17
1,0,0:17
2,0,0:17
0,1,0:17
1,1,0:17
1,2,0:17
0,-2,1:17
2,-2,1:17
0,-1,1:17
1,-1,1:17
-1,0,1:17
0,0,1:17
1,0,1:17
2,0,1:17
0,1,1:17
1,1,1:17
1,2,1:17
0,-1,2:17
1,-1,2:17
0,0,2:17
1,0,2:17
1,1,2:17
0,-1,3:17
1,-1,3:17
-1,0,3:17
0,0,3:17
1,0,3:17
0,1,3:17
1,1,3:17
1,-1,4:17
-1,0,4:17
0,0,4:17
1,0,4:17
-1,1,4:17
0,1,4:17
1,-2,5:17
2,-2,5:17
1,-1,5:17
0,0,5:17.0
1,0,5:17
-1,1,5:17.0
2,-2,6:17.0
1,0,6:17.0
-2,1,6:17
-1,1,6:17.0
-2,2,6:17
3,-3,7:17
2,-2,7:17.0
3,-2,7:17
1,0,7:17.0
1,1,7:17
2,1,7:17
-2,2,7:17.0
3,-3,8:17.0
-2,1,8:17
2,1,8:17.0
-2,2,8:17.0
-3,3,8:17
-2,3,8:17
4,-4,9:17
3,-3,9:17.0
4,-3,9:17
-3,0,9:17
-2,0,9:17
-2,1,9:17.0
2,1,9:17.0
2,2,9:17
3,2,9:17
-3,3,9:17.0
5,-5,10:17
4,-4,10:17.0
5,-4,10:17
-3,-1,10:17
-3,0,10:17.0
3,2,10:17.0
-4,3,10:17
-3,3,10:17.0
-4,4,10:17
6,-6,11:17
5,-5,11:17.0
6,-5,11:17
-4,-1,11:17
-3,-1,11:17.0
-2,-1,11:17
-1,-1,11:17
3,2,11:17.0
3,3,11:17
4,3,11:17
-5,4,11:17
-4,4,11:17.0
-3,4,11:17
-5,5,11:17
-3,5,11:17
7,-7,12:17
6,-6,12:17.0
7,-6,12:17
-4,-2,12:17
-1,-2,12:17
-5,-1,12:17
-4,-1,12:17.0
-1,-1,12:17.0
0,-1,12:17
4,3,12:17.0
-6,5,12:17
-5,5,12:17.0
-3,5,12:17.0
-3,6,12:17
5,-12,13:18
6,-12,13:18
7,-12,13:18
9,-12,13:18
10,-12,13:18
4,-11,13:18
5,-11,13:18
6,-11,13:18
7,-11,13:18
8,-11,13:18
9,-11,13:18
10,-11,13:18
11,-11,13:18
12,-11,13:18
3,-10,13:18
4,-10,13:18
5,-10,13:18
6,-10,13:18
7,-10,13:18
8,-10,13:18
9,-10,13:18
10,-10,13:18
11,-10,13:18
12,-10,13:18
2,-9,13:18
3,-9,13:18
4,-9,13:18
5,-9,13:18
6,-9,13:18
7,-9,13:18
8,-9,13:18
9,-9,13:18
10,-9,13:18
11,-9,13:18
12,-9,13:18
13,-9,13:18
2,-8,13:18
3,-8,13:18
4,-8,13:18
5,-8,13:18
6,-8,13:18
7,-8,13:17
8,-8,13:17
9,-8,13:18
10,-8,13:18
11,-8,13:18
12,-8,13:18
13,-8,13:18
2,-7,13:18
3,-7,13:18
4,-7,13:18
5,-7,13:18
6,-7,13:18
7,-7,13:17.0
8,-7,13:18
9,-7,13:18
10,-7,13:18
11,-7,13:18
12,-7,13:18
13,-7,13:18
-6,-6,13:18
-5,-6,13:18
4,-6,13:18
5,-6,13:18
6,-6,13:18
7,-6,13:18
8,-6,13:18
9,-6,13:18
10,-6,13:18
11,-6,13:18
12,-6,13:18
13,-6,13:18
-6,-5,13:18
-5,-5,13:18
-4,-5,13:18
4,-5,13:18
5,-5,13:18
6,-5,13:18
7,-5,13:18
8,-5,13:18
9,-5,13:18
10,-5,13:18
11,-5,13:18
12,-5,13:18
-8,-4,13:18
-7,-4,13:18
-5,-4,13:17
-4,-4,13:18
-3,-4,13:18
4,-4,13:18
5,-4,13:18
6,-4,13:18
7,-4,13:18
8,-4,13:18
9,-4,13:18
10,-4,13:18
11,-4,13:18
-9,-3,13:18
-8,-3,13:18
-7,-3,13:18
-6,-3,13:18
-5,-3,13:17
-4,-3,13:17
-3,-3,13:18
5,-3,13:18
6,-3,13:18
7,-3,13:18
8,-3,13:18
9,-3,13:18
-9,-2,13:18
-8,-2,13:18
-7,-2,13:18
-6,-2,13:18
-5,-2,13:18
-4,-2,13:17.0
-3,-2,13:18
-2,-2,13:18
-1,-2,13:17.0
6,-2,13:18
7,-2,13:18
8,-2,13:18
-8,-1,13:18
-7,-1,13:18
-6,-1,13:17
-5,-1,13:17.0
-4,-1,13:18
-3,-1,13:18
0,-1,13:17.0
1,-1,13:17
-8,0,13:18
-7,0,13:18
-6,0,13:18
1,0,13:17
-7,1,13:18
-6,1,13:18
-5,1,13:18
-3,1,13:18
-1,1,13:18
0,1,13:18
-7,2,13:18
-6,2,13:18
-5,2,13:18
-3,2,13:18
-2,2,13:18
-6,3,13:18
-5,3,13:18
-4,3,13:18
4,3,13:17.0
5,3,13:17
-7,4,13:18
-6,4,13:18
-4,4,13:18
-3,4,13:18
-2,4,13:18
5,4,13:17
-7,5,13:18
-6,5,13:17.0
-5,5,13:18
-4,5,13:18
-3,5,13:18
-2,5,13:18
-1,5,13:18
-8,6,13:18
-7,6,13:18
-6,6,13:17
-5,6,13:18
-4,6,13:18
-3,6,13:17.0
-2,6,13:18
-1,6,13:18
0,6,13:18
1,6,13:18
-6,7,13:18
-5,7,13:18
-4,7,13:18
-3,7,13:17
-2,7,13:18
-1,7,13:18
0,7,13:18
1,7,13:18
-6,8,13:18
-5,8,13:18
-4,8,13:18
-3,8,13:18
-2,8,13:18
-1,8,13:18
0,8,13:18
1,8,13:18
2,8,13:18
-6,9,13:18
-5,9,13:18
-4,9,13:18
-3,9,13:18
-2,9,13:18
-1,9,13:18
0,9,13:18
-6,10,13:18
-5,10,13:18
-4,10,13:18
-3,10,13:18
-2,10,13:18
-4,11,13:18
-3,11,13:18
7,-13,14:18
6,-12,14:18
7,-12,14:18
8,-12,14:18
9,-12,14:18
10,-12,14:18
4,-11,14:18
5,-11,14:18
6,-11,14:18
7,-11,14:18
8,-11,14:18
9,-11,14:18
10,-11,14:18
11,-11,14:18
4,-10,14:18
5,-10,14:18
7,-10,14:18
9,-10,14:18
10,-10,14:18
11,-10,14:18
12,-10,14:18
-5,-9,14:18
-4,-9,14:18
-3,-9,14:18
3,-9,14:18
4,-9,14:18
5,-9,14:18
6,-9,14:18
7,-9,14:18
8,-9,14:18
9,-9,14:17
10,-9,14:18
11,-9,14:18
12,-9,14:18
-6,-8,14:18
-5,-8,14:18
-4,-8,14:18
-3,-8,14:18
-2,-8,14:18
3,-8,14:18
4,-8,14:18
5,-8,14:18
6,-8,14:18
7,-8,14:18
8,-8,14:18
9,-8,14:18
10,-8,14:18
11,-8,14:18
12,-8,14:18
-7,-7,14:18
-6,-7,14:18
-5,-7,14:18
-4,-7,14:18
-3,-7,14:18
-2,-7,14:18
4,-7,14:18
5,-7,14:18
6,-7,14:18
7,-7,14:18
8,-7,14:18
9,-7,14:18
10,-7,14:18
11,-7,14:18
12,-7,14:18
-8,-6,14:18
-7,-6,14:18
-6,-6,14:18
-5,-6,14:18
-4,-6,14:18
-3,-6,14:18
-2,-6,14:18
5,-6,14:18
6,-6,14:18
7,-6,14:18
8,-6,14:18
9,-6,14:18
11,-6,14:18
12,-6,14:18
-9,-5,14:18
-8,-5,14:18
-7,-5,14:18
-6,-5,14:18
-5,-5,14:17
-4,-5,14:18
-3,-5,14:18
-2,-5,14:18
5,-5,14:18
6,-5,14:18
7,-5,14:18
11,-5,14:18
-9,-4,14:18
-8,-4,14:18
-7,-4,14:18
-6,-4,14:18
-5,-4,14:17.0
-4,-4,14:18
-3,-4,14:18
-2,-4,14:18
0,-4,14:18
6,-4,14:18
7,-4,14:18
9,-4,14:18
10,-4,14:18
-10,-3,14:18
-9,-3,14:18
-8,-3,14:18
-7,-3,14:18
-6,-3,14:18
-4,-3,14:18
-10,-2,14:18
-9,-2,14:18
-6,-2,14:18
-5,-2,14:18
-4,-2,14:18
-3,-2,14:18
-1,-2,14:17.0
-11,-1,14:18
-10,-1,14:18
-9,-1,14:18
-8,-1,14:18
-7,-1,14:18
-6,-1,14:17.0
-5,-1,14:18
-4,-1,14:18
-1,-1,14:18
0,-1,14:18
1,-1,14:18
2,-1,14:18
3,-1,14:18
4,-1,14:18
-7,0,14:18
-6,0,14:18
-2,0,14:18
-1,0,14:18
0,0,14:18
1,0,14:17.0
2,0,14:18
3,0,14:18
4,0,14:18
5,0,14:18
6,0,14:18
7,0,14:18
-11,1,14:18
-8,1,14:18
-6,1,14:18
-5,1,14:18
-3,1,14:18
0,1,14:18
1,1,14:17
2,1,14:17
5,1,14:18
6,1,14:18
7,1,14:18
8,1,14:18
9,1,14:18
-10,2,14:18
-7,2,14:18
-5,2,14:18
-4,2,14:18
-2,2,14:18
0,2,14:18
1,2,14:18
4,2,14:18
5,2,14:18
6,2,14:18
7,2,14:18
8,2,14:18
9,2,14:18
10,2,14:18
-8,3,14:18
-3,3,14:18
0,3,14:18
1,3,14:18
4,3,14:18
5,3,14:18
6,3,14:18
7,3,14:18
8,3,14:18
9,3,14:18
10,3,14:18
-8,4,14:18
-7,4,14:18
-6,4,14:18
-5,4,14:18
0,4,14:18
1,4,14:18
4,4,14:18
5,4,14:17.0
6,4,14:18
7,4,14:18
8,4,14:18
9,4,14:18
10,4,14:18
-8,5,14:18
-7,5,14:18
-4,5,14:18
-3,5,14:18
-1,5,14:18
0,5,14:18
3,5,14:18
4,5,14:18
5,5,14:17
6,5,14:17
7,5,14:18
8,5,14:18
9,5,14:18
10,5,14:18
-8,6,14:18
-7,6,14:18
-6,6,14:17.0
-4,6,14:18
-3,6,14:18
-2,6,14:18
-1,6,14:18
0,6,14:18
2,6,14:18
3,6,14:18
4,6,14:18
5,6,14:18
6,6,14:18
7,6,14:18
8,6,14:18
9,6,14:18
10,6,14:18
-8,7,14:18
-7,7,14:17
-6,7,14:17
-3,7,14:17.0
-2,7,14:18
-1,7,14:18
0,7,14:18
1,7,14:18
2,7,14:18
3,7,14:18
4,7,14:18
5,7,14:18
6,7,14:18
7,7,14:18
8,7,14:18
9,7,14:18
-7,8,14:18
-6,8,14:18
-4,8,14:18
-3,8,14:17
-2,8,14:17
-1,8,14:18
0,8,14:18
2,8,14:18
3,8,14:18
4,8,14:18
5,8,14:18
6,8,14:18
7,8,14:18
8,8,14:18
-7,9,14:18
-6,9,14:18
-4,9,14:18
-3,9,14:18
-2,9,14:18
-1,9,14:18
1,9,14:18
5,9,14:18
6,9,14:18
7,9,14:18
-6,10,14:18
-5,10,14:18
-4,10,14:18
-3,10,14:18
-2,10,14:18
-1,10,14:18
0,10,14:18
1,10,14:18
-6,11,14:18
-5,11,14:18
-4,11,14:18
-3,11,14:18
-2,11,14:18
6,-12,15:18
7,-12,15:18
5,-11,15:18
6,-11,15:18
7,-11,15:18
8,-11,15:18
9,-11,15:18
10,-11,15:18
-4,-10,15:18
-3,-10,15:18
4,-10,15:18
5,-10,15:18
6,-10,15:18
7,-10,15:18
8,-10,15:18
9,-10,15:18
10,-10,15:17
11,-10,15:18
-6,-9,15:18
-5,-9,15:18
-4,-9,15:18
-3,-9,15:18
4,-9,15:18
5,-9,15:18
6,-9,15:18
7,-9,15:18
8,-9,15:18
9,-9,15:18
10,-9,15:18
11,-9,15:18
-7,-8,15:18
-6,-8,15:18
-5,-8,15:18
-4,-8,15:18
-3,-8,15:18
5,-8,15:18
6,-8,15:18
7,-8,15:18
8,-8,15:18
9,-8,15:18
10,-8,15:18
11,-8,15:18
12,-8,15:18
-7,-7,15:18
-6,-7,15:18
-5,-7,15:18
6,-7,15:18
7,-7,15:18
8,-7,15:18
9,-7,15:18
10,-7,15:18
11,-7,15:18
12,-7,15:18
-8,-6,15:18
-7,-6,15:18
-6,-6,15:18
-5,-6,15:18
7,-6,15:18
8,-6,15:18
9,-6,15:18
10,-6,15:18
11,-6,15:18
-10,-5,15:18
-9,-5,15:18
-8,-5,15:18
-7,-5,15:18
-6,-5,15:18
-5,-5,15:17.0
-4,-5,15:18
8,-5,15:18
9,-5,15:18
10,-5,15:18
-10,-4,15:18
-9,-4,15:18
-8,-4,15:18
-7,-4,15:18
-6,-4,15:18
-4,-4,15:18
-3,-4,15:18
0,-4,15:18
-10,-3,15:18
-9,-3,15:18
-6,-3,15:18
-5,-3,15:18
-4,-3,15:18
-3,-3,15:18
-2,-3,15:17
-1,-3,15:17
0,-3,15:18
-10,-2,15:18
-9,-2,15:18
-8,-2,15:18
-7,-2,15:18
-6,-2,15:18
-5,-2,15:18
-4,-2,15:18
-3,-2,15:18
-1,-2,15:17.0
-10,-1,15:18
-9,-1,15:18
-8,-1,15:18
-7,-1,15:18
-6,-1,15:18
-5,-1,15:18
-4,-1,15:18
-3,-1,15:18
-1,-1,15:18
0,-1,15:18
1,-1,15:18
2,-1,15:18
3,-1,15:18
4,-1,15:18
-12,0,15:18
-11,0,15:18
-10,0,15:18
-9,0,15:18
-8,0,15:18
-7,0,15:17
-6,0,15:18
-5,0,15:18
-4,0,15:18
-2,0,15:18
-1,0,15:18
0,0,15:18
1,0,15:18
2,0,15:18
3,0,15:18
4,0,15:18
5,0,15:18
-12,1,15:18
-11,1,15:18
-10,1,15:18
-9,1,15:18
-8,1,15:18
-7,1,15:18
-6,1,15:18
-4,1,15:18
-2,1,15:18
0,1,15:18
1,1,15:18
2,1,15:17.0
3,1,15:18
4,1,15:18
5,1,15:18
6,1,15:18
7,1,15:18
-12,2,15:18
-11,2,15:18
-10,2,15:18
-9,2,15:18
-8,2,15:18
-5,2,15:18
0,2,15:18
1,2,15:18
4,2,15:18
5,2,15:18
6,2,15:18
7,2,15:18
8,2,15:18
9,2,15:18
-11,3,15:18
-10,3,15:18
-9,3,15:18
-8,3,15:18
-4,3,15:18
-3,3,15:18
-2,3,15:18
0,3,15:18
1,3,15:18
4,3,15:18
5,3,15:18
6,3,15:18
7,3,15:18
8,3,15:18
9,3,15:18
10,3,15:18
11,3,15:18
-10,4,15:18
-9,4,15:18
-8,4,15:18
-7,4,15:18
-6,4,15:18
-5,4,15:18
-4,4,15:18
-2,4,15:18
0,4,15:18
1,4,15:18
4,4,15:18
5,4,15:18
6,4,15:18
7,4,15:18
8,4,15:18
9,4,15:18
10,4,15:18
11,4,15:18
-10,5,15:18
-9,5,15:18
-8,5,15:18
-7,5,15:18
-6,5,15:18
-5,5,15:18
-4,5,15:18
-3,5,15:18
-2,5,15:18
-1,5,15:18
0,5,15:18
1,5,15:18
2,5,15:18
3,5,15:18
4,5,15:18
5,5,15:18
6,5,15:17.0
7,5,15:18
8,5,15:18
9,5,15:18
10,5,15:18
11,5,15:18
-12,6,15:18
-11,6,15:18
-10,6,15:18
-9,6,15:18
-8,6,15:18
-7,6,15:18
-4,6,15:18
-3,6,15:18
-2,6,15:18
-1,6,15:18
0,6,15:18
2,6,15:18
3,6,15:18
4,6,15:18
5,6,15:18
6,6,15:18
7,6,15:18
8,6,15:18
9,6,15:18
10,6,15:18
11,6,15:18
-13,7,15:18
-12,7,15:18
-9,7,15:18
-8,7,15:18
-7,7,15:17.0
-5,7,15:18
-4,7,15:18
-3,7,15:18
-2,7,15:18
-1,7,15:18
0,7,15:18
1,7,15:18
2,7,15:18
3,7,15:18
4,7,15:18
5,7,15:18
6,7,15:18
7,7,15:18
8,7,15:18
9,7,15:18
10,7,15:18
-13,8,15:18
-12,8,15:18
-9,8,15:18
-8,8,15:18
-4,8,15:18
-3,8,15:18
-2,8,15:17.0
-1,8,15:18
0,8,15:18
1,8,15:18
2,8,15:18
3,8,15:18
4,8,15:18
5,8,15:18
6,8,15:18
7,8,15:18
8,8,15:18
9,8,15:18
-12,9,15:18
-11,9,15:18
-10,9,15:18
-9,9,15:18
-8,9,15:18
-7,9,15:18
-4,9,15:18
-3,9,15:18
-2,9,15:18
-1,9,15:18
0,9,15:18
1,9,15:18
2,9,15:18
3,9,15:18
4,9,15:18
5,9,15:18
6,9,15:18
7,9,15:18
8,9,15:18
-12,10,15:18
-11,10,15:18
-10,10,15:18
-9,10,15:18
-8,10,15:18
-7,10,15:18
-6,10,15:18
-5,10,15:18
-4,10,15:18
-3,10,15:18
-2,10,15:18
-1,10,15:18
0,10,15:18
1,10,15:18
5,10,15:18
6,10,15:18
7,10,15:18
-10,11,15:18
-9,11,15:18
-8,11,15:18
-7,11,15:18
-6,11,15:18
-5,11,15:18
-4,11,15:18
-3,11,15:18
-2,11,15:18
-1,11,15:18
0,11,15:18
1,11,15:18
-8,12,15:18
-7,12,15:18
-6,12,15:18
-5,12,15:18
-4,12,15:18
-3,12,15:18
-2,12,15:18
7,-11,16:18
8,-11,16:18
5,-10,16:18
6,-10,16:18
7,-10,16:18
8,-10,16:18
9,-10,16:18
10,-10,16:18
-3,-9,16:18
-2,-9,16:18
5,-9,16:18
6,-9,16:18
7,-9,16:18
8,-9,16:18
9,-9,16:18
10,-9,16:18
-4,-8,16:18
-3,-8,16:18
-2,-8,16:18
-1,-8,16:18
6,-8,16:18
7,-8,16:18
8,-8,16:18
9,-8,16:18
10,-8,16:18
11,-8,16:18
-6,-7,16:18
-5,-7,16:18
-4,-7,16:18
0,-7,16:18
1,-7,16:18
7,-7,16:18
8,-7,16:18
9,-7,16:18
10,-7,16:18
11,-7,16:18
-7,-6,16:18
-6,-6,16:18
-5,-6,16:18
-4,-6,16:18
0,-6,16:18
1,-6,16:18
8,-6,16:18
9,-6,16:18
-8,-5,16:18
-7,-5,16:18
-6,-5,16:18
-5,-5,16:18
-4,-5,16:18
-3,-5,16:18
-2,-5,16:18
0,-5,16:18
2,-5,16:18
-10,-4,16:18
-9,-4,16:18
-8,-4,16:18
-6,-4,16:18
-5,-4,16:18
-4,-4,16:18
-3,-4,16:18
-2,-4,16:18
-1,-4,16:18
0,-4,16:18
1,-4,16:18
2,-4,16:18
3,-4,16:18
4,-4,16:18
-10,-3,16:18
-9,-3,16:18
-8,-3,16:18
-7,-3,16:18
-6,-3,16:18
-5,-3,16:18
-4,-3,16:18
-3,-3,16:18
-2,-3,16:17.0
-1,-3,16:18
0,-3,16:18
2,-3,16:18
3,-3,16:18
5,-3,16:18
6,-3,16:18
-9,-2,16:18
-8,-2,16:18
-7,-2,16:18
-6,-2,16:18
-5,-2,16:18
-4,-2,16:18
-3,-2,16:18
0,-2,16:18
4,-2,16:18
5,-2,16:18
6,-2,16:18
-8,-1,16:18
-7,-1,16:18
-6,-1,16:18
-5,-1,16:18
-4,-1,16:18
-2,-1,16:18
-1,-1,16:18
0,-1,16:18
1,-1,16:18
4,-1,16:18
5,-1,16:18
6,-1,16:18
-8,0,16:18
-7,0,16:18
-6,0,16:18
-1,0,16:18
0,0,16:18
1,0,16:18
2,0,16:18
3,0,16:18
4,0,16:18
5,0,16:18
-9,1,16:18
-8,1,16:18
-7,1,16:18
-6,1,16:18
-3,1,16:18
0,1,16:18
1,1,16:18
2,1,16:17.0
3,1,16:18
4,1,16:18
5,1,16:18
-10,2,16:18
-9,2,16:18
-3,2,16:18
-2,2,16:18
-1,2,16:18
0,2,16:18
1,2,16:18
4,2,16:18
5,2,16:18
6,2,16:18
-10,3,16:18
-2,3,16:18
-1,3,16:18
0,3,16:18
1,3,16:18
2,3,16:18
3,3,16:18
4,3,16:18
5,3,16:18
6,3,16:18
7,3,16:18
8,3,16:18
-11,4,16:18
-10,4,16:18
-9,4,16:18
-8,4,16:18
-7,4,16:18
-6,4,16:18
-4,4,16:18
-3,4,16:18
-2,4,16:18
-1,4,16:18
0,4,16:18
1,4,16:18
2,4,16:18
3,4,16:18
4,4,16:18
5,4,16:18
6,4,16:18
7,4,16:18
8,4,16:18
9,4,16:18
-12,5,16:18
-11,5,16:18
-10,5,16:18
-9,5,16:18
-8,5,16:18
-7,5,16:18
-6,5,16:18
-5,5,16:18
-4,5,16:18
-3,5,16:18
-2,5,16:18
-1,5,16:18
0,5,16:18
1,5,16:18
3,5,16:18
4,5,16:18
5,5,16:18
6,5,16:18
7,5,16:18
8,5,16:18
9,5,16:18
10,5,16:18
-11,6,16:18
-10,6,16:18
-9,6,16:18
-8,6,16:18
-5,6,16:18
-4,6,16:18
-3,6,16:18
-2,6,16:18
-1,6,16:18
0,6,16:18
1,6,16:18
2,6,16:18
3,6,16:18
4,6,16:18
5,6,16:18
6,6,16:18
7,6,16:18
8,6,16:18
9,6,16:18
-11,7,16:18
-10,7,16:18
-9,7,16:18
-6,7,16:18
-3,7,16:18
-2,7,16:18
-1,7,16:18
0,7,16:18
2,7,16:18
3,7,16:18
4,7,16:18
5,7,16:18
6,7,16:18
7,7,16:18
8,7,16:18
-11,8,16:18
-10,8,16:18
-9,8,16:18
-8,8,16:17
-7,8,16:18
-6,8,16:18
-5,8,16:18
-4,8,16:18
-3,8,16:18
-2,8,16:17.0
-1,8,16:18
0,8,16:18
2,8,16:18
3,8,16:18
4,8,16:18
5,8,16:18
6,8,16:18
7,8,16:18
8,8,16:18
-10,9,16:18
-9,9,16:18
-8,9,16:18
-7,9,16:18
-6,9,16:18
-5,9,16:18
-4,9,16:18
-3,9,16:18
-2,9,16:18
-1,9,16:18
0,9,16:18
5,9,16:18
6,9,16:18
-9,10,16:18
-8,10,16:18
-7,10,16:18
-6,10,16:18
-5,10,16:18
-4,10,16:18
-3,10,16:18
-2,10,16:18
-8,11,16:18
-7,11,16:18
-6,11,16:18
-5,11,16:18
-4,11,16:18
-3,11,16:18
-8,12,16:18
-6,12,16:18
-5,12,16:18
7,-9,17:18
-2,-8,17:18
-1,-8,17:18
10,-8,17:18
-3,-7,17:18
-2,-7,17:18
-1,-7,17:18
0,-7,17:18
-5,-6,17:18
-4,-6,17:18
-3,-6,17:18
-2,-6,17:18
-1,-6,17:18
0,-6,17:18
1,-6,17:18
-6,-5,17:18
-5,-5,17:18
-4,-5,17:18
-3,-5,17:18
-2,-5,17:18
-1,-5,17:18
0,-5,17:18
1,-5,17:18
-7,-4,17:18
-6,-4,17:18
-5,-4,17:18
-4,-4,17:18
-3,-4,17:18
-2,-4,17:18
-1,-4,17:18
0,-4,17:18
1,-4,17:18
2,-4,17:18
-8,-3,17:18
-7,-3,17:18
-6,-3,17:18
-5,-3,17:18
-4,-3,17:18
-3,-3,17:18
-2,-3,17:18
-1,-3,17:18
0,-3,17:18
3,-3,17:18
4,-3,17:18
-8,-2,17:18
-7,-2,17:18
-6,-2,17:18
-5,-2,17:18
-4,-2,17:18
-3,-2,17:18
-2,-2,17:18
-1,-2,17:18
0,-2,17:18
1,-2,17:18
2,-2,17:18
3,-2,17:18
4,-2,17:18
-7,-1,17:18
-5,-1,17:18
-4,-1,17:18
-3,-1,17:18
-2,-1,17:18
-1,-1,17:18
0,-1,17:18
1,-1,17:18
2,-1,17:18
3,-1,17:18
4,-1,17:18
5,-1,17:18
-7,0,17:18
-6,0,17:18
-4,0,17:18
-3,0,17:18
-2,0,17:18
0,0,17:18
1,0,17:18
2,0,17:18
3,0,17:18
4,0,17:18
5,0,17:18
-7,1,17:18
-6,1,17:18
-5,1,17:18
-4,1,17:18
-3,1,17:18
-2,1,17:18
-1,1,17:18
0,1,17:18
1,1,17:18
2,1,17:18
3,1,17:18
4,1,17:18
5,1,17:18
-8,2,17:18
-7,2,17:18
-6,2,17:18
-5,2,17:18
-4,2,17:18
-3,2,17:18
-2,2,17:18
-1,2,17:18
0,2,17:18
1,2,17:18
2,2,17:18
3,2,17:18
4,2,17:18
-9,3,17:18
-8,3,17:18
-7,3,17:18
-6,3,17:18
-5,3,17:18
-4,3,17:18
-3,3,17:18
-2,3,17:18
-1,3,17:18
0,3,17:18
1,3,17:18
2,3,17:18
3,3,17:18
4,3,17:18
5,3,17:18
-9,4,17:18
-8,4,17:18
-7,4,17:18
-6,4,17:18
-5,4,17:18
-4,4,17:18
-3,4,17:18
-2,4,17:18
-1,4,17:18
0,4,17:18
1,4,17:18
2,4,17:18
3,4,17:18
4,4,17:18
5,4,17:18
6,4,17:18
-10,5,17:18
-9,5,17:18
-8,5,17:18
-7,5,17:18
-6,5,17:18
-5,5,17:18
-4,5,17:18
-3,5,17:18
-2,5,17:18
-1,5,17:18
0,5,17:18
1,5,17:18
2,5,17:18
3,5,17:18
4,5,17:18
5,5,17:18
6,5,17:18
-10,6,17:18
-9,6,17:18
-8,6,17:18
-7,6,17:18
-6,6,17:18
-5,6,17:18
-4,6,17:18
-3,6,17:18
-2,6,17:18
-1,6,17:18
2,6,17:18
3,6,17:18
4,6,17:18
5,6,17:18
-10,7,17:18
-9,7,17:18
-8,7,17:18
-7,7,17:18
-6,7,17:18
-5,7,17:18
-4,7,17:18
-3,7,17:18
-2,7,17:18
-1,7,17:18
4,7,17:18
-9,8,17:18
-8,8,17:18
-7,8,17:18
-6,8,17:18
-5,8,17:18
-4,8,17:18
-3,8,17:18
-2,8,17:18
-8,9,17:18
-7,9,17:18
-6,9,17:18
-5,9,17:18
-4,9,17:18
-3,9,17:18
-8,10,17:18
-7,10,17:18
-6,10,17:18
-5,10,17:18
-6,11,17:18
-2,-6,18:18
-1,-6,18:18
-4,-5,18:18
-3,-5,18:18
-2,-5,18:18
-1,-5,18:18
-6,-4,18:18
-5,-4,18:18
-4,-4,18:18
-3,-4,18:18
-2,-4,18:18
-1,-4,18:18
0,-4,18:18
-6,-3,18:18
-5,-3,18:18
-4,-3,18:18
-3,-3,18:18
-2,-3,18:18
-1,-3,18:18
0,-3,18:18
1,-3,18:18
2,-3,18:18
-6,-2,18:18
-5,-2,18:18
-4,-2,18:18
-3,-2,18:18
-2,-2,18:18
-1,-2,18:18
0,-2,18:18
1,-2,18:18
2,-2,18:18
-7,-1,18:18
-6,-1,18:18
-5,-1,18:18
-4,-1,18:18
-3,-1,18:18
-2,-1,18:18
-1,-1,18:18
0,-1,18:18
1,-1,18:18
2,-1,18:18
-6,0,18:18
-5,0,18:18
-4,0,18:18
-3,0,18:18
-2,0,18:18
-1,0,18:18
0,0,18:18
1,0,18:18
2,0,18:18
3,0,18:18
4,0,18:18
-3,1,18:18
-2,1,18:18
-1,1,18:18
0,1,18:18
1,1,18:18
2,1,18:18
3,1,18:18
-2,2,18:18
-1,2,18:18
-7,3,18:18
-6,3,18:18
-5,3,18:18
2,3,18:18
-7,4,18:18
-6,4,18:18
-5,4,18:18
-4,4,18:18
-3,4,18:18
2,4,18:18
3,4,18:18
-7,5,18:18
-6,5,18:18
-5,5,18:18
-4,5,18:18
-3,5,18:18
3,5,18:18
-8,6,18:18
-7,6,18:18
-6,6,18:18
-5,6,18:18
-4,6,18:18
-3,6,18:18
-8,7,18:18
-7,7,18:18
-6,7,18:18
-5,7,18:18
-4,7,18:18
-3,7,18:18
-8,8,18:18
-7,8,18:18
-6,8,18:18
-5,8,18:18
-6,9,18:18
