[META]
version=2.0
spawnOnBlockType=2
spawnSunlight=True
spawnDarkness=True
spawnWater=False
spawnLava=False
underFill=False
randomRotation=True
dig=True
tree=True
branch=False
needsFoundation=True
rarity=10
collisionPercentage=2
spawnElevationMin=0
spawnElevationMax=256
spawnInBiome=OttaForest
[DATA]
0,0,0:17.0
-1,-1,0:0
0,-1,0:0
1,-1,0:0
1,0,0:0
0,1,0:0
-1,0,0:0
1,1,0:0
-1,1,0:0
0,0,-1:17.0
-1,0,-1:0
-1,-1,-1:0
0,-1,-1:0
0,-2,-1:0
1,-1,-1:0
1,0,-1:0
0,1,-1:0
-1,1,-1:0
1,1,-1:0
0,0,1:17.0
0,0,2:17.0
0,0,3:17.0
0,0,4:17.0
0,0,5:17.0
1,-1,5:18.0
0,-1,5:18.0
-1,-1,5:18.0
-1,0,5:18.0
-1,1,5:18.0
0,1,5:18.0
0,0,6:17.0
0,-1,6:17.0
1,-1,6:18.0
-1,-2,6:18.0
-1,-1,6:18.0
0,-2,6:18.0
-1,0,6:18.0
-1,1,6:18.0
0,0,7:17.0
1,0,7:17.0
-1,-1,7:18.0
0,-1,7:18.0
0,-2,7:18.0
-1,-2,7:18.0
-1,-3,7:18.0
1,-2,7:18.0
1,-1,7:18.0
-1,0,7:18.0
-1,1,7:18.0
0,1,7:18.0
1,1,7:18.0
2,1,7:18.0
2,0,7:18.0
0,0,8:17.0
0,1,8:17.0
1,0,8:18.0
1,1,8:18.0
1,2,8:18.0
0,2,8:18.0
-1,2,8:18.0
-1,1,8:18.0
-1,0,8:18.0
-1,-1,8:18.0
0,-1,8:18.0
0,-2,8:18.0
0,0,9:17.0
0,-1,9:17.0
-1,-1,9:17.0
-1,-2,9:17.0
-1,1,9:18.0
0,1,9:18.0
1,1,9:18.0
1,0,9:18.0
0,-2,9:18.0
0,-3,9:18.0
-1,-3,9:18.0
-2,-2,9:18.0
-1,0,9:18.0
-2,-1,9:18.0
1,-2,9:18.0
1,-3,9:18.0
0,-4,9:18.0
0,2,9:18.0
-3,-2,9:18.0
-3,-1,9:18.0
-2,-3,9:18.0
0,0,10:17.0
-1,0,10:18.0
-1,-1,10:18.0
0,-1,10:18.0
0,-2,10:18.0
-1,-2,10:18.0
-1,-3,10:18.0
1,0,10:18.0
1,-1,10:18.0
0,1,10:18.0
0,0,11:17.0
-1,0,11:18.0
-1,-1,11:18.0
0,-1,11:18.0
0,-2,11:18.0
1,0,11:18.0
1,1,11:18.0
0,1,11:18.0
-1,1,11:18.0
0,0,12:17.0
1,1,12:17.0
0,1,12:17.0
1,2,12:17.0
-1,0,12:18.0
-1,-1,12:18.0
0,-1,12:18.0
1,-1,12:18.0
1,0,12:18.0
0,-2,12:18.0
-1,-2,12:18.0
-2,0,12:18.0
-1,1,12:18.0
-1,2,12:18.0
0,2,12:18.0
0,3,12:18.0
1,3,12:18.0
2,3,12:18.0
2,2,12:18.0
2,1,12:18.0
0,0,13:17.0
1,1,13:18.0
1,2,13:18.0
0,2,13:18.0
0,1,13:18.0
-1,0,13:18.0
-1,1,13:18.0
0,0,14:18.0
0,-1,14:18.0
-1,0,14:18.0
0,1,14:18.0
1,0,14:18.0
0,0,15:18.0
