[META]
version=2.0
spawnOnBlockType=2,3
spawnSunlight=True
spawnDarkness=True
spawnWater=False
spawnLava=False
underFill=False
randomRotation=True
dig=True
tree=True
branch=False
needsFoundation=True
rarity=100
collisionPercentage=100
spawnElevationMin=0
spawnElevationMax=200
spawnInBiome=All
[DATA]
-1,-2,-2:2.5
-2,-1,-2:2.5
-1,-1,-2:17.3
0,-1,-2:2.5
-1,0,-2:2.5
-1,-3,-1:18.15
-2,-2,-1:18.15
-1,-2,-1:18.15
0,-2,-1:18.15
1,-2,-1:18.15
-3,-1,-1:18.15
-2,-1,-1:18.15
-1,-1,-1:17.3
0,-1,-1:18.15
1,-1,-1:18.15
2,-1,-1:18.15
-2,0,-1:18.15
-1,0,-1:18.15
0,0,-1:18.15
1,0,-1:18.15
-2,1,-1:18.15
-1,1,-1:18.15
0,1,-1:18.15
-1,2,-1:18.15
-1,-2,0:18.15
-2,-1,0:18.15
-1,-1,0:18.15
0,-1,0:18.15
1,-1,0:18.15
-1,0,0:18.15
0,0,0:18.15
-1,1,0:18.15
-1,-1,1:18.15
0,-1,1:18.15
-1,0,1:18.7
-1,-1,2:18.15
