[META]
version=2.0
spawnOnBlockType=2
spawnSunlight=True
spawnDarkness=True
spawnWater=False
spawnLava=False
underFill=False
randomRotation=True
dig=False
tree=True
branch=False
needsFoundation=True
rarity=100
collisionPercentage=80
spawnElevationMin=0
spawnElevationMax=240
spawnInBiome=All
[DATA]
0,0,0:85
0,0,1:17.1
-1,0,1:18.2
0,-1,1:18.2
0,1,1:18.2
1,0,1:18.2
0,0,2:18.2
1,-1,2:18.2
-1,-1,2:18.2
-1,1,2:18.2
1,1,2:18.2
-1,0,2:18.2
0,-1,2:18.2
0,1,2:18.2
1,0,2:18.2
0,-2,2:18.2
-2,0,2:18.2
-2,-1,2:18.2
-1,-2,2:18.2
-2,1,2:18.2
-1,2,2:18.2
0,2,2:18.2
1,2,2:18.2
2,1,2:18.2
2,0,2:18.2
2,-1,2:18.2
1,-2,2:18.2
0,0,3:18.2
0,-1,3:18.2
-1,0,3:18.2
0,1,3:18.2
1,0,3:18.2
0,-2,3:18.2
-1,-1,3:18.2
-2,0,3:18.2
-1,1,3:18.2
0,2,3:18.2
1,1,3:18.2
1,-1,3:18.2
2,0,3:18.2
0,0,4:18.2
0,-1,4:18.2
-1,0,4:18.2
0,1,4:18.2
1,0,4:18.2
0,0,5:18.2
