[META]
version=2.0
spawnOnBlockType=2
spawnSunlight=True
spawnDarkness=True
spawnWater=False
spawnLava=False
underFill=False
randomRotation=True
dig=False
tree=True
branch=False
needsFoundation=True
rarity=400
collisionPercentage=100
spawnElevationMin=0
spawnElevationMax=128
spawnInBiome=All
[DATA]
-6,-4,0:18
-5,-4,0:18
-4,-4,0:18
-3,-4,0:18
-2,-4,0:18
-1,-4,0:18
0,-4,0:18
-6,-3,0:18
-5,-3,0:17.0
-4,-3,0:17.0
-3,-3,0:17.0
-2,-3,0:17.0
-1,-3,0:17.0
0,-3,0:18
1,-3,0:18
-6,-2,0:18
-5,-2,0:17.0
-4,-2,0:18
-3,-2,0:18
-2,-2,0:18
-1,-2,0:18
0,-2,0:18
1,-2,0:18
-6,-1,0:18
-5,-1,0:18
-4,-1,0:18
-3,-1,0:18
-2,-1,0:18
-1,-1,0:18
0,-1,0:17.0
1,-1,0:18
-2,0,0:18
-1,0,0:18
0,0,0:17.0
1,0,0:18
-1,1,0:18
0,1,0:17.0
1,1,0:18
0,2,0:18
1,2,0:18
-3,3,0:18
1,3,0:18
-4,4,0:18
-3,4,0:18
-2,4,0:18
-4,5,0:18
-3,5,0:18
-2,5,0:18
-4,6,0:18
-3,6,0:18
-2,6,0:17.0
-1,6,0:18
0,6,0:18
-4,7,0:18
-3,7,0:18
-2,7,0:17.0
-1,7,0:18
0,7,0:18
-3,8,0:18
-2,8,0:18
-1,8,0:18
0,5,0:106.4
1,4,0:106.2
2,3,0:106.2
-4,3,0:106.8
2,2,0:106.2
-3,2,0:106.8
2,1,0:106.2
-2,1,0:106.1
2,0,0:106.2
-3,0,0:106.8
-4,0,0:106.4
-5,0,0:106.4
-6,0,0:106.4
2,-1,0:106.2
-7,-1,0:106.8
2,-2,0:106.2
-7,-2,0:106.8
2,-3,0:106.2
-7,-3,0:106.8
1,-4,0:106.1
-7,-4,0:106.8
0,-5,0:106.1
-1,-5,0:106.1
-2,-5,0:106.1
-3,-5,0:106.1
-4,-5,0:106.1
-5,-5,0:106.1
-6,-5,0:106.1
-1,1,-5:17.0
-1,2,-5:17.0
-1,3,-5:17.0
-1,0,-4:17.0
-2,1,-4:17.0
-1,1,-4:17.0
-2,2,-4:17.0
-1,2,-4:17.0
-2,3,-4:17.0
-1,3,-4:17.0
-2,4,-4:17.0
-2,-1,-3:17.0
-1,-1,-3:17.0
-2,0,-3:17.0
-1,0,-3:17.0
-4,1,-3:2
-3,1,-3:17.0
-2,1,-3:17.0
-1,1,-3:17.0
-4,2,-3:2
-3,2,-3:17.0
-2,2,-3:17.0
-1,2,-3:17.0
0,2,-3:3
-3,3,-3:3
-2,3,-3:17.0
-1,3,-3:17.0
0,3,-3:2
-3,4,-3:3
-2,4,-3:17.0
-1,4,-3:17.0
0,4,-3:2
1,4,-3:2
2,4,-3:2
-3,5,-3:3
-2,5,-3:17.0
-1,5,-3:17.0
0,5,-3:2
1,5,-3:2
2,5,-3:2
-2,6,-3:3
-1,6,-3:3
0,6,-3:3
1,6,-3:2
-2,-2,-2:17.0
-1,-2,-2:17.0
0,-2,-2:17.0
-3,-1,-2:17.0
-2,-1,-2:17.0
-1,-1,-2:17.0
0,-1,-2:17.0
-4,0,-2:17.0
-3,0,-2:17.0
-2,0,-2:17.0
-1,0,-2:17.0
0,0,-2:17.0
-5,1,-2:3
-4,1,-2:18
-3,1,-2:18
-2,1,-2:18
-1,1,-2:17.0
0,1,-2:17.0
-5,2,-2:3
-4,2,-2:18
-3,2,-2:18
-2,2,-2:18
-1,2,-2:18
0,2,-2:17.0
1,2,-2:3
-4,3,-2:2
-3,3,-2:17.0
-2,3,-2:18
-1,3,-2:18
0,3,-2:18
1,3,-2:2
2,3,-2:3
-3,4,-2:3
-2,4,-2:17.0
-1,4,-2:18
0,4,-2:18
1,4,-2:18
2,4,-2:18
3,4,-2:3
-3,5,-2:3
-2,5,-2:17.0
-1,5,-2:18
0,5,-2:18
1,5,-2:18
2,5,-2:18
3,5,-2:3
-3,6,-2:3
-2,6,-2:17.0
-1,6,-2:17.0
0,6,-2:2
1,6,-2:18
2,6,-2:18
-2,7,-2:3
-1,7,-2:3
0,7,-2:3
1,7,-2:3
-6,-4,-1:2
-5,-4,-1:2
-4,-4,-1:2
-3,-4,-1:2
-2,-4,-1:2
-1,-4,-1:2
0,-4,-1:2
-6,-3,-1:2
-5,-3,-1:3
-4,-3,-1:3
-3,-3,-1:3
-2,-3,-1:17.0
-1,-3,-1:17.0
0,-3,-1:17.0
1,-3,-1:2
-6,-2,-1:2
-5,-2,-1:3
-4,-2,-1:17.0
-3,-2,-1:17.0
-2,-2,-1:17.0
-1,-2,-1:2
0,-2,-1:17.0
1,-2,-1:2
-6,-1,-1:2
-5,-1,-1:2
-4,-1,-1:17.0
-3,-1,-1:18
-2,-1,-1:18
-1,-1,-1:17.0
0,-1,-1:17.0
1,-1,-1:2
-5,0,-1:2
-4,0,-1:18
-3,0,-1:18
-2,0,-1:18
-1,0,-1:17.0
0,0,-1:17.0
1,0,-1:2
-5,1,-1:2
-1,1,-1:18
0,1,-1:17.0
1,1,-1:2
-5,2,-1:2
0,2,-1:18
1,2,-1:2
-5,3,-1:2
-4,3,-1:18
-3,3,-1:18
1,3,-1:18
2,3,-1:2
3,3,-1:2
-4,4,-1:2
-3,4,-1:2
-2,4,-1:18
3,4,-1:2
-4,5,-1:2
-3,5,-1:2
-2,5,-1:18
3,5,-1:2
-4,6,-1:2
-3,6,-1:2
-1,6,-1:18
2,6,-1:2
3,6,-1:2
-4,7,-1:2
-3,7,-1:2
-2,7,-1:3
-1,7,-1:17.0
0,7,-1:2
1,7,-1:2
2,7,-1:2
-3,8,-1:2
-2,8,-1:2
-1,8,-1:2
-4,-4,1:18
-3,-4,1:18
-2,-4,1:18
-5,-3,1:18
-4,-3,1:17.0
-3,-3,1:17.0
-2,-3,1:17.0
-1,-3,1:18
0,-3,1:18
-5,-2,1:18
-4,-2,1:18
-3,-2,1:18
-2,-2,1:18
-1,-2,1:18
0,-2,1:18
-1,-1,1:18
0,-1,1:18
-1,0,1:18
0,0,1:18
-1,1,1:18
0,1,1:17.0
1,1,1:18
-1,2,1:18
0,2,1:17.0
1,2,1:18
-3,3,1:18
-2,3,1:18
-1,3,1:18
0,3,1:18
-3,4,1:18
-2,4,1:18
-1,4,1:18
-3,5,1:18
-2,5,1:17.0
-1,5,1:18
-3,6,1:18
-2,6,1:17.0
-1,6,1:18
-2,7,1:18
-3,7,1:106.8
0,6,1:106.2
-4,6,1:106.8
0,5,1:106.4
-4,5,1:106.8
1,4,1:106.2
-4,4,1:106.8
2,3,1:106.2
-4,3,1:106.8
2,2,1:106.2
-3,2,1:106.8
2,1,1:106.2
-2,1,1:106.1
1,0,1:106.2
-2,0,1:106.8
1,-1,1:106.2
-2,-1,1:106.8
-3,-1,1:106.4
-4,-1,1:106.4
-5,-1,1:106.4
-6,-2,1:106.8
1,-3,1:106.2
-6,-3,1:106.8
0,-4,1:106.1
-5,-4,1:106.8
-2,-5,1:106.1
-3,-5,1:106.1
-4,-5,1:106.1
-3,-4,2:18
-4,-3,2:18
-3,-3,2:18
-2,-3,2:18
-1,-1,2:18
-1,0,2:18
-1,1,2:18
0,1,2:18
-2,2,2:18
-1,2,2:18
0,2,2:17.0
1,2,2:18
-3,3,2:18
-2,3,2:17.0
-1,3,2:17.0
0,3,2:17.0
1,3,2:18
-3,4,2:18
-2,4,2:17.0
-1,4,2:18
0,4,2:18
-3,5,2:18
-2,5,2:17.0
-1,5,2:18
-2,6,2:18
-1,6,2:106.4
-3,6,2:106.8
0,5,2:106.4
-4,5,2:106.8
1,4,2:106.2
-4,4,2:106.8
2,3,2:106.2
-4,3,2:106.8
2,2,2:106.2
-3,2,2:106.8
1,1,2:106.2
-2,1,2:106.1
0,0,2:106.2
-2,0,2:106.8
0,-1,2:106.2
-2,-1,2:106.8
-1,-2,2:106.1
-1,-3,2:106.2
-2,-4,2:106.1
-3,-5,2:106.1
0,2,3:18
-2,3,3:18
-1,3,3:18
0,3,3:18
-2,4,3:18
-2,5,3:18
-2,6,3:106.4
-1,5,3:106.2
-3,5,3:106.8
0,4,3:106.4
-1,4,3:106.2
-3,4,3:106.8
1,3,3:106.2
-3,3,3:106.8
1,2,3:106.2
-1,2,3:106.1
-2,2,3:106.1
0,1,3:106.1
