[META]
version=2.0
spawnOnBlockType=2
spawnSunlight=True
spawnDarkness=True
spawnWater=False
spawnLava=False
underFill=False
randomRotation=True
dig=False
tree=True
branch=False
needsFoundation=True
rarity=100
collisionPercentage=100
spawnElevationMin=0
spawnElevationMax=200
spawnInBiome=All
[DATA]
0,-1,0:18
-1,0,0:18
0,0,0:18
1,0,0:18
0,1,0:18
0,2,0:106.4
1,1,0:106.4
2,0,0:106.2
-2,0,0:106.8
1,-1,0:106.1
-1,-1,0:106.8
0,-2,0:106.1
1,-1,-3:17.0
0,0,-3:3
0,-1,-2:17.0
1,-1,-2:3
0,0,-2:3
-1,0,-2:3
0,1,-2:3
0,-1,-1:2
1,-1,-1:2
-1,0,-1:2
0,0,-1:17.0
1,0,-1:2
0,1,-1:2
0,0,1:18
0,2,1:106.4
1,1,1:106.4
2,0,1:106.2
-2,0,1:106.8
0,-2,1:106.1
0,-1,2:18
-1,0,2:18
0,0,2:18
1,0,2:18
0,1,2:18
0,2,2:106.4
1,1,2:106.4
2,0,2:106.2
-2,0,2:106.8
1,-1,2:106.1
-1,-1,2:106.8
0,-2,2:106.1
0,0,3:18
