[META]
version=2.0
spawnOnBlockType=2
spawnSunlight=True
spawnDarkness=True
spawnWater=False
spawnLava=False
underFill=False
randomRotation=True
dig=False
tree=True
branch=False
needsFoundation=True
rarity=100
collisionPercentage=70
spawnElevationMin=0
spawnElevationMax=120
spawnInBiome=All
[DATA]
-2,-4,0:18
2,-4,0:18
-3,-3,0:18
-2,-3,0:17.2
-1,-3,0:18
1,-3,0:18
2,-3,0:17.2
3,-3,0:18
-3,-2,0:18
-2,-2,0:17.2
-1,-2,0:17.2
0,-2,0:18
1,-2,0:18
2,-2,0:17.2
3,-2,0:18
-3,-1,0:18
-2,-1,0:18
-1,-1,0:17.2
0,-1,0:18
1,-1,0:17.2
2,-1,0:17.2
3,-1,0:18
-4,0,0:18
-3,0,0:17.2
-2,0,0:17.2
-1,0,0:18
0,0,0:17.2
1,0,0:18
2,0,0:18
-4,1,0:18
-3,1,0:17.2
-2,1,0:18
-1,1,0:17.2
0,1,0:18
1,1,0:18
2,1,0:17.2
3,1,0:18
-5,2,0:18
-4,2,0:17.2
-3,2,0:18
-1,2,0:18
0,2,0:17.2
1,2,0:17.2
2,2,0:18
-4,3,0:18
-1,3,0:18
0,3,0:17.2
1,3,0:18
0,4,0:18
1,4,0:17.2
2,4,0:18
1,5,0:18
1,6,0:31.1
2,5,0:31.1
0,5,0:38
-1,5,0:37
-2,5,0:31.1
3,4,0:31.1
-1,4,0:31.1
-2,4,0:31.1
-3,4,0:31.1
-4,4,0:31.1
2,3,0:31.1
-2,3,0:31.1
-3,3,0:31.1
-5,3,0:31.1
3,2,0:31.1
-2,2,0:31.1
-6,2,0:37
4,1,0:38
-5,1,0:31.1
3,0,0:31.1
-5,0,0:31.1
4,-1,0:31.1
-4,-1,0:31.1
-5,-1,0:31.1
4,-2,0:31.1
-4,-2,0:37
4,-3,0:31.1
0,-3,0:31.1
-4,-3,0:37
3,-4,0:31.1
1,-4,0:31.1
-1,-4,0:31.1
-3,-4,0:31.1
2,-5,0:31.1
-2,-5,0:31.1
-1,0,-5:3
-1,1,-5:3
0,1,-5:3
-2,-1,-4:3
-1,-1,-4:3
1,-1,-4:3
-2,0,-4:3
-1,0,-4:3
0,0,-4:3
-2,1,-4:3
-1,1,-4:3
0,1,-4:3
1,1,-4:3
-2,2,-4:3
-1,2,-4:3
0,2,-4:3
-2,-3,-3:3
2,-3,-3:3
-2,-2,-3:3
-1,-2,-3:17.2
1,-2,-3:3
2,-2,-3:3
-3,-1,-3:3
-2,-1,-3:3
-1,-1,-3:3
0,-1,-3:3
1,-1,-3:17.2
2,-1,-3:3
-3,0,-3:17.2
-2,0,-3:3
-1,0,-3:17.2
0,0,-3:17.2
1,0,-3:3
-3,1,-3:17.2
-2,1,-3:3
-1,1,-3:3
0,1,-3:17.2
1,1,-3:17.2
2,1,-3:3
-4,2,-3:3
-3,2,-3:3
-2,2,-3:3
-1,2,-3:3
0,2,-3:3
1,2,-3:3
-2,3,-3:3
-1,3,-3:3
0,3,-3:3
1,3,-3:3
1,4,-3:3
-2,-4,-2:3
2,-4,-2:3
-3,-3,-2:3
-2,-3,-2:17.2
-1,-3,-2:3
1,-3,-2:3
2,-3,-2:17.2
3,-3,-2:3
-3,-2,-2:3
-2,-2,-2:17.2
-1,-2,-2:17.2
0,-2,-2:17.2
1,-2,-2:3
2,-2,-2:17.2
3,-2,-2:3
-4,-1,-2:3
-3,-1,-2:17.2
-2,-1,-2:3
-1,-1,-2:17.2
0,-1,-2:3
1,-1,-2:17.2
2,-1,-2:17.2
3,-1,-2:3
-4,0,-2:3
-3,0,-2:17.2
-2,0,-2:17.2
-1,0,-2:17.2
0,0,-2:17.2
1,0,-2:17.2
2,0,-2:3
-4,1,-2:3
-3,1,-2:17.2
-2,1,-2:3
-1,1,-2:17.2
0,1,-2:17.2
1,1,-2:17.2
2,1,-2:17.2
3,1,-2:3
-5,2,-2:3
-4,2,-2:17.2
-3,2,-2:17.2
-2,2,-2:17.2
-1,2,-2:3
0,2,-2:17.2
1,2,-2:17.2
2,2,-2:3
-4,3,-2:3
-3,3,-2:3
-2,3,-2:3
-1,3,-2:3
0,3,-2:17.2
1,3,-2:3
-2,4,-2:3
-1,4,-2:3
0,4,-2:3
1,4,-2:3
2,4,-2:3
1,5,-2:3
-2,-5,-1:2
2,-5,-1:2
-3,-4,-1:2
-2,-4,-1:2
-1,-4,-1:2
1,-4,-1:2
2,-4,-1:2
3,-4,-1:2
-4,-3,-1:2
-3,-3,-1:2
-2,-3,-1:17.2
-1,-3,-1:2
0,-3,-1:2
1,-3,-1:2
2,-3,-1:17.2
3,-3,-1:2
4,-3,-1:2
-4,-2,-1:2
-3,-2,-1:2
-2,-2,-1:17.2
-1,-2,-1:17.2
0,-2,-1:2
1,-2,-1:2
2,-2,-1:17.2
3,-2,-1:2
4,-2,-1:2
-5,-1,-1:2
-4,-1,-1:2
-3,-1,-1:2
-2,-1,-1:2
-1,-1,-1:17.2
0,-1,-1:2
1,-1,-1:17.2
2,-1,-1:17.2
3,-1,-1:2
4,-1,-1:2
-5,0,-1:2
-4,0,-1:2
-3,0,-1:17.2
-2,0,-1:17.2
-1,0,-1:2
0,0,-1:17.2
1,0,-1:2
2,0,-1:2
3,0,-1:2
-5,1,-1:2
-4,1,-1:2
-3,1,-1:17.2
-2,1,-1:2
-1,1,-1:17.2
0,1,-1:2
1,1,-1:2
2,1,-1:17.2
3,1,-1:2
4,1,-1:2
-6,2,-1:2
-5,2,-1:2
-4,2,-1:17.2
-3,2,-1:2
-2,2,-1:2
-1,2,-1:2
0,2,-1:17.2
1,2,-1:17.2
2,2,-1:2
3,2,-1:2
-5,3,-1:2
-4,3,-1:2
-3,3,-1:2
-2,3,-1:2
-1,3,-1:2
0,3,-1:17.2
1,3,-1:2
2,3,-1:2
-4,4,-1:2
-3,4,-1:2
-2,4,-1:2
-1,4,-1:2
0,4,-1:2
1,4,-1:3
2,4,-1:2
3,4,-1:2
-2,5,-1:2
-1,5,-1:2
0,5,-1:2
1,5,-1:2
2,5,-1:2
1,6,-1:2
-2,-3,1:18
-1,-3,1:18
2,-3,1:18
-3,-2,1:18
-2,-2,1:17.2
-1,-2,1:17.2
0,-2,1:18
1,-2,1:18
2,-2,1:17.2
3,-2,1:18
-2,-1,1:18
-1,-1,1:17.2
0,-1,1:18
1,-1,1:17.2
2,-1,1:17.2
3,-1,1:18
-3,0,1:18
-2,0,1:17.2
-1,0,1:18
0,0,1:17.2
1,0,1:18
2,0,1:18
-4,1,1:18
-3,1,1:17.2
-2,1,1:18
-1,1,1:17.2
0,1,1:18
1,1,1:18
2,1,1:18
-4,2,1:18
-3,2,1:18
-1,2,1:18
0,2,1:17.2
1,2,1:17.2
2,2,1:18
-1,3,1:18
0,3,1:17.2
1,3,1:18
0,4,1:18
1,4,1:18
-1,-3,2:18
-2,-2,2:18
-1,-2,2:17.2
0,-2,2:18
1,-2,2:18
2,-2,2:18
-2,-1,2:18
-1,-1,2:17.2
0,-1,2:18
1,-1,2:17.2
2,-1,2:17.2
3,-1,2:18
-3,0,2:18
-2,0,2:17.2
-1,0,2:18
0,0,2:17.2
1,0,2:18
2,0,2:18
-3,1,2:18
-2,1,2:18
-1,1,2:17.2
0,1,2:18
-1,2,2:18
0,2,2:17.2
1,2,2:18
0,3,2:18
-1,-2,3:18
1,-2,3:18
-2,-1,3:18
-1,-1,3:17.2
0,-1,3:18
1,-1,3:17.2
2,-1,3:18
-2,0,3:18
-1,0,3:18
0,0,3:17.2
1,0,3:18
-2,1,3:18
-1,1,3:17.2
0,1,3:18
-1,2,3:18
0,2,3:18
-1,-1,4:18
0,-1,4:18
1,-1,4:18
-1,0,4:18
0,0,4:17.2
1,0,4:18
-1,1,4:18
0,1,4:18
0,0,5:18
