[META]
version=2.0
spawnOnBlockType=2
spawnSunlight=True
spawnDarkness=True
spawnWater=False
spawnLava=False
underFill=False
randomRotation=True
dig=False
tree=True
branch=False
needsFoundation=True
rarity=100
collisionPercentage=80
spawnElevationMin=0
spawnElevationMax=128
spawnInBiome=All
[DATA]
-1,-3,0:18
-2,-2,0:103
-1,-2,0:18
0,-2,0:18
-2,-1,0:18
-1,-1,0:103
0,-1,0:103
1,-1,0:18
-3,0,0:18
-2,0,0:18
-1,0,0:18
0,0,0:103
1,0,0:18
2,0,0:18
-2,1,0:18
-1,1,0:103
0,1,0:18
1,1,0:103
-1,2,0:18
0,2,0:18
1,2,0:31.2
-2,2,0:31.2
2,1,0:31.1
-3,1,0:31.1
2,-1,0:31.1
-3,-1,0:31.1
1,-2,0:31.2
0,-3,0:31.1
-1,0,-4:3
-1,-2,-3:3
-1,-1,-3:3
0,-1,-3:3
-2,0,-3:3
-1,0,-3:17.0
0,0,-3:3
1,0,-3:3
-1,1,-3:3
0,1,-3:3
-1,-2,-2:17.0
0,-2,-2:3
-2,-1,-2:3
-1,-1,-2:17.0
0,-1,-2:3
1,-1,-2:3
-2,0,-2:17.0
-1,0,-2:17.0
0,0,-2:17.0
1,0,-2:17.0
-2,1,-2:3
-1,1,-2:3
0,1,-2:17.0
1,1,-2:3
-1,-3,-1:2
0,-3,-1:2
-2,-2,-1:3
-1,-2,-1:17.0
0,-2,-1:2
1,-2,-1:2
-3,-1,-1:2
-2,-1,-1:2
-1,-1,-1:3
0,-1,-1:3
1,-1,-1:2
2,-1,-1:2
-3,0,-1:2
-2,0,-1:17.0
-1,0,-1:2
0,0,-1:3
1,0,-1:17.0
2,0,-1:2
-3,1,-1:2
-2,1,-1:2
-1,1,-1:3
0,1,-1:17.0
1,1,-1:3
2,1,-1:2
-2,2,-1:2
-1,2,-1:2
0,2,-1:2
1,2,-1:2
