[META]
version=2.0
spawnOnBlockType=2
spawnSunlight=True
spawnDarkness=True
spawnWater=False
spawnLava=False
underFill=False
randomRotation=True
dig=False
tree=True
branch=False
needsFoundation=True
rarity=300
collisionPercentage=100
spawnElevationMin=0
spawnElevationMax=128
spawnInBiome=All
[DATA]
0,1,-4:3.5
-1,0,-3:3.5
0,0,-3:3.5
1,0,-3:3.5
-1,1,-3:3.5
0,1,-3:3.5
1,1,-3:3.5
-1,2,-3:3.5
0,2,-3:3.5
1,2,-3:3.5
-1,-1,-2:2.5
0,-1,-2:2.5
1,-1,-2:2.5
-2,0,-2:2.5
-1,0,-2:2.5
0,0,-2:2.5
1,0,-2:2.5
2,0,-2:2.5
-2,1,-2:2.5
-1,1,-2:2.5
0,1,-2:3.0
1,1,-2:2.5
2,1,-2:2.5
-2,2,-2:2.5
-1,2,-2:2.5
0,2,-2:2.5
1,2,-2:2.5
2,2,-2:2.5
-1,3,-2:2.5
0,3,-2:2.5
1,3,-2:2.5
-1,0,-1:18.14
0,0,-1:18.14
1,0,-1:18.14
-1,1,-1:18.14
0,1,-1:17.0
1,1,-1:18.14
-1,2,-1:18.14
0,2,-1:18.14
1,2,-1:18.6
0,3,-1:18.14
-1,0,0:18.14
0,0,0:18.14
-1,1,0:18.14
0,1,0:17.0
1,1,0:18.14
0,2,0:18.14
0,-1,1:18.14
-1,0,1:18.14
0,0,1:17.0
1,0,1:18.14
0,1,1:18.14
0,-2,2:18.14
0,-1,2:18.14
-1,0,2:18.14
0,0,2:17.0
1,0,2:18.14
0,1,2:18.14
0,-3,3:18.14
-1,-2,3:18.14
0,-2,3:18.14
1,-2,3:18.14
-1,-1,3:18.14
0,-1,3:17.0
1,-1,3:18.14
-1,0,3:18.14
0,0,3:18.14
1,0,3:18.14
0,1,3:18.14
1,1,3:18.14
0,-3,4:18.14
-2,-2,4:18.14
-1,-2,4:18.14
0,-2,4:18.14
-2,-1,4:18.14
-1,-1,4:18.14
0,-1,4:17.0
1,-1,4:18.14
-1,0,4:18.14
0,0,4:18.14
1,0,4:18.14
-1,-3,5:18.14
0,-3,5:18.14
-2,-2,5:18.6
-1,-2,5:18.14
0,-2,5:18.14
-3,-1,5:18.14
-2,-1,5:17.0
-1,-1,5:18.14
0,-1,5:18.14
-2,0,5:18.6
-3,-2,6:18.14
-2,-2,6:18.14
-4,-1,6:18.14
-3,-1,6:18.14
-2,-1,6:18.14
-3,0,6:18.14
-2,0,6:18.14
-3,-1,7:18.14
-3,0,7:18.14
-2,0,7:18.14
