[META]
version=2.0
spawnOnBlockType=2
spawnSunlight=True
spawnDarkness=True
spawnWater=False
spawnLava=False
underFill=False
randomRotation=True
dig=False
tree=True
branch=False
needsFoundation=True
rarity=400
collisionPercentage=30
spawnElevationMin=0
spawnElevationMax=120
spawnInBiome=All
[DATA]
0,0,0:85
0,0,1:85
0,-2,1:18.0
-2,0,1:18.0
2,0,1:18.0
0,2,1:18.0
0,0,2:17.1
0,-2,2:18.0
-2,0,2:18.0
0,2,2:18.0
1,-1,2:18.0
-1,-1,2:18.0
-1,1,2:18.0
1,1,2:18.0
2,0,2:18.0
0,0,3:18.0
3,0,3:18.0
0,-3,3:18.0
-3,0,3:18.0
0,3,3:18.0
2,2,3:18.0
2,-2,3:18.0
-2,-2,3:18.0
-2,2,3:18.0
0,1,4:18.0
1,0,4:18.0
0,-2,4:18.0
-2,0,4:18.0
0,2,4:18.0
2,0,4:18.0
-1,-1,4:18.0
-1,1,4:18.0
1,1,4:18.0
1,-1,4:18.0
-1,0,4:18.0
0,-1,4:18.0
