[META]
version=2.0
spawnOnBlockType=2
spawnSunlight=True
spawnDarkness=True
spawnWater=False
spawnLava=False
underFill=False
randomRotation=True
dig=False
tree=True
branch=False
needsFoundation=True
rarity=100
collisionPercentage=80
spawnElevationMin=0
spawnElevationMax=200
spawnInBiome=All
[DATA]
-1,-3,0:30
-1,0,0:30
-1,1,0:17.0
0,5,0:106.4
-1,4,0:106.4
2,3,0:106.2
0,3,0:106.2
-2,3,0:106.4
1,2,0:106.4
-5,1,0:106.8
0,0,0:106.2
-4,0,0:106.8
1,-1,0:106.2
0,-2,0:31
-1,-2,0:106.1
-3,-2,0:106.1
0,-3,0:106.2
-1,1,1:17.0
0,1,1:30
0,5,1:106.4
-1,4,1:106.4
2,3,1:106.2
0,3,1:106.2
-2,3,1:106.4
1,2,1:106.4
-5,1,1:106.8
0,0,1:106.2
-4,0,1:106.8
1,-1,1:106.2
-1,-2,1:106.1
-3,-2,1:106.1
0,-3,1:106.2
-4,1,2:18
-3,1,2:18
-1,1,2:17.0
0,1,2:18
-3,2,2:18
-1,2,2:18
0,2,2:18
-1,3,2:18
0,5,2:106.4
-1,4,2:106.4
2,3,2:106.2
0,3,2:106.2
-2,3,2:106.4
1,2,2:106.4
-5,1,2:106.8
0,0,2:106.2
-4,0,2:106.8
1,-1,2:106.2
-1,-2,2:106.1
-3,-2,2:106.1
0,-3,2:106.2
-2,-3,3:18
-1,-3,3:18
-3,-1,3:18
-2,-1,3:18
-1,-1,3:18
-3,0,3:18
-2,0,3:18
-1,0,3:17.0
-3,1,3:18
-2,1,3:18
-1,1,3:17.0
0,1,3:18
1,1,3:18
-3,2,3:18
-2,2,3:18
-1,2,3:18
0,2,3:103
0,5,3:106.4
2,3,3:106.2
-2,3,3:106.4
1,2,3:106
-5,1,3:106.8
0,0,3:106.2
-4,0,3:106.8
1,-1,3:106.2
-1,-2,3:106.1
-3,-2,3:106.1
0,-3,3:106.2
-2,-3,4:18
-1,-3,4:18
-2,-2,4:18
-1,-2,4:18
0,-2,4:18
-3,-1,4:103
-2,-1,4:18
-1,-1,4:18
0,-1,4:18
-3,0,4:18
-2,0,4:18
-1,0,4:17.0
0,0,4:18
1,0,4:18
-3,1,4:18
-2,1,4:18
-1,1,4:18
0,1,4:18
-2,2,4:18
-1,2,4:18
0,2,4:18
-2,3,4:18
-1,3,4:18
0,3,4:18
1,3,4:18
1,4,4:18
0,5,4:106.4
2,3,4:106.2
1,2,4:106.1
-5,1,4:106.8
1,-1,4:106.2
-2,-1,5:18
-1,-1,5:18
-4,0,5:18
-3,0,5:18
-2,0,5:18
-1,0,5:18
-4,1,5:18
-3,1,5:18
-1,1,5:18
-2,2,5:18
-1,2,5:18
-2,3,5:18
0,3,5:18
1,3,5:18
-1,4,5:18
0,4,5:18
0,5,5:106.4
1,4,5:106.2
-4,2,5:106.4
-5,1,5:106.8
-5,0,5:106.8
-1,1,-1:17.0
