[META]
version=2.0
spawnOnBlockType=2
spawnSunlight=True
spawnDarkness=True
spawnWater=False
spawnLava=False
underFill=False
randomRotation=True
dig=False
tree=True
branch=False
needsFoundation=True
rarity=100
collisionPercentage=80
spawnElevationMin=0
spawnElevationMax=200
spawnInBiome=All
[DATA]
-2,0,0:17.0
0,4,0:106.4
2,2,0:106.2
0,2,0:31.2
-1,2,0:106.4
-2,1,0:106.8
2,0,0:31.2
0,0,0:106.2
-3,0,0:31.2
-4,0,0:106.8
1,-1,0:106.2
0,-2,0:106.1
-1,-2,0:106.1
-2,-2,0:31.2
-3,-2,0:106.1
-2,-3,0:106.1
-1,-1,0:31.1
-1,0,0:31.1
-1,1,0:31.1
0,1,0:31.1
0,-1,0:31.1
1,1,0:31.1
1,0,0:31.1
-2,-1,1:17.0
-3,0,1:18
-2,0,1:17.0
-1,0,1:30
0,4,1:106.4
2,2,1:106.2
-1,2,1:106.4
1,1,1:106.2
-2,1,1:106.8
0,0,1:106.2
-4,0,1:106.8
1,-1,1:106.2
0,-2,1:106.1
-1,-2,1:106.1
-3,-2,1:106.1
-2,-3,1:106.1
-2,-2,2:18
-3,-1,2:18
-2,-1,2:17.0
-1,-1,2:17.0
-3,0,2:103
-2,0,2:18
-1,0,2:18
-1,1,2:18
0,1,2:18
1,2,2:18
0,4,2:106.4
2,2,2:106.2
-1,2,2:106.4
1,1,2:106.2
-2,1,2:106.8
2,0,2:106.2
0,0,2:106.2
1,-1,2:106.2
0,-2,2:106.1
-1,-2,2:106.1
-3,-2,2:106.1
-2,-3,2:106.1
-1,-2,3:18
-2,-1,3:18
-1,-1,3:17.0
0,-1,3:18
-2,0,3:18
-1,0,3:17.0
0,0,3:103
-2,1,3:18
-1,1,3:17.0
0,1,3:103
1,1,3:18
-1,2,3:18
0,2,3:18
1,2,3:18
0,3,3:18
0,4,3:106.4
2,2,3:106.2
2,0,3:106.2
1,-1,3:106.2
0,-2,3:106.1
-1,-1,4:18
-2,0,4:18
-1,0,4:18
0,0,4:18
1,0,4:18
-2,1,4:18
-1,1,4:18
0,1,4:18
1,1,4:18
0,2,4:18
2,0,4:106.2
-2,-1,-1:17.0
-2,1,-1:17.0
-2,0,-1:2
-2,-2,-1:2
-3,0,-1:2
0,2,-1:2
2,0,-1:2
-1,-1,-1:2
0,-1,-1:2
-1,0,-1:2
-1,1,-1:2
0,1,-1:2
0,0,-1:2
1,0,-1:2
1,1,-1:2
