[META]
version=2.0
spawnOnBlockType=2
spawnSunlight=True
spawnDarkness=True
spawnWater=False
spawnLava=False
underFill=False
randomRotation=True
dig=False
tree=True
branch=False
needsFoundation=True
rarity=100
collisionPercentage=80
spawnElevationMin=0
spawnElevationMax=200
spawnInBiome=All
[DATA]
0,-2,0:18
3,-2,0:17.0
-2,-1,0:17.0
-2,0,0:18
0,1,0:106.4
-1,1,0:106.4
2,0,0:106.4
4,-1,0:106.2
1,-1,0:106.4
4,-3,0:106.2
-1,-3,0:106.1
3,-4,0:106.1
1,-4,0:106.1
3,-2,1:17.0
-2,-1,1:17.0
0,1,1:106.4
-1,1,1:106.4
2,0,1:106.4
4,-1,1:106.2
1,-1,1:106.4
4,-3,1:106.2
-1,-3,1:106.1
3,-4,1:106.1
1,-4,1:106.1
3,-3,2:18
1,-2,2:18
2,-2,2:18
3,-2,2:17.0
4,-2,2:18
-3,-1,2:18
-2,-1,2:18
2,-1,2:18
3,-1,2:18
-2,0,2:18
0,1,2:106.4
-1,1,2:106.4
2,0,2:106.4
4,-1,2:106.2
1,-1,2:106.4
4,-3,2:106.2
-1,-3,2:106.1
3,-4,2:106.1
1,-4,2:106.1
0,-3,3:18
1,-3,3:18
3,-3,3:18
-2,-2,3:18
-1,-2,3:18
0,-2,3:18
1,-2,3:18
2,-2,3:18
3,-2,3:18
-2,-1,3:18
-1,-1,3:103
0,-1,3:18
1,-1,3:18
2,-1,3:18
-2,0,3:18
-1,0,3:18
0,0,3:18
0,1,3:106.4
-1,1,3:106.4
-1,-3,3:106.1
3,-4,3:106.1
1,-4,3:106.1
0,-2,4:18
1,-2,4:18
0,-1,4:18
1,-1,4:103
