[META]
version=2.0
spawnOnBlockType=2,3
spawnSunlight=True
spawnDarkness=True
spawnWater=False
spawnLava=False
underFill=False
randomRotation=False
dig=True
tree=False
branch=False
needsFoundation=True
rarity=10
collisionPercentage=0
spawnElevationMin=0
spawnElevationMax=200
spawnInBiome=All
[DATA]
-1,-3,0:1
0,-3,0:1
-1,-2,0:11
0,-2,0:1
1,-2,0:1
-2,-1,0:11
-1,-1,0:11
0,-1,0:1
1,-1,0:1
-2,0,0:11
-1,0,0:1
0,0,0:11
1,0,0:1
2,0,0:1
-2,1,0:1
-1,1,0:16
0,1,0:1
1,1,0:1
2,1,0:1
0,2,0:16
1,2,0:1
2,2,0:1
0,-1,-4:1
-1,0,-4:1
0,0,-4:49
1,0,-4:1
0,1,-4:1
0,-2,-3:88
-1,-1,-3:1
0,-1,-3:1
1,-1,-3:1
-1,0,-3:1
0,0,-3:56
1,0,-3:1
-1,1,-3:1
0,1,-3:1
1,1,-3:16
-1,-3,-2:88
0,-3,-2:88
1,-3,-2:88
-2,-2,-2:1
-1,-2,-2:1
0,-2,-2:1
1,-2,-2:88
2,-2,-2:88
-3,-1,-2:1
-2,-1,-2:1
-1,-1,-2:1
0,-1,-2:1
1,-1,-2:1
2,-1,-2:88
-3,0,-2:1
-2,0,-2:1
-1,0,-2:1
0,0,-2:11
1,0,-2:1
2,0,-2:16
-2,1,-2:88
-1,1,-2:1
0,1,-2:1
1,1,-2:1
2,1,-2:88
-1,2,-2:88
0,2,-2:16
1,2,-2:88
-1,-4,-1:110
0,-4,-1:110
1,-4,-1:110
-2,-3,-1:1
-1,-3,-1:1
0,-3,-1:1
1,-3,-1:110
2,-3,-1:110
-3,-2,-1:1
-2,-2,-1:11
-1,-2,-1:11
0,-2,-1:1
1,-2,-1:1
2,-2,-1:110
3,-2,-1:110
-4,-1,-1:1
-3,-1,-1:11
-2,-1,-1:11
-1,-1,-1:1
0,-1,-1:1
1,-1,-1:1
2,-1,-1:16
3,-1,-1:110
-4,0,-1:1
-3,0,-1:11
-2,0,-1:11
-1,0,-1:1
0,0,-1:11
1,0,-1:1
2,0,-1:1
3,0,-1:1
-3,1,-1:1
-2,1,-1:1
-1,1,-1:1
0,1,-1:1
1,1,-1:1
2,1,-1:1
3,1,-1:110
-2,2,-1:110
-1,2,-1:110
0,2,-1:1
1,2,-1:1
2,2,-1:3
3,2,-1:110
-1,3,-1:110
0,3,-1:110
1,3,-1:110
2,3,-1:110
0,-2,1:1
-1,-1,1:11
0,-1,1:11
1,-1,1:1
-2,0,1:11
-1,0,1:11
0,0,1:11
1,0,1:1
2,0,1:1
-2,1,1:16
-1,1,1:1
0,1,1:1
1,1,1:1
2,1,1:1
1,2,1:1
0,-2,2:1
0,-1,2:11
1,-1,2:16
-1,0,2:11
0,0,2:11
1,0,2:1
-1,1,2:1
0,1,2:16
1,1,2:1
2,1,2:1
1,2,2:1
1,0,3:1
0,1,3:1
1,1,3:1
2,1,3:1
1,1,4:1
