[META]
version=2.0
spawnOnBlockType=2
spawnSunlight=True
spawnDarkness=True
spawnWater=False
spawnLava=False
underFill=False
randomRotation=True
dig=True
tree=false
branch=False
needsFoundation=True
rarity=100
collisionPercentage=10
spawnElevationMin=0
spawnElevationMax=128
spawnInBiome=All
[DATA]
0,-2,-2:3.0
1,-2,-2:3.0
-1,-1,-2:3.0
0,-1,-2:3.0
1,-1,-2:3.0
2,-1,-2:17.2
-2,0,-2:3.0
-1,0,-2:3.0
0,0,-2:3.0
1,0,-2:3.0
2,0,-2:3.0
-2,1,-2:3.0
-1,1,-2:3.0
0,1,-2:3.0
1,1,-2:3.0
0,2,-2:3.0
0,-3,-1:2.5
1,-3,-1:2.5
-1,-2,-1:2.5
0,-2,-1:9.0
1,-2,-1:9.0
2,-2,-1:17.2
-2,-1,-1:2.5
-1,-1,-1:9.0
0,-1,-1:9.0
1,-1,-1:9.0
2,-1,-1:9.0
3,-1,-1:2.5
-3,0,-1:2.5
-2,0,-1:9.0
-1,0,-1:9.0
0,0,-1:9.0
1,0,-1:9.0
2,0,-1:9.0
3,0,-1:2.5
-3,1,-1:2.5
-2,1,-1:9.0
-1,1,-1:9.0
0,1,-1:9.0
1,1,-1:9.0
2,1,-1:2.5
-2,2,-1:2.5
-1,2,-1:2.5
0,2,-1:9.0
1,2,-1:2.5
0,3,-1:2.5
2,-2,0:17.2
2,-3,1:18.14
1,-2,1:18.14
2,-2,1:18.14
3,-2,1:18.14
2,-1,1:18.14
2,-2,2:18.14
1,2,0:83.0
-1,2,0:31.1
2,1,0:83.4
-1,1,0:111.5
-3,1,0:31.2
3,0,0:31.2
0,0,0:111.5
-2,-1,0:31.1
-1,-2,0:31.1
0,-3,0:31.2
