[META]
version=2.0
spawnOnBlockType=2
spawnSunlight=True
spawnDarkness=True
spawnWater=False
spawnLava=False
underFill=False
randomRotation=True
dig=False
tree=false
branch=False
needsFoundation=True
rarity=70
collisionPercentage=10
spawnElevationMin=0
spawnElevationMax=128
spawnInBiome=All
[DATA]
-1,-1,-3:3.5
0,-1,-3:3.5
-1,0,-3:3.5
-1,-2,-2:3.5
0,-2,-2:3.5
-2,-1,-2:3.5
-1,-1,-2:12.5
0,-1,-2:12.5
1,-1,-2:3.5
-1,0,-2:12.5
0,0,-2:3.0
-1,1,-2:3.5
-1,-2,-1:2.0
0,-2,-1:2.0
1,-2,-1:2.0
-2,-1,-1:2.0
-1,-1,-1:9.0
0,-1,-1:9.0
1,-1,-1:2.0
-2,0,-1:2.0
-1,0,-1:9.0
0,0,-1:2.0
1,0,-1:2.0
-1,1,-1:2.0
0,1,-1:2.0
0,0,2:83.0
0,0,1:83.0
-1,1,0:83.0
0,0,0:83.0
-2,0,0:31.1
1,-1,0:83.0
-1,-1,0:111.5
-2,-1,0:31.1
0,-2,0:31.1
-1,-2,0:31.2
