[META]
version=2.0
spawnOnBlockType=2
spawnSunlight=True
spawnDarkness=True
spawnWater=False
spawnLava=False
underFill=False
randomRotation=True
dig=True
tree=false
branch=False
needsFoundation=True
rarity=100
collisionPercentage=10
spawnElevationMin=0
spawnElevationMax=128
spawnInBiome=All
[DATA]
-2,-1,-2:3.0
-1,-1,-2:3.0
-2,0,-2:3.0
-1,0,-2:3.0
0,0,-2:3.0
-3,1,-2:3.0
-2,1,-2:3.0
-1,1,-2:3.0
0,1,-2:3.0
1,1,-2:3.0
-3,2,-2:3.0
-2,2,-2:3.0
-1,2,-2:3.0
0,2,-2:3.0
1,2,-2:3.0
-2,3,-2:3.0
-1,3,-2:3.0
0,3,-2:3.0
1,3,-2:3.0
-2,4,-2:3.0
-1,4,-2:3.0
0,4,-2:3.0
-2,-3,-1:2.5
-2,-2,-1:2.5
-1,-2,-1:2.5
-3,-1,-1:2.5
-2,-1,-1:9.0
-1,-1,-1:9.0
0,-1,-1:2.5
1,-1,-1:2.5
-3,0,-1:2.5
-2,0,-1:9.0
-1,0,-1:9.0
0,0,-1:9.0
1,0,-1:2.5
-4,1,-1:2.5
-3,1,-1:9.0
-2,1,-1:9.0
-1,1,-1:9.0
0,1,-1:9.0
1,1,-1:9.0
2,1,-1:2.5
-4,2,-1:2.5
-3,2,-1:9.0
-2,2,-1:9.0
-1,2,-1:9.0
0,2,-1:9.0
1,2,-1:9.0
2,2,-1:2.5
-3,3,-1:2.5
-2,3,-1:9.0
-1,3,-1:9.0
0,3,-1:2.5
1,3,-1:2.5
-2,4,-1:2.5
-1,4,-1:2.5
0,4,-1:2.5
-1,4,0:31.2
1,3,0:37.5
0,3,0:83.2
-3,3,0:31.1
2,2,0:31.1
2,1,0:31.1
1,0,0:83.2
-3,0,0:83.0
1,-1,0:31.1
0,-1,0:83.2
-3,-1,0:37.5
-1,-2,0:31.1
-2,-2,0:31.1
-2,-3,0:31.2
