[META]
version=2.0
spawnOnBlockType=2
spawnSunlight=True
spawnDarkness=True
spawnWater=False
spawnLava=False
underFill=False
randomRotation=True
dig=True
tree=False
branch=False
needsFoundation=True
rarity=1
collisionPercentage=10
spawnElevationMin=0
spawnElevationMax=102
groupId=Ruins
groupFrequencyMin=20
groupFrequencyMax=35
groupSeperationMin=5
groupSeperationMax=60
branchLimit=6
spawnInBiome=All
[DATA]
-2,-3,0:17
-1,-3,0:5
0,-3,0:5
1,-3,0:5
2,-3,0:5
3,-3,0:17
-2,-2,0:5
-1,-2,0:47
1,-2,0:61.3
2,-2,0:58
3,-2,0:5
-2,-1,0:5
0,-1,0:17
-2,0,0:5
2,0,0:54
3,0,0:5
-2,1,0:17
-1,1,0:5
0,1,0:5
1,1,0:5
2,1,0:5
3,1,0:17
3,3,0:37
2,3,0:31.1
1,3,0:31.2
0,3,0:39
-2,3,0:38
3,2,0:38
2,2,0:39
0,2,0:31.1
-1,2,0:31.2
-2,2,0:37
-3,2,0:39
4,1,0:31.1
-3,1,0:31.1
-4,1,0:39
5,0,0:31.2
4,0,0:83
1,0,0:40
0,0,0:26.1
-1,0,0:26.9
-3,0,0:106.8
4,-1,0:31.1
-3,-1,0:31.1
5,-2,0:106.2
4,-2,0:31.2
0,-2,0:106.2
-3,-2,0:31.2
-4,-2,0:39
5,-3,0:31.2
4,-3,0:31.1
-3,-3,0:106.8
-4,-3,0:37
4,-4,0:31.2
3,-4,0:31.1
2,-4,0:31.1
1,-4,0:31.1
0,-4,0:31.2
-1,-4,0:37
-2,-4,0:31.1
-3,-4,0:31.2
-4,-4,0:40
2,-5,0:31.2
1,-5,0:31.2
0,-5,0:37
-1,-5,0:38
-2,-5,0:39
-1,-1,0:0
1,-1,0:0
2,-1,0:0
3,-1,0:0
0,-4,-6:1
-1,-3,-6:1
0,-3,-6:1
1,-3,-6:1
2,-3,-6:1
-2,-2,-6:1
-1,-2,-6:1
0,-2,-6:1
1,-2,-6:1
2,-2,-6:1
3,-2,-6:1
-2,-1,-6:1
-1,-1,-6:1
0,-1,-6:1
1,-1,-6:1
2,-1,-6:1
3,-1,-6:1
-2,0,-6:1
-1,0,-6:1
0,0,-6:1
1,0,-6:1
2,0,-6:1
3,0,-6:1
0,1,-6:1
1,1,-6:1
2,1,-6:1
3,1,-6:1
-1,-4,-5:1
0,-4,-5:3
1,-4,-5:1
2,-4,-5:1
-2,-3,-5:1
-1,-3,-5:3
0,-3,-5:5
1,-3,-5:5
2,-3,-5:3
3,-3,-5:1
-3,-2,-5:1
-2,-2,-5:3
-1,-2,-5:3
0,-2,-5:3
1,-2,-5:5
2,-2,-5:3
3,-2,-5:3
4,-2,-5:1
-3,-1,-5:1
-2,-1,-5:3
-1,-1,-5:3
0,-1,-5:5
1,-1,-5:5
2,-1,-5:5
3,-1,-5:5
4,-1,-5:1
-3,0,-5:1
-2,0,-5:3
-1,0,-5:5
0,0,-5:5
1,0,-5:5
2,0,-5:5
3,0,-5:5
4,0,-5:1
-2,1,-5:1
-1,1,-5:3
0,1,-5:5
1,1,-5:5
2,1,-5:5
3,1,-5:5
4,1,-5:1
-1,2,-5:1
0,2,-5:1
1,2,-5:3
2,2,-5:1
3,2,-5:1
1,3,-5:1
0,-5,-4:1
1,-5,-4:1
-2,-4,-4:1
-1,-4,-4:1
0,-4,-4:5
1,-4,-4:5
2,-4,-4:3
3,-4,-4:1
-3,-3,-4:1
-2,-3,-4:3
-1,-3,-4:5
0,-3,-4:54
2,-3,-4:5
3,-3,-4:3
4,-3,-4:1
-4,-2,-4:1
-3,-2,-4:3
-2,-2,-4:3
-1,-2,-4:3
0,-2,-4:47
2,-2,-4:47
3,-2,-4:47
4,-2,-4:1
-4,-1,-4:1
-3,-1,-4:3
-2,-1,-4:3
-1,-1,-4:5
3,-1,-4:30
4,-1,-4:47
5,-1,-4:1
-4,0,-4:1
-3,0,-4:1
-2,0,-4:5
4,0,-4:47
5,0,-4:1
-3,1,-4:1
-2,1,-4:3
-1,1,-4:5
4,1,-4:47
5,1,-4:1
-2,2,-4:1
-1,2,-4:3
0,2,-4:47
1,2,-4:47
2,2,-4:47
3,2,-4:47
4,2,-4:1
-1,3,-4:1
0,3,-4:1
1,3,-4:1
2,3,-4:1
3,3,-4:1
-1,0,-4:65.3
1,-2,-4:64.7
1,-3,-4:0
1,-1,-4:0
0,-1,-4:0
0,0,-4:0
0,1,-4:0
1,1,-4:0
1,0,-4:0
2,0,-4:0
2,-1,-4:0
3,0,-4:0
3,1,-4:0
2,1,-4:0
-1,-5,-3:1
0,-5,-3:1
1,-5,-3:1
-3,-4,-3:1
-2,-4,-3:3
0,-4,-3:5
1,-4,-3:5
2,-4,-3:3
3,-4,-3:3
4,-4,-3:1
-3,-3,-3:3
-2,-3,-3:3
-1,-3,-3:5
1,-3,-3:30
2,-3,-3:5
3,-3,-3:3
4,-3,-3:3
5,-3,-3:1
-4,-2,-3:3
-3,-2,-3:3
-2,-2,-3:3
-1,-2,-3:3
0,-2,-3:47
2,-2,-3:47
3,-2,-3:47
4,-2,-3:3
5,-2,-3:1
-4,-1,-3:1
-3,-1,-3:3
-2,-1,-3:3
-1,-1,-3:5
4,-1,-3:47
5,-1,-3:1
-4,0,-3:1
-3,0,-3:3
-2,0,-3:5
2,0,-3:30
4,0,-3:47
5,0,-3:1
-4,1,-3:1
-3,1,-3:3
-2,1,-3:3
-1,1,-3:5
4,1,-3:47
5,1,-3:1
-3,2,-3:1
-2,2,-3:3
-1,2,-3:3
0,2,-3:47
1,2,-3:47
2,2,-3:47
3,2,-3:47
4,2,-3:3
5,2,-3:1
-2,3,-3:1
-1,3,-3:1
0,3,-3:3
1,3,-3:1
2,3,-3:1
3,3,-3:3
4,3,-3:1
-1,0,-3:65.2
1,-2,-3:64.8
0,-1,-3:0
1,-1,-3:0
1,0,-3:0
0,1,-3:0
0,0,-3:0
1,1,-3:0
2,1,-3:0
3,1,-3:0
3,0,-3:0
2,-1,-3:0
3,-1,-3:0
0,-3,-3:0
-1,-5,-2:3
0,-5,-2:3
1,-5,-2:3
2,-5,-2:3
-2,-4,-2:3
-1,-4,-2:3
0,-4,-2:3
1,-4,-2:3
2,-4,-2:3
3,-4,-2:3
4,-4,-2:1
-4,-3,-2:3
-3,-3,-2:3
-2,-3,-2:3
-1,-3,-2:3
0,-3,-2:5
1,-3,-2:5
2,-3,-2:3
3,-3,-2:3
4,-3,-2:3
-4,-2,-2:3
-3,-2,-2:3
-2,-2,-2:3
-1,-2,-2:3
0,-2,-2:3
1,-2,-2:2
2,-2,-2:3
3,-2,-2:3
4,-2,-2:3
5,-2,-2:1
-4,-1,-2:1
-3,-1,-2:3
-2,-1,-2:3
-1,-1,-2:5
1,-1,-2:2
2,-1,-2:2
3,-1,-2:3
4,-1,-2:3
5,-1,-2:3
-3,0,-2:3
-2,0,-2:5
0,0,-2:30
2,0,-2:3
3,0,-2:3
4,0,-2:3
5,0,-2:3
-4,1,-2:1
-3,1,-2:3
-2,1,-2:3
-1,1,-2:5
2,1,-2:3
3,1,-2:3
4,1,-2:3
5,1,-2:1
-2,2,-2:3
-1,2,-2:3
0,2,-2:3
1,2,-2:3
2,2,-2:3
3,2,-2:3
4,2,-2:3
5,2,-2:1
0,3,-2:3
1,3,-2:3
2,3,-2:3
3,3,-2:3
4,3,-2:1
-1,0,-2:65.3
0,-1,-2:0
1,0,-2:0
1,1,-2:0
0,1,-2:0
-2,-5,-1:2
-1,-5,-1:2
0,-5,-1:2
1,-5,-1:2
2,-5,-1:2
-4,-4,-1:2
-3,-4,-1:2
-2,-4,-1:2
-1,-4,-1:2
0,-4,-1:2
1,-4,-1:2
2,-4,-1:2
3,-4,-1:2
4,-4,-1:2
-4,-3,-1:2
-3,-3,-1:2
-2,-3,-1:3
-1,-3,-1:3
0,-3,-1:3
1,-3,-1:3
2,-3,-1:3
3,-3,-1:3
4,-3,-1:2
5,-3,-1:2
-4,-2,-1:2
-3,-2,-1:2
-2,-2,-1:3
-1,-2,-1:5
0,-2,-1:2
2,-2,-1:5
3,-2,-1:3
4,-2,-1:2
5,-2,-1:2
-3,-1,-1:2
-2,-1,-1:3
-1,-1,-1:5
0,-1,-1:17
3,-1,-1:5
4,-1,-1:2
5,-1,-1:2
-3,0,-1:2
-2,0,-1:5
0,0,-1:5
1,0,-1:5
2,0,-1:5
3,0,-1:9
4,0,-1:2
5,0,-1:2
-4,1,-1:2
-3,1,-1:2
-2,1,-1:3
-1,1,-1:5
0,1,-1:3
1,1,-1:3
2,1,-1:3
3,1,-1:3
4,1,-1:2
5,1,-1:2
-3,2,-1:2
-2,2,-1:2
-1,2,-1:2
0,2,-1:2
1,2,-1:2
2,2,-1:2
3,2,-1:2
4,2,-1:2
5,2,-1:2
-2,3,-1:2
0,3,-1:2
1,3,-1:2
2,3,-1:2
3,3,-1:2
-1,0,-1:65.2
2,-1,-1:37
1,-1,-1:39
1,-2,-1:38
-2,-3,1:17
-1,-3,1:5
1,-3,1:102
2,-3,1:5
3,-3,1:17
-2,-2,1:5
-1,-2,1:47
3,-2,1:5
0,-1,1:17
-2,0,1:5
-1,0,1:30
3,0,1:5
-2,1,1:17
-1,1,1:5
0,1,1:102
2,1,1:5
3,1,1:17
3,2,1:106.4
2,2,1:106.4
-1,2,1:106.4
-2,2,1:106.4
4,1,1:106.2
1,1,1:40
-3,1,1:106.8
4,0,1:83
2,0,1:106.1
0,0,1:106.1
-3,0,1:106.8
4,-1,1:106.2
2,-1,1:106.2
-2,-1,1:39
5,-2,1:106.2
2,-2,1:40
1,-2,1:40
0,-2,1:106.2
-3,-2,1:106.8
4,-3,1:106.2
0,-3,1:40
-3,-3,1:106.8
2,-4,1:106.1
-1,-4,1:106.1
-2,-4,2:53.2
-1,-4,2:53.2
0,-4,2:53.2
1,-4,2:53.2
2,-4,2:53.2
3,-4,2:18
-2,-3,2:17
-1,-3,2:5
0,-3,2:5
1,-3,2:5
3,-3,2:18
-3,-2,2:18
-2,-2,2:5
1,-2,2:30
3,-2,2:5
-2,-1,2:102
0,-1,2:17
3,-1,2:5
-2,0,2:5
3,0,2:5
-2,1,2:17
-1,1,2:5
0,1,2:5
1,1,2:5
2,1,2:5
3,1,2:17
-2,2,2:53.3
0,2,2:53.3
1,2,2:53.3
-1,2,2:106.4
4,0,2:106.2
2,0,2:106.1
0,0,2:106.1
-3,0,2:106.8
4,-1,2:106.2
2,-1,2:106.2
-3,-1,2:106.8
5,-2,2:106.2
-1,-2,2:39
-3,-3,2:106.8
-2,-4,3:18
0,-4,3:18
1,-4,3:18
2,-4,3:18
-2,-3,3:18
-1,-3,3:18
1,-3,3:53.2
2,-3,3:53.2
3,-3,3:18
-3,-2,3:18
-2,-2,3:5
3,-2,3:5
4,-2,3:18
-2,-1,3:5
-1,-1,3:18
0,-1,3:17
1,-1,3:18
3,-1,3:5
-2,0,3:5
0,0,3:18
3,0,3:5
-3,1,3:53.3
-2,1,3:53.3
-1,1,3:18
0,1,3:53.3
1,1,3:18
2,1,3:53.3
3,1,3:53.3
0,2,3:106.4
-1,2,3:106.4
4,-1,3:106
2,-1,3:106.2
-3,-1,3:106.8
5,-2,3:106.2
-1,-2,3:106.1
-2,-3,4:18
0,-3,4:18
1,-3,4:18
2,-3,4:18
3,-3,4:18
-3,-2,4:18
-2,-2,4:53.2
-1,-2,4:18
0,-2,4:18
1,-2,4:18
2,-2,4:18
3,-2,4:53.2
4,-2,4:18
-3,-1,4:18
-2,-1,4:18
-1,-1,4:18
0,-1,4:17
1,-1,4:18
3,-1,4:5
-3,0,4:53.3
-2,0,4:18
-1,0,4:18
0,0,4:18
1,0,4:18
2,0,4:53.3
3,0,4:53.3
4,0,4:53.3
-1,1,4:18
0,1,4:18
2,1,4:18
0,2,4:106.4
-1,2,4:106.4
4,-1,4:106.4
5,-2,4:106.2
-3,-2,5:18
-2,-2,5:18
0,-2,5:18
-3,-1,5:44.2
-2,-1,5:44.2
-1,-1,5:18
0,-1,5:17
1,-1,5:18
2,-1,5:18
3,-1,5:44.2
4,-1,5:44.2
-1,0,5:18
0,0,5:18
1,0,5:18
2,0,5:18
-1,1,5:39
0,-1,6:18
1,0,6:40
