[META]
version=2.0
spawnOnBlockType=3,2
spawnSunlight=True
spawnDarkness=True
spawnWater=False
spawnLava=False
underFill=False
randomRotation=True
dig=True
tree=False
branch=False
needsFoundation=True
rarity=30
collisionPercentage=20
spawnElevationMin=0
spawnElevationMax=75
spawnInBiome=All
[DATA]
2,-6,-8:1.5
3,-6,-8:1.5
3,-5,-8:1.5
2,-7,-7:1.5
2,-6,-7:1.5
3,-6,-7:1.5
2,-5,-7:1.5
3,-5,-7:1.5
4,-5,-7:1.5
2,-8,-6:3.5
1,-7,-6:1.5
2,-7,-6:1.5
3,-7,-6:1.5
1,-6,-6:1.5
2,-6,-6:1.5
3,-6,-6:1.5
4,-6,-6:1.5
1,-5,-6:3.5
2,-5,-6:1.5
3,-5,-6:1.5
4,-5,-6:1.5
5,-5,-6:1.5
2,-4,-6:3.5
3,-4,-6:1.5
4,-4,-6:1.5
2,-10,-5:17.0
3,-10,-5:17.0
6,-10,-5:17.0
2,-9,-5:1.5
6,-9,-5:17.0
1,-8,-5:1.5
2,-8,-5:1.5
3,-8,-5:1.5
5,-8,-5:17.0
-4,-7,-5:17.0
0,-7,-5:1.5
1,-7,-5:1.5
2,-7,-5:1.5
4,-7,-5:17.0
5,-7,-5:17.0
-4,-6,-5:17.0
0,-6,-5:1.5
1,-6,-5:1.5
2,-6,-5:1.5
3,-6,-5:1.5
4,-6,-5:1.5
-1,-5,-5:17.0
0,-5,-5:17.0
1,-5,-5:1.5
2,-5,-5:1.5
3,-5,-5:1.5
4,-5,-5:1.5
5,-5,-5:1.5
6,-5,-5:1.5
7,-5,-5:1.5
-1,-4,-5:17.0
1,-4,-5:1.5
2,-4,-5:17.0
3,-4,-5:17.0
4,-4,-5:1.5
5,-4,-5:1.5
6,-4,-5:1.5
7,-4,-5:88.5
8,-4,-5:17.0
1,-3,-5:17.0
2,-3,-5:3.5
3,-3,-5:1.5
4,-3,-5:88.5
-2,-2,-5:17.0
6,0,-5:17.0
6,1,-5:17.0
2,-10,-4:17.0
6,-10,-4:17.0
2,-9,-4:3.5
-3,-8,-4:17.0
1,-8,-4:3.5
2,-8,-4:1.5
3,-8,-4:3.5
4,-8,-4:3.5
-4,-7,-4:17.0
-3,-7,-4:17.0
0,-7,-4:3.5
1,-7,-4:3.5
2,-7,-4:1.5
3,-7,-4:3.5
4,-7,-4:3.5
5,-7,-4:17.0
-1,-6,-4:88.5
0,-6,-4:3.5
1,-6,-4:1.5
2,-6,-4:1.5
3,-6,-4:1.5
4,-6,-4:88.5
5,-6,-4:17.0
6,-6,-4:3.5
-1,-5,-4:88.5
0,-5,-4:17.0
1,-5,-4:3.5
2,-5,-4:3.5
3,-5,-4:3.5
4,-5,-4:88.5
5,-5,-4:3.5
6,-5,-4:3.5
7,-5,-4:88.5
0,-4,-4:3.5
2,-4,-4:3.5
3,-4,-4:3.5
4,-4,-4:1.5
5,-4,-4:88.5
6,-4,-4:3.5
7,-4,-4:1.5
8,-4,-4:17.0
1,-3,-4:17.0
2,-3,-4:3.5
3,-3,-4:17.0
4,-3,-4:17.0
5,-3,-4:3.5
6,-3,-4:1.5
7,-3,-4:88.5
9,-3,-4:3.5
-3,-2,-4:17.0
4,-2,-4:3.5
5,-2,-4:88.5
6,-2,-4:88.5
6,-1,-4:17.0
8,-1,-4:3.5
9,-1,-4:17.0
6,0,-4:17.0
2,-10,-3:17.0
5,-10,-3:17.0
1,-9,-3:17.0
2,-9,-3:17.0
3,-9,-3:3.5
4,-9,-3:3.5
5,-9,-3:17.0
6,-9,-3:17.0
0,-8,-3:3.5
1,-8,-3:3.5
2,-8,-3:88.5
3,-8,-3:88.5
4,-8,-3:3.5
5,-8,-3:3.5
-4,-7,-3:17.0
-1,-7,-3:3.5
0,-7,-3:3.5
1,-7,-3:88.5
2,-7,-3:3.5
3,-7,-3:88.5
4,-7,-3:88.5
5,-7,-3:88.5
6,-7,-3:3.5
7,-7,-3:3.5
-4,-6,-3:17.0
-2,-6,-3:88.5
-1,-6,-3:3.5
0,-6,-3:3.5
1,-6,-3:88.5
2,-6,-3:3.5
3,-6,-3:88.5
4,-6,-3:88.5
5,-6,-3:17.0
6,-6,-3:88.5
7,-6,-3:3.5
13,-6,-3:17.0
-2,-5,-3:88.5
-1,-5,-3:17.0
0,-5,-3:17.0
1,-5,-3:88.5
2,-5,-3:88.5
3,-5,-3:3.5
4,-5,-3:1.5
5,-5,-3:3.5
6,-5,-3:3.5
7,-5,-3:88.5
8,-5,-3:88.5
9,-5,-3:88.5
-2,-4,-3:88.5
-1,-4,-3:88.5
0,-4,-3:3.5
1,-4,-3:3.5
2,-4,-3:3.5
3,-4,-3:3.5
4,-4,-3:1.5
5,-4,-3:88.5
6,-4,-3:3.5
7,-4,-3:17.0
8,-4,-3:17.0
9,-4,-3:3.5
10,-4,-3:3.5
11,-4,-3:17.0
12,-4,-3:17.0
-3,-3,-3:17.0
-2,-3,-3:3.5
-1,-3,-3:3.5
0,-3,-3:88.5
1,-3,-3:17.0
2,-3,-3:88.5
3,-3,-3:88.5
4,-3,-3:17.0
5,-3,-3:17.0
6,-3,-3:1.5
7,-3,-3:88.5
9,-3,-3:3.5
10,-3,-3:3.5
-3,-2,-3:17.0
1,-2,-3:88.5
2,-2,-3:3.5
3,-2,-3:3.5
4,-2,-3:3.5
5,-2,-3:3.5
6,-2,-3:17.0
7,-2,-3:88.5
9,-2,-3:3.5
3,-1,-3:3.5
4,-1,-3:3.5
5,-1,-3:3.5
6,-1,-3:17.0
7,-1,-3:3.5
8,-1,-3:17.0
9,-1,-3:17.0
4,0,-3:88.5
6,0,-3:3.5
3,-10,-2:3.5
4,-10,-2:88.5
5,-10,-2:88.5
6,-10,-2:88.5
-1,-9,-2:88.5
1,-9,-2:17.0
2,-9,-2:3.5
3,-9,-2:3.5
4,-9,-2:88.5
5,-9,-2:17.0
6,-9,-2:17.0
-2,-8,-2:88.5
-1,-8,-2:88.5
0,-8,-2:88.5
1,-8,-2:17.0
2,-8,-2:88.5
3,-8,-2:88.5
4,-8,-2:88.5
5,-8,-2:88.5
6,-8,-2:3.5
7,-8,-2:3.5
-6,-7,-2:3.5
-5,-7,-2:3.5
-4,-7,-2:3.5
-3,-7,-2:88.5
-2,-7,-2:3.5
-1,-7,-2:88.5
0,-7,-2:3.5
1,-7,-2:3.5
2,-7,-2:3.5
3,-7,-2:3.5
4,-7,-2:3.5
5,-7,-2:3.5
6,-7,-2:17.0
7,-7,-2:88.5
8,-7,-2:88.5
-6,-6,-2:88.5
-5,-6,-2:3.5
-4,-6,-2:17.0
-3,-6,-2:88.5
-2,-6,-2:17.0
-1,-6,-2:88.5
0,-6,-2:88.5
1,-6,-2:3.5
2,-6,-2:3.5
5,-6,-2:17.0
6,-6,-2:3.5
7,-6,-2:88.5
8,-6,-2:3.5
9,-6,-2:88.5
13,-6,-2:17.0
14,-6,-2:17.0
-5,-5,-2:17.0
-4,-5,-2:17.0
-3,-5,-2:88.5
-2,-5,-2:17.0
-1,-5,-2:17.0
0,-5,-2:88.5
1,-5,-2:3.5
2,-5,-2:17.0
3,-5,-2:88.5
4,-5,-2:1.5
5,-5,-2:17.0
6,-5,-2:3.5
7,-5,-2:3.5
8,-5,-2:17.0
9,-5,-2:17.0
10,-5,-2:88.5
11,-5,-2:3.5
12,-5,-2:3.5
13,-5,-2:3.5
-4,-4,-2:3.5
-3,-4,-2:88.5
-2,-4,-2:3.5
-1,-4,-2:3.5
0,-4,-2:3.5
1,-4,-2:17.0
3,-4,-2:3.5
4,-4,-2:3.5
5,-4,-2:3.5
6,-4,-2:3.5
7,-4,-2:17.0
8,-4,-2:17.0
9,-4,-2:88.5
10,-4,-2:3.5
11,-4,-2:17.0
12,-4,-2:3.5
-3,-3,-2:17.0
-2,-3,-2:17.0
-1,-3,-2:88.5
0,-3,-2:88.5
1,-3,-2:17.0
2,-3,-2:88.5
3,-3,-2:3.5
4,-3,-2:3.5
5,-3,-2:17.0
6,-3,-2:3.5
9,-3,-2:88.5
11,-3,-2:88.5
-2,-2,-2:3.5
-1,-2,-2:3.5
0,-2,-2:17.0
1,-2,-2:88.5
2,-2,-2:3.5
3,-2,-2:3.5
4,-2,-2:3.5
5,-2,-2:17.0
6,-2,-2:17.0
7,-2,-2:3.5
8,-2,-2:88.5
9,-2,-2:88.5
10,-2,-2:88.5
1,-1,-2:3.5
2,-1,-2:88.5
3,-1,-2:17.0
4,-1,-2:88.5
5,-1,-2:3.5
7,-1,-2:3.5
8,-1,-2:17.0
9,-1,-2:3.5
2,0,-2:17.0
3,0,-2:88.5
4,0,-2:88.5
5,0,-2:3.5
6,0,-2:17.0
7,0,-2:3.5
8,0,-2:3.5
4,1,-2:17.0
3,-11,-1:110.5
5,-11,-1:110.5
-1,-10,-1:3.0
0,-10,-1:110.5
2,-10,-1:110.5
3,-10,-1:17.0
4,-10,-1:110.5
5,-10,-1:110.5
6,-10,-1:17.0
-2,-9,-1:110.5
-1,-9,-1:110.5
0,-9,-1:110.5
1,-9,-1:110.5
2,-9,-1:110.5
3,-9,-1:3.0
4,-9,-1:3.0
5,-9,-1:17.0
6,-9,-1:3.0
7,-9,-1:110.5
-6,-8,-1:110.5
-5,-8,-1:110.5
-2,-8,-1:110.5
-1,-8,-1:110.5
0,-8,-1:110.5
1,-8,-1:17.0
2,-8,-1:110.5
3,-8,-1:110.5
4,-8,-1:3.0
5,-8,-1:17.0
6,-8,-1:17.0
7,-8,-1:110.5
-7,-7,-1:110.5
-6,-7,-1:17.0
-5,-7,-1:3.0
-4,-7,-1:110.5
-3,-7,-1:110.5
-2,-7,-1:110.5
-1,-7,-1:110.5
0,-7,-1:110.5
1,-7,-1:17.0
2,-7,-1:110.5
3,-7,-1:110.5
4,-7,-1:3.0
5,-7,-1:3.0
6,-7,-1:110.5
7,-7,-1:3.0
8,-7,-1:110.5
-7,-6,-1:110.5
-6,-6,-1:3.0
-5,-6,-1:17.0
-3,-6,-1:3.0
-2,-6,-1:17.0
-1,-6,-1:3.0
0,-6,-1:3.0
1,-6,-1:3.0
2,-6,-1:110.5
3,-6,-1:3.0
4,-6,-1:110.5
5,-6,-1:110.5
6,-6,-1:110.5
7,-6,-1:110.5
8,-6,-1:3.0
9,-6,-1:110.5
12,-6,-1:110.5
13,-6,-1:110.5
14,-6,-1:17.0
-6,-5,-1:110.5
-5,-5,-1:17.0
-4,-5,-1:3.0
-3,-5,-1:3.5
-2,-5,-1:3.0
-1,-5,-1:17.0
0,-5,-1:110.5
2,-5,-1:110.5
3,-5,-1:110.5
4,-5,-1:110.5
5,-5,-1:17.0
6,-5,-1:110.5
7,-5,-1:110.5
8,-5,-1:17.0
9,-5,-1:17.0
10,-5,-1:110.5
11,-5,-1:110.5
12,-5,-1:110.5
13,-5,-1:3.0
14,-5,-1:3.0
-5,-4,-1:3.0
-4,-4,-1:3.0
-3,-4,-1:17.0
-2,-4,-1:3.0
-1,-4,-1:3.0
0,-4,-1:3.0
1,-4,-1:17.0
2,-4,-1:110.5
3,-4,-1:17.0
4,-4,-1:110.5
5,-4,-1:17.0
6,-4,-1:110.5
7,-4,-1:17.0
8,-4,-1:17.0
9,-4,-1:3.0
10,-4,-1:110.5
11,-4,-1:17.0
12,-4,-1:110.5
-5,-3,-1:3.0
-4,-3,-1:110.5
-3,-3,-1:17.0
-2,-3,-1:17.0
-1,-3,-1:3.0
0,-3,-1:3.0
1,-3,-1:3.0
2,-3,-1:3.0
3,-3,-1:110.5
4,-3,-1:3.0
5,-3,-1:17.0
6,-3,-1:110.5
7,-3,-1:110.5
8,-3,-1:110.5
9,-3,-1:3.0
10,-3,-1:3.0
11,-3,-1:110.5
-4,-2,-1:110.5
-3,-2,-1:3.0
-2,-2,-1:3.0
-1,-2,-1:3.0
0,-2,-1:17.0
1,-2,-1:3.0
2,-2,-1:3.0
3,-2,-1:17.0
4,-2,-1:110.5
5,-2,-1:110.5
6,-2,-1:17.0
7,-2,-1:110.5
8,-2,-1:110.5
9,-2,-1:3.0
10,-2,-1:110.5
-4,-1,-1:3.0
-3,-1,-1:110.5
0,-1,-1:110.5
1,-1,-1:110.5
2,-1,-1:110.5
3,-1,-1:110.5
4,-1,-1:110.5
5,-1,-1:110.5
6,-1,-1:110.5
7,-1,-1:110.5
8,-1,-1:17.0
9,-1,-1:110.5
1,0,-1:110.5
2,0,-1:110.5
3,0,-1:3.0
4,0,-1:3.0
5,0,-1:3.0
6,0,-1:3.0
7,0,-1:3.0
8,0,-1:110.5
9,0,-1:110.5
2,1,-1:3.0
3,1,-1:3.0
4,1,-1:17.0
5,1,-1:110.5
6,1,-1:110.5
9,1,-1:3.0
1,2,-1:110.5
2,2,-1:17.0
3,2,-1:110.5
-1,-10,0:99.10
3,-10,0:17.0
6,-10,0:17.0
3,-9,0:17.0
4,-9,0:17.0
5,-9,0:17.0
6,-9,0:17.0
1,-8,0:17.0
4,-8,0:17.0
-6,-7,0:17.0
-5,-7,0:17.0
1,-7,0:17.0
4,-7,0:17.0
5,-7,0:17.0
7,-7,0:17.0
-6,-6,0:17.0
-5,-6,0:17.0
-4,-6,0:17.0
-3,-6,0:17.0
-2,-6,0:17.0
-1,-6,0:17.0
0,-6,0:17.0
1,-6,0:17.0
3,-6,0:17.0
8,-6,0:17.0
14,-6,0:17.0
-5,-5,0:17.0
-4,-5,0:17.0
-3,-5,0:3.5
-2,-5,0:17.0
-1,-5,0:17.0
1,-5,0:17.0
9,-5,0:17.0
13,-5,0:17.0
14,-5,0:17.0
-5,-4,0:17.0
-4,-4,0:17.0
-3,-4,0:17.0
-2,-4,0:17.0
-1,-4,0:17.0
0,-4,0:17.0
9,-4,0:17.0
-5,-3,0:17.0
-3,-3,0:17.0
-2,-3,0:17.0
-1,-3,0:17.0
0,-3,0:17.0
1,-3,0:17.0
2,-3,0:17.0
4,-3,0:99.10
9,-3,0:17.0
10,-3,0:99.10
-3,-2,0:17.0
-2,-2,0:17.0
-1,-2,0:17.0
1,-2,0:17.0
2,-2,0:17.0
9,-2,0:17.0
-4,-1,0:17.0
8,-1,0:17.0
3,0,0:17.0
4,0,0:17.0
5,0,0:17.0
6,0,0:17.0
7,0,0:17.0
2,1,0:17.0
3,1,0:17.0
4,1,0:17.0
9,1,0:17.0
2,2,0:17.0
-1,-10,1:99.10
5,-8,1:17.0
4,-7,1:17.0
5,-7,1:17.0
-5,-6,1:17.0
-4,-6,1:17.0
-2,-6,1:17.0
-1,-6,1:17.0
3,-6,1:17.0
8,-6,1:17.0
-5,-5,1:17.0
-4,-5,1:17.0
-3,-5,1:17.0
0,-5,1:17.0
1,-5,1:17.0
8,-5,1:17.0
9,-5,1:17.0
12,-5,1:17.0
13,-5,1:17.0
-4,-4,1:17.0
-3,-4,1:17.0
-2,-4,1:17.0
-1,-4,1:17.0
0,-4,1:17.0
9,-4,1:17.0
-3,-3,1:17.0
-2,-3,1:17.0
-1,-3,1:17.0
1,-3,1:17.0
2,-3,1:17.0
4,-3,1:99.10
9,-3,1:17.0
10,-3,1:99.10
-3,-2,1:17.0
-2,-2,1:17.0
-1,-2,1:17.0
2,-2,1:17.0
9,-2,1:17.0
8,-1,1:17.0
4,0,1:17.0
5,0,1:17.0
6,0,1:17.0
7,0,1:17.0
8,0,1:17.0
9,0,1:17.0
4,1,1:17.0
9,1,1:17.0
-1,-10,2:99.10
3,-8,2:99.1
4,-8,2:99.3
5,-8,2:17.0
3,-7,2:99.1
4,-7,2:17.0
5,-7,2:17.0
-4,-6,2:17.0
-1,-6,2:17.0
0,-6,2:17.0
3,-6,2:17.0
7,-6,2:17.0
8,-6,2:17.0
-4,-5,2:17.0
-3,-5,2:17.0
0,-5,2:17.0
1,-5,2:17.0
9,-5,2:17.0
11,-5,2:17.0
12,-5,2:17.0
-4,-4,2:17.0
-3,-4,2:17.0
-2,-4,2:17.0
-1,-4,2:17.0
0,-4,2:17.0
1,-4,2:17.0
8,-4,2:17.0
9,-4,2:17.0
10,-4,2:17.0
11,-4,2:17.0
-3,-3,2:17.0
-2,-3,2:17.0
-1,-3,2:17.0
0,-3,2:17.0
1,-3,2:17.0
4,-3,2:99.10
9,-3,2:17.0
10,-3,2:99.10
-3,-2,2:17.0
-2,-2,2:17.0
-1,-2,2:17.0
0,-2,2:17.0
2,-2,2:17.0
8,-2,2:17.0
8,-1,2:17.0
5,0,2:17.0
6,0,2:17.0
7,0,2:17.0
4,1,2:17.0
-2,-11,3:100.1
-1,-11,3:100.1
0,-11,3:100.9
-2,-10,3:100.1
-1,-10,3:100.1
0,-10,3:100.9
-2,-9,3:100.7
-1,-9,3:100.7
0,-9,3:100.9
4,-7,3:17.0
5,-7,3:17.0
0,-6,3:17.0
1,-6,3:17.0
4,-6,3:17.0
5,-6,3:17.0
7,-6,3:17.0
-4,-5,3:17.0
-3,-5,3:17.0
1,-5,3:17.0
8,-5,3:17.0
9,-5,3:17.0
-3,-4,3:17.0
-2,-4,3:17.0
-1,-4,3:17.0
0,-4,3:17.0
1,-4,3:17.0
8,-4,3:17.0
-3,-3,3:17.0
-2,-3,3:17.0
-1,-3,3:17.0
0,-3,3:17.0
1,-3,3:17.0
4,-3,3:99.10
8,-3,3:17.0
10,-3,3:99.10
-1,-2,3:17.0
0,-2,3:17.0
1,-2,3:17.0
8,-1,3:17.0
5,0,3:17.0
6,0,3:17.0
7,0,3:17.0
4,1,3:17.0
5,1,3:99.9
7,1,3:17.0
4,2,3:99.7
5,2,3:99.9
3,-7,4:17.0
4,-7,4:17.0
1,-6,4:17.0
2,-6,4:17.0
3,-6,4:17.0
4,-6,4:17.0
5,-6,4:17.0
6,-6,4:17.0
7,-6,4:17.0
-3,-5,4:17.0
-2,-5,4:17.0
1,-5,4:17.0
6,-5,4:17.0
7,-5,4:17.0
-3,-4,4:17.0
-2,-4,4:17.0
-1,-4,4:17.0
0,-4,4:17.0
1,-4,4:17.0
3,-4,4:100.1
4,-4,4:100.3
5,-4,4:100.3
7,-4,4:17.0
8,-4,4:17.0
9,-4,4:100.1
10,-4,4:100.1
11,-4,4:100.3
-3,-3,4:17.0
-2,-3,4:17.0
-1,-3,4:17.0
0,-3,4:17.0
1,-3,4:17.0
3,-3,4:100.1
4,-3,4:100.9
5,-3,4:100.9
7,-3,4:17.0
8,-3,4:17.0
9,-3,4:100.1
10,-3,4:100.1
11,-3,4:100.3
1,-2,4:17.0
3,-2,4:100.7
4,-2,4:100.7
5,-2,4:100.9
7,-2,4:17.0
9,-2,4:100.7
10,-2,4:100.7
11,-2,4:100.9
7,-1,4:17.0
4,0,4:17.0
5,0,4:17.0
6,0,4:17.0
4,1,4:17.0
7,1,4:17.0
2,-8,5:99.1
3,-8,5:99.3
2,-7,5:99.1
3,-7,5:17.0
4,-7,5:17.0
2,-6,5:17.0
4,-6,5:17.0
7,-6,5:99.1
8,-6,5:99.3
-2,-5,5:17.0
1,-5,5:17.0
5,-5,5:17.0
6,-5,5:17.0
7,-5,5:17.0
8,-5,5:99.3
-3,-4,5:17.0
-2,-4,5:17.0
-1,-4,5:17.0
0,-4,5:17.0
1,-4,5:17.0
5,-4,5:17.0
6,-4,5:17.0
7,-4,5:17.0
8,-4,5:99.9
-2,-3,5:17.0
-1,-3,5:17.0
0,-3,5:17.0
1,-3,5:17.0
6,-3,5:17.0
7,-3,5:17.0
1,-2,5:17.0
7,-2,5:17.0
6,-1,5:17.0
7,-1,5:17.0
2,0,5:17.0
3,0,5:17.0
3,-7,6:17.0
2,-6,6:17.0
4,-6,6:17.0
-3,-5,6:99.1
-2,-5,6:99.1
-1,-5,6:99.1
1,-5,6:17.0
4,-5,6:17.0
7,-5,6:17.0
-3,-4,6:99.7
-2,-4,6:17.0
-1,-4,6:17.0
0,-4,6:17.0
1,-4,6:17.0
5,-4,6:17.0
6,-4,6:17.0
-2,-3,6:17.0
-1,-3,6:17.0
0,-3,6:17.0
1,-3,6:17.0
5,-3,6:17.0
6,-3,6:17.0
0,-2,6:17.0
1,-2,6:17.0
2,-2,6:17.0
2,-1,6:17.0
6,-1,6:17.0
1,0,6:17.0
2,0,6:17.0
3,-7,7:17.0
1,-6,7:17.0
2,-6,7:17.0
4,-6,7:17.0
7,-6,7:99.1
8,-6,7:99.3
0,-5,7:17.0
1,-5,7:17.0
7,-5,7:17.0
8,-5,7:99.3
-2,-4,7:17.0
-1,-4,7:17.0
0,-4,7:17.0
5,-4,7:17.0
7,-4,7:99.9
8,-4,7:99.9
-3,-3,7:99.1
-2,-3,7:17.0
-1,-3,7:17.0
0,-3,7:17.0
4,-3,7:17.0
5,-3,7:17.0
6,-3,7:17.0
-3,-2,7:99.7
-2,-2,7:99.9
-1,-2,7:17.0
0,-2,7:17.0
1,-2,7:17.0
2,-2,7:17.0
0,-1,7:17.0
1,-1,7:17.0
4,-1,7:17.0
5,-1,7:17.0
6,-1,7:99.9
0,0,7:17.0
1,0,7:17.0
2,0,7:99.9
5,0,7:99.7
6,0,7:99.9
1,1,7:99.7
2,1,7:99.9
1,-8,8:99.1
2,-8,8:99.3
3,-8,8:99.3
1,-7,8:99.1
2,-7,8:17.0
3,-7,8:17.0
0,-6,8:17.0
1,-6,8:17.0
4,-6,8:17.0
0,-5,8:17.0
6,-5,8:17.0
7,-5,8:17.0
-3,-4,8:17.0
-2,-4,8:17.0
-1,-4,8:17.0
0,-4,8:17.0
5,-4,8:17.0
-3,-3,8:17.0
-2,-3,8:17.0
-1,-3,8:17.0
0,-3,8:17.0
4,-3,8:17.0
5,-3,8:17.0
-2,-2,8:17.0
-1,-2,8:17.0
0,-2,8:17.0
1,-2,8:17.0
2,-2,8:17.0
4,-2,8:17.0
-1,-1,8:17.0
0,-1,8:17.0
4,-1,8:17.0
0,0,8:17.0
2,-7,9:17.0
3,-7,9:17.0
-3,-6,9:99.1
-2,-6,9:99.1
0,-6,9:17.0
1,-6,9:17.0
2,-6,9:17.0
3,-6,9:17.0
4,-6,9:17.0
6,-6,9:99.3
7,-6,9:99.3
-3,-5,9:99.7
-2,-5,9:17.0
-1,-5,9:17.0
0,-5,9:17.0
2,-5,9:17.0
6,-5,9:17.0
7,-5,9:99.9
-3,-4,9:17.0
-2,-4,9:17.0
-1,-4,9:17.0
4,-4,9:17.0
5,-4,9:17.0
6,-4,9:99.9
7,-4,9:99.9
-3,-3,9:17.0
-2,-3,9:17.0
-1,-3,9:17.0
0,-3,9:17.0
3,-3,9:17.0
4,-3,9:17.0
-4,-2,9:99.1
-3,-2,9:17.0
-2,-2,9:17.0
-1,-2,9:17.0
0,-2,9:17.0
1,-2,9:17.0
2,-2,9:17.0
3,-2,9:17.0
-4,-1,9:99.7
-3,-1,9:99.9
-1,-1,9:17.0
0,-1,9:17.0
1,-1,9:99.9
0,0,9:99.7
1,0,9:99.9
0,-8,10:99.1
1,-8,10:99.3
0,-7,10:99.1
1,-7,10:17.0
2,-7,10:17.0
3,-7,10:17.0
-1,-6,10:17.0
0,-6,10:17.0
2,-6,10:17.0
3,-6,10:17.0
4,-6,10:17.0
-3,-5,10:17.0
-2,-5,10:17.0
-1,-5,10:17.0
0,-5,10:17.0
2,-5,10:17.0
5,-5,10:17.0
6,-5,10:17.0
-4,-4,10:17.0
-3,-4,10:17.0
-2,-4,10:17.0
-1,-4,10:17.0
4,-4,10:17.0
-4,-3,10:17.0
-3,-3,10:17.0
0,-3,10:17.0
3,-3,10:17.0
-4,-2,10:17.0
-3,-2,10:17.0
-2,-2,10:17.0
-1,-2,10:17.0
0,-2,10:17.0
1,-2,10:17.0
2,-2,10:17.0
3,-2,10:17.0
4,-2,10:99.9
-1,-1,10:17.0
0,-1,10:17.0
3,-1,10:99.7
4,-1,10:99.9
0,-7,11:17.0
1,-7,11:17.0
2,-7,11:17.0
-1,-6,11:17.0
2,-6,11:17.0
3,-6,11:17.0
4,-6,11:17.0
-3,-5,11:17.0
-2,-5,11:17.0
-1,-5,11:17.0
2,-5,11:17.0
5,-5,11:17.0
-4,-4,11:17.0
-1,-4,11:17.0
2,-4,11:17.0
-4,-3,11:17.0
0,-3,11:17.0
1,-3,11:17.0
2,-3,11:17.0
3,-3,11:17.0
-5,-2,11:99.1
-4,-2,11:17.0
-3,-2,11:17.0
-2,-2,11:17.0
-1,-2,11:17.0
0,-2,11:17.0
1,-2,11:17.0
2,-2,11:17.0
3,-2,11:17.0
-5,-1,11:99.7
-4,-1,11:99.9
-2,-1,11:17.0
-1,-1,11:17.0
0,-7,12:17.0
1,-7,12:17.0
2,-7,12:17.0
-5,-6,12:99.1
-4,-6,12:99.1
-2,-6,12:17.0
-1,-6,12:17.0
2,-6,12:17.0
4,-6,12:17.0
5,-6,12:99.3
6,-6,12:99.3
-5,-5,12:99.7
-4,-5,12:17.0
-3,-5,12:17.0
2,-5,12:17.0
3,-5,12:17.0
5,-5,12:17.0
6,-5,12:99.9
-4,-4,12:17.0
2,-4,12:17.0
5,-4,12:99.7
6,-4,12:99.9
-4,-3,12:17.0
2,-3,12:17.0
-5,-2,12:17.0
-4,-2,12:17.0
-3,-2,12:17.0
-2,-2,12:17.0
-1,-2,12:17.0
0,-2,12:17.0
1,-2,12:17.0
2,-2,12:17.0
-2,-1,12:17.0
-1,-1,12:17.0
0,-1,12:99.9
-1,0,12:99.7
0,0,12:99.9
-2,-8,13:99.1
-1,-8,13:99.3
0,-8,13:99.3
-2,-7,13:99.1
-1,-7,13:17.0
0,-7,13:17.0
1,-7,13:17.0
-2,-6,13:17.0
1,-6,13:17.0
2,-6,13:17.0
-4,-5,13:17.0
-3,-5,13:17.0
2,-5,13:17.0
3,-5,13:17.0
4,-5,13:17.0
5,-5,13:17.0
-5,-4,13:17.0
2,-4,13:17.0
-5,-3,13:17.0
2,-3,13:17.0
-6,-2,13:99.1
-5,-2,13:17.0
-4,-2,13:17.0
-3,-2,13:17.0
-2,-2,13:17.0
-1,-2,13:17.0
0,-2,13:17.0
1,-2,13:17.0
2,-2,13:17.0
3,-2,13:99.9
-6,-1,13:99.7
-5,-1,13:99.9
-4,-1,13:99.9
-3,-1,13:17.0
-2,-1,13:17.0
-1,-1,13:17.0
2,-1,13:99.7
3,-1,13:99.9
-1,-7,14:17.0
0,-7,14:17.0
1,-7,14:17.0
-3,-6,14:17.0
-2,-6,14:17.0
1,-6,14:17.0
-5,-5,14:17.0
-4,-5,14:17.0
2,-5,14:17.0
3,-5,14:17.0
-5,-4,14:17.0
-5,-3,14:17.0
-5,-2,14:17.0
-2,-2,14:17.0
-1,-2,14:17.0
0,-2,14:17.0
1,-2,14:17.0
-4,-1,14:17.0
-3,-1,14:17.0
-2,-1,14:17.0
-1,-1,14:17.0
0,-1,14:17.0
-2,0,14:17.0
-2,-7,15:17.0
-1,-7,15:17.0
0,-7,15:17.0
-6,-6,15:99.1
-5,-6,15:99.1
-4,-6,15:17.0
-3,-6,15:17.0
1,-6,15:17.0
-6,-5,15:99.7
-5,-5,15:17.0
0,-5,15:17.0
1,-5,15:17.0
2,-5,15:17.0
-5,-4,15:17.0
0,-4,15:17.0
3,-4,15:17.0
-6,-3,15:17.0
3,-3,15:17.0
-5,-2,15:17.0
-3,-2,15:17.0
-2,-2,15:17.0
-1,-2,15:17.0
0,-2,15:17.0
1,-2,15:17.0
-5,-1,15:17.0
-4,-1,15:17.0
-3,-1,15:17.0
-2,-1,15:17.0
-1,-1,15:17.0
0,-1,15:17.0
1,-1,15:17.0
-3,0,15:17.0
-2,0,15:17.0
-1,0,15:17.0
-4,-8,16:99.1
-3,-8,16:99.3
-2,-8,16:99.3
-4,-7,16:99.1
-3,-7,16:17.0
-2,-7,16:17.0
-1,-7,16:17.0
0,-7,16:17.0
-4,-6,16:17.0
0,-6,16:17.0
1,-6,16:17.0
2,-6,16:99.1
3,-6,16:99.3
-5,-5,16:17.0
2,-5,16:17.0
3,-5,16:99.3
-6,-4,16:17.0
3,-4,16:17.0
-6,-3,16:17.0
3,-3,16:17.0
-7,-2,16:99.1
-6,-2,16:17.0
-4,-2,16:17.0
-3,-2,16:17.0
-2,-2,16:17.0
-1,-2,16:17.0
0,-2,16:17.0
1,-2,16:17.0
-7,-1,16:99.7
-6,-1,16:99.7
-5,-1,16:17.0
-4,-1,16:17.0
-3,-1,16:17.0
-2,-1,16:17.0
-1,-1,16:17.0
0,-1,16:17.0
1,-1,16:17.0
2,-1,16:99.9
-7,0,16:99.7
-6,0,16:99.7
-5,0,16:99.9
-4,0,16:17.0
-3,0,16:17.0
-2,0,16:17.0
-1,0,16:17.0
1,0,16:99.7
2,0,16:99.9
-2,1,16:17.0
-3,-7,17:17.0
-2,-7,17:17.0
-1,-7,17:17.0
-5,-6,17:17.0
-4,-6,17:17.0
0,-6,17:17.0
1,-6,17:17.0
-5,-5,17:17.0
2,-5,17:17.0
-6,-4,17:17.0
-5,-4,17:17.0
3,-4,17:17.0
-6,-3,17:17.0
-5,-3,17:17.0
3,-3,17:17.0
-6,-2,17:17.0
-5,-2,17:17.0
-4,-2,17:17.0
-3,-2,17:17.0
-2,-2,17:17.0
-1,-2,17:17.0
0,-2,17:17.0
1,-2,17:17.0
2,-2,17:17.0
3,-2,17:17.0
-5,-1,17:17.0
-4,-1,17:17.0
-3,-1,17:17.0
-2,-1,17:17.0
-1,-1,17:17.0
0,-1,17:17.0
1,-1,17:17.0
-4,0,17:17.0
-3,0,17:17.0
-2,0,17:17.0
-1,0,17:17.0
-2,1,17:17.0
-3,-7,18:17.0
-2,-7,18:17.0
-1,-7,18:17.0
-5,-6,18:17.0
-4,-6,18:17.0
-1,-6,18:17.0
0,-6,18:17.0
1,-6,18:17.0
3,-6,18:99.1
4,-6,18:99.3
-5,-5,18:17.0
2,-5,18:17.0
3,-5,18:17.0
4,-5,18:99.3
-6,-4,18:99.10
-5,-4,18:17.0
4,-4,18:17.0
-5,-3,18:17.0
4,-3,18:17.0
-5,-2,18:17.0
-4,-2,18:17.0
-3,-2,18:17.0
-2,-2,18:17.0
-1,-2,18:17.0
0,-2,18:17.0
1,-2,18:17.0
2,-2,18:17.0
3,-2,18:17.0
-5,-1,18:17.0
-4,-1,18:17.0
-3,-1,18:17.0
-2,-1,18:17.0
-1,-1,18:17.0
0,-1,18:17.0
1,-1,18:17.0
2,-1,18:17.0
-3,0,18:17.0
-2,0,18:17.0
-1,0,18:17.0
0,0,18:99.9
-2,1,18:17.0
-1,1,18:99.7
0,1,18:99.9
-2,-8,19:99.1
-1,-8,19:99.3
-6,-7,19:99.1
-5,-7,19:99.1
-4,-7,19:99.1
-3,-7,19:17.0
-2,-7,19:17.0
-1,-7,19:99.3
-6,-6,19:99.7
-5,-6,19:17.0
-4,-6,19:17.0
-3,-6,19:17.0
-1,-6,19:17.0
0,-6,19:17.0
1,-6,19:17.0
-5,-5,19:17.0
2,-5,19:17.0
3,-5,19:17.0
-6,-4,19:99.10
-5,-4,19:17.0
4,-4,19:17.0
-5,-3,19:17.0
4,-3,19:17.0
-5,-2,19:17.0
-3,-2,19:17.0
-2,-2,19:17.0
-1,-2,19:17.0
0,-2,19:17.0
1,-2,19:17.0
2,-2,19:17.0
3,-2,19:17.0
4,-2,19:17.0
-6,-1,19:99.1
-5,-1,19:17.0
-4,-1,19:17.0
-3,-1,19:17.0
-2,-1,19:17.0
-1,-1,19:17.0
0,-1,19:17.0
2,-1,19:17.0
3,-1,19:17.0
4,-1,19:99.9
-6,0,19:99.7
-5,0,19:99.9
-2,0,19:17.0
3,0,19:99.7
4,0,19:99.9
-3,-7,20:17.0
-2,-7,20:17.0
-4,-6,20:17.0
-3,-6,20:17.0
-2,-6,20:17.0
0,-6,20:17.0
1,-6,20:17.0
-4,-5,20:17.0
1,-5,20:17.0
2,-5,20:17.0
3,-5,20:17.0
4,-5,20:17.0
-6,-4,20:99.10
-4,-4,20:17.0
4,-4,20:17.0
5,-4,20:17.0
-4,-3,20:17.0
4,-3,20:17.0
5,-3,20:17.0
-4,-2,20:17.0
-1,-2,20:17.0
0,-2,20:17.0
1,-2,20:17.0
2,-2,20:17.0
3,-2,20:17.0
4,-2,20:17.0
-4,-1,20:17.0
-3,-1,20:17.0
-2,-1,20:17.0
-1,-1,20:17.0
0,-1,20:17.0
3,-1,20:17.0
0,-7,21:99.1
1,-7,21:99.3
-3,-6,21:17.0
-2,-6,21:17.0
-1,-6,21:17.0
0,-6,21:17.0
1,-6,21:99.3
3,-6,21:99.1
4,-6,21:99.1
5,-6,21:99.3
6,-6,21:99.3
-4,-5,21:17.0
-3,-5,21:17.0
1,-5,21:17.0
2,-5,21:17.0
3,-5,21:17.0
4,-5,21:17.0
5,-5,21:99.3
6,-5,21:99.3
-6,-4,21:99.10
-4,-4,21:17.0
-3,-4,21:17.0
4,-4,21:17.0
5,-4,21:17.0
6,-4,21:99.9
-4,-3,21:17.0
4,-3,21:17.0
5,-3,21:17.0
-5,-2,21:99.1
-4,-2,21:17.0
-3,-2,21:17.0
-1,-2,21:17.0
0,-2,21:17.0
2,-2,21:17.0
3,-2,21:17.0
4,-2,21:17.0
5,-2,21:17.0
6,-2,21:99.3
-5,-1,21:99.7
-4,-1,21:99.9
-2,-1,21:17.0
-1,-1,21:17.0
0,-1,21:99.9
5,-1,21:99.7
6,-1,21:99.9
-1,0,21:99.7
0,0,21:99.9
-4,-6,22:99.1
-3,-6,22:99.1
-2,-6,22:17.0
0,-6,22:17.0
-4,-5,22:99.7
-3,-5,22:17.0
-1,-5,22:17.0
1,-5,22:17.0
4,-5,22:17.0
5,-5,22:17.0
-6,-4,22:99.10
-3,-4,22:17.0
5,-4,22:17.0
6,-4,22:17.0
-3,-3,22:17.0
5,-3,22:17.0
6,-3,22:17.0
-3,-2,22:17.0
-2,-2,22:17.0
-1,-2,22:17.0
0,-2,22:17.0
4,-2,22:17.0
5,-2,22:17.0
6,-2,22:17.0
-2,-5,23:17.0
-1,-5,23:17.0
4,-5,23:17.0
5,-5,23:17.0
6,-5,23:17.0
-6,-4,23:99.10
-2,-4,23:17.0
6,-4,23:17.0
-2,-3,23:17.0
6,-3,23:17.0
-2,-2,23:17.0
-1,-2,23:17.0
0,-2,23:17.0
1,-2,23:99.3
5,-2,23:17.0
6,-2,23:17.0
7,-2,23:17.0
8,-2,23:99.3
0,-1,23:99.7
1,-1,23:99.9
6,-1,23:99.7
7,-1,23:99.7
8,-1,23:99.9
6,-6,24:99.1
7,-6,24:99.3
-7,-5,24:100.1
-6,-5,24:100.3
-5,-5,24:100.3
-2,-5,24:17.0
-1,-5,24:17.0
4,-5,24:99.10
5,-5,24:17.0
6,-5,24:17.0
7,-5,24:99.3
-7,-4,24:100.7
-6,-4,24:100.9
-5,-4,24:100.3
-2,-4,24:17.0
-1,-4,24:17.0
6,-4,24:17.0
7,-4,24:17.0
-7,-3,24:100.7
-6,-3,24:100.9
-5,-3,24:100.9
-2,-3,24:17.0
-1,-3,24:17.0
6,-3,24:17.0
-1,-2,24:17.0
0,-2,24:17.0
7,-2,24:17.0
4,-5,25:99.10
6,-5,25:17.0
7,-5,25:17.0
-1,-4,25:17.0
7,-4,25:17.0
-1,-3,25:17.0
6,-3,25:17.0
7,-3,25:17.0
0,-2,25:17.0
1,-2,25:99.3
7,-2,25:17.0
0,-1,25:99.7
1,-1,25:99.9
6,-6,26:17.0
7,-6,26:17.0
4,-5,26:99.10
7,-5,26:17.0
-1,-4,26:17.0
7,-4,26:17.0
-1,-3,26:17.0
6,-3,26:99.10
7,-3,26:17.0
0,-2,26:17.0
7,-6,27:17.0
4,-5,27:99.10
7,-5,27:17.0
7,-4,27:17.0
8,-4,27:99.3
6,-3,27:99.10
7,-3,27:99.7
8,-3,27:99.9
7,-6,28:17.0
4,-5,28:99.10
7,-5,28:17.0
6,-3,28:99.10
3,-6,29:100.1
4,-6,29:100.1
5,-6,29:100.3
7,-6,29:17.0
3,-5,29:100.7
4,-5,29:100.9
5,-5,29:100.9
3,-4,29:100.7
4,-4,29:100.7
5,-4,29:100.9
6,-3,29:99.10
6,-3,30:99.10
6,-3,31:99.10
5,-4,32:99.1
6,-4,32:99.3
7,-4,32:99.3
5,-3,32:99.7
6,-3,32:99.9
7,-3,32:99.9
5,-2,32:99.7
6,-2,32:99.9
7,-2,32:99.9
-5,-2,20:39.5
-5,-6,20:39.5
-6,-2,18:39.5
1,-7,15:39.5
2,-3,14:39.5
4,-5,14:39.5
2,-6,14:40.5
4,-4,11:39.0
3,-7,11:40.5
5,-4,10:39.5
4,-1,9:39.5
7,-1,6:39.5
7,-3,6:39.5
5,-5,6:40.5
5,-6,5:39.5
8,-1,4:39.5
0,-2,4:39.5
-1,-2,4:39.0
-2,-2,3:39.5
8,0,2:39.5
-5,-5,2:39.5
-2,-6,2:39.5
-5,-3,1:39.0
-5,-4,1:39.5
7,-7,1:39.5
6,-9,1:39.5
9,0,0:39.0
8,0,0:40.5
9,-1,0:39.5
1,-1,0:39.5
0,-1,0:39.0
-3,-1,0:39.5
10,-2,0:40.5
8,-2,0:40.5
0,-2,0:39.0
-4,-2,0:39.0
11,-3,0:39.5
4,-4,0:40.5
11,-5,0:40.5
10,-5,0:39.5
4,-5,0:40.0
-6,-5,0:39.5
2,-6,0:40.5
0,-7,0:39.0
-2,-7,0:39.5
-4,-7,0:40.5
7,-8,0:40.5
2,-8,0:40.0
-1,-8,0:39.5
-2,-8,0:40.0
-5,-8,0:40.0
-6,-8,0:39.5
7,-9,0:40.5
0,-9,0:40.5
-2,-9,0:39.0
5,-10,0:39.5
4,-10,0:39.0
2,-10,0:40.0
