[META]
version=2.0
spawnOnBlockType=3,2
spawnSunlight=True
spawnDarkness=True
spawnWater=False
spawnLava=False
underFill=False
randomRotation=True
dig=True
tree=False
branch=False
needsFoundation=True
rarity=25
collisionPercentage=20
spawnElevationMin=0
spawnElevationMax=240
spawnInBiome=All
[DATA]
-1,-2,-2:88.5
-1,-1,-2:88.5
0,-1,-2:88.5
-2,0,-2:88.5
-1,0,-2:88.5
0,0,-2:88.5
-3,1,-2:88.5
-2,1,-2:88.5
-1,1,-2:88.5
0,1,-2:88.5
-3,2,-2:88.5
-2,2,-2:88.5
-1,2,-2:88.5
-3,3,-2:88.5
-2,3,-2:88.5
-2,4,-2:88.5
-1,-3,-1:3.0
-1,-2,-1:3.0
-1,-1,-1:3.0
0,-1,-1:3.0
-3,0,-1:88.5
-2,0,-1:3.0
-1,0,-1:3.0
0,0,-1:3.0
1,0,-1:3.0
-4,1,-1:3.0
-3,1,-1:88.5
-2,1,-1:3.0
-1,1,-1:3.0
0,1,-1:3.0
1,1,-1:3.0
-4,2,-1:110.5
-3,2,-1:88.5
-2,2,-1:3.0
-1,2,-1:3.0
0,2,-1:3.0
1,2,-1:110.5
-4,3,-1:110.5
-3,3,-1:110.5
-2,3,-1:88.5
-1,3,-1:88.5
0,3,-1:88.5
-3,4,-1:110.5
-2,4,-1:88.5
-1,4,-1:88.5
0,4,-1:110.5
-3,5,-1:110.5
-2,5,-1:88.5
-1,5,-1:110.5
-1,-3,0:17.0
-1,-2,0:17.0
-1,-1,0:17.0
0,-1,0:17.0
-2,0,0:17.0
-1,0,0:17.0
0,0,0:17.0
1,0,0:17.0
-4,1,0:17.0
-3,1,0:17.0
-2,1,0:17.0
-1,1,0:17.0
0,1,0:17.0
1,1,0:17.0
-3,2,0:17.0
-2,2,0:17.0
-1,2,0:17.0
0,2,0:17.0
-2,3,0:17.0
-1,3,0:17.0
0,3,0:17.0
-2,4,0:17.0
-1,4,0:17.0
-2,5,0:17.0
-1,-2,1:17.0
0,-2,1:99.3
1,-2,1:99.3
-1,-1,1:17.0
0,-1,1:17.0
1,-1,1:99.9
-2,0,1:17.0
-1,0,1:17.0
0,0,1:17.0
1,0,1:17.0
-2,1,1:17.0
-1,1,1:17.0
0,1,1:17.0
1,1,1:17.0
-3,2,1:17.0
-2,2,1:17.0
-1,2,1:17.0
0,2,1:17.0
-2,3,1:17.0
-1,3,1:17.0
0,3,1:17.0
-2,4,1:17.0
-1,4,1:17.0
-3,5,1:99.7
-2,5,1:17.0
-1,-1,2:17.0
0,-1,2:17.0
-2,0,2:17.0
-1,0,2:17.0
0,0,2:17.0
1,0,2:17.0
-2,1,2:17.0
-1,1,2:17.0
0,1,2:17.0
1,1,2:17.0
2,1,2:99.3
-2,2,2:17.0
-1,2,2:17.0
0,2,2:17.0
1,2,2:99.9
2,2,2:99.9
-2,3,2:17.0
-1,3,2:17.0
0,3,2:17.0
-1,4,2:17.0
-3,-2,3:99.1
-2,-2,3:99.3
-3,-1,3:99.4
-2,-1,3:99.5
-1,-1,3:17.0
0,-1,3:17.0
-3,0,3:99.7
-2,0,3:17.0
-1,0,3:17.0
0,0,3:17.0
-2,1,3:17.0
-1,1,3:17.0
0,1,3:17.0
1,1,3:17.0
-2,2,3:17.0
-1,2,3:17.0
0,2,3:17.0
-2,3,3:17.0
-1,3,3:17.0
0,3,3:17.0
-1,4,3:17.0
0,4,3:99.6
-1,5,3:99.7
0,5,3:99.9
-1,-1,4:17.0
0,-1,4:17.0
-2,0,4:17.0
-1,0,4:17.0
0,0,4:17.0
-2,1,4:17.0
-1,1,4:17.0
0,1,4:17.0
1,1,4:17.0
-2,2,4:17.0
-1,2,4:17.0
0,2,4:17.0
-1,3,4:17.0
0,3,4:17.0
0,-2,5:99.1
1,-2,5:99.3
-1,-1,5:17.0
0,-1,5:17.0
1,-1,5:99.9
-2,0,5:17.0
-1,0,5:17.0
0,0,5:17.0
-2,1,5:17.0
-1,1,5:17.0
-2,2,5:17.0
-1,2,5:2.5
0,2,5:17.0
-1,3,5:17.0
-1,4,5:17.0
-1,-1,6:17.0
0,-1,6:17.0
-2,0,6:17.0
-2,1,6:17.0
-2,2,6:17.0
0,2,6:17.0
-1,3,6:17.0
-2,0,7:17.0
-2,1,7:17.0
-3,2,7:99.1
-2,2,7:17.0
-3,3,7:99.7
-1,-1,8:17.0
-2,0,8:17.0
-2,1,8:17.0
-2,2,8:17.0
-1,-2,9:99.1
0,-2,9:99.3
-1,-1,9:17.0
0,-1,9:99.9
-2,0,9:17.0
-1,0,9:99.8
0,0,9:99.9
-2,1,9:17.0
-2,2,9:17.0
-1,3,9:17.0
-3,-1,10:99.1
-2,-1,10:99.3
-1,-1,10:17.0
-3,0,10:99.7
-2,0,10:17.0
-2,1,10:17.0
-1,1,10:17.0
-2,0,11:17.0
-2,1,11:17.0
-2,2,11:17.0
-1,2,11:17.0
-2,-2,12:99.1
-1,-2,12:99.3
-2,-1,12:99.4
-1,-1,12:17.0
-2,0,12:17.0
-2,1,12:17.0
-2,2,12:17.0
-1,-1,13:17.0
-2,0,13:17.0
-2,1,13:17.0
-2,0,14:17.0
-2,0,15:39.5
-2,1,14:39.5
-1,-1,14:40.5
-1,4,6:39.5
-1,2,6:31.2
1,1,5:39.5
1,0,3:40.5
-1,-2,2:39.5
-3,1,1:40.5
