[META]
version=2.0
spawnOnBlockType=3,2
spawnSunlight=True
spawnDarkness=True
spawnWater=False
spawnLava=False
underFill=False
randomRotation=False
dig=True
tree=True
branch=False
needsFoundation=True
rarity=100
collisionPercentage=20
spawnElevationMin=0
spawnElevationMax=240
spawnInBiome=All
[DATA]
0,0,-3:88.0
0,-1,-2:88.0
-1,0,-2:88.0
0,0,-2:88.0
1,0,-2:88.0
0,1,-2:88.0
0,-2,-1:110.0
-1,-1,-1:110.0
0,-1,-1:110.0
1,-1,-1:110.0
-2,0,-1:110.0
-1,0,-1:110.0
0,0,-1:3.0
1,0,-1:110.0
2,0,-1:110.0
-1,1,-1:110.0
0,1,-1:110.0
1,1,-1:110.0
0,2,-1:110.0
0,0,0:99.10
0,0,1:99.10
0,0,2:99.10
-1,-5,3:99.1
0,-5,3:99.2
1,-5,3:99.3
-2,-4,3:99.1
2,-4,3:99.3
-3,-3,3:99.1
3,-3,3:99.3
-4,-2,3:99.1
4,-2,3:99.3
-5,-1,3:99.1
5,-1,3:99.3
-5,0,3:99.4
0,0,3:99.10
5,0,3:99.6
-5,1,3:99.7
5,1,3:99.9
-4,2,3:99.7
4,2,3:99.9
-3,3,3:99.7
3,3,3:99.9
-2,4,3:99.7
2,4,3:99.9
-1,5,3:99.7
0,5,3:99.7
1,5,3:99.9
-1,-4,4:99.1
0,-4,4:99.2
1,-4,4:99.3
-2,-3,4:99.1
2,-3,4:99.3
-3,-2,4:99.1
3,-2,4:99.3
-4,-1,4:99.1
4,-1,4:99.3
-4,0,4:99.4
0,0,4:99.10
4,0,4:99.6
-4,1,4:99.7
4,1,4:99.9
-3,2,4:99.7
3,2,4:99.9
-2,3,4:99.7
2,3,4:99.9
-1,4,4:99.7
0,4,4:99.7
1,4,4:99.9
-1,-3,5:99.1
0,-3,5:99.2
1,-3,5:99.3
-2,-2,5:99.1
-1,-2,5:99.1
0,-2,5:99.2
1,-2,5:99.3
2,-2,5:99.3
-3,-1,5:99.1
-2,-1,5:99.1
-1,-1,5:99.1
0,-1,5:99.2
1,-1,5:99.3
2,-1,5:99.3
3,-1,5:99.3
-3,0,5:99.4
-2,0,5:99.4
-1,0,5:99.4
0,0,5:99.4
1,0,5:99.6
2,0,5:99.6
3,0,5:99.6
-3,1,5:99.7
-2,1,5:99.7
-1,1,5:99.7
0,1,5:99.9
1,1,5:99.9
2,1,5:99.9
3,1,5:99.9
-2,2,5:99.7
-1,2,5:99.7
0,2,5:99.9
1,2,5:99.9
2,2,5:99.9
-1,3,5:99.7
0,3,5:99.9
1,3,5:99.9
0,2,0:39.5
2,0,0:39.5
-1,0,0:39.5
0,-1,0:39.5
