[META]
version=2.0
spawnOnBlockType=3,2
spawnSunlight=True
spawnDarkness=True
spawnWater=False
spawnLava=False
underFill=False
randomRotation=False
dig=True
tree=False
branch=False
needsFoundation=True
rarity=10
collisionPercentage=10
spawnElevationMin=0
spawnElevationMax=240
spawnInBiome=All
[DATA]
-1,-1,-5:3.0
0,-1,-5:3.0
-1,0,-5:3.0
0,0,-5:3.0
-1,-2,-4:3.0
0,-2,-4:3.0
-2,-1,-4:3.0
-1,-1,-4:100.10
0,-1,-4:100.10
1,-1,-4:3.0
2,-1,-4:3.5
-3,0,-4:3.5
-2,0,-4:3.0
-1,0,-4:100.10
0,0,-4:100.10
1,0,-4:3.0
-1,1,-4:3.0
0,1,-4:3.0
1,1,-4:3.5
-1,2,-4:3.5
-1,-4,-3:3.5
-1,-3,-3:3.0
0,-3,-3:3.0
1,-3,-3:3.0
2,-3,-3:3.5
-2,-2,-3:3.0
-1,-2,-3:100.10
0,-2,-3:100.10
1,-2,-3:3.0
2,-2,-3:3.0
-3,-1,-3:3.0
-2,-1,-3:100.10
-1,-1,-3:100.10
0,-1,-3:100.10
1,-1,-3:100.10
2,-1,-3:3.0
-3,0,-3:3.0
-2,0,-3:100.10
-1,0,-3:100.10
0,0,-3:100.10
1,0,-3:100.10
2,0,-3:3.0
-3,1,-3:3.5
-2,1,-3:3.0
-1,1,-3:100.10
0,1,-3:100.10
1,1,-3:3.0
2,1,-3:3.5
-1,2,-3:3.5
0,2,-3:3.0
1,2,-3:3.5
0,3,-3:3.5
0,-5,-2:3.5
-2,-4,-2:3.0
-1,-4,-2:3.0
0,-4,-2:3.0
1,-4,-2:3.0
-3,-3,-2:3.0
-2,-3,-2:100.10
-1,-3,-2:100.10
0,-3,-2:100.10
1,-3,-2:100.10
2,-3,-2:3.0
-3,-2,-2:100.10
-2,-2,-2:100.10
-1,-2,-2:100.10
0,-2,-2:100.10
1,-2,-2:100.10
2,-2,-2:100.10
3,-2,-2:3.0
-4,-1,-2:3.5
-3,-1,-2:100.10
-2,-1,-2:100.10
-1,-1,-2:100.10
0,-1,-2:100.10
1,-1,-2:100.10
2,-1,-2:100.10
3,-1,-2:3.0
-4,0,-2:3.0
-3,0,-2:100.10
-2,0,-2:100.10
-1,0,-2:100.10
0,0,-2:100.10
1,0,-2:100.10
2,0,-2:100.10
3,0,-2:3.0
-3,1,-2:3.0
-2,1,-2:100.10
-1,1,-2:100.10
0,1,-2:100.10
1,1,-2:100.10
2,1,-2:3.0
-3,2,-2:3.5
-2,2,-2:3.0
-1,2,-2:100.10
0,2,-2:100.10
1,2,-2:3.0
0,3,-2:3.0
1,3,-2:3.5
-1,4,-2:3.5
-3,-5,-1:110.0
-2,-5,-1:110.0
-1,-5,-1:110.0
0,-5,-1:110.0
1,-5,-1:110.0
2,-5,-1:110.0
-4,-4,-1:110.0
-3,-4,-1:3.0
-2,-4,-1:100.10
-1,-4,-1:100.10
0,-4,-1:100.10
1,-4,-1:100.10
2,-4,-1:3.0
3,-4,-1:110.0
-4,-3,-1:110.0
-3,-3,-1:100.10
-2,-3,-1:100.10
-1,-3,-1:100.10
0,-3,-1:100.10
1,-3,-1:100.10
2,-3,-1:100.10
3,-3,-1:110.0
-5,-2,-1:110.0
-4,-2,-1:100.10
-3,-2,-1:100.10
-2,-2,-1:100.10
-1,-2,-1:100.10
0,-2,-1:100.10
1,-2,-1:100.10
2,-2,-1:100.10
3,-2,-1:100.10
4,-2,-1:110.0
-5,-1,-1:110.0
-4,-1,-1:100.10
-3,-1,-1:100.10
-2,-1,-1:100.10
-1,-1,-1:100.10
0,-1,-1:100.10
1,-1,-1:100.10
2,-1,-1:100.10
3,-1,-1:100.10
4,-1,-1:110.0
-5,0,-1:110.0
-4,0,-1:100.10
-3,0,-1:100.10
-2,0,-1:100.10
-1,0,-1:100.10
0,0,-1:100.10
1,0,-1:100.10
2,0,-1:100.10
3,0,-1:100.10
4,0,-1:110.0
-4,1,-1:110.0
-3,1,-1:100.10
-2,1,-1:100.10
-1,1,-1:100.10
0,1,-1:100.10
1,1,-1:100.10
2,1,-1:100.10
3,1,-1:110.0
-3,2,-1:110.0
-2,2,-1:100.10
-1,2,-1:100.10
0,2,-1:100.10
1,2,-1:100.10
2,2,-1:110.0
-2,3,-1:110.0
-1,3,-1:100.10
0,3,-1:100.10
1,3,-1:110.0
-1,4,-1:110.0
0,4,-1:110.0
-3,-4,0:100.10
-2,-4,0:100.10
1,-4,0:100.10
2,-4,0:100.10
-3,-3,0:100.10
-2,-3,0:54.5
1,-3,0:54.3
2,-3,0:100.10
-4,-2,0:100.10
-3,-2,0:61.5
2,-2,0:61.4
3,-2,0:100.10
-4,-1,0:100.10
-3,-1,0:61.5
2,-1,0:61.4
3,-1,0:100.10
-4,0,0:100.10
-3,0,0:61.5
2,0,0:61.4
3,0,0:100.10
-3,1,0:100.10
-2,1,0:58.0
1,1,0:58.0
2,1,0:100.10
-2,2,0:100.10
-1,2,0:100.10
0,2,0:100.10
1,2,0:100.10
-1,3,0:100.10
0,3,0:100.10
-2,-4,1:100.10
1,-4,1:100.10
-3,-3,1:100.10
2,-3,1:100.10
-3,-2,1:100.10
2,-2,1:100.10
-3,-1,1:100.10
2,-1,1:100.10
-3,0,1:100.10
2,0,1:100.10
-2,1,1:100.10
1,1,1:100.10
-1,2,1:100.10
0,2,1:100.10
-1,-4,2:100.10
0,-4,2:100.10
-2,-3,2:100.10
-1,-3,2:47.0
0,-3,2:47.0
1,-3,2:100.10
-3,-2,2:100.10
-2,-2,2:47.0
1,-2,2:47.0
2,-2,2:100.10
-3,-1,2:100.10
-2,-1,2:47.0
1,-1,2:47.0
2,-1,2:100.10
-3,0,2:100.10
-2,0,2:47.0
1,0,2:47.0
2,0,2:100.10
-2,1,2:100.10
-1,1,2:47.0
0,1,2:47.0
1,1,2:100.10
-1,2,2:100.10
0,2,2:100.10
-2,-9,3:100.1
-1,-9,3:100.2
0,-9,3:100.2
1,-9,3:100.3
-4,-8,3:100.1
-3,-8,3:100.1
2,-8,3:100.3
3,-8,3:100.3
-6,-7,3:100.1
-5,-7,3:100.1
4,-7,3:100.3
5,-7,3:100.3
-7,-6,3:100.1
6,-6,3:100.3
-7,-5,3:100.1
6,-5,3:100.3
-8,-4,3:100.1
7,-4,3:100.3
-8,-3,3:100.1
-1,-3,3:100.10
0,-3,3:100.10
7,-3,3:100.3
-9,-2,3:100.1
-2,-2,3:100.10
-1,-2,3:47.0
0,-2,3:47.0
1,-2,3:100.10
8,-2,3:100.3
-9,-1,3:100.4
-2,-1,3:100.10
1,-1,3:100.10
8,-1,3:100.6
-9,0,3:100.4
-2,0,3:100.10
1,0,3:100.10
8,0,3:100.6
-9,1,3:100.7
-1,1,3:100.10
0,1,3:100.10
8,1,3:100.9
-8,2,3:100.7
7,2,3:100.9
-8,3,3:100.7
7,3,3:100.9
-7,4,3:100.7
6,4,3:100.9
-7,5,3:100.7
6,5,3:100.9
-6,6,3:100.7
-5,6,3:100.7
4,6,3:100.9
5,6,3:100.9
-4,7,3:100.7
-3,7,3:100.7
2,7,3:100.9
3,7,3:100.9
-2,8,3:100.7
-1,8,3:100.8
0,8,3:100.8
1,8,3:100.9
-2,-9,4:100.1
-1,-9,4:100.2
0,-9,4:100.2
1,-9,4:100.3
-4,-8,4:100.1
-3,-8,4:100.1
2,-8,4:100.3
3,-8,4:100.3
-6,-7,4:100.1
-5,-7,4:100.1
4,-7,4:100.3
5,-7,4:100.3
-7,-6,4:100.1
6,-6,4:100.3
-7,-5,4:100.1
6,-5,4:100.3
-8,-4,4:100.1
7,-4,4:100.3
-8,-3,4:100.1
7,-3,4:100.3
-9,-2,4:100.1
-1,-2,4:100.10
0,-2,4:100.10
8,-2,4:100.3
-9,-1,4:100.4
-2,-1,4:100.10
1,-1,4:100.10
8,-1,4:100.6
-9,0,4:100.4
-2,0,4:100.10
0,0,4:30.0
1,0,4:100.10
8,0,4:100.6
-9,1,4:100.7
-1,1,4:100.10
0,1,4:100.10
8,1,4:100.9
-8,2,4:100.7
7,2,4:100.9
-8,3,4:100.7
7,3,4:100.9
-7,4,4:100.7
6,4,4:100.9
-7,5,4:100.7
6,5,4:100.9
-6,6,4:100.7
-5,6,4:100.7
4,6,4:100.9
5,6,4:100.9
-4,7,4:100.7
-3,7,4:100.7
2,7,4:100.9
3,7,4:100.9
-2,8,4:100.7
-1,8,4:100.8
0,8,4:100.8
1,8,4:100.9
-2,-9,5:100.1
-1,-9,5:100.2
0,-9,5:100.2
1,-9,5:100.3
-4,-8,5:100.1
-3,-8,5:100.1
2,-8,5:100.3
3,-8,5:100.3
-6,-7,5:100.1
-5,-7,5:100.1
4,-7,5:100.3
5,-7,5:100.3
-7,-6,5:100.1
6,-6,5:100.3
-7,-5,5:100.1
6,-5,5:100.3
-8,-4,5:100.1
7,-4,5:100.3
-8,-3,5:100.1
7,-3,5:100.3
-9,-2,5:100.1
-1,-2,5:100.10
0,-2,5:100.10
8,-2,5:100.3
-9,-1,5:100.4
-2,-1,5:100.10
-1,-1,5:30.0
0,-1,5:30.0
1,-1,5:100.10
8,-1,5:100.6
-9,0,5:100.4
-2,0,5:100.10
-1,0,5:30.0
0,0,5:30.0
1,0,5:100.10
8,0,5:100.6
-9,1,5:100.7
-1,1,5:100.10
0,1,5:100.10
8,1,5:100.9
-8,2,5:100.7
7,2,5:100.9
-8,3,5:100.7
7,3,5:100.9
-7,4,5:100.7
6,4,5:100.9
-7,5,5:100.7
6,5,5:100.9
-6,6,5:100.7
-5,6,5:100.7
4,6,5:100.9
5,6,5:100.9
-4,7,5:100.7
-3,7,5:100.7
2,7,5:100.9
3,7,5:100.9
-2,8,5:100.7
-1,8,5:100.8
0,8,5:100.8
1,8,5:100.9
-2,-8,6:100.1
-1,-8,6:100.2
0,-8,6:100.2
1,-8,6:100.3
-4,-7,6:100.1
-3,-7,6:100.1
2,-7,6:100.3
3,-7,6:100.3
-6,-6,6:100.1
-5,-6,6:100.1
4,-6,6:100.3
5,-6,6:100.3
-6,-5,6:100.1
5,-5,6:100.3
-7,-4,6:100.1
6,-4,6:100.3
-7,-3,6:100.1
6,-3,6:100.3
-8,-2,6:100.1
7,-2,6:100.3
-8,-1,6:100.4
-1,-1,6:100.10
0,-1,6:100.10
7,-1,6:100.6
-8,0,6:100.4
-1,0,6:100.10
0,0,6:100.10
7,0,6:100.6
-8,1,6:100.7
7,1,6:100.9
-7,2,6:100.7
6,2,6:100.9
-7,3,6:100.7
6,3,6:100.9
-6,4,6:100.7
5,4,6:100.9
-6,5,6:100.7
-5,5,6:100.7
4,5,6:100.9
5,5,6:100.9
-4,6,6:100.7
-3,6,6:100.7
2,6,6:100.9
3,6,6:100.9
-2,7,6:100.7
-1,7,6:100.8
0,7,6:100.8
1,7,6:100.9
-2,-8,7:100.1
-1,-8,7:100.2
0,-8,7:100.2
1,-8,7:100.3
-4,-7,7:100.1
-3,-7,7:100.1
2,-7,7:100.3
3,-7,7:100.3
-6,-6,7:100.1
-5,-6,7:100.1
4,-6,7:100.3
5,-6,7:100.3
-6,-5,7:100.1
5,-5,7:100.3
-7,-4,7:100.1
6,-4,7:100.3
-7,-3,7:100.1
6,-3,7:100.3
-8,-2,7:100.1
7,-2,7:100.3
-8,-1,7:100.4
-1,-1,7:100.10
0,-1,7:100.10
7,-1,7:100.6
-8,0,7:100.4
-1,0,7:100.10
0,0,7:100.10
7,0,7:100.6
-8,1,7:100.7
7,1,7:100.9
-7,2,7:100.7
6,2,7:100.9
-7,3,7:100.7
6,3,7:100.9
-6,4,7:100.7
5,4,7:100.9
-6,5,7:100.7
-5,5,7:100.7
4,5,7:100.9
5,5,7:100.9
-4,6,7:100.7
-3,6,7:100.7
2,6,7:100.9
3,6,7:100.9
-2,7,7:100.7
-1,7,7:100.8
0,7,7:100.8
1,7,7:100.9
-2,-7,8:100.1
-1,-7,8:100.2
0,-7,8:100.2
1,-7,8:100.3
-4,-6,8:100.1
-3,-6,8:100.1
2,-6,8:100.3
3,-6,8:100.3
-5,-5,8:100.1
4,-5,8:100.3
-6,-4,8:100.1
5,-4,8:100.3
-6,-3,8:100.1
5,-3,8:100.3
-7,-2,8:100.1
-1,-2,8:89.0
0,-2,8:89.0
6,-2,8:100.3
-7,-1,8:100.4
-2,-1,8:89.0
-1,-1,8:100.10
0,-1,8:100.10
1,-1,8:89.0
6,-1,8:100.6
-7,0,8:100.4
-2,0,8:89.0
-1,0,8:100.10
0,0,8:100.10
1,0,8:89.0
6,0,8:100.6
-7,1,8:100.7
-1,1,8:89.0
0,1,8:89.0
6,1,8:100.9
-6,2,8:100.7
5,2,8:100.9
-6,3,8:100.7
5,3,8:100.9
-5,4,8:100.7
4,4,8:100.9
-4,5,8:100.7
-3,5,8:100.7
2,5,8:100.9
3,5,8:100.9
-2,6,8:100.7
-1,6,8:100.8
0,6,8:100.8
1,6,8:100.9
-2,-6,9:100.1
-1,-6,9:100.2
0,-6,9:100.2
1,-6,9:100.3
-4,-5,9:100.1
-3,-5,9:100.1
-2,-5,9:100.1
-1,-5,9:100.5
0,-5,9:100.5
1,-5,9:100.3
2,-5,9:100.3
3,-5,9:100.3
-5,-4,9:100.1
-4,-4,9:100.1
-3,-4,9:100.1
2,-4,9:100.3
3,-4,9:100.3
4,-4,9:100.3
-5,-3,9:100.1
-4,-3,9:100.1
-1,-3,9:89.0
0,-3,9:89.0
3,-3,9:100.3
4,-3,9:100.3
-6,-2,9:100.1
-5,-2,9:100.1
-2,-2,9:89.0
-1,-2,9:89.0
0,-2,9:89.0
1,-2,9:89.0
4,-2,9:100.3
5,-2,9:100.3
-6,-1,9:100.4
-5,-1,9:100.5
-3,-1,9:89.0
-2,-1,9:89.0
-1,-1,9:100.10
0,-1,9:100.10
1,-1,9:89.0
2,-1,9:89.0
4,-1,9:100.5
5,-1,9:100.6
-6,0,9:100.4
-5,0,9:100.5
-3,0,9:89.0
-2,0,9:89.0
-1,0,9:100.10
0,0,9:100.10
1,0,9:89.0
2,0,9:89.0
4,0,9:100.5
5,0,9:100.6
-6,1,9:100.7
-5,1,9:100.7
-2,1,9:89.0
-1,1,9:89.0
0,1,9:89.0
1,1,9:89.0
4,1,9:100.9
5,1,9:100.9
-5,2,9:100.7
-4,2,9:100.7
-1,2,9:89.0
0,2,9:89.0
3,2,9:100.9
4,2,9:100.9
-5,3,9:100.7
-4,3,9:100.7
-3,3,9:100.7
2,3,9:100.9
3,3,9:100.9
4,3,9:100.9
-4,4,9:100.7
-3,4,9:100.7
-2,4,9:100.7
-1,4,9:100.5
0,4,9:100.5
1,4,9:100.9
2,4,9:100.9
3,4,9:100.9
-2,5,9:100.7
-1,5,9:100.8
0,5,9:100.8
1,5,9:100.9
-2,-4,10:100.1
-1,-4,10:100.2
0,-4,10:100.2
1,-4,10:100.3
-3,-3,10:100.1
-2,-3,10:100.5
-1,-3,10:100.5
0,-3,10:100.5
1,-3,10:100.5
2,-3,10:100.3
-4,-2,10:100.1
-3,-2,10:100.5
-2,-2,10:100.5
-1,-2,10:100.5
0,-2,10:100.5
1,-2,10:100.5
2,-2,10:100.5
3,-2,10:100.3
-4,-1,10:100.4
-3,-1,10:100.5
-2,-1,10:100.5
-1,-1,10:100.5
0,-1,10:100.5
1,-1,10:100.5
2,-1,10:100.5
3,-1,10:100.6
-4,0,10:100.4
-3,0,10:100.5
-2,0,10:100.5
-1,0,10:100.5
0,0,10:100.5
1,0,10:100.5
2,0,10:100.5
3,0,10:100.6
-4,1,10:100.7
-3,1,10:100.5
-2,1,10:100.5
-1,1,10:100.5
0,1,10:100.5
1,1,10:100.5
2,1,10:100.5
3,1,10:100.9
-3,2,10:100.7
-2,2,10:100.5
-1,2,10:100.5
0,2,10:100.5
1,2,10:100.5
2,2,10:100.9
-2,3,10:100.7
-1,3,10:100.8
0,3,10:100.8
1,3,10:100.9
1,-2,4:40.0
-2,-2,4:40.0
0,-3,4:40.0
-1,-3,4:40.0
0,2,3:40.0
-1,2,3:40.0
-2,1,3:40.0
2,0,3:40.0
-3,0,3:40.0
2,-1,3:40.0
-3,-1,3:40.0
2,-2,3:40.0
-3,-2,3:40.0
1,-3,3:40.0
-2,-3,3:40.0
0,-4,3:40.0
-1,-4,3:40.0
2,-3,2:40.0
-3,-3,2:40.0
1,-4,2:40.0
-2,-4,2:40.0
0,3,1:40.0
-1,3,1:40.0
1,2,1:40.0
-2,2,1:40.0
2,1,1:40.0
-3,1,1:40.0
3,0,1:40.0
-4,0,1:40.0
3,-1,1:40.0
-4,-1,1:40.0
3,-2,1:40.0
-4,-2,1:40.0
2,-4,1:40.0
0,-4,1:64.9
-1,-4,1:64.12
-3,-4,1:40.0
0,4,0:40.0
-1,4,0:40.0
1,3,0:40.0
-2,3,0:40.0
2,2,0:40.0
-3,2,0:40.0
3,1,0:40.0
0,1,0:26.8
-1,1,0:26.8
-4,1,0:40.0
4,0,0:40.0
0,0,0:26.0
-1,0,0:26.0
-5,0,0:40.0
4,-1,0:40.0
-5,-1,0:40.0
4,-2,0:40.0
-5,-2,0:40.0
3,-3,0:40.0
-4,-3,0:40.0
3,-4,0:40.0
0,-4,0:64.1
-1,-4,0:64.4
-4,-4,0:40.0
2,-5,0:40.0
1,-5,0:40.0
0,-5,0:40.0
-1,-5,0:40.0
-2,-5,0:40.0
-3,-5,0:40.0
