[META]
version=2.0
spawnOnBlockType=3,2
spawnSunlight=True
spawnDarkness=True
spawnWater=False
spawnLava=False
underFill=False
randomRotation=False
dig=True
tree=True
branch=False
needsFoundation=True
rarity=100
collisionPercentage=20
spawnElevationMin=0
spawnElevationMax=240
spawnInBiome=All
[DATA]
0,0,-3:88.5
0,-1,-2:88.5
-1,0,-2:88.5
0,0,-2:88.5
1,0,-2:88.5
0,1,-2:88.5
-1,-1,-1:110.5
0,-1,-1:110.5
-1,0,-1:110.5
0,0,-1:3.0
1,0,-1:110.5
0,1,-1:110.5
0,0,0:99.10
0,0,1:99.10
0,0,2:99.10
0,0,3:99.10
0,0,4:99.10
0,0,5:99.10
0,0,6:99.10
-1,-3,7:99.10
0,-3,7:99.10
1,-3,7:99.10
-2,-2,7:99.10
2,-2,7:99.10
-3,-1,7:99.10
3,-1,7:99.10
-3,0,7:99.10
0,0,7:99.10
3,0,7:99.10
-3,1,7:99.10
3,1,7:99.10
-2,2,7:99.10
2,2,7:99.10
-1,3,7:99.10
0,3,7:99.10
1,3,7:99.10
-1,-3,8:99.10
0,-3,8:99.10
1,-3,8:99.10
-2,-2,8:99.10
-1,-2,8:99.10
0,-2,8:99.10
1,-2,8:99.10
2,-2,8:99.10
-3,-1,8:99.10
-2,-1,8:99.10
-1,-1,8:99.10
0,-1,8:99.10
1,-1,8:99.10
2,-1,8:99.10
3,-1,8:99.10
-3,0,8:99.10
-2,0,8:99.10
-1,0,8:99.10
0,0,8:99.10
1,0,8:99.10
2,0,8:99.10
3,0,8:99.10
-3,1,8:99.10
-2,1,8:99.10
-1,1,8:99.10
0,1,8:99.10
1,1,8:99.10
2,1,8:99.10
3,1,8:99.10
-2,2,8:99.10
-1,2,8:99.10
0,2,8:99.10
1,2,8:99.10
2,2,8:99.10
-1,3,8:99.10
0,3,8:99.10
1,3,8:99.10
-1,-1,9:99.10
0,-1,9:99.10
1,-1,9:99.10
-1,0,9:99.10
0,0,9:99.10
1,0,9:99.10
-1,1,9:99.10
0,1,9:99.10
1,1,9:99.10
0,1,0:40.5
1,0,0:40.0
-1,0,0:40.0
0,-1,0:40.0
