[META]
version=2.0
spawnOnBlockType=3,2
spawnSunlight=True
spawnDarkness=True
spawnWater=False
spawnLava=False
underFill=False
randomRotation=False
dig=True
tree=False
branch=False
needsFoundation=True
rarity=20
collisionPercentage=20
spawnElevationMin=0
spawnElevationMax=240
spawnInBiome=All
[DATA]
-1,-1,-6:1.5
-2,0,-6:1.5
-1,0,-6:1.5
0,0,-6:1.5
-1,1,-6:1.5
-1,-2,-5:1.5
0,-2,-5:1.5
-2,-1,-5:1.5
-1,-1,-5:1.5
0,-1,-5:1.5
1,-1,-5:1.5
-3,0,-5:1.5
-2,0,-5:1.5
-1,0,-5:1.5
0,0,-5:1.5
1,0,-5:1.5
-2,1,-5:1.5
-1,1,-5:1.5
0,1,-5:1.5
1,1,-5:1.5
-2,-3,-4:3.5
0,-3,-4:3.5
-3,-2,-4:3.5
-2,-2,-4:3.5
-1,-2,-4:3.5
0,-2,-4:3.5
1,-2,-4:3.5
2,-2,-4:1.5
-3,-1,-4:1.5
-2,-1,-4:3.5
-1,-1,-4:3.5
0,-1,-4:99.10
1,-1,-4:3.5
2,-1,-4:3.5
-3,0,-4:1.5
-2,0,-4:3.5
-1,0,-4:3.5
0,0,-4:3.5
1,0,-4:3.5
2,0,-4:1.5
-3,1,-4:3.5
-2,1,-4:3.5
-1,1,-4:3.5
0,1,-4:3.5
1,1,-4:3.5
2,1,-4:3.5
-3,2,-4:3.5
-2,2,-4:3.5
-1,2,-4:3.5
0,2,-4:3.5
1,2,-4:3.5
-3,3,-4:1.5
-2,-4,-3:3.5
-1,-4,-3:3.5
0,-4,-3:3.5
1,-4,-3:3.5
-3,-3,-3:3.5
-2,-3,-3:3.5
-1,-3,-3:3.5
0,-3,-3:3.5
1,-3,-3:3.5
2,-3,-3:3.5
-4,-2,-3:3.5
-3,-2,-3:3.5
-2,-2,-3:3.5
-1,-2,-3:3.5
0,-2,-3:3.5
1,-2,-3:3.5
2,-2,-3:3.5
-4,-1,-3:1.5
-3,-1,-3:3.5
-2,-1,-3:3.5
-1,-1,-3:99.10
0,-1,-3:99.10
1,-1,-3:99.10
2,-1,-3:3.5
3,-1,-3:3.5
-4,0,-3:1.5
-3,0,-3:3.5
-2,0,-3:3.5
-1,0,-3:3.5
0,0,-3:99.10
1,0,-3:3.5
2,0,-3:3.5
-4,1,-3:3.5
-3,1,-3:3.5
-2,1,-3:3.5
-1,1,-3:3.5
0,1,-3:3.5
1,1,-3:3.5
2,1,-3:3.5
3,1,-3:3.5
-3,2,-3:3.5
-2,2,-3:3.5
-1,2,-3:3.5
0,2,-3:3.5
1,2,-3:3.5
2,2,-3:3.5
-2,3,-3:3.5
-1,3,-3:3.5
0,3,-3:3.5
-1,-5,-2:3.0
1,-5,-2:3.0
-3,-4,-2:3.0
-2,-4,-2:3.0
-1,-4,-2:3.0
0,-4,-2:3.0
1,-4,-2:3.0
2,-4,-2:3.0
-4,-3,-2:3.0
-3,-3,-2:3.0
-2,-3,-2:3.0
-1,-3,-2:3.0
0,-3,-2:3.0
1,-3,-2:3.0
2,-3,-2:3.0
3,-3,-2:3.0
-5,-2,-2:3.0
-4,-2,-2:3.0
-3,-2,-2:3.0
-2,-2,-2:3.0
-1,-2,-2:3.0
0,-2,-2:99.10
1,-2,-2:3.0
2,-2,-2:3.0
3,-2,-2:3.0
-4,-1,-2:3.0
-3,-1,-2:3.0
-2,-1,-2:3.0
-1,-1,-2:99.10
0,-1,-2:99.10
1,-1,-2:99.10
2,-1,-2:3.0
3,-1,-2:3.0
4,-1,-2:3.0
-4,0,-2:3.0
-3,0,-2:3.0
-2,0,-2:3.0
-1,0,-2:3.0
0,0,-2:99.10
1,0,-2:99.10
2,0,-2:3.0
3,0,-2:3.0
-5,1,-2:3.0
-4,1,-2:3.0
-3,1,-2:3.0
-2,1,-2:3.0
-1,1,-2:3.0
0,1,-2:99.10
1,1,-2:3.0
2,1,-2:3.0
3,1,-2:3.0
-3,2,-2:3.0
-2,2,-2:3.0
-1,2,-2:3.0
0,2,-2:3.0
1,2,-2:3.0
2,2,-2:3.0
3,2,-2:3.0
-2,3,-2:3.0
-1,3,-2:3.0
0,3,-2:3.0
1,3,-2:3.0
-2,4,-2:3.0
0,4,-2:3.0
-3,-5,-1:110.0
-2,-5,-1:110.0
-1,-5,-1:3.0
0,-5,-1:3.0
1,-5,-1:110.0
2,-5,-1:110.0
-4,-4,-1:110.0
-3,-4,-1:110.0
-2,-4,-1:3.0
-1,-4,-1:3.0
0,-4,-1:3.0
1,-4,-1:3.0
2,-4,-1:3.0
3,-4,-1:110.0
-5,-3,-1:110.0
-4,-3,-1:3.0
-3,-3,-1:3.0
-2,-3,-1:3.0
-1,-3,-1:3.0
0,-3,-1:99.10
1,-3,-1:99.10
2,-3,-1:3.0
3,-3,-1:3.0
4,-3,-1:3.0
-5,-2,-1:3.0
-4,-2,-1:3.0
-3,-2,-1:99.10
-2,-2,-1:99.10
-1,-2,-1:99.10
0,-2,-1:99.10
1,-2,-1:99.10
2,-2,-1:99.10
3,-2,-1:3.0
4,-2,-1:3.0
-5,-1,-1:3.0
-4,-1,-1:3.0
-3,-1,-1:99.10
-2,-1,-1:99.10
-1,-1,-1:99.10
0,-1,-1:99.10
1,-1,-1:99.10
2,-1,-1:99.10
3,-1,-1:3.0
4,-1,-1:3.0
-5,0,-1:110.0
-4,0,-1:3.0
-3,0,-1:3.0
-2,0,-1:99.10
-1,0,-1:99.10
0,0,-1:99.10
1,0,-1:99.10
2,0,-1:99.10
3,0,-1:99.10
4,0,-1:110.0
-5,1,-1:110.0
-4,1,-1:3.0
-3,1,-1:3.0
-2,1,-1:99.10
-1,1,-1:99.10
0,1,-1:99.10
1,1,-1:99.10
2,1,-1:3.0
3,1,-1:3.0
-4,2,-1:110.0
-3,2,-1:3.0
-2,2,-1:3.0
-1,2,-1:3.0
0,2,-1:3.0
1,2,-1:3.0
2,2,-1:3.0
3,2,-1:110.0
-3,3,-1:110.0
-2,3,-1:3.0
-1,3,-1:3.0
0,3,-1:3.0
1,3,-1:3.0
2,3,-1:110.0
3,3,-1:110.0
-2,4,-1:110.0
-1,4,-1:110.0
0,4,-1:110.0
-1,-5,0:100.10
0,-5,0:100.10
-2,-4,0:100.10
-1,-4,0:100.10
0,-4,0:100.10
1,-4,0:100.10
2,-4,0:100.10
-4,-3,0:100.10
-3,-3,0:100.10
-2,-3,0:100.10
-1,-3,0:100.10
0,-3,0:99.10
2,-3,0:100.10
3,-3,0:100.10
4,-3,0:100.10
-5,-2,0:100.10
-4,-2,0:100.10
-3,-2,0:99.10
2,-2,0:99.10
3,-2,0:100.10
4,-2,0:100.10
-5,-1,0:100.10
-4,-1,0:100.10
-3,-1,0:99.10
3,-1,0:100.10
4,-1,0:100.10
-4,0,0:100.10
-3,0,0:100.10
-4,1,0:100.10
-3,1,0:100.10
-2,1,0:99.10
2,1,0:100.10
3,1,0:100.10
-3,2,0:100.10
-2,2,0:100.10
-1,2,0:100.10
0,2,0:100.10
1,2,0:100.10
2,2,0:100.10
-2,3,0:100.10
-1,3,0:100.10
0,3,0:100.10
1,3,0:100.10
-1,-4,1:100.10
0,-4,1:100.10
1,-4,1:100.10
-3,-3,1:100.10
-2,-3,1:100.10
-1,-3,1:100.10
2,-3,1:100.10
3,-3,1:100.10
-4,-2,1:100.10
-3,-2,1:100.10
3,-2,1:100.10
4,-2,1:100.10
-4,-1,1:100.10
3,-1,1:100.10
-4,0,1:100.10
-3,0,1:100.10
-3,1,1:100.10
-2,1,1:100.10
2,1,1:100.10
3,1,1:100.10
-2,2,1:100.10
-1,2,1:100.10
0,2,1:100.10
1,2,1:100.10
-1,3,1:100.10
0,-4,2:100.10
1,-4,2:100.10
-3,-3,2:100.10
-2,-3,2:100.10
-1,-3,2:100.10
0,-3,2:100.10
1,-3,2:100.10
2,-3,2:100.10
-3,-2,2:100.10
-2,-2,2:100.10
-1,-2,2:100.10
2,-2,2:100.10
3,-2,2:100.10
-4,-1,2:100.10
-3,-1,2:100.10
2,-1,2:100.10
3,-1,2:100.10
-3,0,2:100.10
-2,0,2:100.10
2,0,2:100.10
3,0,2:100.10
-3,1,2:100.10
-2,1,2:100.10
-1,1,2:100.10
0,1,2:100.10
1,1,2:100.10
2,1,2:100.10
3,1,2:100.10
-2,2,2:100.10
-1,2,2:100.10
0,2,2:100.10
1,2,2:100.10
-1,3,2:100.10
-2,-3,3:100.10
-1,-3,3:100.10
0,-3,3:100.10
1,-3,3:100.10
-3,-2,3:100.10
-2,-2,3:100.10
-1,-2,3:100.10
1,-2,3:100.10
2,-2,3:100.10
-3,-1,3:100.10
-2,-1,3:100.10
2,-1,3:100.10
3,-1,3:100.10
-2,0,3:100.10
1,0,3:100.10
2,0,3:100.10
3,0,3:100.10
-2,1,3:100.10
-1,1,3:100.10
0,1,3:100.10
1,1,3:100.10
2,1,3:100.10
-1,2,3:100.10
0,2,3:100.10
0,-3,4:100.10
1,-3,4:100.10
-2,-2,4:100.10
-1,-2,4:100.10
0,-2,4:100.10
1,-2,4:100.10
2,-2,4:100.10
-2,-1,4:100.10
-1,-1,4:100.10
1,-1,4:100.10
2,-1,4:100.10
-2,0,4:100.10
-1,0,4:100.10
0,0,4:100.10
1,0,4:100.10
2,0,4:100.10
3,0,4:100.10
-2,1,4:100.10
-1,1,4:100.10
0,1,4:100.10
1,1,4:100.10
-1,2,4:100.10
-3,-5,5:100.1
-2,-5,5:100.3
-1,-5,5:100.3
0,-5,5:100.3
1,-5,5:100.3
2,-5,5:100.3
3,-5,5:100.3
-4,-4,5:100.1
4,-4,5:100.3
-4,-3,5:100.1
0,-3,5:100.10
1,-3,5:100.10
4,-3,5:100.9
-4,-2,5:100.1
-2,-2,5:100.10
-1,-2,5:100.10
0,-2,5:100.10
1,-2,5:100.10
4,-2,5:100.9
-4,-1,5:100.1
-2,-1,5:100.10
-1,-1,5:100.10
0,-1,5:100.10
1,-1,5:100.10
2,-1,5:100.10
4,-1,5:100.9
-4,0,5:100.1
-2,0,5:100.10
-1,0,5:100.10
0,0,5:100.10
1,0,5:100.10
2,0,5:100.10
4,0,5:100.9
-4,1,5:100.1
-2,1,5:100.10
-1,1,5:100.10
0,1,5:100.10
1,1,5:100.10
4,1,5:100.9
-4,2,5:100.1
4,2,5:100.9
-4,3,5:100.7
4,3,5:100.9
-3,4,5:100.7
-2,4,5:100.7
-1,4,5:100.7
0,4,5:100.7
1,4,5:100.7
2,4,5:100.7
3,4,5:100.9
-3,-5,6:100.1
-2,-5,6:100.1
-1,-5,6:100.1
0,-5,6:100.1
1,-5,6:100.1
2,-5,6:100.1
3,-5,6:100.3
-4,-4,6:100.1
-3,-4,6:100.1
3,-4,6:100.3
4,-4,6:100.3
-4,-3,6:100.7
4,-3,6:100.3
-4,-2,6:100.7
-1,-2,6:100.10
0,-2,6:100.10
1,-2,6:100.10
4,-2,6:100.3
-4,-1,6:100.7
-2,-1,6:100.10
-1,-1,6:100.10
0,-1,6:100.10
1,-1,6:100.10
2,-1,6:100.10
4,-1,6:100.3
-4,0,6:100.7
-1,0,6:100.10
0,0,6:100.10
1,0,6:100.10
4,0,6:100.3
-4,1,6:100.7
-1,1,6:100.10
0,1,6:100.10
4,1,6:100.3
-4,2,6:100.7
4,2,6:100.3
-4,3,6:100.7
-3,3,6:100.7
3,3,6:100.9
4,3,6:100.9
-3,4,6:100.7
-2,4,6:100.7
-1,4,6:100.7
0,4,6:100.7
1,4,6:100.7
2,4,6:100.7
3,4,6:100.9
-3,-5,7:100.1
-2,-5,7:100.1
-1,-5,7:100.1
0,-5,7:100.1
1,-5,7:100.1
2,-5,7:100.1
3,-5,7:100.3
-4,-4,7:100.1
-3,-4,7:100.1
3,-4,7:100.3
4,-4,7:100.3
-4,-3,7:100.7
4,-3,7:100.3
-4,-2,7:100.7
-1,-2,7:100.10
0,-2,7:100.10
4,-2,7:100.3
-4,-1,7:100.7
-1,-1,7:100.10
0,-1,7:100.10
1,-1,7:100.10
4,-1,7:100.3
-4,0,7:100.7
-1,0,7:100.10
0,0,7:100.10
1,0,7:100.10
4,0,7:100.3
-4,1,7:100.7
0,1,7:100.10
4,1,7:100.3
-4,2,7:100.7
4,2,7:100.3
-4,3,7:100.7
-3,3,7:100.7
3,3,7:100.9
4,3,7:100.9
-3,4,7:100.7
-2,4,7:100.9
-1,4,7:100.9
0,4,7:100.9
1,4,7:100.9
2,4,7:100.9
3,4,7:100.9
-2,-4,8:100.1
-1,-4,8:100.1
0,-4,8:100.1
1,-4,8:100.1
2,-4,8:100.3
-3,-3,8:100.1
3,-3,8:100.3
-3,-2,8:100.7
0,-2,8:100.10
3,-2,8:100.3
-3,-1,8:100.7
-1,-1,8:100.10
0,-1,8:100.10
1,-1,8:100.10
3,-1,8:100.3
-3,0,8:100.7
-1,0,8:100.10
0,0,8:100.10
1,0,8:100.10
3,0,8:100.3
-3,1,8:100.7
0,1,8:100.10
3,1,8:100.3
-3,2,8:100.7
3,2,8:100.9
-2,3,8:100.7
-1,3,8:100.9
0,3,8:100.9
1,3,8:100.9
2,3,8:100.9
-2,-4,9:100.1
-1,-4,9:100.3
0,-4,9:100.3
1,-4,9:100.3
2,-4,9:100.3
-3,-3,9:100.1
3,-3,9:100.3
-3,-2,9:100.4
-1,-2,9:89.0
0,-2,9:100.10
1,-2,9:89.0
3,-2,9:100.9
-3,-1,9:100.4
-1,-1,9:100.10
0,-1,9:100.10
1,-1,9:100.10
3,-1,9:100.9
-3,0,9:100.4
-1,0,9:100.10
0,0,9:100.10
1,0,9:100.10
3,0,9:100.9
-3,1,9:100.4
-1,1,9:89.0
0,1,9:100.10
1,1,9:89.0
3,1,9:100.9
-3,2,9:100.7
3,2,9:100.9
-2,3,9:100.7
-1,3,9:100.7
0,3,9:100.7
1,3,9:100.7
2,3,9:100.9
-2,-3,10:100.1
-1,-3,10:100.1
0,-3,10:100.1
1,-3,10:100.1
2,-3,10:100.3
-2,-2,10:100.4
-1,-2,10:100.4
0,-2,10:100.4
1,-2,10:100.4
2,-2,10:100.3
-2,-1,10:100.4
-1,-1,10:100.4
0,-1,10:100.4
1,-1,10:100.4
2,-1,10:100.3
-2,0,10:100.4
-1,0,10:100.4
0,0,10:100.4
1,0,10:100.4
2,0,10:100.3
-2,1,10:100.4
-1,1,10:100.4
0,1,10:100.4
1,1,10:100.4
2,1,10:100.3
-2,2,10:100.7
-1,2,10:100.9
0,2,10:100.9
1,2,10:100.9
2,2,10:100.9
2,-2,5:40.0
-1,3,3:40.0
3,1,3:40.0
-4,0,2:40.0
4,-2,2:40.0
3,-3,2:40.0
-1,-4,2:40.0
1,3,1:40.0
-3,-1,1:40.0
2,-2,1:40.0
0,-3,1:40.0
-2,-4,1:40.0
3,3,0:40.0
3,2,0:40.0
-4,2,0:40.0
1,1,0:40.0
-1,1,0:40.0
0,0,0:40.0
-2,0,0:40.0
2,-1,0:40.0
0,-1,0:40.0
-1,-1,0:40.0
-1,-2,0:40.0
1,-3,0:40.0
-5,-3,0:40.0
