[META]
version=2.0
spawnOnBlockType=3,2
spawnSunlight=True
spawnDarkness=True
spawnWater=False
spawnLava=False
underFill=False
randomRotation=False
dig=True
tree=True
branch=False
needsFoundation=True
rarity=100
collisionPercentage=20
spawnElevationMin=0
spawnElevationMax=240
spawnInBiome=All
[DATA]
-1,-1,-3:88.5
-2,0,-3:88.5
-1,0,-3:88.5
0,0,-3:88.5
-2,1,-3:88.5
-1,1,-3:88.5
0,1,-3:88.5
-1,2,-3:88.5
-1,-2,-2:3.0
-1,-1,-2:3.0
-2,0,-2:3.0
-1,0,-2:3.0
0,0,-2:3.0
-2,1,-2:3.0
-1,1,-2:3.0
0,1,-2:3.0
-2,2,-2:3.0
-1,2,-2:3.0
-1,3,-2:3.0
-1,-2,-1:110.5
-2,-1,-1:110.5
-1,-1,-1:3.0
0,-1,-1:110.5
-2,0,-1:110.5
-1,0,-1:110.5
0,0,-1:110.5
-2,1,-1:110.5
-1,1,-1:110.5
0,1,-1:110.5
-2,2,-1:3.0
-1,2,-1:110.5
0,2,-1:110.5
-1,3,-1:110.5
-1,-1,0:99.10
-2,2,0:99.10
-1,-1,1:99.10
-2,2,1:99.10
-1,-1,2:99.10
-2,2,2:99.10
-1,-1,3:99.10
-2,2,3:99.10
-1,-1,4:99.10
-2,2,4:99.10
-1,-1,5:99.10
-2,2,5:99.10
-2,-3,6:99.10
-1,-3,6:99.10
0,-3,6:99.10
-3,-2,6:99.10
-2,-2,6:99.10
-1,-2,6:99.0
0,-2,6:99.10
1,-2,6:99.10
-3,-1,6:99.10
-2,-1,6:99.0
-1,-1,6:99.10
0,-1,6:99.0
1,-1,6:99.10
-3,0,6:99.10
-2,0,6:99.10
-1,0,6:99.0
0,0,6:99.10
1,0,6:99.10
-2,1,6:99.10
-1,1,6:99.10
0,1,6:99.10
-2,2,6:99.10
-2,-2,7:99.10
-1,-2,7:99.10
0,-2,7:99.10
-2,-1,7:99.10
-1,-1,7:99.10
0,-1,7:99.10
-2,0,7:99.10
-1,0,7:99.10
0,0,7:99.10
-2,2,7:99.10
-2,2,8:99.10
-3,0,9:99.10
-2,0,9:99.10
-1,0,9:99.10
-4,1,9:99.10
-3,1,9:99.10
-2,1,9:99.0
-1,1,9:99.10
0,1,9:99.10
-4,2,9:99.10
-3,2,9:99.0
-2,2,9:99.10
-1,2,9:99.0
0,2,9:99.10
-4,3,9:99.10
-3,3,9:99.10
-2,3,9:99.0
-1,3,9:99.10
0,3,9:99.10
-3,4,9:99.10
-2,4,9:99.10
-1,4,9:99.10
-3,1,10:99.10
-2,1,10:99.10
-1,1,10:99.10
-3,2,10:99.10
-2,2,10:99.10
-1,2,10:99.10
-3,3,10:99.10
-2,3,10:99.10
-1,3,10:99.10
-1,2,0:40.5
-2,1,0:40.0
-1,0,0:40.5
-2,0,0:40.5
0,-1,0:40.5
