[META]
version=2.0
spawnOnBlockType=2,12
spawnSunlight=True
spawnDarkness=True
spawnWater=False
spawnLava=False
underFill=False
randomRotation=True
dig=true
tree=false
branch=False
needsFoundation=True
rarity=200
collisionPercentage=80
spawnElevationMin=0
spawnElevationMax=80
spawnInBiome=All
[DATA]
-1,-1,0:17.3
-1,0,0:17.3
-1,1,0:17.3
0,1,0:17.3
0,0,0:17.3
0,-1,0:17.3
1,-1,0:17.3
1,0,0:17.3
1,1,0:17.3
-2,1,0:17.3
-1,-2,0:17.3
2,-1,0:17.3
2,-2,0:17.3
1,2,0:17.3
2,2,0:17.3
-2,2,0:17.3
-2,0,0:17.3
-3,0,0:17.3
-3,2,0:17.3
-1,-3,0:17.3
-2,-3,0:17.3
-2,-4,0:17.3
2,3,0:17.3
3,3,0:17.3
-1,-4,0:2
0,-2,0:2
0,-3,0:2
1,-2,0:2
-2,-1,0:2
-2,-2,0:2
-3,-1,0:2
-3,1,0:2
-1,2,0:2
0,2,0:2
-2,3,0:2
2,1,0:2
3,2,0:2
2,0,0:2
3,-1,0:2
2,-3,0:2
3,-2,0:2
3,4,0:2
4,3,0:2
4,2,0:2
-4,2,0:2
-3,3,0:2
-4,0,0:2
-4,1,0:2
-3,-2,0:2
-3,-3,0:2
-3,-4,0:2
-2,-5,0:2
-1,-5,0:2
0,-4,0:2
-4,-1,0:2
-1,3,0:2
0,3,0:2
1,3,0:2
2,4,0:2
1,-3,0:2
1,-1,-1:17.3
2,-2,-1:17.3
0,-1,-1:17.3
-1,-1,-1:17.3
-1,-2,-1:17.3
-1,1,-1:17.3
-2,1,-1:17.3
1,1,-1:17.3
1,2,-1:17.3
2,2,-1:17.3
1,0,-1:17.3
0,1,-1:17.3
-1,0,-1:17.3
0,0,-1:17.3
-2,2,-1:17.3
-3,2,-1:17.3
-1,-3,-1:17.3
3,-2,-1:17.3
3,-3,-1:17.3
2,3,-1:17.3
3,3,-1:17.3
-2,-3,-1:17.3
4,2,-1:17.3
3,4,-1:17.3
-4,2,-1:17.3
-4,3,-1:17.3
-3,-4,-1:17.3
-2,-4,-1:17.3
3,-4,-1:17.3
4,-3,-1:17.3
-3,0,-1:17.3
0,-4,-1:17.3
-2,-5,-1:17.3
5,-3,-1:17.3
3,-5,-1:17.3
2,-1,-1:17.3
-4,0,-1:17.3
-5,3,-1:17.3
-4,4,-1:17.3
4,3,-1:17.3
3,5,-1:17.3
3,6,-1:17.3
4,6,-1:17.3
-4,-4,-1:17.3
-4,-5,-1:17.3
-2,-6,-1:17.3
-1,-6,-1:17.3
-1,-7,-1:17.3
5,2,-1:17.3
6,-3,-1:17.3
-5,0,-1:17.3
-2,0,-1:17.3
-5,-1,-1:17.3
-6,0,-1:17.3
-4,5,-1:17.3
-3,5,-1:17.3
-5,5,-1:17.3
-4,6,-1:17.3
4,-2,-1:2
4,-1,-1:2
3,0,-1:2
3,1,-1:2
4,1,-1:2
5,3,-1:2
4,4,-1:2
4,5,-1:2
2,5,-1:2
1,4,-1:2
0,4,-1:2
-1,4,-1:2
-2,4,-1:2
-3,4,-1:2
-5,4,-1:2
-5,2,-1:2
-5,1,-1:2
-5,-2,-1:2
-4,-2,-1:2
-4,-3,-1:2
-3,-5,-1:2
0,-5,-1:2
1,-5,-1:2
1,-4,-1:2
2,-4,-1:2
-4,-1,-1:3
-3,-1,-1:3
-2,-2,-1:3
-3,-3,-1:3
-3,1,-1:3
-3,3,-1:3
-2,3,-1:3
-1,3,-1:3
1,3,-1:3
0,2,-1:3
2,4,-1:3
3,2,-1:3
2,1,-1:3
3,-1,-1:3
2,-3,-1:3
1,-3,-1:3
0,-2,-1:3
-1,-4,-1:3
-1,-1,1:17.3
-1,0,1:17.3
-1,1,1:17.3
0,1,1:17.3
0,0,1:17.3
0,-1,1:17.3
1,-1,1:17.3
1,0,1:17.3
1,1,1:17.3
1,2,1:17.3
-2,1,1:17.3
-1,-2,1:17.3
2,-1,1:17.3
-1,-1,2:17.3
-1,0,2:17.3
-1,1,2:17.3
0,1,2:17.3
0,0,2:17.3
0,-1,2:17.3
1,-1,2:17.3
1,0,2:17.3
1,1,2:17.3
-1,-1,3:17.3
-1,0,3:17.3
-1,1,3:17.3
0,1,3:17.3
0,0,3:17.3
0,-1,3:17.3
1,-1,3:17.3
1,0,3:17.3
1,1,3:17.3
-1,-1,4:17.3
-1,0,4:17.3
-1,1,4:17.3
0,1,4:17.3
0,0,4:17.3
0,-1,4:17.3
1,-1,4:17.3
1,0,4:17.3
1,1,4:17.3
-1,-1,5:17.3
0,-1,5:17.3
1,-1,5:17.3
1,0,5:17.3
-1,0,5:17.3
-1,1,5:17.3
0,1,5:17.3
1,1,5:17.3
0,0,5:17.3
-1,2,5:17.3
-2,2,5:17.3
-2,3,5:17.3
0,-2,5:17.3
0,-3,5:17.3
1,-3,5:17.3
-3,3,5:18.3
-2,4,5:18.3
-1,3,5:18.3
-2,1,5:18.3
-3,1,5:18.3
-2,-1,5:18.3
-1,-3,5:18.3
0,-4,5:18.3
1,-4,5:18.3
2,-3,5:18.3
1,-2,5:18.3
2,1,5:18.3
-1,-1,6:17.3
-1,0,6:17.3
-1,1,6:17.3
0,1,6:17.3
0,0,6:17.3
0,-1,6:17.3
1,-1,6:17.3
1,0,6:17.3
1,1,6:17.3
-2,3,6:18.3
1,-3,6:18.3
0,-3,6:18.3
-1,-1,7:17.3
-1,0,7:17.3
-1,1,7:17.3
0,1,7:17.3
0,0,7:17.3
0,-1,7:17.3
1,-1,7:17.3
1,0,7:17.3
1,1,7:17.3
-1,-1,8:17.3
-1,0,8:17.3
-1,1,8:17.3
0,1,8:17.3
0,0,8:17.3
0,-1,8:17.3
1,-1,8:17.3
1,0,8:17.3
1,1,8:17.3
-2,0,8:17.3
-3,0,8:17.3
-3,-1,8:17.3
-4,0,8:17.3
-5,1,8:17.3
-4,1,8:17.3
2,1,8:17.3
3,1,8:17.3
3,2,8:17.3
4,2,8:17.3
4,3,8:17.3
1,-2,8:17.3
1,-3,8:17.3
0,-3,8:17.3
0,-4,8:17.3
-1,2,8:17.3
-2,2,8:18.3
-1,3,8:18.3
0,2,8:18.3
3,3,8:18.3
4,4,8:18.3
5,3,8:18.3
3,0,8:18.3
4,0,8:18.3
2,-3,8:18.3
0,-2,8:18.3
-1,-4,8:18.3
0,-5,8:18.3
1,-4,8:18.3
-4,-1,8:18.3
-3,-2,8:18.3
-2,-1,8:18.3
-5,0,8:18.3
-6,1,8:18.3
-5,2,8:18.3
-1,-1,9:17.3
-1,0,9:17.3
-1,1,9:17.3
0,1,9:17.3
0,0,9:17.3
0,-1,9:17.3
1,-1,9:17.3
1,0,9:17.3
1,1,9:17.3
-5,1,9:18.3
4,3,9:18.3
4,2,9:18.3
1,-3,9:18.3
0,-3,9:18.3
0,-4,9:18.3
-1,2,9:18.3
-1,-1,10:17.3
-1,0,10:17.3
-1,1,10:17.3
0,1,10:17.3
0,0,10:17.3
0,-1,10:17.3
1,-1,10:17.3
1,0,10:17.3
1,1,10:17.3
-1,-1,11:17.3
-1,0,11:17.3
-1,1,11:17.3
0,1,11:17.3
0,0,11:17.3
0,-1,11:17.3
1,0,11:17.3
1,-1,11:17.3
1,2,11:17.3
1,1,11:17.3
0,2,11:18.3
1,3,11:18.3
2,2,11:18.3
-1,-1,12:17.3
-1,0,12:17.3
-1,1,12:17.3
0,1,12:17.3
0,0,12:17.3
1,0,12:17.3
1,-1,12:17.3
0,-1,12:17.3
1,1,12:17.3
-1,-1,13:17.3
-1,0,13:17.3
-1,1,13:17.3
0,1,13:17.3
0,0,13:17.3
0,-1,13:17.3
1,-1,13:17.3
1,0,13:17.3
1,1,13:17.3
2,0,13:17.3
3,0,13:17.3
3,-1,13:17.3
-2,0,13:17.3
-3,0,13:17.3
-3,1,13:17.3
-3,2,13:17.3
0,-2,13:17.3
-1,-2,13:17.3
-3,3,13:17.3
-4,3,13:17.3
-3,4,13:17.3
-2,3,13:17.3
4,1,13:17.3
4,0,13:17.3
-1,-3,13:17.3
-1,-4,13:17.3
-4,2,13:18.3
-5,3,13:18.3
-4,4,13:18.3
-3,5,13:18.3
-2,4,13:18.3
-2,2,13:18.3
-1,3,13:18.3
-4,0,13:18.3
-3,-1,13:18.3
-4,-1,13:18.3
-2,-3,13:18.3
-2,-4,13:18.3
-1,-5,13:18.3
0,-4,13:18.3
1,-2,13:18.3
3,-2,13:18.3
2,-1,13:18.3
4,-1,13:18.3
5,0,13:18.3
4,2,13:18.3
3,1,13:18.3
5,1,13:18.3
-1,-1,14:17.3
-1,0,14:17.3
-1,1,14:17.3
0,1,14:17.3
0,0,14:17.3
0,-1,14:17.3
1,-1,14:17.3
1,0,14:17.3
1,1,14:17.3
-4,3,14:18.3
-3,3,14:18.3
-3,4,14:18.3
-2,3,14:18.3
-1,-4,14:18.3
-1,-3,14:18.3
4,0,14:18.3
4,1,14:18.3
3,-1,14:18.3
-1,-1,15:17.3
-1,0,15:17.3
-1,1,15:17.3
0,1,15:17.3
0,0,15:17.3
0,-1,15:17.3
1,-1,15:17.3
1,0,15:17.3
1,1,15:17.3
-1,-1,16:17.3
-1,0,16:17.3
-1,1,16:17.3
0,1,16:17.3
0,0,16:17.3
0,-1,16:17.3
1,-1,16:17.3
1,0,16:17.3
1,1,16:17.3
-1,-1,17:17.3
-1,0,17:17.3
-1,1,17:17.3
0,1,17:17.3
0,0,17:17.3
0,-1,17:17.3
1,-1,17:17.3
1,0,17:17.3
1,1,17:17.3
-2,2,17:17.3
-2,1,17:17.3
-2,3,17:17.3
2,0,17:17.3
3,1,17:17.3
3,0,17:17.3
4,1,17:17.3
-1,-2,17:17.3
-1,-3,17:17.3
0,-3,17:17.3
-1,-4,17:17.3
-2,-3,17:17.3
-3,3,17:17.3
-4,3,17:17.3
-3,4,17:17.3
-2,-4,17:18.3
-3,-3,17:18.3
-2,-2,17:18.3
-1,-5,17:18.3
0,-4,17:18.3
1,-3,17:18.3
0,-2,17:18.3
-3,2,17:18.3
-4,2,17:18.3
-5,3,17:18.3
-4,4,17:18.3
-3,5,17:18.3
-2,4,17:18.3
-1,3,17:18.3
3,2,17:18.3
4,2,17:18.3
4,0,17:18.3
5,1,17:18.3
3,-1,17:18.3
-2,0,17:18.3
-1,-1,18:17.3
-1,0,18:17.3
-1,1,18:17.3
0,1,18:17.3
0,0,18:17.3
0,-1,18:17.3
1,-1,18:17.3
1,0,18:17.3
1,1,18:17.3
-4,3,18:18.3
-3,3,18:18.3
-3,4,18:18.3
-3,2,18:18.3
-2,3,18:18.3
-2,-3,18:18.3
-1,-4,18:18.3
0,-3,18:18.3
3,1,18:18.3
3,0,18:18.3
4,1,18:18.3
3,2,18:18.3
-1,-1,19:17.3
-1,0,19:17.3
-1,1,19:17.3
0,1,19:17.3
0,0,19:17.3
0,-1,19:17.3
1,-1,19:17.3
1,0,19:17.3
1,1,19:17.3
-1,-1,20:17.3
-1,0,20:17.3
-1,1,20:17.3
0,1,20:17.3
0,0,20:17.3
0,-1,20:17.3
1,-1,20:17.3
1,0,20:17.3
1,1,20:17.3
-1,-1,21:17.3
-1,0,21:17.3
-1,1,21:17.3
0,1,21:17.3
0,0,21:17.3
0,-1,21:17.3
1,-1,21:17.3
1,0,21:17.3
1,1,21:17.3
-1,-1,22:17.3
-1,0,22:17.3
-1,1,22:17.3
0,1,22:17.3
0,0,22:17.3
1,0,22:17.3
1,1,22:17.3
1,-1,22:17.3
0,-1,22:17.3
0,2,22:17.3
0,3,22:17.3
0,4,22:17.3
0,5,22:17.3
-2,0,22:17.3
-3,0,22:17.3
-3,1,22:17.3
-4,1,22:17.3
-5,1,22:17.3
-6,1,22:17.3
-6,2,22:17.3
-7,2,22:17.3
-8,2,22:17.3
-6,3,22:17.3
-6,4,22:17.3
-6,0,22:17.3
-7,0,22:17.3
-7,-1,22:17.3
-7,-2,22:17.3
-3,-1,22:17.3
-3,-2,22:17.3
-4,-2,22:17.3
-1,-2,22:17.3
-1,-3,22:17.3
0,-3,22:17.3
0,-4,22:17.3
0,-5,22:17.3
0,-6,22:17.3
1,-6,22:17.3
0,-7,22:17.3
0,-8,22:17.3
-1,-6,22:17.3
-2,-6,22:17.3
-2,-7,22:17.3
-3,-7,22:17.3
-4,-7,22:17.3
-7,-3,22:17.3
-7,-4,22:17.3
-8,-4,22:17.3
-9,-4,22:17.3
-8,-5,22:17.3
-5,-6,22:17.3
-5,-7,22:17.3
-5,-8,22:17.3
1,-8,22:17.3
2,-9,22:17.3
1,-3,22:17.3
2,0,22:17.3
3,0,22:17.3
3,-1,22:17.3
3,-2,22:17.3
4,-2,22:17.3
5,-2,22:17.3
5,-3,22:17.3
5,-4,22:17.3
5,-5,22:17.3
6,-4,22:17.3
6,-2,22:17.3
7,-1,22:17.3
6,-1,22:17.3
8,-1,22:17.3
8,0,22:17.3
3,1,22:17.3
4,1,22:17.3
5,1,22:17.3
5,2,22:17.3
5,3,22:17.3
5,4,22:17.3
6,4,22:17.3
7,5,22:17.3
7,4,22:17.3
4,4,22:17.3
4,5,22:17.3
8,-2,22:17.3
9,-2,22:17.3
3,5,22:17.3
3,6,22:17.3
1,4,22:17.3
0,6,22:17.3
-1,6,22:17.3
-2,6,22:17.3
-3,6,22:17.3
-3,7,22:17.3
-3,8,22:17.3
-2,8,22:17.3
-2,9,22:17.3
-1,4,22:17.3
-2,4,22:17.3
-2,3,22:17.3
-6,-4,22:18.3
-6,-3,22:18.3
-6,-2,22:18.3
-6,-1,22:18.3
-7,-5,22:18.3
-8,-6,22:18.3
-9,-6,22:18.3
-9,-5,22:18.3
-10,-5,22:18.3
-10,-4,22:18.3
-10,-3,22:18.3
-9,-3,22:18.3
-8,0,22:18.3
-8,1,22:18.3
-7,1,22:18.3
-9,2,22:18.3
-9,1,22:18.3
-9,3,22:18.3
-7,4,22:18.3
-7,5,22:18.3
-6,5,22:18.3
-5,5,22:18.3
-5,4,22:18.3
-4,7,22:18.3
-4,8,22:18.3
-4,9,22:18.3
-3,9,22:18.3
-2,10,22:18.3
-1,9,22:18.3
-1,8,22:18.3
-2,7,22:18.3
0,7,22:18.3
-1,5,22:18.3
-2,5,22:18.3
-3,4,22:18.3
-2,2,22:18.3
-1,3,22:18.3
1,5,22:18.3
2,4,22:18.3
1,3,22:18.3
2,6,22:18.3
2,7,22:18.3
3,7,22:18.3
4,7,22:18.3
4,6,22:18.3
6,5,22:18.3
6,6,22:18.3
7,6,22:18.3
8,6,22:18.3
8,5,22:18.3
6,3,22:18.3
6,2,22:18.3
3,2,22:18.3
2,1,22:18.3
2,-1,22:18.3
5,-1,22:18.3
7,0,22:18.3
8,1,22:18.3
9,0,22:18.3
10,-2,22:18.3
9,-1,22:18.3
9,-3,22:18.3
7,-2,22:18.3
6,-3,22:18.3
7,-4,22:18.3
6,-5,22:18.3
5,-6,22:18.3
4,-5,22:18.3
3,-3,22:18.3
2,-3,22:18.3
1,-2,22:18.3
1,-4,22:18.3
1,-5,22:18.3
2,-6,22:18.3
1,-7,22:18.3
2,-8,22:18.3
3,-9,22:18.3
2,-10,22:18.3
1,-9,22:18.3
-1,-9,22:18.3
-1,-8,22:18.3
-1,-7,22:18.3
-3,-8,22:18.3
-5,-9,22:18.3
-4,-8,22:18.3
-6,-9,22:18.3
-6,-8,22:18.3
-6,-6,22:18.3
-4,-6,22:18.3
-5,-5,22:18.3
-2,-5,22:18.3
-4,-3,22:18.3
-4,-1,22:18.3
-3,-3,22:18.3
0,9,22:18.3
-1,10,22:18.3
-2,11,22:18.3
-3,10,22:18.3
-5,10,22:18.3
-5,9,22:18.3
-6,9,22:18.3
-5,8,22:18.3
-6,6,22:18.3
-7,6,22:18.3
-8,6,22:18.3
-8,5,22:18.3
-9,6,22:18.3
-7,7,22:18.3
-8,3,22:18.3
-10,1,22:18.3
-11,2,22:18.3
-10,2,22:18.3
-10,3,22:18.3
-11,-4,22:18.3
-7,-9,22:18.3
-6,-10,22:18.3
-2,-9,22:18.3
-2,-10,22:18.3
-1,-10,22:18.3
2,-11,22:18.3
3,-10,22:18.3
4,-9,22:18.3
3,-8,22:18.3
-5,-2,22:18.3
-3,-6,22:18.3
5,-7,22:18.3
6,-7,22:18.3
9,-4,22:18.3
10,-4,22:18.3
9,-5,22:18.3
11,-2,22:18.3
11,-1,22:18.3
9,1,22:18.3
10,1,22:18.3
12,-2,22:18.3
9,6,22:18.3
8,4,22:18.3
7,7,22:18.3
8,7,22:18.3
3,8,22:18.3
3,9,22:18.3
4,8,22:18.3
5,8,22:18.3
2,9,22:18.3
3,10,22:18.3
4,10,22:18.3
1,-10,22:18.3
-2,-11,22:18.3
-3,-10,22:18.3
-9,-7,22:18.3
-10,-7,22:18.3
-1,-1,23:17.3
-1,0,23:17.3
-1,1,23:17.3
0,1,23:17.3
0,0,23:17.3
0,-1,23:17.3
1,-1,23:17.3
1,0,23:17.3
1,1,23:17.3
-9,-4,23:18.3
-8,-5,23:18.3
-8,-4,23:18.3
-7,-4,23:18.3
-7,-3,23:18.3
-7,-2,23:18.3
-7,-1,23:18.3
-7,0,23:18.3
-6,0,23:18.3
-6,1,23:18.3
-7,2,23:18.3
-8,2,23:18.3
-6,2,23:18.3
-5,1,23:18.3
-4,1,23:18.3
-4,-2,23:18.3
-3,-2,23:18.3
-3,-1,23:18.3
-2,0,23:18.3
-3,0,23:18.3
-3,1,23:18.3
-2,1,23:18.3
-2,-1,23:18.3
-5,2,23:18.3
-6,3,23:18.3
-6,4,23:18.3
-3,6,23:18.3
-3,7,23:18.3
-3,8,23:18.3
-2,8,23:18.3
-2,9,23:18.3
-2,6,23:18.3
-2,4,23:18.3
-2,5,23:18.3
-1,5,23:18.3
-1,6,23:18.3
0,6,23:18.3
0,5,23:18.3
0,4,23:18.3
-1,4,23:18.3
-1,3,23:18.3
0,3,23:18.3
0,2,23:18.3
-1,2,23:18.3
-2,2,23:18.3
-2,3,23:18.3
-3,2,23:18.3
-2,-2,23:18.3
-1,-2,23:18.3
-1,-3,23:18.3
0,-3,23:18.3
1,-3,23:18.3
0,-4,23:18.3
0,-5,23:18.3
0,-6,23:18.3
0,-7,23:18.3
0,-8,23:18.3
1,-8,23:18.3
2,-9,23:18.3
1,-6,23:18.3
-1,-6,23:18.3
-2,-7,23:18.3
-2,-6,23:18.3
-1,-7,23:18.3
1,-7,23:18.3
1,-9,23:18.3
-3,-7,23:18.3
-4,-7,23:18.3
-5,-7,23:18.3
-5,-8,23:18.3
-6,-7,23:18.3
-5,-6,23:18.3
-3,-8,23:18.3
-6,-2,23:18.3
-5,-2,23:18.3
-6,-3,23:18.3
-4,0,23:18.3
-4,-1,23:18.3
-3,-3,23:18.3
-4,-3,23:18.3
-7,1,23:18.3
-9,2,23:18.3
-6,5,23:18.3
-7,6,23:18.3
-7,5,23:18.3
-5,4,23:18.3
-4,2,23:18.3
2,-1,23:18.3
2,0,23:18.3
2,1,23:18.3
1,2,23:18.3
2,2,23:18.3
1,3,23:18.3
1,4,23:18.3
3,5,23:18.3
3,6,23:18.3
4,5,23:18.3
4,4,23:18.3
5,4,23:18.3
6,4,23:18.3
7,5,23:18.3
7,4,23:18.3
5,3,23:18.3
5,2,23:18.3
5,1,23:18.3
4,1,23:18.3
3,1,23:18.3
3,0,23:18.3
3,-1,23:18.3
3,-2,23:18.3
4,-2,23:18.3
5,-2,23:18.3
5,-4,23:18.3
5,-5,23:18.3
5,-3,23:18.3
6,-4,23:18.3
6,-2,23:18.3
6,-1,23:18.3
7,-1,23:18.3
7,-2,23:18.3
8,-2,23:18.3
9,-2,23:18.3
8,-1,23:18.3
8,0,23:18.3
8,4,23:18.3
4,-5,23:18.3
5,-6,23:18.3
9,-3,23:18.3
10,-2,23:18.3
9,1,23:18.3
7,6,23:18.3
-1,9,23:18.3
-2,10,23:18.3
-4,8,23:18.3
-8,6,23:18.3
-9,-6,23:18.3
-1,-1,24:17.3
-1,0,24:17.3
-1,1,24:17.3
0,1,24:17.3
0,0,24:17.3
1,0,24:17.3
1,-1,24:17.3
0,-1,24:17.3
1,1,24:17.3
-2,0,24:17.3
-3,0,24:17.3
-3,1,24:17.3
-4,1,24:17.3
-5,1,24:17.3
-5,0,24:17.3
-6,0,24:17.3
-5,-1,24:17.3
-5,-2,24:17.3
-4,2,24:17.3
-1,2,24:17.3
-1,3,24:17.3
-1,4,24:17.3
0,4,24:17.3
0,5,24:17.3
0,6,24:17.3
1,4,24:17.3
2,4,24:17.3
2,5,24:17.3
1,2,24:17.3
2,2,24:17.3
3,2,24:17.3
3,1,24:17.3
2,-1,24:17.3
3,-1,24:17.3
4,-1,24:17.3
4,2,24:17.3
4,3,24:17.3
5,-1,24:17.3
4,-2,24:17.3
6,0,24:17.3
6,-1,24:17.3
0,-2,24:17.3
0,-3,24:17.3
1,-3,24:17.3
2,-3,24:17.3
2,-4,24:17.3
2,-5,24:17.3
-1,-3,24:17.3
-1,-4,24:17.3
-1,-5,24:17.3
-2,-5,24:17.3
-1,-1,25:17.3
-1,0,25:17.3
-1,1,25:17.3
0,1,25:17.3
0,0,25:17.3
0,-1,25:17.3
1,-1,25:17.3
1,0,25:17.3
1,1,25:17.3
-3,-6,25:18.3
-3,-5,25:18.3
-3,-4,25:18.3
-2,-4,25:18.3
-2,-5,25:18.3
-2,-6,25:18.3
-1,-6,25:18.3
-1,-5,25:18.3
0,-5,25:18.3
0,-4,25:18.3
1,-4,25:18.3
1,-5,25:18.3
1,-6,25:18.3
2,-6,25:18.3
3,-6,25:18.3
3,-5,25:18.3
2,-5,25:18.3
2,-4,25:18.3
3,-4,25:18.3
3,-3,25:18.3
4,-3,25:18.3
5,-3,25:18.3
5,-2,25:18.3
6,-2,25:18.3
7,-2,25:18.3
7,-1,25:18.3
7,0,25:18.3
6,0,25:18.3
6,-1,25:18.3
5,-1,25:18.3
4,-2,25:18.3
4,-1,25:18.3
3,-2,25:18.3
2,-2,25:18.3
1,-2,25:18.3
2,-3,25:18.3
1,-3,25:18.3
0,-3,25:18.3
-1,-4,25:18.3
-1,-3,25:18.3
-1,-2,25:18.3
0,-2,25:18.3
-2,-3,25:18.3
-2,-2,25:18.3
-2,-1,25:18.3
-3,-1,25:18.3
-4,-1,25:18.3
-4,-2,25:18.3
-4,-3,25:18.3
-5,-3,25:18.3
-6,-3,25:18.3
-6,-2,25:18.3
-5,-2,25:18.3
-5,-1,25:18.3
-6,-1,25:18.3
-6,0,25:18.3
-5,0,25:18.3
-7,0,25:18.3
-7,-1,25:18.3
-7,1,25:18.3
-6,1,25:18.3
-5,1,25:18.3
-4,0,25:18.3
-3,0,25:18.3
-2,0,25:18.3
-2,1,25:18.3
-3,-2,25:18.3
-3,-3,25:18.3
-3,1,25:18.3
-4,1,25:18.3
-4,2,25:18.3
-2,2,25:18.3
-2,3,25:18.3
-2,4,25:18.3
-1,2,25:18.3
0,2,25:18.3
1,2,25:18.3
1,3,25:18.3
0,3,25:18.3
-1,3,25:18.3
-1,4,25:18.3
-2,5,25:18.3
-1,5,25:18.3
-1,6,25:18.3
-1,7,25:18.3
0,7,25:18.3
0,6,25:18.3
0,5,25:18.3
0,4,25:18.3
1,4,25:18.3
1,5,25:18.3
1,6,25:18.3
2,6,25:18.3
2,5,25:18.3
2,4,25:18.3
2,3,25:18.3
3,3,25:18.3
3,4,25:18.3
3,5,25:18.3
4,4,25:18.3
4,3,25:18.3
4,2,25:18.3
4,1,25:18.3
4,0,25:18.3
3,-1,25:18.3
3,0,25:18.3
2,-1,25:18.3
2,0,25:18.3
2,1,25:18.3
2,2,25:18.3
3,2,25:18.3
3,1,25:18.3
5,2,25:18.3
5,3,25:18.3
5,0,25:18.3
6,1,25:18.3
5,1,25:18.3
1,7,25:18.3
-2,-7,25:18.3
2,-7,25:18.3
8,-1,25:18.3
5,-4,25:18.3
6,-4,25:18.3
6,-5,25:18.3
6,3,25:18.3
7,4,25:18.3
7,3,25:18.3
-3,5,25:18.3
-4,5,25:18.3
-3,6,25:18.3
-7,2,25:18.3
-8,1,25:18.3
-6,-4,25:18.3
-7,-4,25:18.3
-7,-5,25:18.3
-2,-8,25:18.3
2,-8,25:18.3
3,-8,25:18.3
1,-8,25:18.3
2,-9,25:18.3
-3,-8,25:18.3
-3,-9,25:18.3
0,8,25:18.3
3,7,25:18.3
3,8,25:18.3
3,6,25:18.3
4,6,25:18.3
-4,3,25:18.3
-5,3,25:18.3
-3,2,25:18.3
-1,-1,26:17.3
-1,0,26:17.3
-1,1,26:17.3
0,1,26:17.3
0,0,26:17.3
1,0,26:17.3
1,-1,26:17.3
0,-1,26:17.3
1,1,26:17.3
-2,1,26:17.3
-3,0,26:17.3
-4,0,26:17.3
-5,0,26:17.3
-2,0,26:17.3
-1,2,26:17.3
-1,3,26:17.3
-2,3,26:17.3
0,4,26:17.3
-1,4,26:17.3
2,1,26:17.3
3,1,26:17.3
3,2,26:17.3
3,0,26:17.3
4,1,26:17.3
1,-2,26:17.3
1,-3,26:17.3
0,-3,26:17.3
0,-4,26:17.3
-2,-1,26:17.3
-2,-2,26:17.3
-3,-1,26:18.3
-4,-1,26:18.3
-5,-1,26:18.3
-6,0,26:18.3
-5,1,26:18.3
-4,1,26:18.3
-3,1,26:18.3
-2,2,26:18.3
-3,3,26:18.3
-2,4,26:18.3
-1,5,26:18.3
-2,5,26:18.3
0,5,26:18.3
1,5,26:18.3
1,4,26:18.3
1,3,26:18.3
0,3,26:18.3
0,2,26:18.3
1,2,26:18.3
2,2,26:18.3
3,3,26:18.3
4,3,26:18.3
4,2,26:18.3
2,3,26:18.3
5,2,26:18.3
5,1,26:18.3
5,0,26:18.3
4,0,26:18.3
4,-1,26:18.3
3,-1,26:18.3
2,-1,26:18.3
2,0,26:18.3
2,-2,26:18.3
2,-3,26:18.3
2,-4,26:18.3
1,-4,26:18.3
1,-5,26:18.3
0,-5,26:18.3
-1,-5,26:18.3
-1,-4,26:18.3
-1,-3,26:18.3
-1,-2,26:18.3
0,-2,26:18.3
-2,-3,26:18.3
-3,-3,26:18.3
-3,-2,26:18.3
-6,-1,26:18.3
-6,1,26:18.3
-3,2,26:18.3
-3,4,26:18.3
0,0,27:17.3
-5,-1,27:18.3
-5,0,27:18.3
-4,0,27:18.3
-3,0,27:18.3
-2,-1,27:18.3
-2,-2,27:18.3
0,-3,27:18.3
0,-4,27:18.3
1,-3,27:18.3
1,-2,27:18.3
1,-1,27:18.3
0,-1,27:18.3
-1,-1,27:18.3
-1,0,27:18.3
-2,0,27:18.3
-2,2,27:18.3
-1,1,27:18.3
-2,1,27:18.3
-2,3,27:18.3
-1,3,27:18.3
-1,4,27:18.3
0,4,27:18.3
-1,2,27:18.3
0,1,27:18.3
1,1,27:18.3
1,0,27:18.3
2,1,27:18.3
3,1,27:18.3
3,2,27:18.3
4,1,27:18.3
3,0,27:18.3
1,0,28:18.3
-2,0,28:18.3
0,2,28:18.3
2,0,28:18.3
0,-2,28:18.3
1,-1,28:18.3
-1,-1,28:18.3
-1,1,28:18.3
1,1,28:18.3
0,0,28:18.3
-1,0,28:18.3
0,-1,28:18.3
0,1,28:18.3
-2,-2,-2:3
-3,0,-2:3
-1,0,-2:3
0,-1,-2:3
0,1,-2:3
1,0,-2:3
0,0,-2:3
-2,1,-2:3
-1,-1,-2:3
0,-2,-2:3
1,-1,-2:3
2,-1,-2:3
1,1,-2:3
2,2,-2:3
1,3,-2:3
0,2,-2:3
-2,3,-2:3
-4,3,-2:3
-3,2,-2:3
-4,-1,-2:3
-3,-4,-2:3
-2,-4,-2:3
-1,-3,-2:3
-2,-3,-2:3
2,-4,-2:3
3,-3,-2:3
2,-2,-2:3
3,-1,-2:3
3,2,-2:3
2,3,-2:3
3,4,-2:3
2,1,-2:3
4,-3,-2:3
3,-2,-2:3
1,-3,-2:3
-1,2,-2:3
-3,-2,-2:3
-1,-1,-3:3
-2,-3,-3:3
0,0,-3:3
1,0,-3:3
3,-3,-3:3
2,-2,-3:3
2,-1,-3:3
2,1,-3:3
2,3,-3:3
0,2,-3:3
-2,1,-3:3
