[META]
version=2.0
spawnOnBlockType=8,9
spawnSunlight=True
spawnDarkness=True
spawnWater=False
spawnLava=False
underFill=False
randomRotation=True
dig=True
tree=False
branch=False
needsFoundation=True
rarity=100
collisionPercentage=10
spawnElevationMin=0
spawnElevationMax=100
spawnInBiome=All
[DATA]
-1,0,0:17.0
-2,-2,-4:17.0
-3,-1,-4:17.0
-2,-1,-4:17.0
0,-1,-4:17.0
-1,0,-4:17.0
-2,1,-4:17.0
0,1,-4:17.0
1,1,-4:17.0
-1,-1,-3:17.0
-2,0,-3:17.0
-1,0,-3:17.0
0,0,-3:17.0
-1,1,-3:17.0
0,-1,-2:17.0
-1,0,-2:17.0
-2,1,-2:17.0
-1,0,-1:17.0
-1,0,1:17.0
1,2,1:106.2
1,1,1:106.2
-3,0,1:106.8
-1,-3,2:18
-2,-2,2:18
-1,-2,2:18
0,-2,2:18
-3,-1,2:18
-2,-1,2:17.0
-1,-1,2:18
0,-1,2:17.0
1,-1,2:18
-2,0,2:18
-1,0,2:17.0
0,0,2:18
1,0,2:18
-3,1,2:18
-2,1,2:17.0
-1,1,2:18
0,1,2:17.0
-2,2,2:18
-1,2,2:18
0,2,2:18
-1,3,2:18
1,2,2:106.2
1,1,2:106.2
-3,0,2:106.8
-2,-1,3:18
-1,-1,3:18
0,-1,3:18
-2,0,3:18
-1,0,3:18
0,0,3:18
-2,1,3:18
-1,1,3:18
0,1,3:18
0,-2,3:40
-1,0,4:18
-1,1,4:106.4
0,0,4:106.2
-2,0,4:106.8
-1,-1,4:40
-1,0,5:18
0,0,5:106.2
-2,0,5:106.8
