[META]
version=2.0
spawnOnBlockType=8,9
spawnSunlight=True
spawnDarkness=True
spawnWater=False
spawnLava=False
underFill=False
randomRotation=True
dig=True
tree=False
branch=False
needsFoundation=True
rarity=100
collisionPercentage=10
spawnElevationMin=0
spawnElevationMax=100
spawnInBiome=All
[DATA]
-1,-2,0:17.0
0,-2,0:17.0
-1,-1,0:17.0
0,-1,0:17.0
0,0,0:106.4
1,-1,0:106.2
1,-2,0:106.2
-2,-2,0:106.8
0,-3,0:106.1
-1,-3,0:106.1
3,-4,0:106.2
-1,-2,-4:17.0
-1,-3,-4:17.0
3,-5,-4:17.0
-4,-4,-4:17.0
-3,3,-4:17.0
3,2,-4:17.0
1,-3,-3:17.0
-3,-2,-3:17.0
-2,0,-3:17.0
1,0,-3:17.0
-1,1,-3:17.0
2,-4,-3:17.0
2,-5,-3:17.0
3,-5,-3:17.0
2,1,-3:17.0
3,1,-3:17.0
3,2,-3:17.0
-2,2,-3:17.0
-3,2,-3:17.0
-3,3,-3:17.0
-3,-3,-3:17.0
-3,-4,-3:17.0
-4,-4,-3:17.0
-1,-2,-3:17.0
-1,-3,-2:17.0
0,-3,-2:17.0
-2,-2,-2:17.0
1,-2,-2:17.0
-2,-1,-2:17.0
1,-1,-2:17.0
-1,0,-2:17.0
0,0,-2:17.0
-1,-2,-2:17.0
0,-2,-2:17.0
0,-1,-2:17.0
-1,-1,-2:17.0
-3,-3,-2:17.0
-3,-2,-2:17.0
-1,1,-2:17.0
-1,2,-2:17.0
-2,2,-2:17.0
1,0,-2:17.0
2,0,-2:17.0
2,1,-2:17.0
1,-3,-2:17.0
2,-3,-2:17.0
2,-4,-2:17.0
-1,-2,-1:17.0
0,-2,-1:17.0
-1,-1,-1:17.0
0,-1,-1:17.0
-1,-2,1:17.0
0,-2,1:17.0
-1,-1,1:17.0
0,-1,1:17.0
1,-1,1:106.2
1,-2,1:106.2
0,-3,1:106.1
-1,-3,1:106.1
3,-4,1:106.2
-1,-2,2:17.0
0,-2,2:17.0
-1,-1,2:17.0
0,-1,2:17.0
1,-2,2:106.2
0,-3,2:106.1
-1,-3,2:106.1
3,-4,2:106.2
-1,-2,3:17.0
0,-2,3:17.0
-1,-1,3:17.0
0,-1,3:17.0
1,-2,3:106.2
3,-4,3:106.2
-1,-2,4:17.0
0,-2,4:17.0
-1,-1,4:17.0
0,-1,4:17.0
1,-1,4:106.2
1,-2,4:106.2
3,-4,4:106.2
-1,-2,5:17.0
0,-2,5:17.0
-1,-1,5:17.0
0,-1,5:17.0
2,1,5:106.2
1,-1,5:106.2
1,-2,5:106.2
3,-4,5:106.2
-1,-2,6:17.0
0,-2,6:17.0
-1,-1,6:17.0
0,-1,6:17.0
2,1,6:106.2
1,-1,6:106.2
1,-2,6:106.2
3,-4,6:106.2
-1,-2,7:17.0
0,-2,7:17.0
-1,-1,7:17.0
0,-1,7:17.0
2,1,7:106.2
1,-1,7:106.2
1,-2,7:106.2
3,-4,7:106.2
-1,-2,8:17.0
0,-2,8:17.0
-1,-1,8:17.0
0,-1,8:17.0
0,0,8:17.0
2,1,8:106.2
1,-1,8:106.2
1,-2,8:106.2
3,-4,8:106.2
-1,-2,9:17.0
0,-2,9:17.0
-1,-1,9:17.0
0,-1,9:17.0
-2,0,9:18.0
0,0,9:18.0
1,0,9:18.0
2,0,9:18.0
-2,1,9:18.0
-1,1,9:17.0
0,1,9:18.0
1,1,9:18.0
-4,2,9:18.0
-3,2,9:18.0
-2,2,9:18.0
-1,2,9:17.0
0,2,9:18.0
1,2,9:18.0
-2,3,9:18.0
-1,3,9:18.0
0,3,9:18.0
1,3,9:18.0
2,3,9:18.0
-3,4,9:18.0
-2,4,9:18.0
-1,4,9:18.0
0,4,9:18.0
1,4,9:18.0
-2,5,9:18.0
-1,5,9:18.0
0,5,9:18.0
2,1,9:106.2
1,-2,9:106.2
3,-4,9:106.2
-1,-2,10:17.0
0,-2,10:17.0
-1,-1,10:17.0
0,-1,10:17.0
0,0,10:18.0
1,0,10:18.0
-2,1,10:18.0
-1,1,10:18.0
0,1,10:18.0
1,1,10:18.0
-2,2,10:18.0
-1,2,10:18.0
0,2,10:18.0
1,2,10:18.0
-3,3,10:18.0
-2,3,10:18.0
-1,3,10:17.0
0,3,10:18.0
1,3,10:18.0
-2,4,10:18.0
-1,4,10:18.0
-1,5,10:18.0
2,1,10:106.2
1,-1,10:106.2
1,-2,10:106.2
3,-4,10:106.2
-1,-2,11:17.0
0,-2,11:17.0
-1,-1,11:17.0
0,-1,11:17.0
0,0,11:17.0
-1,2,11:18.0
0,2,11:18.0
1,2,11:18.0
-2,3,11:18.0
-1,3,11:18.0
0,3,11:18.0
-1,4,11:18.0
0,1,11:106
-1,1,11:106
-1,0,11:106
1,-1,11:106.2
3,-4,11:106.2
-1,-2,12:17.0
0,-2,12:17.0
-1,-1,12:17.0
0,-1,12:17.0
-1,0,12:18.0
0,0,12:18.0
1,0,12:18.0
2,0,12:18.0
-1,1,12:18.0
0,1,12:18.0
1,1,12:17.0
2,1,12:18.0
3,1,12:18.0
-2,2,12:18.0
-1,2,12:18.0
0,2,12:18.0
1,2,12:17.0
2,2,12:18.0
3,2,12:18.0
4,2,12:18.0
5,2,12:18.0
0,3,12:18.0
1,3,12:18.0
2,3,12:18.0
3,3,12:18.0
4,3,12:18.0
-1,4,12:18.0
0,4,12:18.0
1,4,12:18.0
2,4,12:18.0
4,4,12:18.0
-1,5,12:18.0
0,5,12:18.0
2,5,12:18.0
3,5,12:18.0
1,-1,12:106.2
1,-2,12:106.2
3,-4,12:106.2
-1,-2,13:17.0
0,-2,13:17.0
-1,-1,13:17.0
0,-1,13:17.0
1,0,13:18.0
2,0,13:18.0
3,0,13:18.0
0,1,13:18.0
1,1,13:18.0
2,1,13:18.0
3,1,13:17.0
4,1,13:18.0
-1,2,13:18.0
0,2,13:18.0
1,2,13:18.0
2,2,13:18.0
3,2,13:18.0
-1,3,13:18.0
0,3,13:18.0
1,3,13:18.0
2,3,13:17.0
3,3,13:18.0
1,4,13:18.0
2,4,13:18.0
1,5,13:18.0
1,-1,13:106.2
1,-2,13:106.2
3,-4,13:106.2
-1,-2,14:17.0
0,-2,14:17.0
-1,-1,14:17.0
0,-1,14:17.0
2,1,14:18.0
3,1,14:18.0
0,2,14:18.0
1,2,14:18.0
3,2,14:18.0
0,3,14:18.0
1,3,14:18.0
2,3,14:18.0
1,-1,14:106.2
3,-2,14:106.2
0,-3,14:106
3,-4,14:106.2
-1,-5,15:18.0
0,-5,15:18.0
1,-5,15:18.0
-2,-4,15:18.0
-1,-4,15:18.0
0,-4,15:18.0
1,-4,15:18.0
2,-4,15:18.0
-3,-3,15:18.0
-2,-3,15:18.0
-1,-3,15:18.0
0,-3,15:18.0
1,-3,15:18.0
2,-3,15:18.0
3,-3,15:18.0
-4,-2,15:18.0
-3,-2,15:18.0
-1,-2,15:17.0
0,-2,15:17.0
2,-2,15:18.0
-3,-1,15:18.0
-1,-1,15:17.0
0,-1,15:17.0
2,-1,15:18.0
-2,0,15:18.0
-1,0,15:18.0
1,0,15:18.0
-2,1,15:18.0
-1,1,15:18.0
0,1,15:18.0
1,1,15:18.0
2,1,15:18.0
-2,2,15:18.0
-1,2,15:18.0
0,2,15:18.0
1,2,15:18.0
2,2,15:18.0
3,2,15:18.0
-1,3,15:18.0
0,3,15:18.0
1,3,15:18.0
2,3,15:18.0
0,0,15:106
1,-1,15:106
-2,-1,15:106
3,-2,15:106.2
-2,-2,15:106
3,-4,15:106.2
0,-5,16:18.0
-3,-4,16:18.0
-2,-4,16:18.0
-1,-4,16:18.0
0,-4,16:18.0
1,-4,16:18.0
-4,-3,16:18.0
-3,-3,16:18.0
-2,-3,16:18.0
-1,-3,16:18.0
0,-3,16:18.0
1,-3,16:18.0
2,-3,16:18.0
-5,-2,16:18.0
-4,-2,16:18.0
-3,-2,16:18.0
-2,-2,16:18.0
-1,-2,16:17.0
0,-2,16:18.0
1,-2,16:18.0
2,-2,16:18.0
3,-2,16:18.0
-3,-1,16:18.0
-2,-1,16:18.0
-1,-1,16:18.0
0,-1,16:18.0
1,-1,16:18.0
2,-1,16:18.0
-3,0,16:18.0
-2,0,16:18.0
-1,0,16:18.0
0,0,16:18.0
1,0,16:18.0
-2,1,16:18.0
-1,1,16:18.0
0,1,16:18.0
1,1,16:18.0
-1,2,16:18.0
1,2,16:18.0
2,2,16:18.0
2,-4,16:106.2
-1,-5,17:18.0
-2,-4,17:18.0
-1,-4,17:18.0
-2,-3,17:18.0
-1,-3,17:18.0
0,-3,17:18.0
1,-3,17:18.0
-4,-2,17:18.0
-3,-2,17:18.0
-2,-2,17:18.0
-1,-2,17:18.0
0,-2,17:18.0
1,-2,17:18.0
2,-2,17:18.0
-2,-1,17:18.0
-1,-1,17:18.0
1,-1,17:18.0
2,-1,17:18.0
-2,0,17:18.0
-1,0,17:18.0
0,0,17:18.0
-1,1,17:18.0
0,1,17:18.0
