[META]
version=2.0
spawnOnBlockType=8,9
spawnSunlight=True
spawnDarkness=True
spawnWater=False
spawnLava=False
underFill=False
randomRotation=True
dig=True
tree=False
branch=False
needsFoundation=True
rarity=100
collisionPercentage=10
spawnElevationMin=0
spawnElevationMax=100
spawnInBiome=All
[DATA]
0,-2,-6:17.0
1,-2,-6:17.0
1,0,-6:17.0
0,-2,-5:17.0
1,-2,-5:17.0
2,-1,-5:17.0
1,0,-5:17.0
0,-2,-4:17.0
1,-2,-4:17.0
1,-1,-4:17.0
2,-1,-4:17.0
1,0,-4:17.0
0,-2,-3:17.0
1,-2,-3:17.0
1,-1,-3:17.0
2,-1,-3:17.0
1,0,-3:17.0
0,-2,-2:17.0
1,-1,-2:17.0
1,0,-2:17.0
0,-2,-1:17.0
1,-1,-1:17.0
1,0,-1:17.0
0,-2,0:17.0
1,-1,0:17.0
1,0,0:17.0
0,-2,1:17.0
1,-1,1:17.0
1,0,1:18.12
0,-2,2:18.12
1,-1,2:17.0
1,-1,3:17.0
2,-1,3:18.12
0,-3,4:18.12
1,-3,4:18.12
2,-3,4:18.12
0,-2,4:18.12
1,-2,4:18.12
2,-2,4:18.12
3,-2,4:18.12
-2,-1,4:18.12
-1,-1,4:18.12
0,-1,4:18.12
1,-1,4:17.0
2,-1,4:17.0
3,-1,4:18.12
-1,0,4:18.12
0,0,4:18.12
1,0,4:18.12
2,0,4:18.12
3,0,4:18.12
4,0,4:18.12
0,1,4:18.12
1,1,4:18.12
1,-4,5:18.12
0,-3,5:18.12
1,-3,5:18.12
-2,-2,5:18.12
-1,-2,5:18.12
0,-2,5:18.12
1,-2,5:18.12
2,-2,5:18.12
-3,-1,5:18.12
-2,-1,5:18.12
-1,-1,5:18.12
0,-1,5:17.0
1,-1,5:17.0
2,-1,5:18.12
3,-1,5:18.12
-2,0,5:18.12
-1,0,5:18.12
0,0,5:18.12
1,0,5:17.0
2,0,5:18.12
3,0,5:18.12
-1,1,5:18.4
0,1,5:18.12
1,1,5:18.12
2,1,5:18.12
3,1,5:18.4
0,2,5:18.12
1,2,5:18.12
1,-3,6:18.4
0,-2,6:18.12
1,-2,6:18.12
-2,-1,6:18.4
-1,-1,6:18.12
0,-1,6:18.12
1,-1,6:18.12
2,-1,6:18.12
0,0,6:18.12
1,0,6:18.12
2,0,6:18.12
1,1,6:18.12
0,-1,7:18.12
1,-1,7:18.4
