[META]
version=2.0
spawnOnBlockType=8,9
spawnSunlight=True
spawnDarkness=True
spawnWater=False
spawnLava=False
underFill=False
randomRotation=True
dig=True
tree=False
branch=False
needsFoundation=True
rarity=100
collisionPercentage=10
spawnElevationMin=0
spawnElevationMax=100
spawnInBiome=All
[DATA]
0,-2,0:17.0
-2,0,0:17.0
0,0,0:17.0
2,0,0:17.0
0,2,0:17.0
1,-2,-2:17.0
-2,-1,-2:17.0
0,1,-2:17.0
2,1,-2:17.0
-1,3,-2:17.0
0,-3,-1:17.0
1,-2,-1:17.0
-2,-1,-1:17.0
0,-1,-1:17.0
-3,0,-1:17.0
-1,0,-1:17.0
0,0,-1:17.0
1,0,-1:17.0
3,0,-1:17.0
-2,1,-1:17.0
0,1,-1:17.0
2,1,-1:17.0
-1,2,-1:17.0
-1,3,-1:17.0
0,-1,1:17.0
-1,0,1:17.0
0,0,1:17.0
1,0,1:17.0
0,1,1:17.0
0,0,2:17.0
0,0,3:17.0
-2,2,3:106.4
-3,1,3:106.4
3,-1,3:106.2
-2,-1,3:106.8
2,-2,3:106.1
1,-3,3:106.1
-1,-1,4:18
0,0,4:17.0
1,2,4:106.2
-2,2,4:106.4
-3,1,4:106.4
3,-1,4:106.2
-2,-1,4:106.8
2,-2,4:106.1
1,-3,4:106.1
0,-3,5:18
-1,-2,5:18
0,-2,5:18
1,-2,5:18
-2,-1,5:18
-1,-1,5:18
0,-1,5:17.0
1,-1,5:18
2,-1,5:18
-3,0,5:18
-2,0,5:18
-1,0,5:17.0
0,0,5:17.0
1,0,5:17.0
2,0,5:18
3,0,5:18
-2,1,5:18
-1,1,5:18
0,1,5:17.0
1,1,5:18
2,1,5:18
-1,2,5:18
0,2,5:18
1,2,5:106.2
-2,2,5:106.4
-3,1,5:106.4
3,-1,5:106.2
2,-2,5:106.1
1,-3,5:106.1
0,-1,6:18
-1,0,6:18
0,0,6:17.0
1,0,6:18
0,1,6:18
1,-1,6:40
0,0,7:18
