[META]
version=2.0
spawnOnBlockType=2
spawnSunlight=True
spawnDarkness=True
spawnWater=False
spawnLava=False
underFill=False
randomRotation=True
dig=False
tree=False
branch=False
needsFoundation=True
rarity=300
collisionPercentage=70
spawnElevationMin=0
spawnElevationMax=93
spawnInBiome=All
[DATA]
0,0,0:17.0
-2,-1,0:31.1
1,-2,0:31.2
0,1,0:17.0
0,-1,0:17.0
-1,0,0:17.0
1,0,0:17.0
1,2,0:31.1
-2,0,0:17.0
0,-2,0:17.0
-1,-1,0:17.0
2,0,0:17.0
0,2,0:17.0
1,1,0:17.0
-1,1,0:17.0
1,-1,0:17.0
-2,2,0:31.1
0,-3,0:31.1
2,-1,0:31.2
-1,2,0:31.1
-2,1,0:31.2
2,1,0:31.1
-1,-2,0:31.1
-7,1,0:17.0
5,-7,0:17.0
7,1,0:17.0
-7,0,0:18.1
-6,1,0:18.1
-8,1,0:18.1
-7,2,0:18.1
-7,3,0:18.1
-6,7,0:18.0
-5,6,0:18.0
-5,7,0:18.0
-4,7,0:18.0
-3,7,0:18.0
-7,7,0:18.0
-6,8,0:18.0
3,7,0:18.2
2,7,0:18.2
1,7,0:18.2
1,8,0:18.2
4,7,0:18.2
4,6,0:18.2
5,6,0:18.2
2,6,0:18.2
6,1,0:18.0
5,2,0:18.0
6,2,0:18.0
5,3,0:18.0
7,0,0:18.0
7,-1,0:18.0
6,-1,0:18.0
6,-2,0:18.0
7,2,0:18.0
7,3,0:18.0
7,4,0:18.0
7,5,0:18.0
8,1,0:18.0
8,0,0:18.0
8,2,0:18.0
6,-7,0:18.2
7,-7,0:18.2
7,-6,0:18.2
8,-6,0:18.2
5,-8,0:18.2
4,-8,0:18.2
3,-8,0:18.2
3,-7,0:18.2
2,-8,0:18.2
4,-7,0:18.2
5,-6,0:18.2
6,-6,0:18.2
6,-5,0:18.2
7,-5,0:18.2
-5,-6,0:18.0
-4,-6,0:18.0
-4,-7,0:18.0
-3,-7,0:18.0
-6,-6,0:18.0
-6,-5,0:18.0
-7,-5,0:18.0
-3,-5,0:18.0
-4,-5,0:18.0
-7,-1,0:18.1
-5,1,0:18.1
3,6,0:106.8
5,4,0:106.2
3,-6,0:106.2
0,0,12:17.0
-1,0,12:17.0
0,-1,12:17.0
1,0,12:17.0
1,-1,12:17.0
0,1,12:17.0
3,1,12:17.0
3,0,12:18.0
4,1,12:18.0
3,2,12:18.0
1,1,12:106.4
4,2,12:18.0
4,0,12:18.0
5,1,12:18.0
3,3,12:18.0
2,2,12:18.0
2,0,12:18.0
3,-1,12:18.0
2,-1,12:106.1
-3,0,12:106.4
3,-6,12:106.2
1,-4,12:106.2
-4,-4,12:106.8
5,4,12:106.2
-6,0,12:106.8
-3,4,12:106.8
0,0,11:17.0
-1,0,11:17.0
0,-1,11:17.0
1,-1,11:17.0
1,0,11:17.0
0,1,11:17.0
2,1,11:17.0
1,1,11:17.0
3,1,11:18.0
1,2,11:106.4
-3,0,11:106.4
2,-1,11:106.1
3,-6,11:106.2
1,-4,11:106.2
-4,-4,11:106.8
5,4,11:106.2
-6,0,11:106.8
-3,4,11:106.8
0,0,10:17.0
-1,0,10:17.0
0,-1,10:17.0
1,-1,10:17.0
1,0,10:17.0
0,1,10:17.0
-1,-1,10:106.1
1,2,10:106.4
-3,0,10:106.4
2,-1,10:106.1
3,-6,10:106.2
1,-4,10:106.2
-4,-4,10:106.8
5,4,10:106.2
-6,0,10:106.8
-3,4,10:106.8
0,0,9:17.0
-1,0,9:17.0
1,0,9:17.0
1,-1,9:17.0
0,-1,9:17.0
0,1,9:17.0
-1,-1,9:106.1
1,2,9:106.4
-3,0,9:106.4
2,-1,9:106.1
3,-6,9:106.2
1,-4,9:106.2
-4,-4,9:106.8
-6,0,9:106.8
-3,4,9:106.8
5,4,9:106.2
0,0,8:17.0
-1,0,8:17.0
0,-1,8:17.0
1,-1,8:17.0
1,0,8:17.0
0,1,8:17.0
-1,-1,8:106.1
1,2,8:106.4
-3,0,8:106.4
2,-1,8:106.1
1,-4,8:106.2
-4,-4,8:106.8
-6,0,8:106.8
-3,4,8:106.8
5,4,8:106.2
3,-6,8:106.2
0,0,7:17.0
-1,0,7:17.0
0,-1,7:17.0
1,-1,7:17.0
1,0,7:17.0
0,1,7:17.0
-1,-1,7:106.1
-3,0,7:106.4
2,-1,7:106.1
-4,-4,7:106.8
-6,0,7:106.8
-3,4,7:106.8
5,4,7:106.2
3,-6,7:106.2
1,-4,7:106.2
0,0,6:17.0
-1,0,6:17.0
0,-1,6:17.0
1,-1,6:17.0
1,0,6:17.0
0,1,6:17.0
-1,-1,6:106.1
0,-2,6:106.1
-3,0,6:106.4
2,-1,6:106.1
1,-4,6:106.2
-4,-4,6:106.8
-3,4,6:106.8
5,4,6:106.2
3,-6,6:106.2
0,0,5:17.0
-1,0,5:17.0
0,-1,5:17.0
1,-1,5:17.0
1,0,5:17.0
0,1,5:17.0
-1,-1,5:106.1
0,-2,5:106.1
-3,0,5:106.4
2,-1,5:106.1
1,-4,5:106.2
-4,-4,5:106.8
-3,4,5:106.8
5,4,5:106.2
3,-6,5:106.2
0,0,4:17.0
-1,0,4:17.0
1,0,4:17.0
0,-1,4:17.0
0,1,4:17.0
1,-1,4:17.0
-1,-1,4:106.1
0,-2,4:106.1
2,-1,4:106.1
1,-4,4:106.2
-4,-4,4:106.8
-3,4,4:106.8
5,4,4:106.2
3,-6,4:106.2
0,0,3:17.0
-1,0,3:17.0
0,-1,3:17.0
1,0,3:17.0
0,1,3:17.0
-1,-1,3:17.0
1,-1,3:17.0
1,1,3:17.0
0,-2,3:106.1
1,-4,3:106.2
-4,-4,3:106.8
-3,4,3:106.8
5,4,3:106.2
3,-6,3:106.2
0,0,2:17.0
-1,0,2:17.0
0,-1,2:17.0
1,0,2:17.0
0,1,2:17.0
0,-2,2:17.0
2,0,2:17.0
0,2,2:17.0
-2,0,2:17.0
1,-1,2:17.0
-1,-1,2:17.0
-1,1,2:17.0
1,1,2:17.0
-5,7,2:18.0
4,-7,2:18.2
4,-6,2:18.2
5,-6,2:18.2
7,1,2:18.0
7,2,2:18.0
8,1,2:18.0
4,7,2:18.2
3,7,2:18.2
-7,1,2:18.1
-7,0,2:18.1
-6,0,2:18.1
3,6,2:106.8
5,4,2:106.2
-3,4,2:106.8
-4,-4,2:106.8
3,-6,2:106.2
5,-5,2:30
0,0,1:17.0
-1,0,1:17.0
0,-1,1:17.0
1,0,1:17.0
0,1,1:17.0
-2,0,1:17.0
-1,-1,1:17.0
0,-2,1:17.0
1,-1,1:17.0
2,0,1:17.0
1,1,1:17.0
0,2,1:17.0
-1,1,1:17.0
-7,1,1:18.1
-7,0,1:18.1
-7,2,1:18.1
-6,0,1:18.1
-8,2,1:18.1
-5,7,1:18.0
-6,7,1:18.0
-4,7,1:18.0
3,-7,1:18.2
4,-7,1:18.2
4,-6,1:18.2
5,-7,1:18.2
5,-6,1:18.2
6,-6,1:18.2
7,-6,1:18.2
4,-8,1:18.2
7,0,1:18.0
7,1,1:18.0
6,1,1:18.0
6,2,1:18.0
7,2,1:18.0
8,1,1:18.0
7,3,1:18.0
7,-1,1:18.0
3,7,1:18.2
2,7,1:18.2
4,7,1:18.2
4,6,1:18.2
1,7,1:18.2
-5,-6,1:18.0
-4,-6,1:18.0
-4,-7,1:18.0
-4,-5,1:18.0
-6,-6,1:18.0
3,6,1:106.8
5,4,1:106.2
-3,4,1:106.8
-4,-4,1:106.8
3,-6,1:106.2
-6,2,1:30
6,5,1:30
5,6,1:18.2
7,5,1:18.0
2,-7,1:30
0,0,13:17.0
-1,0,13:17.0
0,-1,13:17.0
1,-1,13:17.0
1,0,13:17.0
0,1,13:17.0
3,1,13:18.0
0,-3,13:18.0
2,0,13:18.0
3,0,13:18.0
4,1,13:18.0
3,2,13:18.0
2,2,13:18.0
2,-1,13:106.1
2,1,13:18.0
-3,0,13:106.4
3,-6,13:106.2
1,-4,13:106.2
-4,-4,13:106.8
5,4,13:106.2
-6,0,13:106.8
-3,4,13:106.8
0,0,18:17.0
-1,0,18:17.0
0,-1,18:17.0
1,0,18:17.0
0,1,18:17.0
0,2,18:17.0
1,3,18:17.0
0,3,18:18.0
1,4,18:18.0
1,2,18:18.0
2,3,18:18.0
-1,2,18:18.0
1,1,18:106.4
-3,0,18:106.4
3,-6,18:106.2
-4,-4,18:106.8
3,1,18:106.4
5,4,18:106.2
-6,0,18:106.8
-3,4,18:106.8
0,0,19:17.0
-1,0,19:17.0
0,-1,19:17.0
0,1,19:17.0
1,0,19:17.0
1,3,19:18.0
-3,0,19:106.4
3,-6,19:106.2
-4,-4,19:106.8
3,1,19:106.4
5,4,19:106.2
-6,0,19:106.8
-3,4,19:106.8
-1,-4,19:106.1
0,0,20:17.0
-1,0,20:17.0
0,-1,20:17.0
1,0,20:17.0
0,1,20:17.0
-3,-1,20:18.0
-2,0,20:18.0
-2,-1,20:18.0
-3,0,20:106.4
-3,-2,20:18.0
-4,-1,20:18.0
3,-6,20:106.2
-4,-4,20:106.8
-1,8,20:106.4
3,1,20:106.4
5,4,20:106.2
-6,0,20:106.8
-3,4,20:106.8
-1,-4,20:106.1
0,0,21:17.0
-1,0,21:17.0
0,-1,21:17.0
1,0,21:17.0
0,1,21:17.0
-2,0,21:17.0
-3,-1,21:17.0
-3,-2,21:18.0
-4,-1,21:18.0
-2,-1,21:18.0
-3,0,21:106.4
-4,0,21:18.0
-3,1,21:18.0
3,1,21:106.4
-5,-1,21:18.0
-4,-2,21:18.0
-4,-3,21:18.0
-3,-3,21:18.0
-4,1,21:18.0
-3,2,21:18.0
-2,-2,21:18.0
-1,-1,21:18.0
-2,1,21:18.0
3,-6,21:106.2
-4,-4,21:106.8
-1,8,21:106.4
5,4,21:106.2
-6,0,21:106.8
-3,4,21:106.8
-1,-4,21:106.1
0,0,22:17.0
-1,0,22:17.0
0,-1,22:17.0
1,0,22:17.0
0,1,22:17.0
-3,-1,22:18.0
3,1,22:106.4
-4,-1,22:18.0
-3,-2,22:18.0
-4,-2,22:18.0
-3,0,22:18.0
-4,0,22:18.0
-2,-1,22:18.0
3,-6,22:106.2
-4,-4,22:106.8
-1,8,22:106.4
5,4,22:106.2
-6,0,22:106.8
-3,4,22:106.8
-1,-4,22:106.1
0,0,23:17.0
-1,0,23:17.0
0,-1,23:17.0
1,0,23:17.0
0,1,23:17.0
3,1,23:106.4
3,-6,23:106.2
-4,-4,23:106.8
-1,8,23:106.4
5,4,23:106.2
-6,0,23:106.8
-3,4,23:106.8
-1,-4,23:106.1
0,0,24:17.0
-1,0,24:17.0
0,-1,24:17.0
1,0,24:17.0
0,1,24:17.0
3,1,24:106.4
3,-6,24:106.2
-4,-4,24:106.8
-1,8,24:106.4
5,4,24:106.2
-6,0,24:106.8
-3,4,24:106.8
-1,-4,24:106.1
0,0,14:17.0
-1,0,14:17.0
0,-1,14:17.0
1,-1,14:17.0
1,0,14:17.0
0,1,14:17.0
0,-2,14:17.0
-1,-3,14:17.0
0,-4,14:18.0
0,-3,14:18.0
1,-3,14:18.0
1,1,14:106.4
2,1,14:18.0
3,1,14:18.0
2,0,14:18.0
-1,-4,14:18.0
0,-5,14:18.0
1,-5,14:18.0
1,-4,14:106.2
-3,0,14:106.4
2,-1,14:106.1
3,-6,14:106.2
-4,-4,14:106.8
5,4,14:106.2
-6,0,14:106.8
-3,4,14:106.8
0,0,15:17.0
-1,0,15:17.0
0,-1,15:17.0
1,-1,15:17.0
1,0,15:17.0
0,1,15:17.0
0,-4,15:17.0
-1,-4,15:18.0
0,-5,15:18.0
0,-3,15:18.0
1,-4,15:106.2
1,1,15:106.4
-2,-4,15:18.0
-1,-5,15:18.0
0,-6,15:18.0
1,-5,15:18.0
1,-3,15:18.0
1,-6,15:18.0
2,-5,15:18.0
2,-4,15:18.0
-1,-3,15:18.0
-2,-3,15:18.0
-2,-5,15:18.0
-1,-6,15:18.0
-3,0,15:106.4
3,-6,15:106.2
-4,-4,15:106.8
3,1,15:106.4
5,4,15:106.2
-6,0,15:106.8
-3,4,15:106.8
0,0,16:17.0
-1,0,16:17.0
0,-1,16:17.0
1,0,16:17.0
0,1,16:17.0
0,-4,16:18.0
-1,-3,16:18.0
0,-2,16:18.0
1,-3,16:18.0
1,1,16:106.4
-1,-4,16:18.0
-1,-5,16:18.0
0,-5,16:18.0
1,-5,16:18.0
1,-4,16:106.2
0,-6,16:18.0
0,-3,16:18.0
-3,0,16:106.4
3,-6,16:106.2
-4,-4,16:106.8
3,1,16:106.4
5,4,16:106.2
-6,0,16:106.8
-3,4,16:106.8
0,0,17:17.0
-1,0,17:17.0
0,-1,17:17.0
1,0,17:17.0
0,1,17:17.0
1,3,17:18.0
0,2,17:18.0
1,1,17:106.4
0,-4,17:18.0
0,-3,17:18.0
-3,0,17:106.4
3,-6,17:106.2
-4,-4,17:106.8
3,1,17:106.4
5,4,17:106.2
-6,0,17:106.8
-3,4,17:106.8
0,0,25:17.0
-3,-4,25:85
-1,0,25:17.0
0,-1,25:17.0
0,1,25:17.0
1,0,25:17.0
3,1,25:106.4
-1,-2,25:106.2
3,-6,25:106.2
-4,-4,25:106.8
-1,8,25:106.4
5,4,25:106.2
-6,0,25:106.8
-3,4,25:106.8
-1,-4,25:106.1
0,0,26:17.0
-3,-4,26:85
-1,0,26:17.0
0,-1,26:17.0
1,0,26:17.0
0,1,26:17.0
3,1,26:106.4
-1,-2,26:106.2
5,4,26:106.2
3,-6,26:106.2
-4,-4,26:106.8
-1,8,26:106.4
-6,0,26:106.8
-3,4,26:106.8
-1,-4,26:106.1
-2,0,-1:2
-1,0,-1:17.0
0,0,-1:17.0
1,0,-1:17.0
2,0,-1:2
0,-2,-1:2
0,-1,-1:17.0
0,1,-1:17.0
0,2,-1:2
-1,1,-1:2
-1,-1,-1:2
1,-1,-1:2
1,1,-1:2
-2,1,-1:2
-2,2,-1:2
-1,2,-1:2
1,2,-1:2
2,1,-1:2
2,-1,-1:2
1,-2,-1:2
0,-3,-1:2
-1,-2,-1:2
-2,-1,-1:2
-3,0,-1:17.0
-2,-2,-1:17.0
1,-3,-1:17.0
3,-1,-1:17.0
2,2,-1:17.0
-1,3,-1:17.0
-5,-6,-1:17.0
5,-7,-1:17.0
7,1,-1:17.0
-7,1,-1:17.0
-5,7,-1:17.0
3,7,-1:17.0
-7,0,-1:2
-6,1,-1:2
-5,6,-1:2
-4,7,-1:2
2,7,-1:2
3,6,-1:2
6,1,-1:2
7,0,-1:2
4,-7,-1:2
5,-6,-1:2
-4,-6,-1:2
-5,-5,-1:2
-5,1,-1:2
-5,0,-1:2
-4,0,-1:2
-4,-1,-1:2
-4,-2,-1:2
-3,-2,-1:2
-4,-4,-1:2
-4,-5,-1:2
-3,-5,-1:2
-3,-4,-1:2
-2,-4,-1:2
-2,-3,-1:2
-1,-4,-1:2
-1,-3,-1:2
-3,-3,-1:2
1,-4,-1:2
2,-4,-1:2
3,-4,-1:2
3,-5,-1:2
4,-6,-1:2
4,-5,-1:2
3,-3,-1:2
2,-3,-1:2
2,-2,-1:2
3,-2,-1:2
4,-2,-1:2
4,-1,-1:2
5,-1,-1:2
5,0,-1:2
6,0,-1:2
5,1,-1:2
4,1,-1:2
4,2,-1:2
3,3,-1:2
3,2,-1:2
3,1,-1:2
4,0,-1:2
3,0,-1:2
2,5,-1:2
2,6,-1:2
2,4,-1:2
2,3,-1:2
1,3,-1:2
1,4,-1:2
1,5,-1:2
0,4,-1:2
0,3,-1:2
-1,5,-1:2
-1,4,-1:2
-3,6,-1:2
-2,6,-1:2
-2,5,-1:2
-4,6,-1:2
-4,5,-1:2
-4,4,-1:2
-3,4,-1:2
-3,3,-1:2
-3,2,-1:2
-4,2,-1:2
-4,1,-1:2
-3,1,-1:2
-5,2,-1:2
0,0,27:17.0
0,1,27:17.0
-1,4,27:85
-3,-4,27:85
-1,0,27:17.0
0,-1,27:17.0
1,0,27:17.0
3,1,27:106.4
-1,-2,27:106.2
5,4,27:106.2
3,-6,27:106.2
-4,-4,27:106.8
-1,8,27:106.4
-6,0,27:106.8
-3,4,27:106.8
-1,-4,27:106.1
0,0,28:17.0
0,-1,28:17.0
0,2,28:17.0
-1,0,28:17.0
1,0,28:17.0
-1,4,28:85
4,-4,28:85
-3,-4,28:85
3,1,28:106.4
-3,2,28:106.4
-1,-4,28:106.1
-1,-2,28:106.2
5,4,28:106.2
-1,8,28:106.4
3,-6,28:106.2
-4,-4,28:106.8
-6,0,28:106.8
-3,4,28:106.8
0,-2,29:17.0
0,2,29:17.0
0,0,29:17.0
-2,1,29:17.0
2,0,29:17.0
-1,4,29:85
4,-4,29:85
-3,-4,29:85
3,1,29:106.4
-3,2,29:106.4
-1,-4,29:106.1
-1,-2,29:106.2
5,4,29:106.2
-1,8,29:106.4
3,-6,29:106.2
-4,-4,29:106.8
-6,0,29:106.8
-3,4,29:106.8
0,0,30:17.0
-2,1,30:17.0
1,1,30:17.0
2,2,30:17.0
0,-3,30:17.0
-1,3,30:17.0
-1,4,30:85
4,-4,30:85
-3,-4,30:85
3,1,30:106.4
-3,2,30:106.4
-1,-4,30:106.1
-1,-2,30:106.2
5,4,30:106.2
-1,8,30:106.4
3,-6,30:106.2
-4,-4,30:106.8
-6,0,30:106.8
-3,4,30:106.8
0,0,31:17.0
-4,2,31:17.0
0,4,31:17.0
2,3,31:17.0
3,2,31:17.0
4,1,31:17.0
-1,-3,31:17.0
1,-3,31:17.0
-2,-2,31:17.0
-2,-4,31:17.0
2,0,31:17.0
-1,4,31:85
4,-4,31:85
-3,-4,31:85
3,1,31:106.4
-3,2,31:106.4
-1,-4,31:106.1
-3,1,31:17.0
-1,-2,31:106.2
5,4,31:106.2
-1,8,31:106.4
3,-6,31:106.2
-4,-4,31:106.8
-6,0,31:106.8
-3,4,31:106.8
0,0,32:17.0
-2,-1,32:17.0
-4,0,32:17.0
-3,-3,32:17.0
-3,-4,32:17.0
-3,3,32:17.0
-1,3,32:17.0
-1,4,32:17.0
3,3,32:17.0
3,0,32:17.0
4,0,32:17.0
2,-2,32:17.0
3,-2,32:17.0
3,-3,32:17.0
1,-4,32:17.0
0,4,32:18.0
5,0,32:18.0
-5,0,32:18.0
0,-5,32:18.0
1,-5,32:18.0
-2,-5,32:18.0
-2,-4,32:18.0
-3,-5,32:18.0
-4,-4,32:106.8
-4,-3,32:18.0
-4,-2,32:18.0
-4,-1,32:18.0
-5,-1,32:18.0
-5,1,32:18.0
-4,3,32:18.0
-4,2,32:18.0
-4,1,32:18.0
-3,4,32:106.8
-2,4,32:18.0
-1,5,32:18.0
3,4,32:17.0
4,2,32:18.0
4,1,32:18.0
5,2,32:18.0
5,1,32:18.0
2,-4,32:18.0
2,-3,32:18.0
3,-4,32:18.0
4,-3,32:18.0
4,-2,32:18.0
4,-1,32:18.0
3,-1,32:18.0
5,-1,32:18.0
4,3,32:18.0
0,5,32:18.0
2,4,32:18.0
1,5,32:18.0
-5,2,32:18.0
-1,-5,32:18.0
0,-6,32:18.0
-1,-6,32:18.0
-2,-6,32:18.0
-5,-3,32:18.0
-5,-2,32:18.0
-5,3,32:18.0
-4,4,32:18.0
-3,5,32:18.0
-2,5,32:18.0
2,5,32:18.0
3,5,32:18.0
4,4,32:18.0
5,-2,32:18.0
3,-5,32:18.0
2,-5,32:18.0
1,-6,32:18.0
4,-4,32:85
1,4,32:18.0
3,1,32:106.4
5,4,32:106.2
-1,8,32:106.4
3,-6,32:106.2
-6,0,32:106.8
0,0,33:18.0
-1,0,33:18.0
-2,0,33:18.0
-3,0,33:17.0
-4,0,33:18.0
-5,0,33:17.0
1,0,33:18.0
2,0,33:17.0
3,0,33:18.0
4,0,33:18.0
5,0,33:17.0
0,1,33:18.0
0,2,33:18.0
0,3,33:18.0
0,4,33:18.0
0,5,33:17.0
0,-1,33:18.0
0,-2,33:18.0
0,-3,33:18.0
0,-4,33:18.0
0,-5,33:18.0
1,-5,33:17.0
-1,-5,33:17.0
-2,-5,33:18.0
-5,-1,33:18.0
-5,2,33:18.0
-5,1,33:18.0
-1,5,33:18.0
1,5,33:18.0
5,-1,33:18.0
5,1,33:18.0
5,2,33:18.0
4,3,33:18.0
3,4,33:17.0
2,4,33:18.0
-2,4,33:18.0
-3,3,33:18.0
-4,3,33:17.0
-4,-2,33:18.0
-4,-3,33:18.0
-3,-4,33:18.0
2,-4,33:18.0
3,-4,33:17.0
4,-3,33:18.0
4,-2,33:18.0
-3,-2,33:18.0
-3,-3,33:18.0
-2,-3,33:18.0
-2,-4,33:17.0
-1,-4,33:18.0
-1,-3,33:18.0
-1,-2,33:18.0
-1,-1,33:18.0
-2,-1,33:18.0
-3,-1,33:18.0
-4,-1,33:17.0
-2,-2,33:18.0
-4,1,33:18.0
-3,1,33:18.0
-2,1,33:18.0
-1,1,33:18.0
-1,2,33:17.0
-2,2,33:18.0
-3,2,33:18.0
-4,2,33:18.0
-2,3,33:18.0
-1,3,33:18.0
-1,4,33:18.0
1,4,33:18.0
2,3,33:18.0
1,3,33:18.0
1,2,33:18.0
1,1,33:18.0
2,1,33:18.0
3,1,33:18.0
4,1,33:18.0
4,2,33:18.0
3,2,33:18.0
3,3,33:18.0
2,2,33:18.0
3,-1,33:18.0
4,-1,33:18.0
2,-1,33:18.0
1,-1,33:18.0
1,-2,33:17.0
2,-3,33:18.0
2,-2,33:18.0
3,-2,33:18.0
3,-3,33:18.0
1,-3,33:18.0
1,-4,33:18.0
-5,-2,33:18.0
-5,-3,33:18.0
-4,-4,33:18.0
-3,-5,33:18.0
-3,-6,33:18.0
-2,-6,33:18.0
-1,-6,33:18.0
0,-7,33:18.0
-1,-7,33:18.0
0,-6,33:18.0
1,-6,33:18.0
2,-6,33:17.0
2,-5,33:18.0
3,-5,33:18.0
4,-5,33:18.0
5,-4,33:18.0
4,-4,33:17.0
5,-3,33:18.0
5,-2,33:18.0
6,-1,33:18.0
6,0,33:17.0
6,1,33:18.0
5,3,33:18.0
5,4,33:106.2
4,4,33:18.0
2,5,33:18.0
3,5,33:17.0
1,6,33:18.0
0,6,33:18.0
-1,6,33:17.0
-2,5,33:18.0
-3,5,33:18.0
-3,4,33:106.8
-4,4,33:18.0
-5,3,33:18.0
-6,1,33:18.0
-6,0,33:106.8
-6,-1,33:18.0
-4,-5,33:18.0
7,0,33:18.0
8,0,33:18.0
7,1,33:18.0
7,-1,33:18.0
6,-2,33:18.0
6,-3,33:18.0
6,2,33:18.0
6,3,33:18.0
4,5,33:18.0
5,5,33:18.0
3,6,33:18.0
2,6,33:18.0
1,7,33:18.0
0,7,33:18.0
-1,7,33:18.0
-2,6,33:18.0
8,-1,33:18.0
7,-2,33:18.0
3,-6,33:106.2
4,-6,33:18.0
5,-5,33:18.0
6,-4,33:18.0
3,-7,33:18.0
2,-7,33:18.0
1,-7,33:18.0
1,-8,33:18.0
0,-8,33:18.0
2,-8,33:18.0
-2,-7,33:18.0
-3,-7,33:18.0
-4,-6,33:18.0
-5,-4,33:18.0
-1,-8,33:18.0
-6,-2,33:18.0
-7,0,33:18.0
-7,-1,33:18.0
-6,-3,33:18.0
-6,2,33:18.0
-7,1,33:18.0
-5,4,33:18.0
-6,3,33:18.0
-4,5,33:18.0
-3,6,33:18.0
-2,7,33:18.0
7,2,33:18.0
8,1,33:18.0
6,4,33:18.0
7,3,33:18.0
2,7,33:18.0
3,7,33:18.0
4,6,33:18.0
5,-6,33:18.0
6,-5,33:18.0
-1,8,33:106.4
-3,0,34:18.0
-2,0,34:18.0
-1,0,34:18.0
0,0,34:18.0
1,0,34:18.0
2,0,34:18.0
0,-3,34:18.0
0,-2,34:18.0
0,-1,34:18.0
0,1,34:18.0
0,2,34:18.0
0,3,34:18.0
1,2,34:18.0
1,1,34:18.0
1,-2,34:18.0
1,-1,34:18.0
2,-1,34:18.0
2,1,34:18.0
-3,1,34:18.0
-2,-1,34:18.0
-2,1,34:18.0
-2,2,34:18.0
-1,3,34:18.0
-1,2,34:18.0
-1,1,34:18.0
-1,-1,34:18.0
-1,-2,34:18.0
-3,-1,34:18.0
-3,-2,34:18.0
-2,-2,34:18.0
-1,-3,34:18.0
0,-4,34:18.0
1,-4,34:18.0
1,-3,34:18.0
2,-3,34:18.0
2,-2,34:18.0
3,-1,34:18.0
3,0,34:18.0
3,-2,34:18.0
3,1,34:18.0
2,2,34:18.0
-2,-3,34:18.0
-1,-4,34:18.0
0,-5,34:18.0
1,3,34:18.0
3,-3,34:18.0
2,-4,34:18.0
1,-5,34:18.0
-2,-4,34:18.0
-1,-5,34:18.0
-3,-3,34:18.0
-4,0,34:18.0
-4,-1,34:18.0
4,-1,34:18.0
4,-2,34:18.0
-5,0,34:18.0
-4,-2,34:18.0
-5,-1,34:18.0
-5,-2,34:18.0
-3,-4,34:18.0
-4,-3,34:18.0
-2,-5,34:18.0
0,-6,34:18.0
1,-6,34:18.0
2,-6,34:18.0
2,-5,34:18.0
3,-4,34:18.0
4,-4,34:18.0
3,-5,34:18.0
4,-3,34:18.0
6,0,34:18.0
5,0,34:18.0
4,0,34:18.0
5,-1,34:18.0
5,-2,34:18.0
5,1,34:18.0
4,1,34:18.0
4,2,34:18.0
3,2,34:18.0
3,3,34:18.0
3,4,34:18.0
3,5,34:18.0
2,3,34:18.0
2,4,34:18.0
2,5,34:18.0
1,4,34:18.0
0,5,34:18.0
-1,5,34:18.0
-1,6,34:18.0
-1,4,34:18.0
0,4,34:18.0
-2,5,34:18.0
-2,4,34:18.0
-3,4,34:18.0
-3,3,34:18.0
-4,3,34:18.0
-2,3,34:18.0
-3,2,34:18.0
-4,1,34:18.0
-4,2,34:18.0
-5,1,34:18.0
4,3,34:18.0
5,2,34:18.0
6,1,34:18.0
4,4,34:18.0
1,5,34:18.0
0,6,34:18.0
1,6,34:18.0
5,4,34:106.2
-1,7,34:106.4
-3,1,35:18.0
-3,0,35:18.0
-3,-1,35:18.0
-3,-2,35:18.0
-2,-3,35:18.0
-1,-3,35:18.0
0,-3,35:18.0
0,-4,35:18.0
1,-4,35:18.0
2,-4,35:18.0
2,-3,35:18.0
3,-3,35:18.0
3,-2,35:18.0
4,-2,35:18.0
4,-1,35:18.0
4,0,35:18.0
4,1,35:18.0
3,1,35:18.0
3,2,35:18.0
3,3,35:18.0
2,4,35:18.0
1,4,35:18.0
0,4,35:18.0
-1,4,35:18.0
-2,3,35:18.0
-2,2,35:18.0
-1,2,35:18.0
-1,3,35:18.0
0,5,35:18.0
1,5,35:18.0
0,3,35:18.0
0,2,35:18.0
-1,1,35:18.0
-2,1,35:18.0
-2,0,35:18.0
-2,-1,35:18.0
-2,-2,35:18.0
-1,-2,35:18.0
0,-2,35:18.0
1,-3,35:18.0
1,-2,35:18.0
1,-1,35:18.0
0,-1,35:18.0
0,0,35:18.0
-1,0,35:18.0
2,-1,35:18.0
-1,-1,35:18.0
2,-2,35:18.0
3,-1,35:18.0
3,0,35:18.0
2,0,35:18.0
2,1,35:18.0
1,1,35:18.0
0,1,35:18.0
1,0,35:18.0
2,2,35:18.0
1,2,35:18.0
1,3,35:18.0
2,3,35:18.0
-4,-5,-2:17.0
-7,1,-2:3
-5,7,-2:3
3,7,-2:3
7,1,-2:3
5,-7,-2:3
-4,-6,-2:3
-5,-5,-2:3
-6,1,-2:17.0
-6,0,-2:3
-6,2,-2:3
-5,6,-2:3
-4,6,-2:17.0
3,6,-2:3
2,6,-2:17.0
6,1,-2:17.0
6,0,-2:3
5,1,-2:3
5,-6,-2:3
4,-6,-2:17.0
4,-5,-2:17.0
3,-5,-2:3
2,5,-2:3
2,4,-2:3
2,3,-2:3
2,2,-2:3
3,2,-2:3
3,1,-2:3
4,1,-2:3
4,0,-2:17.0
4,-1,-2:3
3,-1,-2:3
3,-2,-2:17.0
2,-2,-2:3
2,-3,-2:3
2,-4,-2:17.0
3,-4,-2:3
1,-4,-2:3
1,-3,-2:17.0
0,-3,-2:3
-1,-3,-2:3
-2,-4,-2:17.0
-3,-4,-2:3
-3,-5,-2:3
-5,1,-2:3
-4,1,-2:3
-4,0,-2:3
-3,0,-2:3
-3,-1,-2:17.0
-3,-2,-2:3
-2,-2,-2:3
-2,-3,-2:3
-4,5,-2:3
-3,5,-2:3
-3,4,-2:3
-3,3,-2:3
-3,2,-2:3
-3,1,-2:17.0
-3,6,-2:3
-2,4,-2:17.0
-1,4,-2:3
0,4,-2:3
0,3,-2:3
1,3,-2:3
-1,2,-2:17.0
-2,2,-2:3
-2,1,-2:3
-1,1,-2:3
0,1,-2:3
0,2,-2:3
-1,3,-2:3
-2,3,-2:3
1,1,-2:17.0
1,2,-2:3
-1,0,-2:3
0,0,-2:3
0,-1,-2:3
1,-1,-2:3
2,-1,-2:3
2,0,-2:3
1,0,-2:3
-1,-1,-2:17.0
0,-2,-2:3
-1,-2,-2:3
-2,0,-2:3
1,-2,-2:3
-2,-1,-2:3
2,1,-2:3
3,0,-2:3
1,4,-2:17.0
-2,5,-2:3
1,5,-2:3
3,3,-2:17.0
-2,-4,-3:3
-1,-3,-3:3
4,-5,-3:3
6,1,-3:3
2,6,-3:3
1,5,-3:3
-4,6,-3:3
-3,5,-3:3
-6,1,-3:3
-3,1,-3:3
-2,1,-3:3
-2,-2,-3:3
1,-2,-3:3
3,-1,-3:3
0,1,-3:3
0,-1,-3:3
2,0,-3:3
2,1,-3:3
0,4,-3:3
-1,0,-3:3
1,3,-3:3
2,-3,-3:3
4,1,-3:3
3,3,-3:3
3,2,-3:3
-1,2,-3:3
-1,3,-3:3
-2,4,-3:3
-3,3,-3:3
-3,-1,-3:3
