[META]
version=2.0
spawnOnBlockType=2
spawnSunlight=True
spawnDarkness=True
spawnWater=False
spawnLava=False
underFill=False
randomRotation=True
dig=False
tree=False
branch=False
needsFoundation=True
rarity=300
collisionPercentage=70
spawnElevationMin=0
spawnElevationMax=85
spawnInBiome=All
[DATA]
0,0,0:17.0
-2,-1,0:17.0
1,-2,0:17.0
0,1,0:17.0
0,-1,0:17.0
-1,0,0:17.0
1,0,0:17.0
1,2,0:17.0
-2,0,0:17.0
0,-2,0:17.0
-1,-1,0:17.0
2,0,0:17.0
0,2,0:17.0
1,1,0:17.0
-1,1,0:17.0
1,-1,0:17.0
-2,2,0:31.1
0,-3,0:17.0
2,-1,0:17.0
-1,2,0:17.0
-2,1,0:17.0
2,1,0:17.0
-1,-2,0:17.0
-3,0,0:17.0
3,0,0:17.0
0,3,0:17.0
-2,-2,0:31.1
2,-2,0:31.1
2,2,0:31.2
-7,4,0:17.0
6,6,0:17.0
-2,7,0:18.0
-3,7,0:18.0
-3,6,0:18.0
-4,6,0:18.0
0,7,0:18.0
-1,7,0:18.0
1,7,0:18.0
2,6,0:18.0
2,7,0:18.0
5,6,0:18.0
5,7,0:18.0
5,8,0:18.0
4,8,0:18.0
6,7,0:18.0
7,7,0:18.0
7,6,0:18.0
8,6,0:18.0
6,5,0:18.0
6,4,0:18.0
5,4,0:18.0
5,5,0:18.0
6,3,0:18.0
7,-4,0:18.0
6,-3,0:18.0
7,-3,0:18.0
6,-2,0:18.0
6,-4,0:18.0
5,-4,0:18.0
4,-4,0:18.0
7,-5,0:18.0
7,-6,0:18.0
7,-7,0:18.0
6,-5,0:18.0
5,-5,0:18.0
5,-6,0:18.0
8,-4,0:18.0
9,-4,0:18.0
8,-3,0:18.0
8,-2,0:18.0
1,-8,0:18.0
0,-8,0:18.0
-1,-9,0:18.0
0,-9,0:18.0
2,-8,0:18.0
3,-8,0:18.0
4,-8,0:18.0
1,-7,0:18.0
2,-7,0:18.0
1,-6,0:18.0
0,-6,0:18.0
2,-9,0:18.0
-6,-5,0:18.0
-7,-5,0:18.0
-7,-4,0:18.0
-7,-3,0:18.0
-5,-5,0:18.0
-4,-4,0:18.0
-5,-4,0:18.0
-7,-6,0:18.0
-7,-7,0:18.0
-6,-7,0:18.0
-8,-5,0:18.0
-8,4,0:18.0
-9,4,0:18.0
-9,3,0:18.0
-9,2,0:18.0
-8,5,0:18.0
-8,6,0:18.0
-8,7,0:18.0
-7,3,0:18.0
-6,4,0:18.0
-7,5,0:18.0
-7,2,0:18.0
-7,1,0:18.0
-5,4,0:18.0
3,7,0:106.2
5,-8,0:106.1
-6,3,0:31.2
-6,-4,0:31.2
0,6,0:31.2
-1,6,0:31.2
1,-3,0:31.2
3,1,0:31.2
1,3,0:17.0
0,4,0:17.0
-1,3,0:17.0
0,0,12:17.0
-1,0,12:17.0
0,-1,12:17.0
1,0,12:17.0
1,1,12:17.0
0,1,12:17.0
-1,-1,12:17.0
0,2,12:17.0
-1,3,12:18.0
-2,3,12:18.0
-1,2,12:18.0
-2,4,12:18.0
-1,4,12:18.0
0,3,12:18.0
0,4,12:106.4
-4,1,12:106.8
2,-1,12:106.1
-1,-4,12:106.1
4,-1,12:106.2
-7,4,12:106.8
-1,-9,12:106.1
5,-8,12:106.1
4,2,12:106.2
-5,-4,12:106.8
7,2,12:106.8
2,7,12:106.4
0,0,11:17.0
-1,0,11:17.0
-1,-1,11:17.0
0,-1,11:17.0
1,0,11:17.0
0,1,11:17.0
1,1,11:17.0
0,4,11:106.4
-4,1,11:106.8
-1,-4,11:106.1
4,-1,11:106.2
-7,4,11:106.8
-1,-9,11:106.1
5,-8,11:106.1
4,2,11:106.2
-5,-4,11:106.8
7,2,11:106.8
2,7,11:106.4
0,0,10:17.0
-1,0,10:17.0
-1,-1,10:17.0
0,-1,10:17.0
1,0,10:17.0
1,1,10:17.0
0,1,10:17.0
0,4,10:106.4
-4,1,10:106.8
4,-1,10:106.2
-7,4,10:106.8
-1,-9,10:106.1
5,-8,10:106.1
4,2,10:106.2
-5,-4,10:106.8
7,2,10:106.8
2,7,10:106.4
0,0,9:17.0
-1,0,9:17.0
0,-1,9:17.0
1,0,9:17.0
1,1,9:17.0
1,-1,9:17.0
0,1,9:17.0
-1,-1,9:17.0
0,4,9:106.4
4,-1,9:106.2
-7,4,9:106.8
-4,1,9:106.8
-1,-9,9:106.1
5,-8,9:106.1
4,2,9:106.2
-5,-4,9:106.8
7,2,9:106.8
2,7,9:106.4
0,0,8:17.0
-1,0,8:17.0
-1,-1,8:17.0
0,-1,8:17.0
1,-1,8:17.0
1,0,8:17.0
1,1,8:17.0
0,1,8:17.0
0,4,8:106.4
4,-1,8:106.2
-7,4,8:106.8
-4,1,8:106.8
-1,-9,8:106.1
5,-8,8:106.1
4,2,8:106.2
-5,-4,8:106.8
7,2,8:106.8
2,7,8:106.4
0,0,7:17.0
-1,0,7:17.0
-1,-1,7:17.0
0,-1,7:17.0
1,-1,7:17.0
1,0,7:17.0
1,1,7:17.0
0,1,7:17.0
0,4,7:106.4
4,-1,7:106.2
-7,4,7:106.8
-4,1,7:106.8
5,-8,7:106.1
4,2,7:106.2
-5,-4,7:106.8
7,2,7:106.8
2,7,7:106.4
0,0,6:17.0
-1,0,6:17.0
-1,-1,6:17.0
0,-1,6:17.0
1,-1,6:17.0
1,0,6:17.0
1,1,6:17.0
0,1,6:17.0
0,4,6:106.4
4,-1,6:106.2
-4,1,6:106.8
5,-8,6:106.1
4,2,6:106.2
-5,-4,6:106.8
7,2,6:106.8
2,7,6:106.4
-7,4,6:106.8
0,0,5:17.0
-1,0,5:17.0
-1,-1,5:17.0
0,-1,5:17.0
1,-1,5:17.0
1,0,5:17.0
0,1,5:17.0
1,1,5:17.0
0,4,5:106.4
4,-1,5:106.2
-4,1,5:106.8
5,-8,5:106.1
4,2,5:106.2
-5,-4,5:106.8
7,2,5:106.8
2,7,5:106.4
-7,4,5:106.8
0,0,4:17.0
-1,0,4:17.0
0,1,4:17.0
1,0,4:17.0
0,-1,4:17.0
-1,-1,4:17.0
1,-1,4:17.0
1,1,4:17.0
2,0,4:17.0
4,-1,4:106.2
-4,1,4:106.8
5,-8,4:106.1
4,2,4:106.2
-5,-4,4:106.8
7,2,4:106.8
2,7,4:106.4
-7,4,4:106.8
0,0,3:17.0
0,-1,3:17.0
-1,0,3:17.0
0,1,3:17.0
1,0,3:17.0
-1,-1,3:17.0
1,-1,3:17.0
1,1,3:17.0
0,-2,3:17.0
2,0,3:17.0
4,-1,3:106.2
5,-8,3:106.1
4,2,3:106.2
7,2,3:106.8
-5,-4,3:106.8
2,7,3:106.4
-7,4,3:106.8
0,0,2:17.0
-1,0,2:17.0
0,-1,2:17.0
1,0,2:17.0
0,1,2:17.0
-2,0,2:17.0
-1,-1,2:17.0
0,-2,2:17.0
1,-1,2:17.0
2,0,2:17.0
1,1,2:17.0
0,2,2:17.0
-1,1,2:17.0
1,-2,2:17.0
5,-8,2:106.1
4,2,2:106.2
-5,-4,2:106.8
2,7,2:106.4
-7,4,2:106.8
6,6,2:18.0
5,6,2:18.0
6,5,2:18.0
-8,4,2:18.0
-7,3,2:18.0
-6,-5,2:18.0
-7,-5,2:18.0
2,-8,2:18.0
1,-8,2:18.0
1,-7,2:18.0
7,-4,2:18.0
7,-5,2:18.0
6,-4,2:18.0
0,0,1:17.0
-1,0,1:17.0
0,-1,1:17.0
1,0,1:17.0
0,1,1:17.0
0,2,1:17.0
-1,1,1:17.0
-2,0,1:17.0
-1,-1,1:17.0
0,-2,1:17.0
1,-1,1:17.0
2,0,1:17.0
1,1,1:17.0
0,-3,1:17.0
1,-2,1:17.0
2,-1,1:17.0
-1,-2,1:17.0
-2,-1,1:17.0
4,2,1:106.2
-5,-4,1:106.8
2,7,1:106.4
-8,4,1:18.0
-7,3,1:18.0
-7,5,1:18.0
-7,4,1:106.8
-6,4,1:18.0
-9,4,1:18.0
-8,5,1:18.0
-8,3,1:18.0
-6,3,1:18.0
-1,7,1:18.0
-2,7,1:18.0
-3,6,1:18.0
-2,6,1:18.0
-6,-5,1:18.0
-6,-6,1:18.0
-7,-6,1:18.0
-6,-4,1:18.0
-7,-4,1:18.0
-5,-5,1:18.0
-8,-5,1:18.0
-7,-5,1:18.0
1,-8,1:18.0
0,-8,1:18.0
1,-7,1:18.0
2,-7,1:18.0
2,-8,1:18.0
3,-8,1:18.0
2,-9,1:18.0
7,-4,1:18.0
6,-4,1:18.0
5,-4,1:18.0
7,-5,1:18.0
7,-6,1:18.0
7,-3,1:18.0
8,-4,1:18.0
7,-2,1:18.0
6,6,1:18.0
5,6,1:18.0
5,5,1:18.0
5,4,1:18.0
7,6,1:18.0
8,6,1:18.0
7,7,1:18.0
5,7,1:18.0
6,5,1:18.0
7,5,1:18.0
6,7,1:18.0
6,8,1:18.0
5,-8,1:106.1
0,0,13:17.0
-1,0,13:17.0
-1,-1,13:17.0
0,-1,13:17.0
1,0,13:17.0
1,1,13:17.0
0,1,13:17.0
-1,3,13:17.0
-1,2,13:18.0
-2,3,13:18.0
-1,4,13:18.0
0,3,13:18.0
-2,4,13:18.0
-3,3,13:18.0
-3,4,13:18.0
-1,5,13:18.0
-2,5,13:18.0
0,4,13:106.4
-2,2,13:18.0
1,3,13:18.0
0,2,13:18.0
-4,1,13:106.8
2,-1,13:106.1
-1,-4,13:106.1
-7,4,13:106.8
-1,-9,13:106.1
5,-8,13:106.1
4,2,13:106.2
4,-1,13:106.2
-5,-4,13:106.8
7,2,13:106.8
2,7,13:106.4
0,0,18:17.0
-1,0,18:17.0
0,-1,18:17.0
1,0,18:17.0
1,1,18:17.0
0,1,18:17.0
0,4,18:106.4
-4,1,18:106.8
2,-1,18:106.1
-1,-4,18:106.1
4,-1,18:106.2
-7,4,18:106.8
-1,-9,18:106.1
5,-8,18:106.1
4,2,18:106.2
-5,-4,18:106.8
7,2,18:106.8
2,7,18:106.4
0,0,19:17.0
-1,0,19:17.0
0,-1,19:17.0
1,0,19:17.0
1,1,19:17.0
0,1,19:17.0
0,-2,19:17.0
-1,-3,19:18.0
-2,-3,19:18.0
-2,-4,19:18.0
-1,-4,19:106.1
0,-4,19:18.0
0,-3,19:18.0
-2,-2,19:18.0
-1,-2,19:18.0
-3,-4,19:18.0
-3,-3,19:18.0
-2,-5,19:18.0
-1,-5,19:18.0
0,4,19:106.4
-4,1,19:106.8
2,-1,19:106.1
4,-1,19:106.2
-7,4,19:106.8
-1,-9,19:106.1
5,-8,19:106.1
4,2,19:106.2
-5,-4,19:106.8
7,2,19:106.8
2,7,19:106.4
0,0,20:17.0
-1,0,20:17.0
0,-1,20:17.0
1,0,20:17.0
1,1,20:17.0
0,1,20:17.0
-1,-3,20:17.0
-2,-3,20:18.0
-1,-4,20:106.1
0,-3,20:18.0
-1,-2,20:18.0
-3,-3,20:18.0
-3,-4,20:18.0
-2,-4,20:18.0
-2,-5,20:18.0
-1,-5,20:18.0
0,-5,20:18.0
0,-4,20:18.0
1,-3,20:18.0
1,-4,20:18.0
-2,-2,20:18.0
0,-2,20:18.0
-1,-6,20:18.0
0,-6,20:18.0
-2,-6,20:18.0
-3,-5,20:18.0
-4,-4,20:18.0
-4,-3,20:18.0
-3,-2,20:18.0
-2,-1,20:18.0
0,4,20:106.4
-4,1,20:106.8
2,-1,20:106.1
4,-1,20:106.2
-7,4,20:106.8
-1,-9,20:106.1
5,-8,20:106.1
4,2,20:106.2
-5,-4,20:106.8
7,2,20:106.8
2,7,20:106.4
0,0,21:17.0
-1,0,21:17.0
0,-1,21:17.0
1,0,21:17.0
1,1,21:17.0
0,1,21:17.0
-1,-3,21:18.0
-2,-3,21:18.0
-2,-4,21:18.0
-1,-4,21:106.1
0,-4,21:18.0
0,-3,21:18.0
-1,-2,21:18.0
0,-2,21:18.0
-1,-5,21:18.0
-2,-5,21:18.0
-3,-3,21:18.0
-3,-4,21:18.0
0,4,21:106.4
-4,1,21:106.8
2,-1,21:106.1
4,-1,21:106.2
-7,4,21:106.8
-1,-9,21:106.1
5,-8,21:106.1
4,2,21:106.2
-5,-4,21:106.8
7,2,21:106.8
2,7,21:106.4
0,0,22:17.0
-1,0,22:17.0
0,-1,22:17.0
1,0,22:17.0
1,1,22:17.0
0,1,22:17.0
0,4,22:106.4
-4,1,22:106.8
2,-1,22:106.1
-1,-4,22:106.1
4,-1,22:106.2
-7,4,22:106.8
-1,-9,22:106.1
5,-8,22:106.1
4,2,22:106.2
-5,-4,22:106.8
7,2,22:106.8
2,7,22:106.4
0,0,23:17.0
-1,0,23:17.0
0,-1,23:17.0
1,0,23:17.0
0,1,23:17.0
3,-1,23:18.0
2,7,23:106.4
0,4,23:106.4
-4,1,23:106.8
2,-1,23:106.1
-1,-4,23:106.1
4,-1,23:106.2
-7,4,23:106.8
-1,-9,23:106.1
5,-8,23:106.1
4,2,23:106.2
-5,-4,23:106.8
7,2,23:106.8
0,0,24:17.0
-1,0,24:17.0
0,-1,24:17.0
1,0,24:17.0
0,1,24:17.0
2,0,24:17.0
3,-2,24:18.0
4,-1,24:106.2
3,-1,24:18.0
2,-1,24:106.1
3,0,24:18.0
2,7,24:106.4
2,-2,24:18.0
3,-3,24:18.0
4,-2,24:18.0
5,-1,24:18.0
4,0,24:18.0
1,-1,24:18.0
3,1,24:18.0
0,4,24:106.4
-4,1,24:106.8
-1,-4,24:106.1
-7,4,24:106.8
-1,-9,24:106.1
5,-8,24:106.1
4,2,24:106.2
-5,-4,24:106.8
7,2,24:106.8
0,0,14:17.0
-1,0,14:17.0
0,-1,14:17.0
1,0,14:17.0
1,1,14:17.0
0,1,14:17.0
-1,3,14:18.0
-3,3,14:18.0
-2,3,14:18.0
-2,4,14:18.0
-1,4,14:18.0
-1,5,14:18.0
0,4,14:106.4
1,3,14:18.0
0,3,14:18.0
0,2,14:18.0
-2,2,14:18.0
-2,1,14:18.0
-1,1,14:18.0
-1,2,14:18.0
-3,4,14:18.0
-2,5,14:18.0
-3,2,14:18.0
-4,1,14:106.8
2,-1,14:106.1
-1,-4,14:106.1
4,-1,14:106.2
-7,4,14:106.8
-1,-9,14:106.1
5,-8,14:106.1
4,2,14:106.2
-5,-4,14:106.8
7,2,14:106.8
2,7,14:106.4
0,0,15:17.0
-1,0,15:17.0
0,-1,15:17.0
1,0,15:17.0
1,1,15:17.0
0,1,15:17.0
-2,4,15:18.0
-2,3,15:18.0
-1,3,15:18.0
-1,4,15:18.0
-2,2,15:18.0
-1,2,15:18.0
0,2,15:18.0
0,3,15:18.0
0,4,15:106.4
-4,1,15:106.8
2,-1,15:106.1
-1,-4,15:106.1
4,-1,15:106.2
-7,4,15:106.8
-1,-9,15:106.1
5,-8,15:106.1
4,2,15:106.2
-5,-4,15:106.8
7,2,15:106.8
2,7,15:106.4
0,0,16:17.0
-1,0,16:17.0
0,-1,16:17.0
1,0,16:17.0
1,1,16:17.0
0,1,16:17.0
0,4,16:106.4
-4,1,16:106.8
2,-1,16:106.1
-1,-4,16:106.1
4,-1,16:106.2
-7,4,16:106.8
-1,-9,16:106.1
5,-8,16:106.1
4,2,16:106.2
-5,-4,16:106.8
7,2,16:106.8
2,7,16:106.4
0,0,17:17.0
-1,0,17:17.0
0,-1,17:17.0
1,0,17:17.0
1,1,17:17.0
0,1,17:17.0
0,4,17:106.4
-4,1,17:106.8
2,-1,17:106.1
-1,-4,17:106.1
4,-1,17:106.2
-7,4,17:106.8
-1,-9,17:106.1
5,-8,17:106.1
4,2,17:106.2
-5,-4,17:106.8
7,2,17:106.8
2,7,17:106.4
0,0,25:17.0
-1,0,25:17.0
0,-1,25:17.0
1,0,25:17.0
0,1,25:17.0
3,-1,25:17.0
4,-1,25:106.2
3,-2,25:18.0
2,-1,25:106.1
3,0,25:18.0
2,7,25:106.4
2,-2,25:18.0
3,-3,25:18.0
4,-2,25:18.0
5,-1,25:18.0
5,-2,25:18.0
4,0,25:18.0
4,1,25:18.0
3,1,25:18.0
2,0,25:18.0
1,-1,25:18.0
1,-2,25:18.0
2,-3,25:18.0
4,-3,25:18.0
5,0,25:18.0
0,4,25:106.4
-4,1,25:106.8
-1,-4,25:106.1
-7,4,25:106.8
-1,-9,25:106.1
5,-8,25:106.1
4,2,25:106.2
-5,-4,25:106.8
7,2,25:106.8
0,0,26:17.0
-1,0,26:17.0
0,-1,26:17.0
1,0,26:17.0
0,1,26:17.0
3,-1,26:18.0
3,-2,26:18.0
2,-1,26:106.1
3,0,26:18.0
2,7,26:106.4
2,-2,26:18.0
4,-2,26:18.0
4,-1,26:18.0
4,0,26:18.0
2,0,26:18.0
1,-1,26:18.0
3,-3,26:18.0
5,-1,26:18.0
3,1,26:18.0
0,4,26:106.4
-4,1,26:106.8
-1,-4,26:106.1
-7,4,26:106.8
-1,-9,26:106.1
5,-8,26:106.1
4,2,26:106.2
-5,-4,26:106.8
7,2,26:106.8
-1,0,-1:2
0,0,-1:2
1,0,-1:2
2,0,-1:2
0,-2,-1:2
0,-1,-1:2
0,1,-1:2
0,2,-1:2
-1,1,-1:2
-1,-1,-1:2
1,-1,-1:2
1,1,-1:2
-2,1,-1:2
-2,2,-1:2
-1,2,-1:2
1,2,-1:2
2,1,-1:2
2,-1,-1:2
1,-2,-1:2
0,-3,-1:2
-1,-2,-1:2
-2,-1,-1:2
-3,0,-1:2
3,0,-1:2
0,3,-1:2
-2,-2,-1:2
2,-2,-1:2
2,2,-1:2
-2,0,-1:2
-3,-1,-1:17.0
-1,-3,-1:17.0
0,-4,-1:17.0
3,-1,-1:17.0
4,0,-1:17.0
1,3,-1:17.0
-1,3,-1:17.0
0,4,-1:17.0
-3,1,-1:17.0
-7,4,-1:17.0
-1,7,-1:17.0
6,6,-1:17.0
7,-4,-1:17.0
1,-8,-1:17.0
-6,-5,-1:17.0
-7,3,-1:2
-6,3,-1:2
-1,6,-1:2
5,6,-1:2
6,5,-1:2
6,-4,-1:2
1,-7,-1:2
-5,-5,-1:2
-6,-4,-1:2
1,-3,-1:2
3,1,-1:2
-5,3,-1:2
-4,1,-1:2
-5,1,-1:2
-5,2,-1:2
-4,0,-1:2
-4,-2,-1:2
-4,-3,-1:2
-5,-4,-1:2
-3,-3,-1:2
-4,-4,-1:2
-3,-2,-1:2
-2,-3,-1:2
-2,-4,-1:2
-1,-4,-1:2
0,-7,-1:2
0,-6,-1:2
0,-5,-1:2
-1,-5,-1:2
1,-5,-1:2
1,-4,-1:2
5,-4,-1:2
6,-3,-1:2
5,-3,-1:2
4,-3,-1:2
3,-2,-1:2
4,-2,-1:2
3,-3,-1:2
5,-2,-1:2
4,-1,-1:2
3,2,-1:2
3,3,-1:2
4,3,-1:2
4,4,-1:2
5,4,-1:2
5,5,-1:2
4,5,-1:2
3,4,-1:2
2,4,-1:2
2,3,-1:2
0,6,-1:2
0,5,-1:2
1,5,-1:2
-1,5,-1:2
-1,4,-1:2
1,4,-1:2
-6,2,-1:2
-4,2,-1:2
-3,2,-1:2
0,0,27:17.0
-1,0,27:17.0
0,-1,27:17.0
1,0,27:17.0
0,1,27:17.0
3,-1,27:18.0
2,7,27:106.4
0,4,27:106.4
-4,1,27:106.8
2,-1,27:106.1
-1,-4,27:106.1
-7,4,27:106.8
-1,-9,27:106.1
5,-8,27:106.1
4,2,27:106.2
-5,-4,27:106.8
7,2,27:106.8
0,0,28:17.0
-1,0,28:17.0
0,-1,28:17.0
1,0,28:17.0
0,1,28:17.0
0,2,28:17.0
-1,3,28:18.0
1,3,28:18.0
0,3,28:18.0
2,7,28:106.4
0,4,28:106.4
-4,1,28:106.8
2,-1,28:106.1
-1,-4,28:106.1
-7,4,28:106.8
-1,-9,28:106.1
5,-8,28:106.1
4,2,28:106.2
-5,-4,28:106.8
7,2,28:106.8
0,0,29:17.0
-1,0,29:17.0
0,-1,29:17.0
1,0,29:17.0
0,1,29:17.0
-1,3,29:17.0
1,3,29:17.0
-1,2,29:18.0
-2,3,29:18.0
-1,4,29:18.0
0,3,29:18.0
1,4,29:18.0
2,3,29:18.0
1,2,29:18.0
-1,-9,29:106.1
2,7,29:106.4
0,4,29:106.4
-2,4,29:18.0
2,4,29:18.0
-4,1,29:106.8
2,-1,29:106.1
-1,-4,29:106.1
-7,4,29:106.8
5,-8,29:106.1
4,2,29:106.2
-5,-4,29:106.8
7,2,29:106.8
0,0,30:17.0
-1,0,30:17.0
0,-1,30:17.0
1,0,30:17.0
0,1,30:17.0
-1,3,30:18.0
1,3,30:18.0
2,2,30:18.0
1,2,30:18.0
2,3,30:18.0
-2,3,30:18.0
-1,4,30:18.0
0,4,30:106.4
1,4,30:18.0
0,3,30:18.0
0,2,30:18.0
-1,2,30:18.0
-1,-9,30:106.1
2,-1,30:106.1
2,7,30:106.4
-1,5,30:18.0
0,5,30:18.0
1,5,30:18.0
2,4,30:18.0
-2,4,30:18.0
-3,4,30:18.0
-3,3,30:18.0
-2,2,30:18.0
2,5,30:18.0
3,3,30:18.0
3,4,30:18.0
-2,5,30:18.0
-4,1,30:106.8
-1,-4,30:106.1
-7,4,30:106.8
5,-8,30:106.1
4,2,30:106.2
-5,-4,30:106.8
7,2,30:106.8
0,0,31:17.0
-1,0,31:17.0
0,-1,31:17.0
1,0,31:17.0
0,1,31:17.0
-1,-9,31:106.1
2,-1,31:106.1
2,7,31:106.4
-2,3,31:18.0
-2,4,31:18.0
0,4,31:18.0
1,4,31:18.0
1,3,31:18.0
2,4,31:18.0
0,3,31:18.0
-1,3,31:18.0
-4,1,31:106.8
-1,-4,31:106.1
-7,4,31:106.8
5,-8,31:106.1
4,2,31:106.2
-5,-4,31:106.8
7,2,31:106.8
0,0,32:17.0
-6,1,32:85
-1,0,32:17.0
0,-1,32:17.0
1,0,32:17.0
0,1,32:17.0
-1,-9,32:106.1
2,-1,32:106.1
-4,1,32:106.8
2,7,32:106.4
-1,-4,32:106.1
-7,4,32:106.8
5,-8,32:106.1
4,2,32:106.2
-5,-4,32:106.8
7,2,32:106.8
0,0,33:17.0
-6,1,33:85
-1,0,33:17.0
0,-1,33:17.0
0,1,33:17.0
1,0,33:17.0
-1,-4,33:106.1
-1,-9,33:106.1
2,-1,33:106.1
-4,1,33:106.8
2,7,33:106.4
-7,4,33:106.8
5,-8,33:106.1
4,2,33:106.2
-5,-4,33:106.8
7,2,33:106.8
0,0,34:17.0
1,0,34:17.0
-6,1,34:85
0,7,34:85
0,-1,34:17.0
-1,0,34:17.0
0,1,34:17.0
-1,-4,34:106.1
-1,-9,34:106.1
2,-1,34:106.1
0,3,34:106.2
-4,1,34:106.8
2,7,34:106.4
-7,4,34:106.8
5,-8,34:106.1
-5,-4,34:106.8
7,2,34:106.8
4,2,34:106.2
0,0,35:17.0
0,1,35:17.0
2,0,35:17.0
0,-2,35:17.0
0,-1,35:17.0
-6,1,35:85
0,7,35:85
-1,-4,35:106.1
-1,-9,35:106.1
5,-8,35:106.1
2,-1,35:106.1
0,3,35:106.2
-4,1,35:106.8
-7,4,35:106.8
2,7,35:106.4
4,2,35:106.2
-5,-4,35:106.8
7,2,35:106.8
0,0,36:17.0
0,2,36:17.0
-1,0,36:17.0
0,-2,36:17.0
2,0,36:17.0
-6,1,36:85
0,7,36:85
-1,-4,36:106.1
-1,-9,36:106.1
5,-8,36:106.1
2,-1,36:106.1
0,3,36:106.2
4,2,36:106.2
-4,1,36:106.8
-7,4,36:106.8
2,7,36:106.4
-5,-4,36:106.8
7,2,36:106.8
0,-2,37:17.0
0,2,37:17.0
0,0,37:17.0
-2,1,37:17.0
2,0,37:17.0
-6,1,37:85
0,7,37:85
-1,-4,37:106.1
-1,-9,37:106.1
5,-8,37:106.1
2,-1,37:106.1
0,3,37:106.2
4,2,37:106.2
-4,1,37:106.8
-7,4,37:106.8
2,7,37:106.4
-5,-4,37:106.8
7,2,37:106.8
0,0,38:17.0
-2,1,38:17.0
1,1,38:17.0
2,2,38:17.0
0,-3,38:17.0
-1,3,38:17.0
-6,1,38:85
0,7,38:85
-1,-4,38:106.1
-1,-9,38:106.1
5,-8,38:106.1
2,-1,38:106.1
0,3,38:106.2
4,2,38:106.2
-4,1,38:106.8
-7,4,38:106.8
2,7,38:106.4
-5,-4,38:106.8
7,2,38:106.8
0,0,39:17.0
-3,1,39:17.0
-4,2,39:17.0
0,4,39:17.0
2,3,39:17.0
3,2,39:17.0
4,1,39:17.0
-1,-3,39:17.0
1,-3,39:17.0
-2,-2,39:17.0
-2,-4,39:17.0
2,0,39:17.0
-6,1,39:85
0,7,39:85
-1,-4,39:106.1
5,-8,39:106.1
-1,-9,39:106.1
2,-1,39:106.1
0,3,39:106.2
4,2,39:106.2
-4,1,39:106.8
-7,4,39:106.8
2,7,39:106.4
-5,-4,39:106.8
7,2,39:106.8
0,0,40:17.0
-2,-1,40:17.0
-4,0,40:17.0
-3,-3,40:17.0
-3,-4,40:17.0
-3,3,40:17.0
-1,3,40:17.0
-1,4,40:17.0
3,3,40:17.0
3,0,40:17.0
4,0,40:17.0
2,-2,40:17.0
3,-2,40:17.0
3,-3,40:17.0
1,-4,40:17.0
0,4,40:18.0
5,0,40:18.0
-5,0,40:18.0
0,-5,40:18.0
1,-5,40:18.0
-2,-5,40:18.0
-2,-4,40:18.0
-3,-5,40:18.0
-4,-4,40:18.0
-4,-3,40:18.0
-4,-2,40:18.0
-4,-1,40:18.0
-5,-1,40:18.0
-5,1,40:18.0
-4,3,40:18.0
-4,2,40:18.0
-4,1,40:18.0
-3,4,40:18.0
-2,4,40:18.0
-1,5,40:18.0
3,4,40:17.0
4,2,40:18.0
4,1,40:18.0
5,2,40:18.0
5,1,40:18.0
2,-4,40:18.0
2,-3,40:18.0
3,-4,40:18.0
4,-3,40:18.0
4,-2,40:18.0
4,-1,40:18.0
3,-1,40:18.0
5,-1,40:18.0
4,3,40:18.0
0,5,40:18.0
2,4,40:18.0
1,5,40:18.0
-5,2,40:18.0
-1,-5,40:18.0
0,-6,40:18.0
-1,-6,40:18.0
-2,-6,40:18.0
-5,-3,40:18.0
-5,-2,40:18.0
-5,3,40:18.0
-4,4,40:18.0
-3,5,40:18.0
-2,5,40:18.0
2,5,40:18.0
3,5,40:18.0
4,4,40:18.0
5,-2,40:18.0
3,-5,40:18.0
2,-5,40:18.0
1,-6,40:18.0
-6,1,40:85
0,7,40:85
1,4,40:18.0
4,-4,40:18.0
-1,-9,40:106.1
5,-8,40:106.1
2,-1,40:106.1
0,3,40:106.2
-7,4,40:106.8
2,7,40:106.4
-5,-4,40:106.8
-6,3,40:18.0
-5,4,40:18.0
-4,5,40:18.0
-6,2,40:18.0
-6,-1,40:18.0
-6,-2,40:18.0
-1,6,40:18.0
0,6,40:18.0
-2,6,40:18.0
-3,6,40:18.0
1,6,40:18.0
7,2,40:106.8
0,0,41:18.0
-1,0,41:18.0
-2,0,41:18.0
-3,0,41:17.0
-4,0,41:18.0
-5,0,41:17.0
1,0,41:18.0
2,0,41:17.0
3,0,41:18.0
4,0,41:18.0
5,0,41:17.0
0,1,41:18.0
0,2,41:18.0
0,3,41:18.0
0,4,41:18.0
0,5,41:17.0
0,-1,41:18.0
0,-2,41:18.0
0,-3,41:18.0
0,-4,41:18.0
0,-5,41:18.0
1,-5,41:17.0
-1,-5,41:17.0
-2,-5,41:18.0
-5,-1,41:18.0
-5,2,41:18.0
-5,1,41:18.0
-1,5,41:18.0
1,5,41:18.0
5,-1,41:18.0
5,1,41:18.0
5,2,41:18.0
4,3,41:18.0
3,4,41:17.0
2,4,41:18.0
-2,4,41:18.0
-3,3,41:18.0
-4,3,41:17.0
-4,-2,41:18.0
-4,-3,41:18.0
-3,-4,41:18.0
2,-4,41:18.0
3,-4,41:17.0
4,-3,41:18.0
4,-2,41:18.0
-3,-2,41:18.0
-3,-3,41:18.0
-2,-3,41:18.0
-2,-4,41:17.0
-1,-4,41:18.0
-1,-3,41:18.0
-1,-2,41:18.0
-1,-1,41:18.0
-2,-1,41:18.0
-3,-1,41:18.0
-4,-1,41:17.0
-2,-2,41:18.0
-4,1,41:18.0
-3,1,41:18.0
-2,1,41:18.0
-1,1,41:18.0
-1,2,41:17.0
-2,2,41:18.0
-3,2,41:18.0
-4,2,41:18.0
-2,3,41:18.0
-1,3,41:18.0
-1,4,41:18.0
1,4,41:18.0
2,3,41:18.0
1,3,41:18.0
1,2,41:18.0
1,1,41:18.0
2,1,41:18.0
3,1,41:18.0
4,1,41:18.0
4,2,41:18.0
3,2,41:18.0
3,3,41:18.0
2,2,41:18.0
3,-1,41:18.0
4,-1,41:18.0
2,-1,41:18.0
1,-1,41:18.0
1,-2,41:17.0
2,-3,41:18.0
2,-2,41:18.0
3,-2,41:18.0
3,-3,41:18.0
1,-3,41:18.0
1,-4,41:18.0
-5,-2,41:17.0
-5,-3,41:18.0
-4,-4,41:18.0
-3,-5,41:17.0
-3,-6,41:18.0
-2,-6,41:17.0
-1,-6,41:18.0
0,-7,41:18.0
-1,-7,41:17.0
0,-6,41:18.0
1,-6,41:18.0
2,-6,41:17.0
2,-5,41:18.0
3,-5,41:18.0
4,-5,41:18.0
5,-4,41:17.0
4,-4,41:17.0
5,-3,41:18.0
5,-2,41:18.0
6,-1,41:18.0
6,0,41:17.0
6,1,41:18.0
5,3,41:18.0
5,4,41:18.0
4,4,41:18.0
2,5,41:18.0
3,5,41:17.0
1,6,41:18.0
0,6,41:18.0
-1,6,41:17.0
-2,5,41:18.0
-3,5,41:18.0
-3,4,41:18.0
-4,4,41:18.0
-5,3,41:18.0
-6,1,41:17.0
-6,0,41:18.0
-6,-1,41:18.0
-4,-5,41:18.0
7,0,41:18.0
8,0,41:18.0
7,1,41:17.0
7,-1,41:17.0
6,-2,41:18.0
6,-3,41:18.0
6,2,41:17.0
6,3,41:18.0
4,5,41:18.0
5,5,41:17.0
3,6,41:18.0
2,6,41:18.0
1,7,41:18.0
0,7,41:17.0
-1,7,41:18.0
-2,6,41:18.0
8,-1,41:18.0
7,-2,41:18.0
3,-6,41:18.0
4,-6,41:18.0
5,-5,41:18.0
6,-4,41:18.0
3,-7,41:18.0
2,-7,41:17.0
1,-7,41:18.0
1,-8,41:17.0
0,-8,41:18.0
2,-8,41:18.0
-2,-7,41:18.0
-3,-7,41:18.0
-4,-6,41:18.0
-5,-4,41:106.8
-1,-8,41:18.0
-6,-2,41:18.0
-7,0,41:18.0
-7,-1,41:18.0
-6,-3,41:18.0
-6,2,41:18.0
-7,1,41:18.0
-5,4,41:17.0
-6,3,41:18.0
-4,5,41:18.0
-3,6,41:18.0
-2,7,41:18.0
7,2,41:106.8
8,1,41:18.0
6,4,41:18.0
7,3,41:18.0
2,7,41:106.4
3,7,41:18.0
4,6,41:17.0
5,-6,41:17.0
6,-5,41:17.0
-7,-2,41:18.0
-8,-1,41:18.0
-8,0,41:18.0
-8,1,41:18.0
-7,2,41:18.0
-7,3,41:18.0
-8,2,41:18.0
-6,4,41:18.0
-5,5,41:18.0
-6,5,41:18.0
-4,6,41:18.0
-5,6,41:18.0
-7,-3,41:18.0
-6,-4,41:18.0
-5,-5,41:18.0
-5,-6,41:18.0
-8,-2,41:18.0
-7,-4,41:18.0
-6,-5,41:18.0
-4,-7,41:18.0
-2,-8,41:18.0
3,-8,41:18.0
4,-7,41:18.0
5,-7,41:18.0
6,-6,41:18.0
7,-6,41:18.0
7,-5,41:18.0
7,-4,41:18.0
7,-3,41:18.0
8,-3,41:18.0
8,-2,41:18.0
8,2,41:18.0
8,3,41:18.0
7,4,41:18.0
6,5,41:18.0
5,6,41:18.0
5,7,41:18.0
4,7,41:18.0
6,6,41:18.0
7,5,41:18.0
3,8,41:18.0
2,8,41:18.0
1,8,41:18.0
0,8,41:18.0
-1,8,41:18.0
6,-7,41:18.0
4,8,41:18.0
-1,-9,41:106.1
5,-8,41:106.1
-7,4,41:106.8
-2,-9,41:18.0
0,-9,41:18.0
1,-9,41:18.0
-1,-10,41:18.0
-3,-8,41:18.0
-4,-8,41:18.0
-3,-9,41:18.0
2,-9,41:18.0
4,-8,41:18.0
4,-9,41:18.0
5,-9,41:18.0
6,-8,41:18.0
3,-9,41:18.0
0,-10,41:18.0
1,-10,41:18.0
-4,7,41:18.0
-3,7,41:18.0
-8,3,41:18.0
-8,4,41:18.0
-7,5,41:18.0
-8,5,41:18.0
-6,6,41:18.0
-7,6,41:18.0
-9,4,41:18.0
-9,3,41:18.0
-9,2,41:18.0
-9,1,41:18.0
-3,0,42:18.0
-2,0,42:18.0
-1,0,42:18.0
0,0,42:18.0
1,0,42:18.0
2,0,42:18.0
0,-3,42:18.0
0,-2,42:18.0
0,-1,42:18.0
0,1,42:18.0
0,2,42:18.0
0,3,42:18.0
1,2,42:18.0
1,1,42:18.0
1,-2,42:18.0
1,-1,42:18.0
2,-1,42:18.0
2,1,42:18.0
-3,1,42:18.0
-2,-1,42:18.0
-2,1,42:18.0
-2,2,42:18.0
-1,3,42:18.0
-1,2,42:18.0
-1,1,42:18.0
-1,-1,42:18.0
-1,-2,42:18.0
-3,-1,42:18.0
-3,-2,42:18.0
-2,-2,42:18.0
-1,-3,42:18.0
0,-4,42:18.0
1,-4,42:18.0
1,-3,42:18.0
2,-3,42:18.0
2,-2,42:18.0
3,-1,42:18.0
3,0,42:18.0
3,-2,42:18.0
3,1,42:18.0
2,2,42:18.0
-2,-3,42:18.0
-1,-4,42:18.0
0,-5,42:18.0
1,3,42:18.0
3,-3,42:18.0
2,-4,42:18.0
1,-5,42:18.0
-2,-4,42:18.0
-1,-5,42:18.0
-3,-3,42:18.0
-4,0,42:18.0
-4,-1,42:18.0
4,-1,42:18.0
4,-2,42:18.0
-5,0,42:18.0
-4,-2,42:18.0
-5,-1,42:18.0
-5,-2,42:18.0
-3,-4,42:18.0
-4,-3,42:18.0
-2,-5,42:18.0
0,-6,42:18.0
1,-6,42:18.0
2,-6,42:18.0
2,-5,42:18.0
3,-4,42:18.0
4,-4,42:18.0
3,-5,42:18.0
4,-3,42:18.0
6,0,42:18.0
5,0,42:18.0
4,0,42:18.0
5,-1,42:18.0
5,-2,42:18.0
5,1,42:18.0
4,1,42:18.0
4,2,42:18.0
3,2,42:18.0
3,3,42:18.0
3,4,42:18.0
3,5,42:18.0
2,3,42:18.0
2,4,42:18.0
2,5,42:18.0
1,4,42:18.0
0,5,42:18.0
-1,5,42:18.0
-1,6,42:18.0
-1,4,42:18.0
0,4,42:18.0
-2,5,42:18.0
-2,4,42:18.0
-3,4,42:18.0
-3,3,42:18.0
-4,3,42:18.0
-2,3,42:18.0
-3,2,42:18.0
-4,1,42:18.0
-4,2,42:18.0
-5,1,42:18.0
4,3,42:18.0
5,2,42:18.0
6,1,42:18.0
4,4,42:18.0
1,5,42:18.0
-6,1,42:18.0
-5,4,42:18.0
0,7,42:18.0
4,6,42:18.0
7,1,42:18.0
7,-1,42:18.0
5,-4,42:18.0
6,-5,42:18.0
2,-7,42:18.0
-3,-5,42:18.0
-5,3,42:18.0
-5,2,42:18.0
-6,2,42:18.0
-4,5,42:18.0
-4,4,42:18.0
-3,5,42:18.0
0,6,42:18.0
1,6,42:18.0
2,6,42:18.0
3,6,42:18.0
1,7,42:18.0
2,7,42:106.4
4,5,42:18.0
5,4,42:18.0
5,3,42:18.0
6,3,42:18.0
6,2,42:18.0
7,0,42:18.0
6,-1,42:18.0
6,-2,42:18.0
6,-3,42:18.0
6,-4,42:18.0
5,-3,42:18.0
4,-5,42:18.0
5,-5,42:18.0
4,-6,42:18.0
3,-6,42:18.0
-1,-6,42:18.0
7,-2,42:18.0
5,5,42:18.0
-6,4,42:106.8
-6,-1,42:18.0
-6,-2,42:18.0
-6,-3,42:18.0
-5,-3,42:18.0
-5,-4,42:18.0
-4,-4,42:18.0
-4,-5,42:18.0
-3,-6,42:18.0
-2,-6,42:18.0
-1,-7,42:18.0
0,-7,42:18.0
0,-8,42:18.0
1,-8,42:18.0
1,-7,42:18.0
2,-8,42:18.0
3,-8,42:18.0
5,-6,42:18.0
4,-7,42:18.0
3,-7,42:18.0
-6,3,42:18.0
-6,5,42:18.0
-5,5,42:18.0
-4,6,42:18.0
-3,6,42:18.0
-2,6,42:18.0
-7,3,42:18.0
-7,5,42:18.0
-8,4,42:18.0
-8,3,42:18.0
-8,2,42:18.0
-7,2,42:18.0
-7,1,42:18.0
-6,0,42:18.0
-7,0,42:18.0
-7,-1,42:18.0
-8,1,42:18.0
-7,4,42:18.0
-3,-2,43:18.0
-3,-1,43:18.0
-3,0,43:18.0
-3,1,43:18.0
-3,2,43:18.0
-3,3,43:18.0
-2,3,43:18.0
-1,2,43:18.0
-1,1,43:18.0
0,1,43:18.0
0,0,43:18.0
1,1,43:18.0
1,2,43:18.0
0,2,43:18.0
-1,0,43:18.0
-1,-1,43:18.0
-2,-1,43:18.0
-2,-2,43:18.0
-2,0,43:18.0
-2,1,43:18.0
-2,2,43:18.0
-4,0,43:18.0
-4,1,43:18.0
-3,-3,43:18.0
-2,-3,43:18.0
-1,-3,43:18.0
0,-3,43:18.0
0,-4,43:18.0
1,-4,43:18.0
1,-3,43:18.0
1,-2,43:18.0
1,-1,43:18.0
1,0,43:18.0
0,-1,43:18.0
0,-2,43:18.0
2,-2,43:18.0
3,-2,43:18.0
3,-1,43:18.0
3,0,43:18.0
2,1,43:18.0
2,-1,43:18.0
2,0,43:18.0
3,1,43:18.0
4,1,43:18.0
3,2,43:18.0
2,2,43:18.0
1,3,43:18.0
0,3,43:18.0
-1,3,43:18.0
-1,-2,43:18.0
-4,-1,43:18.0
-4,2,43:18.0
2,-3,43:18.0
4,0,43:18.0
4,-1,43:18.0
-1,4,43:18.0
0,4,43:18.0
-2,4,43:18.0
2,3,43:18.0
1,4,43:18.0
-1,-4,43:18.0
0,-5,43:18.0
1,-5,43:18.0
2,-5,43:18.0
2,-4,43:18.0
3,-3,43:18.0
3,-4,43:18.0
4,-2,43:18.0
-2,-4,43:18.0
-5,-4,-2:17.0
-3,-2,-2:17.0
-6,3,-2:17.0
-4,2,-2:17.0
-1,6,-2:17.0
0,3,-2:17.0
5,5,-2:17.0
6,-4,-2:17.0
1,-7,-2:17.0
-1,-4,-2:17.0
4,-1,-2:17.0
2,0,-2:17.0
1,-2,-2:17.0
-1,0,-2:17.0
2,2,-2:17.0
-2,2,-2:17.0
-5,2,-2:3
-3,1,-2:3
-2,0,-2:3
-4,-1,-2:3
-4,-3,-2:3
-3,-3,-2:3
-2,-3,-2:3
-2,-2,-2:3
-1,-2,-2:3
-1,-1,-2:3
-3,-1,-2:3
-1,1,-2:3
1,1,-2:3
0,0,-2:3
0,-2,-2:3
0,-3,-2:3
0,-5,-2:3
1,-4,-2:3
1,-5,-2:3
0,-6,-2:3
-2,-5,-2:3
-2,-4,-2:3
2,-3,-2:3
3,-4,-2:3
4,-4,-2:3
4,-3,-2:3
2,-2,-2:3
3,-2,-2:3
5,-3,-2:3
2,-1,-2:3
1,-1,-2:3
3,0,-2:3
2,1,-2:3
1,3,-2:3
1,2,-2:3
2,4,-2:3
3,3,-2:3
4,4,-2:3
2,3,-2:3
-1,4,-2:3
-1,3,-2:3
-1,2,-2:3
-2,1,-2:3
-3,-2,-3:3
-1,-3,-3:3
2,-2,-3:3
1,-4,-3:3
0,-4,-3:3
0,-1,-3:3
2,0,-3:3
-1,1,-3:3
-2,-1,-3:3
-2,3,-3:3
-2,2,-3:3
1,1,-3:3
2,2,-3:3
0,3,-3:3
3,3,-3:3
3,-1,-3:3
4,-3,-3:3
0,2,-3:3
-1,-6,-3:3
-4,-3,-3:3
-4,1,-3:3
1,-2,-3:3
-3,0,-3:3
