[META]
version=2.0
spawnOnBlockType=8,9
spawnSunlight=True
spawnDarkness=True
spawnWater=False
spawnLava=False
underFill=False
randomRotation=True
dig=True
tree=False
branch=False
needsFoundation=True
rarity=100
collisionPercentage=10
spawnElevationMin=0
spawnElevationMax=100
spawnInBiome=All
[DATA]
-1,-1,0:17.1
0,-1,0:2
-2,0,0:18
-1,0,0:17.1
0,0,0:17.1
-2,1,0:17.1
0,1,0:18
-2,-1,-6:17.1
0,0,-6:17.1
-2,1,-6:17.1
-2,-1,-5:17.1
0,-1,-5:17.1
0,0,-5:17.1
-2,1,-5:17.1
-2,-1,-4:17.1
-1,-1,-4:17.1
0,-1,-4:17.1
-2,0,-4:17.1
0,0,-4:17.1
-2,1,-4:17.1
-1,1,-4:17.1
-2,-1,-3:17.1
-1,-1,-3:17.1
0,-1,-3:17.1
-2,0,-3:17.1
-1,0,-3:17.1
0,0,-3:17.1
-2,1,-3:17.1
-1,1,-3:17.1
-2,-1,-2:18
-1,-1,-2:17.1
0,-1,-2:17.1
-2,0,-2:18
-1,0,-2:17.1
0,0,-2:17.1
-2,1,-2:17.1
-1,-1,-1:17.1
0,-1,-1:17.1
-2,0,-1:18
-1,0,-1:17.1
0,0,-1:17.1
-2,1,-1:17.1
-1,-1,1:2
-2,0,1:18
-1,0,1:17.1
0,0,1:17.1
-2,1,1:17.1
0,1,1:18
0,2,1:106.4
-2,2,1:106.4
-3,1,1:106.8
1,0,1:106.2
-3,0,1:106.8
0,-1,1:106.1
-2,-1,1:106.1
-1,-2,1:106.1
-2,0,2:18
-1,0,2:17.1
0,0,2:17.1
-2,1,2:2
-1,1,2:18
0,1,2:18
0,2,2:106.4
-1,2,2:106.4
-2,2,2:106.4
1,1,2:106.2
-3,1,2:106.8
1,0,2:106.2
-3,0,2:106.8
-1,-1,2:31.2
-2,-1,2:106.1
-3,-1,2:106.8
-2,-1,3:18
-1,-1,3:18
-2,0,3:18
-1,0,3:17.1
0,0,3:2
-1,1,3:18
-1,2,3:106.4
-2,1,3:31.2
1,0,3:106.2
-3,0,3:106.8
-3,-1,3:106.8
-1,-2,3:106.1
-2,-2,3:106.1
-1,-1,4:18
-1,0,4:17.1
-1,1,4:18
0,4,4:106.4
0,2,4:106.4
-1,2,4:106.4
1,1,4:106.2
0,1,4:106.2
0,0,4:31.2
-3,-1,4:106.8
-1,-2,4:106.1
-2,-2,4:106.1
-2,-1,5:18
-1,-1,5:18
-1,0,5:17.1
-1,1,5:18
0,1,5:18
0,4,5:106.4
0,2,5:106.4
-1,2,5:106.4
1,1,5:106.2
0,0,5:106.2
-3,-1,5:106.8
-1,-2,5:106.1
-2,-2,5:106.1
-3,-3,5:106.1
-3,-2,6:18
0,-2,6:17.1
-3,-1,6:18
-2,-1,6:18
-1,-1,6:17.1
0,-1,6:17.1
-2,0,6:17.1
-1,0,6:17.1
-1,1,6:17.1
0,1,6:18
0,4,6:106.4
1,3,6:106.2
0,2,6:106.4
1,1,6:106.2
0,0,6:106.2
-4,-1,6:106.8
-2,-2,6:106.1
-4,-2,6:106.8
-3,-3,6:106.1
-3,-2,7:18
0,-2,7:17.1
-3,-1,7:17.1
-3,0,7:17.1
-2,0,7:17.1
-1,0,7:2
-1,1,7:17.1
0,1,7:18
-1,2,7:17.1
0,2,7:18
0,3,7:18
0,4,7:106.4
1,3,7:106.2
1,2,7:106.2
1,1,7:106.2
0,0,7:106.2
-1,-1,7:106.1
-2,-2,7:106.2
-4,-2,7:106.8
-3,-3,7:106.1
-3,-2,8:18
-3,-1,8:17.1
-1,2,8:17.1
0,2,8:17.1
0,3,8:18
0,4,8:106.4
1,3,8:106.2
-1,3,8:106.8
-1,1,8:39
-1,0,8:31.2
0,-2,8:39
-2,-2,8:106.2
-4,-2,8:106.8
-3,-3,8:106.1
-3,-2,9:18
-3,-1,9:17.1
0,2,9:17.1
0,3,9:18
0,4,9:106.4
1,3,9:106.2
-2,-2,9:106.2
-4,-2,9:106.8
-3,-3,9:106.1
-3,-2,10:18
-3,-1,10:17.1
0,2,10:18
0,3,10:18
0,4,10:106.4
1,3,10:106.2
-1,3,10:106.8
-1,2,10:106.8
-2,-2,10:106.2
-4,-2,10:106.8
-3,-3,10:106.1
-3,-2,11:18
-3,-1,11:18
0,3,11:40
-2,-1,11:106.2
-4,-1,11:106.8
-2,-2,11:106.2
-4,-2,11:106.8
-3,-3,11:106.1
