[META]
version=2.0
spawnOnBlockType=2
spawnSunlight=True
spawnDarkness=True
spawnWater=False
spawnLava=False
underFill=False
randomRotation=True
dig=True
tree=False
branch=False
needsFoundation=True
rarity=200
collisionPercentage=70
spawnElevationMin=0
spawnElevationMax=102
spawnInBiome=All
[DATA]
0,-2,-5:1.0
-1,-1,-5:1.0
0,-1,-5:1.0
1,-1,-5:1.0
-1,0,-5:1.0
0,0,-5:1.0
1,0,-5:1.0
2,0,-5:1.0
-2,1,-5:1.0
-1,1,-5:1.0
0,1,-5:1.0
1,1,-5:1.0
-1,2,-5:1.0
0,2,-5:1.0
1,2,-5:1.0
2,2,-5:1.0
0,3,-5:1.0
1,3,-5:1.0
2,3,-5:1.0
2,-3,-4:1.0
-1,-2,-4:1.0
0,-2,-4:1.0
1,-2,-4:1.0
2,-2,-4:1.0
3,-2,-4:1.0
-2,-1,-4:1.0
-1,-1,-4:1.0
0,-1,-4:1.0
1,-1,-4:1.0
2,-1,-4:1.0
3,-1,-4:1.0
-2,0,-4:1.0
-1,0,-4:1.0
0,0,-4:1.0
1,0,-4:1.0
2,0,-4:1.0
-3,1,-4:1.0
-2,1,-4:1.0
-1,1,-4:1.0
0,1,-4:1.0
1,1,-4:1.0
2,1,-4:1.0
3,1,-4:1.0
-2,2,-4:1.0
-1,2,-4:1.0
0,2,-4:1.0
1,2,-4:1.0
2,2,-4:1.0
-3,3,-4:1.0
-2,3,-4:1.0
-1,3,-4:1.0
0,3,-4:1.0
1,3,-4:1.0
2,3,-4:1.0
3,3,-4:1.0
0,4,-4:1.0
2,4,-4:1.0
2,-4,-3:1.0
3,-4,-3:1.0
4,-4,-3:1.0
-1,-3,-3:1.0
0,-3,-3:1.0
1,-3,-3:1.0
2,-3,-3:1.0
3,-3,-3:1.0
-2,-2,-3:1.0
-1,-2,-3:1.0
0,-2,-3:1.0
1,-2,-3:1.0
2,-2,-3:1.0
3,-2,-3:1.0
-3,-1,-3:1.0
-2,-1,-3:1.0
-1,-1,-3:1.0
0,-1,-3:1.0
1,-1,-3:1.0
2,-1,-3:1.0
3,-1,-3:1.0
-3,0,-3:1.0
-2,0,-3:1.0
-1,0,-3:1.0
0,0,-3:1.0
1,0,-3:1.0
2,0,-3:1.0
3,0,-3:1.0
4,0,-3:1.0
-4,1,-3:1.0
-3,1,-3:1.0
-2,1,-3:1.0
-1,1,-3:1.0
0,1,-3:1.0
1,1,-3:1.0
2,1,-3:1.0
3,1,-3:1.0
4,1,-3:1.0
-3,2,-3:1.0
-2,2,-3:1.0
-1,2,-3:1.0
0,2,-3:1.0
1,2,-3:1.0
2,2,-3:1.0
3,2,-3:1.0
4,2,-3:1.0
-4,3,-3:1.0
-3,3,-3:1.0
-2,3,-3:1.0
-1,3,-3:1.0
0,3,-3:1.0
1,3,-3:1.0
2,3,-3:1.0
3,3,-3:1.0
4,3,-3:1.0
-3,4,-3:1.0
-2,4,-3:1.0
-1,4,-3:1.0
0,4,-3:1.0
1,4,-3:1.0
2,4,-3:1.0
3,4,-3:1.0
4,4,-3:1.0
-2,5,-3:1.0
2,5,-3:1.0
3,-5,-2:1.0
4,-5,-2:1.0
1,-4,-2:1.0
2,-4,-2:1.0
3,-4,-2:1.0
4,-4,-2:1.0
5,-4,-2:1.0
-2,-3,-2:1.0
-1,-3,-2:1.0
0,-3,-2:1.0
1,-3,-2:1.0
2,-3,-2:1.0
3,-3,-2:1.0
4,-3,-2:1.0
-3,-2,-2:1.0
-2,-2,-2:1.0
-1,-2,-2:1.0
0,-2,-2:1.0
1,-2,-2:1.0
2,-2,-2:1.0
3,-2,-2:1.0
4,-2,-2:1.0
-4,-1,-2:1.0
-3,-1,-2:1.0
-2,-1,-2:1.0
-1,-1,-2:1.0
0,-1,-2:1.0
1,-1,-2:1.0
2,-1,-2:1.0
3,-1,-2:1.0
4,-1,-2:1.0
-4,0,-2:1.0
-3,0,-2:1.0
-2,0,-2:1.0
-1,0,-2:1.0
0,0,-2:1.0
1,0,-2:1.0
2,0,-2:1.0
3,0,-2:1.0
4,0,-2:1.0
5,0,-2:1.0
-5,1,-2:1.0
-4,1,-2:1.0
-3,1,-2:1.0
-2,1,-2:1.0
-1,1,-2:1.0
0,1,-2:1.0
1,1,-2:1.0
2,1,-2:1.0
3,1,-2:1.0
4,1,-2:1.0
5,1,-2:1.0
-4,2,-2:1.0
-3,2,-2:1.0
-2,2,-2:1.0
-1,2,-2:1.0
0,2,-2:1.0
1,2,-2:1.0
2,2,-2:1.0
3,2,-2:1.0
4,2,-2:1.0
5,2,-2:1.0
-5,3,-2:1.0
-4,3,-2:1.0
-3,3,-2:1.0
-2,3,-2:1.0
-1,3,-2:1.0
0,3,-2:1.0
1,3,-2:1.0
2,3,-2:1.0
3,3,-2:1.0
4,3,-2:1.0
5,3,-2:1.0
-4,4,-2:1.0
-3,4,-2:1.0
-2,4,-2:1.0
-1,4,-2:1.0
0,4,-2:1.0
1,4,-2:1.0
2,4,-2:1.0
3,4,-2:1.0
4,4,-2:1.0
-3,5,-2:1.0
-2,5,-2:1.0
-1,5,-2:1.0
0,5,-2:1.0
1,5,-2:1.0
2,5,-2:1.0
3,5,-2:1.0
-2,6,-2:1.0
2,6,-2:1.0
3,-6,-1:2.0
4,-6,-1:2.0
5,-6,-1:2.0
1,-5,-1:2.0
2,-5,-1:2.0
3,-5,-1:2.0
4,-5,-1:2.0
5,-5,-1:2.0
6,-5,-1:2.0
-1,-4,-1:2.0
0,-4,-1:2.0
1,-4,-1:2.0
2,-4,-1:2.0
3,-4,-1:2.0
4,-4,-1:3.0
5,-4,-1:2.0
-2,-3,-1:2.0
-1,-3,-1:2.0
0,-3,-1:2.0
1,-3,-1:2.0
2,-3,-1:2.0
3,-3,-1:2.0
4,-3,-1:2.0
-3,-2,-1:2.0
-2,-2,-1:2.0
-1,-2,-1:2.0
0,-2,-1:2.0
1,-2,-1:2.0
2,-2,-1:2.0
3,-2,-1:2.0
4,-2,-1:2.0
-4,-1,-1:2.0
-3,-1,-1:2.0
-2,-1,-1:2.0
-1,-1,-1:2.0
0,-1,-1:2.0
1,-1,-1:2.0
2,-1,-1:2.0
3,-1,-1:2.0
4,-1,-1:2.0
-5,0,-1:2.0
-4,0,-1:2.0
-3,0,-1:2.0
-2,0,-1:2.0
-1,0,-1:2.0
0,0,-1:3.0
1,0,-1:3.0
2,0,-1:2.0
3,0,-1:2.0
4,0,-1:2.0
5,0,-1:2.0
-6,1,-1:2.0
-5,1,-1:2.0
-4,1,-1:2.0
-3,1,-1:2.0
-2,1,-1:2.0
-1,1,-1:2.0
0,1,-1:3.0
1,1,-1:3.0
2,1,-1:2.0
3,1,-1:2.0
4,1,-1:2.0
5,1,-1:2.0
-5,2,-1:2.0
-4,2,-1:2.0
-3,2,-1:2.0
-2,2,-1:2.0
-1,2,-1:2.0
0,2,-1:2.0
1,2,-1:2.0
2,2,-1:2.0
3,2,-1:2.0
4,2,-1:2.0
5,2,-1:2.0
-4,3,-1:2.0
-3,3,-1:2.0
-2,3,-1:2.0
-1,3,-1:2.0
0,3,-1:2.0
1,3,-1:2.0
2,3,-1:2.0
3,3,-1:2.0
4,3,-1:2.0
5,3,-1:2.0
-4,4,-1:2.0
-3,4,-1:3.0
-2,4,-1:2.0
-1,4,-1:2.0
0,4,-1:2.0
1,4,-1:2.0
2,4,-1:2.5
3,4,-1:2.5
4,4,-1:2.0
5,4,-1:2.0
-4,5,-1:2.0
-3,5,-1:2.0
-2,5,-1:2.0
-1,5,-1:2.0
0,5,-1:2.0
1,5,-1:2.0
2,5,-1:2.0
3,5,-1:2.0
4,5,-1:2.0
-2,6,-1:2.0
-1,6,-1:2.0
2,6,-1:2.0
3,6,-1:2.0
4,-6,0:18.6
5,-6,0:18.14
2,-5,0:18.14
3,-5,0:18.14
0,-4,0:18.14
4,-4,0:17.3
0,-3,0:18.6
3,-3,0:18.6
-2,-2,0:18.14
1,-2,0:18.14
-3,-1,0:18.14
-1,-1,0:18.6
2,-1,0:18.14
4,-1,0:18.6
-4,0,0:18.14
0,0,0:17.3
1,0,0:17.3
-4,1,0:18.14
-2,1,0:18.6
0,1,0:17.3
1,1,0:17.3
2,1,0:18.6
4,1,0:18.6
-4,2,0:18.14
-2,3,0:18.14
-1,3,0:18.14
2,3,0:18.14
-3,4,0:17.3
2,4,0:18.14
3,4,0:18.14
1,5,0:18.14
2,5,0:18.6
-2,6,0:18.6
4,-4,1:17.3
0,0,1:17.3
1,0,1:17.3
0,1,1:17.3
1,1,1:17.3
-1,3,1:18.6
-3,4,1:17.3
4,-4,2:17.3
0,0,2:17.3
1,0,2:17.3
0,1,2:17.3
1,1,2:17.3
-3,4,2:17.3
3,-6,3:18.3
4,-6,3:18.3
5,-6,3:18.3
6,-6,3:18.3
2,-5,3:18.3
3,-5,3:18.3
4,-5,3:18.3
5,-5,3:18.3
6,-5,3:18.3
2,-4,3:18.3
3,-4,3:18.3
4,-4,3:17.3
5,-4,3:18.3
6,-4,3:18.3
2,-3,3:18.3
3,-3,3:18.3
4,-3,3:18.3
5,-3,3:18.3
6,-3,3:18.3
3,-2,3:18.3
4,-2,3:18.3
5,-2,3:18.3
0,0,3:17.3
1,0,3:17.3
0,1,3:17.3
1,1,3:17.3
-3,4,3:17.3
2,-6,4:18.3
3,-6,4:18.3
4,-6,4:18.3
5,-6,4:18.3
2,-5,4:18.3
3,-5,4:18.3
4,-5,4:18.3
5,-5,4:18.3
6,-5,4:18.3
2,-4,4:18.3
3,-4,4:18.3
4,-4,4:17.3
5,-4,4:18.3
6,-4,4:18.3
2,-3,4:18.3
3,-3,4:18.3
4,-3,4:18.3
5,-3,4:18.3
6,-3,4:18.3
2,-2,4:18.3
3,-2,4:18.3
4,-2,4:18.3
5,-2,4:18.3
6,-2,4:18.3
0,0,4:17.3
1,0,4:17.3
0,1,4:17.3
1,1,4:17.3
-3,4,4:17.3
3,-5,5:18.3
4,-5,5:18.3
5,-5,5:18.3
3,-4,5:18.3
4,-4,5:17.3
5,-4,5:18.3
4,-3,5:18.3
5,-3,5:18.3
0,0,5:17.3
1,0,5:17.3
0,1,5:17.3
1,1,5:17.3
-3,4,5:17.3
4,-5,6:18.3
3,-4,6:18.3
4,-4,6:18.3
5,-4,6:18.3
4,-3,6:18.3
0,0,6:17.3
1,0,6:17.3
0,1,6:17.3
1,1,6:17.3
-3,4,6:17.3
0,0,7:17.3
1,0,7:17.3
0,1,7:17.3
1,1,7:17.3
-5,2,7:18.3
-4,2,7:18.3
-3,2,7:18.3
-2,2,7:18.3
-1,2,7:18.3
-5,3,7:18.3
-4,3,7:18.3
-3,3,7:18.3
-2,3,7:18.3
-1,3,7:18.3
-5,4,7:18.3
-4,4,7:18.3
-3,4,7:17.3
-2,4,7:18.3
-1,4,7:18.3
-5,5,7:18.3
-4,5,7:18.3
-3,5,7:18.3
-2,5,7:18.3
-1,5,7:18.3
-4,6,7:18.3
-2,6,7:18.3
-1,6,7:18.3
0,0,8:17.3
1,0,8:17.3
0,1,8:17.3
1,1,8:17.3
-4,2,8:18.3
-3,2,8:18.3
-2,2,8:18.3
-1,2,8:18.3
-5,3,8:18.3
-4,3,8:18.3
-3,3,8:18.3
-1,3,8:18.3
-5,4,8:18.3
-4,4,8:18.3
-3,4,8:17.3
-2,4,8:18.3
-1,4,8:18.3
-5,5,8:18.3
-4,5,8:18.3
-3,5,8:18.3
-2,5,8:18.3
-1,5,8:18.3
-5,6,8:18.3
-4,6,8:18.3
-3,6,8:18.3
-2,6,8:18.3
-1,6,8:18.3
3,-4,9:18.3
4,-4,9:18.3
2,-3,9:18.3
3,-3,9:18.3
4,-3,9:18.3
5,-3,9:18.3
1,-2,9:18.3
2,-2,9:18.3
3,-2,9:18.3
4,-2,9:18.3
5,-2,9:18.3
2,-1,9:18.3
3,-1,9:18.3
4,-1,9:18.3
5,-1,9:18.3
6,-1,9:18.3
0,0,9:17.3
1,0,9:17.3
3,0,9:17.3
4,0,9:18.3
5,0,9:18.3
6,0,9:18.3
0,1,9:17.3
1,1,9:17.3
5,1,9:18.3
-4,3,9:18.3
-3,3,9:18.3
-4,4,9:18.3
-3,4,9:17.3
-2,4,9:18.3
-3,5,9:18.3
3,-4,10:18.3
4,-4,10:18.3
3,-3,10:18.3
4,-3,10:18.3
5,-3,10:18.3
2,-2,10:18.3
3,-2,10:18.3
4,-2,10:18.3
5,-2,10:18.3
6,-2,10:18.3
3,-1,10:18.3
4,-1,10:17.3
5,-1,10:18.3
0,0,10:17.3
1,0,10:17.3
3,0,10:18.3
4,0,10:18.3
5,0,10:18.3
0,1,10:17.3
1,1,10:17.3
3,1,10:18.3
2,2,10:17.3
-3,3,10:18.3
-4,4,10:18.3
-3,4,10:18.3
-2,4,10:18.3
-3,5,10:18.3
3,-3,11:18.3
4,-3,11:18.3
2,-2,11:18.3
3,-2,11:18.3
4,-2,11:18.3
5,-2,11:18.3
2,-1,11:18.3
3,-1,11:18.3
4,-1,11:18.3
5,-1,11:18.3
0,0,11:17.3
1,0,11:17.3
3,0,11:18.3
5,0,11:18.3
0,1,11:17.3
1,1,11:17.3
2,1,11:18.3
3,1,11:18.3
4,1,11:18.3
5,1,11:18.3
2,2,11:18.3
3,2,11:17.3
4,2,11:18.3
5,2,11:18.3
1,3,11:18.3
2,3,11:18.3
3,3,11:18.3
4,3,11:17.3
5,3,11:18.3
6,3,11:18.3
1,4,11:18.3
2,4,11:18.3
3,4,11:18.3
4,4,11:18.3
5,4,11:18.3
6,4,11:18.3
2,5,11:18.3
3,5,11:18.3
5,5,11:18.3
0,0,12:17.3
1,0,12:17.3
3,0,12:18.3
4,0,12:18.3
0,1,12:17.3
1,1,12:17.3
3,1,12:18.3
4,1,12:18.3
5,1,12:18.3
2,2,12:18.3
3,2,12:18.3
4,2,12:18.3
5,2,12:18.3
6,2,12:18.3
1,3,12:18.3
2,3,12:18.3
3,3,12:18.3
4,3,12:17.3
5,3,12:18.3
1,4,12:18.3
2,4,12:18.3
3,4,12:18.3
4,4,12:18.3
5,4,12:18.3
3,5,12:18.3
0,0,13:17.3
1,0,13:17.3
0,1,13:17.3
1,1,13:17.3
3,1,13:18.3
4,1,13:18.3
3,2,13:18.3
2,3,13:18.3
3,3,13:18.3
4,3,13:18.3
3,4,13:18.3
0,0,14:17.3
1,0,14:17.3
0,1,14:17.3
1,1,14:17.3
0,-5,15:18.3
-1,-4,15:18.3
0,-4,15:18.3
1,-4,15:18.3
-2,-3,15:18.3
-1,-3,15:18.3
0,-3,15:18.3
1,-3,15:18.3
2,-3,15:18.3
-3,-2,15:18.3
-2,-2,15:18.3
-1,-2,15:18.3
0,-2,15:18.3
1,-2,15:18.3
2,-2,15:18.3
-2,-1,15:18.3
-1,-1,15:18.3
0,0,15:17.3
1,0,15:17.3
0,1,15:17.3
1,1,15:17.3
1,-5,16:18.3
-1,-4,16:18.3
0,-4,16:18.3
1,-4,16:18.3
2,-4,16:18.3
-1,-3,16:18.3
0,-3,16:18.3
1,-3,16:18.3
2,-3,16:18.3
3,-3,16:18.3
-2,-2,16:18.3
-1,-2,16:18.3
0,-2,16:17.3
1,-2,16:18.3
2,-2,16:18.3
-1,-1,16:18.3
1,-1,16:18.3
2,-1,16:18.3
0,0,16:17.3
1,0,16:17.3
0,1,16:17.3
1,1,16:17.3
0,-4,17:18.3
1,-4,17:18.3
-1,-3,17:18.3
0,-3,17:18.3
1,-3,17:18.3
2,-3,17:18.3
-1,-2,17:18.3
1,-2,17:18.3
0,0,17:17.3
1,0,17:17.3
0,1,17:17.3
1,1,17:17.3
0,-4,18:18.3
1,-4,18:18.3
-1,-3,18:18.3
0,-3,18:18.3
1,-3,18:18.3
2,-3,18:18.3
-2,-2,18:18.3
-1,-2,18:18.3
0,-2,18:18.3
1,-2,18:18.3
2,-2,18:18.3
3,-2,18:18.3
-2,-1,18:18.3
-1,-1,18:18.3
1,-1,18:18.3
2,-1,18:18.3
3,-1,18:18.3
4,-1,18:18.3
-3,0,18:18.3
-2,0,18:18.3
0,0,18:17.3
1,0,18:17.3
2,0,18:18.3
3,0,18:18.3
4,0,18:18.3
5,0,18:18.3
-4,1,18:18.3
-3,1,18:18.3
-2,1,18:18.3
-1,1,18:18.3
0,1,18:17.3
1,1,18:17.3
3,1,18:18.3
4,1,18:18.3
-3,2,18:18.3
-2,2,18:18.3
-1,2,18:18.3
2,2,18:18.3
3,2,18:18.3
-2,3,18:18.3
-1,3,18:18.3
0,3,18:18.3
1,3,18:18.3
-1,4,18:18.3
0,-3,19:18.3
1,-3,19:18.3
-1,-2,19:18.3
0,-2,19:18.3
1,-2,19:18.3
2,-2,19:18.3
-1,-1,19:18.3
1,-1,19:18.3
2,-1,19:18.3
3,-1,19:18.3
-2,0,19:18.3
0,0,19:17.3
1,0,19:18.3
2,0,19:18.3
3,0,19:18.3
4,0,19:18.3
-3,1,19:18.3
-2,1,19:18.3
-1,1,19:18.3
0,1,19:18.3
1,1,19:18.3
2,1,19:18.3
3,1,19:18.3
4,1,19:18.3
-2,2,19:18.3
-1,2,19:18.3
0,2,19:18.3
1,2,19:18.3
2,2,19:18.3
3,2,19:18.3
-1,3,19:18.3
0,3,19:18.3
1,3,19:18.3
2,3,19:18.3
0,4,19:18.3
1,4,19:18.3
0,-3,20:18.3
-1,-2,20:18.3
0,-2,20:18.3
1,-2,20:18.3
-2,-1,20:18.3
-1,-1,20:18.3
0,-1,20:18.3
1,-1,20:18.3
2,-1,20:18.3
-3,0,20:18.3
-2,0,20:18.3
-1,0,20:18.3
0,0,20:18.3
1,0,20:18.3
2,0,20:18.3
-1,1,20:18.3
0,1,20:18.3
1,1,20:18.3
2,1,20:18.3
3,1,20:18.3
-1,2,20:18.3
0,2,20:18.3
1,2,20:18.3
0,3,20:18.3
1,3,20:18.3
-1,0,19:106.8
0,-1,19:106.1
0,2,18:106.4
2,1,18:106.2
-1,0,18:106.8
0,-1,18:106.1
0,2,17:106.4
2,1,17:106.2
-1,1,17:106.8
2,0,17:106.2
-1,0,17:106.8
1,-1,17:106.1
0,-1,17:106.1
1,2,16:106.4
0,2,16:106.4
2,1,16:106.2
-1,1,16:106.8
2,0,16:106.2
-1,0,16:106.8
0,-1,16:106.1
1,2,15:106.4
0,2,15:106.4
2,1,15:106.2
-1,1,15:106.8
2,0,15:106.2
-1,0,15:106.8
1,-1,15:106.1
0,-1,15:106.1
1,2,14:106.4
0,2,14:106.4
2,1,14:106.2
-1,1,14:106.8
2,0,14:106.2
-1,0,14:106.8
1,-1,14:106.1
0,-1,14:106.1
1,2,13:106.4
0,2,13:106.4
2,1,13:106.2
-1,1,13:106.8
2,0,13:106.2
-1,0,13:106.8
1,-1,13:106.1
0,-1,13:106.1
1,2,12:106.4
0,2,12:106.4
2,1,12:106.2
-1,1,12:106.8
2,0,12:106.2
-1,0,12:106.8
1,-1,12:106.1
0,-1,12:106.1
1,2,11:106.4
0,2,11:106.4
-1,1,11:106.8
2,0,11:106.2
-1,0,11:106.8
1,-1,11:106.1
0,-1,11:106.1
1,2,10:106.4
0,2,10:106.4
2,1,10:106.2
-1,1,10:106.8
2,0,10:106.2
-1,0,10:106.8
1,-1,10:106.1
0,-1,10:106.1
1,2,9:106.4
0,2,9:106.4
2,1,9:106.2
-1,1,9:106.8
2,0,9:106.2
-1,0,9:106.8
1,-1,9:106.1
0,-1,9:106.1
1,2,8:106.4
0,2,8:106.4
2,1,8:106.2
-1,1,8:106.8
2,0,8:106.2
-1,0,8:106.8
1,-1,8:106.1
0,-1,8:106.1
-3,6,7:106.4
0,4,7:106.2
1,2,7:106.4
0,2,7:106.4
2,1,7:106.2
-1,1,7:106.8
2,0,7:106.2
-1,0,7:106.8
1,-1,7:106.1
0,-1,7:106.1
-3,6,6:106.4
0,4,6:106.2
1,2,6:106.4
0,2,6:106.4
2,1,6:106.2
-1,1,6:106.8
2,0,6:106.2
-1,0,6:106.8
1,-1,6:106.1
0,-1,6:106.1
-3,6,5:106.4
0,4,5:106.2
1,2,5:106.4
0,2,5:106.4
2,1,5:106.2
-1,1,5:106.8
2,0,5:106.2
-1,0,5:106.8
1,-1,5:106.1
0,-1,5:106.1
-3,6,4:106.4
0,4,4:106.2
1,2,4:106.4
0,2,4:106.4
2,1,4:106.2
-1,1,4:106.8
2,0,4:106.2
-1,0,4:106.8
1,-1,4:106.1
0,-1,4:106.1
-3,6,3:106.4
0,4,3:106.2
1,2,3:106.4
0,2,3:106.4
2,1,3:106.2
-1,1,3:106.8
2,0,3:106.2
-1,0,3:106.8
4,-1,3:106.4
1,-1,3:106.1
0,-1,3:106.1
1,-4,3:106.8
-3,6,2:106.4
0,4,2:106.2
1,2,2:106.4
0,2,2:106.4
2,1,2:106.2
-1,1,2:106.8
2,0,2:106.2
-1,0,2:106.8
4,-1,2:106.4
1,-1,2:106.1
0,-1,2:106.1
3,-2,2:106.0
1,-4,2:106.8
4,-5,2:106.1
-3,6,1:106.4
0,4,1:106.2
1,2,1:106.4
0,2,1:106.4
2,1,1:106.2
-1,1,1:106.8
2,0,1:106.2
-1,0,1:106.8
4,-1,1:106.4
1,-1,1:106.1
0,-1,1:106.1
4,-3,1:106.4
5,-4,1:106.2
1,-4,1:106.8
4,-5,1:106.1
3,6,0:31.1
2,6,0:31.1
-1,6,0:31.1
-3,6,0:106.4
4,5,0:37.0
3,5,0:38.0
0,5,0:31.1
-1,5,0:31.2
-2,5,0:31.2
-3,5,0:31.1
-4,5,0:38.0
5,4,0:31.2
4,4,0:31.2
1,4,0:31.1
0,4,0:31.1
-1,4,0:31.1
-2,4,0:31.2
-4,4,0:31.2
5,3,0:37.0
4,3,0:31.1
3,3,0:31.1
1,3,0:31.2
0,3,0:31.1
3,2,0:31.1
2,2,0:31.1
1,2,0:31.1
0,2,0:31.2
-1,2,0:31.1
-2,2,0:31.1
-3,2,0:31.1
-5,2,0:31.1
5,1,0:31.1
3,1,0:31.1
-1,1,0:31.1
-3,1,0:31.1
-5,1,0:31.2
-6,1,0:31.1
5,0,0:37.0
4,0,0:31.1
3,0,0:31.2
2,0,0:31.1
-1,0,0:31.1
-2,0,0:31.1
-3,0,0:31.2
-5,0,0:31.1
3,-1,0:31.1
1,-1,0:38.0
0,-1,0:38.0
-2,-1,0:31.1
-4,-1,0:31.1
4,-2,0:31.1
3,-2,0:31.1
2,-2,0:31.2
0,-2,0:40.5
-1,-2,0:31.1
-3,-2,0:31.1
4,-3,0:106.4
2,-3,0:31.2
1,-3,0:31.2
-1,-3,0:31.1
5,-4,0:106.2
2,-4,0:31.1
1,-4,0:31.1
-1,-4,0:31.1
6,-5,0:31.1
5,-5,0:31.1
4,-5,0:31.1
1,-5,0:31.1
3,-6,0:31.2
-3,6,-1:106.12
-4,6,-1:106.4
-3,6,-2:106.12
-4,6,-2:106.4
-3,6,-3:106.12
-4,6,-3:106.4
-3,5,-3:106.8
-3,6,-4:106.12
-4,6,-4:106.4
-3,5,-4:106.8
-3,6,-5:106.8
