[META]
version=2.0
spawnOnBlockType=12,8,9
spawnSunlight=True
spawnDarkness=True
spawnWater=True
spawnLava=False
underFill=False
randomRotation=True
dig=True
tree=False
branch=False
needsFoundation=false
rarity=300
collisionPercentage=50
spawnElevationMin=60
spawnElevationMax=64
spawnInBiome=All
[DATA]
0,-1,-6:17.0
0,-3,-5:17.0
2,-3,-5:17.0
-2,-2,-5:17.0
0,-1,-5:17.0
3,-1,-5:17.0
-2,0,-5:17.0
1,1,-5:17.0
0,-5,-4:17.0
-2,-4,-4:17.0
-4,-3,-4:17.0
0,-3,-4:17.0
2,-3,-4:17.0
4,-3,-4:17.0
-2,-2,-4:17.0
0,-1,-4:17.0
3,-1,-4:17.0
-4,0,-4:17.0
-2,0,-4:17.0
1,1,-4:17.0
-3,2,-4:17.0
-1,2,-4:17.0
1,3,-4:17.0
0,-5,-3:17.0
-2,-4,-3:17.0
-4,-3,-3:17.0
0,-3,-3:17.0
2,-3,-3:17.0
4,-3,-3:17.0
-2,-2,-3:17.0
0,-1,-3:17.0
3,-1,-3:17.0
-4,0,-3:17.0
-2,0,-3:17.0
1,1,-3:17.0
3,1,-3:17.0
-3,2,-3:17.0
-1,2,-3:17.0
1,3,-3:17.0
0,-5,-2:17.0
-2,-4,-2:17.0
-4,-3,-2:17.0
0,-3,-2:17.0
2,-3,-2:17.0
4,-3,-2:17.0
-2,-2,-2:17.0
0,-1,-2:17.0
3,-1,-2:17.0
-4,0,-2:17.0
-2,0,-2:17.0
1,1,-2:17.0
3,1,-2:17.0
-3,2,-2:17.0
-1,2,-2:17.0
1,3,-2:17.0
0,-5,-1:17.0
-2,-4,-1:17.0
-4,-3,-1:17.0
0,-3,-1:17.0
2,-3,-1:17.0
4,-3,-1:17.0
-2,-2,-1:17.0
0,-1,-1:17.0
3,-1,-1:17.0
-4,0,-1:17.0
-2,0,-1:17.0
1,1,-1:17.0
3,1,-1:17.0
-3,2,-1:17.0
-1,2,-1:17.0
1,3,-1:17.0
0,-5,0:17.0
-2,-4,0:17.0
-4,-3,0:17.0
0,-3,0:17.0
2,-3,0:17.0
3,-3,0:17.0
-4,-2,0:17.0
-2,-2,0:17.0
0,-1,0:17.0
2,-1,0:17.0
3,-1,0:17.0
-4,0,0:17.0
-2,0,0:17.0
-3,1,0:17.0
1,1,0:17.0
3,1,0:17.0
-3,2,0:17.0
-1,2,0:17.0
1,3,0:17.0
-2,-4,1:17.0
0,-4,1:17.0
-3,-3,1:17.0
0,-3,1:17.0
2,-3,1:17.0
-2,-2,1:17.0
1,-2,1:17.0
0,-1,1:17.0
2,-1,1:17.0
-2,0,1:17.0
-3,1,1:17.0
1,1,1:17.0
2,1,1:17.0
-1,2,1:17.0
1,2,1:17.0
-2,-3,2:17.0
0,-3,2:17.0
-2,-2,2:17.0
1,-2,2:17.0
0,-1,2:17.0
1,-1,2:17.0
-2,0,2:17.0
-1,0,2:17.0
0,0,2:17.0
2,0,2:17.0
0,1,2:17.0
1,1,2:17.0
-1,-2,3:17.0
0,-2,3:17.0
-1,-1,3:17.0
0,-1,3:17.0
1,-1,3:17.0
0,0,3:17.0
0,-1,4:17.0
0,-1,5:17.0
0,-2,6:17.0
1,-2,6:17.0
-1,-1,6:17.0
0,-1,6:17.0
-2,-3,7:17.0
0,-3,7:17.0
2,-3,7:17.0
-3,-2,7:17.0
3,-2,7:17.0
-2,-1,7:17.0
0,-1,7:17.0
2,-1,7:17.0
-1,0,7:17.0
1,0,7:17.0
-2,1,7:17.0
0,1,7:17.0
-1,-6,8:18.12
0,-6,8:18.12
1,-6,8:18.12
-2,-5,8:18.12
-1,-5,8:18.12
0,-5,8:18.12
1,-5,8:18.12
2,-5,8:18.12
3,-5,8:18.12
-4,-4,8:18.12
-3,-4,8:18.12
-2,-4,8:18.12
-1,-4,8:17.0
1,-4,8:17.0
3,-4,8:18.12
4,-4,8:18.12
5,-4,8:18.12
-5,-3,8:18.12
-4,-3,8:18.12
-3,-3,8:17.0
0,-3,8:18.12
1,-3,8:17.0
3,-3,8:17.0
4,-3,8:18.12
5,-3,8:18.12
6,-3,8:18.12
-5,-2,8:18.12
-4,-2,8:18.12
-2,-2,8:18.12
-1,-2,8:17.0
1,-2,8:18.12
2,-2,8:17.0
3,-2,8:18.12
5,-2,8:18.12
6,-2,8:18.12
-5,-1,8:18.12
-4,-1,8:18.12
-3,-1,8:17.0
-2,-1,8:18.12
0,-1,8:17.0
2,-1,8:18.12
4,-1,8:17.0
5,-1,8:18.12
6,-1,8:18.12
-5,0,8:18.12
-4,0,8:17.0
-2,0,8:17.0
-1,0,8:18.12
0,0,8:17.0
1,0,8:18.12
3,0,8:17.0
4,0,8:18.12
5,0,8:18.12
-5,1,8:18.12
-4,1,8:18.12
0,1,8:18.12
2,1,8:17.0
3,1,8:18.12
4,1,8:18.12
5,1,8:18.12
-4,2,8:18.12
-3,2,8:18.12
-2,2,8:18.12
-1,2,8:17.0
1,2,8:17.0
2,2,8:18.12
3,2,8:18.12
4,2,8:18.12
-2,3,8:18.12
-1,3,8:18.12
0,3,8:18.12
1,3,8:18.12
2,3,8:18.12
0,-5,9:18.12
-2,-4,9:18.12
-1,-4,9:18.12
0,-4,9:18.12
1,-4,9:18.12
2,-4,9:18.12
3,-4,9:18.12
-4,-3,9:18.12
-3,-3,9:18.12
-2,-3,9:18.12
-1,-3,9:18.12
0,-3,9:18.12
1,-3,9:18.12
2,-3,9:18.12
3,-3,9:18.12
4,-3,9:18.12
-4,-2,9:18.12
-3,-2,9:18.12
-2,-2,9:18.12
-1,-2,9:18.12
0,-2,9:18.12
1,-2,9:18.12
2,-2,9:18.12
3,-2,9:18.12
4,-2,9:18.12
5,-2,9:18.12
-4,-1,9:18.12
-3,-1,9:18.12
-2,-1,9:18.12
-1,-1,9:18.12
0,-1,9:18.12
1,-1,9:18.12
2,-1,9:18.12
3,-1,9:18.12
4,-1,9:18.12
-4,0,9:18.12
-3,0,9:18.12
-2,0,9:18.12
-1,0,9:18.12
0,0,9:18.12
1,0,9:18.12
2,0,9:18.12
3,0,9:18.12
4,0,9:18.12
-4,1,9:18.12
-3,1,9:18.12
-2,1,9:18.12
-1,1,9:18.12
0,1,9:18.12
1,1,9:18.12
2,1,9:18.12
3,1,9:18.12
-2,2,9:18.12
-1,2,9:18.12
0,2,9:18.12
1,2,9:18.12
2,2,9:18.12
-1,-3,10:18.12
0,-3,10:18.12
1,-3,10:18.12
2,-3,10:18.12
-3,-2,10:18.12
-2,-2,10:18.12
-1,-2,10:18.12
0,-2,10:18.12
1,-2,10:18.12
2,-2,10:18.12
3,-2,10:18.12
-3,-1,10:18.12
-2,-1,10:18.12
-1,-1,10:18.12
0,-1,10:18.12
1,-1,10:18.12
2,-1,10:18.12
3,-1,10:18.12
-3,0,10:18.12
-2,0,10:18.12
-1,0,10:18.12
0,0,10:18.12
1,0,10:18.12
2,0,10:18.12
-1,1,10:18.12
0,1,10:18.12
1,1,10:18.12
0,-2,11:18.12
1,-2,11:18.12
-1,-1,11:18.12
0,-1,11:18.12
1,-1,11:18.12
-1,0,11:18.12
0,0,11:18.12
