[META]
version=2.0
spawnOnBlockType=2,3
spawnSunlight=True
spawnDarkness=True
spawnWater=False
spawnLava=False
underFill=False
randomRotation=False
dig=True
tree=False
branch=False
needsFoundation=True
rarity=30
collisionPercentage=2
spawnElevationMin=0
spawnElevationMax=240
spawnInBiome=All
[DATA]
-1,-1,-4:1.5
0,-1,-4:1.5
-1,0,-4:1.5
0,0,-4:1.5
-2,-2,-3:88.0
-1,-2,-3:1.5
0,-2,-3:1.5
-2,-1,-3:1.5
-1,-1,-3:3.0
0,-1,-3:88.0
1,-1,-3:88.0
-2,0,-3:88.0
-1,0,-3:1.5
0,0,-3:1.5
1,0,-3:88.0
-1,1,-3:88.0
0,1,-3:1.5
-2,-3,-2:88.0
-1,-3,-2:88.0
0,-3,-2:88.0
1,-3,-2:88.0
-3,-2,-2:88.0
-2,-2,-2:88.0
-1,-2,-2:88.0
0,-2,-2:88.0
1,-2,-2:88.0
2,-2,-2:88.0
-3,-1,-2:88.0
-2,-1,-2:88.0
-1,-1,-2:3.0
0,-1,-2:88.0
1,-1,-2:88.0
2,-1,-2:88.0
-3,0,-2:88.0
-2,0,-2:88.0
-1,0,-2:3.0
0,0,-2:88.0
1,0,-2:88.0
2,0,-2:88.0
-2,1,-2:88.0
-1,1,-2:3.0
0,1,-2:3.0
1,1,-2:3.0
-1,2,-2:88.0
0,2,-2:88.0
1,2,-2:88.0
-2,-4,-1:110.0
-1,-4,-1:110.0
0,-4,-1:110.0
1,-4,-1:110.0
-3,-3,-1:110.0
-2,-3,-1:110.0
-1,-3,-1:13.5
0,-3,-1:3.0
1,-3,-1:3.0
2,-3,-1:110.0
-4,-2,-1:110.0
-3,-2,-1:110.0
-2,-2,-1:13.5
-1,-2,-1:3.0
0,-2,-1:3.0
1,-2,-1:3.0
2,-2,-1:3.0
3,-2,-1:110.0
-4,-1,-1:110.0
-3,-1,-1:110.0
-2,-1,-1:88.0
-1,-1,-1:3.0
0,-1,-1:17.1
1,-1,-1:3.0
2,-1,-1:3.0
3,-1,-1:110.0
-4,0,-1:110.0
-3,0,-1:110.0
-2,0,-1:110.0
-1,0,-1:3.0
0,0,-1:3.0
1,0,-1:3.0
2,0,-1:3.0
3,0,-1:110.0
-3,1,-1:110.0
-2,1,-1:110.0
-1,1,-1:110.0
0,1,-1:3.0
1,1,-1:3.0
2,1,-1:110.0
-2,2,-1:110.0
-1,2,-1:110.0
0,2,-1:110.0
1,2,-1:110.0
-1,3,-1:110.0
0,3,-1:110.0
0,-3,0:88.0
1,-3,0:110.0
-1,-2,0:13.5
0,-2,0:88.0
1,-2,0:13.5
2,-2,0:110.0
-1,-1,0:17.1
0,-1,0:17.1
1,-1,0:13.5
2,-1,0:110.0
-1,0,0:17.1
0,0,0:17.1
1,0,0:17.1
2,0,0:17.1
0,1,0:17.1
1,1,0:17.1
0,-2,1:100.10
0,-1,1:17.1
0,0,1:17.1
1,0,1:17.1
0,-2,2:100.10
0,-1,2:30.0
0,0,2:17.1
1,0,2:17.1
0,1,2:17.1
1,1,2:17.1
-1,-4,3:100.1
0,-4,3:100.2
1,-4,3:100.3
-2,-3,3:100.1
2,-3,3:100.3
-2,-2,3:100.4
0,-2,3:100.10
2,-2,3:100.6
-2,-1,3:100.7
2,-1,3:100.9
-1,0,3:100.7
0,0,3:17.1
1,0,3:100.9
0,1,3:17.1
1,1,3:17.1
0,2,3:30.0
-1,-4,4:100.1
0,-4,4:100.2
1,-4,4:100.3
-2,-3,4:100.1
2,-3,4:100.3
-2,-2,4:100.4
0,-2,4:100.10
2,-2,4:100.6
-2,-1,4:100.7
2,-1,4:100.9
-1,0,4:100.7
0,0,4:100.8
1,0,4:100.9
-1,1,4:17.1
0,1,4:17.1
1,1,4:17.1
0,2,4:17.1
-1,-4,5:100.1
0,-4,5:100.2
1,-4,5:100.3
-2,-3,5:100.1
2,-3,5:100.3
-2,-2,5:100.4
0,-2,5:100.10
2,-2,5:100.6
-2,-1,5:100.7
2,-1,5:100.9
-2,0,5:17.1
-1,0,5:100.7
0,0,5:100.8
1,0,5:100.9
2,0,5:17.1
-1,1,5:17.1
0,1,5:17.1
1,1,5:17.1
0,2,5:17.1
0,3,5:17.1
-1,-3,6:100.1
0,-3,6:100.2
1,-3,6:100.3
-1,-2,6:100.4
0,-2,6:100.5
1,-2,6:100.6
-1,-1,6:100.7
0,-1,6:100.8
1,-1,6:100.9
2,-1,6:17.1
-2,0,6:17.1
2,0,6:17.1
0,1,6:17.1
0,2,6:30.0
0,3,6:17.1
2,-1,7:17.1
-2,0,7:17.1
0,0,7:17.1
0,1,7:17.1
0,3,7:30.0
-2,-1,8:30.0
-2,0,8:17.1
0,0,8:17.1
0,3,8:17.1
1,3,8:17.1
-2,-1,9:17.1
-2,0,9:17.1
1,3,9:17.1
-2,-1,10:17.1
-2,-1,11:17.1
2,-1,8:40.5
1,1,6:39.5
-1,1,6:39.5
0,-3,1:39.5
-2,-1,0:40.5
