[META]
version=2.0
spawnOnBlockType=2,3
spawnSunlight=True
spawnDarkness=True
spawnWater=False
spawnLava=False
underFill=False
randomRotation=True
dig=true
tree=false
branch=False
needsFoundation=True
rarity=50
collisionPercentage=50
spawnElevationMin=0
spawnElevationMax=116
spawnInBiome=All
[DATA]
-3,-1,-8:98.0
-2,-1,-8:98.0
-1,-1,-8:98.0
0,-1,-8:98.1
1,-1,-8:98.0
-3,0,-8:98.1
-2,0,-8:98.0
-1,0,-8:98.0
0,0,-8:98.1
1,0,-8:98.0
-3,1,-8:98.0
-2,1,-8:98.1
-1,1,-8:98.1
0,1,-8:98.0
1,1,-8:98.0
-3,2,-8:98.0
-2,2,-8:98.0
-1,2,-8:98.0
0,2,-8:98.1
1,2,-8:98.0
-3,3,-8:98.0
-2,3,-8:98.0
-1,3,-8:98.1
0,3,-8:98.0
1,3,-8:98.0
-3,-2,-7:98.0
-2,-2,-7:98.0
-1,-2,-7:98.1
0,-2,-7:98.1
1,-2,-7:98.0
-4,-1,-7:98.0
2,-1,-7:98.0
-4,0,-7:98.1
2,0,-7:98.0
-4,1,-7:98.1
2,1,-7:98.1
-4,2,-7:98.1
2,2,-7:98.0
-4,3,-7:98.0
2,3,-7:98.0
-3,4,-7:98.0
-2,4,-7:98.0
-1,4,-7:98.1
0,4,-7:98.0
1,4,-7:98.0
-3,-2,-6:98.0
-2,-2,-6:98.0
-1,-2,-6:17.1
0,-2,-6:98.0
1,-2,-6:98.0
-4,-1,-6:98.0
2,-1,-6:98.0
-4,0,-6:98.1
2,0,-6:98.0
-4,1,-6:17.1
2,1,-6:17.1
-4,2,-6:98.0
2,2,-6:98.0
-4,3,-6:98.0
2,3,-6:98.0
-3,4,-6:98.0
-2,4,-6:98.1
-1,4,-6:17.1
0,4,-6:98.1
1,4,-6:98.0
-2,-2,-5:3.5
-1,-2,-5:2.0
0,-2,-5:2.0
-3,-1,-5:98.2
-2,-1,-5:98.2
-1,-1,-5:17.1
0,-1,-5:98.2
1,-1,-5:98.2
-4,0,-5:3.5
-3,0,-5:98.2
1,0,-5:98.2
-4,1,-5:3.5
-3,1,-5:17.1
1,1,-5:17.1
-4,2,-5:3.5
-3,2,-5:98.2
1,2,-5:98.2
-3,3,-5:98.2
-2,3,-5:98.2
-1,3,-5:17.1
0,3,-5:98.2
1,3,-5:98.2
-2,-1,-4:3.5
-1,-1,-4:3.5
0,-1,-4:3.5
1,-1,-4:2.0
-3,0,-4:3.5
-2,0,-4:17.1
-1,0,-4:17.1
0,0,-4:17.1
1,0,-4:2.0
-3,1,-4:3.5
-2,1,-4:17.1
0,1,-4:17.1
-2,2,-4:17.1
-1,2,-4:17.1
0,2,-4:17.1
1,2,-4:3.5
-1,3,-4:3.5
-2,-3,-3:17.1
1,-2,-3:17.1
-2,-1,-3:3.5
-1,-1,-3:3.5
0,-1,-3:17.1
-3,0,-3:3.5
-2,0,-3:3.5
-1,0,-3:17.1
0,0,-3:3.5
4,0,-3:17.1
-4,1,-3:3.5
-3,1,-3:3.5
-2,1,-3:17.1
0,1,-3:17.1
1,1,-3:3.5
-5,2,-3:17.1
-4,2,-3:3.5
-3,2,-3:3.5
-2,2,-3:17.1
-1,2,-3:17.1
0,2,-3:3.5
1,2,-3:3.5
-2,3,-3:3.5
-1,3,-3:3.5
0,3,-3:3.5
2,3,-3:17.1
-2,-2,-2:17.1
0,-2,-2:17.1
-3,-1,-2:3.5
-2,-1,-2:3.5
-1,-1,-2:3.5
0,-1,-2:3.5
1,-1,-2:3.5
-4,0,-2:3.5
-3,0,-2:3.5
-2,0,-2:3.5
-1,0,-2:17.1
0,0,-2:3.5
1,0,-2:3.5
2,0,-2:3.5
3,0,-2:17.1
-4,1,-2:3.5
-3,1,-2:3.5
-2,1,-2:17.1
0,1,-2:17.1
1,1,-2:3.5
-4,2,-2:17.1
-3,2,-2:17.1
-2,2,-2:3.5
-1,2,-2:17.1
0,2,-2:3.5
1,2,-2:3.5
-2,3,-2:3.5
-1,3,-2:3.5
0,3,-2:3.5
1,3,-2:17.1
-1,4,-2:3.5
1,4,-2:17.1
-3,-2,-1:2.5
-2,-2,-1:17.1
-1,-2,-1:2.5
0,-2,-1:17.1
1,-2,-1:2.5
-4,-1,-1:2.5
-3,-1,-1:17.1
-2,-1,-1:17.1
-1,-1,-1:17.1
0,-1,-1:17.1
1,-1,-1:2.5
2,-1,-1:2.5
-4,0,-1:17.1
-3,0,-1:17.1
-2,0,-1:17.1
-1,0,-1:17.1
0,0,-1:17.1
1,0,-1:17.1
2,0,-1:17.1
-4,1,-1:2.5
-3,1,-1:2.5
-2,1,-1:17.1
0,1,-1:17.1
1,1,-1:17.1
2,1,-1:2.5
-4,2,-1:17.1
-3,2,-1:17.1
-2,2,-1:17.1
-1,2,-1:17.1
0,2,-1:17.1
1,2,-1:17.1
2,2,-1:17.1
-4,3,-1:2.5
-3,3,-1:2.5
-2,3,-1:17.1
-1,3,-1:17.1
0,3,-1:17.1
1,3,-1:17.1
2,3,-1:2.5
-3,4,-1:2.5
-2,4,-1:17.1
-1,4,-1:2.5
0,4,-1:17.1
1,4,-1:2.5
-2,-1,0:17.1
0,-1,0:17.1
-3,0,0:17.1
-2,0,0:17.1
-1,0,0:17.1
0,0,0:17.1
1,0,0:17.1
0,1,0:17.1
-3,2,0:17.1
-2,2,0:17.1
-1,2,0:17.1
0,2,0:17.1
1,2,0:17.1
-2,3,0:17.1
0,3,0:17.1
-2,0,1:17.1
-1,0,1:17.1
0,0,1:17.1
0,1,1:17.1
-2,2,1:17.1
-1,2,1:17.1
0,2,1:17.1
-2,0,2:17.1
-1,0,2:17.1
0,0,2:17.1
-2,1,2:17.1
0,1,2:17.1
-2,2,2:17.1
-1,2,2:17.1
0,2,2:17.1
-2,0,3:17.1
-1,0,3:17.1
0,0,3:17.1
-2,1,3:17.1
-1,1,3:17.1
0,1,3:17.1
-2,2,3:17.1
-1,2,3:17.1
0,2,3:17.1
-2,0,4:17.1
-1,0,4:17.1
0,0,4:17.1
-2,1,4:17.1
-1,1,4:17.1
0,1,4:17.1
-2,2,4:17.1
-1,2,4:17.1
0,2,4:17.1
-2,0,5:17.1
-1,0,5:17.1
0,0,5:17.1
-2,1,5:17.1
-1,1,5:17.1
0,1,5:17.1
-2,2,5:17.1
-1,2,5:17.1
0,2,5:17.1
-3,-2,6:18.12
-2,-2,6:18.12
-1,-2,6:18.12
-4,-1,6:18.12
-3,-1,6:17.1
-2,-1,6:17.1
-1,-1,6:17.1
0,-1,6:18.12
-4,0,6:18.12
-3,0,6:17.1
-2,0,6:17.1
-1,0,6:17.1
0,0,6:18.12
-3,1,6:18.12
-2,1,6:17.1
-1,1,6:17.1
0,1,6:17.1
-2,2,6:17.1
-1,2,6:17.1
0,2,6:17.1
1,2,6:17.1
-1,3,6:18.4
0,3,6:17.1
1,3,6:17.1
1,4,6:18.12
-2,-4,7:18.12
-1,-4,7:18.12
-3,-3,7:18.12
-2,-3,7:18.12
-1,-3,7:18.12
0,-3,7:18.12
-4,-2,7:18.12
-3,-2,7:18.12
-2,-2,7:17.1
-1,-2,7:17.1
0,-2,7:18.12
1,-2,7:18.12
-4,-1,7:18.12
-3,-1,7:17.1
-2,-1,7:17.1
-1,-1,7:17.1
0,-1,7:18.12
-5,0,7:18.12
-4,0,7:17.1
-3,0,7:18.12
-2,0,7:17.1
-1,0,7:17.1
0,0,7:18.12
1,0,7:18.12
-4,1,7:18.4
-3,1,7:18.12
-2,1,7:17.1
-1,1,7:17.1
0,1,7:17.1
1,1,7:18.12
-2,2,7:18.12
-1,2,7:18.12
0,2,7:17.1
1,2,7:17.1
2,2,7:18.12
-3,3,7:18.12
-2,3,7:18.12
-1,3,7:18.12
0,3,7:17.1
1,3,7:17.1
2,3,7:18.12
0,4,7:18.12
1,4,7:17.1
2,4,7:18.12
1,5,7:18.12
-2,-5,8:18.12
-4,-4,8:18.12
-3,-4,8:18.12
-2,-4,8:18.12
-1,-4,8:18.12
0,-4,8:18.12
-5,-3,8:18.12
-4,-3,8:18.12
-3,-3,8:17.1
-2,-3,8:17.1
-1,-3,8:18.12
0,-3,8:18.12
1,-3,8:18.12
2,-3,8:18.12
-5,-2,8:18.12
-4,-2,8:18.12
-3,-2,8:18.12
-2,-2,8:17.1
-1,-2,8:17.1
0,-2,8:17.1
1,-2,8:17.1
2,-2,8:18.12
-5,-1,8:18.12
-4,-1,8:17.1
-3,-1,8:18.12
-2,-1,8:17.1
-1,-1,8:17.1
0,-1,8:18.12
1,-1,8:18.12
2,-1,8:18.12
-5,0,8:18.12
-4,0,8:18.12
-2,0,8:18.12
-1,0,8:18.12
0,0,8:18.12
1,0,8:18.12
2,0,8:18.12
-4,1,8:18.12
-3,1,8:18.12
-2,1,8:17.1
-1,1,8:17.1
0,1,8:18.12
1,1,8:18.12
-3,2,8:18.12
-2,2,8:17.1
-1,2,8:18.12
0,2,8:18.12
1,2,8:18.12
2,2,8:18.12
-4,3,8:18.12
-3,3,8:17.1
-2,3,8:17.1
-1,3,8:18.12
0,3,8:18.12
1,3,8:18.12
2,3,8:18.12
3,3,8:18.12
-3,4,8:18.4
-2,4,8:18.12
0,4,8:18.12
1,4,8:17.1
2,4,8:18.12
-2,5,8:18.12
1,5,8:18.12
2,5,8:18.4
-5,-5,9:18.12
-4,-5,9:18.12
-3,-5,9:18.12
-5,-4,9:18.12
-4,-4,9:17.1
-3,-4,9:18.12
-2,-4,9:18.12
-1,-4,9:18.12
0,-4,9:18.12
1,-4,9:18.12
2,-4,9:18.12
-5,-3,9:18.12
-4,-3,9:18.12
-3,-3,9:17.1
-2,-3,9:18.12
-1,-3,9:18.12
0,-3,9:18.12
1,-3,9:18.12
2,-3,9:17.1
3,-3,9:18.4
-6,-2,9:18.4
-5,-2,9:18.12
-4,-2,9:18.12
-3,-2,9:18.12
-2,-2,9:18.12
-1,-2,9:18.12
0,-2,9:18.12
1,-2,9:17.1
2,-2,9:18.12
-6,-1,9:18.12
-5,-1,9:17.1
-4,-1,9:18.12
-3,-1,9:18.12
-2,-1,9:18.12
-1,-1,9:18.12
0,-1,9:18.12
1,-1,9:18.12
2,-1,9:18.12
3,-1,9:18.12
-6,0,9:18.4
-5,0,9:18.12
-3,0,9:18.12
-2,0,9:18.12
-1,0,9:18.12
0,0,9:18.12
1,0,9:18.12
2,0,9:18.12
3,0,9:18.12
-4,1,9:18.12
-3,1,9:17.1
-2,1,9:18.12
-1,1,9:18.12
0,1,9:17.1
1,1,9:18.12
2,1,9:18.12
3,1,9:18.12
-4,2,9:18.12
-3,2,9:18.12
-2,2,9:18.12
-1,2,9:18.12
0,2,9:18.12
1,2,9:18.12
2,2,9:18.12
3,2,9:18.12
-3,3,9:18.12
-2,3,9:18.12
-1,3,9:18.12
0,3,9:18.12
1,3,9:18.12
2,3,9:18.12
-3,4,9:18.12
-2,4,9:17.1
-1,4,9:18.12
0,4,9:18.12
1,4,9:17.1
2,4,9:18.12
-2,5,9:18.12
1,5,9:18.12
2,5,9:17.1
3,5,9:18.12
-2,6,9:18.12
2,6,9:18.12
-4,-5,10:18.12
-5,-4,10:18.12
-4,-4,10:17.1
-3,-4,10:18.12
3,-4,10:18.12
-4,-3,10:18.12
-3,-3,10:18.12
-2,-3,10:18.12
-1,-3,10:18.12
2,-3,10:18.12
3,-3,10:17.1
4,-3,10:18.12
-4,-2,10:18.4
-3,-2,10:18.12
-2,-2,10:18.12
-1,-2,10:18.12
0,-2,10:18.12
1,-2,10:18.12
3,-2,10:18.12
-5,-1,10:18.12
-4,-1,10:18.12
-3,-1,10:18.12
-2,-1,10:18.12
-1,-1,10:18.12
0,-1,10:18.12
1,-1,10:18.12
-4,0,10:18.4
-3,0,10:18.12
-2,0,10:18.12
0,0,10:17.1
1,0,10:18.12
-5,1,10:18.12
-4,1,10:17.1
-3,1,10:18.12
-2,1,10:18.12
-1,1,10:18.12
0,1,10:18.12
1,1,10:17.1
2,1,10:18.12
-4,2,10:18.12
-3,2,10:18.12
-2,2,10:18.12
-1,2,10:18.12
0,2,10:18.12
1,2,10:18.12
-3,3,10:18.12
-2,3,10:18.12
-1,3,10:18.4
1,3,10:18.12
2,3,10:18.12
3,3,10:18.12
-3,4,10:18.12
-2,4,10:18.12
1,4,10:18.12
2,4,10:18.4
-2,5,10:18.12
1,5,10:18.12
2,5,10:17.1
3,5,10:18.12
2,6,10:18.12
-4,-4,11:18.12
3,-3,11:18.12
-2,-2,11:18.12
-1,-2,11:18.4
-3,-1,11:18.12
-2,-1,11:18.12
-1,-1,11:18.12
0,-1,11:18.12
-3,0,11:18.12
-2,0,11:18.12
-1,0,11:17.1
0,0,11:18.12
1,0,11:18.12
2,0,11:18.12
-4,1,11:18.12
-3,1,11:18.12
-2,1,11:18.12
-1,1,11:18.12
0,1,11:18.4
1,1,11:18.12
2,1,11:17.1
3,1,11:18.12
-5,2,11:18.12
-4,2,11:17.1
-3,2,11:18.12
-2,2,11:18.12
1,2,11:18.12
2,2,11:18.12
-4,3,11:18.12
-3,3,11:18.4
2,3,11:18.12
2,5,11:18.12
1,6,11:18.12
2,6,11:18.12
-1,0,12:18.12
-2,1,12:18.12
2,1,12:18.12
-4,2,12:18.12
-2,2,12:18.12
0,4,6:106.4
1,4,5:106.0
0,4,5:106.4
0,4,4:106.4
1,2,4:106.2
-1,-1,4:106.1
-2,-1,4:106.1
0,4,3:106.4
-1,3,3:106.4
1,2,3:106.2
-3,1,3:106.8
-1,-1,3:106.1
-2,-1,3:106.1
-1,3,2:106.4
1,2,2:106.2
-3,1,2:106.8
-2,-1,2:106.1
-1,3,1:106.4
-2,3,1:106.4
-3,1,1:106.8
-2,-1,1:106.1
-1,3,0:106.4
-1,1,0:96.2
-3,1,0:106.8
