[META]
version=2.0
spawnOnBlockType=12,8,9
spawnSunlight=True
spawnDarkness=True
spawnWater=True
spawnLava=False
underFill=False
randomRotation=True
dig=True
tree=False
branch=False
needsFoundation=false
rarity=300
collisionPercentage=50
spawnElevationMin=60
spawnElevationMax=64
spawnInBiome=All
[DATA]
1,-2,-3:17.0
1,0,-3:17.0
0,-3,-2:17.0
2,-2,-2:17.0
3,-2,-2:17.0
1,-1,-2:17.0
0,0,-2:17.0
1,0,-2:17.0
3,0,-2:17.0
0,1,-2:17.0
1,1,-2:17.0
-1,-4,-1:17.0
0,-4,-1:17.0
0,-3,-1:17.0
1,-3,-1:17.0
3,-3,-1:17.0
0,-2,-1:17.0
1,-2,-1:0
2,-2,-1:0
3,-2,-1:0
4,-2,-1:17.0
-1,-1,-1:17.0
0,-1,-1:0
1,-1,-1:17.0
2,-1,-1:17.0
3,-1,-1:0
4,-1,-1:17.0
-2,0,-1:17.0
-1,0,-1:17.0
0,0,-1:0
1,0,-1:0
2,0,-1:0
3,0,-1:17.0
4,0,-1:17.0
0,1,-1:17.0
1,1,-1:9.0
-1,-4,0:17.0
4,-3,0:17.0
2,-1,0:17.0
4,-1,0:17.0
-2,0,0:17.0
-1,-6,1:18.12
-2,-5,1:18.12
-1,-5,1:17.0
0,-5,1:18.12
-1,-4,1:18.12
0,-4,1:18.12
5,-4,1:18.12
5,-3,1:17.0
2,-2,1:18.4
2,-1,1:17.0
3,-1,1:18.12
4,-1,1:17.0
5,-1,1:17.0
-3,0,1:17.0
-2,0,1:17.0
2,0,1:18.12
4,0,1:18.12
-1,-5,2:18.12
5,-3,2:18.12
1,-2,2:18.12
5,-2,2:17.0
6,-2,2:18.12
-3,-1,2:18.12
0,-1,2:18.12
1,-1,2:17.0
2,-1,2:18.12
4,-1,2:18.12
5,-1,2:17.0
6,-1,2:18.12
-4,0,2:18.12
-3,0,2:17.0
-2,0,2:18.12
1,0,2:18.12
5,0,2:18.12
-3,1,2:18.12
5,-3,3:18.12
0,-2,3:18.12
4,-2,3:18.12
5,-2,3:17.0
6,-2,3:18.12
-1,-1,3:18.12
0,-1,3:17.0
1,-1,3:18.12
5,-1,3:18.12
6,-1,3:18.12
-3,0,3:18.12
0,0,3:18.12
0,-2,4:18.4
5,-2,4:18.12
-1,-1,4:18.12
0,-1,4:17.0
1,-1,4:18.12
0,0,4:18.12
0,-1,5:18.12
0,1,4:106.4
1,0,4:106.2
0,1,3:106.4
6,0,3:106.4
5,0,3:106.4
7,-2,3:106.2
4,-3,3:106.1
0,-3,3:106.1
-2,1,2:106.4
-4,1,2:106.4
6,0,2:106.4
-1,0,2:106.2
7,-2,2:106.2
4,-3,2:106.1
1,-3,2:106.1
0,-3,2:106.1
2,1,1:106.4
-2,1,1:106.4
-4,1,1:106.4
6,0,1:106.4
5,0,1:106.4
-1,0,1:106.2
-3,-1,1:106.1
7,-2,1:106.2
0,-3,1:106.1
1,-4,1:106.2
-2,-4,1:106.8
2,1,0:106.4
-2,-1,0:106.1
-3,-1,0:106.1
0,-3,0:106.1
-2,-4,0:106.8
