[META]
version=2.0
spawnOnBlockType=2,12
spawnSunlight=True
spawnDarkness=True
spawnWater=False
spawnLava=False
underFill=False
randomRotation=True
dig=False
tree=True
branch=False
needsFoundation=True
rarity=100
collisionPercentage=2
spawnElevationMin=0
spawnElevationMax=100
spawnInBiome=All
[DATA]
0,0,0:17.0
0,1,0:17.0
0,0,-1:17.0
-1,0,-1:17.0
0,1,-1:17.0
1,0,-1:17.0
-1,1,-1:2
0,-1,-1:2
1,1,-1:2
0,0,1:17.0
0,0,2:17.0
0,0,3:17.0
0,0,4:17.0
0,-1,4:17.0
0,-1,5:17.0
0,-1,6:17.0
0,-1,7:17.0
0,-2,7:17.0
0,-2,8:17.0
0,-2,9:17.0
0,-2,10:17.0
0,-3,10:17.0
0,1,10:18.0
-3,0,10:18.0
-4,-3,10:18.0
-3,-6,10:18.0
0,-7,10:18.0
3,-6,10:18.0
4,-3,10:18.0
3,0,10:18.0
0,-3,11:17.0
0,-4,11:18.0
0,-5,11:18.0
-1,-4,11:18.0
-1,-3,11:18.0
-2,-3,11:18.0
1,-3,11:18.0
2,-3,11:18.0
0,-2,11:18.0
0,-1,11:18.0
-1,-2,11:18.0
1,-4,11:18.0
1,-2,11:18.0
2,-5,11:18.0
0,-6,11:18.0
-2,-5,11:18.0
-3,-3,11:18.0
-2,-1,11:18.0
0,0,11:18.0
2,-1,11:18.0
3,-3,11:18.0
4,-3,11:18.0
3,-6,11:18.0
0,-7,11:18.0
-3,-6,11:18.0
-4,-3,11:18.0
-3,0,11:18.0
0,1,11:18.0
3,0,11:18.0
0,-3,12:18.0
0,-4,12:18.0
-1,-3,12:18.0
1,-3,12:18.0
0,-2,12:18.0
0,-3,13:18.0
-1,0,-2:3
0,0,-2:3
1,0,-2:3
0,-1,-2:3
0,1,-2:3
0,0,-3:3
