[META]
version=2.0
spawnOnBlockType=12,8,9
spawnSunlight=True
spawnDarkness=True
spawnWater=True
spawnLava=False
underFill=False
randomRotation=True
dig=True
tree=False
branch=False
needsFoundation=false
rarity=300
collisionPercentage=50
spawnElevationMin=60
spawnElevationMax=64
spawnInBiome=All
[DATA]
0,0,0:17.0
1,2,0:106.4
0,1,0:106.4
2,0,0:106.2
1,0,0:106.2
-2,-1,0:106.8
1,-2,0:106.2
-1,-2,0:106.1
-1,-1,-3:17.0
1,-1,-3:17.0
-2,0,-3:17.0
-1,1,-3:17.0
1,1,-3:17.0
2,-2,-2:17.0
0,-1,-2:17.0
1,-1,-2:17.0
-1,0,-2:17.0
1,0,-2:17.0
2,0,-2:17.0
-2,1,-2:17.0
-1,1,-2:17.0
0,1,-2:17.0
1,1,-2:17.0
-1,2,-2:17.0
1,2,-2:17.0
2,2,-2:17.0
-1,-2,-1:17.0
1,-2,-1:17.0
-2,-1,-1:17.0
0,-1,-1:17.0
2,-1,-1:17.0
-3,0,-1:17.0
0,0,-1:17.0
1,0,-1:17.0
-1,1,-1:17.0
-2,2,-1:17.0
1,2,-1:17.0
0,0,1:17.0
1,2,1:106.4
2,0,1:106.2
1,0,1:106.2
-2,-1,1:106.8
1,-2,1:106.2
-1,-2,1:106.1
0,-2,2:18
-1,-1,2:18
0,-1,2:17.0
1,-1,2:18
-2,0,2:18
-1,0,2:18
0,0,2:18
1,0,2:18
-2,1,2:18
-1,1,2:18
0,1,2:17.0
1,1,2:18
-1,2,2:18
0,2,2:18
1,2,2:106.4
2,0,2:106.2
-2,-1,2:106.8
1,-2,2:106.2
-1,-2,2:106.1
0,-1,3:18
-1,0,3:18
0,0,3:17.0
1,0,3:18
2,0,3:18
-1,1,3:18
0,1,3:17.0
1,1,3:18
0,2,3:18
1,2,3:106.4
0,0,4:18
0,1,4:18
