[META]
version=2.0
spawnOnBlockType=8,9
spawnSunlight=True
spawnDarkness=True
spawnWater=False
spawnLava=False
underFill=False
randomRotation=True
dig=True
tree=False
branch=False
needsFoundation=True
rarity=100
collisionPercentage=10
spawnElevationMin=0
spawnElevationMax=100
spawnInBiome=All
[DATA]
0,0,-6:17.0
2,5,-6:17.0
-2,6,-6:17.0
0,0,-5:17.0
0,1,-5:17.0
1,5,-5:17.0
2,5,-5:17.0
-2,6,-5:17.0
0,1,-4:17.0
0,2,-4:17.0
-2,5,-4:17.0
1,5,-4:17.0
-2,6,-4:17.0
0,2,-3:17.0
-3,5,-3:17.0
-2,5,-3:17.0
1,5,-3:17.0
1,6,-3:17.0
0,1,-2:17.0
0,2,-2:17.0
-3,4,-2:17.0
-3,5,-2:17.0
1,6,-2:17.0
-1,1,-1:17.0
0,1,-1:17.0
-3,3,-1:17.0
-3,4,-1:17.0
0,5,-1:17.0
1,6,-1:17.0
-1,1,0:17.0
-1,2,0:17.0
-3,3,0:17.0
-2,3,0:17.0
0,4,0:17.0
0,5,0:17.0
-1,2,1:17.0
-2,3,1:17.0
-1,3,1:17.0
-1,4,1:17.0
0,4,1:17.0
-1,3,2:17.0
-1,4,2:17.0
-2,2,3:17.0
-1,2,3:17.0
-1,3,3:17.0
-3,-1,4:18.12
-3,0,4:18.12
-2,0,4:18.12
-3,1,4:18.12
-2,1,4:18.12
-4,2,4:18.12
-3,2,4:17.0
-2,2,4:17.0
-3,-3,5:18.12
-4,-2,5:18.12
-3,-2,5:18.12
-2,-2,5:18.12
-1,-2,5:18.4
-5,-1,5:18.12
-4,-1,5:18.12
-3,-1,5:18.12
-2,-1,5:18.12
-1,-1,5:18.12
0,-1,5:18.12
-5,0,5:18.12
-4,0,5:18.12
-3,0,5:18.12
-2,0,5:18.12
-1,0,5:18.12
-5,1,5:18.12
-4,1,5:18.12
-3,1,5:17.0
-2,1,5:18.12
-4,2,5:18.12
-3,2,5:17.0
-2,2,5:18.12
-3,3,5:18.12
-3,-4,6:18.12
-4,-3,6:18.12
-3,-3,6:18.12
-2,-3,6:18.12
-5,-2,6:18.12
-4,-2,6:18.12
-3,-2,6:17.0
-2,-2,6:18.12
-1,-2,6:18.12
0,-2,6:18.12
-5,-1,6:18.12
-4,-1,6:18.12
-3,-1,6:17.0
-2,-1,6:17.0
-1,-1,6:17.0
0,-1,6:18.12
1,-1,6:18.12
-6,0,6:18.12
-5,0,6:17.0
-4,0,6:17.0
-3,0,6:17.0
-2,0,6:18.12
-1,0,6:18.12
0,0,6:18.4
-5,1,6:18.12
-4,1,6:18.12
-3,1,6:17.0
-2,1,6:18.12
-1,1,6:18.12
-4,2,6:18.12
-3,2,6:18.12
-2,2,6:18.12
-3,3,6:18.12
-3,-3,7:18.12
-2,-3,7:18.12
-4,-2,7:18.12
-3,-2,7:18.12
-2,-2,7:18.12
-1,-2,7:18.12
-5,-1,7:18.12
-4,-1,7:18.12
-3,-1,7:18.12
-2,-1,7:18.12
-1,-1,7:18.12
0,-1,7:18.12
-5,0,7:18.12
-4,0,7:18.12
-3,0,7:17.0
-2,0,7:18.12
-1,0,7:18.12
-5,1,7:18.12
-4,1,7:18.12
-3,1,7:18.12
-2,1,7:18.12
-4,2,7:18.12
-3,2,7:18.12
-4,-2,8:18.12
-3,-2,8:18.12
-4,-1,8:18.12
-3,-1,8:18.12
-2,-1,8:18.12
-5,0,8:18.12
-4,0,8:18.12
-3,0,8:18.12
-2,0,8:18.12
-3,1,8:18.12
-3,-1,9:18.12
-2,3,4:106.4
-3,3,4:106.4
-1,2,4:106.2
-1,4,3:106.4
0,3,3:106.2
-2,3,3:106.4
-3,3,3:106.4
0,2,3:106.2
-3,2,3:106.8
-2,1,3:106.1
-1,5,2:106.4
0,4,2:106.2
-2,4,2:106.8
0,3,2:106.2
-2,3,2:106.12
-3,3,2:106.4
0,2,2:106.2
-3,2,2:106.8
-2,1,2:106.1
0,5,1:106.4
-1,5,1:106.4
1,4,1:106.2
-2,4,1:106.12
0,3,1:106.2
-3,3,1:106.4
0,2,1:106.2
-2,2,1:106.1
-3,2,1:106.8
-2,1,1:106.1
0,6,0:106.4
1,5,0:106.2
-1,5,0:106.12
1,4,0:106.2
-1,4,0:106.8
-2,4,0:106.12
-3,4,0:106.4
0,3,0:106.2
-4,3,0:106.8
0,2,0:106.2
-2,2,0:106.1
-3,2,0:106.9
0,1,0:106.2
-2,1,0:106.9
-1,0,0:106.1
