[META]
version=2.0
spawnOnBlockType=2,3
spawnSunlight=True
spawnDarkness=True
spawnWater=False
spawnLava=False
underFill=False
randomRotation=False
dig=True
tree=False
branch=False
needsFoundation=True
rarity=40
collisionPercentage=2
spawnElevationMin=0
spawnElevationMax=240
spawnInBiome=All
[DATA]
-1,-2,-3:3.0
0,-2,-3:1.5
-2,-1,-3:3.0
-1,-1,-3:3.0
0,-1,-3:3.0
1,-1,-3:88.0
-2,0,-3:3.0
-1,0,-3:1.5
0,0,-3:1.5
1,0,-3:88.0
-1,1,-3:88.0
0,1,-3:1.5
-1,-3,-2:88.0
0,-3,-2:88.0
-2,-2,-2:88.0
-1,-2,-2:88.0
0,-2,-2:17.1
1,-2,-2:88.0
-3,-1,-2:3.0
-2,-1,-2:88.0
-1,-1,-2:3.0
0,-1,-2:3.0
1,-1,-2:88.0
2,-1,-2:88.0
-3,0,-2:88.0
-2,0,-2:88.0
-1,0,-2:3.0
0,0,-2:3.0
1,0,-2:88.0
2,0,-2:88.0
-2,1,-2:88.0
-1,1,-2:88.0
0,1,-2:3.0
1,1,-2:88.0
-1,2,-2:88.0
0,2,-2:1.5
-1,-4,-1:110.0
0,-4,-1:110.0
-2,-3,-1:110.0
-1,-3,-1:110.0
0,-3,-1:13.5
1,-3,-1:110.0
-3,-2,-1:110.0
-2,-2,-1:17.1
-1,-2,-1:17.1
0,-2,-1:88.0
1,-2,-1:3.0
2,-2,-1:110.0
-4,-1,-1:110.0
-3,-1,-1:110.0
-2,-1,-1:88.0
-1,-1,-1:13.5
0,-1,-1:3.0
1,-1,-1:3.0
2,-1,-1:3.0
3,-1,-1:110.0
-4,0,-1:110.0
-3,0,-1:88.0
-2,0,-1:110.0
-1,0,-1:13.5
0,0,-1:3.0
1,0,-1:3.0
2,0,-1:110.0
3,0,-1:110.0
-3,1,-1:110.0
-2,1,-1:110.0
-1,1,-1:110.0
0,1,-1:3.0
1,1,-1:110.0
2,1,-1:110.0
-2,2,-1:110.0
-1,2,-1:110.0
0,2,-1:110.0
1,2,-1:110.0
-1,3,-1:110.0
0,3,-1:110.0
-2,-2,0:17.1
-1,-2,0:17.1
1,-2,0:110.0
0,-1,0:13.5
1,-1,0:110.0
2,-1,0:110.0
0,0,0:110.0
1,0,0:110.0
0,1,0:110.0
-2,-2,1:17.1
-1,-2,1:30.0
-2,-2,2:17.1
-1,-2,2:17.1
-1,-1,2:17.1
-1,-1,3:17.1
-2,-2,4:30.0
-1,-1,4:17.1
0,-1,4:17.1
1,-1,4:30.0
-2,-2,5:17.1
-1,-2,5:30.0
0,-2,5:17.1
-1,-1,5:17.1
0,-1,5:17.1
1,-1,5:17.1
2,-1,5:17.1
0,0,5:17.1
-2,-3,6:17.1
-2,-2,6:17.1
0,-2,6:17.1
2,-1,6:17.1
0,0,6:17.1
0,1,6:17.1
0,2,6:30.0
-2,-3,7:17.1
2,-1,7:17.1
0,1,7:17.1
0,2,7:17.1
-2,-3,8:17.1
2,-1,8:17.1
0,2,8:17.1
0,2,9:40.5
-2,-3,9:39.5
0,0,7:40.5
-1,-1,6:39.5
-2,-2,3:39.5
0,1,1:39.5
1,-2,1:40.5
-3,1,0:40.0
-2,0,0:40.5
-1,-3,0:40.5
