[META]
version=2.0
spawnOnBlockType=8,9
spawnSunlight=True
spawnDarkness=True
spawnWater=False
spawnLava=False
underFill=False
randomRotation=True
dig=True
tree=False
branch=False
needsFoundation=True
rarity=100
collisionPercentage=10
spawnElevationMin=0
spawnElevationMax=100
spawnInBiome=All
[DATA]
-2,2,-8:17.0
-1,3,-8:17.0
-2,1,-7:17.0
-2,2,-7:17.0
-1,3,-7:17.0
0,3,-7:17.0
-3,-2,-6:17.0
-3,2,-6:17.0
-2,2,-6:17.0
0,3,-6:17.0
-3,-2,-5:17.0
-1,0,-5:17.0
1,0,-5:17.0
-3,2,-5:17.0
0,3,-5:17.0
-4,-2,-4:17.0
-3,-2,-4:17.0
-3,-1,-4:17.0
0,0,-4:17.0
-4,2,-4:17.0
-3,2,-4:17.0
0,2,-4:17.0
-3,3,-4:17.0
0,3,-4:17.0
-4,-2,-3:17.0
-4,-1,-3:17.0
0,-1,-3:17.0
0,0,-3:17.0
-4,2,-3:17.0
0,2,-3:17.0
-3,3,-3:17.0
-4,-2,-2:17.0
-4,-1,-2:17.0
0,-1,-2:17.0
-4,2,-2:17.0
0,2,-2:17.0
-4,3,-2:17.0
-5,-2,-1:17.0
-4,-2,-1:17.0
-4,-1,-1:17.0
0,-1,-1:17.0
-4,2,-1:17.0
0,2,-1:17.0
-4,3,-1:17.0
-5,-2,0:17.0
0,-2,0:17.0
-4,2,0:17.0
0,3,0:17.0
-5,-2,1:17.0
0,-2,1:17.0
-4,-1,1:17.0
-1,-1,1:17.0
-4,2,1:17.0
-4,3,1:17.0
-1,3,1:17.0
0,3,1:17.0
-4,-1,2:17.0
-1,-1,2:17.0
-4,2,2:17.0
-3,2,2:17.0
-1,2,2:17.0
-1,3,2:17.0
-2,-1,3:18.14
-1,-1,3:18.14
-3,0,3:17.0
-2,0,3:17.0
-3,1,3:18.14
-2,1,3:17.0
-3,2,3:18.14
-2,2,3:17.0
-1,2,3:18.14
-2,-1,4:18.14
-3,0,4:18.14
-2,0,4:17.0
-1,0,4:18.14
-2,1,4:17.0
-1,1,4:18.14
-2,2,4:17.0
-2,3,4:18.14
-2,-1,5:18.14
-1,-1,5:18.14
-2,0,5:17.0
-2,1,5:18.14
-2,2,5:17.0
-1,2,5:18.14
-2,-1,6:17.0
-2,2,6:17.0
-1,2,6:18.14
-2,3,6:18.14
-1,3,6:18.14
-2,-1,7:17.0
-2,2,7:18.14
-2,3,7:17.0
-2,-2,8:18.14
-1,-2,8:18.6
-4,-1,8:18.6
-3,-1,8:18.14
-2,-1,8:17.0
-1,-1,8:17.0
0,-1,8:18.14
-3,0,8:18.14
-2,0,8:18.14
-1,0,8:18.14
0,0,8:17.0
1,0,8:18.14
-2,1,8:18.14
-1,1,8:18.14
0,1,8:18.14
-3,2,8:18.14
-2,2,8:18.14
-1,2,8:18.14
-3,3,8:18.14
-2,3,8:17.0
-1,3,8:18.14
0,3,8:18.14
-2,4,8:18.14
-1,4,8:18.14
0,4,8:18.6
-1,5,8:18.14
-4,-2,9:18.14
-3,-2,9:18.14
-2,-2,9:18.14
-1,-2,9:18.14
-5,-1,9:18.14
-4,-1,9:17.0
-3,-1,9:18.14
-2,-1,9:18.14
-1,-1,9:18.14
0,-1,9:18.14
-4,0,9:18.14
-3,0,9:17.0
-2,0,9:17.0
-1,0,9:18.14
0,0,9:18.14
1,0,9:18.14
-3,1,9:18.14
-2,1,9:18.14
-1,1,9:18.6
-3,2,9:18.14
-2,2,9:18.14
-3,3,9:18.14
-2,3,9:17.0
-1,3,9:18.14
0,3,9:18.14
-3,4,9:18.14
-2,4,9:17.0
-1,4,9:18.14
-2,5,9:18.14
-1,5,9:17.0
0,5,9:18.14
-1,6,9:18.14
-4,-1,10:18.14
-3,-1,10:18.14
-3,0,10:18.14
-2,0,10:18.14
-2,1,10:18.14
-2,2,10:18.14
-2,3,10:18.14
-1,3,10:18.6
-2,4,10:18.14
-1,5,10:18.14
-4,1,9:106.8
-5,0,9:106.8
-1,-3,9:106.1
-4,-3,9:106.1
0,2,8:106.2
1,1,8:106.2
-3,1,8:106.8
-4,1,8:106.8
-5,0,8:106.8
-5,-1,8:106.8
-3,-2,8:106.1
-1,-3,8:106.1
-4,-3,8:106.1
-2,4,7:106.4
0,2,7:106.2
1,1,7:106.2
-3,1,7:106.8
-4,1,7:106.8
-5,0,7:106.8
-5,-1,7:106.8
-2,-2,7:106.1
-3,-2,7:106.1
-1,-3,7:106.1
-4,-3,7:106.1
-2,4,6:106.4
0,2,6:106.2
-3,2,6:106.8
1,1,6:106.2
-3,1,6:106.8
-4,1,6:106.8
-5,0,6:106.8
-5,-1,6:106.8
-2,-2,6:106.1
-3,-2,6:106.1
-1,-3,6:106.1
-4,-3,6:106.1
-2,4,5:106.4
0,2,5:106.2
-3,2,5:106.8
1,1,5:106.2
-3,1,5:106.8
-4,1,5:106.8
-5,0,5:106.8
-5,-1,5:106.8
-2,-2,5:106.1
-3,-2,5:106.1
-1,-3,5:106.1
-4,-3,5:106.1
-2,4,4:106.4
0,2,4:106.2
-3,2,4:106.8
1,1,4:106.2
0,1,4:106.2
-3,1,4:106.8
-4,1,4:106.8
0,0,4:106.2
-5,0,4:106.8
-3,-1,4:106.1
-5,-1,4:106.8
-2,-2,4:106.1
-3,-2,4:106.1
-1,-3,4:106.1
-4,-3,4:106.1
-2,4,3:106.4
-2,3,3:106.4
0,2,3:106.2
1,1,3:106.2
0,1,3:106.2
-4,1,3:106.8
0,0,3:106.2
-4,0,3:106.8
-5,0,3:106.8
-3,-1,3:106.1
-5,-1,3:106.8
-2,-2,3:106.1
-3,-2,3:106.1
-1,-3,3:106.1
-4,-3,3:106.1
-2,4,2:106.4
-2,3,2:106.4
0,2,2:106.2
1,1,2:106.2
0,1,2:106.2
-4,1,2:106.8
0,0,2:106.2
-4,0,2:106.8
-5,0,2:106.8
-3,-1,2:106.1
-5,-1,2:106.8
-2,-2,2:106.1
-3,-2,2:106.1
-1,-3,2:106.1
-4,-3,2:106.1
-2,4,1:106.4
-2,3,1:106.4
0,2,1:106.2
1,1,1:106.2
0,1,1:106.2
-4,1,1:106.8
0,0,1:106.2
-4,0,1:106.8
-5,0,1:106.8
-3,-1,1:106.1
-5,-1,1:106.8
-2,-2,1:106.1
-3,-2,1:106.1
-1,-3,1:106.1
-4,-3,1:106.1
