[META]
version=2.0
spawnOnBlockType=2
spawnSunlight=True
spawnDarkness=True
spawnWater=False
spawnLava=False
underFill=False
randomRotation=True
dig=True
tree=False
branch=False
needsFoundation=True
rarity=5
collisionPercentage=0
spawnElevationMin=0
spawnElevationMax=100
spawnInBiome=All
[DATA]
0,-1,0:17.2
0,-2,0:17.2
0,-3,0:17.2
0,-4,0:17.2
0,1,0:17.2
0,2,0:17.2
0,3,0:17.2
0,4,0:17.2
0,5,0:17.2
0,-5,0:17.2
-1,0,0:17.2
-2,0,0:17.2
-3,0,0:17.2
-4,0,0:17.2
-5,0,0:17.2
1,0,0:17.2
2,0,0:17.2
3,0,0:17.2
4,0,0:17.2
5,0,0:17.2
0,6,0:17.2
-6,0,0:17.2
0,-6,0:17.2
6,0,0:17.2
1,-6,0:17.2
-1,-6,0:17.2
-6,-1,0:17.2
-6,1,0:17.2
-1,6,0:17.2
1,6,0:17.2
6,1,0:17.2
6,-1,0:17.2
-2,-5,0:17.2
-3,-5,0:17.2
-4,-4,0:17.2
-5,-3,0:17.2
-5,-2,0:17.2
-5,2,0:17.2
-4,3,0:17.2
-3,4,0:17.2
-2,5,0:17.2
-3,5,0:17.2
-5,3,0:17.2
-4,4,0:17.2
2,5,0:17.2
3,5,0:17.2
5,2,0:17.2
5,3,0:17.2
4,4,0:17.2
5,-2,0:17.2
5,-3,0:17.2
3,-5,0:17.2
2,-5,0:17.2
4,-4,0:17.2
-5,1,0:17.2
-4,1,0:17.2
-3,1,0:17.2
-2,1,0:17.2
-1,1,0:17.2
-1,2,0:17.2
-1,3,0:17.2
-1,4,0:17.2
-1,5,0:17.2
-2,4,0:17.2
-2,3,0:17.2
-3,3,0:17.2
-3,2,0:17.2
-4,2,0:17.2
-2,2,0:17.2
-5,-1,0:17.2
-4,-1,0:17.2
-4,-2,0:17.2
-4,-3,0:17.2
-3,-3,0:17.2
-3,-4,0:17.2
-2,-4,0:17.2
-1,-4,0:17.2
-1,-5,0:17.2
-1,-3,0:17.2
-2,-3,0:17.2
-3,-2,0:17.2
-2,-2,0:17.2
-1,-2,0:17.2
-1,-1,0:17.2
-2,-1,0:17.2
-3,-1,0:17.2
1,-5,0:17.2
1,-4,0:17.2
1,-3,0:17.2
1,-2,0:17.2
1,-1,0:17.2
2,-1,0:17.2
2,-2,0:17.2
2,-3,0:17.2
2,-4,0:17.2
3,-4,0:17.2
3,-3,0:17.2
3,-2,0:17.2
3,-1,0:17.2
4,-1,0:17.2
4,-2,0:17.2
4,-3,0:17.2
5,-1,0:17.2
5,1,0:17.2
4,1,0:17.2
3,1,0:17.2
2,1,0:17.2
1,1,0:17.2
1,2,0:17.2
2,2,0:17.2
3,2,0:17.2
4,2,0:17.2
4,3,0:17.2
3,3,0:17.2
2,3,0:17.2
1,3,0:17.2
1,4,0:17.2
2,4,0:17.2
3,4,0:17.2
1,5,0:17.2
0,0,0:0
-5,-1,1:17.2
-5,0,1:17.2
-5,1,1:17.2
-4,-2,1:17.2
-4,-3,1:17.2
-3,-4,1:17.2
-2,-4,1:17.2
-1,-5,1:17.2
0,-5,1:17.2
1,-5,1:17.2
2,-4,1:17.2
3,-4,1:17.2
4,-2,1:17.2
4,-3,1:17.2
5,-1,1:17.2
5,0,1:17.2
5,1,1:17.2
4,2,1:17.2
4,3,1:17.2
3,4,1:17.2
2,4,1:17.2
1,5,1:17.2
0,5,1:17.2
-1,5,1:17.2
-2,4,1:17.2
-3,4,1:17.2
-4,3,1:17.2
-4,2,1:17.2
-4,1,1:17.2
-4,0,1:17.2
-3,0,1:17.2
-3,-1,1:17.2
-2,-1,1:17.2
-2,-2,1:17.2
-3,-2,1:17.2
-4,-1,1:17.2
-2,-3,1:17.2
-1,-3,1:17.2
0,-3,1:17.2
-3,-3,1:17.2
-1,-4,1:17.2
0,-4,1:17.2
1,-4,1:17.2
1,-3,1:17.2
0,-2,1:17.2
-1,-2,1:17.2
1,-2,1:17.2
2,-2,1:17.2
3,-2,1:17.2
3,-3,1:17.2
2,-3,1:17.2
-1,-1,1:17.2
0,-1,1:0
1,-1,1:17.2
2,-1,1:17.2
3,-1,1:17.2
4,-1,1:17.2
4,0,1:17.2
3,0,1:17.2
2,0,1:17.2
1,0,1:0
0,0,1:0
-1,0,1:0
-2,0,1:17.2
-2,1,1:17.2
-1,1,1:17.2
0,2,1:17.2
1,2,1:17.2
1,1,1:17.2
2,1,1:17.2
3,1,1:17.2
4,1,1:17.2
-1,2,1:17.2
-3,1,1:17.2
0,1,1:0
-2,2,1:17.2
-3,2,1:17.2
-3,3,1:17.2
-2,3,1:17.2
-1,3,1:17.2
0,3,1:17.2
1,3,1:17.2
1,4,1:17.2
0,4,1:17.2
-1,4,1:17.2
2,2,1:17.2
2,3,1:17.2
3,3,1:17.2
3,2,1:17.2
-5,-1,2:17.2
-5,0,2:17.2
-5,1,2:17.2
-4,-2,2:17.2
-4,-3,2:17.2
-3,-4,2:17.2
-2,-4,2:17.2
-1,-5,2:17.2
0,-5,2:17.2
1,-5,2:17.2
2,-4,2:17.2
3,-4,2:17.2
4,-2,2:17.2
4,-3,2:17.2
5,-1,2:17.2
5,0,2:17.2
5,1,2:17.2
4,2,2:17.2
4,3,2:17.2
3,4,2:17.2
2,4,2:17.2
1,5,2:17.2
0,5,2:17.2
-1,5,2:17.2
-2,4,2:17.2
-3,4,2:17.2
-4,3,2:17.2
-4,2,2:17.2
-4,1,2:17.2
-4,0,2:17.2
-3,0,2:17.2
-3,-1,2:17.2
-2,-1,2:17.2
-2,-2,2:17.2
-3,-2,2:17.2
-4,-1,2:17.2
-2,-3,2:17.2
-1,-3,2:17.2
0,-3,2:17.2
-3,-3,2:17.2
-1,-4,2:17.2
0,-4,2:17.2
1,-4,2:17.2
1,-3,2:17.2
0,-2,2:0
-1,-2,2:17.2
1,-2,2:17.2
2,-2,2:17.2
3,-2,2:17.2
3,-3,2:17.2
2,-3,2:17.2
-1,-1,2:0
0,-1,2:0
1,-1,2:0
2,-1,2:17.2
3,-1,2:17.2
4,-1,2:17.2
4,0,2:17.2
3,0,2:17.2
2,0,2:0
1,0,2:0
0,0,2:0
-1,0,2:0
-2,0,2:0
-2,1,2:17.2
-1,1,2:0
0,2,2:0
1,2,2:17.2
1,1,2:0
2,1,2:17.2
3,1,2:17.2
4,1,2:17.2
-1,2,2:17.2
-3,1,2:17.2
0,1,2:0
-2,2,2:17.2
-3,2,2:17.2
-3,3,2:17.2
-2,3,2:17.2
-1,3,2:17.2
0,3,2:17.2
1,3,2:17.2
1,4,2:17.2
0,4,2:17.2
-1,4,2:17.2
2,2,2:17.2
2,3,2:17.2
3,3,2:17.2
3,2,2:17.2
-5,-1,3:17.2
-5,0,3:17.2
-5,1,3:17.2
-4,-2,3:17.2
-4,-3,3:17.2
-3,-4,3:17.2
-2,-4,3:17.2
-1,-5,3:17.2
0,-5,3:17.2
1,-5,3:17.2
2,-4,3:17.2
3,-4,3:17.2
4,-2,3:17.2
4,-3,3:17.2
5,-1,3:17.2
5,0,3:17.2
5,1,3:17.2
4,2,3:17.2
4,3,3:17.2
3,4,3:17.2
2,4,3:17.2
1,5,3:17.2
0,5,3:17.2
-1,5,3:17.2
-2,4,3:17.2
-3,4,3:17.2
-4,3,3:17.2
-4,2,3:17.2
-4,1,3:17.2
-4,0,3:17.2
-3,0,3:17.2
-3,-1,3:17.2
-2,-1,3:17.2
-2,-2,3:17.2
-3,-2,3:17.2
-4,-1,3:17.2
-2,-3,3:17.2
-1,-3,3:17.2
0,-3,3:17.2
-3,-3,3:17.2
-1,-4,3:17.2
0,-4,3:17.2
1,-4,3:17.2
1,-3,3:17.2
0,-2,3:0
-1,-2,3:17.2
1,-2,3:17.2
2,-2,3:17.2
3,-2,3:17.2
3,-3,3:17.2
2,-3,3:17.2
-1,-1,3:0
0,-1,3:0
1,-1,3:0
2,-1,3:17.2
3,-1,3:17.2
4,-1,3:17.2
4,0,3:17.2
3,0,3:17.2
2,0,3:0
1,0,3:0
0,0,3:0
-1,0,3:0
-2,0,3:0
-2,1,3:17.2
-1,1,3:0
0,2,3:0
1,2,3:17.2
1,1,3:0
2,1,3:17.2
3,1,3:17.2
4,1,3:17.2
-1,2,3:17.2
-3,1,3:17.2
0,1,3:0
-2,2,3:17.2
-3,2,3:17.2
-3,3,3:17.2
-2,3,3:17.2
-1,3,3:17.2
0,3,3:17.2
1,3,3:17.2
1,4,3:17.2
0,4,3:17.2
-1,4,3:17.2
2,2,3:17.2
2,3,3:17.2
3,3,3:17.2
3,2,3:17.2
-5,-1,4:17.2
-5,0,4:17.2
-5,1,4:17.2
-4,-2,4:17.2
-4,-3,4:17.2
-3,-4,4:17.2
-2,-4,4:17.2
-1,-5,4:17.2
0,-5,4:17.2
1,-5,4:17.2
2,-4,4:17.2
3,-4,4:17.2
4,-2,4:17.2
4,-3,4:17.2
5,-1,4:17.2
5,0,4:17.2
5,1,4:17.2
4,2,4:17.2
4,3,4:17.2
3,4,4:17.2
2,4,4:17.2
1,5,4:17.2
0,5,4:17.2
-1,5,4:17.2
-2,4,4:17.2
-3,4,4:17.2
-4,3,4:17.2
-4,2,4:17.2
-4,1,4:17.2
-4,0,4:17.2
-3,0,4:17.2
-3,-1,4:17.2
-2,-1,4:17.2
-2,-2,4:17.2
-3,-2,4:17.2
-4,-1,4:17.2
-2,-3,4:17.2
-1,-3,4:17.2
0,-3,4:17.2
-3,-3,4:17.2
-1,-4,4:17.2
0,-4,4:17.2
1,-4,4:17.2
1,-3,4:17.2
0,-2,4:0
-1,-2,4:17.2
1,-2,4:17.2
2,-2,4:17.2
3,-2,4:17.2
3,-3,4:17.2
2,-3,4:17.2
-1,-1,4:0
0,-1,4:0
1,-1,4:0
2,-1,4:17.2
3,-1,4:17.2
4,-1,4:17.2
4,0,4:17.2
3,0,4:17.2
2,0,4:0
1,0,4:0
0,0,4:0
-1,0,4:0
-2,0,4:0
-2,1,4:17.2
-1,1,4:0
0,2,4:0
1,2,4:17.2
1,1,4:0
2,1,4:17.2
3,1,4:17.2
4,1,4:17.2
-1,2,4:17.2
-3,1,4:17.2
0,1,4:0
-2,2,4:17.2
-3,2,4:17.2
-3,3,4:17.2
-2,3,4:17.2
-1,3,4:17.2
0,3,4:17.2
1,3,4:17.2
1,4,4:17.2
0,4,4:17.2
-1,4,4:17.2
2,2,4:17.2
2,3,4:17.2
3,3,4:17.2
3,2,4:17.2
-5,-1,5:17.2
-5,0,5:17.2
-5,1,5:17.2
-4,-2,5:17.2
-4,-3,5:17.2
-3,-4,5:17.2
-2,-4,5:17.2
-1,-5,5:17.2
0,-5,5:17.2
1,-5,5:17.2
2,-4,5:17.2
3,-4,5:17.2
4,-2,5:17.2
4,-3,5:17.2
5,-1,5:17.2
5,0,5:17.2
5,1,5:17.2
4,2,5:17.2
4,3,5:17.2
3,4,5:17.2
2,4,5:17.2
1,5,5:17.2
0,5,5:17.2
-1,5,5:17.2
-2,4,5:17.2
-3,4,5:17.2
-4,3,5:17.2
-4,2,5:17.2
-4,1,5:17.2
-4,0,5:17.2
-3,0,5:0
-3,-1,5:17.2
-2,-1,5:0
-2,-2,5:17.2
-3,-2,5:17.2
-4,-1,5:17.2
-2,-3,5:17.2
-1,-3,5:17.2
0,-3,5:0
-3,-3,5:17.2
-1,-4,5:17.2
0,-4,5:17.2
1,-4,5:17.2
1,-3,5:17.2
0,-2,5:0
-1,-2,5:0
1,-2,5:0
2,-2,5:17.2
3,-2,5:17.2
3,-3,5:17.2
2,-3,5:17.2
-1,-1,5:0
0,-1,5:0
1,-1,5:0
2,-1,5:0
3,-1,5:17.2
4,-1,5:17.2
4,0,5:17.2
3,0,5:0
2,0,5:0
1,0,5:0
0,0,5:0
-1,0,5:0
-2,0,5:0
-2,1,5:0
-1,1,5:0
0,2,5:0
1,2,5:0
1,1,5:0
2,1,5:0
3,1,5:17.2
4,1,5:17.2
-1,2,5:0
-3,1,5:17.2
0,1,5:0
-2,2,5:17.2
-3,2,5:17.2
-3,3,5:17.2
-2,3,5:17.2
-1,3,5:17.2
0,3,5:0
1,3,5:17.2
1,4,5:17.2
0,4,5:17.2
-1,4,5:17.2
2,2,5:17.2
2,3,5:17.2
3,3,5:17.2
3,2,5:17.2
-5,-1,6:17.2
-5,0,6:17.2
-5,1,6:17.2
-4,-2,6:17.2
-4,-3,6:17.2
-3,-4,6:17.2
-2,-4,6:17.2
-1,-5,6:17.2
0,-5,6:17.2
1,-5,6:17.2
2,-4,6:17.2
3,-4,6:17.2
4,-2,6:17.2
4,-3,6:17.2
5,-1,6:17.2
5,0,6:17.2
5,1,6:17.2
4,2,6:17.2
4,3,6:17.2
3,4,6:17.2
2,4,6:17.2
1,5,6:17.2
0,5,6:17.2
-1,5,6:17.2
-2,4,6:17.2
-3,4,6:17.2
-4,3,6:17.2
-4,2,6:17.2
-4,1,6:17.2
-4,0,6:17.2
-3,0,6:0
-3,-1,6:17.2
-2,-1,6:0
-2,-2,6:17.2
-3,-2,6:17.2
-4,-1,6:17.2
-2,-3,6:17.2
-1,-3,6:17.2
0,-3,6:0
-3,-3,6:17.2
-1,-4,6:17.2
0,-4,6:17.2
1,-4,6:17.2
1,-3,6:17.2
0,-2,6:0
-1,-2,6:0
1,-2,6:0
2,-2,6:17.2
3,-2,6:17.2
3,-3,6:17.2
2,-3,6:17.2
-1,-1,6:0
0,-1,6:0
1,-1,6:0
2,-1,6:0
3,-1,6:17.2
4,-1,6:17.2
4,0,6:17.2
3,0,6:0
2,0,6:0
1,0,6:0
0,0,6:0
-1,0,6:0
-2,0,6:0
-2,1,6:0
-1,1,6:0
0,2,6:0
1,2,6:0
1,1,6:0
2,1,6:0
3,1,6:17.2
4,1,6:17.2
-1,2,6:0
-3,1,6:17.2
0,1,6:0
-2,2,6:17.2
-3,2,6:17.2
-3,3,6:17.2
-2,3,6:17.2
-1,3,6:17.2
0,3,6:0
1,3,6:17.2
1,4,6:17.2
0,4,6:17.2
-1,4,6:17.2
2,2,6:17.2
2,3,6:17.2
3,3,6:17.2
3,2,6:17.2
-5,-1,7:17.2
-5,0,7:17.2
-5,1,7:17.2
-4,-2,7:17.2
-4,-3,7:17.2
-3,-4,7:17.2
-2,-4,7:17.2
-1,-5,7:17.2
0,-5,7:17.2
1,-5,7:17.2
2,-4,7:17.2
3,-4,7:17.2
4,-2,7:17.2
4,-3,7:17.2
5,-1,7:17.2
5,0,7:17.2
5,1,7:17.2
4,2,7:17.2
4,3,7:17.2
3,4,7:17.2
2,4,7:17.2
1,5,7:17.2
0,5,7:17.2
-1,5,7:17.2
-2,4,7:17.2
-3,4,7:17.2
-4,3,7:17.2
-4,2,7:17.2
-4,1,7:17.2
-4,0,7:17.2
-3,0,7:0
-3,-1,7:17.2
-2,-1,7:0
-2,-2,7:17.2
-3,-2,7:17.2
-4,-1,7:17.2
-2,-3,7:17.2
-1,-3,7:17.2
0,-3,7:0
-3,-3,7:17.2
-1,-4,7:17.2
0,-4,7:17.2
1,-4,7:17.2
1,-3,7:17.2
0,-2,7:0
-1,-2,7:0
1,-2,7:0
2,-2,7:17.2
3,-2,7:17.2
3,-3,7:17.2
2,-3,7:17.2
-1,-1,7:0
0,-1,7:0
1,-1,7:0
2,-1,7:0
3,-1,7:17.2
4,-1,7:17.2
4,0,7:17.2
3,0,7:0
2,0,7:0
1,0,7:0
0,0,7:0
-1,0,7:0
-2,0,7:0
-2,1,7:0
-1,1,7:0
0,2,7:0
1,2,7:0
1,1,7:0
2,1,7:0
3,1,7:17.2
4,1,7:17.2
-1,2,7:0
-3,1,7:17.2
0,1,7:0
-2,2,7:17.2
-3,2,7:17.2
-3,3,7:17.2
-2,3,7:17.2
-1,3,7:17.2
0,3,7:0
1,3,7:17.2
1,4,7:17.2
0,4,7:17.2
-1,4,7:17.2
2,2,7:17.2
2,3,7:17.2
3,3,7:17.2
3,2,7:17.2
-5,-1,8:17.2
-5,0,8:17.2
-5,1,8:17.2
-4,-2,8:17.2
-4,-3,8:17.2
-3,-4,8:17.2
-2,-4,8:17.2
-1,-5,8:17.2
0,-5,8:17.2
1,-5,8:17.2
2,-4,8:17.2
3,-4,8:17.2
4,-2,8:17.2
4,-3,8:17.2
5,-1,8:17.2
5,0,8:17.2
5,1,8:17.2
4,2,8:17.2
4,3,8:17.2
3,4,8:17.2
2,4,8:17.2
1,5,8:17.2
0,5,8:17.2
-1,5,8:17.2
-2,4,8:17.2
-3,4,8:17.2
-4,3,8:17.2
-4,2,8:17.2
-4,1,8:17.2
-4,0,8:17.2
-3,0,8:17.2
-3,-1,8:17.2
-2,-1,8:17.2
-2,-2,8:17.2
-3,-2,8:17.2
-4,-1,8:17.2
-2,-3,8:17.2
-1,-3,8:17.2
0,-3,8:17.2
-3,-3,8:17.2
-1,-4,8:17.2
0,-4,8:17.2
1,-4,8:17.2
1,-3,8:17.2
0,-2,8:0
-1,-2,8:17.2
1,-2,8:17.2
2,-2,8:17.2
3,-2,8:17.2
3,-3,8:17.2
2,-3,8:17.2
-1,-1,8:0
0,-1,8:0
1,-1,8:0
2,-1,8:17.2
3,-1,8:17.2
4,-1,8:17.2
4,0,8:17.2
3,0,8:17.2
2,0,8:0
1,0,8:0
0,0,8:0
-1,0,8:0
-2,0,8:0
-2,1,8:17.2
-1,1,8:0
0,2,8:0
1,2,8:17.2
1,1,8:0
2,1,8:17.2
3,1,8:17.2
4,1,8:17.2
-1,2,8:17.2
-3,1,8:17.2
0,1,8:0
-2,2,8:17.2
-3,2,8:17.2
-3,3,8:17.2
-2,3,8:17.2
-1,3,8:17.2
0,3,8:17.2
1,3,8:17.2
1,4,8:17.2
0,4,8:17.2
-1,4,8:17.2
2,2,8:17.2
2,3,8:17.2
3,3,8:17.2
3,2,8:17.2
-5,-1,9:17.2
-5,0,9:17.2
-5,1,9:17.2
-4,-2,9:17.2
-4,-3,9:17.2
-3,-4,9:17.2
-2,-4,9:17.2
-1,-5,9:17.2
0,-5,9:17.2
1,-5,9:17.2
2,-4,9:17.2
3,-4,9:17.2
4,-2,9:17.2
4,-3,9:17.2
5,-1,9:17.2
5,0,9:17.2
5,1,9:17.2
4,2,9:17.2
4,3,9:17.2
3,4,9:17.2
2,4,9:17.2
1,5,9:17.2
0,5,9:17.2
-1,5,9:17.2
-2,4,9:17.2
-3,4,9:17.2
-4,3,9:17.2
-4,2,9:17.2
-4,1,9:17.2
-4,0,9:17.2
-3,0,9:17.2
-3,-1,9:17.2
-2,-1,9:17.2
-2,-2,9:17.2
-3,-2,9:17.2
-4,-1,9:17.2
-2,-3,9:17.2
-1,-3,9:17.2
0,-3,9:17.2
-3,-3,9:17.2
-1,-4,9:17.2
0,-4,9:17.2
1,-4,9:17.2
1,-3,9:17.2
0,-2,9:0
-1,-2,9:17.2
1,-2,9:17.2
2,-2,9:17.2
3,-2,9:17.2
3,-3,9:17.2
2,-3,9:17.2
-1,-1,9:0
0,-1,9:0
1,-1,9:0
2,-1,9:17.2
3,-1,9:17.2
4,-1,9:17.2
4,0,9:17.2
3,0,9:17.2
2,0,9:0
1,0,9:0
0,0,9:0
-1,0,9:0
-2,0,9:0
-2,1,9:17.2
-1,1,9:0
0,2,9:0
1,2,9:17.2
1,1,9:0
2,1,9:17.2
3,1,9:17.2
4,1,9:17.2
-1,2,9:17.2
-3,1,9:17.2
0,1,9:0
-2,2,9:17.2
-3,2,9:17.2
-3,3,9:17.2
-2,3,9:17.2
-1,3,9:17.2
0,3,9:17.2
1,3,9:17.2
1,4,9:17.2
0,4,9:17.2
-1,4,9:17.2
2,2,9:17.2
2,3,9:17.2
3,3,9:17.2
3,2,9:17.2
-5,-1,10:17.2
-5,0,10:17.2
-5,1,10:17.2
-4,-2,10:17.2
-4,-3,10:17.2
-3,-4,10:17.2
-2,-4,10:17.2
-1,-5,10:17.2
0,-5,10:17.2
1,-5,10:17.2
2,-4,10:17.2
3,-4,10:17.2
4,-2,10:17.2
4,-3,10:17.2
5,-1,10:17.2
5,0,10:17.2
5,1,10:17.2
4,2,10:17.2
4,3,10:17.2
3,4,10:17.2
2,4,10:17.2
1,5,10:17.2
0,5,10:17.2
-1,5,10:17.2
-2,4,10:17.2
-3,4,10:17.2
-4,3,10:17.2
-4,2,10:17.2
-4,1,10:17.2
-4,0,10:17.2
-3,0,10:17.2
-3,-1,10:17.2
-2,-1,10:17.2
-2,-2,10:17.2
-3,-2,10:17.2
-4,-1,10:17.2
-2,-3,10:17.2
-1,-3,10:17.2
0,-3,10:17.2
-3,-3,10:17.2
-1,-4,10:17.2
0,-4,10:17.2
1,-4,10:17.2
1,-3,10:17.2
0,-2,10:0
-1,-2,10:17.2
1,-2,10:17.2
2,-2,10:17.2
3,-2,10:17.2
3,-3,10:17.2
2,-3,10:17.2
-1,-1,10:0
0,-1,10:0
1,-1,10:0
2,-1,10:17.2
3,-1,10:17.2
4,-1,10:17.2
4,0,10:17.2
3,0,10:17.2
2,0,10:0
1,0,10:0
0,0,10:0
-1,0,10:0
-2,0,10:0
-2,1,10:17.2
-1,1,10:0
0,2,10:0
1,2,10:17.2
1,1,10:0
2,1,10:17.2
3,1,10:17.2
4,1,10:17.2
-1,2,10:17.2
-3,1,10:17.2
0,1,10:0
-2,2,10:17.2
-3,2,10:17.2
-3,3,10:17.2
-2,3,10:17.2
-1,3,10:17.2
0,3,10:17.2
1,3,10:17.2
1,4,10:17.2
0,4,10:17.2
-1,4,10:17.2
2,2,10:17.2
2,3,10:17.2
3,3,10:17.2
3,2,10:17.2
-5,-1,11:17.2
-5,0,11:17.2
-5,1,11:17.2
-4,-2,11:17.2
-4,-3,11:17.2
-3,-4,11:17.2
-2,-4,11:17.2
-1,-5,11:17.2
0,-5,11:17.2
1,-5,11:17.2
2,-4,11:17.2
3,-4,11:17.2
4,-2,11:17.2
4,-3,11:17.2
5,-1,11:17.2
5,0,11:17.2
5,1,11:17.2
4,2,11:17.2
4,3,11:17.2
3,4,11:17.2
2,4,11:17.2
1,5,11:17.2
0,5,11:17.2
-1,5,11:17.2
-2,4,11:17.2
-3,4,11:17.2
-4,3,11:17.2
-4,2,11:17.2
-4,1,11:17.2
-4,0,11:17.2
-3,0,11:17.2
-3,-1,11:17.2
-2,-1,11:17.2
-2,-2,11:17.2
-3,-2,11:17.2
-4,-1,11:17.2
-2,-3,11:17.2
-1,-3,11:17.2
0,-3,11:17.2
-3,-3,11:17.2
-1,-4,11:17.2
0,-4,11:17.2
1,-4,11:17.2
1,-3,11:17.2
0,-2,11:17.2
-1,-2,11:17.2
1,-2,11:17.2
2,-2,11:17.2
3,-2,11:17.2
3,-3,11:17.2
2,-3,11:17.2
-1,-1,11:17.2
0,-1,11:0
1,-1,11:17.2
2,-1,11:17.2
3,-1,11:17.2
4,-1,11:17.2
4,0,11:17.2
3,0,11:17.2
2,0,11:17.2
1,0,11:0
0,0,11:0
-1,0,11:0
-2,0,11:17.2
-2,1,11:17.2
-1,1,11:17.2
0,2,11:17.2
1,2,11:17.2
1,1,11:17.2
2,1,11:17.2
3,1,11:17.2
4,1,11:17.2
-1,2,11:17.2
-3,1,11:17.2
0,1,11:0
-2,2,11:17.2
-3,2,11:17.2
-3,3,11:17.2
-2,3,11:17.2
-1,3,11:17.2
0,3,11:17.2
1,3,11:17.2
1,4,11:17.2
0,4,11:17.2
-1,4,11:17.2
2,2,11:17.2
2,3,11:17.2
3,3,11:17.2
3,2,11:17.2
-5,-1,12:17.2
-5,0,12:17.2
-5,1,12:17.2
-4,-2,12:17.2
-4,-3,12:17.2
-3,-4,12:17.2
-2,-4,12:17.2
-1,-5,12:17.2
0,-5,12:17.2
1,-5,12:17.2
2,-4,12:17.2
3,-4,12:17.2
4,-2,12:17.2
4,-3,12:17.2
5,-1,12:17.2
5,0,12:17.2
5,1,12:17.2
4,2,12:17.2
4,3,12:17.2
3,4,12:17.2
2,4,12:17.2
1,5,12:17.2
0,5,12:17.2
-1,5,12:17.2
-2,4,12:17.2
-3,4,12:17.2
-4,3,12:17.2
-4,2,12:17.2
-4,1,12:17.2
-4,0,12:17.2
-3,0,12:17.2
-3,-1,12:17.2
-2,-1,12:17.2
-2,-2,12:17.2
-3,-2,12:17.2
-4,-1,12:17.2
-2,-3,12:17.2
-1,-3,12:17.2
0,-3,12:17.2
-3,-3,12:17.2
-1,-4,12:17.2
0,-4,12:17.2
1,-4,12:17.2
1,-3,12:17.2
0,-2,12:17.2
-1,-2,12:17.2
1,-2,12:17.2
2,-2,12:17.2
3,-2,12:17.2
3,-3,12:17.2
2,-3,12:17.2
-1,-1,12:17.2
0,-1,12:17.2
1,-1,12:17.2
2,-1,12:17.2
3,-1,12:17.2
4,-1,12:17.2
4,0,12:17.2
3,0,12:17.2
2,0,12:17.2
1,0,12:17.2
0,0,12:0
-1,0,12:17.2
-2,0,12:17.2
-2,1,12:17.2
-1,1,12:17.2
0,2,12:17.2
1,2,12:17.2
1,1,12:17.2
2,1,12:17.2
3,1,12:17.2
4,1,12:17.2
-1,2,12:17.2
-3,1,12:17.2
0,1,12:17.2
-2,2,12:17.2
-3,2,12:17.2
-3,3,12:17.2
-2,3,12:17.2
-1,3,12:17.2
0,3,12:17.2
1,3,12:17.2
1,4,12:17.2
0,4,12:17.2
-1,4,12:17.2
2,2,12:17.2
2,3,12:17.2
3,3,12:17.2
3,2,12:17.2
-5,-1,13:17.2
-5,0,13:17.2
-5,1,13:17.2
-4,-2,13:17.2
-4,-3,13:17.2
-3,-4,13:17.2
-2,-4,13:17.2
-1,-5,13:17.2
0,-5,13:17.2
1,-5,13:17.2
2,-4,13:17.2
3,-4,13:17.2
4,-2,13:17.2
4,-3,13:17.2
5,-1,13:17.2
5,0,13:17.2
5,1,13:17.2
4,2,13:17.2
4,3,13:17.2
3,4,13:17.2
2,4,13:17.2
1,5,13:17.2
0,5,13:17.2
-1,5,13:17.2
-2,4,13:17.2
-3,4,13:17.2
-4,3,13:17.2
-4,2,13:17.2
-4,1,13:17.2
-4,0,13:17.2
-3,0,13:17.2
-3,-1,13:17.2
-2,-1,13:17.2
-2,-2,13:17.2
-3,-2,13:17.2
-4,-1,13:17.2
-2,-3,13:17.2
-1,-3,13:17.2
0,-3,13:17.2
-3,-3,13:17.2
-1,-4,13:17.2
0,-4,13:17.2
1,-4,13:17.2
1,-3,13:17.2
0,-2,13:17.2
-1,-2,13:17.2
1,-2,13:17.2
2,-2,13:17.2
3,-2,13:17.2
3,-3,13:17.2
2,-3,13:17.2
-1,-1,13:17.2
0,-1,13:17.2
1,-1,13:17.2
2,-1,13:17.2
3,-1,13:17.2
4,-1,13:17.2
4,0,13:17.2
3,0,13:17.2
2,0,13:17.2
1,0,13:17.2
0,0,13:0
-1,0,13:17.2
-2,0,13:17.2
-2,1,13:17.2
-1,1,13:17.2
0,2,13:17.2
1,2,13:17.2
1,1,13:17.2
2,1,13:17.2
3,1,13:17.2
4,1,13:17.2
-1,2,13:17.2
-3,1,13:17.2
0,1,13:17.2
-2,2,13:17.2
-3,2,13:17.2
-3,3,13:17.2
-2,3,13:17.2
-1,3,13:17.2
0,3,13:17.2
1,3,13:17.2
1,4,13:17.2
0,4,13:17.2
-1,4,13:17.2
2,2,13:17.2
2,3,13:17.2
3,3,13:17.2
3,2,13:17.2
-4,1,14:17.2
-4,0,14:17.2
-3,0,14:17.2
-3,-1,14:17.2
-2,-1,14:17.2
-2,-2,14:17.2
-3,-2,14:17.2
-4,-1,14:17.2
-2,-3,14:17.2
-1,-3,14:17.2
0,-3,14:17.2
-3,-3,14:17.2
-1,-4,14:17.2
0,-4,14:17.2
1,-4,14:17.2
1,-3,14:17.2
0,-2,14:17.2
-1,-2,14:17.2
1,-2,14:17.2
2,-2,14:17.2
3,-2,14:17.2
3,-3,14:17.2
2,-3,14:17.2
-1,-1,14:17.2
0,-1,14:17.2
1,-1,14:17.2
2,-1,14:17.2
3,-1,14:17.2
4,-1,14:17.2
4,0,14:17.2
3,0,14:17.2
2,0,14:17.2
1,0,14:17.2
0,0,14:17.2
-1,0,14:17.2
-2,0,14:17.2
-2,1,14:17.2
-1,1,14:17.2
0,2,14:17.2
1,2,14:17.2
1,1,14:17.2
2,1,14:17.2
3,1,14:17.2
4,1,14:17.2
-1,2,14:17.2
-3,1,14:17.2
0,1,14:17.2
-2,2,14:17.2
-3,2,14:17.2
-3,3,14:17.2
-2,3,14:17.2
-1,3,14:17.2
0,3,14:17.2
1,3,14:17.2
1,4,14:17.2
0,4,14:17.2
-1,4,14:17.2
2,2,14:17.2
2,3,14:17.2
3,3,14:17.2
3,2,14:17.2
0,-5,14:17.2
-5,0,14:17.2
0,5,14:17.2
5,0,14:17.2
-3,-1,15:17.2
-3,0,15:17.2
-3,1,15:17.2
-2,-2,15:17.2
-1,-2,15:17.2
0,-2,15:17.2
-2,-3,15:17.2
-1,-3,15:17.2
0,-3,15:17.2
1,-3,15:17.2
2,-3,15:17.2
3,-1,15:17.2
3,0,15:17.2
3,1,15:17.2
-2,3,15:17.2
-1,3,15:17.2
0,3,15:17.2
1,3,15:17.2
2,3,15:17.2
2,2,15:17.2
2,1,15:17.2
2,0,15:17.2
2,-1,15:17.2
2,-2,15:17.2
1,-2,15:17.2
-2,-1,15:17.2
-1,-1,15:17.2
-1,0,15:17.2
0,0,15:17.2
1,0,15:17.2
0,1,15:17.2
0,-1,15:17.2
1,-1,15:17.2
-2,0,15:17.2
-2,1,15:17.2
-2,2,15:17.2
-1,2,15:17.2
0,2,15:17.2
1,1,15:17.2
1,2,15:17.2
-1,1,15:17.2
3,2,15:17.2
3,-2,15:17.2
-3,-2,15:17.2
-3,2,15:17.2
0,-4,15:17.2
-4,0,15:17.2
0,4,15:17.2
4,0,15:17.2
-1,-4,15:17.2
1,-4,15:17.2
4,-1,15:17.2
4,1,15:17.2
1,4,15:17.2
-1,4,15:17.2
-4,1,15:17.2
-4,-1,15:17.2
-2,-1,16:17.2
-2,0,16:17.2
-2,1,16:17.2
-1,-2,16:17.2
0,-2,16:17.2
1,-2,16:17.2
-1,-1,16:17.2
0,-1,16:17.2
1,-1,16:17.2
2,-1,16:17.2
2,0,16:17.2
2,1,16:17.2
1,1,16:17.2
1,0,16:17.2
0,0,16:17.2
-1,0,16:17.2
-1,1,16:17.2
0,1,16:17.2
-1,2,16:17.2
0,2,16:17.2
1,2,16:17.2
0,-3,16:17.2
-3,0,16:17.2
3,0,16:17.2
0,3,16:17.2
-3,-1,16:17.2
-3,1,16:17.2
-1,-3,16:17.2
3,-1,16:17.2
3,1,16:17.2
1,-3,16:17.2
-1,3,16:17.2
1,3,16:17.2
-2,2,16:17.2
-2,-2,16:17.2
2,-2,16:17.2
2,2,16:17.2
0,-4,16:17.2
-4,0,16:17.2
0,4,16:17.2
4,0,16:17.2
0,0,17:17.2
0,-1,17:17.2
-1,-1,17:17.2
-1,0,17:17.2
-1,1,17:17.2
0,1,17:17.2
1,1,17:17.2
1,0,17:17.2
1,-1,17:17.2
-4,3,17:17.2
-2,-7,17:17.2
-7,5,17:17.2
4,7,17:17.2
5,1,17:17.2
-2,0,17:17.2
0,-2,17:17.2
2,0,17:17.2
0,2,17:17.2
-2,-1,17:17.2
-1,-2,17:17.2
1,-2,17:17.2
2,-1,17:17.2
2,1,17:17.2
1,2,17:17.2
-1,2,17:17.2
-2,1,17:17.2
5,-4,17:17.2
0,-3,17:17.2
-3,0,17:17.2
0,3,17:17.2
3,0,17:17.2
2,-2,17:17.2
2,2,17:17.2
1,3,17:17.2
-3,1,17:17.2
0,-7,17:17.2
0,-8,17:17.2
7,0,17:17.2
7,-2,17:17.2
5,-5,17:18.0
6,-4,17:18.0
8,-2,17:18.0
7,1,17:18.0
5,2,17:18.0
3,7,17:18.0
5,7,17:18.0
-5,3,17:18.0
-7,6,17:18.0
0,-9,17:18.0
2,-7,17:18.0
1,-7,17:18.0
1,-8,17:18.0
-3,-7,17:18.0
-1,-8,17:18.0
4,8,17:18.0
4,6,17:18.0
-8,5,17:18.0
-7,4,17:18.0
-6,4,17:18.0
-6,5,17:18.0
-2,-6,17:18.0
-1,-7,17:18.0
1,-6,17:18.0
0,-6,17:18.0
4,-4,17:18.0
6,-2,17:18.0
6,0,17:18.0
7,-3,17:18.0
6,2,17:18.0
-4,4,17:18.0
-2,-8,17:18.0
5,-3,17:18.0
7,-1,17:18.0
8,0,17:18.0
5,0,17:18.0
-4,2,17:18.0
6,1,17:18.0
4,1,17:18.0
0,8,17:17.2
0,7,17:18.0
-1,8,17:18.0
0,9,17:18.0
1,8,17:18.0
-6,-1,17:17.2
-7,-1,17:18.0
-6,-2,17:18.0
-5,-1,17:18.0
-6,0,17:18.0
-7,-7,17:17.2
-8,-7,17:18.0
-7,-8,17:18.0
-6,-7,17:18.0
-7,-6,17:18.0
0,0,18:17.2
0,1,18:17.2
-1,1,18:17.2
2,3,18:17.2
1,2,18:17.2
-2,1,18:17.2
-4,2,18:17.2
-4,4,18:17.2
-6,4,18:17.2
-7,4,18:17.2
-5,-1,18:17.2
3,-6,18:17.2
5,0,18:17.2
-1,-7,18:17.2
-3,-7,18:17.2
5,6,18:17.2
-1,0,18:17.2
-1,-1,18:17.2
0,-1,18:17.2
1,0,18:17.2
1,-1,18:17.2
1,1,18:17.2
-2,0,18:17.2
1,3,18:17.2
2,2,18:17.2
2,-1,18:17.2
1,-2,18:17.2
2,-2,18:17.2
-4,3,18:17.2
-5,4,18:17.2
5,-2,18:17.2
5,-3,18:17.2
-3,1,18:17.2
6,-1,18:17.2
7,1,18:17.2
7,-3,18:17.2
0,-7,18:18.0
3,-7,18:18.0
5,-4,18:18.0
7,-2,18:18.0
6,1,18:18.0
5,5,18:18.0
-7,5,18:18.0
-7,3,18:18.0
-6,3,18:18.0
-5,0,18:18.0
-1,-8,18:18.0
-4,-8,18:18.0
-4,-6,18:18.0
6,-3,18:18.0
7,-4,18:18.0
8,-3,18:18.0
8,0,18:18.0
7,2,18:18.0
4,7,18:18.0
6,6,18:18.0
-4,5,18:18.0
-3,4,18:18.0
-6,-2,18:18.0
-2,-8,18:18.0
-6,5,18:18.0
-8,3,18:18.0
-8,4,18:18.0
-6,-1,18:18.0
-3,-6,18:18.0
2,-6,18:18.0
4,-6,18:18.0
5,7,18:18.0
0,-8,18:18.0
-2,-7,18:18.0
7,0,18:18.0
5,1,18:18.0
5,-1,18:18.0
4,-2,18:18.0
4,0,18:18.0
3,-5,18:18.0
-1,-6,18:18.0
-4,-1,18:18.0
-5,-2,18:18.0
0,7,18:17.2
-1,7,18:18.0
0,8,18:18.0
0,6,18:18.0
1,7,18:18.0
-7,-6,18:17.2
-8,-6,18:18.0
-7,-7,18:18.0
-6,-6,18:18.0
-7,-5,18:18.0
-3,2,18:17.2
-1,1,19:17.2
2,-2,19:17.2
0,2,19:17.2
3,4,19:17.2
-3,1,19:17.2
-3,5,19:17.2
-5,4,19:17.2
-1,6,19:17.2
0,7,19:17.2
-7,3,19:17.2
-4,0,19:17.2
-5,-2,19:17.2
-6,-1,19:17.2
-5,-1,19:17.2
-1,-4,19:17.2
-1,-5,19:17.2
2,-6,19:17.2
5,-1,19:17.2
-1,-6,19:17.2
4,6,19:17.2
-1,-1,19:17.2
0,-1,19:17.2
0,0,19:17.2
-1,0,19:17.2
-2,1,19:17.2
-2,0,19:17.2
2,2,19:17.2
1,2,19:17.2
1,1,19:17.2
0,1,19:17.2
2,3,19:17.2
3,3,19:17.2
3,5,19:17.2
2,-3,19:17.2
2,-1,19:17.2
-3,2,19:17.2
-3,4,19:17.2
-6,-8,19:17.2
7,2,19:17.2
8,-3,19:17.2
-6,-7,19:18.0
-2,-6,19:18.0
1,-7,19:18.0
3,-3,19:18.0
4,-1,19:18.0
7,-3,19:18.0
8,-4,19:18.0
8,2,19:18.0
7,3,19:18.0
4,7,19:18.0
0,8,19:18.0
-3,6,19:18.0
0,6,19:18.0
-5,5,19:18.0
-8,3,19:18.0
0,-6,19:18.0
-6,-9,19:18.0
-7,-8,19:18.0
-7,-1,19:18.0
-6,-3,19:18.0
-5,-3,19:18.0
-7,2,19:18.0
-5,3,19:18.0
-2,5,19:18.0
-1,7,19:18.0
1,7,19:18.0
5,6,19:18.0
6,2,19:18.0
9,-3,19:18.0
3,-6,19:18.0
4,5,19:18.0
-6,4,19:18.0
-7,4,19:18.0
-5,-8,19:18.0
2,-7,19:18.0
8,-2,19:18.0
6,-1,19:18.0
5,0,19:18.0
5,-2,19:18.0
7,1,19:18.0
-1,-7,19:18.0
-3,-7,19:18.0
5,-3,19:18.0
-4,4,19:18.0
-1,5,19:18.0
-6,-6,19:17.2
-7,-6,19:18.0
-6,-5,19:18.0
-5,-6,19:18.0
-6,-2,19:18.0
-6,0,19:18.0
-1,0,20:17.2
2,-3,20:17.2
1,3,20:17.2
4,5,20:17.2
-2,6,20:17.2
0,6,20:17.2
-1,5,20:17.2
-7,2,20:17.2
-7,-1,20:17.2
-5,-3,20:17.2
-8,-3,20:17.2
-4,-4,20:17.2
-3,-3,20:17.2
-1,-4,20:17.2
-1,-6,20:17.2
2,-5,20:17.2
4,-1,20:17.2
0,-1,20:17.2
-1,-1,20:17.2
3,5,20:17.2
2,-4,20:17.2
-3,5,20:17.2
-6,-7,20:17.2
3,-4,20:17.2
2,-7,20:17.2
3,3,20:17.2
1,7,20:17.2
-5,5,20:17.2
7,3,20:17.2
8,-4,20:17.2
-6,-6,20:18.0
-7,-2,20:18.0
-7,1,20:18.0
-5,-4,20:18.0
-4,-5,20:18.0
-2,-6,20:18.0
1,-7,20:18.0
3,-5,20:18.0
8,-5,20:18.0
5,-1,20:18.0
7,4,20:18.0
3,4,20:18.0
4,6,20:18.0
1,8,20:18.0
-2,7,20:18.0
-5,6,20:18.0
-1,4,20:18.0
1,2,20:18.0
1,-4,20:18.0
3,-8,20:18.0
-6,-8,20:18.0
-9,-2,20:18.0
-8,0,20:18.0
-8,3,20:18.0
-6,5,20:18.0
-3,6,20:18.0
-1,6,20:18.0
0,7,20:18.0
5,4,20:18.0
8,3,20:18.0
9,-4,20:18.0
4,-2,20:18.0
3,-7,20:18.0
-1,-7,20:18.0
7,2,20:18.0
8,-3,20:18.0
2,-8,20:18.0
-7,-7,20:18.0
-9,-3,20:18.0
-7,-4,20:18.0
-6,3,20:18.0
-8,2,20:18.0
-7,3,20:18.0
-4,5,20:18.0
2,7,20:18.0
5,6,20:18.0
5,5,20:18.0
3,2,20:18.0
4,3,20:18.0
4,0,20:18.0
-8,-4,20:18.0
-8,-1,20:18.0
-8,-2,20:18.0
-1,-10,20:17.2
1,-11,20:17.2
1,-12,20:18.0
2,-11,20:18.0
0,-11,20:18.0
-2,-10,20:18.0
-1,-11,20:18.0
1,-10,20:18.0
-6,-1,20:18.0
-5,-2,20:18.0
-5,4,20:18.0
-3,4,20:18.0
-5,-1,20:18.0
2,-6,20:18.0
-1,-5,20:18.0
-4,0,20:18.0
-3,2,20:18.0
7,-4,20:18.0
0,0,20:17.2
-1,-1,21:17.2
0,-2,21:17.2
2,2,21:17.2
4,0,21:17.2
-1,4,21:17.2
-6,1,21:17.2
-7,1,21:17.2
-8,-2,21:17.2
-5,-4,21:17.2
-3,-4,21:17.2
-1,-3,21:17.2
2,-4,21:17.2
-4,-5,21:17.2
-1,-2,21:17.2
-5,-7,21:17.2
-1,2,21:17.2
-2,3,21:17.2
0,3,21:17.2
4,-4,21:17.2
2,-8,21:17.2
4,3,21:17.2
1,8,21:17.2
-5,6,21:17.2
6,3,21:17.2
7,-5,21:17.2
-5,-8,21:18.0
-6,-7,21:18.0
-8,-3,21:18.0
-7,-1,21:18.0
-7,2,21:18.0
-6,5,21:18.0
0,8,21:18.0
4,4,21:18.0
6,2,21:18.0
2,1,21:18.0
0,4,21:18.0
5,0,21:18.0
7,-6,21:18.0
4,-5,21:18.0
2,-6,21:18.0
2,-5,21:18.0
1,-8,21:18.0
-3,-5,21:18.0
-2,-3,21:18.0
-2,2,21:18.0
-6,-4,21:18.0
3,-9,21:18.0
5,-4,21:18.0
8,-5,21:18.0
4,1,21:18.0
6,4,21:18.0
7,2,21:18.0
3,3,21:18.0
1,7,21:18.0
-4,6,21:18.0
-8,1,21:18.0
-9,-2,21:18.0
-4,-7,21:18.0
-5,-5,21:18.0
1,-4,21:18.0
8,2,21:17.2
9,2,21:18.0
0,9,21:18.0
-6,8,21:17.2
-7,6,21:17.2
-6,7,21:18.0
-7,8,21:18.0
-6,9,21:18.0
-5,8,21:18.0
-8,6,21:18.0
-7,5,21:18.0
-7,7,21:18.0
-6,6,21:18.0
-5,7,21:18.0
-5,5,21:18.0
2,8,21:18.0
7,3,21:18.0
1,9,21:18.0
7,-4,21:18.0
6,-5,21:18.0
2,-9,21:18.0
3,-4,21:18.0
4,-1,21:18.0
-8,-1,21:18.0
-4,-6,21:18.0
-7,0,21:18.0
3,-8,21:18.0
-6,-6,21:18.0
5,3,21:18.0
4,2,21:18.0
1,-9,21:17.2
0,-10,21:17.2
0,-11,21:18.0
-1,-10,21:18.0
1,-10,21:18.0
0,-9,21:18.0
4,5,21:18.0
-3,5,21:18.0
4,-3,21:18.0
2,-7,21:18.0
-1,-6,21:18.0
-5,-3,21:18.0
1,-11,21:18.0
-2,6,21:18.0
0,6,21:18.0
3,5,21:18.0
-5,-6,21:17.2
8,-4,21:18.0
-1,6,21:18.0
-1,5,21:18.0
1,-3,22:17.2
3,1,22:17.2
-1,-2,22:17.2
-5,-6,22:17.2
-6,1,22:17.2
-1,3,22:17.2
4,-5,22:17.2
5,-6,22:17.2
1,-8,22:17.2
4,4,22:17.2
0,8,22:17.2
-6,6,22:17.2
6,2,22:17.2
1,-9,22:18.0
0,-8,22:18.0
1,-7,22:18.0
2,-8,22:18.0
-4,-6,22:18.0
-6,-6,22:18.0
-6,0,22:18.0
-7,1,22:18.0
-7,6,22:18.0
-5,7,22:18.0
-1,8,22:18.0
0,7,22:18.0
-2,3,22:18.0
-1,4,22:18.0
2,1,22:18.0
3,5,22:18.0
5,4,22:18.0
5,2,22:18.0
6,1,22:18.0
7,3,22:18.0
3,0,22:18.0
-2,-2,22:18.0
1,-4,22:18.0
2,-3,22:18.0
5,-7,22:18.0
6,-6,22:18.0
4,-6,22:18.0
4,-4,22:18.0
0,9,22:17.2
0,-2,22:18.0
-1,-1,22:18.0
-1,2,22:18.0
0,3,22:18.0
0,4,22:18.0
1,9,22:18.0
-7,7,22:18.0
-6,7,22:17.2
-5,5,22:18.0
-7,0,22:18.0
-5,-8,22:18.0
-9,-2,22:18.0
7,-5,22:18.0
6,-5,22:18.0
-8,-2,22:18.0
2,2,22:18.0
4,5,22:18.0
7,2,22:17.2
3,-5,22:18.0
0,-3,22:18.0
8,1,22:18.0
7,1,22:18.0
8,2,22:18.0
0,10,22:18.0
-1,9,22:18.0
1,8,22:18.0
-8,6,22:17.2
-9,6,22:18.0
-8,5,22:18.0
-8,7,22:18.0
-6,8,22:18.0
-6,2,22:18.0
4,3,22:18.0
3,4,22:18.0
6,3,22:18.0
-5,-7,22:18.0
0,-10,22:18.0
-4,-5,22:18.0
2,-4,22:18.0
-5,-4,22:18.0
-3,-4,22:18.0
-1,-3,22:18.0
4,0,22:18.0
3,2,22:18.0
-6,5,22:18.0
1,-8,23:18.0
-5,-6,23:18.0
-1,-2,23:18.0
1,-3,23:18.0
4,-5,23:18.0
5,-6,23:18.0
3,1,23:18.0
4,4,23:18.0
6,2,23:18.0
0,8,23:18.0
-1,3,23:18.0
-6,6,23:18.0
-6,1,23:18.0
0,9,23:18.0
-8,6,23:18.0
-6,7,23:18.0
7,2,23:18.0
-6,-1,-1:17.2
-6,0,-1:17.2
-6,1,-1:17.2
6,-1,-1:17.2
6,0,-1:17.2
6,1,-1:17.2
-1,6,-1:17.2
0,6,-1:17.2
1,6,-1:17.2
-1,-6,-1:17.2
0,-6,-1:17.2
1,-6,-1:17.2
2,-5,-1:17.2
3,-5,-1:17.2
4,-4,-1:17.2
5,-3,-1:17.2
5,-2,-1:17.2
5,3,-1:17.2
5,2,-1:17.2
4,4,-1:17.2
3,5,-1:17.2
2,5,-1:17.2
-2,5,-1:17.2
-3,5,-1:17.2
-5,2,-1:17.2
-5,3,-1:17.2
-4,4,-1:17.2
-5,-2,-1:17.2
-5,-3,-1:17.2
-3,-5,-1:17.2
-2,-5,-1:17.2
-4,-4,-1:17.2
-2,0,-1:17.2
-2,-1,-1:17.2
-1,-1,-1:17.2
0,-1,-1:17.2
1,0,-1:17.2
1,1,-1:17.2
0,1,-1:17.2
0,0,-1:17.2
-1,0,-1:17.2
-1,1,-1:17.2
1,-1,-1:17.2
2,0,-1:17.2
2,1,-1:17.2
2,2,-1:17.2
1,2,-1:17.2
1,3,-1:17.2
0,3,-1:17.2
-1,3,-1:17.2
-1,2,-1:17.2
-2,2,-1:17.2
-2,1,-1:17.2
-3,1,-1:17.2
-3,0,-1:17.2
-3,-1,-1:17.2
-3,-2,-1:17.2
-2,-2,-1:17.2
-2,-3,-1:17.2
-1,-3,-1:17.2
0,-3,-1:17.2
1,-2,-1:17.2
2,-2,-1:17.2
2,-1,-1:17.2
0,2,-1:17.2
-1,-2,-1:17.2
0,-2,-1:17.2
2,3,-1:17.2
3,-1,-1:17.2
3,0,-1:17.2
3,1,-1:17.2
1,-3,-1:17.2
3,2,-1:17.2
3,3,-1:17.2
4,2,-1:17.2
4,3,-1:17.2
2,4,-1:17.2
3,4,-1:17.2
1,4,-1:17.2
1,5,-1:17.2
0,5,-1:17.2
-1,5,-1:17.2
-1,4,-1:17.2
0,4,-1:17.2
-2,4,-1:17.2
-3,4,-1:17.2
-3,3,-1:17.2
-2,3,-1:17.2
-3,2,-1:17.2
-4,3,-1:17.2
-4,2,-1:17.2
-4,1,-1:17.2
-5,1,-1:17.2
-5,0,-1:17.2
-5,-1,-1:17.2
-4,-1,-1:17.2
-4,0,-1:17.2
-4,-2,-1:17.2
-4,-3,-1:17.2
-3,-3,-1:17.2
-3,-4,-1:17.2
-2,-4,-1:17.2
-1,-4,-1:17.2
-1,-5,-1:17.2
0,-5,-1:17.2
1,-5,-1:17.2
1,-4,-1:17.2
2,-4,-1:17.2
0,-4,-1:17.2
3,-4,-1:17.2
3,-3,-1:17.2
2,-3,-1:17.2
4,-3,-1:17.2
4,-2,-1:17.2
3,-2,-1:17.2
4,-1,-1:17.2
5,-1,-1:17.2
5,0,-1:17.2
4,0,-1:17.2
5,1,-1:17.2
4,1,-1:17.2
-3,-2,-2:17.2
-3,-1,-2:17.2
-2,-1,-2:17.2
-2,0,-2:3
-6,1,-2:17.2
-6,0,-2:17.2
-5,0,-2:17.2
-5,-1,-2:17.2
-5,1,-2:17.2
-5,2,-2:17.2
-4,3,-2:17.2
-4,2,-2:17.2
-3,4,-2:17.2
-2,4,-2:17.2
-2,3,-2:17.2
-2,2,-2:3
-2,1,-2:17.2
1,6,-2:17.2
1,5,-2:17.2
1,4,-2:17.2
1,3,-2:17.2
2,5,-2:17.2
2,4,-2:3
2,3,-2:17.2
1,2,-2:17.2
0,2,-2:17.2
5,3,-2:17.2
4,3,-2:17.2
4,2,-2:17.2
3,2,-2:3
2,2,-2:3
5,-1,-2:17.2
4,-1,-2:17.2
3,-1,-2:17.2
2,-1,-2:17.2
2,0,-2:3
2,1,-2:17.2
1,1,-2:17.2
0,1,-2:17.2
3,-2,-2:17.2
4,0,-2:17.2
4,1,-2:17.2
5,-2,-2:17.2
3,-4,-2:17.2
2,-4,-2:17.2
2,-3,-2:17.2
1,-3,-2:17.2
0,-2,-2:17.2
0,-1,-2:17.2
-1,-1,-2:17.2
-2,-3,-2:17.2
-2,-4,-2:17.2
-3,-3,-2:17.2
-5,-3,-2:17.2
-5,-2,-2:17.2
-4,-1,-2:17.2
-3,1,-2:3
-3,2,-2:3
-3,3,-2:17.2
-4,4,-2:17.2
-2,5,-2:17.2
-1,5,-2:17.2
-1,4,-2:17.2
0,5,-2:17.2
-1,1,-2:17.2
3,3,-2:17.2
3,4,-2:3
3,5,-2:17.2
1,-5,-2:17.2
1,-4,-2:17.2
-1,-3,-2:17.2
0,-5,-2:17.2
0,-4,-2:17.2
4,-3,-2:17.2
-4,1,-2:3
-4,0,-2:3
-3,0,-2:3
-4,-2,-2:3
-2,-2,-2:3
-1,-2,-2:3
0,-3,-2:3
1,-2,-2:3
2,-2,-2:3
1,-1,-2:3
1,0,-2:3
-1,0,-2:3
0,0,-2:3
-1,3,-2:3
-1,2,-2:3
0,3,-2:3
0,4,-2:3
3,1,-2:3
3,0,-2:3
4,-2,-2:3
3,-3,-2:3
-1,-4,-2:3
-4,-3,-2:3
-6,-1,-2:3
-5,3,-2:3
-6,2,-2:3
-3,5,-2:3
0,6,-2:3
2,6,-2:3
4,4,-2:3
5,2,-2:3
5,0,-2:3
5,1,-2:3
-8,-2,-3:17.2
-7,-1,-3:17.2
-6,-1,-3:17.2
-8,1,-3:17.2
-7,1,-3:17.2
-6,1,-3:17.2
-6,0,-3:17.2
-7,5,-3:17.2
-7,4,-3:17.2
-6,3,-3:17.2
-5,3,-3:17.2
-5,2,-3:17.2
-4,2,-3:3
-4,1,-3:17.2
-4,0,-3:17.2
-3,0,-3:17.2
-3,-1,-3:17.2
-2,-1,-3:17.2
-2,-2,-3:17.2
-1,-2,-3:17.2
-1,-3,-3:17.2
0,-3,-3:17.2
0,-4,-3:17.2
1,-4,-3:17.2
1,-5,-3:17.2
1,-6,-3:17.2
1,-7,-3:17.2
-2,-6,-3:17.2
-2,-5,-3:17.2
-1,-4,-3:17.2
0,-2,-3:3
1,-2,-3:17.2
2,-2,-3:17.2
3,-2,-3:3
4,-2,-3:17.2
4,-1,-3:3
5,0,-3:17.2
5,1,-3:17.2
6,1,-3:17.2
7,1,-3:17.2
5,5,-3:17.2
4,5,-3:17.2
4,4,-3:17.2
3,4,-3:3
3,3,-3:3
2,3,-3:17.2
1,2,-3:3
0,2,-3:3
-1,2,-3:17.2
-1,1,-3:3
-2,1,-3:3
-2,0,-3:17.2
-3,-2,-3:17.2
-4,-2,-3:17.2
-4,-3,-3:17.2
-4,-4,-3:17.2
-5,-4,-3:17.2
-5,-5,-3:17.2
-6,-6,-3:17.2
1,-1,-3:17.2
0,-1,-3:3
0,0,-3:17.2
0,1,-3:3
0,3,-3:17.2
0,4,-3:17.2
0,5,-3:3
1,5,-3:3
1,6,-3:17.2
1,7,-3:17.2
1,8,-3:17.2
-1,3,-3:17.2
-2,3,-3:17.2
-2,4,-3:3
-3,4,-3:3
-3,5,-3:17.2
-4,5,-3:17.2
-4,6,-3:17.2
-4,7,-3:17.2
3,-3,-3:17.2
4,-3,-3:17.2
5,-3,-3:17.2
6,-3,-3:17.2
6,-4,-3:17.2
1,0,-3:17.2
2,0,-3:3
2,1,-3:3
3,1,-3:17.2
4,1,-3:3
4,2,-3:3
5,2,-3:17.2
6,4,-3:17.2
7,4,-3:17.2
8,0,-3:17.2
3,-1,-3:3
2,-1,-3:3
3,0,-3:17.2
4,0,-3:3
1,1,-3:3
-1,0,-3:17.2
-3,2,-3:3
1,-3,-3:3
2,-3,-3:3
-1,-1,-3:3
-2,-3,-3:3
-3,-3,-3:3
-2,-4,-3:3
-4,-1,-3:3
-5,-1,-3:3
-5,0,-3:3
-5,1,-3:3
-5,-2,-3:3
-5,-3,-3:3
-6,2,-3:3
-3,1,-3:3
1,3,-3:3
2,4,-3:3
2,2,-3:3
3,2,-3:3
-1,5,-3:3
-1,4,-3:3
-4,3,-3:3
-2,5,-3:3
2,5,-3:3
3,5,-3:3
1,4,-3:17.2
-2,2,-3:3
-3,3,-3:3
-4,4,-3:3
4,3,-3:3
5,-1,-3:3
5,-2,-3:3
5,4,-3:3
2,-4,-3:3
3,-4,-3:17.2
-1,6,-3:3
0,6,-3:3
3,6,-3:17.2
2,6,-3:3
3,7,-3:17.2
5,3,-3:3
3,-5,-3:17.2
4,-6,-3:17.2
4,-7,-3:17.2
-3,-7,-3:17.2
2,-5,-3:3
0,-5,-3:3
4,-4,-3:3
-3,-2,-4:17.2
-2,-1,-4:17.2
-1,0,-4:17.2
0,0,-4:17.2
1,-1,-4:17.2
2,-2,-4:17.2
2,-3,-4:17.2
4,-1,-4:17.2
1,1,-4:17.2
3,3,-4:17.2
3,2,-4:17.2
2,2,-4:17.2
0,2,-4:17.2
0,4,-4:17.2
-1,3,-4:17.2
-2,3,-4:17.2
-3,2,-4:17.2
1,5,-4:17.2
0,-2,-4:17.2
-1,-3,-4:17.2
-1,-4,-4:17.2
-4,-3,-4:17.2
-3,0,-4:17.2
-4,3,-4:17.2
3,0,-4:17.2
2,0,-4:17.2
