[META]
version=2.0
spawnOnBlockType=2,3
spawnSunlight=True
spawnDarkness=True
spawnWater=False
spawnLava=False
underFill=False
randomRotation=False
dig=True
tree=False
branch=False
needsFoundation=True
rarity=40
collisionPercentage=2
spawnElevationMin=0
spawnElevationMax=240
spawnInBiome=All
[DATA]
-1,-3,0:110
-2,-2,0:110
-1,-2,0:3
0,-2,0:13
-3,-1,0:110
-2,-1,0:3
-1,-1,0:17.1
0,-1,0:88
-2,0,0:110
-1,0,0:3
0,0,0:88
1,0,0:110
-1,1,0:110
0,1,0:110
2,0,0:39
-1,-1,-4:1
0,-1,-4:1
0,0,-4:1
-1,-2,-3:88
0,-2,-3:88
-2,-1,-3:1
-1,-1,-3:3
0,-1,-3:3
1,-1,-3:88
-1,0,-3:1
0,0,-3:1
1,0,-3:1
0,1,-3:88
-1,-3,-2:88
0,-3,-2:88
-2,-2,-2:88
-1,-2,-2:3
0,-2,-2:3
1,-2,-2:88
-3,-1,-2:88
-2,-1,-2:3
-1,-1,-2:3
0,-1,-2:3
1,-1,-2:3
2,-1,-2:88
-2,0,-2:88
-1,0,-2:3
0,0,-2:3
1,0,-2:3
2,0,-2:1
-1,1,-2:88
0,1,-2:88
1,1,-2:88
0,2,-2:88
-1,-4,-1:110
0,-4,-1:110
-2,-3,-1:110
-1,-3,-1:3
0,-3,-1:13
1,-3,-1:110
-3,-2,-1:110
-2,-2,-1:3
-1,-2,-1:3
0,-2,-1:3
1,-2,-1:88
2,-2,-1:110
-4,-1,-1:110
-3,-1,-1:3
-2,-1,-1:3
-1,-1,-1:3
0,-1,-1:3
1,-1,-1:88
2,-1,-1:88
3,-1,-1:110
-3,0,-1:110
-2,0,-1:3
-1,0,-1:3
0,0,-1:3
1,0,-1:3
2,0,-1:110
3,0,-1:110
-2,1,-1:110
-1,1,-1:3
0,1,-1:3
1,1,-1:110
2,1,-1:110
-1,2,-1:110
0,2,-1:110
1,2,-1:110
0,3,-1:110
-1,-2,1:110
-2,-1,1:110
-1,-1,1:17.1
-1,0,1:110
0,-1,1:40
-2,-2,1:39
-1,-1,2:17.1
0,-1,2:17.1
-1,-2,2:39
-1,-1,3:30
0,-1,3:17.1
1,-1,3:30
0,-2,4:17.1
-1,-1,4:17.1
0,-1,4:17.1
1,-1,4:17.1
-2,0,4:17.1
-1,0,4:30
0,0,4:17.1
0,1,4:17.1
0,-3,5:17.1
0,-2,5:17.1
0,-1,5:17.1
2,-1,5:17.1
-2,0,5:17.1
0,0,5:30
-3,1,5:17.1
0,1,5:17.1
0,-4,6:30
0,-3,6:17.1
0,-1,6:17.1
2,-1,6:17.1
3,-1,6:17.1
-3,1,6:17.1
0,1,6:17.1
-2,0,6:40
0,-4,7:17.1
0,-3,7:17.1
0,-1,7:17.1
3,-1,7:17.1
2,-1,7:39
0,-4,8:17.1
0,-1,8:17.1
