[META]
version=2.0
spawnOnBlockType=8,9
spawnSunlight=True
spawnDarkness=True
spawnWater=False
spawnLava=False
underFill=False
randomRotation=True
dig=True
tree=False
branch=False
needsFoundation=True
rarity=30
collisionPercentage=10
spawnElevationMin=0
spawnElevationMax=100
spawnInBiome=All
[DATA]
-2,-3,-6:17.0
2,-3,-6:17.0
0,1,-6:17.0
-2,-3,-5:17.0
1,-3,-5:17.0
2,-3,-5:17.0
-2,-2,-5:17.0
0,0,-5:17.0
0,1,-5:17.0
1,-3,-4:17.0
-2,-2,-4:17.0
-1,-2,-4:17.0
1,-2,-4:17.0
0,0,-4:17.0
-1,-2,-3:17.0
1,-2,-3:17.0
0,0,-3:17.0
0,1,-3:17.0
-1,-3,-2:17.0
-1,-2,-2:17.0
1,-2,-2:17.0
2,-2,-2:17.0
0,1,-2:17.0
-1,-3,-1:17.0
2,-2,-1:17.0
0,0,-1:17.0
0,1,-1:17.0
-1,-3,0:17.0
-1,-2,0:17.0
2,-2,0:17.0
1,-1,0:17.0
2,-1,0:17.0
0,0,0:17.0
-1,-2,1:17.0
0,-2,1:17.0
0,-1,1:17.0
1,-1,1:17.0
0,0,1:17.0
0,-1,2:17.0
0,-3,3:17.0
0,-2,3:17.0
-1,-1,3:17.0
0,-1,3:17.0
1,-1,3:17.0
2,-1,3:17.0
-1,0,3:17.0
-1,1,3:17.0
0,-3,4:17.0
-1,-2,4:98.1
0,-2,4:98.1
1,-2,4:98.1
2,-2,4:17.0
3,-2,4:17.0
-1,-1,4:109.0
0,-1,4:89.5
1,-1,4:98.1
2,-1,4:17.0
-1,0,4:98.1
0,0,4:98.1
1,0,4:98.0
-1,1,4:17.0
-1,-3,5:18.12
0,-3,5:17.0
-1,-2,5:109.3
0,-2,5:109.3
1,-2,5:98.1
2,-2,5:18.12
3,-2,5:17.0
-1,-1,5:98.2
1,-1,5:98.1
2,-1,5:18.12
3,-1,5:18.12
-1,0,5:109.2
0,0,5:109.2
1,0,5:98.1
-2,1,5:17.0
-1,1,5:17.0
0,-4,6:18.12
-1,-3,6:18.12
0,-3,6:17.0
1,-3,6:18.12
3,-3,6:18.12
-1,-2,6:98.1
0,-2,6:98.1
1,-2,6:98.1
2,-2,6:18.12
3,-2,6:17.0
4,-2,6:18.12
-1,-1,6:98.1
0,-1,6:98.1
1,-1,6:98.0
2,-1,6:17.0
3,-1,6:17.0
4,-1,6:18.12
-1,0,6:98.1
0,0,6:98.1
1,0,6:98.1
2,0,6:18.12
3,0,6:18.4
-3,1,6:18.12
-2,1,6:17.0
-1,1,6:18.12
-3,2,6:18.12
-2,2,6:18.12
-1,-4,7:18.12
0,-4,7:18.12
1,-4,7:18.12
-2,-3,7:18.12
-1,-3,7:18.12
0,-3,7:17.0
1,-3,7:18.12
2,-3,7:18.12
3,-3,7:18.12
-2,-2,7:18.12
-1,-2,7:18.12
0,-2,7:18.12
2,-2,7:18.12
3,-2,7:18.12
4,-2,7:18.12
-3,-1,7:18.12
-2,-1,7:18.12
-1,-1,7:18.12
0,-1,7:18.12
1,-1,7:18.12
2,-1,7:17.0
3,-1,7:18.12
4,-1,7:18.12
-3,0,7:18.12
-2,0,7:17.0
-1,0,7:18.12
1,0,7:18.12
2,0,7:18.12
3,0,7:18.12
-3,1,7:18.12
-2,1,7:17.0
-1,1,7:18.12
1,1,7:18.12
2,1,7:18.12
-3,2,7:18.12
-2,2,7:18.12
-1,2,7:18.4
-1,-4,8:18.12
0,-4,8:18.12
1,-4,8:18.12
-2,-3,8:18.12
-1,-3,8:18.12
0,-3,8:17.0
1,-3,8:18.12
2,-3,8:18.12
-2,-2,8:18.12
-1,-2,8:18.12
0,-2,8:18.12
2,-2,8:18.12
3,-2,8:18.12
-3,-1,8:18.12
-2,-1,8:18.12
0,-1,8:18.12
1,-1,8:18.12
2,-1,8:17.0
3,-1,8:18.12
4,-1,8:18.12
-3,0,8:18.12
-2,0,8:17.0
-1,0,8:18.12
0,0,8:18.12
1,0,8:18.12
2,0,8:18.12
3,0,8:18.12
-3,1,8:18.12
-2,1,8:18.12
-1,1,8:18.12
1,1,8:18.12
2,1,8:18.12
-3,2,8:18.12
-2,2,8:18.12
-1,2,8:18.12
0,-4,9:18.12
1,-4,9:18.12
-1,-3,9:18.12
0,-3,9:18.12
1,-3,9:18.12
2,-3,9:18.12
-1,-2,9:18.12
0,-2,9:18.12
1,-2,9:18.12
2,-2,9:18.12
3,-2,9:18.12
-2,-1,9:18.12
1,-1,9:18.12
2,-1,9:17.0
3,-1,9:18.12
-3,0,9:18.12
-2,0,9:18.12
1,0,9:18.12
2,0,9:18.12
3,0,9:18.12
-3,1,9:18.12
-2,1,9:18.12
-2,2,9:18.12
0,-3,10:18.12
2,-2,10:18.12
2,-1,10:18.12
3,-1,10:18.12
-2,0,10:18.12
2,0,10:18.12
2,-1,11:18.12
3,1,6:106.4
2,1,6:106.4
1,1,6:106.4
3,1,5:106.4
2,1,5:106.4
1,1,5:106.4
4,-2,5:106.2
-1,2,4:106.4
3,1,4:106.4
2,1,4:106.4
1,1,4:106.4
0,1,4:106.2
2,0,4:106.4
-2,0,4:106.8
3,-1,4:106.2
4,-2,4:106.2
-1,2,3:106.4
3,1,3:106.4
2,1,3:106.4
1,1,3:106.4
0,1,3:106.2
2,0,3:106.4
1,0,3:106.4
0,0,3:106.4
-2,0,3:106.8
3,-1,3:106.2
-2,-1,3:106.8
4,-2,3:106.2
2,-2,3:106.1
1,-2,3:106.1
-1,2,2:106.4
3,1,2:106.4
2,1,2:106.4
1,1,2:106.4
0,1,2:106.2
2,0,2:106.4
1,0,2:106.4
0,0,2:106.4
-2,0,2:106.8
3,-1,2:106.2
-1,-1,2:106.8
-2,-1,2:106.8
4,-2,2:106.2
2,-2,2:106.1
1,-2,2:106.1
-1,2,1:106.4
3,1,1:106.4
2,1,1:106.4
1,1,1:106.4
0,1,1:106.6
2,0,1:106.4
1,0,1:106.4
-1,0,1:106.8
-2,0,1:106.8
3,-1,1:106.2
-1,-1,1:106.8
-2,-1,1:106.8
4,-2,1:106.2
2,-2,1:106.1
1,-2,1:106.1
-2,-2,1:106.8
0,-3,1:106.1
-1,2,0:106.4
3,1,0:106.4
2,1,0:106.4
1,1,0:106.4
0,1,0:106.6
2,0,0:106.4
1,0,0:106.4
-1,0,0:106.8
-2,0,0:106.8
3,-1,0:106.2
-1,-1,0:106.8
-2,-1,0:106.8
4,-2,0:106.2
3,-2,0:106.2
1,-2,0:106.1
-2,-2,0:106.8
2,-3,0:106.1
0,-3,0:106.1
-2,-3,0:106.8
