[META]
version=2.0
spawnOnBlockType=12,8,9
spawnSunlight=True
spawnDarkness=True
spawnWater=True
spawnLava=False
underFill=False
randomRotation=True
dig=True
tree=False
branch=False
needsFoundation=false
rarity=300
collisionPercentage=50
spawnElevationMin=60
spawnElevationMax=64
spawnInBiome=All
[DATA]
-1,0,-6:17.0
1,1,-6:17.0
-2,-2,-5:17.0
0,-2,-5:17.0
2,-1,-5:17.0
-1,0,-5:17.0
1,1,-5:17.0
-1,-4,-4:17.0
-2,-2,-4:17.0
0,-2,-4:17.0
2,-1,-4:17.0
-3,0,-4:17.0
-1,0,-4:17.0
1,1,-4:17.0
-2,2,-4:17.0
0,3,-4:17.0
-1,-4,-3:17.0
-2,-2,-3:17.0
0,-2,-3:17.0
2,-1,-3:17.0
-3,0,-3:17.0
-1,0,-3:17.0
1,1,-3:17.0
-2,2,-3:17.0
0,3,-3:17.0
-1,-4,-2:17.0
-2,-2,-2:17.0
0,-2,-2:17.0
2,-1,-2:17.0
-3,0,-2:17.0
-1,0,-2:17.0
1,1,-2:17.0
-2,2,-2:17.0
0,3,-2:17.0
-1,-4,-1:17.0
-1,-3,-1:17.0
-2,-2,-1:17.0
0,-2,-1:17.0
1,-1,-1:17.0
2,-1,-1:17.0
-3,0,-1:17.0
-1,0,-1:17.0
1,1,-1:17.0
-2,2,-1:17.0
0,2,-1:17.0
-1,-3,0:17.0
-2,-2,0:17.0
0,-2,0:17.0
1,-1,0:17.0
-3,0,0:17.0
-1,0,0:17.0
1,1,0:17.0
-2,2,0:17.0
0,2,0:17.0
-1,-2,1:17.0
1,-1,1:17.0
-3,0,1:17.0
-2,0,1:17.0
-1,0,1:17.0
1,1,1:17.0
-1,2,1:17.0
0,2,1:17.0
-1,-2,2:17.0
-1,-1,2:17.0
-2,0,2:17.0
-1,0,2:17.0
0,0,2:17.0
-2,1,2:17.0
-1,1,2:17.0
1,1,2:17.0
-2,0,3:17.0
-1,0,3:17.0
-1,0,4:17.0
-1,0,5:17.0
-1,0,6:17.0
-1,0,7:17.0
-1,-1,8:17.0
-1,0,8:17.0
0,0,8:17.0
-1,1,8:17.0
-1,-3,9:18.14
-2,-2,9:18.14
-1,-2,9:17.0
0,-2,9:18.14
-3,-1,9:17.0
-4,0,9:18.6
-2,0,9:17.0
-1,0,9:17.0
1,0,9:17.0
0,1,9:18.14
-2,2,9:18.14
-1,2,9:17.0
1,2,9:18.14
-2,-4,10:18.6
-1,-4,10:18.14
0,-4,10:18.6
-3,-3,10:18.14
-2,-3,10:18.14
-1,-3,10:18.14
0,-3,10:18.14
1,-3,10:18.14
-3,-2,10:18.14
-2,-2,10:18.14
-1,-2,10:18.14
0,-2,10:18.14
1,-2,10:18.14
2,-2,10:18.14
-4,-1,10:18.14
-3,-1,10:18.14
-2,-1,10:18.14
-1,-1,10:18.14
0,-1,10:18.14
1,-1,10:18.14
2,-1,10:18.14
3,-1,10:18.6
-4,0,10:18.14
-3,0,10:18.14
-2,0,10:18.14
-1,0,10:18.14
0,0,10:18.14
1,0,10:18.14
2,0,10:18.14
3,0,10:18.14
-4,1,10:18.14
-3,1,10:18.14
-2,1,10:18.14
-1,1,10:18.14
0,1,10:18.14
1,1,10:18.14
2,1,10:18.14
3,1,10:18.14
-3,2,10:18.14
-2,2,10:18.14
-1,2,10:18.14
0,2,10:18.14
1,2,10:18.14
2,2,10:18.14
-2,3,10:18.14
-1,3,10:18.14
0,3,10:18.14
1,3,10:18.14
-1,-2,11:18.14
0,-2,11:18.14
-2,-1,11:18.14
-1,-1,11:18.14
0,-1,11:18.14
1,-1,11:18.14
-3,0,11:18.14
-2,0,11:18.14
-1,0,11:18.14
0,0,11:18.14
1,0,11:18.14
-2,1,11:18.14
-1,1,11:18.14
0,1,11:18.14
1,1,11:18.14
-1,2,11:18.14
0,2,11:18.6
-1,-1,12:18.14
0,-1,12:18.6
-2,0,12:18.6
-1,0,12:18.14
0,0,12:18.14
-1,1,12:18.14
