[META]
version=2.0
spawnOnBlockType=8,9
spawnSunlight=True
spawnDarkness=True
spawnWater=False
spawnLava=False
underFill=False
randomRotation=True
dig=True
tree=False
branch=False
needsFoundation=True
rarity=100
collisionPercentage=10
spawnElevationMin=0
spawnElevationMax=100
spawnInBiome=All
[DATA]
1,-3,0:17.0
-4,-2,0:17.0
1,-2,0:17.0
2,-2,0:17.0
-5,-1,0:17.0
-4,-1,0:17.0
-3,-1,0:17.0
-4,4,0:17.0
-3,4,0:17.0
1,4,0:17.0
2,4,0:17.0
3,4,0:17.0
-4,5,0:17.0
1,5,0:17.0
-5,5,0:106.4
-1,4,0:106.4
-2,4,0:106.4
2,3,0:106.1
1,3,0:106
-1,3,0:106.4
-4,3,0:106.8
-5,3,0:106.8
2,2,0:106.2
1,2,0:106.2
-5,2,0:106.8
3,1,0:106.2
1,1,0:106.2
2,0,0:106.2
-3,0,0:106.2
-5,0,0:106.8
2,-1,0:106.2
-2,-1,0:106.1
-1,-2,0:106.1
-1,-3,0:106.1
-2,-4,0:106.1
-3,-4,0:106.1
3,2,-8:17.0
-3,0,-7:17.0
0,2,-7:17.0
3,2,-7:17.0
-4,4,-7:17.0
-3,0,-6:17.0
0,2,-6:17.0
3,2,-6:17.0
-4,4,-6:17.0
-1,-2,-5:17.0
-3,0,-5:17.0
0,2,-5:17.0
3,3,-5:17.0
-4,4,-5:17.0
1,4,-5:17.0
-2,-2,-4:17.0
-3,-1,-4:17.0
0,1,-4:17.0
3,3,-4:17.0
-5,4,-4:17.0
1,4,-4:17.0
-3,5,-4:17.0
-2,-2,-3:17.0
-3,-1,-3:17.0
1,0,-3:17.0
1,1,-3:17.0
-5,4,-3:17.0
2,4,-3:17.0
3,4,-3:17.0
-2,5,-3:17.0
-3,-2,-2:17.0
1,-1,-2:17.0
-5,1,-2:17.0
3,4,-2:17.0
-5,5,-2:17.0
-1,5,-2:17.0
-4,-2,-1:17.0
1,-2,-1:17.0
-5,0,-1:17.0
3,3,-1:17.0
-4,5,-1:17.0
0,5,-1:17.0
3,5,-1:17.0
-4,-2,1:17.0
1,-2,1:17.0
-4,-1,1:17.0
-3,3,1:17.0
-3,4,1:17.0
1,4,1:17.0
2,4,1:17.0
1,5,1:106.4
-4,5,1:106.4
-5,5,1:106.4
3,4,1:106.2
-1,4,1:106.4
-2,4,1:106.4
2,3,1:106.1
1,3,1:106
-1,3,1:106.4
-4,3,1:106.8
-5,3,1:106.8
2,2,1:106.2
1,2,1:106.2
-5,2,1:106.8
3,1,1:106.2
1,1,1:106.2
2,0,1:106.2
-3,0,1:106.2
-5,0,1:106.8
2,-1,1:106.2
-2,-1,1:106.1
-3,-1,1:106.1
-5,-1,1:106.8
-1,-2,1:106.1
1,-3,1:106.1
-1,-3,1:106.1
-2,-4,1:106.1
-3,-4,1:106.1
1,-2,2:17.0
-4,-1,2:17.0
0,-1,2:17.0
1,-1,2:17.0
-4,0,2:17.0
-3,3,2:17.0
0,3,2:17.0
0,4,2:17.0
1,4,2:17.0
1,5,2:106.4
-4,5,2:106.4
-5,5,2:106.4
-1,4,2:106.4
-2,4,2:106.4
1,3,2:106
-1,3,2:106.4
-4,3,2:106.8
-5,3,2:106.8
2,2,2:106.2
1,2,2:106.2
-5,2,2:106.8
3,1,2:106.2
1,1,2:106.2
2,0,2:106.2
-3,0,2:106.2
-5,0,2:106.8
2,-1,2:106.2
-2,-1,2:106.1
-3,-1,2:106.1
-5,-1,2:106.8
-1,-2,2:106.1
1,-3,2:106.1
-1,-3,2:106.1
-2,-4,2:106.1
-3,-4,2:106.1
-4,-1,3:18
-1,-1,3:18
0,-1,3:18
1,-1,3:17.0
-4,0,3:17.0
-3,0,3:18
-2,0,3:18
-1,0,3:17.0
0,0,3:17.0
1,0,3:18
-4,1,3:18
-3,1,3:17.0
-2,1,3:17.0
-1,1,3:17.0
0,1,3:18
-4,2,3:18
-3,2,3:17.0
-2,2,3:17.0
-1,2,3:17.0
0,2,3:18
-3,3,3:18
-2,3,3:17.0
0,3,3:17.0
-4,5,3:106.4
-5,5,3:106.4
-1,4,3:106.4
-2,4,3:106.4
1,3,3:106.4
-1,3,3:106.4
-4,3,3:106.8
-5,3,3:106.8
2,2,3:106.2
1,2,3:106.2
-5,2,3:106.8
3,1,3:106.2
1,1,3:106.2
2,0,3:106.2
-5,0,3:106.8
2,-1,3:106.2
-2,-1,3:106.1
-3,-1,3:106.1
-5,-1,3:106.8
-1,-2,3:106.1
-1,-3,3:106.1
-2,-4,3:106.1
-3,-4,3:106.1
-4,0,4:18
-3,0,4:17.0
-1,0,4:17.0
0,0,4:18
-4,1,4:18
-3,1,4:17.0
-2,1,4:18
-1,1,4:17.0
0,1,4:18
-3,2,4:18
-2,2,4:17.0
-1,2,4:18
-2,3,4:18
-4,5,4:106.4
-5,5,4:106.4
-1,4,4:106.4
1,3,4:106.4
-5,3,4:106.8
2,2,4:106.2
-5,2,4:106.8
3,1,4:106.2
-5,-1,4:106.8
-1,-3,4:106.1
-2,-4,4:106.1
-3,-4,4:106.1
-3,0,5:18
-1,0,5:18
-4,1,5:18
-3,1,5:17.0
-2,1,5:18
-1,1,5:17.0
-2,2,5:17.0
-1,2,5:18
-4,5,5:106.4
-5,5,5:106.4
-1,4,5:106.4
1,3,5:106.4
-5,3,5:106.8
2,2,5:106.2
-5,2,5:106.8
3,1,5:106.2
-5,-1,5:106.8
-1,-3,5:106.1
-2,-4,5:106.1
-3,-4,5:106.1
-3,1,6:17.0
-1,1,6:17.0
-2,2,6:17.0
-4,5,6:106.4
-5,5,6:106.4
-1,4,6:106.4
1,3,6:106.4
-5,3,6:106.8
2,2,6:106.2
-5,2,6:106.8
3,1,6:106.2
-5,-1,6:106.8
-1,-3,6:106.1
-2,-4,6:106.1
-3,-4,6:106.1
-2,-1,7:18
-1,-1,7:18
-3,0,7:17.0
-2,0,7:18
-1,0,7:18
1,0,7:18
-3,1,7:17.0
-2,1,7:18
-1,1,7:17.0
0,1,7:18
1,1,7:18
2,1,7:18
-2,2,7:17.0
-1,2,7:18
0,2,7:18
1,2,7:18
-2,3,7:18
-1,3,7:18
-2,4,7:18
-4,5,7:106.4
-5,5,7:106.4
-1,4,7:106.4
1,3,7:106.4
-5,3,7:106.8
2,2,7:106.2
-5,2,7:106.8
3,1,7:106.2
-5,-1,7:106.8
-1,-3,7:106.1
-2,-4,7:106.1
-3,-4,7:106.1
-3,-3,8:18
-2,-3,8:18
0,-3,8:18
-4,-2,8:18
-3,-2,8:17.0
-2,-2,8:18
-1,-2,8:18
0,-2,8:17.0
1,-2,8:18
-4,-1,8:18
-3,-1,8:18
-2,-1,8:17.0
-1,-1,8:17.0
0,-1,8:18
1,-1,8:18
-3,0,8:18
-2,0,8:18
-1,0,8:18
0,0,8:18
1,0,8:18
-3,1,8:18
-2,1,8:18
-1,1,8:18
0,1,8:17.0
1,1,8:18
-4,2,8:18
-3,2,8:18
-2,2,8:17.0
-1,2,8:18
0,2,8:18
1,2,8:17.0
2,2,8:18
-4,3,8:18
-3,3,8:18
-2,3,8:18
1,3,8:18
-2,4,8:18
-4,5,8:106.4
-5,5,8:106.4
-5,3,8:106.8
-5,2,8:106.8
-5,-1,8:106.8
-1,-3,8:106.1
-2,-4,8:106.1
-3,-4,8:106.1
-3,-2,9:18
-2,-2,9:18
0,-2,9:18
-3,-1,9:18
-2,-1,9:18
-1,-1,9:18
0,-1,9:18
-2,0,9:18
-1,0,9:18
0,0,9:18
1,0,9:18
-3,1,9:18
-2,1,9:18
-1,1,9:18
0,1,9:18
1,1,9:18
-4,2,9:18
-3,2,9:18
-2,2,9:17.0
-1,2,9:18
0,2,9:18
1,2,9:18
-5,3,9:18
-4,3,9:17.0
-3,3,9:17.0
-2,3,9:18
0,3,9:18
-5,4,9:18
-4,4,9:18
-3,4,9:18
-4,5,9:106.4
-5,5,9:106.4
-5,2,9:106.8
0,-1,10:18
-1,0,10:18
-2,1,10:18
-1,1,10:18
0,1,10:18
-3,2,10:18
-2,2,10:18
-4,3,10:18
-3,3,10:18
