[META]
version=2.0
spawnOnBlockType=8,9
spawnSunlight=True
spawnDarkness=True
spawnWater=False
spawnLava=False
underFill=False
randomRotation=True
dig=True
tree=False
branch=False
needsFoundation=True
rarity=100
collisionPercentage=10
spawnElevationMin=0
spawnElevationMax=100
spawnInBiome=All
[DATA]
-1,0,-6:17.0
0,0,-6:17.0
-2,1,-6:17.0
-1,1,-6:17.0
0,1,-6:17.0
1,1,-6:17.0
-2,2,-6:17.0
-1,2,-6:17.0
0,2,-6:17.0
-1,0,-5:17.0
0,0,-5:17.0
-2,1,-5:17.0
-1,1,-5:17.0
0,1,-5:17.0
1,1,-5:17.0
-2,2,-5:17.0
-1,2,-5:17.0
-1,0,-4:17.0
0,0,-4:17.0
-2,1,-4:17.0
-1,1,-4:17.0
0,1,-4:17.0
1,1,-4:17.0
-1,2,-4:17.0
-1,0,-3:17.0
0,0,-3:17.0
-1,1,-3:17.0
0,1,-3:17.0
-1,2,-3:17.0
-1,0,-2:17.0
0,0,-2:17.0
-1,1,-2:17.0
0,1,-2:17.0
-1,0,-1:17.0
-1,1,-1:17.0
0,1,-1:17.0
-1,0,0:17.0
-1,1,0:17.0
0,1,0:17.0
-1,0,1:17.0
-1,1,1:17.0
0,1,1:18.12
-1,0,2:18.12
-1,1,2:17.0
-1,1,3:17.0
-1,1,4:17.0
-1,1,5:17.0
-1,1,6:17.0
-1,-1,7:18.4
-1,0,7:18.12
-3,1,7:18.12
-2,1,7:18.12
-1,1,7:17.0
0,1,7:18.12
-1,2,7:18.12
-1,-2,8:18.12
-2,-1,8:18.12
-1,-1,8:17.0
0,-1,8:18.12
-3,0,8:18.12
-2,0,8:18.12
-1,0,8:17.0
0,0,8:18.12
-4,1,8:18.12
-3,1,8:17.0
-2,1,8:17.0
-1,1,8:17.0
0,1,8:17.0
1,1,8:18.12
-3,2,8:18.12
-2,2,8:18.12
-1,2,8:17.0
0,2,8:18.12
-2,3,8:18.12
-1,3,8:18.12
-1,-5,9:18.12
-2,-4,9:18.12
-1,-4,9:18.12
0,-4,9:18.12
-3,-3,9:18.12
-2,-3,9:18.12
-1,-3,9:18.12
0,-3,9:18.12
1,-3,9:18.12
-3,-2,9:18.12
-2,-2,9:18.12
-1,-2,9:18.12
0,-2,9:18.12
1,-2,9:18.12
2,-2,9:18.12
-4,-1,9:18.12
-3,-1,9:18.12
-2,-1,9:18.12
-1,-1,9:17.0
0,-1,9:18.12
1,-1,9:18.12
2,-1,9:18.12
-5,0,9:18.12
-4,0,9:18.12
-3,0,9:18.12
-2,0,9:18.12
-1,0,9:18.12
0,0,9:18.12
1,0,9:18.12
2,0,9:18.12
3,0,9:18.12
-6,1,9:18.12
-5,1,9:18.12
-4,1,9:18.12
-3,1,9:17.0
-2,1,9:18.12
-1,1,9:18.12
0,1,9:17.0
1,1,9:17.0
2,1,9:18.12
3,1,9:18.12
4,1,9:18.12
-5,2,9:18.12
-4,2,9:18.12
-3,2,9:18.12
-2,2,9:18.12
-1,2,9:17.0
0,2,9:18.12
1,2,9:18.12
2,2,9:18.12
3,2,9:18.12
-4,3,9:18.12
-3,3,9:18.12
-2,3,9:18.12
-1,3,9:17.0
0,3,9:18.12
1,3,9:18.12
2,3,9:18.12
-3,4,9:18.12
-2,4,9:18.12
-1,4,9:18.12
0,4,9:18.12
1,4,9:18.12
-2,5,9:18.12
-1,5,9:18.12
0,5,9:18.12
1,5,9:18.12
-1,6,9:18.12
0,6,9:18.12
-1,-4,10:18.12
-2,-3,10:18.12
-1,-3,10:18.12
0,-3,10:18.12
-3,-2,10:18.12
-2,-2,10:18.12
-1,-2,10:18.12
0,-2,10:18.12
1,-2,10:18.4
-3,-1,10:18.12
-2,-1,10:18.12
-1,-1,10:18.12
0,-1,10:18.12
1,-1,10:18.12
-4,0,10:18.12
-3,0,10:18.12
-2,0,10:18.12
-1,0,10:18.12
0,0,10:18.12
1,0,10:18.12
2,0,10:18.12
-5,1,10:18.12
-4,1,10:18.12
-3,1,10:18.12
-2,1,10:18.12
-1,1,10:18.12
0,1,10:18.12
1,1,10:18.12
2,1,10:18.12
3,1,10:18.12
-4,2,10:18.12
-3,2,10:18.12
-2,2,10:18.12
-1,2,10:18.12
0,2,10:18.12
1,2,10:18.12
2,2,10:18.12
-3,3,10:18.12
-2,3,10:18.12
-1,3,10:18.12
0,3,10:18.12
1,3,10:18.12
-2,4,10:18.4
-1,4,10:18.12
0,4,10:18.12
-1,5,10:18.12
0,5,10:18.4
-1,-1,11:18.12
-2,0,11:18.12
-1,0,11:18.12
0,0,11:18.12
-3,1,11:18.12
-2,1,11:18.12
-1,1,11:18.12
0,1,11:18.12
1,1,11:18.12
-2,2,11:18.12
-1,2,11:18.12
0,2,11:18.12
-1,3,11:18.12
0,-4,10:106.1
0,7,9:106.4
-1,7,9:106.4
1,6,9:106.4
-2,6,9:106.4
2,5,9:106.2
-3,5,9:106.4
2,4,9:106.4
-4,4,9:106.4
-5,3,9:106.4
-6,2,9:106.8
-7,1,9:106.8
-6,0,9:106.8
-5,-1,9:106.8
3,-2,9:106.2
-4,-2,9:106.8
2,-3,9:106.2
-4,-3,9:106.8
-3,-4,9:106.1
-2,-5,9:106.1
-1,-6,9:106.1
0,7,8:106.4
-1,7,8:106.4
1,6,8:106.4
-2,6,8:106.4
2,5,8:106.2
-3,5,8:106.4
-4,4,8:106.4
-6,2,8:106.8
-5,1,8:106.8
-7,1,8:106.8
-4,0,8:106.8
-6,0,8:106.8
-3,-1,8:106.8
-4,-2,8:106.8
2,-3,8:106.2
-1,-3,8:106.1
-4,-3,8:106.8
0,7,7:106.4
-1,7,7:106.4
1,6,7:106.4
2,5,7:106.2
-3,5,7:106.4
-4,4,7:106.4
-1,3,7:106.4
-3,2,7:106.4
1,1,7:106.2
-4,1,7:106.8
0,0,7:106.1
-4,0,7:106.8
-2,-1,7:106.8
-3,-1,7:106.8
-1,-2,7:106.1
-4,-2,7:106.8
-1,-3,7:106.1
-4,-3,7:106.8
-4,4,6:106.4
-1,3,6:106.4
-1,2,6:106.4
0,1,6:106.2
-2,1,6:106.8
0,0,6:106.1
-1,0,6:106.1
-4,-2,6:106.8
-4,4,5:106.4
-1,2,5:106.4
0,1,5:106.2
-2,1,5:106.8
0,0,5:106.1
-1,0,5:106.1
-1,2,4:106.4
0,1,4:106.2
-2,1,4:106.8
-1,0,4:106.1
-1,2,3:106.4
0,1,3:106.2
-2,1,3:106.8
-1,0,3:106.1
-1,2,2:106.4
0,1,2:106.2
-2,1,2:106.8
0,0,2:106.2
-2,0,2:106.8
-1,-1,2:106.1
0,2,1:106.4
-1,2,1:106.4
1,1,1:106.2
-2,1,1:106.8
0,0,1:106.3
-2,0,1:106.8
-1,-1,1:106.1
0,2,0:106.4
-1,2,0:106.4
1,1,0:106.2
-2,1,0:106.8
0,0,0:106.3
-2,0,0:106.8
-1,-1,0:106.1
