[META]
version=2.0
spawnOnBlockType=2,3
spawnSunlight=True
spawnDarkness=True
spawnWater=False
spawnLava=False
underFill=True
randomRotation=False
dig=True
tree=False
branch=False
needsFoundation=True
rarity=20
collisionPercentage=2
spawnElevationMin=0
spawnElevationMax=115
spawnInBiome=All
[DATA]
0,-1,0:17.1
0,0,0:13
-1,0,0:40
-2,-1,0:39
0,-2,0:40
-1,-1,-3:1
0,-1,-3:88
-1,0,-3:3
0,0,-3:1
-1,-2,-2:88
0,-2,-2:88
-2,-1,-2:3
-1,-1,-2:17.1
0,-1,-2:3
1,-1,-2:88
-2,0,-2:88
-1,0,-2:88
0,0,-2:88
1,0,-2:88
-1,1,-2:88
0,1,-2:88
-1,-3,-1:110
0,-3,-1:110
-2,-2,-1:110
-1,-2,-1:88
0,-2,-1:88
1,-2,-1:110
-3,-1,-1:110
-2,-1,-1:88
-1,-1,-1:17.1
0,-1,-1:17.1
1,-1,-1:88
2,-1,-1:110
-3,0,-1:110
-2,0,-1:110
-1,0,-1:88
0,0,-1:3
1,0,-1:88
2,0,-1:110
-2,1,-1:110
-1,1,-1:13
0,1,-1:13
1,1,-1:110
-1,2,-1:110
0,2,-1:110
0,-1,1:17.1
0,0,1:30
1,-2,2:17.1
0,-1,2:17.1
0,0,2:17.1
1,-2,3:17.1
0,-1,3:30
0,0,3:17.1
0,1,3:17.1
0,1,4:17.1
1,-2,4:39
0,1,5:40
