[META]
version=2.0
spawnOnBlockType=2
spawnSunlight=True
spawnDarkness=True
spawnWater=False
spawnLava=False
underFill=False
randomRotation=True
dig=False
tree=true
branch=False
needsFoundation=True
rarity=50
collisionPercentage=70
spawnElevationMin=0
spawnElevationMax=100
spawnInBiome=All
[DATA]
0,0,0:17.0
0,1,0:17.0
0,2,0:31.0
-1,2,0:31.0
-2,1,0:31.0
1,0,0:31.0
-2,0,0:31.0
2,-1,0:31.0
-1,-1,0:31.0
0,-2,0:31.0
0,0,-4:3
-1,-1,-3:3
0,-1,-3:3
-1,0,-3:3
0,0,-3:17.0
1,0,-3:3
0,1,-3:3
0,-2,-2:3
-1,-1,-2:17.0
0,-1,-2:17.0
1,-1,-2:3
-2,0,-2:3
-1,0,-2:17.0
0,0,-2:17.0
1,0,-2:17.0
2,0,-2:17.0
-2,1,-2:3
-1,1,-2:3
0,1,-2:17.0
1,1,-2:17.0
-1,2,-2:3
0,2,-2:3
0,-2,-1:2
1,-2,-1:17.0
-2,-1,-1:17.0
-1,-1,-1:2
0,-1,-1:17.0
1,-1,-1:17.0
2,-1,-1:2
-2,0,-1:2
-1,0,-1:17.0
0,0,-1:17.0
1,0,-1:2
2,0,-1:17.0
-2,1,-1:2
-1,1,-1:17.0
0,1,-1:3
1,1,-1:17.0
-1,2,-1:2
0,2,-1:2
0,0,1:17.0
0,0,2:17.0
0,0,3:17.0
0,0,4:17.0
0,-1,5:17.0
-1,0,5:17.0
0,0,5:17.0
1,0,5:17.0
0,1,5:17.0
0,-2,6:17.0
2,-1,6:17.0
-2,0,6:17.0
0,0,6:17.0
2,1,6:17.0
0,2,6:17.0
0,-2,7:17.0
-2,-1,7:17.0
2,-1,7:17.0
0,0,7:17.0
-2,1,7:17.0
2,1,7:17.0
0,2,7:17.0
0,-3,8:17.0
-3,-2,8:17.0
3,-2,8:17.0
0,0,8:17.0
-3,2,8:17.0
3,2,8:17.0
-1,3,8:17.0
0,0,9:17.0
1,0,9:17.0
-1,1,9:17.0
0,-1,10:17.0
0,0,10:17.0
2,0,10:17.0
-2,2,10:17.0
-1,-2,11:17.0
0,0,11:17.0
3,0,11:17.0
0,1,11:17.0
1,-1,12:17.0
0,0,12:17.0
0,0,13:17.0
