[META]
version=2.0
spawnOnBlockType=8,9
spawnSunlight=True
spawnDarkness=True
spawnWater=False
spawnLava=False
underFill=False
randomRotation=True
dig=True
tree=False
branch=False
needsFoundation=True
rarity=100
collisionPercentage=10
spawnElevationMin=0
spawnElevationMax=100
spawnInBiome=All
[DATA]
-1,-1,0:17.0
-3,1,0:17.0
1,1,0:17.0
0,4,0:17.0
0,5,0:106.4
-1,5,0:106.4
1,4,0:106.2
-2,4,0:106.8
0,3,0:106.2
-2,3,0:106
1,2,0:106.4
0,2,0:106
-2,2,0:106.8
-3,2,0:106.4
2,1,0:106.2
-4,1,0:106.8
1,0,0:106.1
0,0,0:106
-2,0,0:106
0,-1,0:106.2
-2,-1,0:106.8
-1,-2,0:106.1
-2,-2,0:106.8
-1,-3,0:106.1
-1,-2,-6:17.0
-4,1,-6:17.0
1,1,-6:17.0
-1,4,-6:17.0
-1,-2,-5:17.0
-1,-1,-5:17.0
-4,1,-5:17.0
1,1,-5:17.0
-1,4,-5:17.0
-1,-1,-4:17.0
-1,0,-4:17.0
-4,1,-4:17.0
-3,1,-4:17.0
0,1,-4:17.0
1,1,-4:17.0
-1,3,-4:17.0
-1,4,-4:17.0
-1,0,-3:17.0
-3,1,-3:17.0
0,1,-3:17.0
-1,3,-3:17.0
-1,0,-2:17.0
-3,1,-2:17.0
0,1,-2:17.0
1,1,-2:17.0
-1,3,-2:17.0
-1,-1,-1:17.0
-3,1,-1:17.0
1,1,-1:17.0
-1,3,-1:17.0
0,4,-1:17.0
-1,-1,1:17.0
-1,0,1:17.0
-3,1,1:17.0
1,1,1:17.0
-1,3,1:17.0
-1,4,1:17.0
0,4,1:17.0
0,5,1:106.4
-1,5,1:106.4
1,4,1:106.2
-2,4,1:106.8
0,3,1:106.2
-2,3,1:106
-4,3,1:106.8
1,2,1:106.4
0,2,1:106
-2,2,1:106.8
-3,2,1:106.4
2,1,1:106.2
-4,1,1:106.8
1,0,1:106.1
0,0,1:106
-2,0,1:106
0,-1,1:106.2
-2,-1,1:106.8
-1,-2,1:106.1
-2,-2,1:106.8
-1,-3,1:106.1
-1,0,2:17.0
-3,1,2:17.0
-2,1,2:17.0
-1,1,2:17.0
0,1,2:17.0
1,1,2:17.0
-1,2,2:17.0
-1,3,2:17.0
-1,4,2:106.4
0,3,2:106.2
-2,3,2:106
-4,3,2:106.8
1,2,2:106.4
0,2,2:106
-2,2,2:106.8
-3,2,2:106.4
2,1,2:106.2
-4,1,2:106.8
1,0,2:106.1
0,0,2:106
-2,0,2:106
0,-1,2:106.2
-2,-1,2:106.8
0,-2,2:106.2
-2,-2,2:106.8
-1,-3,2:106.1
-2,1,3:17.0
-1,1,3:17.0
0,1,3:17.0
-1,2,3:17.0
-1,3,3:106.4
-2,3,3:106.4
-4,3,3:106.8
1,2,3:106.4
0,2,3:106
-2,2,3:106.8
2,1,3:106.2
1,1,3:106.2
1,0,3:106.1
0,0,3:106
-1,0,3:106.1
-2,0,3:106
0,-1,3:106.2
-2,-1,3:106.8
0,-2,3:106.2
-2,-2,3:106.8
-1,-3,3:106.1
-1,1,4:17.0
0,1,4:17.0
-1,2,4:17.0
-1,3,4:106.4
-2,3,4:106.4
-4,3,4:106.8
1,2,4:106.4
0,2,4:106
-2,2,4:106.8
2,1,4:106.2
1,1,4:106.2
-2,1,4:106
1,0,4:106.1
0,0,4:106
-1,0,4:106.1
-2,0,4:106.8
0,-1,4:106.2
-2,-1,4:106.8
0,-2,4:106.2
-2,-2,4:106.8
-1,-3,4:106.1
-1,1,5:17.0
-1,2,5:17.0
-1,3,5:106.4
-2,3,5:106.4
-4,3,5:106.8
1,2,5:106.4
0,2,5:106
-2,2,5:106.8
-3,2,5:106.8
2,1,5:106.2
-2,1,5:106
1,0,5:106.1
0,0,5:106.2
-1,0,5:106.1
-2,0,5:106.8
0,-1,5:106.2
-2,-1,5:106.8
0,-2,5:106.2
-2,-2,5:106.8
-1,-3,5:106.1
-1,0,6:17.0
-1,1,6:17.0
-3,4,6:106.4
-2,3,6:106.4
-4,3,6:106.8
1,2,6:106.4
0,2,6:106.4
-1,2,6:106.4
-3,2,6:106.8
2,1,6:106.2
-2,1,6:106
1,0,6:106.1
0,0,6:106.2
-2,0,6:106.8
0,-1,6:106.2
-2,-1,6:106.8
0,-2,6:106.2
-2,-2,6:106.8
-1,-3,6:106.1
-1,-1,7:17.0
-1,0,7:17.0
-1,1,7:17.0
0,1,7:17.0
-2,2,7:17.0
-3,4,7:106.4
-2,3,7:106.4
-4,3,7:106.8
1,2,7:106.4
0,2,7:106.4
-1,2,7:106.4
-3,2,7:106.8
2,1,7:106.2
-2,1,7:106
1,0,7:106.1
-2,0,7:106.8
0,-1,7:106.2
-2,-1,7:106.8
0,-2,7:106.2
-2,-2,7:106.8
-1,-3,7:106.1
-1,-2,8:17.0
-1,-1,8:17.0
0,1,8:17.0
-2,2,8:17.0
-3,4,8:106.4
-2,3,8:106.4
-4,3,8:106.8
1,2,8:106.4
0,2,8:106.4
-3,2,8:106.8
2,1,8:106.2
-1,1,8:106.8
-2,1,8:106.1
1,0,8:106.1
-1,0,8:39
-2,-1,8:106.8
0,-2,8:106.2
-2,-2,8:106.8
-1,-3,8:106.1
-1,-2,9:17.0
0,1,9:17.0
1,1,9:17.0
-2,2,9:17.0
-3,3,9:17.0
-3,4,9:106.4
-4,3,9:106.8
1,2,9:106.4
-3,2,9:106.8
2,1,9:106.2
-1,1,9:106.8
-2,1,9:106.1
1,0,9:106.1
-1,-1,9:106.4
-2,-2,9:106.8
-1,-3,9:106.1
-1,-2,10:17.0
1,1,10:17.0
-3,3,10:17.0
-4,3,10:106.8
1,2,10:106.4
-2,2,10:40
2,1,10:106.2
0,1,10:106.8
1,0,10:106.1
-1,-1,10:106.4
-2,-2,10:106.8
1,1,11:17.0
1,2,11:106.4
2,1,11:106.2
0,1,11:106.8
1,0,11:106.1
-1,-2,11:40
1,1,12:17.0
1,2,12:106.4
0,1,12:106.8
1,0,12:106.1
