[META]
version=2.0
spawnOnBlockType=8,9
spawnSunlight=True
spawnDarkness=True
spawnWater=False
spawnLava=False
underFill=False
randomRotation=True
dig=True
tree=False
branch=False
needsFoundation=True
rarity=100
collisionPercentage=10
spawnElevationMin=0
spawnElevationMax=100
spawnInBiome=All
[DATA]
-4,2,-6:17.0
-4,3,-6:17.0
-3,3,-6:17.0
-1,4,-6:17.0
0,4,-6:17.0
-1,5,-6:17.0
-4,6,-6:17.0
-3,6,-6:17.0
-1,6,-6:17.0
-3,7,-6:17.0
-4,2,-5:17.0
-4,3,-5:17.0
-3,3,-5:17.0
-1,4,-5:17.0
0,4,-5:17.0
-1,5,-5:17.0
-4,6,-5:17.0
-3,6,-5:17.0
-1,6,-5:17.0
-3,7,-5:17.0
-4,2,-4:17.0
-4,3,-4:17.0
-3,3,-4:17.0
-1,4,-4:17.0
-1,5,-4:17.0
0,5,-4:17.0
-4,6,-4:17.0
-3,6,-4:17.0
-4,7,-4:17.0
-3,7,-4:17.0
-5,2,-3:17.0
-4,2,-3:17.0
-3,2,-3:17.0
-4,3,-3:17.0
-3,3,-3:17.0
-1,4,-3:17.0
0,4,-3:17.0
-1,5,-3:17.0
0,5,-3:17.0
-4,7,-3:17.0
-3,7,-3:17.0
-5,2,-2:17.0
-4,2,-2:17.0
-3,2,-2:17.0
-4,3,-2:17.0
-3,3,-2:17.0
0,4,-2:17.0
1,4,-2:17.0
0,5,-2:17.0
1,5,-2:17.0
-4,6,-2:17.0
-4,7,-2:17.0
-3,7,-2:17.0
-5,1,-1:17.0
-4,1,-1:17.0
-5,2,-1:17.0
-4,2,-1:17.0
-3,2,-1:17.0
0,3,-1:17.0
0,4,-1:17.0
1,4,-1:17.0
0,5,-1:17.0
1,5,-1:17.0
-4,6,-1:17.0
-4,7,-1:17.0
-3,7,-1:17.0
-5,1,0:17.0
-4,1,0:17.0
-5,2,0:17.0
-4,2,0:17.0
-3,2,0:17.0
-1,2,0:18.4
-5,3,0:18.4
-1,3,0:17.0
0,3,0:17.0
-3,4,0:17.0
-1,4,0:17.0
0,4,0:17.0
1,4,0:17.0
0,5,0:18.4
1,5,0:17.0
-4,6,0:17.0
-3,6,0:17.0
-4,7,0:18.4
-3,7,0:17.0
-5,1,1:18.12
-4,1,1:17.0
-5,2,1:18.12
-4,2,1:17.0
-2,2,1:18.12
-1,2,1:18.12
-4,3,1:17.0
-2,3,1:17.0
-1,3,1:17.0
0,3,1:17.0
-3,4,1:17.0
-2,4,1:17.0
-1,4,1:17.0
0,4,1:17.0
1,4,1:17.0
-4,5,1:17.0
-3,5,1:17.0
1,5,1:18.12
-3,6,1:17.0
-3,7,1:18.12
-5,1,2:18.12
-4,1,2:18.12
-4,2,2:17.0
-3,2,2:17.0
-2,2,2:18.12
-4,3,2:17.0
-3,3,2:17.0
-2,3,2:17.0
-1,3,2:17.0
-4,4,2:17.0
-3,4,2:17.0
-2,4,2:17.0
-1,4,2:17.0
0,4,2:17.0
1,4,2:18.12
-4,5,2:17.0
-3,5,2:17.0
-3,6,2:17.0
-3,7,2:18.12
-4,2,3:18.12
-3,2,3:17.0
-2,2,3:18.12
-4,3,3:17.0
-3,3,3:17.0
-2,3,3:17.0
-1,3,3:17.0
-4,4,3:17.0
-3,4,3:17.0
-2,4,3:17.0
-1,4,3:17.0
0,4,3:18.12
-3,5,3:17.0
-1,5,3:18.12
-3,6,3:18.12
-4,2,4:18.12
-3,2,4:17.0
-3,3,4:17.0
-2,3,4:17.0
-1,3,4:18.12
-3,4,4:17.0
-2,4,4:17.0
-1,4,4:17.0
-3,5,4:18.12
-1,5,4:18.12
-4,2,5:18.4
-3,2,5:17.0
-3,3,5:17.0
-2,3,5:17.0
-1,3,5:18.12
-4,4,5:18.12
-3,4,5:17.0
-2,4,5:17.0
-1,4,5:17.0
-4,5,5:18.4
-3,5,5:18.12
-1,5,5:18.12
-4,2,6:18.12
-3,2,6:17.0
-2,2,6:17.0
-1,2,6:18.12
-3,3,6:17.0
-2,3,6:17.0
-1,3,6:17.0
-4,4,6:18.12
-3,4,6:17.0
-2,4,6:17.0
-1,4,6:17.0
-2,5,6:18.12
-4,2,7:18.12
-3,2,7:18.12
-2,2,7:17.0
-1,2,7:18.12
-3,3,7:17.0
-2,3,7:17.0
-1,3,7:17.0
-4,4,7:18.4
-3,4,7:17.0
-2,4,7:17.0
-2,5,7:18.12
-3,1,8:18.12
-3,2,8:18.12
-2,2,8:17.0
-1,2,8:18.12
-3,3,8:17.0
-2,3,8:17.0
-1,3,8:17.0
-4,4,8:18.12
-3,4,8:17.0
-2,4,8:17.0
-2,5,8:18.12
-3,1,9:18.12
-2,1,9:18.12
-3,2,9:17.0
-2,2,9:17.0
-1,2,9:18.12
-4,3,9:18.12
-3,3,9:17.0
-2,3,9:17.0
-1,3,9:17.0
-2,4,9:18.12
-2,5,9:18.12
-2,0,10:18.12
-1,0,10:18.12
-3,1,10:18.12
-2,1,10:17.0
-1,1,10:18.12
-3,2,10:17.0
-2,2,10:17.0
-1,2,10:17.0
-4,3,10:18.12
-3,3,10:17.0
-2,3,10:17.0
-1,3,10:18.12
-2,4,10:18.12
-1,4,10:18.12
-2,0,11:18.12
-1,0,11:18.12
-2,1,11:17.0
-1,1,11:17.0
0,1,11:18.12
-4,2,11:18.4
-3,2,11:18.12
-2,2,11:17.0
-1,2,11:17.0
-1,3,11:18.12
0,-1,12:18.12
-2,0,12:18.12
-1,0,12:17.0
0,0,12:18.12
1,0,12:18.12
-2,1,12:18.12
-1,1,12:17.0
0,1,12:17.0
1,1,12:18.12
-3,2,12:18.12
-2,2,12:18.12
-1,2,12:18.12
0,2,12:18.12
-1,3,12:18.12
0,-2,13:18.12
-1,-1,13:18.12
0,-1,13:17.0
1,-1,13:18.12
-2,0,13:18.12
-1,0,13:17.0
0,0,13:17.0
1,0,13:17.0
2,0,13:18.12
-2,1,13:18.12
-1,1,13:17.0
0,1,13:17.0
1,1,13:18.12
-2,2,13:18.12
-1,2,13:18.12
0,2,13:18.12
1,2,13:18.12
-1,3,13:18.12
0,3,13:18.12
0,-6,14:18.12
1,-6,14:18.12
0,-5,14:18.12
1,-5,14:18.12
2,-3,14:18.12
-1,-2,14:18.12
0,-2,14:18.12
1,-2,14:18.12
-1,-1,14:18.12
0,-1,14:17.0
1,-1,14:17.0
2,-1,14:18.12
3,-1,14:18.12
4,-1,14:18.4
-3,0,14:18.12
-2,0,14:18.12
-1,0,14:17.0
0,0,14:17.0
1,0,14:17.0
2,0,14:18.12
-2,1,14:18.4
-1,1,14:18.12
0,1,14:18.12
1,1,14:18.12
-2,2,14:18.12
-1,2,14:18.12
0,2,14:18.12
1,2,14:18.12
2,2,14:18.4
-1,3,14:18.12
0,3,14:18.12
0,-7,15:18.12
-1,-6,15:18.12
0,-6,15:18.12
1,-6,15:18.12
1,-5,15:18.12
0,-4,15:18.12
1,-4,15:18.12
2,-4,15:18.12
3,-4,15:18.12
0,-3,15:18.12
1,-3,15:18.12
2,-3,15:18.12
3,-3,15:18.12
-1,-2,15:18.12
0,-2,15:18.12
1,-2,15:18.12
2,-2,15:18.12
3,-2,15:18.12
4,-2,15:18.12
-5,-1,15:18.12
-4,-1,15:18.12
-3,-1,15:18.12
-2,-1,15:18.12
-1,-1,15:18.12
0,-1,15:17.0
1,-1,15:17.0
2,-1,15:17.0
3,-1,15:17.0
4,-1,15:17.0
5,-1,15:18.12
-5,0,15:18.12
-4,0,15:18.12
-3,0,15:18.12
-2,0,15:18.12
-1,0,15:18.12
0,0,15:18.12
1,0,15:17.0
2,0,15:18.12
3,0,15:18.12
4,0,15:18.12
-4,1,15:18.12
-3,1,15:18.12
-2,1,15:18.12
-1,1,15:18.12
0,1,15:18.12
1,1,15:18.12
2,1,15:18.12
3,1,15:18.12
4,1,15:18.12
-6,2,15:18.12
-5,2,15:18.12
-4,2,15:18.12
-3,2,15:18.12
-2,2,15:18.12
-1,2,15:18.12
0,2,15:18.12
1,2,15:18.12
2,2,15:18.12
3,2,15:18.12
-6,3,15:18.12
-4,3,15:18.12
-3,3,15:18.12
-2,3,15:18.12
-1,3,15:18.12
0,3,15:18.12
1,3,15:18.12
2,3,15:18.12
3,3,15:18.12
-1,4,15:18.12
0,4,15:18.12
1,4,15:18.4
2,4,15:18.12
3,4,15:18.12
3,5,15:18.12
4,5,15:18.12
-2,-7,16:18.12
-1,-7,16:18.12
0,-7,16:18.12
-2,-6,16:18.12
-1,-6,16:18.12
0,-6,16:18.12
1,-6,16:18.12
2,-6,16:18.12
3,-6,16:18.12
-2,-5,16:18.12
-1,-5,16:18.12
0,-5,16:18.12
1,-5,16:18.12
2,-5,16:18.12
3,-5,16:18.12
4,-5,16:18.12
-1,-4,16:18.12
0,-4,16:18.12
1,-4,16:18.12
2,-4,16:18.12
3,-4,16:18.12
4,-4,16:18.12
5,-4,16:18.12
9,-4,16:18.12
10,-4,16:18.12
11,-4,16:18.12
-3,-3,16:18.12
-2,-3,16:18.12
-1,-3,16:18.12
0,-3,16:18.12
1,-3,16:18.12
2,-3,16:18.12
3,-3,16:18.12
4,-3,16:18.12
5,-3,16:18.12
7,-3,16:18.12
8,-3,16:18.12
9,-3,16:18.12
10,-3,16:18.4
-3,-2,16:18.12
-2,-2,16:18.12
-1,-2,16:18.12
0,-2,16:18.12
1,-2,16:17.0
2,-2,16:17.0
3,-2,16:18.12
4,-2,16:18.12
5,-2,16:18.12
6,-2,16:18.12
7,-2,16:18.12
8,-2,16:18.12
9,-2,16:18.12
-7,-1,16:18.12
-6,-1,16:18.12
-4,-1,16:18.12
-3,-1,16:17.0
-2,-1,16:17.0
-1,-1,16:17.0
0,-1,16:17.0
1,-1,16:17.0
2,-1,16:18.12
3,-1,16:18.12
4,-1,16:17.0
5,-1,16:17.0
6,-1,16:18.12
7,-1,16:18.12
-7,0,16:18.12
-6,0,16:18.12
-5,0,16:18.12
-4,0,16:18.12
-3,0,16:18.12
-2,0,16:18.12
-1,0,16:18.12
0,0,16:18.12
1,0,16:17.0
2,0,16:18.12
3,0,16:18.12
4,0,16:18.12
5,0,16:18.12
6,0,16:18.4
-7,1,16:18.12
-6,1,16:18.12
-5,1,16:18.12
-4,1,16:18.12
-3,1,16:18.12
-2,1,16:18.12
-1,1,16:18.12
0,1,16:18.12
1,1,16:18.12
2,1,16:18.12
4,1,16:18.12
5,1,16:18.12
-7,2,16:18.12
-6,2,16:18.12
-5,2,16:18.12
-4,2,16:18.12
-3,2,16:18.12
-2,2,16:18.12
-1,2,16:18.12
0,2,16:18.12
1,2,16:18.12
2,2,16:18.12
3,2,16:18.12
4,2,16:18.12
-7,3,16:18.12
-6,3,16:18.12
-5,3,16:18.12
-4,3,16:18.12
-3,3,16:18.12
-2,3,16:18.12
-1,3,16:18.12
0,3,16:18.12
1,3,16:18.12
2,3,16:18.12
3,3,16:18.12
4,3,16:18.12
-6,4,16:18.12
-4,4,16:18.12
-3,4,16:18.12
-2,4,16:18.12
-1,4,16:18.12
0,4,16:18.12
1,4,16:18.12
2,4,16:18.12
3,4,16:18.12
4,4,16:18.12
-2,5,16:18.12
-1,5,16:18.12
0,5,16:18.12
1,5,16:18.12
2,5,16:18.12
3,5,16:18.12
4,5,16:18.12
5,5,16:18.12
-1,6,16:18.4
0,6,16:18.12
2,6,16:18.12
3,6,16:18.4
-3,-10,17:18.12
-4,-9,17:18.12
-2,-9,17:18.12
-3,-8,17:18.12
-2,-8,17:18.12
-1,-8,17:18.12
-3,-7,17:18.12
-2,-7,17:18.12
-1,-7,17:18.12
0,-7,17:18.12
1,-7,17:18.12
9,-7,17:18.12
-3,-6,17:18.12
-2,-6,17:18.12
-1,-6,17:18.12
0,-6,17:18.12
1,-6,17:18.12
3,-6,17:18.12
4,-6,17:18.12
8,-6,17:18.12
9,-6,17:18.12
-3,-5,17:18.12
-2,-5,17:18.12
-1,-5,17:18.12
0,-5,17:18.12
1,-5,17:18.12
2,-5,17:18.12
3,-5,17:18.12
4,-5,17:18.12
6,-5,17:18.12
9,-5,17:18.12
10,-5,17:18.12
11,-5,17:18.12
-3,-4,17:18.12
-2,-4,17:18.12
-1,-4,17:18.12
0,-4,17:17.0
1,-4,17:17.0
2,-4,17:18.12
3,-4,17:18.12
4,-4,17:18.12
5,-4,17:18.12
6,-4,17:18.12
7,-4,17:18.12
8,-4,17:18.12
9,-4,17:18.12
10,-4,17:18.12
11,-4,17:18.12
-4,-3,17:18.12
-3,-3,17:18.12
-2,-3,17:18.12
-1,-3,17:18.12
0,-3,17:18.12
1,-3,17:17.0
2,-3,17:18.12
3,-3,17:18.12
4,-3,17:18.12
5,-3,17:18.12
6,-3,17:18.12
7,-3,17:17.0
8,-3,17:17.0
9,-3,17:18.12
10,-3,17:18.12
11,-3,17:18.12
-5,-2,17:18.12
-4,-2,17:18.12
-3,-2,17:18.12
-2,-2,17:18.12
-1,-2,17:18.12
0,-2,17:18.12
1,-2,17:17.0
2,-2,17:18.12
3,-2,17:18.12
4,-2,17:18.12
5,-2,17:18.12
6,-2,17:17.0
7,-2,17:17.0
8,-2,17:18.12
9,-2,17:18.12
10,-2,17:18.12
11,-2,17:18.12
-6,-1,17:18.12
-5,-1,17:18.12
-4,-1,17:18.12
-3,-1,17:17.0
-2,-1,17:18.12
-1,-1,17:18.12
0,-1,17:18.12
1,-1,17:18.12
2,-1,17:18.12
3,-1,17:18.12
4,-1,17:18.12
5,-1,17:17.0
6,-1,17:17.0
7,-1,17:18.12
8,-1,17:18.12
9,-1,17:18.12
10,-1,17:18.12
11,-1,17:18.12
-7,0,17:18.12
-6,0,17:18.12
-5,0,17:18.12
-4,0,17:17.0
-3,0,17:17.0
-2,0,17:18.12
-1,0,17:18.12
0,0,17:18.12
1,0,17:17.0
2,0,17:18.12
4,0,17:18.12
5,0,17:18.12
6,0,17:18.12
7,0,17:18.12
8,0,17:18.12
9,0,17:18.12
10,0,17:18.4
-8,1,17:18.12
-7,1,17:18.12
-6,1,17:18.12
-5,1,17:17.0
-4,1,17:17.0
-3,1,17:18.12
-2,1,17:18.12
-1,1,17:18.12
0,1,17:18.12
1,1,17:17.0
2,1,17:18.12
3,1,17:18.12
4,1,17:18.12
5,1,17:18.12
6,1,17:18.12
7,1,17:18.12
9,1,17:18.12
-9,2,17:18.12
-8,2,17:18.12
-7,2,17:18.12
-6,2,17:18.12
-5,2,17:18.12
-4,2,17:18.12
-3,2,17:18.12
-2,2,17:18.12
-1,2,17:18.12
0,2,17:18.12
1,2,17:17.0
2,2,17:18.12
3,2,17:18.12
4,2,17:18.12
5,2,17:18.12
6,2,17:18.12
7,2,17:18.12
-9,3,17:18.12
-8,3,17:18.12
-7,3,17:18.12
-6,3,17:18.12
-5,3,17:18.12
-3,3,17:18.12
-2,3,17:18.12
-1,3,17:18.12
0,3,17:18.12
1,3,17:17.0
2,3,17:17.0
3,3,17:18.12
4,3,17:18.12
5,3,17:18.12
-10,4,17:18.12
-9,4,17:18.12
-8,4,17:18.12
-7,4,17:18.12
-6,4,17:18.12
-4,4,17:18.12
-3,4,17:18.12
-2,4,17:18.12
-1,4,17:18.12
0,4,17:18.12
1,4,17:18.12
2,4,17:18.12
3,4,17:18.12
4,4,17:18.12
-10,5,17:18.12
-7,5,17:18.12
-4,5,17:18.12
-3,5,17:18.12
-2,5,17:18.12
-1,5,17:18.12
0,5,17:18.12
1,5,17:18.12
2,5,17:18.12
3,5,17:18.12
4,5,17:18.12
5,5,17:18.12
-3,6,17:18.12
-2,6,17:18.12
-1,6,17:18.12
0,6,17:18.12
1,6,17:18.12
2,6,17:18.12
3,6,17:18.12
4,6,17:18.12
5,6,17:18.12
-2,7,17:18.12
-1,7,17:18.12
0,7,17:18.12
1,7,17:18.4
2,7,17:18.12
3,7,17:18.12
4,7,17:18.12
-1,8,17:18.12
0,8,17:18.12
0,9,17:18.12
-2,-12,18:18.12
-4,-11,18:18.12
-2,-11,18:18.12
-5,-10,18:18.12
-4,-10,18:18.12
-3,-10,18:18.12
-1,-10,18:18.12
-5,-9,18:18.12
-4,-9,18:18.12
-3,-9,18:18.12
-2,-9,18:18.12
-5,-8,18:18.4
-4,-8,18:18.12
-3,-8,18:18.12
-2,-8,18:18.12
-1,-8,18:18.12
0,-8,18:18.12
1,-8,18:18.12
-4,-7,18:18.12
-3,-7,18:18.12
-2,-7,18:17.0
-1,-7,18:17.0
0,-7,18:18.12
1,-7,18:18.12
2,-7,18:18.12
3,-7,18:18.12
-5,-6,18:18.4
-4,-6,18:18.12
-3,-6,18:18.12
-2,-6,18:18.12
-1,-6,18:17.0
0,-6,18:18.12
1,-6,18:18.12
2,-6,18:18.12
3,-6,18:18.12
4,-6,18:18.12
7,-6,18:18.12
8,-6,18:18.12
9,-6,18:18.12
10,-6,18:18.12
11,-6,18:18.12
12,-6,18:18.12
-4,-5,18:18.12
-3,-5,18:18.12
-2,-5,18:18.12
-1,-5,18:17.0
0,-5,18:18.12
1,-5,18:18.12
2,-5,18:18.12
3,-5,18:18.12
4,-5,18:18.12
5,-5,18:18.12
6,-5,18:18.12
7,-5,18:18.12
8,-5,18:18.12
9,-5,18:18.12
10,-5,18:18.12
11,-5,18:18.12
12,-5,18:18.12
-5,-4,18:18.12
-4,-4,18:18.12
-3,-4,18:18.12
-2,-4,18:18.12
-1,-4,18:17.0
0,-4,18:17.0
1,-4,18:18.12
2,-4,18:18.12
3,-4,18:18.12
4,-4,18:18.12
5,-4,18:18.12
6,-4,18:18.12
7,-4,18:18.12
8,-4,18:17.0
9,-4,18:17.0
10,-4,18:18.12
11,-4,18:18.12
12,-4,18:18.12
-6,-3,18:18.12
-5,-3,18:18.12
-4,-3,18:18.12
-3,-3,18:18.12
-2,-3,18:18.12
-1,-3,18:18.12
0,-3,18:18.12
1,-3,18:18.12
2,-3,18:18.12
3,-3,18:18.12
4,-3,18:18.12
5,-3,18:18.12
6,-3,18:18.12
7,-3,18:18.12
8,-3,18:17.0
9,-3,18:18.12
10,-3,18:18.12
11,-3,18:18.12
-7,-2,18:18.12
-6,-2,18:18.12
-5,-2,18:18.12
-4,-2,18:18.12
-3,-2,18:18.12
-2,-2,18:18.12
-1,-2,18:18.12
0,-2,18:18.12
1,-2,18:18.12
2,-2,18:18.12
3,-2,18:18.12
4,-2,18:18.12
5,-2,18:18.12
6,-2,18:18.12
7,-2,18:18.12
8,-2,18:18.12
9,-2,18:18.12
10,-2,18:18.12
11,-2,18:18.4
-7,-1,18:18.12
-6,-1,18:18.12
-5,-1,18:18.12
-4,-1,18:18.12
-3,-1,18:18.12
-2,-1,18:18.12
-1,-1,18:18.12
0,-1,18:18.12
1,-1,18:18.12
2,-1,18:18.12
3,-1,18:18.12
4,-1,18:18.12
5,-1,18:18.12
6,-1,18:18.12
7,-1,18:18.12
8,-1,18:18.12
9,-1,18:18.12
10,-1,18:18.12
-7,0,18:18.12
-6,0,18:18.12
-5,0,18:18.12
-4,0,18:18.12
-3,0,18:18.12
-2,0,18:18.12
-1,0,18:18.12
0,0,18:18.12
1,0,18:18.12
2,0,18:18.12
3,0,18:18.12
4,0,18:18.12
5,0,18:18.12
6,0,18:18.12
7,0,18:18.12
9,0,18:18.12
-8,1,18:18.12
-7,1,18:18.12
-6,1,18:17.0
-5,1,18:17.0
-4,1,18:18.12
-3,1,18:18.12
-2,1,18:18.12
-1,1,18:18.12
0,1,18:18.12
1,1,18:18.12
2,1,18:18.12
3,1,18:18.12
4,1,18:18.12
5,1,18:18.12
6,1,18:18.12
-10,2,18:18.12
-9,2,18:18.12
-8,2,18:18.12
-7,2,18:18.12
-6,2,18:17.0
-5,2,18:18.12
-4,2,18:18.12
-3,2,18:18.12
-2,2,18:18.12
-1,2,18:18.12
0,2,18:18.12
1,2,18:18.12
2,2,18:18.12
3,2,18:18.12
4,2,18:18.12
5,2,18:18.12
6,2,18:18.12
-11,3,18:18.12
-10,3,18:18.12
-9,3,18:18.12
-8,3,18:17.0
-7,3,18:17.0
-6,3,18:17.0
-5,3,18:18.12
-4,3,18:18.12
-3,3,18:18.12
-2,3,18:18.12
-1,3,18:18.12
0,3,18:18.12
1,3,18:18.12
2,3,18:17.0
3,3,18:18.12
4,3,18:18.12
5,3,18:18.12
6,3,18:18.12
-10,4,18:18.12
-9,4,18:18.12
-8,4,18:18.12
-7,4,18:18.12
-6,4,18:18.12
-5,4,18:18.12
-4,4,18:18.12
-3,4,18:18.12
-2,4,18:18.12
-1,4,18:18.12
0,4,18:18.12
1,4,18:18.12
2,4,18:17.0
3,4,18:18.12
4,4,18:18.12
5,4,18:18.12
6,4,18:18.12
7,4,18:18.12
8,4,18:18.12
-11,5,18:18.12
-10,5,18:18.12
-9,5,18:18.12
-8,5,18:18.12
-7,5,18:18.12
-5,5,18:18.12
-4,5,18:18.12
-3,5,18:18.12
-2,5,18:18.12
-1,5,18:18.12
0,5,18:18.12
1,5,18:18.12
2,5,18:17.0
3,5,18:17.0
4,5,18:17.0
5,5,18:18.12
6,5,18:18.12
7,5,18:18.12
8,5,18:18.12
9,5,18:18.4
-11,6,18:18.12
-10,6,18:18.12
-8,6,18:18.12
-3,6,18:18.12
-2,6,18:18.12
-1,6,18:18.12
0,6,18:18.12
1,6,18:18.12
2,6,18:18.12
3,6,18:18.12
4,6,18:18.12
5,6,18:18.12
6,6,18:18.12
7,6,18:18.12
8,6,18:18.12
-3,7,18:18.12
-2,7,18:18.12
-1,7,18:18.12
0,7,18:18.12
1,7,18:18.12
2,7,18:18.12
3,7,18:18.12
4,7,18:18.12
5,7,18:18.12
-1,8,18:18.12
0,8,18:18.12
1,8,18:18.12
2,8,18:18.12
3,8,18:18.12
4,8,18:18.12
5,8,18:18.12
6,8,18:18.12
-1,9,18:18.12
0,9,18:18.12
1,9,18:18.12
3,9,18:18.12
5,9,18:18.12
5,10,18:18.4
-5,-12,19:18.12
-4,-12,19:18.12
-1,-12,19:18.12
-5,-11,19:18.12
-4,-11,19:18.12
-3,-11,19:18.12
-2,-11,19:18.12
-1,-11,19:18.12
0,-11,19:18.12
1,-11,19:18.4
-6,-10,19:18.12
-5,-10,19:18.12
-4,-10,19:18.12
-3,-10,19:18.12
-2,-10,19:18.12
-1,-10,19:18.12
0,-10,19:18.12
1,-10,19:18.12
-7,-9,19:18.12
-6,-9,19:18.12
-5,-9,19:18.12
-4,-9,19:17.0
-3,-9,19:17.0
-2,-9,19:18.12
-1,-9,19:18.12
0,-9,19:18.12
1,-9,19:18.4
3,-9,19:18.12
-5,-8,19:18.12
-4,-8,19:18.12
-3,-8,19:17.0
-2,-8,19:17.0
-1,-8,19:18.12
0,-8,19:18.12
1,-8,19:18.12
2,-8,19:18.12
3,-8,19:18.12
4,-8,19:18.12
-4,-7,19:18.12
-3,-7,19:18.12
-2,-7,19:17.0
-1,-7,19:18.12
0,-7,19:18.12
1,-7,19:18.12
3,-7,19:18.12
4,-7,19:18.12
-3,-6,19:18.12
-2,-6,19:18.12
-1,-6,19:18.12
0,-6,19:18.12
1,-6,19:18.12
2,-6,19:18.12
3,-6,19:18.12
4,-6,19:18.12
5,-6,19:18.12
6,-6,19:18.12
9,-6,19:18.12
10,-6,19:18.12
11,-6,19:18.12
-3,-5,19:18.12
-2,-5,19:18.12
-1,-5,19:18.12
0,-5,19:18.12
1,-5,19:18.12
2,-5,19:18.12
3,-5,19:18.12
4,-5,19:18.12
5,-5,19:18.12
6,-5,19:18.12
7,-5,19:18.12
8,-5,19:18.12
9,-5,19:18.12
10,-5,19:17.0
11,-5,19:18.12
-3,-4,19:18.12
-2,-4,19:18.12
-1,-4,19:18.12
0,-4,19:18.12
1,-4,19:18.12
2,-4,19:18.12
3,-4,19:18.12
4,-4,19:18.12
5,-4,19:18.12
6,-4,19:18.4
7,-4,19:18.12
8,-4,19:18.12
9,-4,19:17.0
10,-4,19:17.0
11,-4,19:18.12
-4,-3,19:18.12
-3,-3,19:18.12
-2,-3,19:18.12
-1,-3,19:18.12
0,-3,19:18.12
1,-3,19:18.12
2,-3,19:18.12
3,-3,19:18.12
4,-3,19:18.12
5,-3,19:18.12
6,-3,19:18.12
7,-3,19:18.12
8,-3,19:18.12
9,-3,19:18.12
10,-3,19:18.12
-5,-2,19:18.4
-4,-2,19:18.12
-3,-2,19:18.12
-2,-2,19:18.12
-1,-2,19:18.12
0,-2,19:18.4
1,-2,19:18.12
2,-2,19:18.12
3,-2,19:18.4
4,-2,19:18.12
5,-2,19:18.12
6,-2,19:18.12
7,-2,19:18.12
8,-2,19:18.12
9,-2,19:18.12
-7,-1,19:18.12
-5,-1,19:18.12
-4,-1,19:18.12
-3,-1,19:18.12
-2,-1,19:18.12
-1,-1,19:18.12
0,-1,19:18.12
1,-1,19:18.12
2,-1,19:18.12
3,-1,19:18.12
4,-1,19:18.12
5,-1,19:18.12
6,-1,19:18.12
7,-1,19:18.12
-7,0,19:18.12
-6,0,19:18.12
-4,0,19:18.12
-3,0,19:18.12
-2,0,19:18.4
-1,0,19:18.12
1,0,19:18.12
2,0,19:18.12
3,0,19:18.12
4,0,19:18.12
5,0,19:18.12
6,0,19:18.12
-7,1,19:18.12
-6,1,19:18.12
-5,1,19:18.12
-4,1,19:18.12
-3,1,19:18.12
-2,1,19:18.12
-1,1,19:18.12
0,1,19:18.12
1,1,19:18.12
2,1,19:18.12
5,1,19:18.12
6,1,19:18.12
-9,2,19:18.12
-8,2,19:18.12
-7,2,19:18.12
-6,2,19:18.12
-5,2,19:18.12
-4,2,19:18.12
-3,2,19:18.12
-2,2,19:18.4
-1,2,19:18.12
0,2,19:18.12
1,2,19:18.12
2,2,19:18.12
3,2,19:18.12
6,2,19:18.4
-9,3,19:18.12
-8,3,19:18.12
-7,3,19:18.12
-6,3,19:18.12
-5,3,19:18.12
-4,3,19:18.12
-1,3,19:18.12
0,3,19:18.12
1,3,19:18.12
2,3,19:18.12
3,3,19:18.12
4,3,19:18.12
-10,4,19:18.12
-9,4,19:18.12
-8,4,19:18.12
-6,4,19:18.12
-5,4,19:18.12
0,4,19:18.12
1,4,19:18.12
2,4,19:18.12
3,4,19:18.12
4,4,19:18.12
5,4,19:18.12
6,4,19:18.4
-10,5,19:18.12
-9,5,19:18.12
-1,5,19:18.12
0,5,19:18.12
1,5,19:18.12
2,5,19:18.12
3,5,19:18.12
4,5,19:17.0
5,5,19:18.12
6,5,19:18.12
7,5,19:18.12
-1,6,19:18.12
0,6,19:18.12
1,6,19:18.12
2,6,19:18.12
3,6,19:18.12
4,6,19:17.0
5,6,19:18.12
6,6,19:18.12
0,7,19:18.12
1,7,19:18.12
2,7,19:18.12
3,7,19:18.12
4,7,19:18.12
5,7,19:18.12
6,7,19:18.12
7,7,19:18.12
3,8,19:18.12
4,8,19:18.12
5,8,19:18.4
3,9,19:18.12
4,9,19:18.12
-6,-11,20:18.12
-5,-11,20:18.12
-4,-11,20:18.4
-2,-11,20:18.12
-7,-10,20:18.4
-6,-10,20:18.12
-5,-10,20:18.12
-4,-10,20:18.12
-3,-10,20:18.12
-2,-10,20:18.12
-1,-10,20:18.12
-5,-9,20:18.12
-4,-9,20:18.12
-3,-9,20:18.12
-2,-9,20:18.12
0,-9,20:18.12
-5,-8,20:18.12
-4,-8,20:18.12
-3,-8,20:18.12
-2,-8,20:18.12
-1,-8,20:18.12
0,-8,20:18.12
3,-8,20:18.4
-2,-7,20:18.12
-1,-7,20:18.4
3,-7,20:18.12
4,-7,20:18.12
1,-6,20:18.12
3,-6,20:18.12
-2,-5,20:18.12
0,-5,20:18.12
2,-5,20:18.12
4,-5,20:18.12
5,-5,20:18.12
10,-5,20:18.12
-2,-4,20:18.12
-1,-4,20:18.12
1,-4,20:18.12
2,-4,20:18.4
8,-4,20:18.12
9,-4,20:18.12
10,-4,20:18.12
-2,-3,20:18.4
7,-3,20:18.12
9,-3,20:18.12
-3,-2,20:18.12
-2,-2,20:18.12
-1,-2,20:18.12
2,-2,20:18.12
4,-2,20:18.12
5,-2,20:18.12
-2,-1,20:18.12
0,-1,20:18.12
1,-1,20:18.12
2,-1,20:18.12
3,-1,20:18.12
5,-1,20:18.12
6,-1,20:18.4
-7,0,20:18.4
-5,0,20:18.12
2,0,20:18.12
3,0,20:18.12
5,0,20:18.12
-7,1,20:18.12
-6,1,20:18.12
-5,1,20:18.12
-3,1,20:18.12
-1,1,20:18.12
0,1,20:18.12
1,1,20:18.4
-7,2,20:18.12
0,2,20:18.12
1,2,20:18.12
2,2,20:18.12
-8,3,20:18.12
1,3,20:18.12
2,3,20:18.12
3,3,20:18.12
-6,4,20:18.4
2,4,20:18.12
3,4,20:18.12
4,4,20:18.12
5,4,20:18.12
1,5,20:18.12
2,5,20:18.12
3,5,20:18.12
4,5,20:18.12
5,5,20:18.12
6,5,20:18.12
3,6,20:18.12
4,6,20:18.12
5,6,20:18.12
6,6,20:18.12
3,7,20:18.12
4,7,20:18.12
5,7,20:18.12
3,8,20:18.12
4,8,20:18.12
-5,-11,21:18.12
-5,-10,21:18.12
-3,-10,21:18.12
-5,-9,21:18.12
-3,-9,21:18.12
-4,-8,21:18.12
-2,-8,21:18.12
9,-4,21:18.12
10,-4,21:18.12
9,-3,21:18.4
-2,-2,21:18.12
2,-2,21:18.12
-2,-1,21:18.12
-7,1,21:18.12
-5,1,21:18.12
2,3,21:18.12
4,5,21:18.12
4,6,21:18.12
-5,-11,22:18.4
-3,-10,22:18.12
8,-3,21:106.8
7,-1,20:106.2
7,-2,20:106.4
10,-3,20:106.4
8,-3,20:106.12
11,-4,20:106.2
-8,-10,20:106.8
-7,-11,20:106.1
-4,-12,20:106.1
-6,-12,20:106.1
3,10,19:106.4
5,9,19:106.4
6,8,19:106.4
-1,7,19:106.4
-9,6,19:106.4
7,4,19:106.2
-8,0,19:106.8
-8,-1,19:106.8
11,-3,19:106.4
-5,-3,19:106.8
-4,-5,19:106.8
8,-6,19:106.1
9,-7,19:106.1
6,-7,19:106.1
5,-7,19:106.1
-8,-9,19:106.8
-7,-10,19:106.8
-6,-11,19:106.8
1,-12,19:106.1
-2,-12,19:106.8
-6,-12,19:106.8
-1,-13,19:106.1
-5,-13,19:106.1
6,10,18:106.2
3,10,18:106.4
1,10,18:106.4
0,10,18:106.4
6,9,18:106.4
4,9,18:106.2
2,9,18:106.4
7,8,18:106.2
-2,8,18:106.4
-3,8,18:106.4
8,7,18:106.4
7,7,18:106.4
6,7,18:106.4
-8,7,18:106.4
-11,7,18:106.4
-4,6,18:106.8
-5,6,18:106.4
-7,6,18:106.4
-9,6,18:106.4
-12,6,18:106.8
10,5,18:106.2
-6,5,18:106.4
9,4,18:106.1
-11,4,18:106.8
8,3,18:106.1
7,3,18:106.2
-12,3,18:106.8
7,2,18:106.2
-8,0,18:106.8
-8,-1,18:106.8
12,-2,18:106.2
12,-3,18:106.4
-7,-3,18:106.8
13,-4,18:106.2
-6,-4,18:106.8
13,-5,18:106.2
-5,-5,18:106.1
-6,-6,18:106.8
11,-7,18:106.1
10,-7,18:106.1
8,-7,18:106.1
4,-7,18:106.1
-5,-7,18:106.8
0,-9,18:106.1
-6,-9,18:106.8
-6,-10,18:106.8
-6,-12,18:106.8
-2,-13,18:106.1
3,10,17:106.4
4,9,17:106.2
-1,9,17:106.4
7,8,17:106.2
4,8,17:106.4
-2,8,17:106.8
6,7,17:106.4
-3,7,17:106.8
-10,6,17:106.4
-6,5,17:106.4
-9,5,17:106.4
-11,5,17:106.8
-11,4,17:106.8
8,3,17:106.1
7,3,17:106.2
-10,2,17:106.8
10,1,17:106.2
-9,1,17:106.1
-8,0,17:106.8
12,-1,17:106.2
-7,-1,17:106.0
12,-2,17:106.2
-6,-2,17:106.1
12,-3,17:106.2
-5,-3,17:106.1
12,-4,17:106.2
-4,-4,17:106.8
12,-5,17:106.2
-4,-5,17:106.8
-5,-5,17:106.1
-4,-6,17:106.8
3,-7,17:106.1
-4,-7,17:106.8
1,-8,17:106.1
-4,-8,17:106.8
-3,-9,17:106.1
-5,-9,17:106.8
-4,-10,17:106.1
-2,6,16:106.8
-3,5,16:106.8
-9,5,16:106.4
-8,2,16:106.8
-8,1,16:106.8
-8,0,16:106.8
-8,-1,16:106.8
-6,-2,16:106.1
-4,-3,16:106.8
-2,-4,16:106.8
12,-5,16:106.2
-3,-5,16:106.8
-4,-6,16:106.8
0,-8,16:106.1
-1,-8,16:106.1
-4,-10,16:106.1
3,6,15:106.4
2,5,15:106.4
1,5,15:106.4
0,5,15:106.4
-1,5,15:106.4
-2,4,15:106.8
-3,4,15:106.4
-4,4,15:106.4
-6,4,15:106.4
-5,3,15:106.8
-5,1,15:106.1
-6,0,15:106.8
-6,-1,15:106.8
-8,-1,15:106.8
-2,-2,15:106.1
-3,-2,15:106.1
-4,-2,15:106.1
-5,-2,15:106.1
4,-3,15:106.1
-1,-3,15:106.1
4,-4,15:106.2
-1,-4,15:106.8
2,-5,15:106.1
2,-6,15:106.2
-2,-6,15:106.8
0,-8,15:106.1
0,5,14:106.4
-1,4,14:106.4
-6,4,14:106.4
-2,3,14:106.8
-5,3,14:106.8
-3,2,14:106.8
-4,0,14:106.8
-3,-1,14:106.1
0,-3,14:106.1
-1,-3,14:106.1
-1,-4,14:106.8
-1,-5,14:106.8
2,-6,14:106.2
-1,-6,14:106.8
1,-7,14:106.1
0,-7,14:106.1
-1,4,13:106.4
-2,3,13:106.4
-3,2,13:106.8
-3,1,13:106.8
-2,-1,13:106.1
-1,-2,13:106.1
-1,-3,13:106.1
-1,-5,13:106.8
0,-7,13:106.1
-3,1,12:106.8
-1,-1,12:106.1
-2,-1,12:106.1
0,-2,12:106.1
-1,-5,12:106.8
-1,4,11:106.4
-3,3,11:106.4
-3,1,11:106.8
-2,-1,11:106.1
-1,5,10:106.4
-2,5,10:106.4
-3,4,10:106.4
-4,4,10:106.4
-2,-1,10:106.1
-2,6,9:106.4
-3,4,9:106.4
-4,4,9:106.4
-2,-1,9:106.1
-2,6,8:106.4
-3,5,8:106.4
-4,5,8:106.4
-5,4,8:106.8
-1,1,8:106.1
-2,1,8:106.1
-2,6,7:106.4
-4,5,7:106.4
-5,4,7:106.8
0,3,7:106.2
0,2,7:106.2
-5,2,7:106.8
-3,1,7:106.1
-2,6,6:106.4
-4,5,6:106.4
0,4,6:106.2
0,3,6:106.2
-4,3,6:106.8
-5,2,6:106.8
-2,1,6:106.1
-3,1,6:106.1
-4,1,6:106.1
-1,6,5:106.4
0,5,5:106.2
-5,5,5:106.8
0,4,5:106.2
-5,4,5:106.8
-4,3,5:106.8
-2,2,5:106.1
-5,2,5:106.8
-3,1,5:106.1
-1,6,4:106.4
0,5,4:106.2
-4,5,4:106.8
0,4,4:106.2
-4,3,4:106.8
-3,1,4:106.1
-3,7,3:106.4
-1,6,3:106.4
0,5,3:106.2
-2,5,3:106.2
-4,5,3:106.8
1,4,3:106.2
-5,4,3:106.8
0,3,3:106.2
-5,3,3:106.8
-1,2,3:106.1
-3,1,3:106.1
-3,8,2:106.4
-4,7,2:106.8
-2,6,2:106.2
-4,6,2:106.8
1,5,2:106.4
0,5,2:106.6
-1,5,2:106.4
-2,5,2:106.2
-5,5,2:106.8
2,4,2:106.2
-5,4,2:106.8
0,3,2:106.2
-5,3,2:106.8
-5,2,2:106.8
-3,1,2:106.1
-5,0,2:106.1
-3,8,1:106.4
-2,7,1:106.2
-4,7,1:106.8
1,6,1:106.4
-2,6,1:106.2
-4,6,1:106.8
2,5,1:106.2
0,5,1:106.4
-1,5,1:106.4
-2,5,1:106.2
-5,5,1:106.8
2,4,1:106.2
-4,4,1:106.8
-5,4,1:106.8
1,3,1:106.2
-5,3,1:106.8
0,2,1:106.1
-3,1,1:106.1
-6,1,1:106.8
-2,7,0:106.2
1,6,0:106.4
0,6,0:106.4
-5,6,0:106.8
2,5,0:106.2
-1,5,0:106.4
2,4,0:106.2
-4,4,0:106.8
1,3,0:106.2
-6,3,0:106.8
