[META]
version=2.0
spawnOnBlockType=2
spawnSunlight=True
spawnDarkness=True
spawnWater=False
spawnLava=False
underFill=False
randomRotation=True
dig=True
tree=False
branch=False
needsFoundation=True
rarity=10
collisionPercentage=40
spawnElevationMin=0
spawnElevationMax=100
spawnInBiome=All
[DATA]
0,-2,-3:3.0
1,-2,-3:3.0
-2,-1,-3:3.0
-1,-1,-3:3.0
0,-1,-3:1.0
1,-1,-3:3.0
-2,0,-3:3.0
-1,0,-3:1.0
0,0,-3:1.0
-2,1,-3:3.0
-1,1,-3:3.0
0,1,-3:3.0
1,-3,-2:3.0
-3,-2,-2:3.0
-2,-2,-2:3.0
-1,-2,-2:3.0
0,-2,-2:3.0
1,-2,-2:3.0
2,-2,-2:3.0
-3,-1,-2:3.0
-2,-1,-2:3.0
-1,-1,-2:3.0
0,-1,-2:3.0
1,-1,-2:1.0
2,-1,-2:3.0
-3,0,-2:3.0
-2,0,-2:3.0
-1,0,-2:3.0
0,0,-2:3.0
1,0,-2:3.0
-3,1,-2:3.0
-2,1,-2:3.0
-1,1,-2:3.0
0,1,-2:3.0
1,1,-2:3.0
-3,2,-2:3.0
-2,2,-2:3.0
-1,2,-2:3.0
0,2,-2:3.0
1,2,-2:3.0
1,-4,-1:2.5
-3,-3,-1:2.0
-2,-3,-1:2.0
-1,-3,-1:2.0
0,-3,-1:2.0
1,-3,-1:2.0
2,-3,-1:2.5
-4,-2,-1:2.0
-3,-2,-1:17.0
-2,-2,-1:2.0
-1,-2,-1:2.0
0,-2,-1:2.0
1,-2,-1:17.0
2,-2,-1:2.0
3,-2,-1:2.5
-4,-1,-1:2.0
-3,-1,-1:2.0
-2,-1,-1:2.0
-1,-1,-1:2.0
0,-1,-1:2.0
1,-1,-1:2.0
2,-1,-1:2.0
3,-1,-1:2.5
-4,0,-1:2.0
-3,0,-1:3.0
-2,0,-1:2.0
-1,0,-1:2.0
0,0,-1:2.0
1,0,-1:2.0
2,0,-1:2.0
-4,1,-1:2.0
-3,1,-1:2.0
-2,1,-1:2.0
-1,1,-1:2.0
0,1,-1:2.0
1,1,-1:2.0
2,1,-1:2.0
-4,2,-1:2.0
-3,2,-1:17.0
-2,2,-1:2.0
-1,2,-1:2.0
0,2,-1:2.0
1,2,-1:17.0
2,2,-1:2.0
-3,3,-1:2.0
-2,3,-1:2.0
-1,3,-1:2.0
0,3,-1:2.0
1,3,-1:2.0
1,-4,0:18.12
0,-3,0:18.4
1,-3,0:18.12
2,-3,0:18.12
-3,-2,0:17.0
0,-2,0:18.12
1,-2,0:17.0
2,-2,0:18.12
3,-2,0:18.12
1,-1,0:18.12
-3,0,0:17.0
-3,2,0:17.0
1,2,0:17.0
1,-3,1:18.12
-3,-2,1:17.0
1,-2,1:17.0
2,-2,1:18.12
-3,0,1:17.0
-3,2,1:17.0
1,2,1:17.0
1,-3,2:18.4
-3,-2,2:17.0
1,-2,2:17.0
-3,0,2:17.0
-3,2,2:17.0
1,2,2:17.0
-3,-2,3:17.0
-2,-2,3:43.2
-1,-2,3:43.2
0,-2,3:43.2
1,-2,3:17.0
-3,-1,3:43.2
-2,-1,3:44.2
-1,-1,3:44.2
0,-1,3:58.0
1,-1,3:43.2
-3,0,3:17.0
-1,0,3:44.2
0,0,3:44.2
1,0,3:43.2
-3,1,3:43.2
-2,1,3:44.2
-1,1,3:44.2
0,1,3:44.2
1,1,3:43.2
-3,2,3:17.0
-2,2,3:43.2
-1,2,3:43.2
0,2,3:43.2
1,2,3:17.0
-2,3,3:18.12
-1,3,3:18.12
0,3,3:18.12
-3,-2,4:17.0
1,-2,4:17.0
-3,0,4:17.0
-4,2,4:18.12
-3,2,4:17.0
1,2,4:17.0
2,2,4:18.4
-3,3,4:18.12
-2,3,4:18.12
-1,3,4:18.12
0,3,4:18.12
1,3,4:18.12
-3,-3,5:18.12
1,-3,5:18.12
-4,-2,5:18.12
-3,-2,5:17.0
1,-2,5:17.0
-3,0,5:17.0
1,0,5:18.12
2,1,5:18.12
-4,2,5:18.12
-3,2,5:17.0
-1,2,5:18.12
1,2,5:17.0
2,2,5:18.12
-4,3,5:18.12
-3,3,5:18.12
-2,3,5:18.12
0,3,5:18.12
1,3,5:18.12
2,3,5:18.12
1,4,5:18.12
-4,-3,6:18.12
-3,-3,6:18.12
-2,-3,6:18.12
0,-3,6:18.12
1,-3,6:18.12
-4,-2,6:18.12
-3,-2,6:17.0
-2,-2,6:5.0
-1,-2,6:5.0
0,-2,6:5.0
1,-2,6:17.0
2,-2,6:18.12
-3,-1,6:5.0
0,-1,6:5.0
1,-1,6:18.12
-3,0,6:5.0
0,0,6:5.0
1,0,6:18.12
-4,1,6:18.12
-3,1,6:5.0
-2,1,6:5.0
-1,1,6:5.0
0,1,6:5.0
1,1,6:18.12
2,1,6:18.12
-4,2,6:18.12
-3,2,6:17.0
-2,2,6:18.12
0,2,6:18.12
1,2,6:17.0
2,2,6:18.12
-3,3,6:18.12
0,3,6:18.12
1,3,6:18.12
2,3,6:18.12
1,4,6:18.12
-3,-3,7:18.4
0,-3,7:18.4
1,-3,7:18.12
-4,-2,7:18.12
-3,-2,7:18.12
-2,-2,7:18.12
0,-2,7:18.12
1,-2,7:17.0
2,-2,7:18.12
-2,-1,7:5.0
-1,-1,7:5.0
0,-1,7:18.4
1,-1,7:18.12
2,-1,7:18.12
-2,0,7:5.0
-1,0,7:5.0
-3,1,7:18.12
1,1,7:18.12
-4,2,7:18.12
-3,2,7:17.0
-2,2,7:18.12
0,2,7:18.12
1,2,7:18.12
2,2,7:18.12
-3,3,7:18.12
1,3,7:18.12
2,3,7:18.12
1,-3,8:18.12
-3,-2,8:18.12
0,-2,8:18.12
1,-2,8:18.12
2,-2,8:18.12
1,-1,8:18.12
2,-1,8:18.4
-3,1,8:18.12
-4,2,8:18.12
-3,2,8:18.12
-2,2,8:18.12
1,2,8:18.12
-3,3,8:18.12
1,3,8:18.12
1,-2,9:18.12
-3,2,9:18.12
1,4,8:106.4
-4,3,8:106.4
-5,2,8:106.8
3,-1,8:106.2
3,-2,8:106.2
1,-4,8:106.1
2,4,7:106.4
1,4,7:106.4
-3,4,7:106.4
3,3,7:106.2
0,3,7:106.4
-4,3,7:106.4
3,2,7:106.2
-5,2,7:106.8
3,-1,7:106.2
3,-2,7:106.2
-5,-2,7:106.8
-2,-3,7:106.2
1,-4,7:106.1
0,-4,7:106.1
-3,-4,7:106.1
1,5,6:106.4
2,4,6:106.4
0,4,6:106.4
-3,4,6:106.4
3,3,6:106.2
-4,3,6:106.4
3,2,6:106.2
-1,2,6:106.8
-5,2,6:106.8
3,1,6:106.2
-5,1,6:106.8
-4,0,6:106.8
3,-1,6:106.2
-4,-1,6:106.8
3,-2,6:106.2
-5,-2,6:106.8
-1,-3,6:106.1
-5,-3,6:106.8
1,-4,6:106.1
0,-4,6:106.1
-2,-4,6:106.1
-3,-4,6:106.1
-4,-4,6:106.1
1,5,5:106.4
2,4,5:106.4
0,4,5:106.4
-3,4,5:106.4
3,3,5:106.2
-1,3,5:106.4
-5,3,5:106.8
3,2,5:106.2
0,2,5:85.0
-2,2,5:85.0
-5,2,5:106.8
3,1,5:106.2
1,1,5:85.0
-3,1,5:85.0
-5,1,5:106.8
-4,0,5:106.8
3,-1,5:106.2
1,-1,5:85.0
-3,-1,5:85.0
-4,-1,5:106.8
3,-2,5:106.2
0,-2,5:85.0
-2,-2,5:85.0
-5,-2,5:106.8
-1,-3,5:106.1
-5,-3,5:106.8
1,-4,5:106.1
0,-4,5:106.1
-2,-4,5:106.1
-3,-4,5:106.1
-4,-4,5:106.1
1,5,4:106.4
2,4,4:106.4
0,4,4:106.4
-1,4,4:106.4
-2,4,4:106.4
-3,4,4:106.4
3,3,4:106.2
-5,3,4:106.8
3,2,4:106.2
0,2,4:85.0
-1,2,4:85.0
-2,2,4:85.0
-5,2,4:106.8
3,1,4:106.2
1,1,4:85.0
-3,1,4:85.0
-5,1,4:106.8
1,0,4:85.0
-2,0,4:65.5
-4,0,4:106.8
3,-1,4:106.2
1,-1,4:85.0
-3,-1,4:85.0
-4,-1,4:106.8
3,-2,4:106.2
0,-2,4:85.0
-1,-2,4:85.0
-2,-2,4:85.0
-4,-2,4:106.8
-5,-2,4:106.8
-1,-3,4:106.1
-3,-3,4:106.1
-5,-3,4:106.8
1,-4,4:106.1
0,-4,4:106.1
-2,-4,4:106.1
-3,-4,4:106.1
-4,-4,4:106.1
1,5,3:106.4
2,4,3:106.4
0,4,3:106.4
-1,4,3:106.4
-2,4,3:106.4
-3,4,3:106.4
3,3,3:106.2
1,3,3:106.4
-3,3,3:106.4
-5,3,3:106.8
3,2,3:106.2
2,2,3:106.2
-4,2,3:106.8
-5,2,3:106.8
3,1,3:106.2
2,1,3:106.2
-4,1,3:106.8
-5,1,3:106.8
2,0,3:106.2
-2,0,3:65.5
-4,0,3:106.8
3,-1,3:106.2
2,-1,3:106.2
-4,-1,3:106.8
3,-2,3:106.2
-4,-2,3:106.8
-5,-2,3:106.8
0,-3,3:106.1
-1,-3,3:106.1
-2,-3,3:106.1
-3,-3,3:106.1
-5,-3,3:106.8
1,-4,3:106.1
0,-4,3:106.1
-2,-4,3:106.1
-3,-4,3:106.1
-4,-4,3:106.1
1,5,2:106.4
2,4,2:106.4
0,4,2:106.4
-1,4,2:106.4
-2,4,2:106.4
-3,4,2:106.4
3,3,2:106.2
1,3,2:106.4
-3,3,2:106.4
-5,3,2:106.8
3,2,2:106.2
2,2,2:106.2
-4,2,2:106.8
-5,2,2:106.8
3,1,2:106.2
2,1,2:106.2
1,1,2:106.1
-4,1,2:106.8
-5,1,2:106.8
2,0,2:106.2
-2,0,2:65.5
-4,0,2:106.8
3,-1,2:106.2
2,-1,2:106.2
-4,-1,2:106.8
3,-2,2:106.2
-4,-2,2:106.8
-5,-2,2:106.8
0,-3,2:106.1
-1,-3,2:106.1
-2,-3,2:106.1
-3,-3,2:106.1
-5,-3,2:106.8
1,-4,2:106.1
0,-4,2:106.1
-2,-4,2:106.1
-3,-4,2:106.1
1,5,1:106.4
2,4,1:106.4
0,4,1:106.4
-1,4,1:106.4
-2,4,1:106.4
-3,4,1:106.4
3,3,1:106.2
1,3,1:106.4
-3,3,1:106.4
-5,3,1:106.8
3,2,1:106.2
2,2,1:106.2
-4,2,1:106.8
-5,2,1:106.8
3,1,1:106.2
2,1,1:106.2
1,1,1:106.1
-4,1,1:106.8
-5,1,1:106.8
2,0,1:106.2
-2,0,1:65.5
-4,0,1:106.8
3,-1,1:106.2
2,-1,1:106.2
-4,-1,1:106.8
3,-2,1:106.2
-4,-2,1:106.8
-5,-2,1:106.8
0,-3,1:106.1
-1,-3,1:106.1
-2,-3,1:106.1
-3,-3,1:106.1
-5,-3,1:106.8
1,-4,1:106.1
0,-4,1:106.1
-2,-4,1:106.1
-3,-4,1:106.1
1,5,0:106.4
2,4,0:106.4
0,4,0:106.4
-1,4,0:106.4
-2,4,0:106.4
-3,4,0:106.4
3,3,0:106.2
1,3,0:106.4
0,3,0:31.1
-1,3,0:31.1
-2,3,0:31.1
-3,3,0:106.4
-5,3,0:106.8
3,2,0:106.2
2,2,0:106.2
0,2,0:31.1
-1,2,0:31.1
-2,2,0:31.1
-4,2,0:106.8
-5,2,0:106.8
3,1,0:106.2
2,1,0:31.1
1,1,0:106.1
0,1,0:31.1
-1,1,0:31.1
-2,1,0:37.0
-3,1,0:31.1
-4,1,0:106.8
-5,1,0:106.8
2,0,0:31.1
1,0,0:31.1
0,0,0:38.0
-2,0,0:31.1
-4,0,0:106.8
3,-1,0:31.1
2,-1,0:31.1
0,-1,0:31.1
-1,-1,0:31.1
-4,-1,0:106.8
-4,-2,0:106.8
-5,-2,0:106.8
-1,-3,0:106.1
-2,-3,0:106.1
-3,-3,0:106.1
-5,-3,0:106.8
0,-4,0:106.1
-2,-4,0:106.1
-3,-4,0:106.1
1,5,-2:106.0
1,4,-2:106.0
0,4,-2:106.0
2,3,-2:106.0
1,3,-2:106.0
