[META]
version=2.0
spawnOnBlockType=2
spawnSunlight=True
spawnDarkness=True
spawnWater=False
spawnLava=False
underFill=False
randomRotation=True
dig=False
tree=False
branch=False
needsFoundation=True
rarity=5
collisionPercentage=10
spawnElevationMin=0
spawnElevationMax=100
spawnInBiome=All
[DATA]
-4,0,-5:1.5
-4,2,-5:1.5
-4,7,-5:1.5
-3,8,-5:1.5
-3,-1,-4:3.0
-5,0,-4:1.5
-4,0,-4:1.5
-3,0,-4:1.5
-2,0,-4:3.0
-4,1,-4:1.5
-3,1,-4:1.5
-4,2,-4:1.5
-3,2,-4:3.0
-4,3,-4:1.5
-4,4,-4:1.5
-4,5,-4:1.5
-4,6,-4:1.5
-3,6,-4:3.0
-4,7,-4:1.5
-3,7,-4:1.5
-4,8,-4:1.5
-3,8,-4:1.5
-5,-1,-3:3.0
-4,-1,-3:3.0
-3,-1,-3:1.0
-2,-1,-3:3.0
-1,-1,-3:3.0
-5,0,-3:3.0
-4,0,-3:1.0
-3,0,-3:1.0
-2,0,-3:3.0
-1,0,-3:3.0
-5,1,-3:3.0
-4,1,-3:3.0
-3,1,-3:3.0
-2,1,-3:3.0
-5,2,-3:3.0
-4,2,-3:3.0
-3,2,-3:3.0
-2,2,-3:3.0
-4,3,-3:3.0
-3,3,-3:3.0
-4,4,-3:3.0
-3,4,-3:3.0
-5,5,-3:3.0
-4,5,-3:3.0
-3,5,-3:3.0
-4,6,-3:3.0
-3,6,-3:3.0
-2,6,-3:3.0
-5,7,-3:3.0
-4,7,-3:3.0
-3,7,-3:1.0
-2,7,-3:3.0
-5,8,-3:3.0
-4,8,-3:1.0
-3,8,-3:1.0
-2,8,-3:3.0
-5,9,-3:3.0
-4,9,-3:3.0
-3,9,-3:3.0
-6,-2,-2:3.0
-5,-2,-2:3.0
-4,-2,-2:3.0
-3,-2,-2:3.0
-2,-2,-2:3.0
-1,-2,-2:3.0
-6,-1,-2:3.0
-5,-1,-2:3.0
-4,-1,-2:3.0
-3,-1,-2:3.0
-2,-1,-2:1.0
-1,-1,-2:3.0
0,-1,-2:3.0
-6,0,-2:3.0
-5,0,-2:3.0
-4,0,-2:3.0
-3,0,-2:3.0
-2,0,-2:3.0
-1,0,-2:3.0
0,0,-2:3.0
-6,1,-2:3.0
-5,1,-2:3.0
-4,1,-2:3.0
-3,1,-2:3.0
-2,1,-2:3.0
-1,1,-2:3.0
-6,2,-2:3.0
-5,2,-2:3.0
-4,2,-2:3.0
-3,2,-2:3.0
-2,2,-2:3.0
-1,2,-2:3.0
0,2,-2:3.0
-6,3,-2:3.0
-5,3,-2:3.0
-4,3,-2:3.0
-3,3,-2:3.0
-2,3,-2:3.0
-1,3,-2:3.0
-6,4,-2:3.0
-5,4,-2:3.0
-4,4,-2:3.0
-3,4,-2:3.0
-2,4,-2:3.0
-6,5,-2:3.0
-5,5,-2:3.0
-4,5,-2:3.0
-3,5,-2:3.0
-2,5,-2:3.0
-6,6,-2:3.0
-5,6,-2:3.0
-4,6,-2:3.0
-3,6,-2:3.0
-2,6,-2:3.0
-1,6,-2:3.0
-6,7,-2:3.0
-5,7,-2:3.0
-4,7,-2:3.0
-3,7,-2:3.0
-2,7,-2:1.0
-1,7,-2:3.0
-6,8,-2:3.0
-5,8,-2:3.0
-4,8,-2:3.0
-3,8,-2:3.0
-2,8,-2:3.0
-1,8,-2:3.0
-6,9,-2:3.0
-5,9,-2:3.0
-4,9,-2:3.0
-3,9,-2:3.0
-2,9,-2:3.0
-1,9,-2:3.0
-6,10,-2:3.0
-5,10,-2:3.0
-4,10,-2:3.0
-3,10,-2:3.0
-2,10,-2:3.0
-6,-3,-1:2.0
-5,-3,-1:2.0
-4,-3,-1:2.0
-3,-3,-1:2.0
-2,-3,-1:2.0
-7,-2,-1:2.0
-6,-2,-1:17.0
-5,-2,-1:2.0
-4,-2,-1:2.0
-3,-2,-1:2.0
-2,-2,-1:17.0
-1,-2,-1:2.0
0,-2,-1:2.5
1,-2,-1:2.5
-7,-1,-1:2.0
-6,-1,-1:2.0
-5,-1,-1:2.0
-4,-1,-1:2.0
-3,-1,-1:2.0
-2,-1,-1:2.0
-1,-1,-1:2.0
0,-1,-1:2.5
1,-1,-1:2.5
-7,0,-1:2.0
-6,0,-1:3.0
-5,0,-1:2.0
-4,0,-1:2.0
-3,0,-1:2.0
-2,0,-1:2.0
-1,0,-1:2.0
0,0,-1:2.5
1,0,-1:2.5
-7,1,-1:2.0
-6,1,-1:2.0
-5,1,-1:2.0
-4,1,-1:2.0
-3,1,-1:2.0
-2,1,-1:2.0
-1,1,-1:2.0
0,1,-1:2.5
-7,2,-1:2.0
-6,2,-1:17.0
-5,2,-1:2.0
-4,2,-1:2.0
-3,2,-1:2.0
-2,2,-1:17.0
-1,2,-1:2.0
0,2,-1:2.5
1,2,-1:2.5
-6,3,-1:2.0
-5,3,-1:2.0
-4,3,-1:2.0
-3,3,-1:2.0
-2,3,-1:2.0
-1,3,-1:2.5
0,3,-1:2.5
-6,4,-1:2.5
-5,4,-1:2.5
-4,4,-1:2.5
-3,4,-1:2.5
-2,4,-1:2.5
-1,4,-1:2.5
-7,5,-1:2.5
-6,5,-1:2.5
-5,5,-1:2.5
-4,5,-1:2.5
-3,5,-1:2.5
-2,5,-1:2.5
-1,5,-1:2.5
-7,6,-1:2.0
-6,6,-1:17.0
-5,6,-1:3.0
-4,6,-1:2.0
-3,6,-1:2.0
-2,6,-1:17.0
-1,6,-1:2.0
0,6,-1:2.5
-7,7,-1:2.0
-6,7,-1:2.0
-5,7,-1:2.0
-4,7,-1:2.0
-3,7,-1:2.0
-2,7,-1:2.0
-1,7,-1:2.0
0,7,-1:2.5
-7,8,-1:2.0
-6,8,-1:3.0
-5,8,-1:2.0
-4,8,-1:2.0
-3,8,-1:2.0
-2,8,-1:2.0
-1,8,-1:2.0
0,8,-1:2.5
-7,9,-1:2.0
-6,9,-1:2.0
-5,9,-1:2.0
-4,9,-1:2.0
-3,9,-1:2.0
-2,9,-1:2.0
-1,9,-1:2.0
0,9,-1:2.5
-7,10,-1:2.0
-6,10,-1:17.0
-5,10,-1:2.0
-4,10,-1:2.0
-3,10,-1:2.0
-2,10,-1:17.0
-1,10,-1:2.0
-6,11,-1:2.0
-5,11,-1:2.0
-4,11,-1:2.0
-3,11,-1:2.0
-2,11,-1:2.0
-6,-2,0:17.0
-2,-2,0:17.0
-6,0,0:17.0
-2,0,0:18.12
-3,1,0:18.12
-2,1,0:18.12
-1,1,0:18.12
-6,2,0:17.0
-4,2,0:18.12
-3,2,0:18.12
-2,2,0:17.0
-1,2,0:18.12
0,2,0:18.12
-3,3,0:18.4
-2,3,0:18.12
-1,3,0:18.12
-2,4,0:18.12
-6,6,0:17.0
-5,6,0:61.5
-2,6,0:17.0
-6,8,0:17.0
-6,10,0:17.0
-2,10,0:17.0
-6,-2,1:17.0
-2,-2,1:17.0
-6,0,1:17.0
-2,1,1:18.12
-6,2,1:17.0
-3,2,1:18.12
-2,2,1:17.0
-1,2,1:18.12
-2,3,1:18.12
-6,6,1:17.0
-2,6,1:17.0
-6,8,1:17.0
-6,10,1:17.0
-2,10,1:17.0
-6,-2,2:17.0
-2,-2,2:17.0
-6,0,2:17.0
-6,2,2:17.0
-2,2,2:17.0
-6,6,2:17.0
-2,6,2:17.0
-6,8,2:17.0
-6,10,2:17.0
-2,10,2:17.0
-6,-2,3:17.0
-5,-2,3:43.2
-4,-2,3:43.2
-3,-2,3:43.2
-2,-2,3:17.0
-1,-2,3:43.2
0,-2,3:43.2
-6,-1,3:43.2
-5,-1,3:44.2
-4,-1,3:44.2
-3,-1,3:44.2
-2,-1,3:44.2
-1,-1,3:44.2
0,-1,3:44.2
-6,0,3:17.0
-4,0,3:44.2
-3,0,3:44.2
-2,0,3:44.2
-1,0,3:44.2
0,0,3:44.2
-6,1,3:43.2
-5,1,3:44.2
-4,1,3:44.2
-3,1,3:44.2
-2,1,3:58.0
-1,1,3:44.2
0,1,3:44.2
-6,2,3:17.0
-5,2,3:43.2
-4,2,3:43.2
-3,2,3:43.2
-2,2,3:17.0
-1,2,3:43.2
0,2,3:43.2
-6,6,3:17.0
-5,6,3:43.2
-4,6,3:43.2
-3,6,3:43.2
-2,6,3:17.0
-6,7,3:43.2
-5,7,3:44.2
-4,7,3:44.2
-3,7,3:44.2
-2,7,3:43.2
-6,8,3:17.0
-4,8,3:44.2
-3,8,3:44.2
-2,8,3:43.2
-6,9,3:43.2
-5,9,3:44.2
-4,9,3:44.2
-3,9,3:44.2
-2,9,3:43.2
-6,10,3:17.0
-5,10,3:43.2
-4,10,3:43.2
-3,10,3:43.2
-2,10,3:17.0
-6,-2,4:17.0
-2,-2,4:17.0
-6,0,4:17.0
-6,2,4:17.0
-2,2,4:17.0
-2,5,4:18.12
-6,6,4:17.0
-4,6,4:18.12
-3,6,4:18.12
-2,6,4:17.0
-1,6,4:18.12
-6,8,4:17.0
-6,10,4:17.0
-2,10,4:17.0
-6,-3,5:18.12
-2,-3,5:18.12
-6,-2,5:17.0
-2,-2,5:17.0
-6,0,5:17.0
-6,2,5:17.0
-2,2,5:17.0
-2,3,5:18.12
-2,5,5:18.12
-6,6,5:17.0
-4,6,5:18.12
-3,6,5:18.12
-2,6,5:17.0
-1,6,5:18.12
-6,8,5:17.0
-6,10,5:17.0
-2,10,5:17.0
-6,11,5:18.12
-6,-3,6:18.12
-5,-3,6:18.12
-2,-3,6:18.12
-6,-2,6:17.0
-5,-2,6:5.0
-4,-2,6:5.0
-3,-2,6:5.0
-2,-2,6:17.0
-1,-2,6:18.12
-6,-1,6:5.0
-5,-1,6:5.0
-4,-1,6:5.0
-3,-1,6:5.0
-2,-1,6:5.0
-1,-1,6:18.12
-6,0,6:17.0
-4,0,6:5.0
-3,0,6:5.0
-2,0,6:5.0
-6,1,6:5.0
-5,1,6:5.0
-4,1,6:5.0
-3,1,6:5.0
-2,1,6:5.0
-6,2,6:17.0
-5,2,6:5.0
-4,2,6:5.0
-3,2,6:5.0
-2,2,6:17.0
-1,2,6:18.12
-4,3,6:44.2
-2,3,6:18.12
-1,3,6:18.12
-4,4,6:44.2
-2,4,6:18.4
-4,5,6:44.2
-2,5,6:18.12
-1,5,6:18.12
-6,6,6:17.0
-5,6,6:5.0
-4,6,6:5.0
-3,6,6:5.0
-2,6,6:17.0
-1,6,6:18.12
0,6,6:18.12
-6,7,6:5.0
-5,7,6:5.0
-4,7,6:5.0
-3,7,6:5.0
-2,7,6:5.0
-1,7,6:18.12
-6,8,6:17.0
-4,8,6:5.0
-3,8,6:5.0
-2,8,6:5.0
-6,9,6:5.0
-5,9,6:5.0
-4,9,6:5.0
-3,9,6:5.0
-2,9,6:5.0
-6,10,6:17.0
-5,10,6:5.0
-4,10,6:5.0
-3,10,6:5.0
-2,10,6:17.0
-6,11,6:18.12
-5,11,6:18.4
-6,-3,7:18.12
-5,-3,7:18.12
-4,-3,7:18.12
-2,-3,7:18.12
-1,-3,7:18.12
-6,-2,7:17.0
-5,-2,7:18.12
-2,-2,7:17.0
-1,-2,7:18.12
-3,-1,7:54.3
-1,-1,7:18.12
-6,0,7:17.0
-1,1,7:18.4
-7,2,7:18.12
-6,2,7:17.0
-2,2,7:17.0
-1,2,7:18.12
0,2,7:18.12
-6,3,7:18.12
-2,3,7:18.12
-1,3,7:18.12
0,3,7:18.12
-2,4,7:18.12
-1,4,7:18.12
-2,5,7:18.12
-1,5,7:18.12
0,5,7:18.4
-6,6,7:17.0
-2,6,7:17.0
-1,6,7:18.12
0,6,7:18.12
-1,7,7:18.12
0,7,7:18.12
-6,8,7:17.0
-1,8,7:18.12
-3,9,7:58.0
-7,10,7:18.12
-6,10,7:17.0
-2,10,7:17.0
-6,11,7:18.12
-5,11,7:18.12
-6,-4,8:18.12
-7,-3,8:18.12
-6,-3,8:18.12
-5,-3,8:18.12
-4,-3,8:18.12
-2,-3,8:18.12
-1,-3,8:18.12
-7,-2,8:18.4
-6,-2,8:17.0
-5,-2,8:18.12
-2,-2,8:18.12
-1,-2,8:18.12
-7,-1,8:18.12
-1,-1,8:18.12
-7,2,8:18.12
-6,2,8:17.0
-2,2,8:17.0
-1,2,8:18.12
-7,3,8:18.12
-2,3,8:18.12
-1,3,8:18.12
-2,4,8:18.4
-2,5,8:18.12
-1,5,8:18.12
0,5,8:18.12
-6,6,8:17.0
-2,6,8:18.12
-1,6,8:18.12
0,6,8:18.12
-1,7,8:18.12
0,7,8:18.12
-1,8,8:18.12
-7,10,8:18.12
-6,10,8:17.0
-2,10,8:17.0
-7,11,8:18.12
-6,11,8:18.12
-5,11,8:18.12
-6,12,8:18.12
-6,-4,9:18.12
-5,-4,9:18.4
-7,-3,9:18.12
-6,-3,9:18.12
-5,-3,9:18.12
-4,-3,9:18.12
-8,-2,9:18.12
-7,-2,9:18.12
-6,-2,9:17.0
-5,-2,9:43.2
-4,-2,9:43.2
-3,-2,9:43.2
-2,-2,9:44.2
-1,-2,9:18.12
-7,-1,9:18.12
-6,-1,9:43.2
-5,-1,9:43.2
-4,-1,9:43.2
-3,-1,9:43.2
-2,-1,9:43.2
-6,0,9:43.2
-5,0,9:43.2
-3,0,9:43.2
-2,0,9:43.2
-6,1,9:43.2
-5,1,9:43.2
-4,1,9:43.2
-3,1,9:43.2
-2,1,9:43.2
-8,2,9:18.12
-7,2,9:18.12
-6,2,9:17.0
-5,2,9:5.0
-4,2,9:43.2
-3,2,9:43.2
-2,2,9:44.2
-7,3,9:18.12
-6,3,9:18.12
-5,3,9:44.2
-4,3,9:44.2
-3,3,9:44.2
-2,3,9:18.12
-5,4,9:44.2
-4,4,9:44.2
-3,4,9:44.2
-5,5,9:44.2
-4,5,9:44.2
-3,5,9:44.2
-2,5,9:18.12
-1,5,9:18.12
-6,6,9:44.2
-5,6,9:43.2
-4,6,9:43.2
-3,6,9:43.2
-2,6,9:18.12
-1,6,9:18.12
0,6,9:18.12
-6,7,9:43.2
-2,7,9:5.0
-1,7,9:18.12
-6,8,9:43.2
-2,8,9:43.2
-1,8,9:18.12
-6,9,9:43.2
-2,9,9:43.2
-8,10,9:18.12
-7,10,9:18.12
-6,10,9:17.0
-5,10,9:5.0
-4,10,9:43.2
-3,10,9:43.2
-2,10,9:44.2
-7,11,9:18.12
-6,11,9:18.12
-5,11,9:18.12
-6,12,9:18.12
-6,-4,10:18.12
-7,-3,10:18.12
-6,-3,10:18.12
-5,-3,10:18.12
-4,-3,10:18.12
-8,-2,10:18.12
-7,-2,10:18.12
-6,-2,10:17.0
-5,-2,10:18.12
-4,-2,10:18.12
-7,-1,10:18.12
-6,-1,10:18.12
-5,-1,10:18.12
-4,-1,10:18.12
-5,0,10:18.12
-4,0,10:18.12
-3,0,10:18.4
-6,1,10:18.12
-5,1,10:18.12
-4,1,10:18.12
-8,2,10:18.12
-7,2,10:18.12
-6,2,10:18.12
-5,2,10:18.12
-4,2,10:18.12
-3,2,10:18.12
-6,3,10:18.12
-5,3,10:18.4
-2,5,10:18.12
-2,6,10:18.12
-1,6,10:18.12
-5,7,10:44.2
-4,7,10:44.2
-3,7,10:44.2
-2,7,10:18.12
-1,7,10:18.4
-5,8,10:44.2
-4,8,10:43.2
-3,8,10:44.2
-6,9,10:18.12
-5,9,10:44.2
-4,9,10:44.2
-3,9,10:44.2
-8,10,10:18.12
-7,10,10:18.12
-6,10,10:18.12
-5,10,10:18.12
-6,11,10:18.12
-7,-3,11:18.12
-6,-3,11:18.12
-5,-3,11:18.12
-7,-2,11:18.12
-6,-2,11:18.12
-5,-2,11:18.12
-6,-1,11:18.12
-5,-1,11:18.12
-6,1,11:18.12
-5,1,11:18.12
-7,2,11:18.12
-6,2,11:18.12
-5,2,11:18.12
-7,3,11:18.4
-6,3,11:18.12
-2,6,11:18.12
-6,9,11:18.12
-5,9,11:18.12
-7,10,11:18.12
-6,10,11:18.12
-5,10,11:18.12
-7,11,11:18.4
-6,11,11:18.12
-6,-3,12:18.12
-6,-2,12:18.12
-5,-2,12:18.12
-7,2,12:18.12
-6,2,12:18.12
-7,10,12:18.12
-6,10,12:18.12
-5,10,12:106.2
-6,9,12:106.1
-7,9,12:106.1
-5,2,12:106.2
-6,1,12:106.1
-7,1,12:106.1
-5,-3,12:106.1
-6,-4,12:106.1
-5,11,11:106.2
-8,11,11:106.8
-4,10,11:106.2
-4,9,11:106.2
-7,9,11:106.1
-5,8,11:106.1
-6,8,11:106.1
-2,7,11:106.4
-1,6,11:106.2
-2,5,11:106.1
-5,3,11:106.2
-8,3,11:106.8
-4,2,11:106.2
-4,1,11:106.2
-7,1,11:106.1
-5,0,11:106.1
-6,0,11:106.1
-4,-1,11:106.2
-4,-2,11:106.2
-8,-2,11:106.8
-8,-3,11:106.8
-5,-4,11:106.1
-6,-4,11:106.1
-7,-4,11:106.1
-5,11,10:106.2
-8,11,10:106.8
-4,10,10:106.2
-9,10,10:106.8
-7,9,10:106.9
-8,9,10:106.1
-1,8,10:106.4
-2,8,10:106.4
-6,8,10:106.1
0,7,10:106.2
0,6,10:106.2
-1,5,10:106.2
-2,4,10:106.1
-8,3,10:106.8
-2,2,10:106.2
-9,2,10:106.8
-7,1,10:106.9
-8,1,10:106.1
-2,0,10:106.2
-6,0,10:106.1
-9,-2,10:106.8
-8,-3,10:106.9
-4,-4,10:106.1
-5,-4,10:106.1
-7,-4,10:106.1
-6,-5,10:106.1
-6,13,9:106.4
-5,12,9:106.4
-7,12,9:106.4
-3,11,9:106.4
-4,11,9:106.4
-8,11,9:106.8
-9,10,9:106.8
-1,9,9:106.2
-7,9,9:106.9
-8,9,9:106.1
0,8,9:106.2
-7,8,9:106.8
0,7,9:106.2
-7,7,9:106.8
1,6,9:106.2
-1,4,9:106.1
-2,4,9:106.1
-7,4,9:106.4
-8,3,9:106.8
-9,2,9:106.8
-1,1,9:106.2
-7,1,9:106.9
-8,1,9:106.1
-1,0,9:106.2
-7,0,9:106.8
-9,-2,9:106.8
-3,-3,9:106.1
-8,-3,9:106.9
-4,-4,9:106.1
-7,-4,9:106.1
-5,-5,9:106.1
-6,-5,9:106.1
-6,13,8:106.4
-5,12,8:106.4
-7,12,8:106.4
-2,11,8:106.4
-3,11,8:106.4
-4,11,8:106.4
-8,11,8:106.8
-1,10,8:106.2
-3,10,8:85.0
-4,10,8:85.0
-5,10,8:85.0
-8,10,8:106.8
-9,10,8:106.8
-1,9,8:106.2
-2,9,8:85.0
-6,9,8:85.0
-7,9,8:106.9
-8,9,8:106.1
0,8,8:106.2
-2,8,8:85.0
-6,8,8:85.0
-7,8,8:106.8
1,7,8:106.2
-2,7,8:85.0
-6,7,8:85.0
-7,7,8:106.8
1,6,8:106.2
-3,6,8:85.0
-5,6,8:85.0
-7,6,8:106.8
1,5,8:106.2
-3,5,8:85.0
-5,5,8:85.0
0,4,8:106.1
-1,4,8:106.1
-3,4,8:85.0
-5,4,8:85.0
-7,4,8:106.4
-3,3,8:85.0
-5,3,8:85.0
-8,3,8:106.8
-3,2,8:85.0
-5,2,8:85.0
-8,2,8:106.8
-9,2,8:106.8
-1,1,8:106.2
-2,1,8:85.0
-6,1,8:85.0
-7,1,8:106.9
-8,1,8:106.1
-1,0,8:106.2
-2,0,8:85.0
-6,0,8:85.0
0,-1,8:106.2
-2,-1,8:85.0
-6,-1,8:85.0
-3,-2,8:85.0
-4,-2,8:85.0
-9,-2,8:106.8
-3,-3,8:106.1
-8,-3,8:106.9
-2,-4,8:106.1
-4,-4,8:106.1
-7,-4,8:106.1
-5,-5,8:106.1
-6,-5,8:106.1
-6,13,7:106.4
-5,12,7:106.4
-6,12,7:106.4
-7,12,7:106.4
-2,11,7:106.4
-3,11,7:106.4
-4,11,7:106.4
-8,11,7:106.8
-1,10,7:106.2
-3,10,7:85.0
-4,10,7:85.0
-5,10,7:85.0
-8,10,7:106.8
-9,10,7:106.8
-1,9,7:106.2
-2,9,7:85.0
-6,9,7:85.0
-7,9,7:106.9
-8,9,7:106.1
0,8,7:106.2
-2,8,7:85.0
-5,8,7:65.5
-7,8,7:106.8
1,7,7:106.2
-2,7,7:85.0
-6,7,7:85.0
-7,7,7:106.8
1,6,7:106.2
-3,6,7:85.0
-5,6,7:85.0
-7,6,7:106.8
1,5,7:106.2
-3,5,7:85.0
-5,5,7:85.0
0,4,7:106.1
-3,4,7:85.0
-5,4,7:85.0
-6,4,7:106.4
-7,4,7:106.4
1,3,7:106.2
-3,3,7:85.0
-5,3,7:85.0
-8,3,7:106.8
1,2,7:106.2
-3,2,7:85.0
-5,2,7:85.0
-8,2,7:106.8
-9,2,7:106.8
-2,1,7:85.0
-6,1,7:85.0
-7,1,7:106.9
-8,1,7:106.1
-1,0,7:106.2
-2,0,7:85.0
-5,0,7:65.5
-7,0,7:106.8
0,-1,7:106.2
-2,-1,7:85.0
-6,-1,7:85.0
-3,-2,7:85.0
-4,-2,7:85.0
-7,-2,7:106.8
-9,-2,7:106.8
-3,-3,7:106.1
-8,-3,7:106.9
-2,-4,7:106.1
-4,-4,7:106.1
-5,-4,7:106.1
-6,-4,7:106.1
-7,-4,7:106.1
-5,-5,7:106.1
-6,-5,7:106.1
-6,13,6:106.4
-5,12,6:106.4
-6,12,6:106.4
-7,12,6:106.4
-2,11,6:106.4
-3,11,6:106.4
-4,11,6:106.4
-8,11,6:106.8
-1,10,6:106.2
-7,10,6:106.8
-8,10,6:106.8
-9,10,6:106.8
-1,9,6:106.2
-7,9,6:106.9
-8,9,6:106.1
-1,8,6:106.2
-5,8,6:65.5
-7,8,6:106.8
1,7,6:106.2
0,7,6:106.2
-7,7,6:106.8
1,6,6:106.2
-7,6,6:106.8
1,5,6:106.2
0,5,6:106.2
-3,5,6:85.0
-5,5,6:85.0
0,4,6:106.1
-1,4,6:106.2
-3,4,6:85.0
-5,4,6:85.0
-6,4,6:106.4
-7,4,6:106.4
1,3,6:106.2
0,3,6:106.2
-3,3,6:85.0
-5,3,6:85.0
-6,3,6:106.4
-8,3,6:106.8
1,2,6:106.2
-7,2,6:106.8
-8,2,6:106.8
-9,2,6:106.8
-1,1,6:106.2
-7,1,6:106.9
-8,1,6:106.1
-1,0,6:106.2
-5,0,6:65.5
-7,0,6:106.8
0,-1,6:106.2
-7,-1,6:106.8
-7,-2,6:106.8
-9,-2,6:106.8
-1,-3,6:106.1
-3,-3,6:106.1
-4,-3,6:106.1
-8,-3,6:106.9
-2,-4,6:106.1
-4,-4,6:106.1
-5,-4,6:106.1
-6,-4,6:106.1
-7,-4,6:106.1
-5,-5,6:106.1
-6,-5,6:106.1
-6,13,5:106.4
-5,12,5:106.4
-6,12,5:106.4
-7,12,5:106.4
-2,11,5:106.4
-3,11,5:106.4
-4,11,5:106.4
-8,11,5:106.8
-1,10,5:106.2
-3,10,5:85.0
-4,10,5:85.0
-5,10,5:85.0
-7,10,5:106.8
-8,10,5:106.8
-9,10,5:106.8
-1,9,5:106.2
-2,9,5:85.0
-6,9,5:85.0
-7,9,5:106.9
-8,9,5:106.1
-1,8,5:106.2
-2,8,5:85.0
-5,8,5:65.5
-7,8,5:106.8
1,7,5:106.2
0,7,5:106.2
-2,7,5:85.0
-6,7,5:85.0
-7,7,5:106.8
1,6,5:106.2
0,6,5:106.2
-5,6,5:85.0
-7,6,5:106.8
1,5,5:106.2
0,5,5:106.2
-1,5,5:106.1
0,4,5:106.1
-6,4,5:106.4
-7,4,5:106.4
1,3,5:106.2
0,3,5:106.2
-1,3,5:106.2
-6,3,5:106.4
-8,3,5:106.8
-1,2,5:106.2
-3,2,5:85.0
-4,2,5:85.0
-5,2,5:85.0
-7,2,5:106.8
-8,2,5:106.8
-9,2,5:106.8
-1,1,5:106.2
-6,1,5:85.0
-7,1,5:106.9
-8,1,5:106.1
-1,0,5:106.2
-5,0,5:65.5
-7,0,5:106.8
0,-1,5:106.2
-6,-1,5:85.0
-7,-1,5:106.8
-1,-2,5:106.2
-3,-2,5:85.0
-4,-2,5:85.0
-5,-2,5:85.0
-7,-2,5:106.8
-9,-2,5:106.8
-1,-3,5:106.1
-3,-3,5:106.1
-4,-3,5:106.1
-8,-3,5:106.9
-2,-4,5:106.1
-4,-4,5:106.1
-5,-4,5:106.1
-6,-4,5:106.1
-7,-4,5:106.1
-5,-5,5:106.1
-6,-5,5:106.1
-5,12,4:106.4
-6,12,4:106.4
-7,12,4:106.4
-2,11,4:106.4
-3,11,4:106.4
-4,11,4:106.4
-6,11,4:106.4
-8,11,4:106.8
-1,10,4:106.2
-3,10,4:85.0
-4,10,4:85.0
-5,10,4:85.0
-7,10,4:106.8
-8,10,4:106.8
-9,10,4:106.8
-1,9,4:106.2
-2,9,4:85.0
-6,9,4:85.0
-7,9,4:106.9
-8,9,4:106.1
-1,8,4:106.2
-2,8,4:85.0
-5,8,4:65.5
-7,8,4:106.8
1,7,4:106.2
0,7,4:106.2
-2,7,4:85.0
-6,7,4:85.0
-7,7,4:106.8
1,6,4:106.2
0,6,4:106.2
-5,6,4:85.0
-7,6,4:106.8
1,5,4:106.2
-1,5,4:106.1
0,4,4:106.1
-6,4,4:106.4
-7,4,4:106.4
1,3,4:106.2
0,3,4:106.2
-1,3,4:106.2
-2,3,4:106.4
-6,3,4:106.4
-8,3,4:106.8
1,2,4:85.0
0,2,4:85.0
-1,2,4:85.0
-3,2,4:85.0
-4,2,4:85.0
-5,2,4:85.0
-7,2,4:106.8
-8,2,4:106.8
-9,2,4:106.8
1,1,4:85.0
-6,1,4:85.0
-7,1,4:106.9
-8,1,4:106.1
-1,0,4:106.2
-5,0,4:65.5
-7,0,4:106.8
1,-1,4:85.0
0,-1,4:106.2
-6,-1,4:85.0
-7,-1,4:106.8
1,-2,4:85.0
0,-2,4:85.0
-1,-2,4:85.0
-3,-2,4:85.0
-4,-2,4:85.0
-5,-2,4:85.0
-7,-2,4:106.8
-1,-3,4:106.1
-2,-3,4:106.1
-4,-3,4:106.1
-6,-3,4:106.1
-8,-3,4:106.8
-2,-4,4:106.1
-4,-4,4:106.1
-5,-4,4:106.1
-6,-4,4:106.1
-7,-4,4:106.1
-6,-5,4:106.1
-5,12,3:106.4
-6,12,3:106.4
-7,12,3:106.4
-2,11,3:106.4
-3,11,3:106.4
-4,11,3:106.4
-5,11,3:106.4
-6,11,3:106.4
-8,11,3:106.8
-1,10,3:106.2
-7,10,3:106.8
-8,10,3:106.8
-9,10,3:106.8
-1,9,3:106.2
-7,9,3:106.9
-8,9,3:106.1
-1,8,3:106.2
-5,8,3:65.5
-7,8,3:106.8
1,7,3:106.2
0,7,3:106.2
-1,7,3:106.2
-7,7,3:106.8
1,6,3:106.2
0,6,3:106.2
-7,6,3:106.8
1,5,3:106.2
-1,5,3:106.1
0,4,3:106.1
-7,4,3:106.4
0,3,3:106.6
-1,3,3:106.2
-2,3,3:106.4
-3,3,3:106.4
-4,3,3:106.4
-5,3,3:106.4
-6,3,3:106.4
-8,3,3:106.8
1,2,3:85.0
-7,2,3:106.8
-8,2,3:106.8
-9,2,3:106.8
1,1,3:85.0
-7,1,3:106.9
-8,1,3:106.1
1,0,3:85.0
-5,0,3:65.5
-7,0,3:106.8
1,-1,3:85.0
-7,-1,3:106.8
1,-2,3:85.0
-7,-2,3:106.8
0,-3,3:106.1
-1,-3,3:106.1
-2,-3,3:106.1
-3,-3,3:106.1
-4,-3,3:106.1
-5,-3,3:106.1
-6,-3,3:106.1
-2,-4,3:106.1
-4,-4,3:106.1
-5,-4,3:106.1
-6,-4,3:106.1
-7,-4,3:106.1
-6,-5,3:106.1
-5,12,2:106.4
-6,12,2:106.4
-7,12,2:106.4
-2,11,2:106.4
-3,11,2:106.4
-4,11,2:106.4
-5,11,2:106.4
-6,11,2:106.4
-8,11,2:106.8
-1,10,2:106.2
-7,10,2:106.8
-9,10,2:106.8
-1,9,2:106.2
-2,9,2:106.1
-7,9,2:106.9
-1,8,2:106.2
-5,8,2:65.5
-7,8,2:106.8
1,7,2:106.2
0,7,2:106.2
-1,7,2:106.2
-7,7,2:106.8
1,6,2:106.2
0,6,2:106.2
-7,6,2:106.8
1,5,2:106.2
-1,5,2:106.1
0,4,2:106.1
-7,4,2:106.4
0,3,2:106.6
-1,3,2:106.2
-2,3,2:106.4
-3,3,2:106.4
-4,3,2:106.4
-5,3,2:106.4
-6,3,2:106.4
-8,3,2:106.8
1,2,2:85.0
-1,2,2:85.0
-7,2,2:106.8
-9,2,2:106.8
-2,1,2:106.1
-5,0,2:65.5
-7,0,2:106.8
-2,-1,2:106.4
-7,-1,2:106.8
1,-2,2:85.0
-1,-2,2:85.0
-7,-2,2:106.8
0,-3,2:106.1
-1,-3,2:106.1
-2,-3,2:106.1
-3,-3,2:106.1
-4,-3,2:106.1
-5,-3,2:106.1
-6,-3,2:106.1
-2,-4,2:106.1
-5,-4,2:106.1
-6,-4,2:106.1
-7,-4,2:106.1
-6,-5,2:106.1
-6,12,1:106.4
-7,12,1:106.4
-2,11,1:106.4
-3,11,1:106.4
-4,11,1:106.4
-5,11,1:106.4
-6,11,1:106.4
-8,11,1:106.8
-1,10,1:106.2
-7,10,1:106.8
-9,10,1:106.8
-1,9,1:106.2
-2,9,1:106.1
-7,9,1:106.9
-1,8,1:106.2
-5,8,1:65.5
-7,8,1:106.8
1,7,1:106.2
0,7,1:106.2
-1,7,1:106.2
-7,7,1:106.8
1,6,1:106.2
0,6,1:106.2
-7,6,1:106.8
-1,5,1:106.1
-7,4,1:106.4
0,3,1:106.6
-1,3,1:106.2
-3,3,1:106.4
-4,3,1:106.4
-5,3,1:106.4
-6,3,1:106.4
-8,3,1:106.8
1,2,1:85.0
-7,2,1:106.8
-5,0,1:65.5
-7,0,1:106.8
-2,-1,1:106.4
1,-2,1:85.0
-7,-2,1:106.8
0,-3,1:106.1
-1,-3,1:106.1
-2,-3,1:106.1
-3,-3,1:106.1
-4,-3,1:106.1
-5,-3,1:106.1
-6,-3,1:106.1
-2,-4,1:106.1
-6,-4,1:106.1
-7,-4,1:106.1
-6,-5,1:106.1
-6,12,0:106.4
-7,12,0:106.4
-2,11,0:106.4
-3,11,0:31.1
-4,11,0:106.4
-5,11,0:31.1
-6,11,0:106.4
-8,11,0:106.8
-1,10,0:106.2
-3,10,0:38.0
-4,10,0:31.1
-5,10,0:31.1
-7,10,0:106.8
-9,10,0:106.8
0,9,0:31.1
-1,9,0:31.1
-2,9,0:31.1
-3,9,0:31.1
-4,9,0:31.1
-5,9,0:31.1
-6,9,0:31.1
-7,9,0:31.1
0,8,0:31.1
-1,8,0:31.1
-2,8,0:31.1
-3,8,0:31.1
-4,8,0:31.1
-5,8,0:31.1
-7,8,0:106.8
1,7,0:106.2
0,7,0:31.1
-1,7,0:31.1
-2,7,0:31.1
-3,7,0:31.1
-4,7,0:37.0
-5,7,0:31.1
-6,7,0:31.1
-7,7,0:31.1
1,6,0:106.2
0,6,0:106.2
-1,6,0:31.1
-3,6,0:31.1
-4,6,0:31.1
-7,6,0:106.8
-2,5,0:31.1
-4,5,0:31.1
-5,5,0:31.1
-6,5,0:31.1
-7,5,0:31.1
-1,4,0:31.1
-3,4,0:31.1
-5,4,0:31.1
-6,4,0:31.1
-7,4,0:106.4
0,3,0:31.1
-4,3,0:106.4
-5,3,0:31.1
-6,3,0:106.4
-8,3,0:106.8
1,2,0:85.0
-5,2,0:31.1
-7,2,0:106.8
0,1,0:31.1
-4,1,0:31.1
-5,1,0:31.1
-6,1,0:31.1
1,0,0:31.1
0,0,0:31.1
-1,0,0:31.1
-3,0,0:31.1
-4,0,0:31.1
-5,0,0:31.1
-7,0,0:106.8
1,-1,0:31.1
0,-1,0:31.1
-1,-1,0:31.1
-2,-1,0:31.1
-3,-1,0:31.1
-4,-1,0:37.0
-5,-1,0:31.1
-6,-1,0:31.1
1,-2,0:85.0
0,-2,0:38.0
-1,-2,0:31.1
-3,-2,0:31.1
-4,-2,0:31.1
-5,-2,0:31.1
-7,-2,0:106.8
0,-3,0:106.1
-2,-3,0:37.0
-3,-3,0:31.1
-4,-3,0:31.1
-5,-3,0:31.1
-6,-3,0:106.1
-2,-4,0:106.1
-6,-4,0:106.1
-6,-5,0:106.1
