[META]
version=2.0
spawnOnBlockType=2
spawnSunlight=True
spawnDarkness=True
spawnWater=False
spawnLava=False
underFill=False
randomRotation=True
dig=False
tree=True
branch=False
needsFoundation=True
rarity=10
collisionPercentage=2
spawnElevationMin=0
spawnElevationMax=100
spawnInBiome=All
[DATA]
1,-3,-3:1.5
2,-3,-3:1.5
3,-3,-3:1.5
2,-4,-2:3.5
3,-4,-2:17.0
1,-3,-2:3.5
2,-3,-2:3.5
3,-3,-2:3.5
1,-2,-2:17.0
2,-2,-2:3.5
1,-4,-1:2.5
2,-4,-1:2.5
3,-4,-1:2.5
0,-3,-1:2.5
1,-3,-1:2.5
2,-3,-1:17.0
3,-3,-1:2.5
4,-3,-1:2.5
1,-2,-1:2.5
2,-2,-1:2.5
3,-2,-1:2.5
2,-3,0:17.0
2,-3,1:17.0
1,-3,2:17.0
2,-3,2:17.0
0,-3,3:17.0
1,-3,3:17.0
3,-3,3:17.0
4,-4,4:17.0
-1,-3,4:17.0
1,-3,4:17.0
4,-3,4:17.0
4,-5,5:17.0
-2,-4,5:17.0
2,-3,5:17.0
4,-3,5:17.0
-2,-2,5:17.0
2,-2,5:17.0
4,-6,6:17.0
-3,-5,6:17.0
-2,-5,6:17.0
-1,-4,6:17.0
2,-4,6:17.0
-3,-3,6:17.0
1,-3,6:17.0
3,-3,6:17.0
5,-3,6:17.0
5,-2,6:17.0
-2,-1,6:17.0
2,-1,6:17.0
2,0,6:17.0
1,-7,7:18.14
2,-7,7:18.14
3,-7,7:18.14
-3,-6,7:17.0
-2,-6,7:18.14
-1,-6,7:18.14
0,-6,7:18.14
3,-6,7:17.0
4,-6,7:18.6
-4,-5,7:18.14
1,-5,7:17.0
5,-5,7:18.14
6,-5,7:18.14
-5,-4,7:18.14
5,-4,7:18.14
7,-4,7:18.14
-5,-3,7:18.14
-4,-3,7:17.0
-3,-3,7:18.14
-1,-3,7:18.14
0,-3,7:17.0
3,-3,7:17.0
5,-3,7:18.14
6,-3,7:17.0
7,-3,7:17.0
8,-3,7:18.14
-4,-2,7:18.14
-3,-2,7:17.0
8,-2,7:18.14
-3,-1,7:18.14
1,-1,7:17.0
3,-1,7:17.0
5,-1,7:17.0
7,-1,7:18.14
-2,0,7:18.14
6,0,7:18.14
-1,1,7:18.14
2,1,7:17.0
5,1,7:18.14
0,2,7:18.14
2,2,7:18.14
3,2,7:18.14
4,2,7:18.14
-2,-8,8:18.14
-1,-8,8:18.14
0,-8,8:18.14
2,-8,8:18.14
3,-8,8:18.14
-3,-7,8:18.14
-2,-7,8:18.14
-1,-7,8:18.14
0,-7,8:18.14
1,-7,8:18.14
2,-7,8:18.14
3,-7,8:18.14
4,-7,8:18.14
-5,-6,8:18.14
-4,-6,8:18.14
-3,-6,8:18.14
-2,-6,8:18.14
-1,-6,8:18.14
0,-6,8:18.14
1,-6,8:18.14
2,-6,8:18.14
3,-6,8:18.14
4,-6,8:18.14
5,-6,8:18.14
6,-6,8:18.14
7,-6,8:18.14
-6,-5,8:18.14
-5,-5,8:18.14
-4,-5,8:18.14
-2,-5,8:18.14
-1,-5,8:18.14
0,-5,8:18.14
2,-5,8:18.14
3,-5,8:18.14
4,-5,8:18.14
5,-5,8:18.14
6,-5,8:18.14
7,-5,8:18.14
8,-5,8:18.14
-6,-4,8:18.14
-5,-4,8:18.14
-4,-4,8:18.14
-3,-4,8:18.14
3,-4,8:17.0
5,-4,8:18.14
6,-4,8:17.0
7,-4,8:18.14
8,-4,8:18.14
9,-4,8:18.14
-6,-3,8:18.14
-5,-3,8:18.14
-4,-3,8:18.14
-3,-3,8:18.14
-2,-3,8:18.14
-1,-3,8:17.0
1,-3,8:18.14
3,-3,8:18.14
5,-3,8:18.14
8,-3,8:18.14
9,-3,8:18.14
-6,-2,8:18.14
-5,-2,8:18.14
-4,-2,8:18.14
-1,-2,8:18.14
0,-2,8:18.14
3,-2,8:17.0
6,-2,8:17.0
8,-2,8:18.14
9,-2,8:18.14
-5,-1,8:18.14
-4,-1,8:18.14
-3,-1,8:18.14
-2,-1,8:18.14
-1,-1,8:18.14
7,-1,8:17.0
8,-1,8:18.14
9,-1,8:18.14
-4,0,8:18.14
-3,0,8:18.14
-2,0,8:18.14
-1,0,8:18.14
0,0,8:17.0
1,0,8:18.14
2,0,8:17.0
5,0,8:18.14
6,0,8:18.14
7,0,8:18.14
8,0,8:18.14
-3,1,8:18.14
-2,1,8:18.14
-1,1,8:18.14
0,1,8:18.14
4,1,8:18.14
5,1,8:18.14
6,1,8:18.14
-2,2,8:18.14
-1,2,8:18.14
0,2,8:18.14
1,2,8:18.6
2,2,8:17.0
3,2,8:18.14
4,2,8:18.14
5,2,8:18.14
6,2,8:18.14
-1,3,8:18.14
0,3,8:18.14
1,3,8:18.14
2,3,8:18.14
3,3,8:18.14
4,3,8:18.14
1,-7,9:18.14
2,-7,9:18.14
-2,-6,9:18.14
-1,-6,9:18.14
0,-6,9:18.14
1,-6,9:18.14
2,-6,9:18.14
3,-6,9:18.14
-3,-5,9:18.14
-2,-5,9:18.14
-1,-5,9:18.14
0,-5,9:18.14
1,-5,9:18.14
2,-5,9:18.14
3,-5,9:18.14
4,-5,9:18.14
5,-5,9:18.14
-3,-4,9:18.14
-2,-4,9:18.14
-1,-4,9:18.14
0,-4,9:18.14
1,-4,9:18.14
2,-4,9:18.14
3,-4,9:18.14
4,-4,9:18.14
5,-4,9:18.14
6,-4,9:18.14
7,-4,9:18.14
-3,-3,9:18.14
-2,-3,9:18.14
-1,-3,9:18.14
0,-3,9:17.0
1,-3,9:17.0
2,-3,9:18.14
3,-3,9:18.14
4,-3,9:18.14
5,-3,9:18.14
6,-3,9:18.14
7,-3,9:18.14
8,-3,9:18.14
-3,-2,9:18.14
-2,-2,9:18.14
-1,-2,9:18.14
0,-2,9:18.14
1,-2,9:18.14
2,-2,9:18.14
3,-2,9:18.14
4,-2,9:18.14
5,-2,9:18.14
6,-2,9:18.14
7,-2,9:18.14
8,-2,9:18.14
-2,-1,9:18.14
-1,-1,9:18.14
0,-1,9:18.14
1,-1,9:18.14
2,-1,9:18.14
3,-1,9:18.14
4,-1,9:18.14
5,-1,9:18.14
6,-1,9:18.14
7,-1,9:18.14
8,-1,9:18.14
-1,0,9:18.14
0,0,9:18.14
1,0,9:18.14
2,0,9:18.14
3,0,9:18.14
4,0,9:18.14
0,1,9:18.14
1,1,9:18.14
2,1,9:18.14
3,1,9:18.14
4,1,9:18.14
1,2,9:18.14
2,2,9:18.14
3,2,9:18.14
0,-5,10:18.14
2,-5,10:18.14
-1,-4,10:18.14
0,-4,10:18.14
1,-4,10:18.14
2,-4,10:18.14
3,-4,10:18.14
4,-4,10:18.14
-1,-3,10:18.14
0,-3,10:18.14
1,-3,10:18.14
2,-3,10:18.14
3,-3,10:18.14
4,-3,10:18.14
5,-3,10:18.14
6,-3,10:18.6
-1,-2,10:18.14
0,-2,10:18.14
1,-2,10:18.14
2,-2,10:18.14
3,-2,10:18.14
4,-2,10:18.14
5,-2,10:18.14
6,-2,10:18.14
0,-1,10:18.14
1,-1,10:18.14
2,-1,10:18.14
3,-1,10:18.14
4,-1,10:18.14
1,0,10:18.14
2,0,10:18.14
3,0,10:18.6
3,-2,0:31.1
2,-2,0:31.1
1,-2,0:31.1
4,-3,0:31.1
3,-3,0:31.1
1,-3,0:31.1
0,-3,0:31.1
3,-4,0:31.1
2,-4,0:31.1
1,-4,0:31.1
