[META]
version=2.0
spawnOnBlockType=12,8,9
spawnSunlight=True
spawnDarkness=True
spawnWater=True
spawnLava=False
underFill=False
randomRotation=True
dig=True
tree=False
branch=False
needsFoundation=false
rarity=300
collisionPercentage=50
spawnElevationMin=60
spawnElevationMax=64
spawnInBiome=All
[DATA]
1,-5,-2:17.0
3,-5,-2:17.0
-3,-3,-2:17.0
2,-3,-2:17.0
4,-3,-2:17.0
0,-2,-2:17.0
-3,-1,-2:17.0
5,-1,-2:17.0
0,0,-2:17.0
-3,1,-2:17.0
2,1,-2:17.0
5,1,-2:17.0
0,3,-2:17.0
2,3,-2:17.0
4,3,-2:17.0
1,-5,-1:17.0
3,-5,-1:17.0
-3,-3,-1:17.0
2,-3,-1:17.0
4,-3,-1:17.0
0,-2,-1:17.0
-3,-1,-1:17.0
5,-1,-1:17.0
0,0,-1:17.0
-3,1,-1:17.0
2,1,-1:17.0
5,1,-1:17.0
0,3,-1:17.0
2,3,-1:17.0
4,3,-1:17.0
1,-5,0:17.0
3,-5,0:17.0
-1,-4,0:17.0
-3,-3,0:17.0
1,-3,0:17.0
2,-3,0:17.0
4,-3,0:17.0
-1,-2,0:17.0
0,-2,0:17.0
-3,-1,0:17.0
1,-1,0:17.0
5,-1,0:17.0
0,0,0:17.0
3,0,0:17.0
-3,1,0:17.0
2,1,0:17.0
5,1,0:17.0
0,3,0:17.0
2,3,0:17.0
4,3,0:17.0
1,-5,1:17.0
3,-5,1:17.0
-1,-4,1:17.0
3,-4,1:17.0
-3,-3,1:17.0
-2,-3,1:17.0
-1,-3,1:17.0
2,-3,1:17.0
3,-3,1:17.0
4,-3,1:17.0
-1,-2,1:17.0
2,-2,1:17.0
-3,-1,1:17.0
-2,-1,1:17.0
1,-1,1:17.0
5,-1,1:17.0
1,0,1:17.0
3,0,1:17.0
-3,1,1:17.0
-2,1,1:17.0
1,1,1:17.0
4,1,1:17.0
5,1,1:17.0
0,2,1:17.0
1,2,1:17.0
2,2,1:17.0
4,2,1:17.0
0,3,1:17.0
2,3,1:17.0
4,3,1:17.0
1,-5,2:17.0
1,-4,2:17.0
1,-3,2:17.0
-1,-2,2:17.0
1,-2,2:17.0
-2,-1,2:17.0
-1,-1,2:17.0
1,-1,2:17.0
2,-1,2:17.0
4,-1,2:17.0
5,-1,2:17.0
1,0,2:17.0
2,0,2:17.0
3,0,2:17.0
4,0,2:17.0
-2,1,2:17.0
-1,1,2:17.0
0,1,2:17.0
1,1,2:17.0
4,1,2:17.0
1,-3,3:17.0
1,-2,3:17.0
-1,-1,3:17.0
0,-1,3:17.0
1,-1,3:17.0
1,0,3:17.0
2,0,3:17.0
3,0,3:17.0
1,1,3:17.0
1,-2,4:17.0
0,-1,4:17.0
1,-1,4:17.0
1,0,4:17.0
2,0,4:17.0
1,-1,5:17.0
1,0,5:17.0
1,-1,6:17.0
1,-1,7:17.0
-1,-1,8:17.0
0,-1,8:17.0
1,-1,8:17.0
-1,-7,9:18.12
0,-7,9:18.12
1,-7,9:18.12
-3,-5,9:18.12
-3,-4,9:18.4
1,-3,9:17.0
-6,-2,9:18.4
-5,-2,9:18.12
-2,-2,9:18.4
1,-2,9:17.0
5,-2,9:18.4
-6,-1,9:18.12
-5,-1,9:18.12
-1,-1,9:17.0
1,-1,9:17.0
4,-1,9:18.12
-5,0,9:18.12
2,2,9:18.12
-2,3,9:18.4
-1,3,9:18.12
-1,4,9:18.12
0,5,9:18.4
-1,-7,10:18.12
0,-7,10:18.8
1,-7,10:18.8
2,-7,10:18.8
3,-7,10:18.8
-2,-6,10:18.8
-1,-6,10:18.8
0,-6,10:18.8
1,-6,10:17.0
2,-6,10:18.8
3,-6,10:18.8
4,-6,10:18.8
5,-6,10:18.8
-3,-5,10:18.8
-2,-5,10:18.8
-1,-5,10:17.0
0,-5,10:17.0
1,-5,10:17.0
2,-5,10:17.0
3,-5,10:17.0
4,-5,10:18.12
5,-5,10:18.8
-4,-4,10:18.8
-3,-4,10:18.8
-2,-4,10:18.8
-1,-4,10:18.12
0,-4,10:18.8
1,-4,10:17.0
2,-4,10:18.8
3,-4,10:18.8
4,-4,10:18.8
5,-4,10:18.8
6,-4,10:18.8
-5,-3,10:18.12
-4,-3,10:18.8
-3,-3,10:18.8
-2,-3,10:18.8
-1,-3,10:18.8
0,-3,10:18.8
1,-3,10:18.8
2,-3,10:17.0
3,-3,10:17.0
4,-3,10:17.0
5,-3,10:17.0
6,-3,10:18.8
7,-3,10:18.8
-5,-2,10:18.12
-4,-2,10:18.8
-3,-2,10:17.0
-2,-2,10:18.8
-1,-2,10:18.12
0,-2,10:18.8
1,-2,10:18.8
2,-2,10:18.8
3,-2,10:18.8
4,-2,10:17.0
5,-2,10:18.8
6,-2,10:18.8
7,-2,10:18.8
-5,-1,10:18.12
-4,-1,10:17.0
-3,-1,10:17.0
-2,-1,10:17.0
-1,-1,10:18.8
0,-1,10:18.8
1,-1,10:17.0
2,-1,10:18.8
3,-1,10:18.8
4,-1,10:18.8
5,-1,10:17.0
6,-1,10:18.8
7,-1,10:18.8
-5,0,10:18.12
-4,0,10:18.8
-3,0,10:17.0
-2,0,10:18.8
-1,0,10:18.8
0,0,10:18.8
1,0,10:17.0
2,0,10:18.8
3,0,10:17.0
4,0,10:17.0
5,0,10:18.8
6,0,10:18.8
7,0,10:18.8
-4,1,10:18.8
-3,1,10:18.8
-2,1,10:17.0
-1,1,10:18.8
0,1,10:18.8
1,1,10:17.0
2,1,10:17.0
3,1,10:17.0
4,1,10:18.8
5,1,10:18.8
6,1,10:18.8
-3,2,10:18.8
-2,2,10:18.8
-1,2,10:18.8
0,2,10:18.8
1,2,10:17.0
2,2,10:18.8
3,2,10:18.8
4,2,10:18.8
5,2,10:18.8
-4,3,10:18.12
-3,3,10:18.8
-2,3,10:18.8
-1,3,10:18.8
0,3,10:17.0
1,3,10:17.0
2,3,10:18.8
3,3,10:18.8
4,3,10:18.8
5,3,10:18.12
-3,4,10:18.12
-1,4,10:18.8
0,4,10:18.8
1,4,10:18.8
2,4,10:18.8
3,4,10:18.8
0,5,10:18.12
2,5,10:18.12
3,5,10:18.12
1,-6,11:18.4
-1,-5,11:18.4
0,-5,11:18.8
1,-5,11:18.8
2,-5,11:18.8
3,-5,11:18.12
4,-5,11:18.4
-1,-4,11:18.8
0,-4,11:18.8
1,-4,11:18.8
2,-4,11:18.8
3,-4,11:18.8
-2,-3,11:18.8
-1,-3,11:18.8
0,-3,11:18.8
1,-3,11:18.8
2,-3,11:18.8
3,-3,11:18.8
4,-3,11:18.8
5,-3,11:18.4
-3,-2,11:18.8
-2,-2,11:18.8
-1,-2,11:18.8
0,-2,11:18.8
1,-2,11:18.8
2,-2,11:18.8
3,-2,11:18.8
4,-2,11:18.8
5,-2,11:18.8
-4,-1,11:18.12
-3,-1,11:18.8
-2,-1,11:18.8
-1,-1,11:18.8
0,-1,11:18.8
1,-1,11:17.0
2,-1,11:18.8
3,-1,11:18.8
4,-1,11:18.8
5,-1,11:18.4
-3,0,11:18.4
-2,0,11:18.8
-1,0,11:18.8
0,0,11:18.8
1,0,11:18.8
2,0,11:18.8
3,0,11:18.8
4,0,11:18.8
-2,1,11:18.8
-1,1,11:18.8
0,1,11:18.8
1,1,11:18.8
2,1,11:18.8
3,1,11:18.8
4,1,11:18.8
-3,2,11:18.12
-2,2,11:18.12
-1,2,11:18.8
0,2,11:18.8
1,2,11:18.8
2,2,11:18.8
3,2,11:18.8
-2,3,11:18.12
0,3,11:18.12
1,3,11:18.8
1,-4,12:18.4
0,-3,12:18.8
1,-3,12:18.8
2,-3,12:18.8
-1,-2,12:18.8
0,-2,12:18.8
1,-2,12:18.8
2,-2,12:18.8
3,-2,12:18.8
-1,-1,12:18.8
0,-1,12:18.8
1,-1,12:18.8
2,-1,12:18.8
3,-1,12:18.8
-1,0,12:18.8
0,0,12:18.8
1,0,12:18.8
2,0,12:18.8
0,1,12:18.8
1,1,12:18.8
