[META]
version=2.0
spawnOnBlockType=8,9
spawnSunlight=True
spawnDarkness=True
spawnWater=False
spawnLava=False
underFill=False
randomRotation=True
dig=True
tree=False
branch=False
needsFoundation=True
rarity=100
collisionPercentage=10
spawnElevationMin=0
spawnElevationMax=100
spawnInBiome=All
[DATA]
-1,-2,-6:17.0
2,-2,-6:17.0
-2,0,-6:17.0
1,-3,-5:17.0
-2,-2,-5:17.0
-1,-2,-5:17.0
1,-2,-5:17.0
2,-2,-5:17.0
-2,0,-5:17.0
-2,1,-5:17.0
0,-4,-4:17.0
-3,-3,-4:17.0
-2,-3,-4:17.0
0,-3,-4:17.0
1,-3,-4:17.0
-2,-2,-4:17.0
-2,1,-4:17.0
0,-4,-3:17.0
-3,-3,-3:17.0
-2,1,-3:17.0
-2,2,-3:17.0
-1,2,-3:17.0
0,2,-3:17.0
0,-4,-2:17.0
1,-4,-2:17.0
2,-4,-2:17.0
-3,-3,-2:17.0
-3,-2,-2:17.0
0,2,-2:17.0
2,-4,-1:17.0
2,-3,-1:17.0
-3,-2,-1:17.0
2,-2,-1:17.0
0,2,-1:17.0
2,-3,0:17.0
-3,-2,0:17.0
-2,-2,0:18.4
1,-2,0:17.0
2,-2,0:17.0
-3,-1,0:17.0
-2,-1,0:17.0
0,1,0:17.0
0,2,0:17.0
-2,-2,1:18.12
0,-2,1:17.0
1,-2,1:17.0
-3,-1,1:18.12
-2,-1,1:17.0
-1,0,1:17.0
0,0,1:17.0
0,1,1:17.0
-3,-2,2:18.4
-2,-2,2:18.12
-1,-2,2:17.0
0,-2,2:17.0
-3,-1,2:18.12
-2,-1,2:17.0
-1,-1,2:17.0
-1,0,2:17.0
-3,-2,3:18.12
-2,-2,3:18.12
-1,-2,3:17.0
-3,-1,3:18.12
-2,-1,3:17.0
-1,-1,3:17.0
-2,0,3:17.0
-1,0,3:17.0
-3,-2,4:18.12
-3,-1,4:18.12
-2,-1,4:17.0
-1,-1,4:17.0
0,-1,4:18.4
-2,0,4:17.0
-3,-2,5:18.4
-1,-2,5:17.0
0,-2,5:18.12
-3,-1,5:18.12
-2,-1,5:17.0
-1,-1,5:17.0
0,-1,5:18.12
-2,0,5:17.0
-1,-3,6:18.12
-2,-2,6:17.0
-1,-2,6:17.0
0,-2,6:18.12
-3,-1,6:18.12
-2,-1,6:17.0
-1,-1,6:17.0
0,-1,6:17.0
1,-1,6:18.12
-2,0,6:18.12
-2,-3,7:18.12
-1,-3,7:18.12
-2,-2,7:17.0
-1,-2,7:17.0
-3,-1,7:18.12
-2,-1,7:17.0
-1,-1,7:17.0
0,-1,7:17.0
1,-1,7:18.4
-2,0,7:18.12
0,0,7:17.0
-2,-3,8:18.12
-3,-2,8:17.0
-2,-2,8:17.0
-1,-2,8:18.12
0,-2,8:18.12
-3,-1,8:18.4
-2,-1,8:17.0
-1,-1,8:17.0
0,-1,8:17.0
1,-1,8:18.12
-2,0,8:18.12
-1,0,8:18.12
0,0,8:17.0
1,0,8:17.0
0,1,8:18.12
1,1,8:18.12
-3,-3,9:18.12
-2,-3,9:18.12
-4,-2,9:18.12
-3,-2,9:17.0
-2,-2,9:17.0
-1,-2,9:18.12
-3,-1,9:18.12
-2,-1,9:18.12
-1,-1,9:17.0
0,-1,9:18.12
1,-1,9:18.12
2,-1,9:18.12
-1,0,9:18.12
0,0,9:18.12
1,0,9:17.0
2,0,9:17.0
0,1,9:18.4
1,1,9:18.12
2,1,9:18.12
-4,-3,10:18.12
-3,-3,10:18.12
1,-3,10:18.12
-4,-2,10:17.0
-3,-2,10:17.0
-2,-2,10:18.12
-1,-2,10:18.12
0,-2,10:18.12
1,-2,10:18.12
-4,-1,10:18.12
-3,-1,10:18.12
-2,-1,10:18.12
-1,-1,10:17.0
0,-1,10:17.0
1,-1,10:18.12
2,-1,10:18.12
-1,0,10:18.12
0,0,10:18.12
1,0,10:18.12
2,0,10:17.0
3,0,10:18.12
1,1,10:18.12
2,1,10:17.0
3,1,10:18.12
2,2,10:18.12
3,2,10:18.12
-4,-4,11:18.12
-5,-3,11:18.12
-4,-3,11:17.0
-3,-3,11:18.12
-1,-3,11:18.4
0,-3,11:18.12
1,-3,11:18.12
2,-3,11:18.12
-5,-2,11:18.12
-4,-2,11:17.0
-3,-2,11:17.0
-2,-2,11:18.12
-1,-2,11:18.12
0,-2,11:17.0
1,-2,11:18.12
2,-2,11:18.12
-4,-1,11:18.4
-1,-1,11:18.12
0,-1,11:17.0
1,-1,11:18.12
2,-1,11:18.4
-1,0,11:18.12
0,0,11:18.12
1,0,11:18.12
2,0,11:18.12
3,0,11:18.12
1,1,11:18.12
2,1,11:17.0
3,1,11:18.12
1,2,11:18.12
2,2,11:18.12
3,2,11:18.12
4,2,11:18.12
2,3,11:18.12
3,3,11:18.12
4,3,11:18.12
2,-5,12:18.4
3,-5,12:18.12
-4,-4,12:18.4
0,-4,12:18.12
1,-4,12:18.12
2,-4,12:18.12
3,-4,12:18.12
4,-4,12:18.4
-5,-3,12:18.12
-4,-3,12:17.0
-3,-3,12:18.12
-1,-3,12:18.12
0,-3,12:18.12
1,-3,12:18.12
2,-3,12:18.12
3,-3,12:18.12
-4,-2,12:17.0
-3,-2,12:18.12
-1,-2,12:18.12
0,-2,12:17.0
1,-2,12:18.12
2,-2,12:18.12
3,-2,12:18.12
-1,-1,12:18.12
0,-1,12:18.12
1,-1,12:18.12
2,-1,12:18.12
-1,0,12:18.12
0,0,12:18.12
1,0,12:18.12
2,0,12:18.12
3,0,12:18.12
1,1,12:18.12
2,1,12:17.0
3,1,12:18.12
4,1,12:18.12
1,2,12:18.12
2,2,12:17.0
3,2,12:17.0
4,2,12:18.12
5,2,12:18.12
1,3,12:18.12
2,3,12:18.12
3,3,12:17.0
4,3,12:18.12
2,4,12:18.12
3,4,12:18.12
4,4,12:18.12
5,4,12:18.12
3,5,12:18.4
4,5,12:18.12
5,5,12:18.12
1,-6,13:18.12
2,-6,13:18.12
3,-6,13:18.12
-4,-5,13:18.12
0,-5,13:18.12
1,-5,13:18.12
2,-5,13:18.12
3,-5,13:18.12
4,-5,13:18.12
-5,-4,13:18.12
-4,-4,13:17.0
-3,-4,13:18.12
-1,-4,13:18.12
0,-4,13:18.12
1,-4,13:18.12
2,-4,13:18.12
3,-4,13:18.12
4,-4,13:18.12
5,-4,13:18.12
-4,-3,13:17.0
-1,-3,13:18.12
0,-3,13:18.12
1,-3,13:17.0
2,-3,13:18.12
3,-3,13:18.12
4,-3,13:18.12
5,-3,13:18.12
-4,-2,13:18.12
-1,-2,13:18.12
0,-2,13:17.0
1,-2,13:17.0
2,-2,13:18.12
3,-2,13:18.12
4,-2,13:18.12
0,-1,13:18.12
1,-1,13:18.12
2,-1,13:18.12
3,-1,13:18.12
1,0,13:18.4
2,0,13:18.12
2,1,13:18.12
3,1,13:18.12
2,2,13:18.12
3,2,13:18.12
4,2,13:18.12
2,3,13:18.12
3,3,13:18.12
4,3,13:18.12
3,4,13:18.12
4,4,13:18.12
2,-6,14:18.4
-4,-5,14:18.12
1,-5,14:18.12
2,-5,14:18.12
3,-5,14:18.12
-5,-4,14:18.12
-4,-4,14:17.0
-3,-4,14:18.12
0,-4,14:18.4
1,-4,14:18.12
2,-4,14:17.0
3,-4,14:18.12
4,-4,14:18.12
-4,-3,14:18.12
0,-3,14:18.12
1,-3,14:17.0
2,-3,14:17.0
3,-3,14:18.12
4,-3,14:18.12
0,-2,14:18.12
1,-2,14:18.12
2,-2,14:18.12
3,-2,14:18.12
3,2,14:18.12
3,3,14:18.12
1,-5,15:18.12
2,-5,15:18.12
3,-5,15:18.12
-4,-4,15:18.12
1,-4,15:18.12
2,-4,15:17.0
3,-4,15:18.12
1,-3,15:18.12
2,-3,15:18.12
3,-3,15:18.12
2,-5,16:18.4
1,-4,16:18.12
2,-4,16:18.12
3,-4,16:18.12
2,-3,16:18.12
2,-4,17:18.12
3,-3,16:106.4
4,-4,16:106.2
3,-5,16:106.1
2,-2,15:106.4
4,-4,15:106.2
3,-6,15:106.1
1,-1,14:106.4
0,-1,14:106.4
5,-4,14:106.2
-6,-4,14:106.8
4,-5,14:106.1
-3,-5,14:106.1
-4,-6,14:106.1
1,1,13:106.4
-5,-2,13:106.8
6,-3,13:106.2
-5,-3,13:106.8
6,-4,13:106.2
-3,-5,13:106.1
-5,-5,13:106.1
-4,-6,13:106.1
5,6,12:106.4
4,6,12:106.4
3,6,12:106.4
6,5,12:106.2
2,5,12:106.4
6,4,12:106.2
5,3,12:106.2
6,2,12:106.2
5,1,12:106.1
0,1,12:106.4
3,-1,12:106.2
-4,-1,12:106.4
4,-2,12:106.2
-2,-2,12:106.2
-5,-2,12:106.12
6,-3,12:106.2
-2,-3,12:106.2
-6,-3,12:106.8
6,-4,12:106.2
5,-4,12:106.2
-3,-4,12:106.1
4,-5,12:106.1
-4,-5,12:106.1
-5,-5,12:106.1
-4,-6,12:106.1
5,6,11:106.4
4,6,11:106.4
3,6,11:106.4
2,5,11:106.4
6,4,11:106.2
4,4,11:106.4
3,4,11:106.4
2,4,11:106.4
5,3,11:106.2
6,2,11:106.2
0,1,11:106.4
-1,1,11:106.4
4,0,11:106.2
3,-1,11:106.1
4,-2,11:106.2
-2,-3,11:106.1
-6,-3,11:106.8
5,-4,11:106.2
-3,-4,11:106.1
-4,-5,11:106.1
-4,-6,11:106.1
3,6,10:106.4
2,5,10:106.4
6,4,10:106.2
4,4,10:106.4
3,4,10:106.4
2,4,10:106.4
5,3,10:106.2
3,3,10:106.4
4,2,10:106.2
4,1,10:106.2
0,1,10:106.4
-1,1,10:106.4
4,0,10:106.2
-4,0,10:106.4
3,-1,10:106.1
4,-2,10:106.2
2,-2,10:106.1
2,-3,10:106.2
0,-3,10:106.1
-1,-3,10:106.1
-2,-3,10:106.1
5,-4,10:106.2
1,-4,10:106.1
-3,-4,10:106.1
-4,-5,10:106.1
2,5,9:106.4
6,4,9:106.2
3,4,9:106.4
2,4,9:106.4
3,3,9:106.4
4,2,9:106.2
2,2,9:106.4
1,2,9:106.4
4,1,9:106.2
3,1,9:106.2
-1,1,9:106.4
4,0,9:106.2
3,0,9:106.2
-4,0,9:106.4
3,-1,9:106.1
2,-2,9:106.1
1,-2,9:106.1
0,-2,9:106.0
2,-3,9:106.2
0,-3,9:106.1
-1,-3,9:106.1
5,-4,9:106.2
1,-4,9:106.1
-3,-4,9:106.1
3,4,8:106.4
3,3,8:106.4
4,2,8:106.2
2,2,8:106.4
1,2,8:106.4
4,1,8:106.2
3,1,8:106.2
2,1,8:106.2
-1,1,8:106.4
3,0,8:106.2
2,0,8:106.2
-3,0,8:106.8
2,-1,8:106.2
1,-2,8:106.1
0,-3,8:106.1
1,-4,8:106.1
-2,-4,8:106.1
-3,-4,8:106.1
3,3,7:106.4
2,2,7:106.4
3,1,7:106.2
2,1,7:106.2
0,1,7:106.4
3,0,7:106.2
2,0,7:106.2
1,0,7:106.2
-1,0,7:106.4
-3,0,7:106.12
2,-1,7:106.2
-4,-1,7:106.8
1,-2,7:106.1
0,-2,7:106.1
0,-3,7:106.2
1,-4,7:106.1
-1,-4,7:106.1
-2,-4,7:106.1
-3,-4,7:106.1
2,2,6:106.4
2,1,6:106.2
0,1,6:106.4
1,0,6:106.6
0,0,6:106.4
-1,0,6:106.4
2,-1,6:106.2
-4,-1,6:106.8
1,-2,6:106.1
0,-3,6:106.3
-2,-3,6:106.1
-1,-4,6:106.1
-2,-4,6:106.1
-3,-4,6:106.1
2,1,5:106.2
-2,1,5:106.4
1,0,5:106.6
-1,0,5:106.4
-3,0,5:106.4
-4,-1,5:106.8
1,-2,5:106.2
-2,-2,5:106.1
-4,-2,5:106.8
0,-3,5:106.1
-2,-3,5:106.1
-1,-4,5:106.1
-3,-4,5:106.1
-2,1,4:106.4
1,0,4:106.6
-1,0,4:106.4
-3,0,4:106.4
-4,-1,4:106.8
1,-2,4:106.2
-2,-2,4:106.1
-4,-2,4:106.8
-1,-4,4:106.1
-1,1,3:106.4
-2,1,3:106.4
1,0,3:106.6
0,0,3:106.2
-3,0,3:106.4
0,-1,3:106.2
-4,-1,3:106.8
-4,-2,3:106.8
-1,-3,3:106.1
-3,-3,3:106.1
-1,-4,3:106.1
-1,1,2:106.4
-2,1,2:106.4
1,0,2:106.6
0,0,2:106.2
0,-1,2:106.2
-4,-1,2:106.8
-4,-2,2:106.8
-1,-3,2:106.1
-2,-3,2:106.1
-1,1,1:106.4
-2,1,1:106.4
1,0,1:106.6
-2,0,1:106.4
-3,0,1:106.4
0,-1,1:106.2
-3,-2,1:106.0
-4,-2,1:106.8
1,-3,1:106.1
0,-3,1:106.1
-1,-3,1:106.1
-2,-3,1:106.1
1,1,0:106.2
-1,1,0:106.4
-2,1,0:106.4
1,0,0:106.6
-3,0,0:106.4
3,-2,0:106.2
-4,-2,0:106.8
3,-3,0:106.2
1,-3,0:106.1
-1,-3,0:106.1
2,-4,0:106.1
