[META]
version=2.0
spawnOnBlockType=8,9
spawnSunlight=True
spawnDarkness=True
spawnWater=False
spawnLava=False
underFill=False
randomRotation=True
dig=False
tree=False
branch=False
needsFoundation=False
rarity=200
collisionPercentage=0
spawnElevationMin=0
spawnElevationMax=66
spawnInBiome=All
[DATA]
0,0,0:17.0
0,0,-1:17.0
0,0,1:17.0
0,0,2:17.0
0,0,3:17.0
0,0,4:17.0
0,0,5:17.0
0,0,6:17.0
-1,-1,6:17.0
0,1,6:17.0
-1,2,6:17.0
-1,2,7:17.0
-1,-2,7:17.0
-2,-1,7:17.0
1,0,7:17.0
2,-1,7:17.0
-2,2,7:18.0
0,0,7:17.0
0,3,8:17.0
-2,2,8:17.0
-3,-1,8:17.0
0,-3,8:17.0
2,-1,8:17.0
3,0,8:17.0
0,4,8:18.0
1,2,8:18.0
-3,0,8:18.0
0,0,8:17.0
3,0,9:17.0
2,-1,9:18.0
0,-3,9:18.0
-1,-3,9:18.0
-1,-1,9:17.0
-1,1,9:17.0
0,0,-2:17.0
0,-1,-2:17.0
-1,0,-2:17.0
0,1,-2:17.0
1,0,-2:17.0
0,-2,-3:17.0
2,0,-3:17.0
1,2,-3:17.0
-2,1,-3:17.0
-2,-1,-3:17.0
0,0,-3:17.0
-2,-1,-4:17.0
-2,1,-4:17.0
1,2,-4:17.0
2,0,-4:17.0
0,-2,-4:17.0
0,0,-4:17.0
0,-2,-5:17.0
-2,-1,-5:17.0
-2,1,-5:17.0
1,2,-5:17.0
2,0,-5:17.0
0,0,-5:17.0
