[META]
version=2.0
spawnOnBlockType=8,9
spawnSunlight=True
spawnDarkness=True
spawnWater=False
spawnLava=False
underFill=False
randomRotation=True
dig=True
tree=False
branch=False
needsFoundation=True
rarity=100
collisionPercentage=10
spawnElevationMin=0
spawnElevationMax=100
spawnInBiome=All
[DATA]
-1,-2,-6:17.0
-1,0,-6:17.0
0,2,-6:17.0
-1,-1,-5:17.0
0,1,-5:17.0
-2,2,-5:17.0
-1,-1,-4:17.0
-1,1,-4:17.0
-3,2,-4:17.0
-1,-2,-3:17.0
-3,2,-3:17.0
-1,2,-3:17.0
0,4,-3:17.0
-1,-2,-2:17.0
-3,2,-2:17.0
0,2,-2:17.0
0,5,-2:17.0
0,-2,-1:17.0
1,3,-1:17.0
-2,5,-1:17.0
0,5,-1:17.0
-1,-2,0:17.0
0,-2,0:17.0
0,-1,0:17.0
-4,0,0:17.0
1,1,0:17.0
-4,2,0:17.0
1,2,0:17.0
-1,4,0:17.0
-1,5,0:17.0
-1,-2,1:17.0
-1,-1,1:17.0
0,-1,1:17.0
-1,0,1:17.0
-4,1,1:17.0
-3,1,1:17.0
1,1,1:17.0
-3,2,1:17.0
-1,4,1:17.0
-2,0,2:18.14
-1,0,2:17.0
0,0,2:18.14
-3,1,2:17.0
-2,1,2:17.0
-1,1,2:17.0
0,1,2:17.0
-1,2,2:17.0
0,2,2:18.14
-1,3,2:17.0
-1,0,3:18.14
-2,1,3:17.0
-1,1,3:17.0
0,1,3:18.14
-2,2,3:18.14
-1,2,3:17.0
0,2,3:18.14
-1,3,3:18.14
-2,1,4:18.6
-1,1,4:17.0
-1,2,4:18.14
-1,1,5:17.0
-1,0,6:17.0
-1,1,6:17.0
0,1,6:18.6
-1,2,6:17.0
-2,3,6:18.6
-1,-2,7:18.14
0,-2,7:18.14
1,-2,7:18.14
-2,-1,7:18.14
-1,-1,7:18.14
0,-1,7:17.0
1,-1,7:18.14
-3,0,7:18.14
-2,0,7:17.0
-1,0,7:18.14
0,0,7:18.14
-3,1,7:18.14
-2,1,7:18.14
-1,1,7:18.14
0,1,7:18.14
-3,2,7:18.14
-2,2,7:18.14
-1,2,7:18.14
0,2,7:18.14
-3,3,7:18.14
-2,3,7:17.0
-1,3,7:18.14
0,3,7:18.14
-3,4,7:18.14
-2,4,7:18.14
-1,4,7:18.14
0,-1,8:18.14
-2,0,8:18.14
-1,0,8:18.14
-2,1,8:18.14
-1,1,8:18.14
-2,2,8:18.14
-1,2,8:18.14
-2,3,8:18.14
-1,5,7:106.4
-3,5,7:106.4
1,3,7:106.2
-4,2,7:106.8
1,1,7:106.2
2,-1,7:106.2
-2,-2,7:106.8
1,-3,7:106.1
-1,-3,7:106.1
-1,5,6:106.4
-3,5,6:106.4
-2,4,6:106.4
1,3,6:106.2
-3,3,6:106.8
-4,2,6:106.8
1,1,6:106.2
-2,0,6:106.8
2,-1,6:106.2
-2,-2,6:106.8
1,-3,6:106.1
-1,-3,6:106.1
-1,5,5:106.4
-3,5,5:106.4
-2,4,5:106.4
1,3,5:106.2
-3,3,5:106.8
-4,2,5:106.8
1,1,5:106.2
-2,0,5:106.8
2,-1,5:106.2
-2,-2,5:106.8
1,-3,5:106.1
-1,-3,5:106.1
-1,5,4:106.4
-3,5,4:106.4
-2,4,4:106.4
1,3,4:106.2
-3,3,4:106.8
-4,2,4:106.8
1,1,4:106.2
-2,0,4:106.8
2,-1,4:106.2
-2,-2,4:106.8
1,-3,4:106.1
-1,-3,4:106.1
-1,5,3:106.4
-3,5,3:106.4
-2,4,3:106.4
1,3,3:106.2
-3,3,3:106.8
1,2,3:106.2
-4,2,3:106.8
1,1,3:106.2
-2,0,3:106.8
2,-1,3:106.2
-2,-2,3:106.8
1,-3,3:106.1
-1,-3,3:106.1
-1,5,2:106.4
-3,5,2:106.4
-2,4,2:106.4
1,3,2:106.2
-3,3,2:106.8
1,2,2:106.2
-4,2,2:106.8
1,1,2:106.2
1,0,2:106.2
-3,0,2:106.8
2,-1,2:106.2
-2,-1,2:106.1
-2,-2,2:106.8
1,-3,2:106.1
-1,-3,2:106.1
-1,5,1:106.4
-3,5,1:106.4
-2,4,1:106.4
1,3,1:106.2
-3,3,1:106.8
1,2,1:106.2
-4,2,1:106.8
1,0,1:106.2
-3,0,1:106.8
2,-1,1:106.2
-2,-1,1:106.9
-2,-2,1:106.8
1,-3,1:106.1
-1,-3,1:106.1
-3,5,0:106.4
-2,4,0:106.4
1,3,0:106.2
-3,3,0:106.8
1,0,0:106.2
-3,0,0:106.8
2,-1,0:106.2
-2,-1,0:106.9
-2,-2,0:106.8
1,-3,0:106.1
-1,-3,0:106.1
