[META]
version=2.0
spawnOnBlockType=8,9
spawnSunlight=True
spawnDarkness=True
spawnWater=False
spawnLava=False
underFill=False
randomRotation=True
dig=True
tree=False
branch=False
needsFoundation=True
rarity=10
collisionPercentage=10
spawnElevationMin=0
spawnElevationMax=100
spawnInBiome=All
[DATA]
-4,1,0:17.0
-3,1,0:17.0
-4,2,0:44.2
-3,2,0:44.2
-4,3,0:44.2
-3,3,0:43.2
-1,4,0:17.0
-4,5,0:17.0
-1,5,0:17.0
-1,6,0:106.4
-4,6,0:106.4
0,5,0:106.2
-3,5,0:106.4
-5,5,0:106.8
0,4,0:106.2
-2,4,0:106.4
-5,4,0:106.8
0,3,0:106.2
-2,2,0:106.2
1,1,0:106.1
-2,1,0:106.2
-5,1,0:106.8
1,0,0:106.2
-3,0,0:106.1
-4,0,0:106.1
0,-1,0:106.1
-5,5,-4:17.0
0,5,-4:17.0
-2,2,-4:17.0
-2,1,-4:17.0
-4,4,-3:17.0
-4,5,-3:17.0
-5,5,-3:17.0
0,5,-3:17.0
-2,2,-3:17.0
-2,2,-2:17.0
-4,4,-2:17.0
-4,5,-2:17.0
-1,5,-2:17.0
0,5,-2:17.0
-3,1,-1:17.0
-2,1,-1:17.0
-2,2,-1:17.0
-4,5,-1:17.0
-1,5,-1:17.0
-4,1,1:17.0
-3,3,1:43.2
-2,3,1:17.0
-1,3,1:17.0
-4,4,1:17.0
-1,4,1:17.0
-4,5,1:17.0
-1,7,1:106.4
-4,6,1:106.4
-1,5,1:106.4
-3,5,1:106.4
-5,5,1:106.8
0,4,1:106.2
-2,4,1:106.4
-5,4,1:106.8
0,3,1:106.2
-4,3,1:65.4
2,2,1:106.2
-1,2,1:85
-2,2,1:106.2
-4,2,1:106.8
1,1,1:106.1
-1,1,1:85
-2,1,1:85
-3,1,1:85
-5,1,1:106.8
1,0,1:106.2
-3,0,1:106.1
-4,0,1:106.1
0,-1,1:106.1
-4,1,2:17.0
-3,1,2:17.0
-3,3,2:17.0
-2,3,2:17.0
-4,4,2:17.0
-3,4,2:17.0
-1,7,2:106.4
-4,6,2:106.4
-3,5,2:106.4
-4,5,2:106.4
-6,5,2:106.8
-1,4,2:85
-2,4,2:106.4
-5,4,2:106.8
-1,3,2:106.2
-4,3,2:65.4
2,2,2:106.2
-2,2,2:106.2
-4,2,2:106.8
1,1,2:106.1
-1,1,2:85
-2,1,2:106.2
-5,1,2:106.8
1,0,2:106.2
-3,0,2:106.1
-4,0,2:106.1
0,-1,2:106.1
-3,1,3:17.0
-3,2,3:17.0
-3,3,3:17.0
-2,3,3:17.0
-3,4,3:17.0
0,7,3:106.4
-1,7,3:106.4
-4,6,3:106.4
-3,5,3:106.4
-6,5,3:106.8
-1,4,3:85
-2,4,3:106.4
-4,4,3:85
-1,3,3:106.2
-4,3,3:65.4
2,2,3:106.2
-2,2,3:106.2
-4,2,3:106.8
1,1,3:106.1
-1,1,3:85
-2,1,3:106.2
-4,1,3:85
1,0,3:106.2
-3,0,3:106.1
0,-1,3:106.1
-3,2,4:17.0
-2,2,4:17.0
-3,3,4:17.0
-2,3,4:17.0
0,7,4:106.4
-1,7,4:106.4
-4,6,4:106.4
-5,6,4:106.4
-1,5,4:85
-4,5,4:85
-6,5,4:106.8
0,4,4:85
-1,4,4:85
-2,4,4:85
-3,4,4:85
-4,4,4:85
-5,4,4:85
-1,3,4:85
-4,3,4:65.4
2,2,4:106.2
-1,2,4:85
-4,2,4:85
1,1,4:106.1
0,1,4:85
-1,1,4:85
-2,1,4:85
-3,1,4:85
-4,1,4:85
-5,1,4:85
1,0,4:106.2
-1,0,4:85
-4,0,4:85
0,-1,4:106.1
-5,0,5:44.2
-4,0,5:44.2
-3,0,5:44.2
-2,0,5:44.2
-1,0,5:44.2
0,0,5:43.2
-5,1,5:44.2
-4,1,5:44.2
-3,1,5:44.2
-2,1,5:44.2
-1,1,5:44.2
0,1,5:43.2
-5,2,5:44.2
-4,2,5:44.2
-3,2,5:17.0
-2,2,5:17.0
-1,2,5:44.2
0,2,5:43.2
1,2,5:43.2
-5,3,5:44.2
-3,3,5:17.0
-2,3,5:17.0
-1,3,5:44.2
0,3,5:44.2
1,3,5:43.2
-5,4,5:44.2
-4,4,5:44.2
-3,4,5:44.2
-2,4,5:44.2
-1,4,5:44.2
0,4,5:44.2
1,4,5:43.2
-5,5,5:43.2
-4,5,5:43.2
-3,5,5:43.2
-2,5,5:44.2
-1,5,5:44.2
0,5,5:44.2
1,5,5:43.2
-3,6,5:43.2
-2,6,5:43.2
-1,6,5:43.2
0,6,5:43.2
1,6,5:43.2
0,7,5:106.4
-1,7,5:106.4
-4,6,5:106.4
-5,6,5:106.4
-6,5,5:106.8
-4,3,5:65.4
2,2,5:106.2
1,1,5:106.1
1,0,5:106.2
0,-1,5:106.1
-3,2,6:17.0
-2,2,6:17.0
-3,3,6:17.0
-2,3,6:17.0
1,6,6:85
0,6,6:85
-1,6,6:85
-2,6,6:85
-3,6,6:85
1,5,6:85
-3,5,6:85
-4,5,6:85
-5,5,6:85
1,4,6:85
1,3,6:85
1,2,6:85
0,2,6:85
0,1,6:85
0,0,6:85
-3,-2,7:18
-3,-1,7:18
-4,2,7:18
-3,2,7:17.0
-2,2,7:17.0
-3,3,7:17.0
-2,3,7:17.0
1,6,7:85
-3,6,7:85
-3,5,7:85
1,2,7:85
0,2,7:85
-2,-4,8:18
-3,-3,8:18
-2,-3,8:18
-1,-3,8:18
-3,-2,8:18
-2,-2,8:18
-1,-2,8:18
-4,-1,8:18
-3,-1,8:18
-2,-1,8:18
-1,-1,8:18
-4,0,8:18
-3,0,8:17.0
-2,0,8:18
-4,1,8:18
-3,1,8:17.0
-2,1,8:18
-5,2,8:18
-4,2,8:18
-3,2,8:17.0
-2,2,8:17.0
-1,2,8:17.0
0,2,8:44.2
1,2,8:44.2
-4,3,8:18
-3,3,8:17.0
-2,3,8:44.2
-1,3,8:44.2
0,3,8:44.2
1,3,8:44.2
-3,4,8:17.0
-2,4,8:44.2
-1,4,8:44.2
0,4,8:44.2
1,4,8:44.2
-3,5,8:44.2
-2,5,8:44.2
-1,5,8:44.2
0,5,8:44.2
1,5,8:44.2
-3,6,8:44.2
-2,6,8:44.2
-1,6,8:44.2
0,6,8:44.2
1,6,8:44.2
-2,-5,9:18
-3,-4,9:18
-2,-4,9:18
-1,-4,9:18
-4,-3,9:18
-3,-3,9:18
-2,-3,9:17.0
-1,-3,9:18
0,-3,9:18
-4,-2,9:18
-3,-2,9:18
-2,-2,9:17.0
-1,-2,9:18
0,-2,9:18
-5,-1,9:18
-4,-1,9:18
-3,-1,9:17.0
-2,-1,9:17.0
-1,-1,9:18
0,-1,9:18
-5,0,9:18
-4,0,9:18
-3,0,9:17.0
-2,0,9:18
-1,0,9:18
0,0,9:18
-4,1,9:18
-3,1,9:18
-2,1,9:18
-1,1,9:18
0,1,9:18
1,1,9:18
-6,2,9:18
-5,2,9:18
-4,2,9:18
-3,2,9:17.0
-2,2,9:18
-1,2,9:17.0
0,2,9:17.0
1,2,9:18
-5,3,9:18
-4,3,9:18
-3,3,9:18
-2,3,9:18
-1,3,9:18
0,3,9:18
1,3,9:18
-4,4,9:18
-3,4,9:17.0
-2,4,9:18
-1,4,9:18
0,4,9:18
-3,5,9:18
-2,5,9:18
-1,5,9:18
-2,6,9:18
-1,6,9:18
-2,-4,10:18
-3,-3,10:18
-2,-3,10:18
-1,-3,10:18
-3,-2,10:18
-2,-2,10:18
-1,-2,10:18
-4,-1,10:18
-3,-1,10:18
-2,-1,10:18
-1,-1,10:18
-4,0,10:18
-3,0,10:18
-2,0,10:18
-1,0,10:18
0,0,10:18
1,0,10:18
-5,1,10:18
-4,1,10:18
-3,1,10:18
-2,1,10:18
-1,1,10:18
0,1,10:17.0
1,1,10:17.0
2,1,10:18
-6,2,10:18
-5,2,10:18
-4,2,10:17.0
-3,2,10:17.0
-2,2,10:18
-1,2,10:18
0,2,10:17.0
1,2,10:18
2,2,10:18
-6,3,10:18
-5,3,10:18
-4,3,10:18
-3,3,10:18
0,3,10:18
1,3,10:18
-5,4,10:18
-4,4,10:18
-3,4,10:17.0
-2,4,10:17.0
-1,4,10:18
0,4,10:18
-4,5,10:18
-3,5,10:18
-2,5,10:17.0
-1,5,10:18
0,5,10:18
-4,6,10:18
-3,6,10:18
-2,6,10:17.0
-1,6,10:18
0,6,10:18
-3,7,10:18
-2,7,10:18
-1,7,10:18
-2,8,10:18
-2,-3,11:18
-2,-2,11:18
-3,-1,11:18
-2,-1,11:18
-1,-1,11:18
0,-1,11:18
1,-1,11:18
-5,0,11:18
-4,0,11:18
-3,0,11:18
-2,0,11:18
-1,0,11:18
0,0,11:18
1,0,11:18
2,0,11:18
-6,1,11:18
-5,1,11:18
-4,1,11:18
-3,1,11:18
-2,1,11:18
-1,1,11:18
0,1,11:18
1,1,11:17.0
2,1,11:18
-7,2,11:18
-6,2,11:18
-5,2,11:17.0
-4,2,11:17.0
-3,2,11:18
-2,2,11:18
-1,2,11:18
0,2,11:18
1,2,11:18
2,2,11:18
-7,3,11:18
-6,3,11:18
-5,3,11:17.0
-4,3,11:18
-3,3,11:18
-2,3,11:18
-1,3,11:18
0,3,11:18
1,3,11:18
-6,4,11:18
-5,4,11:18
-3,4,11:18
-2,4,11:18
-1,4,11:18
-5,5,11:18
-3,5,11:18
-2,5,11:18
-1,5,11:18
-3,6,11:18
-2,6,11:18
-1,6,11:18
-2,7,11:18
-2,-1,12:18
-3,0,12:18
-2,0,12:18
-1,0,12:18
0,0,12:18
1,0,12:18
-5,1,12:18
-4,1,12:18
-2,1,12:18
-1,1,12:18
0,1,12:18
1,1,12:18
2,1,12:18
-6,2,12:18
-5,2,12:18
-4,2,12:18
-3,2,12:18
-2,2,12:18
-1,2,12:18
0,2,12:18
1,2,12:18
-7,3,12:18
-6,3,12:18
-5,3,12:17.0
-4,3,12:18
-3,3,12:18
-2,3,12:18
-1,3,12:18
-7,4,12:18
-6,4,12:18
-5,4,12:17.0
-4,4,12:18
-3,4,12:18
-2,4,12:18
-1,4,12:18
-6,5,12:18
-5,5,12:18
-4,5,12:18
-3,5,12:18
-2,5,12:18
-5,6,12:18
-2,6,12:18
-2,0,13:18
-1,1,13:18
1,1,13:18
-5,2,13:18
-4,2,13:18
-6,3,13:18
-5,3,13:18
-4,3,13:18
-1,3,13:18
-6,4,13:18
-5,4,13:18
-4,4,13:18
-5,5,13:18
-5,3,14:18
-5,4,14:18
-5,5,-5:17.0
0,5,-5:17.0
-2,1,-5:17.0
-1,1,-5:17.0
-5,5,-6:17.0
0,5,-6:17.0
0,4,-6:17.0
-1,1,-6:17.0
