[META]
version=2.0
spawnOnBlockType=2
spawnSunlight=True
spawnDarkness=True
spawnWater=False
spawnLava=False
underFill=False
randomRotation=True
dig=False
tree=True
branch=False
needsFoundation=True
rarity=10
collisionPercentage=50
spawnElevationMin=0
spawnElevationMax=90
spawnInBiome=All
[DATA]
-1,0,0:17.2
0,0,0:17.2
0,1,0:17.2
-1,1,0:17.2
1,1,0:17.2
0,-1,0:17.2
-2,0,0:17.2
0,2,0:17.2
1,0,0:17.2
-1,-1,0:31.1
0,-2,0:31.1
1,-1,0:31.1
2,1,0:31.1
-1,2,0:31.1
-3,1,0:31.1
0,3,0:31.1
-2,1,0:31.1
-2,-1,0:31.1
1,2,0:31.2
-1,-2,0:31.2
-3,0,0:31.2
2,0,0:31.2
-1,3,0:31.2
-2,2,0:31.2
-1,0,1:17.2
0,0,1:17.2
0,1,1:17.2
1,0,1:17.2
0,-1,1:17.2
0,0,2:17.2
0,1,2:17.2
0,-1,2:17.2
-1,0,2:17.2
1,0,2:17.2
0,0,3:17.2
0,-1,3:17.2
-1,0,3:17.2
0,1,3:17.2
1,0,3:17.2
0,0,4:17.2
0,-1,4:17.2
-1,0,4:17.2
1,0,4:17.2
0,1,4:17.2
0,0,5:17.2
-1,0,5:17.2
0,-1,5:17.2
0,1,5:17.2
1,0,5:17.2
0,0,6:17.2
-1,0,6:17.2
0,-1,6:17.2
0,1,6:17.2
1,0,6:17.2
0,0,7:17.2
-1,-6,7:35.0
-6,-4,7:35.0
-8,3,7:35.0
1,4,7:35.0
-1,0,7:17.2
0,-1,7:17.2
0,1,7:17.2
1,0,7:17.2
0,0,8:17.2
4,-3,8:17.2
-6,-4,8:17.2
1,4,8:17.2
-4,7,8:17.2
-5,7,8:17.2
-8,3,8:17.2
-8,2,8:17.2
-1,-1,8:17.2
4,0,8:17.2
-1,-6,8:17.2
-3,9,8:17.2
-1,-7,8:18.0
-7,-3,8:18.0
-9,1,8:18.0
-7,4,8:18.0
-2,-1,8:18.0
4,-2,8:18.0
5,0,8:18.0
2,5,8:18.0
-4,6,8:18.0
-2,9,8:18.0
1,0,8:17.2
-6,-5,8:18.0
-7,-4,8:18.0
0,-6,8:18.0
4,-4,8:18.0
2,4,8:18.0
-6,7,8:18.0
-3,10,8:18.0
-8,-6,8:35.0
6,-2,8:35.0
-1,0,8:17.2
0,-1,8:17.2
0,1,8:17.2
0,0,9:17.2
-4,7,9:17.2
2,5,9:17.2
3,-3,9:17.2
-6,-3,9:17.2
0,4,9:17.2
-1,-3,9:17.2
-7,3,9:17.2
-8,3,9:17.2
3,0,9:17.2
1,0,9:17.2
-1,-5,9:17.2
-8,-6,9:17.2
6,-2,9:17.2
-4,9,9:17.2
-8,-7,9:18.0
-7,-3,9:18.0
-2,-5,9:18.0
-1,-6,9:18.0
0,-2,9:18.0
-1,-2,9:17.2
3,-4,9:18.0
4,-2,9:18.0
5,-3,9:18.0
6,-3,9:18.0
7,-1,9:18.0
3,1,9:18.0
2,-1,9:18.0
0,1,9:18.0
-1,-1,9:18.0
-1,4,9:18.0
1,3,9:18.0
1,5,9:18.0
3,4,9:18.0
-5,6,9:18.0
-3,9,9:18.0
-4,8,9:18.0
-8,4,9:18.0
-6,3,9:18.0
-8,2,9:18.0
-5,-2,9:18.0
-6,-4,9:18.0
4,0,9:18.0
1,4,9:18.0
-9,-6,9:18.0
-9,3,9:18.0
-4,10,9:18.0
7,-2,9:18.0
2,6,9:18.0
-1,0,9:17.2
0,-1,9:17.2
0,0,10:17.2
-7,3,10:17.2
-5,-3,10:17.2
2,-3,10:17.2
-4,-3,10:17.2
-4,6,10:17.2
-4,5,10:17.2
-1,4,10:17.2
-1,3,10:17.2
-1,-3,10:17.2
-2,1,10:17.2
2,0,10:17.2
1,6,10:17.2
-1,-4,10:17.2
-8,-5,10:17.2
-1,1,10:17.2
6,-1,10:17.2
-4,8,10:17.2
-2,-5,10:18.0
-7,-5,10:18.0
-6,-2,10:18.0
-7,2,10:18.0
-5,5,10:18.0
-4,7,10:18.0
-2,2,10:18.0
-2,4,10:18.0
2,6,10:18.0
0,4,10:18.0
2,1,10:18.0
3,-4,10:18.0
6,-2,10:18.0
0,-3,10:18.0
-2,0,10:18.0
-9,-5,10:18.0
-8,-6,10:18.0
-7,4,10:18.0
-5,8,10:18.0
1,7,10:18.0
6,0,10:18.0
2,-4,10:18.0
0,-4,10:18.0
-3,1,10:18.0
0,9,10:35.0
7,5,10:35.0
-3,-7,10:35.0
3,-5,10:35.0
-1,0,10:17.2
0,-1,10:17.2
1,0,10:17.2
0,0,11:17.2
3,-5,11:17.2
-1,2,11:17.2
-3,-2,11:17.2
-4,-2,11:17.2
-3,-1,11:17.2
-7,2,11:17.2
-6,2,11:17.2
-4,4,11:17.2
-4,3,11:17.2
2,-2,11:17.2
2,-1,11:17.2
-3,-7,11:17.2
-3,-5,11:17.2
-2,-5,11:17.2
-2,-4,11:17.2
-3,2,11:17.2
-3,1,11:17.2
-1,5,11:17.2
1,2,11:17.2
1,1,11:17.2
0,5,11:17.2
1,5,11:17.2
1,7,11:17.2
0,7,11:17.2
-7,-5,11:17.2
7,5,11:17.2
5,-1,11:17.2
0,9,11:17.2
-3,-8,11:18.0
-2,-7,11:18.0
3,-2,11:18.0
3,-6,11:18.0
-8,-5,11:18.0
-6,-4,11:18.0
-4,-3,11:18.0
-2,-3,11:18.0
-1,-4,11:18.0
-1,0,11:18.0
1,-1,11:18.0
3,0,11:18.0
5,-2,11:18.0
0,2,11:18.0
-2,1,11:18.0
-4,2,11:18.0
-6,1,11:18.0
-5,4,11:18.0
-1,4,11:18.0
1,6,11:18.0
0,8,11:18.0
1,10,11:18.0
-1,7,11:18.0
7,4,11:18.0
-3,5,11:18.0
-7,-6,11:18.0
-7,1,11:18.0
-8,2,11:18.0
-1,9,11:18.0
0,10,11:18.0
7,6,11:18.0
8,5,11:18.0
6,-1,11:18.0
2,-5,11:18.0
4,-5,11:18.0
-4,-7,11:18.0
-7,-4,11:18.0
-7,3,11:18.0
-4,9,11:18.0
1,9,11:18.0
2,7,11:18.0
2,5,11:18.0
-1,6,11:18.0
1,4,11:18.0
-9,0,11:35.0
6,-6,11:35.0
0,-1,11:17.2
1,0,11:17.2
-3,-6,12:17.2
1,-1,12:17.2
1,0,12:17.2
-2,-1,12:17.2
-2,0,12:17.2
-5,2,12:17.2
-4,2,12:17.2
0,0,12:17.2
-3,5,12:17.2
3,2,12:17.2
2,2,12:17.2
-2,5,12:17.2
2,-5,12:17.2
1,-5,12:17.2
4,3,12:17.2
-5,-1,12:17.2
0,8,12:17.2
-9,0,12:17.2
-6,-5,12:17.2
-6,-4,12:17.2
6,5,12:17.2
-1,1,12:17.2
4,-1,12:17.2
6,-6,12:17.2
-3,-7,12:18.0
-2,-5,12:18.0
3,-5,12:18.0
6,-7,12:18.0
4,-2,12:18.0
0,-1,12:17.2
-6,-6,12:18.0
-5,-3,12:18.0
-9,-1,12:18.0
-6,-1,12:18.0
-3,-2,12:18.0
-2,1,12:18.0
-1,0,12:18.0
1,1,12:18.0
2,-1,12:18.0
5,-1,12:18.0
2,1,12:18.0
3,3,12:18.0
5,2,12:18.0
6,4,12:18.0
7,6,12:18.0
-2,4,12:18.0
0,5,12:18.0
-1,7,12:18.0
1,8,12:18.0
-6,2,12:18.0
-4,4,12:18.0
7,-6,12:18.0
-7,-5,12:18.0
-10,1,12:18.0
-10,0,12:18.0
0,9,12:18.0
-1,8,12:18.0
6,6,12:18.0
7,4,12:18.0
5,-6,12:18.0
-2,-6,12:18.0
-7,7,12:35.0
-3,6,13:17.2
4,2,13:17.2
0,0,13:17.2
1,-4,13:17.2
0,-3,13:17.2
3,2,13:17.2
-4,0,13:17.2
-4,-1,13:17.2
-5,-4,13:17.2
5,5,13:17.2
5,-6,13:17.2
-7,7,13:17.2
-8,0,13:17.2
3,-1,13:17.2
5,8,13:17.2
-6,-4,13:18.0
-9,0,13:18.0
-5,-1,13:18.0
-2,-1,13:18.0
1,-5,13:18.0
6,-7,13:18.0
3,-2,13:18.0
4,0,13:18.0
2,2,13:18.0
4,3,13:18.0
4,5,13:18.0
6,9,13:18.0
-2,7,13:18.0
-2,6,13:18.0
-7,6,13:18.0
-4,3,13:18.0
-2,0,13:18.0
1,0,13:17.2
-4,6,13:18.0
-7,8,13:18.0
-8,7,13:18.0
6,8,13:18.0
4,-7,13:18.0
-3,-8,13:35.0
3,7,13:35.0
0,-1,13:17.2
0,-3,14:17.2
0,-1,14:17.2
-2,1,14:17.2
-4,1,14:17.2
0,0,14:17.2
-5,-3,14:17.2
5,4,14:17.2
5,-5,14:17.2
-1,7,14:17.2
-6,7,14:17.2
-8,1,14:17.2
6,1,14:17.2
3,7,14:17.2
3,0,14:17.2
5,7,14:17.2
-3,-8,14:17.2
-2,-9,14:18.0
-6,-3,14:18.0
-9,0,14:18.0
-7,2,14:18.0
-3,0,14:18.0
-1,2,14:18.0
-1,-1,14:18.0
1,-3,14:18.0
4,-5,14:18.0
6,-6,14:18.0
2,-1,14:18.0
4,1,14:18.0
5,0,14:18.0
6,2,14:18.0
4,4,14:18.0
6,5,14:18.0
4,7,14:18.0
6,8,14:18.0
2,6,14:18.0
0,8,14:18.0
-2,6,14:18.0
-4,7,14:18.0
-6,6,14:18.0
-4,-8,14:18.0
-3,-9,14:18.0
-9,1,14:18.0
-6,8,14:18.0
-7,7,14:18.0
5,8,14:18.0
5,6,14:18.0
5,-6,14:18.0
6,-4,14:18.0
1,0,14:17.2
-1,0,-1:17.2
0,0,-1:17.2
0,1,-1:17.2
-1,1,-1:17.2
-2,0,-1:17.2
0,-1,-1:17.2
1,1,-1:17.2
0,2,-1:17.2
-3,0,-1:2
-1,-2,-1:2
2,1,-1:2
-3,1,-1:2
-2,2,-1:2
-1,3,-1:2
0,3,-1:2
1,2,-1:2
2,0,-1:2
1,-1,-1:2
0,-2,-1:2
-2,-1,-1:2
-2,1,-1:2
-1,-1,-1:2
1,0,-1:17.2
-1,2,-1:2
2,-1,-1:31.2
-2,3,-1:31.2
-4,1,-1:31.2
-3,2,-1:31.1
0,4,-1:31.1
1,3,-1:31.1
2,2,-1:31.1
0,-3,-1:31.1
1,-2,-1:31.1
-3,1,-2:17.2
-2,1,-2:17.2
-2,0,-2:17.2
-2,2,-2:17.2
0,-2,-2:17.2
0,-1,-2:17.2
1,1,-2:17.2
0,2,-2:17.2
0,3,-2:17.2
0,-3,-2:3
-1,-2,-2:3
-1,-1,-2:3
1,-2,-2:3
1,0,-2:17.2
2,1,-2:3
0,4,-2:3
-1,3,-2:3
-3,2,-2:3
-4,1,-2:3
-3,0,-2:3
-2,-1,-2:3
-2,3,-2:3
-1,2,-2:3
-1,1,-2:3
-1,0,-2:3
0,0,-2:3
0,1,-2:3
1,-1,-2:3
1,2,-2:3
1,3,-2:3
2,0,-2:3
0,3,-3:17.2
0,4,-3:17.2
-3,1,-3:17.2
-4,1,-3:17.2
0,-2,-3:17.2
0,-3,-3:17.2
0,-4,-3:3
-1,-3,-3:3
-1,-2,-3:3
1,-3,-3:3
1,-2,-3:3
0,-1,-3:3
-3,0,-3:3
-4,0,-3:3
-5,1,-3:3
-2,1,-3:3
-3,2,-3:3
0,2,-3:3
-1,4,-3:3
-1,3,-3:3
1,3,-3:3
1,4,-3:3
0,5,-3:3
-1,-1,-3:3
-1,0,-3:3
-2,0,-3:3
0,0,-3:3
1,0,-3:3
1,-1,-3:3
1,1,-3:3
1,2,-3:3
0,1,-3:3
-1,1,-3:3
-1,2,-3:3
-2,2,-3:3
-2,-1,-3:3
-4,2,-3:3
0,-2,15:17.2
-3,1,15:17.2
0,0,15:17.2
-4,-3,15:17.2
1,1,15:17.2
4,4,15:17.2
4,-4,15:17.2
4,-5,15:17.2
-2,6,15:17.2
-1,6,15:17.2
-6,6,15:17.2
-8,2,15:17.2
6,0,15:17.2
4,7,15:17.2
-1,1,15:17.2
4,0,15:17.2
-2,-8,15:17.2
-2,-9,15:18.0
-5,-3,15:18.0
-9,1,15:18.0
-3,2,15:18.0
0,-1,15:17.2
0,1,15:18.0
3,0,15:18.0
5,-5,15:18.0
1,-3,15:18.0
4,1,15:18.0
5,4,15:18.0
3,8,15:18.0
5,8,15:18.0
0,5,15:18.0
-3,7,15:18.0
-5,6,15:18.0
-7,6,15:18.0
-3,-8,15:18.0
-1,-7,15:18.0
-1,-8,15:18.0
-9,2,15:18.0
-6,7,15:18.0
7,0,15:18.0
6,-1,15:18.0
3,-5,15:18.0
4,-6,15:18.0
-7,2,15:35.0
1,0,15:17.2
0,0,16:17.2
-3,-2,16:17.2
-1,-8,16:17.2
2,1,16:17.2
2,2,16:17.2
4,3,16:17.2
3,-3,16:17.2
3,-4,16:17.2
-1,2,16:17.2
-7,2,16:17.2
-3,6,16:17.2
-5,6,16:17.2
0,7,16:17.2
6,0,16:17.2
5,0,16:17.2
4,-8,16:17.2
4,6,16:17.2
-4,-3,16:18.0
-1,-7,16:18.0
-2,-8,16:18.0
4,-9,16:18.0
5,-7,16:18.0
4,-4,16:18.0
0,-2,16:18.0
-3,1,16:18.0
-8,2,16:18.0
-6,6,16:18.0
-3,7,16:18.0
-1,7,16:18.0
0,2,16:18.0
1,0,16:18.0
3,1,16:18.0
5,-1,16:18.0
5,3,16:18.0
5,6,16:18.0
-1,-9,16:18.0
5,-8,16:18.0
3,-8,16:18.0
-7,1,16:18.0
4,7,16:35.0
4,-7,16:35.0
0,-1,16:17.2
0,0,17:17.2
-2,-3,17:17.2
-1,-5,17:17.2
-1,-7,17:17.2
3,2,17:17.2
2,0,17:17.2
3,-2,17:17.2
-1,3,17:17.2
-2,3,17:17.2
-6,3,17:17.2
-4,5,17:17.2
-4,6,17:17.2
-6,2,17:17.2
-1,7,17:17.2
5,-1,17:17.2
4,-7,17:17.2
4,5,17:17.2
-2,-6,17:18.0
4,-8,17:18.0
5,-6,17:18.0
2,-2,17:18.0
-3,-3,17:18.0
-6,1,17:18.0
-5,6,17:18.0
-1,2,17:18.0
2,2,17:18.0
3,1,17:18.0
5,0,17:18.0
4,4,17:18.0
0,7,17:18.0
-3,6,17:18.0
3,-4,17:18.0
-7,2,17:18.0
-1,-8,17:18.0
0,-7,17:18.0
-2,-7,17:18.0
-3,-2,17:18.0
-2,-4,17:18.0
3,-7,17:18.0
5,-2,17:18.0
6,-1,17:18.0
4,6,17:18.0
3,5,17:18.0
5,5,17:18.0
-2,7,17:18.0
-1,8,17:18.0
-5,5,17:18.0
-4,7,17:18.0
-7,3,17:18.0
-6,4,17:18.0
-1,-3,17:35.0
0,-1,17:17.2
0,0,18:17.2
-1,-3,18:17.2
-1,-4,18:17.2
-1,-6,18:17.2
2,-1,18:17.2
2,-2,18:17.2
4,-1,18:17.2
4,-3,18:17.2
-3,3,18:17.2
-4,4,18:17.2
-5,3,18:17.2
-8,-2,18:17.2
-3,7,18:17.2
-2,7,18:17.2
3,-7,18:17.2
2,2,18:17.2
3,5,18:17.2
-2,-6,18:18.0
0,-4,18:18.0
-8,-3,18:18.0
-9,-1,18:18.0
-6,2,18:18.0
-5,5,18:18.0
-4,6,18:18.0
-1,6,18:18.0
-2,3,18:18.0
-4,2,18:18.0
0,1,18:18.0
2,3,18:18.0
4,5,18:18.0
2,0,18:18.0
3,-2,18:18.0
5,-1,18:18.0
5,-4,18:18.0
4,-8,18:18.0
-2,-3,18:18.0
-1,-7,18:18.0
-9,-2,18:18.0
2,-8,18:18.0
4,-7,18:18.0
3,2,18:18.0
3,6,18:18.0
-3,8,18:18.0
-2,8,18:18.0
-1,7,18:18.0
0,-1,18:17.2
-1,1,19:17.2
0,0,19:17.2
-1,-2,19:17.2
-1,-7,19:17.2
3,-2,19:17.2
-4,3,19:17.2
2,-5,19:17.2
2,-6,19:17.2
-7,-1,19:17.2
-7,-2,19:17.2
-3,6,19:17.2
2,3,19:17.2
2,5,19:17.2
-2,-6,19:18.0
-2,-2,19:18.0
1,-7,19:18.0
3,-6,19:18.0
4,-2,19:18.0
3,3,19:18.0
1,6,19:18.0
0,1,19:18.0
-4,4,19:18.0
-2,7,19:18.0
-8,-2,19:18.0
-2,-4,19:17.2
-4,-3,19:17.2
-4,-4,19:18.0
-1,-8,19:18.0
-2,-7,19:18.0
-8,-1,19:18.0
-7,-3,19:18.0
-5,3,19:18.0
-3,7,19:18.0
-4,6,19:18.0
3,5,19:18.0
3,-3,19:18.0
2,-7,19:18.0
-2,5,19:35.0
0,-1,19:17.2
-1,0,20:17.2
-1,-1,20:17.2
0,0,20:17.2
-2,1,20:17.2
1,0,20:17.2
-1,2,20:17.2
0,2,20:17.2
1,-4,20:17.2
1,-5,20:17.2
-6,0,20:17.2
-7,0,20:17.2
-2,5,20:17.2
-2,6,20:17.2
2,4,20:17.2
0,-6,20:18.0
3,-6,20:18.0
2,-4,20:18.0
2,-1,20:18.0
3,-2,20:18.0
-1,-2,20:18.0
1,1,20:18.0
0,-1,20:18.0
-1,1,20:18.0
-2,0,20:18.0
-2,2,20:18.0
1,3,20:18.0
3,4,20:18.0
1,5,20:18.0
-3,5,20:18.0
-1,7,20:18.0
-1,5,20:18.0
-7,-1,20:18.0
-8,0,20:18.0
-6,1,20:18.0
-3,-4,20:17.2
-3,-3,20:18.0
-1,-4,20:18.0
1,-6,20:18.0
-7,1,20:18.0
-3,6,20:18.0
-2,7,20:18.0
2,5,20:18.0
2,3,20:18.0
-3,1,21:17.2
2,0,21:17.2
0,3,21:17.2
0,4,21:17.2
-5,0,21:17.2
3,-1,21:17.2
-2,4,21:17.2
3,-3,21:17.2
2,-3,21:17.2
0,-5,21:18.0
3,-4,21:18.0
4,-1,21:18.0
3,1,21:18.0
-1,3,21:18.0
1,4,21:18.0
-2,5,21:18.0
-4,1,21:18.0
-6,-1,21:18.0
-7,0,21:18.0
-4,-1,21:18.0
-6,1,21:18.0
2,-1,21:18.0
1,-3,21:18.0
1,2,21:18.0
-3,3,21:18.0
4,-3,21:18.0
2,-4,21:18.0
-5,-1,21:18.0
-3,4,21:18.0
-2,6,21:18.0
-4,1,22:17.2
2,-1,22:17.2
-1,4,22:17.2
-4,0,22:17.2
3,-2,22:17.2
-2,4,22:18.0
0,3,22:18.0
-5,0,22:18.0
-3,2,22:18.0
-4,-1,22:18.0
2,-2,22:18.0
4,-1,22:18.0
3,-4,22:18.0
2,1,22:18.0
-1,5,22:18.0
-5,2,22:18.0
-5,1,22:18.0
4,-2,22:18.0
-4,0,23:18.0
2,-1,23:18.0
-1,4,23:18.0
3,-3,23:18.0
-4,1,23:18.0
3,-2,23:18.0
