[META]
version=2.0
spawnOnBlockType=12,2
spawnSunlight=True
spawnDarkness=True
spawnWater=False
spawnLava=False
underFill=false
randomRotation=True
dig=True
tree=False
branch=False
needsFoundation=True
rarity=100
collisionPercentage=2
spawnElevationMin=0
spawnElevationMax=128
spawnInBiome=All
[DATA]
0,0,0:17.0
0,0,-1:17.0
0,0,1:17.0
0,0,2:17.0
0,0,3:17.0
0,0,4:17.0
0,0,5:17.0
0,0,6:17.0
0,0,7:17.0
0,0,8:17.0
0,0,9:17.0
1,-1,9:18.0
-1,-1,9:18.0
-1,1,9:18.0
1,1,9:18.0
2,2,9:18.0
-2,2,9:18.0
-2,-2,9:18.0
2,-2,9:18.0
0,-4,9:18.0
-4,0,9:18.0
0,4,9:18.0
4,0,9:18.0
0,0,10:18.0
-1,-1,10:18.0
1,-1,10:18.0
1,1,10:18.0
-1,1,10:18.0
1,0,10:18.0
0,-1,10:18.0
-1,0,10:18.0
0,1,10:18.0
0,3,10:18.0
3,0,10:18.0
-3,0,10:18.0
0,-3,10:18.0
-1,0,11:18.0
-2,0,11:18.0
0,-1,11:18.0
0,-2,11:18.0
0,1,11:18.0
0,2,11:18.0
1,0,11:18.0
2,0,11:18.0
