[META]
version=2.0
spawnOnBlockType=8,9
spawnSunlight=True
spawnDarkness=True
spawnWater=False
spawnLava=False
underFill=False
randomRotation=True
dig=True
tree=False
branch=False
needsFoundation=True
rarity=100
collisionPercentage=10
spawnElevationMin=0
spawnElevationMax=100
spawnInBiome=All
[DATA]
-3,0,0:17.0
0,1,0:17.0
0,2,0:106.4
1,1,0:106.2
-1,1,0:106.4
-2,1,0:106.4
-3,1,0:106.4
1,0,0:106.2
0,0,0:106.1
-1,0,0:106.2
-4,0,0:106.8
0,-1,0:106.1
-1,-1,0:106.1
-2,-1,0:106.1
-3,-1,0:106.1
-3,-1,-6:17.0
0,1,-6:17.0
-3,-1,-5:17.0
0,0,-5:17.0
0,1,-5:17.0
-3,-1,-4:17.0
-3,0,-4:17.0
0,0,-4:17.0
-3,0,-3:17.0
0,0,-3:17.0
0,1,-3:17.0
-3,0,-2:17.0
0,1,-2:17.0
-3,0,-1:17.0
0,1,-1:17.0
-3,0,1:17.0
-2,0,1:17.0
0,0,1:17.0
0,1,1:17.0
0,2,1:106.4
1,1,1:106.2
-1,1,1:106.4
-2,1,1:106.4
-3,1,1:106.4
1,0,1:106.2
-1,0,1:106.2
-4,0,1:106.8
0,-1,1:106.1
-1,-1,1:106.1
-2,-1,1:106.1
-3,-1,1:106.1
-2,0,2:17.0
-1,0,2:17.0
0,0,2:17.0
-1,1,2:106.4
-2,1,2:106.4
1,0,2:106.2
0,-1,2:106.1
-1,-1,2:106.1
-2,-1,2:106.1
-1,0,3:17.0
-2,0,3:106.8
-1,-1,3:106.1
-1,-2,4:17.0
-1,-1,4:17.0
-2,0,4:18
-1,0,4:17.0
0,0,4:17.0
-1,1,4:18
-1,-3,5:18
-2,-2,5:18
-1,-2,5:17.0
0,-2,5:18
-3,-1,5:18
-2,-1,5:18
-1,-1,5:18
0,-1,5:18
1,-1,5:18
2,-1,5:18
-3,0,5:18
-2,0,5:17.0
-1,0,5:17.0
0,0,5:18
1,0,5:17.0
2,0,5:18
3,0,5:18
-2,1,5:18
-1,1,5:17.0
0,1,5:18
1,1,5:18
2,1,5:18
-1,2,5:18
-1,-4,6:18
-2,-3,6:18
-1,-3,6:18
0,-3,6:18
-2,-2,6:18
-1,-2,6:17.0
0,-2,6:18
-3,-1,6:18
-2,-1,6:18
-1,-1,6:18
0,-1,6:18
1,-1,6:18
-4,0,6:18
-3,0,6:18
-2,0,6:18
-1,0,6:17.0
0,0,6:18
1,0,6:18
2,0,6:18
-3,1,6:18
-2,1,6:18
-1,1,6:18
0,1,6:18
1,1,6:18
-2,2,6:18
-1,2,6:17.0
0,2,6:18
-1,3,6:18
-1,-2,7:18
-2,-1,7:18
-1,-1,7:18
0,-1,7:18
-3,0,7:18
-2,0,7:18
-1,0,7:18
0,0,7:18
-2,1,7:18
-1,1,7:18
0,1,7:18
-1,2,7:18
-1,-1,8:18
-2,0,8:18
-1,0,8:18
