[META]
version=2.0
spawnOnBlockType=2
spawnSunlight=True
spawnDarkness=True
spawnWater=False
spawnLava=False
underFill=False
randomRotation=True
dig=True
tree=True
branch=False
needsFoundation=True
rarity=10
collisionPercentage=2
spawnElevationMin=0
spawnElevationMax=100
spawnInBiome=All
[DATA]
0,0,-3:1.5
0,-1,-2:3.0
-1,0,-2:3.0
0,0,-2:3.0
1,0,-2:1.5
-1,1,-2:3.5
0,1,-2:1.5
1,1,-2:3.5
0,-2,-1:2.5
-1,-1,-1:2.5
0,-1,-1:2.5
1,-1,-1:2.5
-2,0,-1:2.5
-1,0,-1:2.5
0,0,-1:3.0
1,0,-1:2.5
2,0,-1:2.5
-1,1,-1:2.5
0,1,-1:2.5
1,1,-1:2.5
0,2,-1:2.5
-1,0,0:18.4
0,0,0:17.0
0,1,0:18.12
0,0,1:17.0
0,0,2:17.0
0,-1,3:18.4
0,0,3:17.0
2,-2,4:17.0
1,-1,4:17.0
2,-1,4:17.0
0,0,4:17.0
1,0,4:17.0
2,-3,5:17.0
2,-2,5:17.0
-3,-1,5:17.0
-2,-1,5:17.0
0,-1,5:18.4
-2,0,5:17.0
-1,0,5:17.0
0,0,5:17.0
1,0,5:18.12
0,1,5:17.0
2,-4,6:18.12
3,-4,6:18.4
-4,-3,6:18.12
-3,-3,6:18.12
1,-3,6:18.12
2,-3,6:17.0
3,-3,6:18.12
-5,-2,6:18.12
-4,-2,6:17.0
-3,-2,6:17.0
-2,-2,6:18.12
0,-2,6:18.12
1,-2,6:18.12
2,-2,6:18.12
3,-2,6:18.4
-4,-1,6:18.12
-3,-1,6:17.0
-2,-1,6:18.12
-1,-1,6:18.12
0,-1,6:18.12
1,-1,6:18.12
2,-1,6:18.12
-3,0,6:18.12
-2,0,6:18.12
-1,0,6:18.12
0,0,6:18.12
1,0,6:18.12
-2,1,6:18.12
-1,1,6:18.12
0,1,6:17.0
1,1,6:18.12
2,1,6:18.12
-1,2,6:18.12
0,2,6:17.0
1,2,6:17.0
2,2,6:18.12
0,3,6:18.12
1,3,6:17.0
2,3,6:18.12
1,4,6:18.12
3,-6,7:18.4
2,-5,7:18.12
3,-5,7:18.12
4,-5,7:18.12
-4,-4,7:18.12
-3,-4,7:18.12
1,-4,7:18.12
2,-4,7:18.12
3,-4,7:18.12
4,-4,7:18.12
5,-4,7:18.12
-5,-3,7:18.12
-4,-3,7:18.12
-3,-3,7:18.12
-2,-3,7:18.12
0,-3,7:18.12
1,-3,7:18.12
2,-3,7:18.12
3,-3,7:18.12
4,-3,7:18.12
5,-3,7:18.12
-6,-2,7:18.12
-5,-2,7:18.12
-4,-2,7:18.12
-3,-2,7:18.12
-2,-2,7:18.12
-1,-2,7:18.12
0,-2,7:18.12
1,-2,7:18.12
2,-2,7:18.12
3,-2,7:18.12
4,-2,7:18.12
5,-2,7:18.4
-5,-1,7:18.12
-4,-1,7:18.12
-3,-1,7:18.12
-2,-1,7:18.12
-1,-1,7:18.12
0,-1,7:18.12
1,-1,7:18.12
2,-1,7:18.12
3,-1,7:18.12
4,-1,7:18.12
-4,0,7:18.12
-3,0,7:18.12
-2,0,7:18.12
-1,0,7:18.12
0,0,7:18.12
1,0,7:18.12
2,0,7:18.12
3,0,7:18.12
4,0,7:18.12
-3,1,7:18.12
-2,1,7:18.12
-1,1,7:18.12
0,1,7:18.12
1,1,7:18.12
2,1,7:18.12
3,1,7:18.12
4,1,7:18.12
-2,2,7:18.4
-1,2,7:18.12
0,2,7:18.12
1,2,7:18.12
2,2,7:18.12
3,2,7:18.12
4,2,7:18.12
-1,3,7:18.12
0,3,7:18.12
1,3,7:18.12
2,3,7:18.12
3,3,7:18.12
4,3,7:18.12
0,4,7:18.12
1,4,7:18.12
2,4,7:18.12
3,4,7:18.12
0,5,7:18.12
1,5,7:18.12
2,5,7:18.12
3,5,7:18.4
1,6,7:18.12
2,6,7:18.12
3,-4,8:18.12
4,-4,8:18.12
-4,-3,8:18.12
2,-3,8:18.12
3,-3,8:18.12
4,-3,8:18.12
-5,-2,8:18.12
-4,-2,8:18.12
-3,-2,8:18.12
-2,-2,8:18.4
1,-2,8:18.12
2,-2,8:18.12
3,-2,8:18.12
4,-2,8:18.12
-4,-1,8:18.4
-2,-1,8:18.12
-1,-1,8:18.12
0,-1,8:18.12
1,-1,8:18.12
2,-1,8:18.12
3,-1,8:18.12
-1,0,8:18.12
0,0,8:18.12
1,0,8:18.12
2,0,8:18.12
3,0,8:18.12
0,1,8:18.12
1,1,8:18.12
2,1,8:18.12
3,1,8:18.12
0,2,8:18.12
1,2,8:18.12
2,2,8:18.12
0,3,8:18.12
1,3,8:18.12
2,3,8:18.12
1,4,8:18.12
2,-2,9:18.12
3,-2,9:18.12
1,-1,9:18.4
2,-1,9:18.12
2,0,9:18.12
1,2,9:18.12
1,3,9:18.12
0,2,0:31.1
1,1,0:31.1
-1,1,0:31.1
2,0,0:31.1
1,0,0:31.1
-2,0,0:31.1
1,-1,0:31.1
0,-1,0:31.1
-1,-1,0:31.1
0,-2,0:31.1
