[META]
version=2.0
spawnOnBlockType=2
spawnSunlight=True
spawnDarkness=True
spawnWater=False
spawnLava=False
underFill=False
randomRotation=True
dig=True
tree=False
branch=False
needsFoundation=True
rarity=200
collisionPercentage=80
spawnElevationMin=0
spawnElevationMax=102
spawnInBiome=All
[DATA]
2,-7,0:17
3,-6,0:17
4,-6,0:17
0,-5,0:17
4,-5,0:17
5,-5,0:17
-6,-4,0:17
-5,-4,0:17
-1,-4,0:17
0,-4,0:17
2,-4,0:17
4,-4,0:17
5,-4,0:17
-4,-3,0:17
0,-3,0:17
3,-3,0:17
4,-3,0:17
-5,-2,0:17
-4,-2,0:17
-3,-2,0:17
-2,-2,0:17
3,-2,0:17
4,-2,0:17
5,-2,0:17
-3,-1,0:17
-2,-1,0:17
0,-1,0:17
1,-1,0:17
2,-1,0:17
3,-1,0:17
5,-1,0:17
6,-1,0:17
-3,0,0:17
-2,0,0:17
1,0,0:17
2,0,0:17
-3,1,0:17
-2,1,0:17
-1,1,0:17
0,1,0:17
-2,2,0:17
-1,2,0:17
0,2,0:17
1,2,0:17
-6,3,0:17
-2,3,0:17
-1,3,0:17
0,3,0:17
1,3,0:17
2,3,0:17
5,3,0:17
-6,4,0:17
-4,4,0:17
-3,4,0:17
-2,4,0:17
2,4,0:17
3,4,0:17
4,4,0:17
-5,5,0:17
-4,5,0:17
3,5,0:17
-7,6,0:17
-6,6,0:17
-5,6,0:17
4,6,0:17
-4,10,0:106.4
-5,10,0:106.4
-3,9,0:106.2
-6,9,0:106.8
3,8,0:106.4
-2,8,0:106.2
-7,8,0:106.8
5,7,0:106.4
4,7,0:106.4
2,7,0:106.4
-1,7,0:106.4
-6,7,0:106.8
6,6,0:106.2
1,6,0:106.4
0,6,0:106.4
7,5,0:106.2
-7,5,0:106.4
6,4,0:106.4
-8,4,0:106
8,3,0:106.2
7,3,0:106.4
-9,3,0:106.4
8,2,0:106.2
4,2,0:106.8
-4,2,0:106.8
-10,2,0:106.8
8,1,0:106
3,1,0:106.8
-9,1,0:106.8
8,0,0:106.4
7,0,0:106.2
-8,0,0:106.8
9,-1,0:106.2
-9,-1,0:106.8
10,-2,0:106.2
-8,-2,0:106.8
9,-3,0:106.2
-7,-3,0:106.8
8,-4,0:106.2
6,-4,0:106.1
-2,-4,0:106.1
-8,-4,0:106.8
7,-5,0:106.1
-1,-5,0:106.8
-3,-5,0:106.1
-7,-5,0:106.8
-2,-6,0:106.8
-4,-6,0:106.1
-5,-6,0:106.1
-6,-6,0:106.1
3,-7,0:106.2
-2,-7,0:106.8
2,-8,0:106.2
-3,-8,0:106.8
-2,-9,0:106.8
0,-10,0:106.1
-1,-10,0:106.1
-1,-3,-8:1
0,-3,-8:1
1,-3,-8:1
0,-2,-8:1
1,-2,-8:1
2,-2,-8:1
1,-1,-8:1
2,-1,-8:1
-1,-4,-7:1
0,-4,-7:1
-2,-3,-7:1
-1,-3,-7:1
0,-3,-7:1
1,-3,-7:1
2,-3,-7:1
-1,-2,-7:1
0,-2,-7:1
1,-2,-7:1
2,-2,-7:1
-1,-1,-7:1
0,-1,-7:1
1,-1,-7:1
2,-1,-7:1
-1,0,-7:1
0,0,-7:1
1,0,-7:1
2,0,-7:1
-1,1,-7:1
-1,-5,-6:1
0,-5,-6:1
-1,-4,-6:1
0,-4,-6:1
1,-4,-6:1
2,-4,-6:1
-3,-3,-6:1
-2,-3,-6:1
-1,-3,-6:1
0,-3,-6:1
1,-3,-6:1
2,-3,-6:1
-3,-2,-6:1
-2,-2,-6:1
0,-2,-6:1
1,-2,-6:1
2,-2,-6:1
3,-2,-6:1
-4,-1,-6:1
-3,-1,-6:1
-2,-1,-6:1
-1,-1,-6:1
0,-1,-6:1
1,-1,-6:1
2,-1,-6:1
3,-1,-6:1
4,-1,-6:1
-3,0,-6:1
-2,0,-6:1
-1,0,-6:1
0,0,-6:1
1,0,-6:1
2,0,-6:1
3,0,-6:1
-2,1,-6:1
-1,1,-6:1
0,1,-6:1
1,1,-6:1
2,1,-6:1
3,1,-6:1
-1,2,-6:1
0,2,-6:1
1,2,-6:1
2,2,-6:1
3,2,-6:1
0,-7,-5:1
-1,-6,-5:1
0,-6,-5:1
4,-6,-5:17
-2,-5,-5:1
-1,-5,-5:1
0,-5,-5:1
1,-5,-5:1
2,-5,-5:1
-5,-4,-5:17
-4,-4,-5:1
-3,-4,-5:1
-2,-4,-5:1
-1,-4,-5:1
0,-4,-5:1
1,-4,-5:1
2,-4,-5:1
3,-4,-5:1
-4,-3,-5:1
-3,-3,-5:1
-2,-3,-5:1
-1,-3,-5:1
0,-3,-5:1
1,-3,-5:1
2,-3,-5:1
3,-3,-5:1
4,-3,-5:1
-5,-2,-5:1
-4,-2,-5:1
-3,-2,-5:1
-2,-2,-5:1
-1,-2,-5:1
0,-2,-5:1
1,-2,-5:1
2,-2,-5:1
3,-2,-5:1
4,-2,-5:1
-5,-1,-5:1
-4,-1,-5:1
-3,-1,-5:1
-2,-1,-5:1
-1,-1,-5:1
0,-1,-5:1
1,-1,-5:1
2,-1,-5:1
3,-1,-5:1
4,-1,-5:1
5,-1,-5:1
-5,0,-5:1
-4,0,-5:1
-3,0,-5:1
-2,0,-5:1
-1,0,-5:1
0,0,-5:1
1,0,-5:1
2,0,-5:1
3,0,-5:1
4,0,-5:1
5,0,-5:1
-4,1,-5:1
-3,1,-5:1
-2,1,-5:1
-1,1,-5:1
0,1,-5:1
1,1,-5:1
2,1,-5:1
3,1,-5:1
4,1,-5:1
-4,2,-5:1
-3,2,-5:1
-2,2,-5:1
-1,2,-5:1
0,2,-5:1
1,2,-5:1
2,2,-5:1
3,2,-5:1
4,2,-5:1
-4,3,-5:1
-3,3,-5:1
-2,3,-5:1
-1,3,-5:1
0,3,-5:1
1,3,-5:1
2,3,-5:1
3,3,-5:1
-4,4,-5:1
-3,4,-5:1
-2,4,-5:1
-3,5,-5:17
0,-9,-4:2
1,-9,-4:17
0,-8,-4:3
1,-8,-4:17
2,-8,-4:17
4,-8,-4:17
5,-8,-4:17
-1,-7,-4:3
0,-7,-4:3
1,-7,-4:3
4,-7,-4:17
5,-7,-4:17
-2,-6,-4:3
-1,-6,-4:3
0,-6,-4:3
1,-6,-4:3
2,-6,-4:3
4,-6,-4:17
5,-6,-4:17
-5,-5,-4:3
-4,-5,-4:3
-3,-5,-4:3
-2,-5,-4:3
-1,-5,-4:3
0,-5,-4:3
1,-5,-4:3
2,-5,-4:3
4,-5,-4:17
5,-5,-4:3
-6,-4,-4:17
-5,-4,-4:17
-4,-4,-4:3
-3,-4,-4:3
-2,-4,-4:3
-1,-4,-4:3
0,-4,-4:3
1,-4,-4:3
2,-4,-4:3
3,-4,-4:1
4,-4,-4:3
5,-4,-4:3
-6,-3,-4:17
-5,-3,-4:3
-4,-3,-4:3
-3,-3,-4:3
-2,-3,-4:3
-1,-3,-4:3
0,-3,-4:3
1,-3,-4:3
2,-3,-4:3
3,-3,-4:3
4,-3,-4:3
5,-3,-4:3
-6,-2,-4:3
-5,-2,-4:3
-4,-2,-4:3
-3,-2,-4:3
-2,-2,-4:3
-1,-2,-4:3
0,-2,-4:3
1,-2,-4:3
2,-2,-4:3
3,-2,-4:3
4,-2,-4:3
5,-2,-4:3
6,-2,-4:17
-6,-1,-4:3
-5,-1,-4:3
-4,-1,-4:3
-3,-1,-4:3
-2,-1,-4:3
-1,-1,-4:3
0,-1,-4:3
1,-1,-4:3
2,-1,-4:3
3,-1,-4:3
4,-1,-4:3
5,-1,-4:3
6,-1,-4:17
-7,0,-4:3
-6,0,-4:3
-5,0,-4:3
-4,0,-4:3
-3,0,-4:3
-2,0,-4:3
-1,0,-4:3
0,0,-4:3
1,0,-4:3
2,0,-4:3
3,0,-4:3
4,0,-4:3
5,0,-4:3
-8,1,-4:3
-7,1,-4:3
-6,1,-4:3
-5,1,-4:3
-4,1,-4:1
-3,1,-4:3
-2,1,-4:3
-1,1,-4:3
0,1,-4:3
1,1,-4:3
2,1,-4:3
3,1,-4:3
4,1,-4:3
5,1,-4:3
6,1,-4:17
-8,2,-4:17
-7,2,-4:17
-5,2,-4:3
-4,2,-4:3
-3,2,-4:3
-2,2,-4:3
-1,2,-4:3
0,2,-4:3
1,2,-4:3
2,2,-4:3
3,2,-4:3
4,2,-4:3
5,2,-4:17
6,2,-4:17
-5,3,-4:3
-4,3,-4:3
-3,3,-4:3
-2,3,-4:3
-1,3,-4:3
0,3,-4:3
1,3,-4:3
2,3,-4:3
3,3,-4:3
4,3,-4:3
-5,4,-4:3
-4,4,-4:3
-3,4,-4:3
-2,4,-4:3
-1,4,-4:1
0,4,-4:3
1,4,-4:3
2,4,-4:3
3,4,-4:3
-3,5,-4:17
4,5,-4:3
5,5,-4:17
4,6,-4:3
3,7,-4:17
1,-9,-3:17
2,-9,-3:17
-1,-8,-3:3
0,-8,-3:3
1,-8,-3:17
2,-8,-3:17
3,-8,-3:2
4,-8,-3:17
5,-8,-3:17
-2,-7,-3:3
-1,-7,-3:3
0,-7,-3:3
1,-7,-3:3
2,-7,-3:3
4,-7,-3:17
5,-7,-3:17
6,-7,-3:3
-2,-6,-3:3
-1,-6,-3:3
0,-6,-3:3
1,-6,-3:3
2,-6,-3:3
3,-6,-3:3
4,-6,-3:17
5,-6,-3:17
6,-6,-3:3
7,-6,-3:17
-5,-5,-3:3
-4,-5,-3:3
-3,-5,-3:3
-2,-5,-3:3
-1,-5,-3:3
0,-5,-3:3
1,-5,-3:3
2,-5,-3:3
3,-5,-3:3
4,-5,-3:17
5,-5,-3:17
6,-5,-3:3
-6,-4,-3:3
-5,-4,-3:17
-4,-4,-3:3
-3,-4,-3:3
-2,-4,-3:3
-1,-4,-3:3
0,-4,-3:3
1,-4,-3:3
2,-4,-3:3
3,-4,-3:3
4,-4,-3:17
5,-4,-3:3
-6,-3,-3:17
-5,-3,-3:17
-4,-3,-3:3
-3,-3,-3:3
-2,-3,-3:3
0,-3,-3:3
1,-3,-3:3
2,-3,-3:3
3,-3,-3:17
4,-3,-3:3
5,-3,-3:3
-6,-2,-3:3
-5,-2,-3:3
-4,-2,-3:17
-3,-2,-3:3
-2,-2,-3:3
-1,-2,-3:3
0,-2,-3:3
1,-2,-3:3
2,-2,-3:3
3,-2,-3:3
4,-2,-3:3
5,-2,-3:3
6,-2,-3:2
-6,-1,-3:3
-5,-1,-3:3
-4,-1,-3:3
-3,-1,-3:3
-2,-1,-3:3
-1,-1,-3:3
0,-1,-3:3
1,-1,-3:3
2,-1,-3:3
3,-1,-3:3
4,-1,-3:3
5,-1,-3:3
6,-1,-3:17
-7,0,-3:3
-6,0,-3:3
-5,0,-3:3
-4,0,-3:3
-3,0,-3:3
-2,0,-3:3
-1,0,-3:3
0,0,-3:3
1,0,-3:3
2,0,-3:3
3,0,-3:3
4,0,-3:3
5,0,-3:3
-8,1,-3:3
-7,1,-3:3
-6,1,-3:3
-5,1,-3:3
-4,1,-3:3
-3,1,-3:3
-2,1,-3:3
-1,1,-3:3
0,1,-3:3
1,1,-3:3
2,1,-3:3
3,1,-3:3
4,1,-3:3
5,1,-3:3
-8,2,-3:17
-7,2,-3:17
-6,2,-3:3
-5,2,-3:3
-4,2,-3:3
-3,2,-3:3
-2,2,-3:3
-1,2,-3:3
0,2,-3:3
1,2,-3:3
2,2,-3:3
3,2,-3:3
4,2,-3:3
5,2,-3:17
6,2,-3:17
-7,3,-3:3
-6,3,-3:3
-5,3,-3:3
-4,3,-3:3
-3,3,-3:3
-2,3,-3:3
-1,3,-3:3
0,3,-3:3
1,3,-3:3
2,3,-3:3
3,3,-3:3
4,3,-3:3
5,3,-3:3
-7,4,-3:3
-6,4,-3:3
-5,4,-3:3
-4,4,-3:3
-3,4,-3:17
-2,4,-3:3
-1,4,-3:3
0,4,-3:3
1,4,-3:3
2,4,-3:3
3,4,-3:3
4,4,-3:3
5,4,-3:3
-6,5,-3:3
-4,5,-3:3
-3,5,-3:17
-2,5,-3:3
-1,5,-3:3
0,5,-3:3
1,5,-3:3
2,5,-3:3
3,5,-3:3
4,5,-3:17
5,5,-3:17
-7,6,-3:17
-6,6,-3:17
-4,6,-3:3
-3,6,-3:3
-2,6,-3:3
2,6,-3:3
3,6,-3:3
4,6,-3:17
5,6,-3:17
3,7,-3:17
4,7,-3:17
-2,-9,-2:3
-1,-9,-2:3
0,-9,-2:3
-2,-8,-2:3
-1,-8,-2:3
0,-8,-2:3
1,-8,-2:17
2,-8,-2:17
5,-8,-2:17
6,-8,-2:3
-2,-7,-2:3
-1,-7,-2:3
0,-7,-2:3
1,-7,-2:17
2,-7,-2:17
3,-7,-2:3
4,-7,-2:17
5,-7,-2:17
6,-7,-2:17
7,-7,-2:17
-5,-6,-2:3
-4,-6,-2:3
-3,-6,-2:3
-2,-6,-2:3
-1,-6,-2:17
0,-6,-2:3
1,-6,-2:3
2,-6,-2:3
3,-6,-2:3
4,-6,-2:17
5,-6,-2:17
6,-6,-2:3
7,-6,-2:17
-6,-5,-2:3
-5,-5,-2:3
-4,-5,-2:3
-3,-5,-2:3
-2,-5,-2:3
-1,-5,-2:3
0,-5,-2:3
1,-5,-2:3
2,-5,-2:3
3,-5,-2:3
4,-5,-2:17
5,-5,-2:17
6,-5,-2:3
7,-5,-2:3
-7,-4,-2:3
-6,-4,-2:17
-5,-4,-2:17
-4,-4,-2:3
-3,-4,-2:3
-2,-4,-2:3
-1,-4,-2:3
0,-4,-2:3
1,-4,-2:3
2,-4,-2:3
3,-4,-2:3
4,-4,-2:17
5,-4,-2:17
6,-4,-2:3
7,-4,-2:3
-7,-3,-2:3
-6,-3,-2:17
-5,-3,-2:17
-4,-3,-2:3
-3,-3,-2:3
-2,-3,-2:3
-1,-3,-2:3
0,-3,-2:3
1,-3,-2:3
2,-3,-2:3
3,-3,-2:17
4,-3,-2:17
5,-3,-2:3
-7,-2,-2:3
-6,-2,-2:3
-5,-2,-2:17
-4,-2,-2:17
-3,-2,-2:17
-2,-2,-2:3
-1,-2,-2:3
0,-2,-2:3
1,-2,-2:3
2,-2,-2:17
3,-2,-2:17
4,-2,-2:3
5,-2,-2:3
-7,-1,-2:3
-6,-1,-2:3
-5,-1,-2:3
-4,-1,-2:3
-3,-1,-2:17
-2,-1,-2:3
-1,-1,-2:3
0,-1,-2:3
1,-1,-2:3
2,-1,-2:17
3,-1,-2:3
4,-1,-2:3
5,-1,-2:17
6,-1,-2:17
-7,0,-2:3
-6,0,-2:3
-5,0,-2:3
-4,0,-2:3
-3,0,-2:3
-2,0,-2:3
-1,0,-2:3
0,0,-2:3
1,0,-2:3
2,0,-2:3
3,0,-2:3
4,0,-2:3
5,0,-2:3
6,0,-2:3
-8,1,-2:3
-7,1,-2:3
-6,1,-2:3
-5,1,-2:3
-4,1,-2:3
-3,1,-2:3
-2,1,-2:3
-1,1,-2:3
0,1,-2:3
1,1,-2:3
2,1,-2:3
3,1,-2:3
4,1,-2:3
5,1,-2:3
-8,2,-2:3
-7,2,-2:17
-6,2,-2:17
-5,2,-2:3
-4,2,-2:3
-3,2,-2:3
-2,2,-2:17
-1,2,-2:17
0,2,-2:3
1,2,-2:3
2,2,-2:3
3,2,-2:3
4,2,-2:3
5,2,-2:17
6,2,-2:17
-8,3,-2:3
-7,3,-2:3
-6,3,-2:17
-5,3,-2:3
-4,3,-2:3
-3,3,-2:17
-2,3,-2:17
-1,3,-2:3
0,3,-2:3
1,3,-2:3
2,3,-2:3
3,3,-2:3
4,3,-2:3
5,3,-2:17
-8,4,-2:3
-7,4,-2:3
-6,4,-2:3
-5,4,-2:3
-4,4,-2:17
-3,4,-2:17
-2,4,-2:3
-1,4,-2:3
0,4,-2:3
1,4,-2:3
2,4,-2:17
3,4,-2:17
4,4,-2:3
5,4,-2:3
-7,5,-2:17
-6,5,-2:17
-5,5,-2:3
-4,5,-2:3
-3,5,-2:3
-2,5,-2:3
-1,5,-2:3
0,5,-2:3
1,5,-2:3
2,5,-2:3
3,5,-2:17
4,5,-2:17
5,5,-2:3
-7,6,-2:17
-6,6,-2:17
-5,6,-2:3
-4,6,-2:3
-3,6,-2:3
-2,6,-2:3
-1,6,-2:3
0,6,-2:3
1,6,-2:3
2,6,-2:3
3,6,-2:3
4,6,-2:17
5,6,-2:17
-5,7,-2:3
-4,7,-2:3
-3,7,-2:3
-2,7,-2:3
1,7,-2:3
2,7,-2:3
3,7,-2:3
4,7,-2:17
-1,-10,-1:2
0,-10,-1:2
-2,-9,-1:2
-1,-9,-1:2
0,-9,-1:2
1,-9,-1:2
2,-9,-1:2
-3,-8,-1:2
-2,-8,-1:2
-1,-8,-1:2
0,-8,-1:2
1,-8,-1:17
2,-8,-1:17
3,-8,-1:2
4,-8,-1:2
5,-8,-1:2
6,-8,-1:2
-4,-7,-1:2
-3,-7,-1:2
-2,-7,-1:2
-1,-7,-1:2
0,-7,-1:2
1,-7,-1:2
2,-7,-1:17
3,-7,-1:2
4,-7,-1:17
5,-7,-1:17
6,-7,-1:17
7,-7,-1:2
-6,-6,-1:2
-5,-6,-1:2
-4,-6,-1:2
-3,-6,-1:2
-2,-6,-1:2
-1,-6,-1:17
0,-6,-1:2
1,-6,-1:2
2,-6,-1:2
3,-6,-1:17
4,-6,-1:17
5,-6,-1:2
6,-6,-1:2
7,-6,-1:2
8,-6,-1:2
-7,-5,-1:2
-6,-5,-1:2
-5,-5,-1:2
-4,-5,-1:2
-3,-5,-1:2
-2,-5,-1:2
-1,-5,-1:17
0,-5,-1:17
1,-5,-1:2
2,-5,-1:2
3,-5,-1:2
4,-5,-1:17
5,-5,-1:17
6,-5,-1:2
7,-5,-1:2
8,-5,-1:2
-8,-4,-1:2
-7,-4,-1:2
-6,-4,-1:17
-5,-4,-1:17
-4,-4,-1:2
-3,-4,-1:2
-2,-4,-1:2
-1,-4,-1:3
0,-4,-1:3
1,-4,-1:2
2,-4,-1:3
3,-4,-1:2
4,-4,-1:17
5,-4,-1:17
6,-4,-1:2
7,-4,-1:2
8,-4,-1:2
-8,-3,-1:2
-7,-3,-1:2
-6,-3,-1:2
-5,-3,-1:17
-4,-3,-1:17
-3,-3,-1:2
-2,-3,-1:2
-1,-3,-1:2
0,-3,-1:3
1,-3,-1:2
2,-3,-1:2
3,-3,-1:17
4,-3,-1:17
5,-3,-1:2
6,-3,-1:2
7,-3,-1:2
-8,-2,-1:2
-7,-2,-1:2
-6,-2,-1:2
-5,-2,-1:17
-4,-2,-1:17
-3,-2,-1:17
-2,-2,-1:3
-1,-2,-1:2
0,-2,-1:2
1,-2,-1:2
2,-2,-1:2
3,-2,-1:17
4,-2,-1:17
5,-2,-1:17
6,-2,-1:2
7,-2,-1:2
-9,-1,-1:2
-8,-1,-1:2
-7,-1,-1:2
-6,-1,-1:2
-5,-1,-1:2
-4,-1,-1:2
-3,-1,-1:17
-2,-1,-1:17
-1,-1,-1:2
0,-1,-1:3
1,-1,-1:17
2,-1,-1:17
3,-1,-1:17
4,-1,-1:2
5,-1,-1:17
6,-1,-1:17
7,-1,-1:2
-9,0,-1:2
-8,0,-1:2
-7,0,-1:2
-6,0,-1:2
-5,0,-1:2
-4,0,-1:2
-3,0,-1:17
-2,0,-1:17
-1,0,-1:2
0,0,-1:2
1,0,-1:17
2,0,-1:17
3,0,-1:2
4,0,-1:2
5,0,-1:2
6,0,-1:2
-9,1,-1:2
-8,1,-1:2
-7,1,-1:2
-6,1,-1:2
-5,1,-1:2
-4,1,-1:2
-3,1,-1:3
-2,1,-1:3
-1,1,-1:17
0,1,-1:17
1,1,-1:2
2,1,-1:2
3,1,-1:2
4,1,-1:2
5,1,-1:2
6,1,-1:2
-10,2,-1:2
-9,2,-1:2
-8,2,-1:2
-7,2,-1:2
-6,2,-1:17
-5,2,-1:2
-4,2,-1:2
-3,2,-1:2
-2,2,-1:17
-1,2,-1:17
0,2,-1:17
1,2,-1:17
2,2,-1:2
3,2,-1:2
4,2,-1:2
5,2,-1:17
6,2,-1:2
7,2,-1:2
-9,3,-1:2
-8,3,-1:2
-7,3,-1:2
-6,3,-1:17
-5,3,-1:2
-4,3,-1:2
-3,3,-1:17
-2,3,-1:17
-1,3,-1:17
0,3,-1:3
1,3,-1:3
2,3,-1:17
3,3,-1:2
4,3,-1:2
5,3,-1:17
6,3,-1:2
7,3,-1:2
-9,4,-1:2
-8,4,-1:2
-7,4,-1:2
-6,4,-1:17
-5,4,-1:2
-4,4,-1:17
-3,4,-1:17
-2,4,-1:17
-1,4,-1:2
0,4,-1:2
1,4,-1:2
2,4,-1:17
3,4,-1:17
4,4,-1:17
5,4,-1:2
6,4,-1:2
-8,5,-1:2
-7,5,-1:2
-6,5,-1:17
-5,5,-1:17
-4,5,-1:17
-3,5,-1:2
-2,5,-1:2
-1,5,-1:2
0,5,-1:2
1,5,-1:2
2,5,-1:2
3,5,-1:17
4,5,-1:17
5,5,-1:2
6,5,-1:2
-7,6,-1:17
-6,6,-1:17
-5,6,-1:17
-4,6,-1:2
-3,6,-1:2
-2,6,-1:2
-1,6,-1:2
0,6,-1:2
1,6,-1:2
2,6,-1:2
3,6,-1:2
4,6,-1:17
5,6,-1:17
-6,7,-1:2
-5,7,-1:2
-4,7,-1:2
-3,7,-1:2
-2,7,-1:2
-1,7,-1:2
0,7,-1:2
1,7,-1:2
2,7,-1:2
3,7,-1:2
4,7,-1:2
5,7,-1:2
-6,8,-1:2
-5,8,-1:2
-4,8,-1:2
-3,8,-1:2
-2,8,-1:2
-5,9,-1:2
-4,9,-1:2
-3,9,-1:2
0,-3,1:17
4,-3,1:17
-4,-2,1:17
-3,-2,1:17
0,-2,1:17
3,-2,1:17
4,-2,1:17
-1,-1,1:17
0,-1,1:17
1,-1,1:17
2,-1,1:17
3,-1,1:17
-2,0,1:17
-1,0,1:17
-3,1,1:17
-2,1,1:17
-1,1,1:17
0,1,1:17
1,1,1:17
-3,2,1:17
-1,2,1:17
1,2,1:17
-2,3,1:17
-1,3,1:17
0,3,1:17
2,3,1:17
-4,4,1:17
-2,4,1:17
2,4,1:17
3,4,1:17
-5,5,1:17
-4,5,1:17
-4,10,1:106.4
-5,10,1:106.4
-3,9,1:106.2
-6,9,1:106.8
3,8,1:106.4
-2,8,1:106.2
-7,8,1:106.8
5,7,1:106.4
4,7,1:106.4
2,7,1:106.4
-1,7,1:106.4
-6,7,1:106.8
6,6,1:106.2
1,6,1:106.4
0,6,1:106.4
-6,6,1:106.8
7,5,1:106.2
-7,5,1:106.4
7,4,1:106.2
6,4,1:106.4
-8,4,1:106
8,3,1:106.2
7,3,1:106.4
5,3,1:106.4
-9,3,1:106.4
9,2,1:106.2
8,2,1:106.2
4,2,1:106.8
-4,2,1:106.8
-10,2,1:106.8
8,1,1:106
3,1,1:106.8
-9,1,1:106.8
8,0,1:106.4
7,0,1:106.2
-8,0,1:106.8
9,-1,1:106.2
-9,-1,1:106.8
10,-2,1:106.2
-8,-2,1:106.8
9,-3,1:106.2
-7,-3,1:106.8
8,-4,1:106.2
6,-4,1:106.1
-1,-4,1:106.8
-2,-4,1:106.1
-8,-4,1:106.8
7,-5,1:106.1
5,-5,1:106.1
4,-5,1:106.1
-1,-5,1:106.8
-3,-5,1:106.1
-7,-5,1:106.8
3,-6,1:106.1
-2,-6,1:106.8
-4,-6,1:106.1
-5,-6,1:106.1
-6,-6,1:106.1
3,-7,1:106.2
-2,-7,1:106.8
2,-8,1:106.2
-3,-8,1:106.8
-2,-9,1:106.8
0,-10,1:106.1
-1,-10,1:106.1
-3,-2,2:17
-3,-1,2:17
-2,-1,2:17
-1,-1,2:17
1,-1,2:17
-2,0,2:17
-1,0,2:17
0,0,2:17
1,0,2:17
-2,1,2:17
-1,1,2:17
0,1,2:17
1,1,2:17
-2,2,2:17
-1,2,2:17
-4,10,2:106.4
-5,10,2:106.4
-3,9,2:106.2
-6,9,2:106.8
3,8,2:106.4
-2,8,2:106.2
-7,8,2:106.8
5,7,2:106.4
4,7,2:106.4
2,7,2:106.4
-1,7,2:106.4
-6,7,2:106.8
6,6,2:106.2
1,6,2:106.4
0,6,2:106.4
-6,6,2:106.8
7,5,2:106.2
-7,5,2:106.4
7,4,2:106.2
6,4,2:106.4
-8,4,2:106
8,3,2:106.2
7,3,2:106.4
5,3,2:106.4
-9,3,2:106.4
9,2,2:106.2
8,2,2:106.2
4,2,2:106.8
-4,2,2:106.8
-10,2,2:106.8
8,1,2:106
3,1,2:106.8
-9,1,2:106.8
8,0,2:106.4
7,0,2:106
-8,0,2:106.8
9,-1,2:106.2
-9,-1,2:106.8
10,-2,2:106.2
-8,-2,2:106.8
9,-3,2:106.2
0,-3,2:106.8
-7,-3,2:106.8
8,-4,2:106.2
6,-4,2:106.1
-1,-4,2:106.8
-2,-4,2:106.1
-8,-4,2:106.8
7,-5,2:106.1
5,-5,2:106.1
4,-5,2:106.1
-1,-5,2:106.8
-3,-5,2:106.1
-7,-5,2:106.8
3,-6,2:106.1
-2,-6,2:106.8
-4,-6,2:106.1
-5,-6,2:106.1
-6,-6,2:106.1
3,-7,2:106.2
-2,-7,2:106.8
2,-8,2:106.2
-3,-8,2:106.8
-2,-9,2:106.8
0,-10,2:106.1
-1,-10,2:106.1
-3,-1,3:17
-2,-1,3:17
-1,-1,3:17
1,-1,3:17
-3,0,3:17
-2,0,3:17
1,0,3:17
2,0,3:17
-2,1,3:17
-1,1,3:17
0,1,3:17
1,1,3:17
-2,2,3:17
-1,2,3:17
0,2,3:17
-2,3,3:17
-1,3,3:17
-4,10,3:106.4
-5,10,3:106.4
-3,9,3:106.2
-6,9,3:106.8
3,8,3:106.4
-2,8,3:106.2
-7,8,3:106.8
5,7,3:106.4
4,7,3:106.4
2,7,3:106.4
-1,7,3:106.4
-6,7,3:106.8
6,6,3:106.2
1,6,3:106.4
0,6,3:106.4
-6,6,3:106.8
7,5,3:106.2
-7,5,3:106.4
7,4,3:106.2
6,4,3:106.4
-8,4,3:106
8,3,3:106.2
7,3,3:106.4
5,3,3:106.4
-9,3,3:106.4
9,2,3:106.2
8,2,3:106.2
4,2,3:106.8
-4,2,3:106.8
-10,2,3:106.8
8,1,3:106
3,1,3:106.8
-9,1,3:106.8
8,0,3:106.4
7,0,3:106
-8,0,3:106.8
9,-1,3:106.2
-9,-1,3:106.8
10,-2,3:106.2
-8,-2,3:106.8
9,-3,3:106.2
0,-3,3:106.8
-7,-3,3:106.8
8,-4,3:106.2
6,-4,3:106.1
-1,-4,3:106.8
-2,-4,3:106.1
-8,-4,3:106.8
7,-5,3:106.1
5,-5,3:106.1
4,-5,3:106.1
-1,-5,3:106.8
-3,-5,3:106.1
-7,-5,3:106.8
3,-6,3:106.1
-2,-6,3:106.8
-4,-6,3:106.1
-5,-6,3:106.1
-6,-6,3:106.1
3,-7,3:106.2
-2,-7,3:106.8
2,-8,3:106.2
-3,-8,3:106.8
-2,-9,3:106.8
0,-10,3:106.1
-1,-10,3:106.1
7,-4,4:18
6,-3,4:18
8,-3,4:18
1,-2,4:17
-3,-1,4:17
-2,-1,4:17
1,-1,4:17
2,-1,4:17
-3,0,4:17
-2,0,4:17
1,0,4:17
2,0,4:17
-8,1,4:18
-1,1,4:17
1,1,4:17
-9,2,4:18
-2,2,4:17
-1,2,4:17
0,2,4:17
5,2,4:18
7,2,4:18
-8,3,4:18
-2,3,4:17
-1,3,4:17
0,3,4:17
6,3,4:18
-4,10,4:106.4
-5,10,4:106.4
-3,9,4:106.2
-6,9,4:106.8
3,8,4:106.4
-2,8,4:106.2
-7,8,4:106.8
5,7,4:106.4
4,7,4:106.4
2,7,4:106.4
-1,7,4:106.4
-6,7,4:106.8
6,6,4:106.2
1,6,4:106.4
0,6,4:106.4
-6,6,4:106.8
7,5,4:106.2
-7,5,4:106.4
7,4,4:106.2
6,4,4:106.4
-8,4,4:106
8,3,4:106.2
7,3,4:106.4
5,3,4:106.4
-9,3,4:106.4
9,2,4:106.2
8,2,4:106.2
4,2,4:106.8
-4,2,4:106.8
-10,2,4:106.8
8,1,4:106
3,1,4:106.8
-9,1,4:106.8
8,0,4:106.4
7,0,4:106
-8,0,4:106.8
9,-1,4:106.2
-9,-1,4:106.8
10,-2,4:106.2
-1,-2,4:106.8
-8,-2,4:106.8
9,-3,4:106.2
0,-3,4:106.8
-7,-3,4:106.8
8,-4,4:106.2
6,-4,4:106.1
-1,-4,4:106.8
-2,-4,4:106.1
-8,-4,4:106.8
7,-5,4:106.1
5,-5,4:106.1
4,-5,4:106.1
-1,-5,4:106.8
-3,-5,4:106.1
-7,-5,4:106.8
3,-6,4:106.1
-2,-6,4:106.8
-4,-6,4:106.1
-5,-6,4:106.1
-6,-6,4:106.1
3,-7,4:106.2
-2,-7,4:106.8
2,-8,4:106.2
-3,-8,4:106.8
1,-9,4:106.1
-2,-9,4:106.8
0,-10,4:106.1
-1,-10,4:106.1
7,-4,5:18
6,-3,5:18
7,-3,5:17
8,-3,5:18
-7,-2,5:18
2,-2,5:17
9,-2,5:18
-8,-1,5:18
-4,-1,5:17
-3,-1,5:17
-2,-1,5:17
1,-1,5:17
2,-1,5:17
3,-1,5:17
7,-1,5:18
8,-1,5:18
-7,0,5:18
-3,0,5:17
-2,0,5:17
0,0,5:17
1,0,5:17
2,0,5:17
3,0,5:17
6,0,5:18
-8,1,5:18
-4,1,5:18
-3,1,5:17
7,1,5:18
-9,2,5:18
-8,2,5:17
-3,2,5:17
-2,2,5:17
-1,2,5:17
0,2,5:17
5,2,5:18
6,2,5:17
7,2,5:18
-8,3,5:18
-2,3,5:17
-1,3,5:17
0,3,5:17
6,3,5:18
-1,5,5:18
-4,10,5:106.4
-5,10,5:106.4
-3,9,5:106.2
-6,9,5:106.8
3,8,5:106.4
-2,8,5:106.2
-7,8,5:106.8
5,7,5:106.4
4,7,5:106.4
2,7,5:106.4
-1,7,5:106.4
-6,7,5:106.8
6,6,5:106.2
1,6,5:106.4
0,6,5:106.4
-6,6,5:106.8
7,5,5:106.2
-7,5,5:106.4
7,4,5:106.2
6,4,5:106.4
-8,4,5:106
8,3,5:106.2
7,3,5:106.4
5,3,5:106.4
-9,3,5:106.4
9,2,5:106.2
8,2,5:106.2
4,2,5:106.8
-4,2,5:106.8
-10,2,5:106.8
8,1,5:106
3,1,5:106.8
-9,1,5:106.8
8,0,5:106.4
7,0,5:106
-8,0,5:106.8
9,-1,5:106.2
-9,-1,5:106.8
10,-2,5:106.2
-1,-2,5:106.8
-8,-2,5:106.8
9,-3,5:106.2
0,-3,5:106.8
-7,-3,5:106.8
8,-4,5:106.2
6,-4,5:106.1
-1,-4,5:106.8
-2,-4,5:106.1
-8,-4,5:106.8
7,-5,5:106.1
5,-5,5:106.1
4,-5,5:106.1
-1,-5,5:106.8
-3,-5,5:106.1
-7,-5,5:106.8
3,-6,5:106.1
-2,-6,5:106.8
-4,-6,5:106.1
-5,-6,5:106.1
-6,-6,5:106.1
3,-7,5:106.2
-2,-7,5:106.8
2,-8,5:106.2
-3,-8,5:106.8
1,-9,5:106.1
-2,-9,5:106.8
0,-10,5:106.1
-1,-10,5:106.1
7,-4,6:18
1,-3,6:18
4,-3,6:18
6,-3,6:18
7,-3,6:17
8,-3,6:18
-7,-2,6:18
2,-2,6:17
3,-2,6:17
7,-2,6:17
8,-2,6:17
9,-2,6:18
-8,-1,6:18
-7,-1,6:17
-4,-1,6:17
-3,-1,6:17
1,-1,6:18
2,-1,6:17
3,-1,6:17
4,-1,6:17
7,-1,6:18
8,-1,6:18
-7,0,6:18
-6,0,6:18
-4,0,6:17
-3,0,6:17
-2,0,6:17
0,0,6:17
6,0,6:18
-8,1,6:18
-7,1,6:18
-5,1,6:18
-4,1,6:18
-3,1,6:17
0,1,6:17
4,1,6:18
6,1,6:17
7,1,6:18
-9,2,6:18
-8,2,6:17
-6,2,6:18
-3,2,6:18
-2,2,6:17
5,2,6:18
6,2,6:17
7,2,6:18
-8,3,6:18
-4,3,6:18
-2,3,6:17
-1,3,6:17
0,3,6:17
6,3,6:18
-7,4,6:18
-2,4,6:17
-1,4,6:17
-1,5,6:18
0,5,6:18
1,5,6:18
-5,7,6:18
-6,8,6:18
-3,8,6:18
-5,9,6:18
-4,9,6:18
-4,10,6:106.4
-5,10,6:106.4
-3,9,6:106.2
-6,9,6:106.8
3,8,6:106.4
-2,8,6:106.2
-7,8,6:106.8
5,7,6:106.4
4,7,6:106.4
2,7,6:106.4
-1,7,6:106.4
-6,7,6:106.8
6,6,6:106.2
1,6,6:106.4
0,6,6:106.4
-6,6,6:106.8
7,5,6:106.2
-7,5,6:106.4
7,4,6:106.2
6,4,6:106.4
-8,4,6:106
8,3,6:106.2
7,3,6:106.4
5,3,6:106.4
-9,3,6:106.4
9,2,6:106.2
8,2,6:106.2
4,2,6:106.8
-4,2,6:106.8
-10,2,6:106.8
8,1,6:106
3,1,6:106.8
-9,1,6:106.8
8,0,6:106.4
7,0,6:106
2,0,6:106
-8,0,6:106.8
9,-1,6:106.2
-9,-1,6:106.8
10,-2,6:106.2
-1,-2,6:106.8
-8,-2,6:106.8
9,-3,6:106.2
0,-3,6:106.8
-7,-3,6:106.8
8,-4,6:106.2
6,-4,6:106.1
-1,-4,6:106.8
-2,-4,6:106.1
-8,-4,6:106.8
7,-5,6:106.1
5,-5,6:106.1
4,-5,6:106.1
-1,-5,6:106.8
-3,-5,6:106.1
-7,-5,6:106.8
3,-6,6:106.1
-2,-6,6:106.8
-4,-6,6:106.1
-5,-6,6:106.1
-6,-6,6:106.1
3,-7,6:106.2
-2,-7,6:106.8
2,-8,6:106.2
-3,-8,6:106.8
1,-9,6:106.1
-2,-9,6:106.8
0,-10,6:106.1
-1,-10,6:106.1
-6,-5,7:18
-7,-4,7:18
5,-4,7:18
7,-4,7:18
-6,-3,7:18
1,-3,7:18
2,-3,7:17
4,-3,7:18
6,-3,7:18
7,-3,7:17
8,-3,7:18
-7,-2,7:18
2,-2,7:17
3,-2,7:17
4,-2,7:17
6,-2,7:17
7,-2,7:17
8,-2,7:18
-8,-1,7:18
-7,-1,7:17
-6,-1,7:17
-5,-1,7:17
-4,-1,7:17
-3,-1,7:17
1,-1,7:18
2,-1,7:17
3,-1,7:17
4,-1,7:17
5,-1,7:17
6,-1,7:18
7,-1,7:18
-7,0,7:18
-6,0,7:18
-5,0,7:17
-4,0,7:17
-3,0,7:17
-2,0,7:17
-1,0,7:17
0,0,7:17
3,0,7:18
6,0,7:18
-8,1,7:18
-7,1,7:18
-5,1,7:18
-4,1,7:18
-3,1,7:17
-1,1,7:17
4,1,7:18
5,1,7:17
6,1,7:17
7,1,7:18
-9,2,7:18
-8,2,7:17
-7,2,7:17
-6,2,7:18
-3,2,7:18
-2,2,7:17
5,2,7:18
6,2,7:18
-8,3,7:18
-7,3,7:17
-6,3,7:17
-5,3,7:18
-4,3,7:18
-3,3,7:17
-2,3,7:17
-1,3,7:17
0,3,7:17
1,3,7:17
-7,4,7:18
-4,4,7:17
-3,4,7:17
-2,4,7:17
-1,4,7:17
0,4,7:17
1,4,7:17
-6,5,7:18
-2,5,7:17
-1,5,7:18
0,5,7:18
1,5,7:18
-5,6,7:18
-5,7,7:18
-6,8,7:18
-5,8,7:17
-4,8,7:17
-3,8,7:18
-5,9,7:18
-4,9,7:18
-4,10,7:106.4
-5,10,7:106.4
-3,9,7:106.2
-6,9,7:106.8
3,8,7:106.4
-2,8,7:106.2
-7,8,7:106.8
5,7,7:106.4
4,7,7:106.4
2,7,7:106.4
-1,7,7:106.4
-6,7,7:106.8
6,6,7:106.2
1,6,7:106.4
0,6,7:106.4
-6,6,7:106.8
7,5,7:106.2
-7,5,7:106.4
7,4,7:106.2
-8,4,7:106
8,3,7:106.2
5,3,7:106.4
-9,3,7:106.4
9,2,7:106.2
4,2,7:106.8
-4,2,7:106.8
-10,2,7:106.8
8,1,7:106
3,1,7:106.8
-9,1,7:106.8
7,0,7:106
2,0,7:106
-8,0,7:106.8
-9,-1,7:106.8
-1,-2,7:106.8
-8,-2,7:106.8
9,-3,7:106.2
0,-3,7:106.8
-7,-3,7:106.8
8,-4,7:106.2
6,-4,7:106.1
-1,-4,7:106.8
-2,-4,7:106.1
-8,-4,7:106.8
7,-5,7:106.1
5,-5,7:106.1
4,-5,7:106.1
-1,-5,7:106
-3,-5,7:106.1
-7,-5,7:106.8
3,-6,7:106.1
-2,-6,7:106.8
-4,-6,7:106.1
-5,-6,7:106.1
-6,-6,7:106.1
3,-7,7:106.2
-2,-7,7:106.8
2,-8,7:106.2
-3,-8,7:106.8
1,-9,7:106.1
-2,-9,7:106.8
0,-10,7:106.1
-1,-10,7:106.1
-1,-9,8:18
-2,-8,8:18
-1,-7,8:18
-6,-5,8:18
-5,-5,8:18
3,-5,8:18
-7,-4,8:18
-6,-4,8:17
-4,-4,8:18
4,-4,8:18
5,-4,8:18
-6,-3,8:18
-4,-3,8:18
1,-3,8:18
2,-3,8:17
4,-3,8:18
5,-3,8:17
6,-3,8:18
7,-3,8:18
-7,-2,8:18
-6,-2,8:17
-5,-2,8:17
-3,-2,8:18
0,-2,8:18
2,-2,8:17
3,-2,8:17
4,-2,8:17
5,-2,8:17
6,-2,8:17
7,-2,8:17
8,-2,8:18
-7,-1,8:18
-6,-1,8:18
-5,-1,8:17
-4,-1,8:17
-3,-1,8:18
1,-1,8:18
2,-1,8:17
3,-1,8:18
4,-1,8:17
5,-1,8:17
6,-1,8:18
7,-1,8:18
-5,0,8:18
-4,0,8:17
-3,0,8:17
-2,0,8:17
-1,0,8:17
3,0,8:18
4,0,8:17
5,0,8:17
6,0,8:18
-4,1,8:18
-1,1,8:17
4,1,8:18
5,1,8:17
6,1,8:17
7,1,8:18
-8,2,8:18
-7,2,8:18
-6,2,8:18
-3,2,8:18
-2,2,8:17
-1,2,8:17
5,2,8:18
6,2,8:18
-8,3,8:18
-7,3,8:17
-6,3,8:17
-5,3,8:18
-4,3,8:18
-3,3,8:17
-2,3,8:17
-1,3,8:17
0,3,8:17
1,3,8:17
-7,4,8:18
-6,4,8:17
-5,4,8:17
-4,4,8:17
-3,4,8:17
-2,4,8:17
-1,4,8:18
0,4,8:17
1,4,8:17
-6,5,8:18
-5,5,8:17
-4,5,8:17
-2,5,8:18
0,5,8:18
1,5,8:18
-5,6,8:18
-4,6,8:17
-1,6,8:18
-5,7,8:18
-4,7,8:17
-2,7,8:18
-6,8,8:18
-5,8,8:17
-4,8,8:17
-3,8,8:18
-5,9,8:18
-4,9,8:18
-4,10,8:106.4
-5,10,8:106.4
-3,9,8:106.2
-6,9,8:106.8
3,8,8:106.4
-2,8,8:106.2
-7,8,8:106.8
5,7,8:106.4
4,7,8:106.4
2,7,8:106.4
-1,7,8:106.4
-6,7,8:106.8
6,6,8:106.2
1,6,8:106.4
0,6,8:106.4
-6,6,8:106.8
7,5,8:106.2
-7,5,8:106.4
7,4,8:106.2
-8,4,8:106
8,3,8:106.2
5,3,8:106.4
9,2,8:106.2
4,2,8:106.8
-4,2,8:106.8
8,1,8:106
3,1,8:106.8
-5,1,8:106.8
7,0,8:106
2,0,8:106
0,0,8:106.4
-6,0,8:106.8
-1,-2,8:106.8
-8,-2,8:106.8
0,-3,8:106.8
-7,-3,8:106.8
6,-4,8:106.1
-1,-4,8:106.8
-2,-4,8:106.1
-8,-4,8:106.8
5,-5,8:106.1
4,-5,8:106.1
-1,-5,8:106
-3,-5,8:106.1
-7,-5,8:106.8
3,-6,8:106.1
-2,-6,8:106.8
-4,-6,8:106.1
-5,-6,8:106.1
-6,-6,8:106.1
3,-7,8:106.2
-2,-7,8:106.8
2,-8,8:106.2
-3,-8,8:106.8
1,-9,8:106.1
-2,-9,8:106.8
0,-10,8:106.1
-1,-10,8:106.1
-1,-9,9:18
0,-9,9:18
-2,-8,9:18
-1,-8,9:17
1,-8,9:18
-1,-7,9:18
2,-6,9:18
-6,-5,9:18
-5,-5,9:18
0,-5,9:18
3,-5,9:18
-7,-4,9:18
-6,-4,9:17
-5,-4,9:17
-4,-4,9:18
0,-4,9:18
2,-4,9:17
3,-4,9:17
4,-4,9:18
-6,-3,9:18
-5,-3,9:17
-4,-3,9:18
1,-3,9:18
2,-3,9:17
3,-3,9:17
4,-3,9:18
5,-3,9:18
6,-3,9:18
-6,-2,9:18
-5,-2,9:17
-4,-2,9:17
-3,-2,9:18
0,-2,9:18
1,-2,9:17
2,-2,9:17
3,-2,9:18
4,-2,9:18
5,-2,9:17
6,-2,9:17
7,-2,9:18
-5,-1,9:18
-4,-1,9:17
-3,-1,9:18
-2,-1,9:17
-1,-1,9:17
1,-1,9:18
2,-1,9:18
4,-1,9:18
5,-1,9:17
6,-1,9:18
-4,0,9:18
-2,0,9:17
-1,0,9:17
4,0,9:18
5,0,9:18
5,1,9:18
6,1,9:18
0,2,9:17
1,2,9:17
-7,3,9:18
-6,3,9:18
-5,3,9:18
-4,3,9:18
-3,3,9:18
-2,3,9:17
-1,3,9:18
0,3,9:17
1,3,9:17
2,3,9:17
-7,4,9:18
-6,4,9:17
-5,4,9:17
-4,4,9:17
-3,4,9:17
-2,4,9:17
-1,4,9:18
0,4,9:18
1,4,9:17
-6,5,9:18
-5,5,9:17
-4,5,9:17
-3,5,9:17
-2,5,9:18
1,5,9:18
-5,6,9:18
-4,6,9:17
-3,6,9:17
-2,6,9:17
-1,6,9:18
2,6,9:18
4,6,9:18
-4,7,9:18
-3,7,9:17
-2,7,9:18
3,7,9:18
-5,8,9:18
-4,8,9:18
-3,8,9:18
3,8,9:106.4
-2,8,9:106.2
5,7,9:106.4
4,7,9:106.4
2,7,9:106.4
-1,7,9:106.4
6,6,9:106.2
1,6,9:106.4
-6,6,9:106.8
7,5,9:106.2
-7,5,9:106.4
7,4,9:106.2
-8,4,9:106.8
8,3,9:106.2
9,2,9:106.2
-4,2,9:106.8
8,1,9:106.1
-5,1,9:106.8
7,0,9:106.1
6,0,9:106.1
3,0,9:106.1
2,0,9:106.4
0,0,9:106.4
-6,0,9:106.8
-6,-1,9:106.8
-1,-2,9:106.8
0,-3,9:106.8
-7,-3,9:106.8
6,-4,9:106.1
-1,-4,9:106.8
-2,-4,9:106.1
-8,-4,9:106.8
4,-5,9:106.1
-1,-5,9:106
-3,-5,9:106.1
-7,-5,9:106.8
3,-6,9:106.1
-2,-6,9:106.8
-4,-6,9:106.1
-5,-6,9:106.1
-6,-6,9:106.1
3,-7,9:106.2
-2,-7,9:106.8
2,-8,9:106.2
-3,-8,9:106.8
1,-9,9:106.1
-2,-9,9:106.8
0,-10,9:106.1
-1,-10,9:106.1
-1,-9,10:18
0,-9,10:18
-2,-8,10:18
-1,-8,10:17
0,-8,10:17
1,-8,10:18
-1,-7,10:18
0,-7,10:17
2,-7,10:18
-1,-6,10:18
2,-6,10:18
0,-5,10:18
1,-5,10:17
2,-5,10:17
3,-5,10:18
-6,-4,10:18
-5,-4,10:18
0,-4,10:18
1,-4,10:17
2,-4,10:17
3,-4,10:17
4,-4,10:18
-5,-3,10:18
1,-3,10:18
2,-3,10:17
3,-3,10:17
4,-3,10:18
-5,-2,10:18
-4,-2,10:18
1,-2,10:18
2,-2,10:18
5,-2,10:18
6,-2,10:18
-4,-1,10:18
-2,-1,10:17
5,-1,10:18
-2,0,10:17
-1,0,10:17
-3,1,10:18
1,1,10:17
3,1,10:18
0,2,10:18
1,2,10:17
2,2,10:17
-2,3,10:18
0,3,10:18
1,3,10:17
2,3,10:17
-6,4,10:18
-5,4,10:18
-4,4,10:18
-3,4,10:18
-2,4,10:17
-1,4,10:18
1,4,10:17
2,4,10:17
-5,5,10:18
-4,5,10:18
-3,5,10:18
-2,5,10:18
1,5,10:18
4,5,10:18
-4,6,10:18
-3,6,10:17
-2,6,10:18
2,6,10:18
3,6,10:17
4,6,10:18
-3,7,10:18
3,7,10:18
3,8,10:106.4
5,7,10:106.4
4,7,10:106.4
2,7,10:106.4
6,6,10:106.2
1,6,10:106.4
7,5,10:106.2
7,4,10:106.2
8,3,10:106.2
-3,3,10:106.8
9,2,10:106.2
-4,2,10:106.8
8,1,10:106.1
-5,1,10:106.8
7,0,10:106.1
6,0,10:106.1
3,0,10:106.1
0,0,10:106.4
-6,0,10:106.8
4,-1,10:106.1
2,-1,10:106.1
1,-1,10:106.1
-6,-1,10:106.8
-6,-2,10:106.4
0,-3,10:106.8
-7,-3,10:106.8
-1,-4,10:106.8
-2,-4,10:106.1
4,-5,10:106.1
-1,-5,10:106
-3,-5,10:106.1
-5,-5,10:106.1
3,-6,10:106.1
-2,-6,10:106.8
-4,-6,10:106.1
3,-7,10:106.2
-2,-7,10:106.8
2,-8,10:106.2
-3,-8,10:106.8
1,-9,10:106.1
-2,-9,10:106.8
0,-10,10:106.1
-1,-10,10:106.1
0,-9,11:18
-1,-8,11:18
0,-8,11:17
1,-8,11:18
-1,-7,11:18
0,-7,11:17
1,-7,11:17
2,-7,11:18
-1,-6,11:18
0,-6,11:17
1,-6,11:17
2,-6,11:18
0,-5,11:18
1,-5,11:17
2,-5,11:17
1,-4,11:18
2,-4,11:17
3,-4,11:18
2,-3,11:18
3,-3,11:18
-2,-1,11:17
-1,-1,11:17
-3,0,11:17
-2,0,11:17
-1,0,11:17
1,0,11:18
2,0,11:18
5,0,11:18
-3,1,11:18
-2,1,11:17
1,1,11:17
2,1,11:17
3,1,11:18
6,1,11:18
7,1,11:18
1,2,11:17
2,2,11:17
8,2,11:18
1,3,11:17
2,3,11:17
3,3,11:17
5,3,11:18
7,3,11:18
-2,4,11:18
1,4,11:18
2,4,11:17
1,5,11:18
2,5,11:17
3,5,11:17
4,5,11:18
-3,6,11:18
2,6,11:18
3,6,11:17
4,6,11:18
3,7,11:18
3,8,11:106.4
5,7,11:106.4
4,7,11:106.4
2,7,11:106.4
6,6,11:106.2
1,6,11:106.4
7,5,11:106.2
7,4,11:106.2
-1,4,11:106.4
8,3,11:106.2
0,3,11:106.2
-3,3,11:106.8
9,2,11:106.2
-4,2,11:106.8
8,1,11:106.1
-5,1,11:106.8
7,0,11:106.1
6,0,11:106.1
3,0,11:106.1
0,0,11:106.4
-6,0,11:106.8
5,-1,11:106.1
4,-1,11:106.1
2,-1,11:106.1
1,-1,11:106.1
-6,-1,11:106.8
2,-2,11:106.2
-6,-2,11:106.4
-7,-3,11:106.8
4,-4,11:106.2
-2,-4,11:106.1
-6,-4,11:106.1
-1,-5,11:106
-3,-5,11:106.1
-5,-5,11:106.1
3,-6,11:106.1
-2,-6,11:106.8
-4,-6,11:106.1
3,-7,11:106.2
-2,-7,11:106.8
2,-8,11:106.2
1,-9,11:106.1
0,-10,11:106.1
0,-8,12:18
-1,-7,12:18
0,-7,12:17
1,-7,12:18
-1,-6,12:18
0,-6,12:17
1,-6,12:17
2,-6,12:18
0,-5,12:18
1,-5,12:17
2,-5,12:18
1,-4,12:18
2,-4,12:18
-3,-3,12:18
-2,-3,12:18
-3,-2,12:18
-1,-2,12:17
-5,-1,12:18
-2,-1,12:17
-1,-1,12:17
-3,0,12:17
-2,0,12:17
-1,0,12:17
4,0,12:18
5,0,12:18
-3,1,12:18
-2,1,12:17
2,1,12:18
3,1,12:18
5,1,12:17
6,1,12:18
7,1,12:18
-3,2,12:18
0,2,12:18
1,2,12:17
2,2,12:17
3,2,12:17
7,2,12:17
8,2,12:18
-2,3,12:18
-1,3,12:18
1,3,12:18
2,3,12:17
3,3,12:17
4,3,12:17
5,3,12:18
6,3,12:18
7,3,12:18
2,4,12:18
6,4,12:18
2,5,12:18
3,5,12:18
4,5,12:18
6,5,12:18
3,6,12:18
5,6,12:18
5,7,12:106.4
6,6,12:106.2
7,5,12:106.2
7,4,12:106.2
-1,4,12:106.4
-2,4,12:106.4
8,3,12:106.2
0,3,12:106.2
-3,3,12:106.8
9,2,12:106.2
-4,2,12:106.8
8,1,12:106.1
-5,1,12:106.8
7,0,12:106.1
6,0,12:106.1
3,0,12:106.1
0,0,12:106.4
-6,0,12:106.8
5,-1,12:106.1
4,-1,12:106.1
-6,-1,12:106.8
2,-2,12:106.2
-6,-2,12:106.4
3,-3,12:106.2
-7,-3,12:106.8
4,-4,12:106.2
-2,-4,12:106.1
-6,-4,12:106.1
-1,-5,12:106
-3,-5,12:106.1
-5,-5,12:106.1
3,-6,12:106.1
-2,-6,12:106.8
-4,-6,12:106.1
2,-7,12:106.1
-2,-7,12:106.8
1,-8,12:106.1
0,-7,13:18
0,-6,13:18
1,-6,13:18
-4,-5,13:18
1,-5,13:18
-5,-4,13:18
-3,-4,13:18
-6,-3,13:18
-4,-3,13:17
-3,-3,13:18
-2,-3,13:18
-5,-2,13:18
-3,-2,13:18
-2,-2,13:17
-1,-2,13:17
-5,-1,13:18
-4,-1,13:17
-3,-1,13:17
-2,-1,13:17
-1,-1,13:17
-5,0,13:18
-3,0,13:17
-2,0,13:17
-1,0,13:17
4,0,13:18
5,0,13:18
-4,1,13:18
-3,1,13:18
-2,1,13:17
-1,1,13:17
2,1,13:18
3,1,13:18
4,1,13:17
5,1,13:17
6,1,13:18
7,1,13:18
-3,2,13:18
-2,2,13:17
-1,2,13:17
0,2,13:18
1,2,13:18
2,2,13:17
3,2,13:17
4,2,13:17
5,2,13:17
6,2,13:17
7,2,13:17
8,2,13:18
-2,3,13:18
-1,3,13:18
2,3,13:18
3,3,13:18
4,3,13:17
5,3,13:18
6,3,13:18
7,3,13:18
3,4,13:18
4,4,13:17
5,4,13:17
6,4,13:18
4,5,13:18
5,5,13:17
6,5,13:18
5,6,13:18
5,7,13:106.4
6,6,13:106.2
7,5,13:106.2
7,4,13:106.2
-1,4,13:106.4
-2,4,13:106.4
8,3,13:106.2
0,3,13:106.2
-3,3,13:106.8
9,2,13:106.2
-4,2,13:106.8
8,1,13:106.1
-5,1,13:106.8
7,0,13:106.1
6,0,13:106.1
3,0,13:106.1
0,0,13:106.4
-6,0,13:106.8
5,-1,13:106.1
4,-1,13:106.1
-6,-1,13:106.8
2,-2,13:106.2
-6,-2,13:106.4
3,-3,13:106.2
-7,-3,13:106.8
4,-4,13:106.2
-2,-4,13:106.1
-6,-4,13:106.1
-1,-5,13:106.1
-3,-5,13:106.1
-5,-5,13:106.1
3,-6,13:106.1
-1,-6,13:106.8
-4,-6,13:106.1
2,-7,13:106.1
1,-8,13:106.1
-4,-5,14:18
-5,-4,14:18
-4,-4,14:17
-3,-4,14:18
-6,-3,14:18
-5,-3,14:17
-4,-3,14:17
-3,-3,14:18
-2,-3,14:18
-5,-2,14:18
-4,-2,14:17
-3,-2,14:18
-2,-2,14:17
-1,-2,14:17
-5,-1,14:18
-4,-1,14:17
-3,-1,14:18
-2,-1,14:17
-1,-1,14:17
0,-1,14:18
-5,0,14:18
-4,0,14:17
-3,0,14:18
-2,0,14:17
-1,0,14:18
-4,1,14:18
-2,1,14:18
-1,1,14:18
4,1,14:18
5,1,14:18
6,1,14:18
-3,2,14:18
-2,2,14:17
-1,2,14:18
2,2,14:18
3,2,14:18
4,2,14:17
5,2,14:17
6,2,14:17
7,2,14:18
-2,3,14:18
4,3,14:18
5,3,14:18
6,3,14:18
4,4,14:18
5,4,14:18
5,5,14:18
-2,4,14:106.4
-3,3,14:106.8
-4,2,14:106.8
-5,1,14:106.8
6,0,14:106.1
0,0,14:106.4
-6,0,14:106.8
-6,-1,14:106.8
2,-2,14:106.2
-6,-2,14:106.4
3,-3,14:106.2
-7,-3,14:106.8
4,-4,14:106.2
-2,-4,14:106.1
-6,-4,14:106.1
4,-5,14:106.2
-1,-5,14:106.1
-3,-5,14:106.1
-5,-5,14:106.1
3,-6,14:106.1
-1,-6,14:106.8
-4,-6,14:106.1
2,-7,14:106.1
0,-7,14:106.8
1,-8,14:106.1
2,-6,15:18
0,-5,15:18
3,-5,15:18
-4,-4,15:18
-1,-4,15:18
-5,-3,15:18
-4,-3,15:18
-2,-3,15:18
-4,-2,15:18
-3,-2,15:18
-2,-2,15:17
-1,-2,15:17
1,-2,15:18
-4,-1,15:18
-3,-1,15:18
-2,-1,15:17
-1,-1,15:17
0,-1,15:18
-4,0,15:18
-2,0,15:18
-1,0,15:18
-2,2,15:18
4,2,15:18
5,2,15:18
6,2,15:18
0,0,15:106.4
2,-2,15:106.2
3,-3,15:106.2
-3,-3,15:106.8
4,-4,15:106.2
-2,-4,15:106.1
4,-5,15:106.2
-1,-5,15:106.1
3,-6,15:106.1
-1,-6,15:106.8
2,-7,15:106.1
0,-7,15:106.8
1,-8,15:106.1
1,-7,16:18
0,-6,16:18
2,-6,16:18
0,-5,16:18
2,-5,16:17
3,-5,16:18
-1,-4,16:18
-2,-3,16:18
-1,-3,16:17
0,-3,16:17
-3,-2,16:18
-2,-2,16:17
-1,-2,16:17
0,-2,16:17
1,-2,16:18
-3,-1,16:18
-2,-1,16:17
-1,-1,16:17
0,-1,16:18
-2,0,16:18
-1,0,16:18
0,0,16:106.4
2,-2,16:106.2
3,-3,16:106.2
-3,-3,16:106.8
4,-4,16:106.2
-2,-4,16:106.1
4,-5,16:106.2
-1,-5,16:106.1
3,-6,16:106.1
-1,-6,16:106.8
2,-7,16:106.1
0,-7,16:106.8
1,-8,16:106.1
1,-7,17:18
0,-6,17:18
1,-6,17:17
2,-6,17:18
0,-5,17:18
1,-5,17:17
2,-5,17:17
3,-5,17:18
-1,-4,17:18
3,-4,17:18
-2,-3,17:18
-1,-3,17:17
0,-3,17:17
2,-3,17:18
-2,-2,17:18
-1,-2,17:17
0,-2,17:17
1,-2,17:18
-2,-1,17:18
-1,-1,17:18
0,-1,17:18
0,0,17:106.4
2,-2,17:106.2
3,-3,17:106.2
-3,-3,17:106.8
4,-4,17:106.2
-2,-4,17:106.1
4,-5,17:106.2
-1,-5,17:106.1
3,-6,17:106.1
-1,-6,17:106.8
2,-7,17:106.1
0,-7,17:106.8
1,-8,17:106.1
1,-7,18:18
0,-6,18:18
1,-6,18:17
2,-6,18:18
0,-5,18:18
1,-5,18:17
2,-5,18:17
3,-5,18:18
-1,-4,18:18
0,-4,18:17
1,-4,18:17
2,-4,18:17
3,-4,18:18
-2,-3,18:18
-1,-3,18:17
0,-3,18:17
1,-3,18:17
2,-3,18:18
-1,-2,18:18
0,-2,18:17
1,-2,18:18
0,-1,18:18
0,0,18:106.4
2,-2,18:106.2
3,-3,18:106.2
-3,-3,18:106.8
4,-4,18:106.2
-2,-4,18:106.1
4,-5,18:106.2
-1,-5,18:106.1
3,-6,18:106.1
-1,-6,18:106.8
2,-7,18:106.1
0,-7,18:106.8
1,-8,18:106.1
1,-6,19:18
1,-5,19:18
2,-5,19:18
0,-4,19:18
1,-4,19:17
2,-4,19:18
-1,-3,19:18
0,-3,19:17
1,-3,19:18
0,-2,19:18
1,-4,20:18
0,-3,20:18
