[META]
version=2.0
spawnOnBlockType=12,8,9
spawnSunlight=True
spawnDarkness=True
spawnWater=True
spawnLava=False
underFill=False
randomRotation=True
dig=True
tree=False
branch=False
needsFoundation=false
rarity=300
collisionPercentage=50
spawnElevationMin=60
spawnElevationMax=64
spawnInBiome=All
[DATA]
0,-5,0:17.0
5,-5,0:17.0
0,-4,0:17.0
1,-4,0:18
5,-4,0:17.0
1,-2,0:17.0
2,-2,0:17.0
-3,0,0:17.0
-2,0,0:17.0
-2,1,0:17.0
4,1,0:17.0
2,2,0:17.0
1,-4,-4:17.0
-1,-3,-4:17.0
1,-3,-4:17.0
2,-3,-4:17.0
3,-3,-4:17.0
4,-3,-4:17.0
4,-2,-4:17.0
2,-1,-4:17.0
1,0,-4:17.0
2,0,-4:17.0
2,-6,-3:17.0
1,-5,-3:17.0
2,-5,-3:17.0
3,-5,-3:17.0
0,-4,-3:17.0
3,-4,-3:17.0
5,-4,-3:17.0
-1,-3,-3:17.0
0,-3,-3:17.0
2,-3,-3:17.0
3,-3,-3:17.0
4,-3,-3:17.0
5,-3,-3:17.0
-2,-2,-3:17.0
-1,-2,-3:17.0
2,-2,-3:17.0
3,-2,-3:17.0
5,-2,-3:17.0
-2,-1,-3:17.0
1,-1,-3:17.0
3,-1,-3:17.0
4,-1,-3:17.0
5,-1,-3:17.0
-1,0,-3:17.0
0,0,-3:17.0
1,0,-3:17.0
4,0,-3:17.0
5,0,-3:17.0
1,1,-3:17.0
2,1,-3:17.0
3,1,-3:17.0
4,1,-3:17.0
2,2,-3:17.0
1,-6,-2:17.0
3,-6,-2:17.0
4,-6,-2:17.0
0,-5,-2:17.0
4,-5,-2:17.0
-1,-4,-2:17.0
1,-4,-2:17.0
4,-4,-2:17.0
5,-4,-2:17.0
6,-4,-2:17.0
1,-3,-2:17.0
2,-3,-2:17.0
6,-3,-2:17.0
-1,-2,-2:17.0
1,-2,-2:17.0
2,-2,-2:17.0
5,-2,-2:17.0
-2,-1,-2:17.0
-1,-1,-2:17.0
0,-1,-2:17.0
2,-1,-2:17.0
-2,0,-2:17.0
2,0,-2:17.0
3,0,-2:17.0
1,1,-2:17.0
4,1,-2:17.0
1,2,-2:17.0
2,2,-2:17.0
3,2,-2:17.0
0,-5,-1:17.0
4,-5,-1:17.0
5,-5,-1:17.0
1,-4,-1:17.0
4,-4,-1:17.0
5,-4,-1:17.0
2,-2,-1:17.0
-2,0,-1:17.0
4,1,-1:17.0
2,2,-1:17.0
5,-6,1:18
0,-5,1:18
4,-5,1:18
5,-5,1:17.0
-1,-4,1:17.0
0,-4,1:17.0
1,-4,1:18
5,-4,1:18
6,-4,1:17.0
7,-4,1:18
-1,-3,1:17.0
6,-3,1:17.0
1,-2,1:17.0
2,-2,1:18
-4,0,1:17.0
3,0,1:18
2,1,1:18
3,1,1:17.0
4,1,1:17.0
-2,2,1:17.0
1,2,1:18
2,2,1:17.0
3,2,1:18
4,2,1:18
0,2,1:106.8
1,-5,1:106.2
-1,-5,1:106.8
0,-6,1:106.1
6,-6,2:18
5,-5,2:18
6,-5,2:17.0
-1,-4,2:18
0,-4,2:18
6,-4,2:18
7,-4,2:18
-1,-3,2:17.0
6,-3,2:18
7,-3,2:17.0
8,-3,2:18
-1,-2,2:18
1,-2,2:18
0,-1,2:18
1,-1,2:17.0
2,-1,2:18
-4,0,2:17.0
1,0,2:18
-4,1,2:18
-3,1,2:18
-2,1,2:18
3,1,2:18
4,1,2:18
5,1,2:18
-2,2,2:17.0
-1,2,2:18
2,2,2:18
4,2,2:18
5,2,2:17.0
6,2,2:18
7,-6,3:18
6,-5,3:18
7,-5,3:17.0
8,-5,3:18
-2,-4,3:18
7,-4,3:18
-2,-3,3:17.0
-1,-3,3:18
2,-3,3:18
6,-3,3:18
7,-3,3:18
8,-3,3:18
-2,-2,3:18
1,-2,3:18
2,-2,3:17.0
3,-2,3:18
6,-2,3:18
7,-2,3:17.0
8,-2,3:18
1,-1,3:18
2,-1,3:17.0
3,-1,3:18
7,-1,3:18
8,-1,3:18
-4,0,3:18
-3,0,3:18
-2,0,3:18
2,0,3:18
-5,1,3:18
-4,1,3:17.0
-3,1,3:18
-2,1,3:17.0
-1,1,3:18
-4,2,3:18
-3,2,3:18
-2,2,3:18
5,2,3:18
7,-7,4:18
6,-6,4:18
7,-6,4:17.0
8,-6,4:18
6,-5,4:18
7,-5,4:18
-4,-4,4:18
-3,-4,4:18
-4,-3,4:18
-3,-3,4:17.0
-2,-3,4:18
-3,-2,4:18
-2,-2,4:18
2,-2,4:18
7,-2,4:18
2,-1,4:18
-4,1,4:18
-3,1,4:18
-2,1,4:18
7,-6,5:18
-3,-3,5:18
