[META]
version=2.0
spawnOnBlockType=2,1
spawnSunlight=True
spawnDarkness=False
spawnWater=False
spawnLava=False
underFill=True
randomRotation=True
dig=True
tree=True
branch=False
needsFoundation=True
rarity=10
collisionPercentage=2
spawnElevationMin=0
spawnElevationMax=128
spawnInBiome=OttaWildlands
[DATA]
-2,0,0:17.3
-1,0,0:17.3
-3,1,0:17.3
-2,1,0:17.3
-1,1,0:17.3
-3,2,0:17.3
-2,2,0:17.3
-2,0,1:17.3
-1,0,1:17.3
-3,1,1:17.3
-2,1,1:17.3
-1,1,1:17.3
-3,2,1:17.3
-2,2,1:17.3
-2,0,2:17.3
-1,0,2:17.3
-3,1,2:17.3
-2,1,2:17.3
-1,1,2:17.3
-3,2,2:17.3
-2,2,2:17.3
-2,0,3:17.3
-1,0,3:17.3
-3,1,3:17.3
-2,1,3:17.3
-1,1,3:17.3
-3,2,3:17.3
-2,2,3:17.3
-2,0,4:17.3
-3,1,4:17.3
-2,1,4:17.3
-1,1,4:17.3
-2,2,4:17.3
-3,1,5:17.3
-2,1,5:17.3
-1,1,5:17.3
-2,1,6:17.3
-2,1,7:17.3
-2,1,8:17.3
-2,1,9:17.3
-2,1,10:17.3
-2,1,11:17.3
-2,1,12:17.3
-2,1,13:17.3
-2,1,14:17.3
-2,1,15:17.3
-2,1,16:17.3
-2,1,17:17.3
-2,1,18:17.3
-2,1,19:17.3
-2,1,20:17.3
-4,1,21:103
-2,1,21:17.3
0,-1,22:103
-4,1,22:85
-2,1,22:17.3
-2,4,22:103
0,-1,23:85
-4,1,23:85
-2,1,23:17.3
-2,4,23:85
0,-1,24:85
-2,0,24:17
-1,0,24:17
0,0,24:17
-4,1,24:17
-3,1,24:17
-2,1,24:17.3
-2,2,24:17
-2,4,24:85
0,-1,25:17
-5,0,25:17
-4,0,25:17
0,0,25:17.3
-4,1,25:17.3
-2,2,25:17.3
-2,3,25:17
-2,4,25:17
-5,-4,26:18
-4,-4,26:18
-3,-4,26:18
-2,-4,26:18
-1,-4,26:18
0,-4,26:18
-6,-3,26:18
-5,-3,26:18
-4,-3,26:18
-3,-3,26:18
-2,-3,26:18
-1,-3,26:18
0,-3,26:18
1,-3,26:18
-6,-2,26:18
-5,-2,26:18
-4,-2,26:18
-3,-2,26:18
-2,-2,26:18
-1,-2,26:18
0,-2,26:18
1,-2,26:18
2,-2,26:18
-7,-1,26:18
-6,-1,26:18
-5,-1,26:18
-4,-1,26:18
-3,-1,26:18
-2,-1,26:18
-1,-1,26:18
0,-1,26:17.3
1,-1,26:17
2,-1,26:18
-7,0,26:18
-6,0,26:18
-5,0,26:17.3
-4,0,26:18
-3,0,26:18
-2,0,26:18
-1,0,26:18
0,0,26:18
1,0,26:18
2,0,26:18
3,0,26:18
-7,1,26:18
-6,1,26:18
-5,1,26:18
-4,1,26:18
-3,1,26:18
-2,1,26:18
-1,1,26:18
0,1,26:18
1,1,26:18
2,1,26:18
3,1,26:18
-6,2,26:18
-5,2,26:18
-4,2,26:18
-3,2,26:18
-2,2,26:18
-1,2,26:18
0,2,26:18
1,2,26:18
2,2,26:18
-6,3,26:18
-5,3,26:18
-4,3,26:18
-3,3,26:18
-2,3,26:18
-1,3,26:18
0,3,26:18
1,3,26:18
2,3,26:18
-5,4,26:18
-4,4,26:18
-3,4,26:18
-2,4,26:17.3
-1,4,26:18
0,4,26:18
1,4,26:18
-4,5,26:18
-3,5,26:18
-2,5,26:17
-1,5,26:18
0,5,26:18
1,5,26:18
-3,6,26:18
-2,6,26:18
-1,6,26:18
0,6,26:18
-4,-6,27:18
-3,-6,27:18
-2,-6,27:18
-6,-5,27:18
-5,-5,27:18
-4,-5,27:18
-3,-5,27:18
-2,-5,27:18
-1,-5,27:18
0,-5,27:18
1,-5,27:18
-6,-4,27:18
-5,-4,27:18
-4,-4,27:18
-3,-4,27:18
-2,-4,27:18
-1,-4,27:18
0,-4,27:18
1,-4,27:18
2,-4,27:18
3,-4,27:18
-7,-3,27:18
-6,-3,27:18
-5,-3,27:18
-4,-3,27:18
-3,-3,27:18
-2,-3,27:18
-1,-3,27:18
0,-3,27:18
1,-3,27:18
2,-3,27:18
3,-3,27:18
-8,-2,27:18
-7,-2,27:18
-6,-2,27:18
-5,-2,27:18
-4,-2,27:18
-3,-2,27:18
-2,-2,27:18
-1,-2,27:18
0,-2,27:18
1,-2,27:18
2,-2,27:18
3,-2,27:18
4,-2,27:18
-8,-1,27:18
-7,-1,27:18
-6,-1,27:18
-5,-1,27:18
-4,-1,27:18
-3,-1,27:18
-2,-1,27:18
-1,-1,27:18
0,-1,27:18
1,-1,27:17.3
2,-1,27:18
3,-1,27:18
4,-1,27:18
-8,0,27:18
-7,0,27:18
-6,0,27:18
-5,0,27:17.3
-4,0,27:18
-3,0,27:18
-2,0,27:18
-1,0,27:18
0,0,27:18
1,0,27:18
2,0,27:18
3,0,27:18
4,0,27:18
-8,1,27:18
-7,1,27:18
-6,1,27:18
-5,1,27:18
-4,1,27:18
-3,1,27:18
-2,1,27:18
-1,1,27:18
0,1,27:18
1,1,27:18
2,1,27:18
3,1,27:18
4,1,27:18
-8,2,27:18
-7,2,27:18
-6,2,27:18
-5,2,27:18
-4,2,27:18
-3,2,27:18
-2,2,27:18
-1,2,27:18
0,2,27:18
1,2,27:18
2,2,27:18
3,2,27:18
4,2,27:18
-8,3,27:18
-7,3,27:18
-6,3,27:18
-5,3,27:18
-4,3,27:18
-3,3,27:18
-2,3,27:18
-1,3,27:18
0,3,27:18
1,3,27:18
2,3,27:18
3,3,27:18
4,3,27:18
-8,4,27:18
-7,4,27:18
-6,4,27:18
-5,4,27:18
-4,4,27:18
-3,4,27:18
-2,4,27:18
-1,4,27:18
0,4,27:18
1,4,27:18
2,4,27:18
3,4,27:18
4,4,27:18
-7,5,27:18
-6,5,27:18
-5,5,27:18
-4,5,27:18
-3,5,27:18
-2,5,27:17.3
-1,5,27:18
0,5,27:18
1,5,27:18
2,5,27:18
3,5,27:18
-7,6,27:18
-6,6,27:18
-5,6,27:18
-4,6,27:18
-3,6,27:18
-2,6,27:18
-1,6,27:18
0,6,27:18
1,6,27:18
2,6,27:18
3,6,27:18
-6,7,27:18
-5,7,27:18
-4,7,27:18
-3,7,27:18
-2,7,27:18
-1,7,27:18
0,7,27:18
1,7,27:18
2,7,27:18
-4,8,27:18
-3,8,27:18
-2,8,27:18
-1,8,27:18
0,8,27:18
1,8,27:18
2,8,27:18
-3,9,27:18
-2,9,27:18
-1,9,27:18
0,9,27:18
1,9,27:18
-4,-5,28:18
-3,-5,28:18
-5,-4,28:18
-4,-4,28:18
-3,-4,28:18
-2,-4,28:18
-1,-4,28:18
0,-4,28:18
1,-4,28:18
-6,-3,28:18
-5,-3,28:18
-4,-3,28:18
-3,-3,28:18
-2,-3,28:18
-1,-3,28:18
0,-3,28:18
1,-3,28:18
2,-3,28:18
-7,-2,28:18
-6,-2,28:18
-5,-2,28:18
-4,-2,28:18
-3,-2,28:18
-2,-2,28:18
-1,-2,28:18
0,-2,28:18
1,-2,28:18
2,-2,28:18
3,-2,28:18
-7,-1,28:18
-6,-1,28:18
-5,-1,28:18
-4,-1,28:18
-3,-1,28:18
-2,-1,28:18
-1,-1,28:18
0,-1,28:18
1,-1,28:18
2,-1,28:18
3,-1,28:18
-7,0,28:18
-6,0,28:18
-5,0,28:18
-4,0,28:18
-3,0,28:18
-2,0,28:18
-1,0,28:18
0,0,28:18
1,0,28:18
2,0,28:18
3,0,28:18
-7,1,28:18
-6,1,28:18
-5,1,28:18
-4,1,28:18
-3,1,28:18
-2,1,28:18
-1,1,28:18
0,1,28:18
1,1,28:18
2,1,28:18
3,1,28:18
-7,2,28:18
-6,2,28:18
-5,2,28:18
-4,2,28:18
-3,2,28:18
-2,2,28:18
-1,2,28:18
0,2,28:18
1,2,28:18
2,2,28:18
3,2,28:18
-7,3,28:18
-6,3,28:18
-5,3,28:18
-4,3,28:18
-3,3,28:18
-2,3,28:18
-1,3,28:18
0,3,28:18
1,3,28:18
2,3,28:18
3,3,28:18
-6,4,28:18
-5,4,28:18
-4,4,28:18
-3,4,28:18
-2,4,28:18
-1,4,28:18
0,4,28:18
1,4,28:18
2,4,28:18
-6,5,28:18
-5,5,28:18
-4,5,28:18
-3,5,28:18
-2,5,28:18
-1,5,28:18
0,5,28:18
1,5,28:18
2,5,28:18
-5,6,28:18
-4,6,28:18
-3,6,28:18
-2,6,28:18
-1,6,28:18
0,6,28:18
1,6,28:18
2,6,28:18
-4,7,28:18
-3,7,28:18
-2,7,28:18
-1,7,28:18
0,7,28:18
1,7,28:18
-3,8,28:18
-2,8,28:18
-1,8,28:18
0,8,28:18
-4,-4,29:18
-3,-4,29:18
-2,-4,29:18
-5,-3,29:18
-4,-3,29:18
-3,-3,29:18
-2,-3,29:18
-1,-3,29:18
0,-3,29:18
1,-3,29:18
-6,-2,29:18
-5,-2,29:18
-4,-2,29:18
-3,-2,29:18
-2,-2,29:18
-1,-2,29:18
0,-2,29:18
1,-2,29:18
2,-2,29:18
-6,-1,29:18
-5,-1,29:18
-4,-1,29:18
-3,-1,29:18
-2,-1,29:18
-1,-1,29:18
0,-1,29:18
1,-1,29:18
2,-1,29:18
-6,0,29:18
-5,0,29:18
-4,0,29:18
-3,0,29:18
-2,0,29:18
-1,0,29:18
0,0,29:18
1,0,29:18
2,0,29:18
-6,1,29:18
-5,1,29:18
-4,1,29:18
-3,1,29:18
-2,1,29:18
-1,1,29:18
0,1,29:18
1,1,29:18
2,1,29:18
-6,2,29:18
-5,2,29:18
-4,2,29:18
-3,2,29:18
-2,2,29:18
-1,2,29:18
0,2,29:18
1,2,29:18
2,2,29:18
-5,3,29:18
-4,3,29:18
-3,3,29:18
-2,3,29:18
-1,3,29:18
0,3,29:18
1,3,29:18
2,3,29:18
-5,4,29:18
-4,4,29:18
-3,4,29:18
-2,4,29:18
-1,4,29:18
0,4,29:18
1,4,29:18
-4,5,29:18
-3,5,29:18
-2,5,29:18
-1,5,29:18
0,5,29:18
1,5,29:18
-3,6,29:18
-2,6,29:18
-1,6,29:18
0,6,29:18
-3,7,29:18
-2,7,29:18
-1,7,29:18
0,7,29:18
