[META]
version=2.0
spawnOnBlockType=2
spawnSunlight=True
spawnDarkness=False
spawnWater=False
spawnLava=False
underFill=True
randomRotation=True
dig=True
tree=True
branch=False
needsFoundation=True
rarity=10
collisionPercentage=20
spawnElevationMin=0
spawnElevationMax=128
spawnInBiome=OttaFlatPlainsLakeBirchBorder
[DATA]
0,0,0:17.2
0,0,1:17.2
0,0,2:17.2
0,-1,3:17.2
0,0,3:17.2
0,-1,4:17.2
0,-1,5:17.2
0,0,5:18.2
1,-1,5:18.2
0,-1,6:17.2
0,0,6:18.2
1,0,6:18.2
1,-1,6:18.2
0,-2,6:18.2
0,-2,7:18.2
0,-1,7:17.2
-1,-1,7:18.2
0,0,7:18.2
-1,0,7:18.2
0,-2,8:17.2
-1,-1,8:18.2
0,-1,8:17.2
1,0,8:18.2
0,0,8:18.2
1,-1,8:18.2
0,-3,8:18.2
-1,-2,8:18.2
1,-2,8:18.2
-1,-2,9:18.2
0,-2,9:17.2
1,-2,9:18.2
0,-1,9:18.2
0,0,9:18.2
1,0,9:17.2
0,-3,9:18.2
1,-1,9:18.2
0,1,9:18.2
2,0,9:18.2
1,1,9:18.2
0,-3,10:18.2
-1,-2,10:18.2
0,-2,10:17.2
1,-2,10:18.2
1,0,10:17.2
0,0,10:18.2
0,1,10:18.2
1,1,10:18.2
2,0,10:18.2
0,-1,10:18.2
1,-1,10:18.2
0,-3,11:17.2
1,-3,11:18.2
-1,-2,11:17.2
0,-2,11:17.2
1,-2,11:18.2
1,0,11:17.2
0,-4,11:18.2
-1,-3,11:18.2
-2,-2,11:18.2
-1,-1,11:18.2
0,-1,11:18.2
1,1,11:17.2
0,0,11:18.2
0,1,11:18.2
2,0,11:18.2
1,2,11:18.2
2,1,11:18.2
1,-1,11:18.2
-1,-3,12:18.2
0,-3,12:17.2
-1,-2,12:17.2
0,-2,12:18.2
-1,-1,12:18.2
1,-3,12:18.2
-2,-2,12:18.2
-2,-3,12:18.2
1,-2,12:18.2
1,0,12:18.2
1,1,12:18.2
0,-3,13:17.2
1,-3,13:17.2
2,-3,13:18.2
-1,-2,13:17.2
0,-2,13:18.2
-2,-2,13:18.2
-2,-1,13:18.2
-1,-1,13:18.2
1,-2,13:18.2
0,-4,13:18.2
1,-4,13:18.2
-1,-3,13:18.2
1,-4,14:18.2
1,-3,14:17.2
2,-3,14:18.2
-1,-2,14:17.2
0,-3,14:18.2
0,-2,14:18.2
-1,-1,14:18.2
-2,-2,14:18.2
1,-2,14:18.2
-1,-3,14:18.2
2,-4,15:18.2
0,-3,15:18.2
1,-3,15:17.2
2,-3,15:17.2
3,-3,15:18.2
1,-4,15:18.2
0,-2,15:18.2
1,-2,15:18.2
2,-4,16:18.2
2,-3,16:17.2
1,-3,16:18.2
3,-3,16:18.2
2,-2,16:18.2
2,-3,17:17.2
1,-3,17:18.2
2,-2,17:18.2
3,-3,17:18.2
2,-4,17:18.2
2,-3,18:18.2
0,0,-1:17.2
-1,0,-1:17.2
-1,0,-2:17.2
-2,0,-2:17.2
-2,1,-2:17.2
-2,2,-2:17.2
