[META]
version=2.0
spawnOnBlockType=3,2
spawnSunlight=True
spawnDarkness=False
spawnWater=False
spawnLava=False
underFill=True
randomRotation=True
dig=True
tree=False
branch=False
needsFoundation=True
rarity=15
collisionPercentage=2
spawnElevationMin=0
spawnElevationMax=128
spawnInBiome=OttaFlatPlainsRockField
[DATA]
-2,-2,0:1
-1,-2,0:1
0,-2,0:1
2,-1,0:1
1,-1,0:1
0,-1,0:1
-1,-1,0:1
-2,-1,0:1
-3,-1,0:1
-3,0,0:1
-2,0,0:1
-1,0,0:1
0,0,0:1
1,0,0:1
2,0,0:1
1,1,0:1
0,1,0:1
-1,1,0:1
-2,1,0:1
-2,2,0:1
-1,2,0:1
0,2,0:1
1,-2,0:2
2,-2,0:2
3,-1,0:2
3,0,0:2
2,1,0:2
1,2,0:2
0,3,0:2
-1,3,0:2
-2,3,0:2
-3,2,0:2
-3,1,0:2
-4,0,0:2
-4,-1,0:2
-3,-2,0:2
-1,-3,0:2
0,-3,0:2
1,3,0:2
0,4,0:2
-1,4,0:2
-3,3,0:2
-4,1,0:2
-4,-2,0:2
-2,-3,0:2
-3,-3,0:2
1,-3,0:2
3,-2,0:2
3,1,0:2
2,2,0:2
4,0,0:2
4,-1,0:2
-1,-4,0:2
-2,-4,0:2
0,-4,0:2
-1,-5,0:2
-5,-1,0:2
-5,0,0:2
-2,-2,-1:1
-1,-2,-1:1
0,-2,-1:1
-3,-1,-1:1
-2,-1,-1:1
-1,-1,-1:1
0,-1,-1:1
1,-1,-1:1
2,-1,-1:1
2,0,-1:1
1,0,-1:1
0,0,-1:1
-1,0,-1:1
-2,0,-1:1
-3,0,-1:1
-2,1,-1:1
-1,1,-1:1
0,1,-1:1
1,1,-1:1
-2,2,-1:1
-1,2,-1:1
0,2,-1:1
1,-2,-1:2
2,-2,-1:2
3,-1,-1:2
3,0,-1:2
2,1,-1:2
1,2,-1:2
0,3,-1:2
-1,3,-1:2
-2,3,-1:2
-3,2,-1:2
-3,1,-1:2
-4,0,-1:2
-4,-1,-1:2
-3,-2,-1:2
-2,-3,-1:2
-1,-3,-1:2
0,-3,-1:2
1,-2,-2:1
0,-2,-2:1
-1,-2,-2:1
-2,-2,-2:1
-3,-1,-2:1
-2,-1,-2:1
-1,-1,-2:1
0,-1,-2:1
1,-1,-2:1
2,-1,-2:1
2,0,-2:1
1,0,-2:1
0,0,-2:1
-1,0,-2:1
-1,1,-2:1
-2,1,-2:1
-2,0,-2:1
-3,0,-2:1
-3,1,-2:1
0,1,-2:1
1,1,-2:1
1,2,-2:1
0,2,-2:1
-1,2,-2:1
-2,2,-2:1
3,-1,-2:2
3,0,-2:2
2,1,-2:2
2,2,-2:2
1,3,-2:2
-1,3,-2:2
0,3,-2:2
-2,3,-2:2
-3,2,-2:2
-4,1,-2:2
-4,0,-2:2
-4,-1,-2:2
-3,-2,-2:2
-2,-3,-2:2
-1,-3,-2:2
0,-3,-2:2
1,-3,-2:2
2,-2,-2:2
-1,-2,-3:1
0,-2,-3:1
1,-2,-3:1
1,-1,-3:1
1,0,-3:1
2,-1,-3:1
2,0,-3:1
1,1,-3:1
1,2,-3:1
0,2,-3:1
-1,2,-3:1
-1,1,-3:1
-1,0,-3:1
-1,-1,-3:1
-2,-2,-3:1
-2,-1,-3:1
-2,0,-3:1
-2,1,-3:1
-2,2,-3:1
-3,-1,-3:1
-3,0,-3:1
-3,1,-3:1
0,-1,-3:1
0,0,-3:1
0,1,-3:1
2,1,-3:2
2,2,-3:2
1,3,-3:2
0,3,-3:2
-1,3,-3:2
-2,3,-3:2
-3,2,-3:2
3,-1,-3:2
3,0,-3:2
2,-2,-3:2
1,-3,-3:2
0,-3,-3:2
-1,-3,-3:2
-2,-3,-3:2
-4,-1,-3:2
-4,0,-3:2
-4,1,-3:2
-3,-2,-3:2
-2,-2,1:1
-1,-2,1:1
0,-2,1:1
-3,-1,1:1
-2,-1,1:1
-1,-1,1:1
0,-1,1:1
1,-1,1:1
2,-1,1:1
2,0,1:1
1,0,1:1
0,0,1:1
-1,0,1:1
-2,0,1:1
-3,0,1:1
-2,1,1:1
-1,1,1:1
0,1,1:1
1,1,1:1
-2,2,1:1
-1,2,1:1
0,2,1:1
0,-3,1:2
1,-2,1:2
-1,3,1:2
0,3,1:2
1,2,1:2
2,1,1:2
3,-1,1:2
3,0,1:2
-3,1,1:2
-4,0,1:2
-4,-1,1:2
-3,-2,1:2
4,0,1:2
-1,-3,1:2
-2,-3,1:2
-1,-4,1:2
-5,0,1:2
1,-1,2:1
0,-1,2:1
-1,-1,2:1
-2,-1,2:1
-3,-1,2:1
1,0,2:1
0,0,2:1
-1,0,2:1
-2,0,2:1
-3,0,2:1
-2,1,2:1
-1,1,2:1
0,1,2:1
1,1,2:1
0,-2,2:1
-1,-2,2:1
-2,-2,2:1
-2,2,2:1
-1,2,2:1
0,2,2:1
-4,0,2:2
0,3,2:2
2,0,2:2
3,0,2:2
2,-1,2:2
-1,-3,2:2
-1,-2,3:1
0,-2,3:1
0,-1,3:1
0,0,3:1
1,0,3:1
1,1,3:1
0,1,3:1
-1,1,3:1
-1,2,3:1
0,2,3:1
-1,0,3:1
-1,-1,3:1
-2,-1,3:1
-3,-1,3:1
-3,0,3:1
-2,0,3:1
-2,1,3:1
2,0,3:2
-3,0,4:1
-2,0,4:1
-2,-1,4:1
-2,1,4:1
-1,1,4:1
0,1,4:1
1,1,4:1
1,0,4:1
0,0,4:1
-1,0,4:1
-1,-1,4:1
0,-1,4:1
-1,-2,4:1
0,2,4:1
-1,-1,5:1
-1,0,5:1
-2,0,5:1
-1,1,5:1
0,1,5:1
1,1,5:1
1,0,5:1
0,0,5:1
0,-1,5:1
0,1,6:1
1,0,6:1
0,0,6:1
0,-1,6:1
-1,0,6:1
-1,1,6:1
-1,0,7:1
0,0,7:1
-1,1,7:1
0,1,7:1
-1,0,8:1
0,0,8:1
0,1,8:1
0,0,9:1
