[META]
version=2.0
spawnOnBlockType=2,1
spawnSunlight=True
spawnDarkness=False
spawnWater=False
spawnLava=False
underFill=True
randomRotation=True
dig=True
tree=True
branch=False
needsFoundation=True
rarity=10
collisionPercentage=2
spawnElevationMin=0
spawnElevationMax=128
spawnInBiome=OttaWildlands
[DATA]
0,-1,0:17.3
-1,0,0:17.3
0,0,0:17.3
1,0,0:17.3
-1,1,0:17.3
0,1,0:17.3
0,-1,1:17.3
-1,0,1:17.3
0,0,1:17.3
1,0,1:17.3
-1,1,1:17.3
0,1,1:17.3
0,-1,2:17.3
-1,0,2:17.3
0,0,2:17.3
1,0,2:17.3
-1,1,2:17.3
0,1,2:17.3
0,-1,3:17.3
-1,0,3:17.3
0,0,3:17.3
1,0,3:17.3
-1,1,3:17.3
0,1,3:17.3
0,-1,4:17.3
0,0,4:17.3
1,0,4:17.3
-1,1,4:17.3
0,1,4:17.3
0,0,5:17.3
1,0,5:17.3
0,1,5:17.3
0,0,6:17.3
1,0,6:17.3
0,1,6:17.3
0,0,7:17.3
0,1,7:17.3
0,0,8:17.3
0,0,9:17.3
0,0,10:17.3
0,0,11:17.3
0,0,12:17.3
0,0,13:17.3
0,0,14:17.3
0,0,15:17.3
0,0,16:17.3
0,0,17:17.3
0,0,18:17.3
0,0,19:17.3
0,0,20:17.3
-3,0,21:103
0,0,21:17.3
-3,0,22:85
0,0,22:17.3
2,0,22:103
-3,0,23:85
0,0,23:17.3
2,0,23:85
-3,0,24:85
-2,0,24:17
-1,0,24:17
0,0,24:17.3
2,0,24:85
-3,0,25:17
-2,0,25:17.3
0,0,25:17.3
1,0,25:17
2,0,25:85
-2,-4,26:18
-1,-4,26:18
0,-4,26:18
1,-4,26:18
2,-4,26:18
-3,-3,26:18
-2,-3,26:18
-1,-3,26:18
0,-3,26:18
1,-3,26:18
2,-3,26:18
3,-3,26:18
-4,-2,26:18
-3,-2,26:18
-2,-2,26:18
-1,-2,26:18
0,-2,26:18
1,-2,26:18
2,-2,26:18
3,-2,26:18
4,-2,26:18
-5,-1,26:18
-4,-1,26:18
-3,-1,26:18
-2,-1,26:17
-1,-1,26:18
0,-1,26:17
1,-1,26:18
2,-1,26:18
3,-1,26:18
4,-1,26:18
-5,0,26:18
-4,0,26:18
-3,0,26:18
-2,0,26:17.3
-1,0,26:18
0,0,26:17.3
1,0,26:17.3
2,0,26:17
3,0,26:18
4,0,26:18
-4,1,26:18
-3,1,26:18
-2,1,26:18
-1,1,26:18
0,1,26:17
1,1,26:18
2,1,26:18
3,1,26:18
4,1,26:18
-3,2,26:18
-2,2,26:18
-1,2,26:18
0,2,26:18
1,2,26:18
2,2,26:18
3,2,26:18
-2,3,26:18
-1,3,26:18
0,3,26:18
1,3,26:18
2,3,26:18
-1,4,26:18
0,4,26:18
1,4,26:18
2,4,26:18
0,-6,27:18
1,-6,27:18
-3,-5,27:18
-2,-5,27:18
-1,-5,27:18
0,-5,27:18
1,-5,27:18
2,-5,27:18
3,-5,27:18
-4,-4,27:18
-3,-4,27:18
-2,-4,27:18
-1,-4,27:18
0,-4,27:18
1,-4,27:18
2,-4,27:18
3,-4,27:18
4,-4,27:18
-6,-3,27:18
-5,-3,27:18
-4,-3,27:18
-3,-3,27:18
-2,-3,27:18
-1,-3,27:18
0,-3,27:18
1,-3,27:18
2,-3,27:18
3,-3,27:18
4,-3,27:18
5,-3,27:18
-6,-2,27:18
-5,-2,27:18
-4,-2,27:18
-3,-2,27:18
-2,-2,27:18
-1,-2,27:18
0,-2,27:18
1,-2,27:18
2,-2,27:18
3,-2,27:18
4,-2,27:18
5,-2,27:18
-6,-1,27:18
-5,-1,27:18
-4,-1,27:18
-3,-1,27:18
-2,-1,27:18
-1,-1,27:18
0,-1,27:18
1,-1,27:18
2,-1,27:18
3,-1,27:18
4,-1,27:18
5,-1,27:18
-6,0,27:18
-5,0,27:18
-4,0,27:18
-3,0,27:18
-2,0,27:18
-1,0,27:18
0,0,27:18
1,0,27:18
2,0,27:18
3,0,27:18
4,0,27:18
5,0,27:18
-6,1,27:18
-5,1,27:18
-4,1,27:18
-3,1,27:18
-2,1,27:18
-1,1,27:18
0,1,27:18
1,1,27:18
2,1,27:18
3,1,27:18
4,1,27:18
5,1,27:18
-6,2,27:18
-5,2,27:18
-4,2,27:18
-3,2,27:18
-2,2,27:18
-1,2,27:18
0,2,27:18
1,2,27:18
2,2,27:18
3,2,27:18
4,2,27:18
5,2,27:18
-5,3,27:18
-4,3,27:18
-3,3,27:18
-2,3,27:18
-1,3,27:18
0,3,27:18
1,3,27:18
2,3,27:18
3,3,27:18
4,3,27:18
-4,4,27:18
-3,4,27:18
-2,4,27:18
-1,4,27:18
0,4,27:18
1,4,27:18
2,4,27:18
3,4,27:18
-3,5,27:18
-2,5,27:18
-1,5,27:18
0,5,27:18
1,5,27:18
2,5,27:18
3,5,27:18
-2,-7,28:18
-1,-7,28:18
0,-7,28:18
1,-7,28:18
2,-7,28:18
-4,-6,28:18
-3,-6,28:18
-2,-6,28:18
-1,-6,28:18
0,-6,28:18
1,-6,28:18
2,-6,28:18
-5,-5,28:18
-4,-5,28:18
-3,-5,28:18
-2,-5,28:18
-1,-5,28:18
0,-5,28:18
1,-5,28:18
2,-5,28:18
3,-5,28:18
4,-5,28:18
5,-5,28:18
-6,-4,28:18
-5,-4,28:18
-4,-4,28:18
-3,-4,28:18
-2,-4,28:18
-1,-4,28:18
0,-4,28:18
1,-4,28:18
2,-4,28:18
3,-4,28:18
4,-4,28:18
5,-4,28:18
6,-4,28:18
-6,-3,28:18
-5,-3,28:18
-4,-3,28:18
-3,-3,28:18
-2,-3,28:18
-1,-3,28:18
0,-3,28:18
1,-3,28:18
2,-3,28:18
3,-3,28:18
4,-3,28:18
5,-3,28:18
6,-3,28:18
-7,-2,28:18
-6,-2,28:18
-5,-2,28:18
-4,-2,28:18
-3,-2,28:18
-2,-2,28:18
-1,-2,28:18
0,-2,28:18
1,-2,28:18
2,-2,28:18
3,-2,28:18
4,-2,28:18
5,-2,28:18
6,-2,28:18
-7,-1,28:18
-6,-1,28:18
-5,-1,28:18
-4,-1,28:18
-3,-1,28:18
-2,-1,28:18
-1,-1,28:18
0,-1,28:18
1,-1,28:18
2,-1,28:18
3,-1,28:18
4,-1,28:18
5,-1,28:18
6,-1,28:18
-7,0,28:18
-6,0,28:18
-5,0,28:18
-4,0,28:18
-3,0,28:18
-2,0,28:18
-1,0,28:18
0,0,28:18
1,0,28:18
2,0,28:18
3,0,28:18
4,0,28:18
5,0,28:18
6,0,28:18
-7,1,28:18
-6,1,28:18
-5,1,28:18
-4,1,28:18
-3,1,28:18
-2,1,28:18
-1,1,28:18
0,1,28:18
1,1,28:18
2,1,28:18
3,1,28:18
4,1,28:18
5,1,28:18
6,1,28:18
-7,2,28:18
-6,2,28:18
-5,2,28:18
-4,2,28:18
-3,2,28:18
-2,2,28:18
-1,2,28:18
0,2,28:18
1,2,28:18
2,2,28:18
3,2,28:18
4,2,28:18
5,2,28:18
6,2,28:18
-7,3,28:18
-6,3,28:18
-5,3,28:18
-4,3,28:18
-3,3,28:18
-2,3,28:18
-1,3,28:18
0,3,28:18
1,3,28:18
2,3,28:18
3,3,28:18
4,3,28:18
5,3,28:18
6,3,28:18
-6,4,28:18
-5,4,28:18
-4,4,28:18
-3,4,28:18
-2,4,28:18
-1,4,28:18
0,4,28:18
1,4,28:18
2,4,28:18
3,4,28:18
4,4,28:18
5,4,28:18
-5,5,28:18
-4,5,28:18
-3,5,28:18
-2,5,28:18
-1,5,28:18
0,5,28:18
1,5,28:18
2,5,28:18
-4,6,28:18
-3,6,28:18
-2,6,28:18
-1,6,28:18
0,6,28:18
1,6,28:18
2,6,28:18
-3,7,28:18
-2,7,28:18
-1,7,28:18
0,7,28:18
-1,-6,29:18
0,-6,29:18
1,-6,29:18
-4,-5,29:18
-3,-5,29:18
-2,-5,29:18
-1,-5,29:18
0,-5,29:18
1,-5,29:18
2,-5,29:18
-4,-4,29:18
-3,-4,29:18
-2,-4,29:18
-1,-4,29:18
0,-4,29:18
1,-4,29:18
2,-4,29:18
3,-4,29:18
-5,-3,29:18
-4,-3,29:18
-3,-3,29:18
-2,-3,29:18
-1,-3,29:18
0,-3,29:18
1,-3,29:18
2,-3,29:18
3,-3,29:18
4,-3,29:18
-5,-2,29:18
-4,-2,29:18
-3,-2,29:18
-2,-2,29:18
-1,-2,29:18
0,-2,29:18
1,-2,29:18
2,-2,29:18
3,-2,29:18
4,-2,29:18
5,-2,29:18
-6,-1,29:18
-5,-1,29:18
-4,-1,29:18
-3,-1,29:18
-2,-1,29:18
-1,-1,29:18
0,-1,29:18
1,-1,29:18
2,-1,29:18
3,-1,29:18
4,-1,29:18
5,-1,29:18
-6,0,29:18
-5,0,29:18
-4,0,29:18
-3,0,29:18
-2,0,29:18
-1,0,29:18
0,0,29:18
1,0,29:18
2,0,29:18
3,0,29:18
4,0,29:18
5,0,29:18
-6,1,29:18
-5,1,29:18
-4,1,29:18
-3,1,29:18
-2,1,29:18
-1,1,29:18
0,1,29:18
1,1,29:18
2,1,29:18
3,1,29:18
4,1,29:18
5,1,29:18
-6,2,29:18
-5,2,29:18
-4,2,29:18
-3,2,29:18
-2,2,29:18
-1,2,29:18
0,2,29:18
1,2,29:18
2,2,29:18
3,2,29:18
4,2,29:18
5,2,29:18
-5,3,29:18
-4,3,29:18
-3,3,29:18
-2,3,29:18
-1,3,29:18
0,3,29:18
1,3,29:18
2,3,29:18
3,3,29:18
4,3,29:18
-5,4,29:18
-4,4,29:18
-3,4,29:18
-2,4,29:18
-1,4,29:18
0,4,29:18
1,4,29:18
2,4,29:18
-4,5,29:18
-3,5,29:18
-2,5,29:18
-1,5,29:18
0,5,29:18
1,5,29:18
-2,6,29:18
-1,6,29:18
0,6,29:18
-1,-5,30:18
0,-5,30:18
-3,-4,30:18
-2,-4,30:18
-1,-4,30:18
0,-4,30:18
1,-4,30:18
2,-4,30:18
-4,-3,30:18
-3,-3,30:18
-2,-3,30:18
-1,-3,30:18
0,-3,30:18
1,-3,30:18
2,-3,30:18
-4,-2,30:18
-3,-2,30:18
-2,-2,30:18
-1,-2,30:18
0,-2,30:18
1,-2,30:18
2,-2,30:18
3,-2,30:18
4,-2,30:18
-5,-1,30:18
-4,-1,30:18
-3,-1,30:18
-2,-1,30:18
-1,-1,30:18
0,-1,30:18
1,-1,30:18
2,-1,30:18
3,-1,30:18
4,-1,30:18
-5,0,30:18
-4,0,30:18
-3,0,30:18
-2,0,30:18
-1,0,30:18
0,0,30:18
1,0,30:18
2,0,30:18
3,0,30:18
4,0,30:18
-5,1,30:18
-4,1,30:18
-3,1,30:18
-2,1,30:18
-1,1,30:18
0,1,30:18
1,1,30:18
2,1,30:18
3,1,30:18
4,1,30:18
-5,2,30:18
-4,2,30:18
-3,2,30:18
-2,2,30:18
-1,2,30:18
0,2,30:18
1,2,30:18
2,2,30:18
3,2,30:18
-4,3,30:18
-3,3,30:18
-2,3,30:18
-1,3,30:18
0,3,30:18
1,3,30:18
2,3,30:18
-3,4,30:18
-2,4,30:18
-1,4,30:18
0,4,30:18
1,4,30:18
-2,5,30:18
-1,5,30:18
