[META]
version=2.0
spawnOnBlockType=12
spawnSunlight=True
spawnDarkness=False
spawnWater=True
spawnLava=False
underFill=True
randomRotation=True
dig=True
tree=False
branch=False
needsFoundation=True
rarity=35
collisionPercentage=2
spawnElevationMin=0
spawnElevationMax=256
spawnInBiome=OttaAtollBeach
[DATA]
-1,-4,0:1
0,-4,0:1
-1,-3,0:1
0,-3,0:1
1,-3,0:1
1,-2,0:1
2,-1,0:1
1,-1,0:1
-1,-1,0:1
-2,-1,0:1
-1,-2,0:1
-2,-2,0:1
0,-2,0:1
0,-1,0:1
2,0,0:1
2,1,0:1
2,2,0:1
1,3,0:1
0,3,0:1
-1,3,0:1
-2,3,0:1
-1,4,0:1
0,4,0:1
-1,5,0:1
-2,2,0:1
-2,1,0:1
-2,0,0:1
-3,0,0:1
-3,1,0:1
-1,0,0:1
-1,1,0:1
-1,2,0:1
0,2,0:1
1,2,0:1
1,1,0:1
1,0,0:1
0,0,0:1
0,1,0:1
-1,-5,0:12
0,-5,0:12
1,-4,0:12
-2,-4,0:12
-2,-3,0:12
-3,-2,0:12
-3,-1,0:12
-4,0,0:12
-4,1,0:12
-3,2,0:12
-3,3,0:12
-2,4,0:12
-2,5,0:12
-1,6,0:12
0,5,0:12
1,4,0:12
2,3,0:12
3,1,0:12
3,0,0:12
2,-2,0:12
2,-3,0:12
3,-1,0:12
0,-5,-1:1
-1,-5,-1:1
-1,-4,-1:1
-2,-2,-1:1
-2,-3,-1:1
-1,-3,-1:1
0,-4,-1:1
1,-4,-1:1
1,-3,-1:1
1,-2,-1:1
2,-1,-1:1
2,-2,-1:1
2,0,-1:1
3,0,-1:1
2,1,-1:1
3,1,-1:1
2,2,-1:1
2,3,-1:1
1,4,-1:1
0,5,-1:1
-1,5,-1:1
-1,6,-1:1
-2,4,-1:1
-2,3,-1:1
-2,2,-1:1
-3,2,-1:1
-3,1,-1:1
-3,0,-1:1
-3,-1,-1:1
-2,-1,-1:1
-2,0,-1:1
-2,1,-1:1
-1,1,-1:1
-1,2,-1:1
-1,3,-1:1
-1,4,-1:1
0,4,-1:1
0,3,-1:1
0,2,-1:1
0,1,-1:1
0,0,-1:1
0,-1,-1:1
0,-2,-1:1
0,-3,-1:1
-1,-2,-1:1
-1,-1,-1:1
-1,0,-1:1
1,3,-1:1
1,2,-1:1
1,1,-1:1
1,0,-1:1
1,-1,-1:1
-3,3,-1:12
-4,1,-1:12
-4,2,-1:12
-4,0,-1:12
-4,-1,-1:12
-3,-2,-1:12
-3,-3,-1:12
-2,-4,-1:12
-2,-5,-1:12
-1,-6,-1:12
0,-6,-1:12
1,-5,-1:12
2,-4,-1:12
2,-3,-1:12
3,-2,-1:12
3,-1,-1:12
4,0,-1:12
4,1,-1:12
3,2,-1:12
3,3,-1:12
2,4,-1:12
1,5,-1:12
0,6,-1:12
-1,7,-1:12
-2,5,-1:12
-2,6,-1:12
-3,4,-1:12
3,0,-2:1
-3,0,-2:1
-3,-1,-2:1
-3,-2,-2:1
3,-1,-2:1
3,1,-2:1
3,2,-2:1
2,3,-2:1
2,4,-2:1
1,5,-2:1
0,6,-2:1
-1,7,-2:1
-1,6,-2:1
-2,5,-2:1
-2,4,-2:1
-2,3,-2:1
-3,3,-2:1
-3,2,-2:1
-3,1,-2:1
-4,-1,-2:1
-4,0,-2:1
2,-2,-2:1
2,-3,-2:1
1,-4,-2:1
1,-5,-2:1
-2,-3,-2:1
-2,-4,-2:1
-1,-5,-2:1
-1,-6,-2:1
0,-6,-2:1
0,-5,-2:1
0,-4,-2:1
0,-3,-2:1
0,-2,-2:1
0,-1,-2:1
0,0,-2:1
0,1,-2:1
0,2,-2:1
0,3,-2:1
0,4,-2:1
0,5,-2:1
-1,5,-2:1
-1,4,-2:1
-1,3,-2:1
-1,2,-2:1
-1,1,-2:1
-1,0,-2:1
-1,-1,-2:1
-1,-2,-2:1
-1,-3,-2:1
-1,-4,-2:1
-2,-2,-2:1
-2,-1,-2:1
-2,0,-2:1
-2,1,-2:1
-2,2,-2:1
1,3,-2:1
1,4,-2:1
1,2,-2:1
1,-3,-2:1
1,-2,-2:1
1,-1,-2:1
1,0,-2:1
1,1,-2:1
2,2,-2:1
2,1,-2:1
2,0,-2:1
2,-1,-2:1
1,-2,1:1
0,-3,1:1
-1,-3,1:1
-1,-2,1:1
0,-2,1:1
1,-1,1:1
1,0,1:1
1,1,1:1
1,2,1:1
2,1,1:1
2,0,1:1
-2,-1,1:1
-2,0,1:1
-2,1,1:1
-2,2,1:1
0,3,1:1
-1,3,1:1
-1,4,1:1
-1,2,1:1
0,2,1:1
0,1,1:1
0,0,1:1
0,-1,1:1
-1,-1,1:1
-1,0,1:1
-1,1,1:1
-3,-1,1:12
-2,-3,1:12
2,-2,1:12
3,0,1:12
3,1,1:12
-2,4,1:12
-1,-2,2:1
0,-2,2:1
-1,-1,2:1
0,-1,2:1
1,0,2:1
1,1,2:1
0,2,2:1
-1,2,2:1
-2,1,2:1
-2,0,2:1
-1,0,2:1
0,0,2:1
0,1,2:1
-1,1,2:1
-1,3,2:1
-1,-1,3:1
-1,0,3:1
0,0,3:1
-1,1,3:1
0,1,3:1
-1,2,3:1
