[META]
version=2.0
spawnOnBlockType=2
spawnSunlight=True
spawnDarkness=True
spawnWater=False
spawnLava=False
underFill=False
randomRotation=True
dig=True
tree=True
branch=False
needsFoundation=True
rarity=20
collisionPercentage=2
spawnElevationMin=0
spawnElevationMax=256
spawnInBiome=OttaForest
[DATA]
0,0,0:17.0
0,-2,-1:17
1,-2,-1:17
0,-1,-1:17
0,0,-1:17.0
0,1,-1:17
0,2,-1:17
1,-2,-2:17.0
0,2,-2:17.0
0,0,1:17.0
0,0,2:17.0
-1,-1,3:18
0,-1,3:18
-1,0,3:18
0,0,3:17.0
0,-1,4:17.0
0,0,4:17.0
0,-1,5:17.0
-1,0,5:18
0,0,5:18
-1,1,5:18
0,1,5:18
0,-2,6:18
1,-2,6:18
-1,-1,6:18
0,-1,6:17.0
1,-1,6:18
2,-1,6:18
-1,0,6:18
0,0,6:18
-2,1,6:18
-1,1,6:18
0,1,6:18
2,1,6:18
-1,2,6:18
2,2,6:18
2,-4,7:18
3,-4,7:18
1,-3,7:18
2,-3,7:18
3,-3,7:18
-2,-2,7:18
-1,-2,7:18
0,-2,7:18
1,-2,7:17
2,-2,7:17
3,-2,7:18
-2,-1,7:18
-1,-1,7:17.0
0,-1,7:17.0
1,-1,7:17
2,-1,7:18
-3,0,7:18
-2,0,7:17
-1,0,7:17
0,0,7:18
1,0,7:17
2,0,7:17
3,0,7:18
4,0,7:18
-3,1,7:18
-2,1,7:18
-1,1,7:18
0,1,7:18
1,1,7:18
2,1,7:17
3,1,7:17
4,1,7:18
-2,2,7:18
-1,2,7:18
0,2,7:18
1,2,7:18
2,2,7:18
3,2,7:18
4,2,7:18
2,3,7:18
3,3,7:18
3,-5,8:18
1,-4,8:18
2,-4,8:18
3,-4,8:18
4,-4,8:18
0,-3,8:18
1,-3,8:18
2,-3,8:17.0
3,-3,8:17.0
4,-3,8:18
-1,-2,8:18
0,-2,8:17.0
1,-2,8:18
2,-2,8:17.0
3,-2,8:18
4,-2,8:18
-2,-1,8:18
-1,-1,8:18
0,-1,8:17.0
1,-1,8:18
2,-1,8:18
3,-1,8:18
-3,0,8:18
-2,0,8:17.0
-1,0,8:18
0,0,8:18
1,0,8:18
2,0,8:18
3,0,8:18
-3,1,8:17.0
-2,1,8:17.0
-1,1,8:18
0,1,8:18
1,1,8:18
2,1,8:18
3,1,8:18
4,1,8:18
-3,2,8:18
-2,2,8:18
-1,2,8:18
2,2,8:18
3,2,8:18
-4,1,8:18.0
-1,-5,9:18
0,-5,9:18
1,-5,9:18
-1,-4,9:18
0,-4,9:17
1,-4,9:18
2,-4,9:18
3,-4,9:18
-1,-3,9:18
0,-3,9:17
1,-3,9:18
2,-3,9:18
3,-3,9:17.0
4,-3,9:18
-2,-2,9:18
-1,-2,9:18
0,-2,9:17.0
1,-2,9:18
2,-2,9:18
3,-2,9:18
4,-2,9:18
-2,-1,9:18
-1,-1,9:18
0,-1,9:17.0
1,-1,9:18
2,-1,9:18
3,-1,9:18
-3,0,9:18
-2,0,9:18
-1,0,9:18
0,0,9:18
2,0,9:18
3,0,9:18
-3,1,9:17.0
-2,1,9:18
-1,1,9:18
-3,2,9:18
-2,2,9:18
-4,1,9:18.0
-4,0,9:18.0
-1,-4,10:18
0,-4,10:18
1,-4,10:18
-2,-3,10:18
-1,-3,10:18
0,-3,10:17.0
1,-3,10:18
2,-3,10:18
3,-3,10:18
-2,-2,10:18
-1,-2,10:18
0,-2,10:18
1,-2,10:18
-3,-1,10:18
-2,-1,10:18
-1,-1,10:18
0,-1,10:17.0
1,-1,10:18
2,-1,10:18
3,-1,10:18
-3,0,10:18
-2,0,10:18
-1,0,10:18
0,0,10:18
1,0,10:18
2,0,10:18
-3,1,10:18
-1,1,10:18
0,1,10:18
1,1,10:18
-4,0,10:18.0
-4,-1,10:18.0
-1,-3,11:18
0,-3,11:18
-2,-2,11:18
-1,-2,11:18
0,-2,11:18
1,-2,11:18
-2,-1,11:18
-1,-1,11:17.0
0,-1,11:17.0
1,-1,11:18
2,-1,11:18
-2,0,11:18
-1,0,11:18
0,0,11:18
1,0,11:18
-2,1,11:18
-1,1,11:18
0,1,11:18
1,1,11:18
-1,2,11:18
0,2,11:18
1,2,11:18
-3,-1,11:18.0
0,-2,12:18
-1,-1,12:18
0,-1,12:18
-1,0,12:18
0,0,12:18
