[META]
version=2.0
spawnOnBlockType=3,2
spawnSunlight=True
spawnDarkness=True
spawnWater=False
spawnLava=False
underFill=True
randomRotation=True
dig=True
tree=False
branch=False
needsFoundation=True
rarity=450
collisionPercentage=2
spawnElevationMin=0
spawnElevationMax=190
spawnInBiome=OttaJungle
spawnAboveGround=False
spawnUnderGround=False
collisionBlockType=All
groupId=
diggingBranch=false
branchLimit=6
groupFrequencyMin=1
groupFrequencyMax=5
groupSeperationMin=0
groupSeperationMax=5
[DATA]
-3,-5,0:17.3
-3,-4,0:17.3
-3,-3,0:17.3
-2,-3,0:17.3
-2,-2,0:17.3
-1,-2,0:17.3
-1,-1,0:17.3
0,-1,0:17.3
-1,0,0:17.3
-1,1,0:17.3
0,1,0:17.3
1,1,0:17.3
1,0,0:17.3
1,-1,0:17.3
1,-2,0:17.3
2,-2,0:17.3
2,-3,0:17.3
3,-3,0:17.3
1,2,0:17.3
2,2,0:17.3
2,3,0:17.3
1,3,0:17.3
1,4,0:17.3
1,5,0:17.3
0,5,0:17.3
-2,1,0:17.3
-3,1,0:17.3
2,0,0:17.3
3,0,0:17.3
0,-2,0:17.3
-2,-1,0:17.3
-2,0,0:17.3
-1,2,0:17.3
0,2,0:17.3
-4,1,0:17.3
4,-3,0:17.3
4,-4,0:17.3
-3,-6,0:17.3
-4,-6,0:17.3
-4,2,0:17.3
-4,3,0:17.3
-5,3,0:17.3
3,3,0:17.3
4,4,0:17.3
-1,-1,-1:17.3
-1,0,-1:17.3
-1,1,-1:17.3
0,1,-1:17.3
1,1,-1:17.3
1,0,-1:17.3
1,-1,-1:17.3
0,-1,-1:17.3
0,0,-1:17.3
2,-2,-1:17.3
2,-3,-1:17.3
3,-3,-1:17.3
1,2,-1:17.3
1,3,-1:17.3
2,3,-1:17.3
-2,1,-1:17.3
-3,1,-1:17.3
-4,1,-1:17.3
-4,2,-1:17.3
-1,-2,-1:17.3
-2,-2,-1:17.3
-2,-3,-1:17.3
-2,-4,-1:17.3
-3,-3,-1:17.3
-3,-4,-1:17.3
-3,-5,-1:17.3
3,3,-1:17.3
4,3,-1:17.3
4,4,-1:17.3
4,-3,-1:17.3
4,-4,-1:17.3
4,-5,-1:17.3
-4,3,-1:17.3
-5,3,-1:17.3
-2,2,-1:17.3
-1,-4,-1:17.3
-4,-4,-1:17.3
-5,4,-1:17.3
3,2,-1:17.3
2,-4,-1:17.3
5,-3,-1:17.3
5,4,-1:17.3
1,4,-1:17.3
0,4,-1:17.3
0,5,-1:17.3
-3,-6,-1:17.3
-4,-6,-1:17.3
-4,-7,-1:17.3
5,-2,-1:17.3
6,-2,-1:17.3
6,5,-1:17.3
1,6,-1:17.3
-1,6,-1:17.3
-3,-9,-1:17.3
-4,-8,-1:17.3
-5,-7,-1:17.3
2,0,-1:17.3
3,0,-1:17.3
4,0,-1:17.3
-3,-3,1:17.3
-2,-3,1:17.3
-2,-2,1:17.3
-1,-2,1:17.3
-1,-1,1:17.3
0,-1,1:17.3
-1,0,1:17.3
-1,1,1:17.3
0,1,1:17.3
1,1,1:17.3
1,0,1:17.3
0,0,1:17.3
1,-1,1:17.3
1,-2,1:17.3
2,-2,1:17.3
-2,1,1:17.3
1,2,1:17.3
1,3,1:17.3
2,3,1:17.3
2,-3,1:17.3
2,-4,1:17.3
1,4,1:17.3
-3,1,1:17.3
-3,2,1:17.3
-3,-4,1:17.3
-4,-4,1:17.3
2,0,1:17.3
3,0,1:17.3
1,5,1:17.3
3,-3,1:17.3
-3,-5,1:17.3
-4,2,1:17.3
-4,3,1:17.3
-2,-1,1:17.3
-2,0,1:17.3
0,2,1:17.3
-1,-2,2:17.3
-1,-1,2:17.3
-1,0,2:17.3
-1,1,2:17.3
-2,1,2:17.3
0,1,2:17.3
1,1,2:17.3
0,-1,2:17.3
1,-1,2:17.3
1,-2,2:17.3
1,0,2:17.3
0,0,2:17.3
2,0,2:17.3
1,2,2:17.3
-2,0,2:17.3
2,-2,2:17.3
-2,-2,2:17.3
-1,-1,3:17.3
-1,0,3:17.3
-1,1,3:17.3
0,1,3:17.3
1,1,3:17.3
1,0,3:17.3
1,-1,3:17.3
0,-1,3:17.3
0,0,3:17.3
-2,1,3:17.3
-1,-2,3:17.3
1,2,3:17.3
2,0,3:17.3
1,-2,3:17.3
-1,-1,4:17.3
-1,0,4:17.3
0,0,4:17.3
0,1,4:17.3
1,1,4:17.3
1,0,4:17.3
1,-1,4:17.3
0,-1,4:17.3
-1,1,4:17.3
-1,-1,5:17.3
-1,0,5:17.3
-1,1,5:17.3
0,1,5:17.3
1,1,5:17.3
1,0,5:17.3
1,-1,5:17.3
0,-1,5:17.3
0,0,5:17.3
-1,-1,6:17.3
-1,0,6:17.3
-1,1,6:17.3
0,1,6:17.3
1,1,6:17.3
1,0,6:17.3
1,-1,6:17.3
0,-1,6:17.3
0,0,6:17.3
-1,-2,6:18.3
2,1,6:18.3
-1,-1,7:17.3
-1,0,7:17.3
-1,1,7:17.3
0,1,7:17.3
0,0,7:17.3
1,0,7:17.3
1,-1,7:17.3
0,-1,7:17.3
1,1,7:17.3
-5,-1,7:106.2
-1,-1,8:17.3
-1,0,8:17.3
-1,1,8:17.3
0,1,8:17.3
1,1,8:17.3
1,0,8:17.3
1,-1,8:17.3
0,-1,8:17.3
0,0,8:17.3
-5,-1,8:106.2
5,1,8:106.8
-1,-1,9:17.3
-1,0,9:17.3
-1,1,9:17.3
0,1,9:17.3
1,1,9:17.3
1,0,9:17.3
1,-1,9:17.3
0,-1,9:17.3
0,0,9:17.3
0,2,9:18.3
-5,-1,9:106.2
5,1,9:106.8
-1,-1,10:17.3
-1,0,10:17.3
-1,1,10:17.3
0,1,10:17.3
1,1,10:17.3
1,0,10:17.3
1,-1,10:17.3
0,-1,10:17.3
0,0,10:17.3
-3,1,10:106.2
-5,-1,10:106.2
5,1,10:106.8
-1,-1,11:17.3
-1,0,11:17.3
-1,1,11:17.3
0,1,11:17.3
1,1,11:17.3
1,0,11:17.3
1,-1,11:17.3
0,-1,11:17.3
0,0,11:17.3
0,-2,11:18.3
-3,1,11:106.2
-5,-1,11:106.2
5,1,11:106.8
-1,-1,12:17.3
-1,0,12:17.3
-1,1,12:17.3
0,1,12:17.3
1,1,12:17.3
1,0,12:17.3
1,-1,12:17.3
0,-1,12:17.3
0,0,12:17.3
-3,1,12:106.2
-5,-1,12:106.2
5,1,12:106.8
4,-1,12:106.8
-1,-1,13:17.3
-1,0,13:17.3
-1,1,13:17.3
0,1,13:17.3
1,1,13:17.3
1,0,13:17.3
0,0,13:17.3
0,-1,13:17.3
1,-1,13:17.3
-3,1,13:106.2
-5,-1,13:106.2
5,1,13:106.8
4,-1,13:106.8
-5,-5,13:106.4
1,5,13:106.1
-1,-1,14:17.3
-1,0,14:17.3
-1,1,14:17.3
0,1,14:17.3
1,1,14:17.3
1,0,14:17.3
1,-1,14:17.3
0,-1,14:17.3
0,0,14:17.3
-3,1,14:106.2
-5,-1,14:106.2
5,1,14:106.8
4,-1,14:106.8
-5,-5,14:106.4
1,5,14:106.1
-1,-1,15:17.3
-1,0,15:17.3
-1,1,15:17.3
0,1,15:17.3
1,1,15:17.3
1,0,15:17.3
1,-1,15:17.3
0,-1,15:17.3
0,0,15:17.3
2,0,15:18.3
0,2,15:18.3
-3,1,15:106.2
-5,-1,15:106.2
5,1,15:106.8
4,-1,15:106.8
-5,-5,15:106.4
1,5,15:106.1
-1,-1,16:17.3
-1,0,16:17.3
-1,1,16:17.3
0,1,16:17.3
1,1,16:17.3
1,0,16:17.3
1,-1,16:17.3
0,-1,16:17.3
0,0,16:17.3
-3,1,16:106.2
-5,-1,16:106.2
5,1,16:106.8
4,-1,16:106.8
-5,-5,16:106.4
1,5,16:106.1
-1,-1,17:17.3
-1,0,17:17.3
-1,1,17:17.3
0,1,17:17.3
0,0,17:17.3
1,0,17:17.3
1,1,17:17.3
1,-1,17:17.3
0,-1,17:17.3
-3,1,17:106.2
-5,-1,17:106.2
5,1,17:106.8
4,-1,17:106.8
-5,-5,17:106.4
1,5,17:106.1
-1,-1,18:17.3
-1,0,18:17.3
-1,1,18:17.3
0,1,18:17.3
1,1,18:17.3
1,0,18:17.3
1,-1,18:17.3
0,-1,18:17.3
0,0,18:17.3
0,-2,18:18.3
-3,1,18:106.2
-5,-1,18:106.2
5,1,18:106.8
4,-1,18:106.8
-5,-5,18:106.4
1,5,18:106.1
-1,-1,19:17.3
-1,0,19:17.3
-1,1,19:17.3
0,1,19:17.3
1,1,19:17.3
1,0,19:17.3
1,-1,19:17.3
0,-1,19:17.3
0,0,19:17.3
-2,0,19:18.3
-2,2,19:18.3
1,-3,19:18.3
2,1,19:18.3
-2,-2,19:18.3
4,-1,19:106.8
-5,-5,19:106.4
-3,1,19:106.2
-5,-1,19:106.2
5,1,19:106.8
1,5,19:106.1
-1,0,20:17.3
0,0,20:17.3
1,0,20:17.3
0,-1,20:17.3
0,1,20:17.3
-1,2,20:17.3
-2,2,20:17.3
2,1,20:17.3
3,1,20:17.3
1,-2,20:17.3
1,-3,20:17.3
2,-3,20:17.3
-2,-1,20:17.3
-2,-2,20:17.3
-3,2,20:18.3
-2,3,20:18.3
3,2,20:18.3
4,1,20:18.3
2,0,20:18.3
2,-4,20:18.3
3,-3,20:18.3
-2,-3,20:18.3
-3,-2,20:18.3
1,5,20:106.1
4,-1,20:106.8
-5,-5,20:106.4
-3,1,20:106.2
-5,-1,20:106.2
5,1,20:106.8
-1,0,21:17.3
0,0,21:17.3
1,0,21:17.3
0,-1,21:17.3
0,1,21:17.3
2,0,21:18.3
-1,-1,21:18.3
1,5,21:106.1
4,-1,21:106.8
-5,-5,21:106.4
-3,1,21:106.2
-5,-1,21:106.2
5,1,21:106.8
-1,0,22:17.3
0,0,22:17.3
1,0,22:17.3
0,-1,22:17.3
0,1,22:17.3
-2,0,22:18.3
0,2,22:18.3
1,5,22:106.1
4,-1,22:106.8
-5,-5,22:106.4
-3,1,22:106.2
-5,-1,22:106.2
5,1,22:106.8
-1,0,23:17.3
0,0,23:17.3
1,0,23:17.3
0,-1,23:17.3
0,1,23:17.3
0,-2,23:18.3
1,5,23:106.1
4,-1,23:106.8
-5,-5,23:106.4
-3,1,23:106.2
-5,-1,23:106.2
5,1,23:106.8
-1,0,24:17.3
0,0,24:17.3
1,0,24:17.3
0,-1,24:17.3
0,1,24:17.3
1,5,24:106.1
4,-1,24:106.8
-5,-5,24:106.4
-3,1,24:106.2
-5,-1,24:106.2
5,1,24:106.8
-1,0,25:17.3
0,0,25:17.3
1,0,25:17.3
0,-1,25:17.3
0,1,25:17.3
2,0,25:18.3
0,2,25:18.3
1,5,25:106.1
4,-1,25:106.8
-5,-5,25:106.4
-3,1,25:106.2
-5,-1,25:106.2
5,1,25:106.8
0,-1,26:17.3
0,0,26:17.3
0,1,26:17.3
-1,0,26:17.3
1,0,26:17.3
0,-2,26:17.3
0,2,26:17.3
-2,0,26:17.3
2,0,26:17.3
1,5,26:106.1
4,-1,26:106.8
-5,-5,26:106.4
-3,1,26:106.2
-5,-1,26:106.2
5,1,26:106.8
2,0,27:17.3
3,0,27:17.3
0,2,27:17.3
0,3,27:17.3
-2,0,27:17.3
-3,0,27:17.3
0,-2,27:17.3
0,-3,27:17.3
0,0,27:17.3
1,5,27:106.1
4,-1,27:106.8
-5,-5,27:106.4
-3,1,27:106.2
-5,-1,27:106.2
5,1,27:106.8
5,0,27:18.3
0,0,28:17.3
-3,0,28:17.3
-4,0,28:17.3
0,3,28:17.3
0,4,28:17.3
3,0,28:17.3
4,0,28:17.3
0,-3,28:17.3
0,-4,28:17.3
1,-3,28:17.3
-3,1,28:17.3
-1,4,28:17.3
5,0,28:17.3
5,1,28:17.3
1,5,28:106.1
4,-1,28:106.8
-5,-5,28:106.4
-5,-1,28:106.2
-5,0,28:18.3
-1,-5,28:18.3
-1,-4,28:18.3
3,-4,28:18.3
3,-3,28:18.3
5,2,28:18.3
-1,5,28:18.3
4,0,29:17.3
4,-1,29:17.3
5,1,29:17.3
5,2,29:17.3
-1,4,29:17.3
-1,5,29:17.3
0,3,29:17.3
1,3,29:17.3
-4,0,29:17.3
-5,0,29:17.3
-3,1,29:17.3
-3,2,29:17.3
-4,2,29:17.3
0,-4,29:17.3
-1,-4,29:17.3
-1,-5,29:17.3
1,-3,29:17.3
2,-3,29:17.3
3,-3,29:17.3
3,-4,29:17.3
0,0,29:17.3
0,-1,29:17.3
-1,-1,29:17.3
0,1,29:17.3
1,1,29:17.3
1,5,29:106.1
-5,-5,29:106.4
-5,-1,29:106.2
-6,3,29:18.3
-5,3,29:18.3
-6,-3,29:18.3
-6,-2,29:18.3
-3,5,29:18.3
-3,6,29:18.3
1,6,29:18.3
1,7,29:18.3
-2,-7,29:18.3
-1,-7,29:18.3
0,6,29:18.3
-7,-2,29:18.3
4,-5,29:18.3
5,-5,29:18.3
3,-6,29:18.3
6,-2,29:18.3
6,-1,29:18.3
6,2,29:18.3
7,2,29:18.3
7,3,29:18.3
4,3,29:18.3
-1,-6,29:18.3
5,-1,29:18.3
1,1,30:17.3
2,1,30:17.3
-1,-1,30:17.3
-2,-1,30:17.3
-2,-2,30:17.3
-1,-4,30:17.3
-2,-4,30:17.3
-1,-5,30:17.3
-1,-6,30:17.3
-1,-7,30:17.3
3,-4,30:17.3
3,-5,30:17.3
2,-5,30:17.3
4,-5,30:17.3
3,-6,30:17.3
5,-5,30:17.3
4,-1,30:17.3
5,-1,30:17.3
6,-1,30:17.3
6,-2,30:17.3
5,2,30:17.3
4,2,30:17.3
4,3,30:17.3
6,2,30:17.3
7,2,30:17.3
7,3,30:17.3
-1,5,30:17.3
-1,6,30:17.3
0,6,30:17.3
1,6,30:17.3
1,7,30:17.3
-2,5,30:17.3
-3,5,30:17.3
-3,6,30:17.3
-4,2,30:17.3
-5,2,30:17.3
-5,3,30:17.3
-6,3,30:17.3
-5,0,30:17.3
-5,-1,30:17.3
-6,-1,30:17.3
-6,-2,30:17.3
-7,-2,30:17.3
1,3,30:17.3
1,4,30:17.3
0,1,30:17.3
-1,1,30:17.3
-1,2,30:17.3
2,-3,30:17.3
2,-2,30:17.3
-6,-3,30:17.3
-2,-7,30:17.3
1,5,30:106.1
-5,-5,30:106.4
-2,-7,31:17.3
-2,-8,31:17.3
-2,-9,31:17.3
-3,-9,31:17.3
-1,-9,31:17.3
-2,-10,31:17.3
-7,-2,31:17.3
-8,-2,31:17.3
-9,-2,31:17.3
-9,-3,31:17.3
-9,-1,31:17.3
-10,-2,31:17.3
-6,-3,31:17.3
-6,-4,31:17.3
-6,-5,31:17.3
-7,-5,31:17.3
-6,-6,31:17.3
-5,-5,31:17.3
-2,-4,31:17.3
-3,-4,31:17.3
-3,-3,31:17.3
-1,-1,31:17.3
0,-1,31:17.3
0,-2,31:17.3
-2,-1,31:17.3
-3,-1,31:17.3
-3,0,31:17.3
-5,0,31:17.3
-6,0,31:17.3
-6,1,31:17.3
-7,1,31:17.3
-8,1,31:17.3
-8,2,31:17.3
-6,3,31:17.3
-6,4,31:17.3
-7,4,31:17.3
-7,5,31:17.3
-7,6,31:17.3
-8,6,31:17.3
-6,6,31:17.3
-7,7,31:17.3
-4,2,31:17.3
-4,3,31:17.3
-3,3,31:17.3
-4,6,31:17.3
-4,7,31:17.3
-4,8,31:17.3
-3,8,31:17.3
-4,9,31:17.3
-1,6,31:17.3
-1,7,31:17.3
-2,5,31:17.3
1,7,31:17.3
2,7,31:17.3
2,8,31:17.3
2,9,31:17.3
1,9,31:17.3
3,9,31:17.3
2,10,31:17.3
4,3,31:17.3
4,4,31:17.3
4,5,31:17.3
3,5,31:17.3
4,6,31:17.3
5,5,31:17.3
7,3,31:17.3
8,3,31:17.3
7,4,31:17.3
6,2,31:17.3
6,1,31:17.3
2,1,31:17.3
2,0,31:17.3
2,2,31:17.3
-1,2,31:17.3
1,4,31:17.3
0,4,31:17.3
2,-3,31:17.3
2,-5,31:17.3
1,-5,31:17.3
1,-6,31:17.3
3,-6,31:17.3
3,-7,31:17.3
4,-7,31:17.3
4,-8,31:17.3
5,-7,31:17.3
5,-5,31:17.3
5,-4,31:17.3
6,-4,31:17.3
6,-1,31:17.3
7,-1,31:17.3
8,-1,31:17.3
8,-2,31:17.3
8,0,31:17.3
9,-1,31:17.3
4,-1,31:17.3
-10,-1,31:18.3
-10,-3,31:18.3
-11,-2,31:18.3
-8,-5,31:18.3
-7,-6,31:18.3
-6,-7,31:18.3
-5,-6,31:18.3
-4,-5,31:18.3
-5,-4,31:18.3
-7,-4,31:18.3
-3,-8,31:18.3
-4,-9,31:18.3
-3,-10,31:18.3
-2,-11,31:18.3
-1,-10,31:18.3
-1,-8,31:18.3
3,-8,31:18.3
4,-9,31:18.3
5,-8,31:18.3
6,-7,31:18.3
5,-6,31:18.3
6,-5,31:18.3
7,-4,31:18.3
6,-3,31:18.3
2,-6,31:18.3
1,-7,31:18.3
0,-6,31:18.3
1,-3,31:18.3
2,-2,31:18.3
3,-3,31:18.3
5,-1,31:18.3
8,-3,31:18.3
9,-2,31:18.3
10,-1,31:18.3
9,0,31:18.3
8,1,31:18.3
7,1,31:18.3
6,0,31:18.3
5,1,31:18.3
7,2,31:18.3
8,2,31:18.3
9,3,31:18.3
8,4,31:18.3
7,5,31:18.3
6,4,31:18.3
6,5,31:18.3
5,6,31:18.3
4,7,31:18.3
3,6,31:18.3
2,5,31:18.3
1,6,31:18.3
0,7,31:18.3
1,8,31:18.3
0,9,31:18.3
2,11,31:18.3
1,10,31:18.3
3,10,31:18.3
4,9,31:18.3
3,8,31:18.3
-1,8,31:18.3
-2,7,31:18.3
-2,8,31:18.3
-3,9,31:18.3
-4,10,31:18.3
-5,9,31:18.3
-6,7,31:18.3
-5,6,31:18.3
-6,5,31:18.3
-8,7,31:18.3
-7,9,31:18.3
-7,8,31:18.3
-9,6,31:18.3
-8,5,31:18.3
-8,3,31:18.3
-7,2,31:18.3
-9,2,31:18.3
1,5,31:106.1
-1,0,31:18.3
-10,-2,32:17.3
-8,6,32:17.3
-4,9,32:17.3
-8,2,32:17.3
-7,-5,32:17.3
-2,-10,32:17.3
4,-8,32:17.3
2,-5,32:17.3
-2,-7,32:17.3
-3,-3,32:18.3
6,-4,32:17.3
8,-2,32:17.3
8,0,32:17.3
4,-1,32:17.3
2,1,32:17.3
-1,-1,32:17.3
1,9,32:17.3
3,9,32:17.3
-3,3,32:17.3
-6,0,32:17.3
1,4,32:17.3
-4,6,32:17.3
-6,4,32:17.3
4,4,32:17.3
4,6,32:17.3
8,3,32:17.3
7,4,32:17.3
6,-1,32:17.3
5,-7,32:17.3
5,-5,32:17.3
-3,-9,32:17.3
-8,5,32:18.3
-9,6,32:18.3
-8,7,32:18.3
-7,4,32:18.3
-6,3,32:18.3
-6,5,32:18.3
-5,4,32:18.3
-5,6,32:18.3
-4,5,32:18.3
-3,6,32:18.3
-4,7,32:18.3
-4,8,32:18.3
-3,9,32:18.3
-4,10,32:18.3
-5,9,32:18.3
2,9,32:18.3
2,10,32:18.3
1,10,32:18.3
0,9,32:18.3
1,8,32:18.3
3,10,32:18.3
4,9,32:18.3
3,8,32:18.3
2,7,32:18.3
0,4,32:18.3
1,3,32:18.3
1,5,32:17.3
2,4,32:18.3
3,5,32:18.3
3,6,32:18.3
4,7,32:18.3
5,6,32:18.3
5,5,32:18.3
4,3,32:18.3
5,4,32:18.3
7,3,32:18.3
6,4,32:18.3
7,5,32:18.3
8,4,32:18.3
9,3,32:18.3
8,2,32:18.3
6,2,32:18.3
6,1,32:18.3
7,0,32:18.3
8,1,32:18.3
9,0,32:18.3
9,-1,32:18.3
8,-1,32:18.3
7,-1,32:18.3
7,-2,32:18.3
8,-3,32:18.3
9,-2,32:18.3
6,-2,32:18.3
5,-1,32:18.3
6,0,32:18.3
4,0,32:18.3
4,-2,32:18.3
3,-1,32:18.3
3,1,32:18.3
2,0,32:18.3
1,1,32:18.3
2,2,32:18.3
4,5,32:18.3
2,8,32:18.3
1,7,32:18.3
5,-4,32:18.3
7,-4,32:18.3
6,-3,32:18.3
6,-5,32:18.3
5,-6,32:18.3
6,-7,32:18.3
5,-8,32:18.3
4,-9,32:18.3
3,-8,32:18.3
3,-7,32:18.3
4,-7,32:18.3
3,-6,32:18.3
2,-6,32:18.3
1,-6,32:18.3
1,-5,32:18.3
3,-5,32:18.3
2,-4,32:18.3
2,-3,32:18.3
4,-5,32:18.3
-1,-7,32:18.3
-2,-8,32:18.3
-2,-9,32:18.3
-1,-9,32:18.3
-1,-10,32:18.3
-2,-11,32:18.3
-3,-10,32:18.3
-4,-9,32:18.3
-3,-8,32:18.3
-3,-7,32:18.3
-2,-6,32:18.3
-2,-4,32:18.3
-3,-4,32:18.3
-2,-3,32:18.3
-3,-2,32:18.3
-4,-3,32:18.3
-5,-5,32:18.3
-6,-6,32:18.3
-6,-5,32:18.3
-7,-6,32:18.3
-8,-5,32:18.3
-7,-4,32:18.3
-6,-4,32:18.3
-6,-3,32:18.3
-7,-2,32:18.3
-8,-2,32:18.3
-9,-2,32:18.3
-9,-3,32:18.3
-10,-3,32:18.3
-11,-2,32:18.3
-10,-1,32:18.3
-9,-1,32:18.3
-8,1,32:18.3
-9,2,32:18.3
-8,3,32:18.3
-7,2,32:18.3
-6,1,32:18.3
-5,0,32:18.3
-5,-1,32:18.3
-6,-1,32:18.3
-7,0,32:18.3
-3,-1,32:18.3
-3,0,32:18.3
-2,-1,32:18.3
-1,-2,32:18.3
-1,0,32:18.3
0,0,32:18.3
0,-1,32:18.3
0,-2,32:18.3
-1,2,32:18.3
-3,2,32:18.3
-2,3,32:18.3
-3,4,32:18.3
-4,4,32:18.3
-4,3,32:18.3
-4,2,32:18.3
-7,5,32:18.3
-7,6,32:18.3
-6,6,32:18.3
-7,7,32:18.3
-3,8,32:18.3
-2,5,32:18.3
-1,6,32:18.3
-1,7,32:18.3
-10,-2,33:18.3
-8,2,33:18.3
-8,6,33:18.3
-6,0,33:18.3
-6,4,33:18.3
-4,6,33:18.3
-4,9,33:18.3
-3,3,33:18.3
-1,-1,33:18.3
-3,-3,33:18.3
-7,-5,33:18.3
-3,-9,33:18.3
-2,-10,33:18.3
-2,-7,33:18.3
2,-5,33:18.3
4,-8,33:18.3
5,-7,33:18.3
5,-5,33:18.3
6,-4,33:18.3
6,-1,33:18.3
8,-2,33:18.3
8,0,33:18.3
4,-1,33:18.3
2,1,33:18.3
1,4,33:18.3
4,4,33:18.3
4,6,33:18.3
3,9,33:18.3
1,9,33:18.3
7,4,33:18.3
8,3,33:18.3
