[META]
version=2.0
spawnOnBlockType=2
spawnSunlight=True
spawnDarkness=False
spawnWater=False
spawnLava=False
underFill=True
randomRotation=True
dig=True
tree=False
branch=False
needsFoundation=True
rarity=10
collisionPercentage=2
spawnElevationMin=0
spawnElevationMax=128
spawnInBiome=All
[DATA]
-2,-2,0:3
-1,-2,0:1
0,-2,0:1
1,-2,0:3
-2,-1,0:1
-1,-1,0:3
0,-1,0:3
1,-1,0:1
-2,0,0:1
-1,0,0:3
0,0,0:3
1,0,0:1
-2,1,0:1
-1,1,0:3
0,1,0:3
1,1,0:1
-2,2,0:3
-1,2,0:1
0,2,0:1
1,2,0:3
-2,-2,1:2
-1,-2,1:1
0,-2,1:1
1,-2,1:2
-2,-1,1:1
-1,-1,1:3
0,-1,1:3
1,-1,1:1
-2,0,1:1
-1,0,1:3
0,0,1:3
1,0,1:1
-2,1,1:1
-1,1,1:3
0,1,1:3
1,1,1:1
-2,2,1:2
-1,2,1:1
0,2,1:1
1,2,1:2
-1,-2,2:1
0,-2,2:1
-2,-1,2:1
-1,-1,2:1
0,-1,2:1
1,-1,2:18
-2,0,2:1
-1,0,2:1
0,0,2:1
1,0,2:1
-1,1,2:1
0,1,2:1
0,2,2:18
-1,-1,3:1
0,-1,3:18
1,-1,3:18
-2,0,3:1
-1,0,3:1
0,0,3:1
1,0,3:106.2
-1,1,3:106.4
0,1,3:106.4
0,2,3:18
0,-1,4:18
-1,0,4:1
0,0,4:106.2
-1,1,4:106.4
0,-1,5:18
