[META]
version=2.0
spawnOnBlockType=2,1
spawnSunlight=True
spawnDarkness=False
spawnWater=False
spawnLava=False
underFill=True
randomRotation=True
dig=True
tree=True
branch=False
needsFoundation=True
rarity=10
collisionPercentage=2
spawnElevationMin=0
spawnElevationMax=128
spawnInBiome=OttaWildlands
[DATA]
-1,-1,0:17.3
-2,0,0:17.3
-1,0,0:17.3
0,0,0:17.3
-1,1,0:17.3
0,1,0:17.3
-1,-1,1:17.3
-2,0,1:17.3
-1,0,1:17.3
0,0,1:17.3
-1,1,1:17.3
0,1,1:17.3
-1,-1,2:17.3
-2,0,2:17.3
-1,0,2:17.3
0,0,2:17.3
-1,1,2:17.3
0,1,2:17.3
-2,0,3:17.3
-1,0,3:17.3
-1,1,3:17.3
-1,0,4:17.3
-1,0,5:17.3
-1,0,6:17.3
-1,0,7:17.3
-1,0,8:17.3
-1,0,9:17.3
-1,0,10:17.3
-1,0,11:17.3
-1,0,12:17.3
-1,0,13:17.3
-1,-2,14:103
-1,0,14:17.3
-1,-2,15:85
-1,0,15:17.3
-1,-2,16:85
-1,0,16:17.3
0,1,16:103
-1,-2,17:85
-1,0,17:17.3
0,1,17:85
-1,-2,18:17
-1,-1,18:17
-1,0,18:17.3
0,1,18:85
-2,-4,19:18
-1,-4,19:18
0,-4,19:18
-3,-3,19:18
-2,-3,19:18
-1,-3,19:18
0,-3,19:18
1,-3,19:18
-4,-2,19:18
-3,-2,19:18
-2,-2,19:18
-1,-2,19:17.3
0,-2,19:18
1,-2,19:18
2,-2,19:18
-5,-1,19:18
-4,-1,19:18
-3,-1,19:18
-2,-1,19:18
-1,-1,19:18
0,-1,19:18
1,-1,19:18
2,-1,19:18
-5,0,19:18
-4,0,19:18
-3,0,19:18
-2,0,19:17
-1,0,19:17.3
0,0,19:17
1,0,19:18
2,0,19:18
3,0,19:18
-5,1,19:18
-4,1,19:18
-3,1,19:18
-2,1,19:18
-1,1,19:18
0,1,19:17
1,1,19:18
2,1,19:18
3,1,19:18
-5,2,19:18
-4,2,19:18
-3,2,19:18
-2,2,19:18
-1,2,19:18
0,2,19:18
1,2,19:18
2,2,19:18
3,2,19:18
-4,3,19:18
-3,3,19:18
-2,3,19:18
-1,3,19:18
0,3,19:18
1,3,19:18
2,3,19:18
3,3,19:18
-3,4,19:18
-2,4,19:18
-1,4,19:18
0,4,19:18
1,4,19:18
2,4,19:18
-1,5,19:18
0,5,19:18
1,5,19:18
-3,-5,20:18
-2,-5,20:18
-1,-5,20:18
0,-5,20:18
1,-5,20:18
-4,-4,20:18
-3,-4,20:18
-2,-4,20:18
-1,-4,20:18
0,-4,20:18
1,-4,20:18
-5,-3,20:18
-4,-3,20:18
-3,-3,20:18
-2,-3,20:18
-1,-3,20:18
0,-3,20:18
1,-3,20:18
2,-3,20:18
3,-3,20:18
-5,-2,20:18
-4,-2,20:18
-3,-2,20:18
-2,-2,20:18
-1,-2,20:18
0,-2,20:18
1,-2,20:18
2,-2,20:18
3,-2,20:18
4,-2,20:18
-6,-1,20:18
-5,-1,20:18
-4,-1,20:18
-3,-1,20:18
-2,-1,20:18
-1,-1,20:18
0,-1,20:18
1,-1,20:18
2,-1,20:18
3,-1,20:18
4,-1,20:18
-6,0,20:18
-5,0,20:18
-4,0,20:18
-3,0,20:17
-2,0,20:17.3
-1,0,20:18
0,0,20:18
1,0,20:18
2,0,20:18
3,0,20:18
4,0,20:18
-6,1,20:18
-5,1,20:18
-4,1,20:18
-3,1,20:18
-2,1,20:18
-1,1,20:18
0,1,20:17.3
1,1,20:17
2,1,20:18
3,1,20:18
4,1,20:18
-6,2,20:18
-5,2,20:18
-4,2,20:18
-3,2,20:18
-2,2,20:18
-1,2,20:18
0,2,20:18
1,2,20:17
2,2,20:18
3,2,20:18
4,2,20:18
-5,3,20:18
-4,3,20:18
-3,3,20:18
-2,3,20:18
-1,3,20:18
0,3,20:18
1,3,20:18
2,3,20:18
3,3,20:18
4,3,20:18
-4,4,20:18
-3,4,20:18
-2,4,20:18
-1,4,20:18
0,4,20:18
1,4,20:18
2,4,20:18
3,4,20:18
4,4,20:18
-3,5,20:18
-2,5,20:18
-1,5,20:18
0,5,20:18
1,5,20:18
2,5,20:18
3,5,20:18
-2,6,20:18
-1,6,20:18
0,6,20:18
1,6,20:18
2,6,20:18
-3,-4,21:18
-2,-4,21:18
-1,-4,21:18
0,-4,21:18
-4,-3,21:18
-3,-3,21:18
-2,-3,21:18
-1,-3,21:18
0,-3,21:18
1,-3,21:18
-5,-2,21:18
-4,-2,21:18
-3,-2,21:18
-2,-2,21:18
-1,-2,21:18
0,-2,21:18
1,-2,21:18
2,-2,21:18
-5,-1,21:18
-4,-1,21:18
-3,-1,21:18
-2,-1,21:18
-1,-1,21:18
0,-1,21:18
1,-1,21:18
2,-1,21:18
3,-1,21:18
-5,0,21:18
-4,0,21:18
-3,0,21:17.3
-2,0,21:18
-1,0,21:18
0,0,21:18
1,0,21:18
2,0,21:18
3,0,21:18
-5,1,21:18
-4,1,21:18
-3,1,21:18
-2,1,21:18
-1,1,21:18
0,1,21:18
1,1,21:18
2,1,21:18
3,1,21:18
-5,2,21:18
-4,2,21:18
-3,2,21:18
-2,2,21:18
-1,2,21:18
0,2,21:18
1,2,21:18
2,2,21:18
3,2,21:18
-4,3,21:18
-3,3,21:18
-2,3,21:18
-1,3,21:18
0,3,21:18
1,3,21:18
2,3,21:18
3,3,21:18
-3,4,21:18
-2,4,21:18
-1,4,21:18
0,4,21:18
1,4,21:18
2,4,21:18
3,4,21:18
-2,5,21:18
-1,5,21:18
0,5,21:18
1,5,21:18
2,5,21:18
-3,-3,22:18
-2,-3,22:18
-1,-3,22:18
0,-3,22:18
-3,-2,22:18
-2,-2,22:18
-1,-2,22:18
0,-2,22:18
1,-2,22:18
-4,-1,22:18
-3,-1,22:18
-2,-1,22:18
-1,-1,22:18
0,-1,22:18
1,-1,22:18
2,-1,22:18
-4,0,22:18
-3,0,22:18
-2,0,22:18
-1,0,22:18
0,0,22:18
1,0,22:18
2,0,22:18
-4,1,22:18
-3,1,22:18
-2,1,22:18
-1,1,22:18
0,1,22:18
1,1,22:18
2,1,22:18
-3,2,22:18
-2,2,22:18
-1,2,22:18
0,2,22:18
1,2,22:18
2,2,22:18
-2,3,22:18
-1,3,22:18
0,3,22:18
1,3,22:18
2,3,22:18
-2,4,22:18
-1,4,22:18
0,4,22:18
1,4,22:18
