[META]
version=2.0
spawnOnBlockType=1,2,3
spawnSunlight=True
spawnDarkness=True
spawnWater=False
spawnLava=False
underFill=True
randomRotation=True
dig=True
tree=False
branch=False
needsFoundation=True
rarity=50
collisionPercentage=5
spawnElevationMin=0
spawnElevationMax=160
spawnInBiome=OttaJungle
spawnAboveGround=False
spawnUnderGround=False
collisionBlockType=All
groupId=
diggingBranch=false
branchLimit=6
groupFrequencyMin=1
groupFrequencyMax=5
groupSeperationMin=0
groupSeperationMax=5
[DATA]
-1,-1,0:17.3
-1,0,0:17.3
-1,1,0:17.3
0,1,0:17.3
0,0,0:17.3
0,-1,0:17.3
1,-1,0:17.3
1,0,0:17.3
1,1,0:17.3
-2,1,0:17.3
-1,-2,0:17.3
2,-1,0:17.3
2,-2,0:17.3
1,2,0:17.3
2,2,0:17.3
-2,2,0:17.3
-2,0,0:17.3
-3,0,0:17.3
-3,2,0:17.3
-1,-3,0:17.3
-2,-3,0:17.3
-2,-4,0:17.3
2,3,0:17.3
3,3,0:17.3
1,-1,-1:17.3
2,-2,-1:17.3
0,-1,-1:17.3
-1,-1,-1:17.3
-1,-2,-1:17.3
-1,1,-1:17.3
-2,1,-1:17.3
1,1,-1:17.3
1,2,-1:17.3
2,2,-1:17.3
1,0,-1:17.3
0,1,-1:17.3
-1,0,-1:17.3
0,0,-1:17.3
-2,2,-1:17.3
-3,2,-1:17.3
-1,-3,-1:17.3
3,-2,-1:17.3
3,-3,-1:17.3
2,3,-1:17.3
3,3,-1:17.3
-2,-3,-1:17.3
4,2,-1:17.3
3,4,-1:17.3
-4,2,-1:17.3
-4,3,-1:17.3
-3,-4,-1:17.3
-2,-4,-1:17.3
3,-4,-1:17.3
4,-3,-1:17.3
-3,0,-1:17.3
0,-4,-1:17.3
-2,-5,-1:17.3
5,-3,-1:17.3
3,-5,-1:17.3
2,-1,-1:17.3
-4,0,-1:17.3
-5,3,-1:17.3
-4,4,-1:17.3
4,3,-1:17.3
3,5,-1:17.3
3,6,-1:17.3
4,6,-1:17.3
-4,-4,-1:17.3
-4,-5,-1:17.3
-2,-6,-1:17.3
-1,-6,-1:17.3
-1,-7,-1:17.3
5,2,-1:17.3
6,-3,-1:17.3
-5,0,-1:17.3
-2,0,-1:17.3
-5,-1,-1:17.3
-6,0,-1:17.3
-4,5,-1:17.3
-3,5,-1:17.3
-5,5,-1:17.3
-4,6,-1:17.3
-1,-1,1:17.3
-1,0,1:17.3
-1,1,1:17.3
0,1,1:17.3
0,0,1:17.3
0,-1,1:17.3
1,-1,1:17.3
1,0,1:17.3
1,1,1:17.3
1,2,1:17.3
-2,1,1:17.3
-1,-2,1:17.3
2,-1,1:17.3
-1,-1,2:17.3
-1,0,2:17.3
-1,1,2:17.3
0,1,2:17.3
0,0,2:17.3
0,-1,2:17.3
1,-1,2:17.3
1,0,2:17.3
1,1,2:17.3
-1,-1,3:17.3
-1,0,3:17.3
-1,1,3:17.3
0,1,3:17.3
0,0,3:17.3
0,-1,3:17.3
1,-1,3:17.3
1,0,3:17.3
1,1,3:17.3
-1,-1,4:17.3
-1,0,4:17.3
-1,1,4:17.3
0,1,4:17.3
0,0,4:17.3
0,-1,4:17.3
1,-1,4:17.3
1,0,4:17.3
1,1,4:17.3
-1,-1,5:17.3
0,-1,5:17.3
1,-1,5:17.3
1,0,5:17.3
-1,0,5:17.3
-1,1,5:17.3
0,1,5:17.3
1,1,5:17.3
0,0,5:17.3
-1,2,5:17.3
-2,2,5:17.3
-2,3,5:17.3
0,-2,5:17.3
0,-3,5:17.3
1,-3,5:17.3
-3,3,5:18.3
-2,4,5:18.3
-1,3,5:18.3
-2,1,5:18.3
-3,1,5:18.3
-2,-1,5:18.3
-1,-3,5:18.3
0,-4,5:18.3
1,-4,5:18.3
2,-3,5:18.3
1,-2,5:18.3
2,1,5:18.3
-1,-1,6:17.3
-1,0,6:17.3
-1,1,6:17.3
0,1,6:17.3
0,0,6:17.3
0,-1,6:17.3
1,-1,6:17.3
1,0,6:17.3
1,1,6:17.3
-2,3,6:18.3
1,-3,6:18.3
0,-3,6:18.3
-1,-1,7:17.3
-1,0,7:17.3
-1,1,7:17.3
0,1,7:17.3
0,0,7:17.3
0,-1,7:17.3
1,-1,7:17.3
1,0,7:17.3
1,1,7:17.3
-1,-1,8:17.3
-1,0,8:17.3
-1,1,8:17.3
0,1,8:17.3
0,0,8:17.3
0,-1,8:17.3
1,-1,8:17.3
1,0,8:17.3
1,1,8:17.3
-2,0,8:17.3
-3,0,8:17.3
-3,-1,8:17.3
-4,0,8:17.3
-5,1,8:17.3
-4,1,8:17.3
2,1,8:17.3
3,1,8:17.3
3,2,8:17.3
4,2,8:17.3
4,3,8:17.3
1,-2,8:17.3
1,-3,8:17.3
0,-3,8:17.3
0,-4,8:17.3
-1,2,8:17.3
-2,2,8:18.3
-1,3,8:18.3
0,2,8:18.3
3,3,8:18.3
4,4,8:18.3
5,3,8:18.3
3,0,8:18.3
4,0,8:18.3
2,-3,8:18.3
0,-2,8:18.3
-1,-4,8:18.3
0,-5,8:18.3
1,-4,8:18.3
-4,-1,8:18.3
-3,-2,8:18.3
-2,-1,8:18.3
-5,0,8:18.3
-6,1,8:18.3
-5,2,8:18.3
-1,-1,9:17.3
-1,0,9:17.3
-1,1,9:17.3
0,1,9:17.3
0,0,9:17.3
0,-1,9:17.3
1,-1,9:17.3
1,0,9:17.3
1,1,9:17.3
-5,1,9:18.3
4,3,9:18.3
4,2,9:18.3
1,-3,9:18.3
0,-3,9:18.3
0,-4,9:18.3
-1,2,9:18.3
-1,-1,10:17.3
-1,0,10:17.3
-1,1,10:17.3
0,1,10:17.3
0,0,10:17.3
0,-1,10:17.3
1,-1,10:17.3
1,0,10:17.3
1,1,10:17.3
-1,-1,11:17.3
-1,0,11:17.3
-1,1,11:17.3
0,1,11:17.3
0,0,11:17.3
0,-1,11:17.3
1,0,11:17.3
1,-1,11:17.3
1,2,11:17.3
1,1,11:17.3
0,2,11:18.3
1,3,11:18.3
2,2,11:18.3
-1,-1,12:17.3
-1,0,12:17.3
-1,1,12:17.3
0,1,12:17.3
0,0,12:17.3
1,0,12:17.3
1,-1,12:17.3
0,-1,12:17.3
1,1,12:17.3
-1,-1,13:17.3
-1,0,13:17.3
-1,1,13:17.3
0,1,13:17.3
0,0,13:17.3
0,-1,13:17.3
1,-1,13:17.3
1,0,13:17.3
1,1,13:17.3
2,0,13:17.3
3,0,13:17.3
3,-1,13:17.3
-2,0,13:17.3
-3,0,13:17.3
-3,1,13:17.3
-3,2,13:17.3
0,-2,13:17.3
-1,-2,13:17.3
-3,3,13:17.3
-4,3,13:17.3
-3,4,13:17.3
-2,3,13:17.3
4,1,13:17.3
4,0,13:17.3
-1,-3,13:17.3
-1,-4,13:17.3
-4,2,13:18.3
-5,3,13:18.3
-4,4,13:18.3
-3,5,13:18.3
-2,4,13:18.3
-2,2,13:18.3
-1,3,13:18.3
-4,0,13:18.3
-3,-1,13:18.3
-4,-1,13:18.3
-2,-3,13:18.3
-2,-4,13:18.3
-1,-5,13:18.3
0,-4,13:18.3
1,-2,13:18.3
3,-2,13:18.3
2,-1,13:18.3
4,-1,13:18.3
5,0,13:18.3
4,2,13:18.3
3,1,13:18.3
5,1,13:18.3
-1,-1,14:17.3
-1,0,14:17.3
-1,1,14:17.3
0,1,14:17.3
0,0,14:17.3
0,-1,14:17.3
1,-1,14:17.3
1,0,14:17.3
1,1,14:17.3
-4,3,14:18.3
-3,3,14:18.3
-3,4,14:18.3
-2,3,14:18.3
-1,-4,14:18.3
-1,-3,14:18.3
4,0,14:18.3
4,1,14:18.3
3,-1,14:18.3
-1,-1,15:17.3
-1,0,15:17.3
-1,1,15:17.3
0,1,15:17.3
0,0,15:17.3
0,-1,15:17.3
1,-1,15:17.3
1,0,15:17.3
1,1,15:17.3
-1,-1,16:17.3
-1,0,16:17.3
-1,1,16:17.3
0,1,16:17.3
0,0,16:17.3
0,-1,16:17.3
1,-1,16:17.3
1,0,16:17.3
1,1,16:17.3
-1,-1,17:17.3
-1,0,17:17.3
-1,1,17:17.3
0,1,17:17.3
0,0,17:17.3
0,-1,17:17.3
1,-1,17:17.3
1,0,17:17.3
1,1,17:17.3
-2,2,17:17.3
-2,1,17:17.3
-2,3,17:17.3
2,0,17:17.3
3,1,17:17.3
3,0,17:17.3
4,1,17:17.3
-1,-2,17:17.3
-1,-3,17:17.3
0,-3,17:17.3
-1,-4,17:17.3
-2,-3,17:17.3
-3,3,17:17.3
-4,3,17:17.3
-3,4,17:17.3
-2,-4,17:18.3
-3,-3,17:18.3
-2,-2,17:18.3
-1,-5,17:18.3
0,-4,17:18.3
1,-3,17:18.3
0,-2,17:18.3
-3,2,17:18.3
-4,2,17:18.3
-5,3,17:18.3
-4,4,17:18.3
-3,5,17:18.3
-2,4,17:18.3
-1,3,17:18.3
3,2,17:18.3
4,2,17:18.3
4,0,17:18.3
5,1,17:18.3
3,-1,17:18.3
-2,0,17:18.3
-1,-1,18:17.3
-1,0,18:17.3
-1,1,18:17.3
0,1,18:17.3
0,0,18:17.3
0,-1,18:17.3
1,-1,18:17.3
1,0,18:17.3
1,1,18:17.3
-4,3,18:18.3
-3,3,18:18.3
-3,4,18:18.3
-3,2,18:18.3
-2,3,18:18.3
-2,-3,18:18.3
-1,-4,18:18.3
0,-3,18:18.3
3,1,18:18.3
3,0,18:18.3
4,1,18:18.3
3,2,18:18.3
-1,-1,19:17.3
-1,0,19:17.3
-1,1,19:17.3
0,1,19:17.3
0,0,19:17.3
0,-1,19:17.3
1,-1,19:17.3
1,0,19:17.3
1,1,19:17.3
-1,-1,20:17.3
-1,0,20:17.3
-1,1,20:17.3
0,1,20:17.3
0,0,20:17.3
0,-1,20:17.3
1,-1,20:17.3
1,0,20:17.3
1,1,20:17.3
-1,-1,21:17.3
-1,0,21:17.3
-1,1,21:17.3
0,1,21:17.3
0,0,21:17.3
0,-1,21:17.3
1,-1,21:17.3
1,0,21:17.3
1,1,21:17.3
-1,-1,22:17.3
-1,0,22:17.3
-1,1,22:17.3
0,1,22:17.3
0,0,22:17.3
1,0,22:17.3
1,1,22:17.3
1,-1,22:17.3
0,-1,22:17.3
0,2,22:17.3
0,3,22:17.3
0,4,22:17.3
0,5,22:17.3
-2,0,22:17.3
-3,0,22:17.3
-3,1,22:17.3
-4,1,22:17.3
-5,1,22:17.3
-6,1,22:17.3
-6,2,22:17.3
-7,2,22:17.3
-8,2,22:17.3
-6,3,22:17.3
-6,4,22:17.3
-6,0,22:17.3
-7,0,22:17.3
-7,-1,22:17.3
-7,-2,22:17.3
-3,-1,22:17.3
-3,-2,22:17.3
-4,-2,22:17.3
-1,-2,22:17.3
-1,-3,22:17.3
0,-3,22:17.3
0,-4,22:17.3
0,-5,22:17.3
0,-6,22:17.3
1,-6,22:17.3
0,-7,22:17.3
0,-8,22:17.3
-1,-6,22:17.3
-2,-6,22:17.3
-2,-7,22:17.3
-3,-7,22:17.3
-4,-7,22:17.3
-7,-3,22:17.3
-7,-4,22:17.3
-8,-4,22:17.3
-9,-4,22:17.3
-8,-5,22:17.3
-5,-6,22:17.3
-5,-7,22:17.3
-5,-8,22:17.3
1,-8,22:17.3
2,-9,22:17.3
1,-3,22:17.3
2,0,22:17.3
3,0,22:17.3
3,-1,22:17.3
3,-2,22:17.3
4,-2,22:17.3
5,-2,22:17.3
5,-3,22:17.3
5,-4,22:17.3
5,-5,22:17.3
6,-4,22:17.3
6,-2,22:17.3
7,-1,22:17.3
6,-1,22:17.3
8,-1,22:17.3
8,0,22:17.3
3,1,22:17.3
4,1,22:17.3
5,1,22:17.3
5,2,22:17.3
5,3,22:17.3
5,4,22:17.3
6,4,22:17.3
7,5,22:17.3
7,4,22:17.3
4,4,22:17.3
4,5,22:17.3
8,-2,22:17.3
9,-2,22:17.3
3,5,22:17.3
3,6,22:17.3
1,4,22:17.3
0,6,22:17.3
-1,6,22:17.3
-2,6,22:17.3
-3,6,22:17.3
-3,7,22:17.3
-3,8,22:17.3
-2,8,22:17.3
-2,9,22:17.3
-1,4,22:17.3
-2,4,22:17.3
-2,3,22:17.3
-6,-4,22:18.3
-6,-3,22:18.3
-6,-2,22:18.3
-6,-1,22:18.3
-7,-5,22:18.3
-8,-6,22:18.3
-9,-6,22:18.3
-9,-5,22:18.3
-10,-5,22:18.3
-10,-4,22:18.3
-10,-3,22:18.3
-9,-3,22:18.3
-8,0,22:18.3
-8,1,22:18.3
-7,1,22:18.3
-9,2,22:18.3
-9,1,22:18.3
-9,3,22:18.3
-7,4,22:18.3
-7,5,22:18.3
-6,5,22:18.3
-5,5,22:18.3
-5,4,22:18.3
-4,7,22:18.3
-4,8,22:18.3
-4,9,22:18.3
-3,9,22:18.3
-2,10,22:18.3
-1,9,22:18.3
-1,8,22:18.3
-2,7,22:18.3
0,7,22:18.3
-1,5,22:18.3
-2,5,22:18.3
-3,4,22:18.3
-2,2,22:18.3
-1,3,22:18.3
1,5,22:18.3
2,4,22:18.3
1,3,22:18.3
2,6,22:18.3
2,7,22:18.3
3,7,22:18.3
4,7,22:18.3
4,6,22:18.3
6,5,22:18.3
6,6,22:18.3
7,6,22:18.3
8,6,22:18.3
8,5,22:18.3
6,3,22:18.3
6,2,22:18.3
3,2,22:18.3
2,1,22:18.3
2,-1,22:18.3
5,-1,22:18.3
7,0,22:18.3
8,1,22:18.3
9,0,22:18.3
10,-2,22:18.3
9,-1,22:18.3
9,-3,22:18.3
7,-2,22:18.3
6,-3,22:18.3
7,-4,22:18.3
6,-5,22:18.3
5,-6,22:18.3
4,-5,22:18.3
3,-3,22:18.3
2,-3,22:18.3
1,-2,22:18.3
1,-4,22:18.3
1,-5,22:18.3
2,-6,22:18.3
1,-7,22:18.3
2,-8,22:18.3
3,-9,22:18.3
2,-10,22:18.3
1,-9,22:18.3
-1,-9,22:18.3
-1,-8,22:18.3
-1,-7,22:18.3
-3,-8,22:18.3
-5,-9,22:18.3
-4,-8,22:18.3
-6,-9,22:18.3
-6,-8,22:18.3
-6,-6,22:18.3
-4,-6,22:18.3
-5,-5,22:18.3
-2,-5,22:18.3
-4,-3,22:18.3
-4,-1,22:18.3
-3,-3,22:18.3
0,9,22:18.3
-1,10,22:18.3
-2,11,22:18.3
-3,10,22:18.3
-5,10,22:18.3
-5,9,22:18.3
-6,9,22:18.3
-5,8,22:18.3
-6,6,22:18.3
-7,6,22:18.3
-8,6,22:18.3
-8,5,22:18.3
-9,6,22:18.3
-7,7,22:18.3
-8,3,22:18.3
-10,1,22:18.3
-11,2,22:18.3
-10,2,22:18.3
-10,3,22:18.3
-11,-4,22:18.3
-7,-9,22:18.3
-6,-10,22:18.3
-2,-9,22:18.3
-2,-10,22:18.3
-1,-10,22:18.3
2,-11,22:18.3
3,-10,22:18.3
4,-9,22:18.3
3,-8,22:18.3
-5,-2,22:18.3
-3,-6,22:18.3
5,-7,22:18.3
6,-7,22:18.3
9,-4,22:18.3
10,-4,22:18.3
9,-5,22:18.3
11,-2,22:18.3
11,-1,22:18.3
9,1,22:18.3
10,1,22:18.3
12,-2,22:18.3
9,6,22:18.3
8,4,22:18.3
7,7,22:18.3
8,7,22:18.3
3,8,22:18.3
3,9,22:18.3
4,8,22:18.3
5,8,22:18.3
2,9,22:18.3
3,10,22:18.3
4,10,22:18.3
1,-10,22:18.3
-2,-11,22:18.3
-3,-10,22:18.3
-9,-7,22:18.3
-10,-7,22:18.3
-1,-1,23:17.3
-1,0,23:17.3
-1,1,23:17.3
0,1,23:17.3
0,0,23:17.3
0,-1,23:17.3
1,-1,23:17.3
1,0,23:17.3
1,1,23:17.3
-9,-4,23:18.3
-8,-5,23:18.3
-8,-4,23:18.3
-7,-4,23:18.3
-7,-3,23:18.3
-7,-2,23:18.3
-7,-1,23:18.3
-7,0,23:18.3
-6,0,23:18.3
-6,1,23:18.3
-7,2,23:18.3
-8,2,23:18.3
-6,2,23:18.3
-5,1,23:18.3
-4,1,23:18.3
-4,-2,23:18.3
-3,-2,23:18.3
-3,-1,23:18.3
-2,0,23:18.3
-3,0,23:18.3
-3,1,23:18.3
-2,1,23:18.3
-2,-1,23:18.3
-5,2,23:18.3
-6,3,23:18.3
-6,4,23:18.3
-3,6,23:18.3
-3,7,23:18.3
-3,8,23:18.3
-2,8,23:18.3
-2,9,23:18.3
-2,6,23:18.3
-2,4,23:18.3
-2,5,23:18.3
-1,5,23:18.3
-1,6,23:18.3
0,6,23:18.3
0,5,23:18.3
0,4,23:18.3
-1,4,23:18.3
-1,3,23:18.3
0,3,23:18.3
0,2,23:18.3
-1,2,23:18.3
-2,2,23:18.3
-2,3,23:18.3
-3,2,23:18.3
-2,-2,23:18.3
-1,-2,23:18.3
-1,-3,23:18.3
0,-3,23:18.3
1,-3,23:18.3
0,-4,23:18.3
0,-5,23:18.3
0,-6,23:18.3
0,-7,23:18.3
0,-8,23:18.3
1,-8,23:18.3
2,-9,23:18.3
1,-6,23:18.3
-1,-6,23:18.3
-2,-7,23:18.3
-2,-6,23:18.3
-1,-7,23:18.3
1,-7,23:18.3
1,-9,23:18.3
-3,-7,23:18.3
-4,-7,23:18.3
-5,-7,23:18.3
-5,-8,23:18.3
-6,-7,23:18.3
-5,-6,23:18.3
-3,-8,23:18.3
-6,-2,23:18.3
-5,-2,23:18.3
-6,-3,23:18.3
-4,0,23:18.3
-4,-1,23:18.3
-3,-3,23:18.3
-4,-3,23:18.3
-7,1,23:18.3
-9,2,23:18.3
-6,5,23:18.3
-7,6,23:18.3
-7,5,23:18.3
-5,4,23:18.3
-4,2,23:18.3
2,-1,23:18.3
2,0,23:18.3
2,1,23:18.3
1,2,23:18.3
2,2,23:18.3
1,3,23:18.3
1,4,23:18.3
3,5,23:18.3
3,6,23:18.3
4,5,23:18.3
4,4,23:18.3
5,4,23:18.3
6,4,23:18.3
7,5,23:18.3
7,4,23:18.3
5,3,23:18.3
5,2,23:18.3
5,1,23:18.3
4,1,23:18.3
3,1,23:18.3
3,0,23:18.3
3,-1,23:18.3
3,-2,23:18.3
4,-2,23:18.3
5,-2,23:18.3
5,-4,23:18.3
5,-5,23:18.3
5,-3,23:18.3
6,-4,23:18.3
6,-2,23:18.3
6,-1,23:18.3
7,-1,23:18.3
7,-2,23:18.3
8,-2,23:18.3
9,-2,23:18.3
8,-1,23:18.3
8,0,23:18.3
8,4,23:18.3
4,-5,23:18.3
5,-6,23:18.3
9,-3,23:18.3
10,-2,23:18.3
9,1,23:18.3
7,6,23:18.3
-1,9,23:18.3
-2,10,23:18.3
-4,8,23:18.3
-8,6,23:18.3
-9,-6,23:18.3
-1,-1,24:17.3
-1,0,24:17.3
-1,1,24:17.3
0,1,24:17.3
0,0,24:17.3
1,0,24:17.3
1,-1,24:17.3
0,-1,24:17.3
1,1,24:17.3
-2,0,24:17.3
-3,0,24:17.3
-3,1,24:17.3
-4,1,24:17.3
-5,1,24:17.3
-5,0,24:17.3
-6,0,24:17.3
-5,-1,24:17.3
-5,-2,24:17.3
-4,2,24:17.3
-1,2,24:17.3
-1,3,24:17.3
-1,4,24:17.3
0,4,24:17.3
0,5,24:17.3
0,6,24:17.3
1,4,24:17.3
2,4,24:17.3
2,5,24:17.3
1,2,24:17.3
2,2,24:17.3
3,2,24:17.3
3,1,24:17.3
2,-1,24:17.3
3,-1,24:17.3
4,-1,24:17.3
4,2,24:17.3
4,3,24:17.3
5,-1,24:17.3
4,-2,24:17.3
6,0,24:17.3
6,-1,24:17.3
0,-2,24:17.3
0,-3,24:17.3
1,-3,24:17.3
2,-3,24:17.3
2,-4,24:17.3
2,-5,24:17.3
-1,-3,24:17.3
-1,-4,24:17.3
-1,-5,24:17.3
-2,-5,24:17.3
-1,-1,25:17.3
-1,0,25:17.3
-1,1,25:17.3
0,1,25:17.3
0,0,25:17.3
0,-1,25:17.3
1,-1,25:17.3
1,0,25:17.3
1,1,25:17.3
-3,-6,25:18.3
-3,-5,25:18.3
-3,-4,25:18.3
-2,-4,25:18.3
-2,-5,25:18.3
-2,-6,25:18.3
-1,-6,25:18.3
-1,-5,25:18.3
0,-5,25:18.3
0,-4,25:18.3
1,-4,25:18.3
1,-5,25:18.3
1,-6,25:18.3
2,-6,25:18.3
3,-6,25:18.3
3,-5,25:18.3
2,-5,25:18.3
2,-4,25:18.3
3,-4,25:18.3
3,-3,25:18.3
4,-3,25:18.3
5,-3,25:18.3
5,-2,25:18.3
6,-2,25:18.3
7,-2,25:18.3
7,-1,25:18.3
7,0,25:18.3
6,0,25:18.3
6,-1,25:18.3
5,-1,25:18.3
4,-2,25:18.3
4,-1,25:18.3
3,-2,25:18.3
2,-2,25:18.3
1,-2,25:18.3
2,-3,25:18.3
1,-3,25:18.3
0,-3,25:18.3
-1,-4,25:18.3
-1,-3,25:18.3
-1,-2,25:18.3
0,-2,25:18.3
-2,-3,25:18.3
-2,-2,25:18.3
-2,-1,25:18.3
-3,-1,25:18.3
-4,-1,25:18.3
-4,-2,25:18.3
-4,-3,25:18.3
-5,-3,25:18.3
-6,-3,25:18.3
-6,-2,25:18.3
-5,-2,25:18.3
-5,-1,25:18.3
-6,-1,25:18.3
-6,0,25:18.3
-5,0,25:18.3
-7,0,25:18.3
-7,-1,25:18.3
-7,1,25:18.3
-6,1,25:18.3
-5,1,25:18.3
-4,0,25:18.3
-3,0,25:18.3
-2,0,25:18.3
-2,1,25:18.3
-3,-2,25:18.3
-3,-3,25:18.3
-3,1,25:18.3
-4,1,25:18.3
-4,2,25:18.3
-2,2,25:18.3
-2,3,25:18.3
-2,4,25:18.3
-1,2,25:18.3
0,2,25:18.3
1,2,25:18.3
1,3,25:18.3
0,3,25:18.3
-1,3,25:18.3
-1,4,25:18.3
-2,5,25:18.3
-1,5,25:18.3
-1,6,25:18.3
-1,7,25:18.3
0,7,25:18.3
0,6,25:18.3
0,5,25:18.3
0,4,25:18.3
1,4,25:18.3
1,5,25:18.3
1,6,25:18.3
2,6,25:18.3
2,5,25:18.3
2,4,25:18.3
2,3,25:18.3
3,3,25:18.3
3,4,25:18.3
3,5,25:18.3
4,4,25:18.3
4,3,25:18.3
4,2,25:18.3
4,1,25:18.3
4,0,25:18.3
3,-1,25:18.3
3,0,25:18.3
2,-1,25:18.3
2,0,25:18.3
2,1,25:18.3
2,2,25:18.3
3,2,25:18.3
3,1,25:18.3
5,2,25:18.3
5,3,25:18.3
5,0,25:18.3
6,1,25:18.3
5,1,25:18.3
1,7,25:18.3
-2,-7,25:18.3
2,-7,25:18.3
8,-1,25:18.3
5,-4,25:18.3
6,-4,25:18.3
6,-5,25:18.3
6,3,25:18.3
7,4,25:18.3
7,3,25:18.3
-3,5,25:18.3
-4,5,25:18.3
-3,6,25:18.3
-7,2,25:18.3
-8,1,25:18.3
-6,-4,25:18.3
-7,-4,25:18.3
-7,-5,25:18.3
-2,-8,25:18.3
2,-8,25:18.3
3,-8,25:18.3
1,-8,25:18.3
2,-9,25:18.3
-3,-8,25:18.3
-3,-9,25:18.3
0,8,25:18.3
3,7,25:18.3
3,8,25:18.3
3,6,25:18.3
4,6,25:18.3
-4,3,25:18.3
-5,3,25:18.3
-3,2,25:18.3
-1,-1,26:17.3
-1,0,26:17.3
-1,1,26:17.3
0,1,26:17.3
0,0,26:17.3
1,0,26:17.3
1,-1,26:17.3
0,-1,26:17.3
1,1,26:17.3
-2,1,26:17.3
-3,0,26:17.3
-4,0,26:17.3
-5,0,26:17.3
-2,0,26:17.3
-1,2,26:17.3
-1,3,26:17.3
-2,3,26:17.3
0,4,26:17.3
-1,4,26:17.3
2,1,26:17.3
3,1,26:17.3
3,2,26:17.3
3,0,26:17.3
4,1,26:17.3
1,-2,26:17.3
1,-3,26:17.3
0,-3,26:17.3
0,-4,26:17.3
-2,-1,26:17.3
-2,-2,26:17.3
-3,-1,26:18.3
-4,-1,26:18.3
-5,-1,26:18.3
-6,0,26:18.3
-5,1,26:18.3
-4,1,26:18.3
-3,1,26:18.3
-2,2,26:18.3
-3,3,26:18.3
-2,4,26:18.3
-1,5,26:18.3
-2,5,26:18.3
0,5,26:18.3
1,5,26:18.3
1,4,26:18.3
1,3,26:18.3
0,3,26:18.3
0,2,26:18.3
1,2,26:18.3
2,2,26:18.3
3,3,26:18.3
4,3,26:18.3
4,2,26:18.3
2,3,26:18.3
5,2,26:18.3
5,1,26:18.3
5,0,26:18.3
4,0,26:18.3
4,-1,26:18.3
3,-1,26:18.3
2,-1,26:18.3
2,0,26:18.3
2,-2,26:18.3
2,-3,26:18.3
2,-4,26:18.3
1,-4,26:18.3
1,-5,26:18.3
0,-5,26:18.3
-1,-5,26:18.3
-1,-4,26:18.3
-1,-3,26:18.3
-1,-2,26:18.3
0,-2,26:18.3
-2,-3,26:18.3
-3,-3,26:18.3
-3,-2,26:18.3
-6,-1,26:18.3
-6,1,26:18.3
-3,2,26:18.3
-3,4,26:18.3
0,0,27:17.3
-5,-1,27:18.3
-5,0,27:18.3
-4,0,27:18.3
-3,0,27:18.3
-2,-1,27:17.3
-2,-2,27:18.3
0,-3,27:18.3
0,-4,27:18.3
1,-3,27:18.3
1,-2,27:18.3
1,-1,27:17.3
0,-1,27:17.3
-1,-1,27:17.3
-1,0,27:17.3
-2,0,27:18.3
-2,2,27:18.3
-1,1,27:17.3
-2,1,27:18.3
-2,3,27:18.3
-1,3,27:18.3
-1,4,27:18.3
0,4,27:18.3
-1,2,27:18.3
0,1,27:17.3
1,1,27:17.3
1,0,27:17.3
2,1,27:17.3
3,1,27:18.3
3,2,27:18.3
4,1,27:18.3
3,0,27:18.3
1,0,28:17.3
-2,0,28:18.3
0,2,28:18.3
2,0,28:18.3
0,-2,28:18.3
1,-1,28:17.3
-1,-1,28:17.3
-1,1,28:17.3
1,1,28:17.3
0,0,28:17.3
-1,0,28:17.3
0,-1,28:17.3
0,1,28:17.3
-3,-1,28:17.3
-3,-2,28:17.3
2,1,28:17.3
2,2,28:17.3
-2,-1,28:17.3
3,3,28:17.3
2,3,28:17.3
-4,-2,28:17.3
-1,2,28:17.3
-2,2,28:17.3
-2,3,28:17.3
-2,4,28:17.3
-3,4,28:17.3
1,-2,28:17.3
1,-3,28:17.3
2,-3,28:17.3
2,-4,28:17.3
3,-4,28:17.3
3,-5,28:17.3
-2,5,28:18.3
-3,3,28:18.3
-4,3,28:18.3
-4,4,28:18.3
-4,5,28:18.3
-4,-1,28:18.3
-5,-1,28:18.3
-5,-2,28:18.3
-5,-3,28:18.3
-4,-3,28:18.3
-3,-3,28:18.3
1,-4,28:18.3
1,-5,28:18.3
2,-5,28:18.3
2,-6,28:18.3
3,-6,28:18.3
4,-6,28:18.3
4,-5,28:18.3
4,-4,28:18.3
4,-3,28:18.3
3,-3,28:18.3
3,1,28:18.3
3,2,28:18.3
4,2,28:18.3
4,3,28:18.3
4,4,28:18.3
3,4,28:18.3
2,4,28:18.3
1,4,28:18.3
1,3,28:18.3
-4,-3,29:17.3
-4,-2,29:17.3
-3,-2,29:17.3
-3,-1,29:17.3
-2,-1,29:17.3
-1,-1,29:17.3
0,-1,29:17.3
1,-1,29:17.3
1,-2,29:17.3
1,-3,29:17.3
0,-3,29:17.3
0,-4,29:17.3
-1,-4,29:17.3
-1,-5,29:17.3
2,-3,29:17.3
2,-4,29:17.3
3,-4,29:17.3
3,-5,29:17.3
4,-5,29:18.3
1,0,29:17.3
1,1,29:17.3
2,1,29:17.3
2,2,29:17.3
2,3,29:17.3
3,3,29:17.3
3,4,29:17.3
3,5,29:17.3
4,5,29:17.3
5,5,29:17.3
4,3,29:17.3
4,2,29:17.3
4,1,29:17.3
5,1,29:17.3
1,3,29:17.3
1,4,29:17.3
1,5,29:17.3
1,6,29:17.3
0,6,29:17.3
0,1,29:17.3
-1,1,29:17.3
-1,0,29:17.3
0,0,29:17.3
-1,2,29:17.3
-2,2,29:17.3
-2,3,29:17.3
-2,4,29:17.3
-3,4,29:17.3
-4,4,29:17.3
-5,4,29:17.3
-5,5,29:17.3
-5,6,29:17.3
-4,6,29:17.3
-5,3,29:17.3
-6,3,29:17.3
-5,-3,29:17.3
-5,-4,29:17.3
-3,-3,29:18.3
-3,-4,29:18.3
-4,-4,29:18.3
-4,-5,29:18.3
-5,-5,29:18.3
-6,-5,29:18.3
-6,-4,29:18.3
-6,-3,29:18.3
-6,-2,29:18.3
-5,-2,29:18.3
-5,-1,29:18.3
-4,-1,29:18.3
-4,3,29:18.3
-4,2,29:18.3
-5,2,29:18.3
-6,2,29:18.3
-7,2,29:18.3
-7,3,29:18.3
-7,4,29:18.3
-6,4,29:18.3
-6,5,29:18.3
-6,6,29:18.3
-6,7,29:18.3
-5,7,29:18.3
-4,7,29:18.3
-3,7,29:18.3
-3,6,29:18.3
0,4,29:18.3
0,5,29:18.3
-1,5,29:18.3
-1,6,29:18.3
-1,7,29:18.3
0,7,29:18.3
1,7,29:18.3
2,7,29:18.3
2,6,29:18.3
2,5,29:18.3
4,6,29:18.3
5,6,29:18.3
6,6,29:18.3
6,5,29:18.3
6,4,29:18.3
5,4,29:18.3
5,3,29:18.3
5,2,29:18.3
6,2,29:18.3
6,1,29:18.3
6,0,29:18.3
5,0,29:18.3
4,0,29:18.3
3,0,29:18.3
2,-1,29:18.3
2,-2,29:18.3
3,-2,29:18.3
3,-3,29:18.3
4,-3,29:18.3
4,-4,29:18.3
5,-4,29:18.3
5,-5,29:18.3
4,-6,29:18.3
3,-6,29:18.3
2,-6,29:18.3
2,-5,29:18.3
1,-5,29:18.3
0,-5,29:18.3
0,-6,29:18.3
-1,-6,29:18.3
-2,-6,29:18.3
-2,-5,29:18.3
-2,-4,29:18.3
-2,-3,29:18.3
-1,-3,29:18.3
-1,-1,30:17.3
-1,0,30:17.3
-1,1,30:17.3
0,1,30:17.3
1,1,30:17.3
1,0,30:17.3
1,-1,30:17.3
0,-1,30:17.3
0,0,30:17.3
-2,-1,30:18.3
-3,-1,30:18.3
-4,-1,30:18.3
-4,-2,30:18.3
-4,-3,30:18.3
-4,-4,30:18.3
-5,-4,30:18.3
-5,-3,30:18.3
-5,-2,30:18.3
-3,-2,30:18.3
-2,-2,30:18.3
-2,-3,30:18.3
-2,-4,30:18.3
-1,-4,30:18.3
-1,-5,30:18.3
0,-5,30:18.3
0,-4,30:18.3
1,-4,30:18.3
1,-3,30:18.3
1,-2,30:18.3
0,-3,30:18.3
2,-3,30:18.3
2,-4,30:18.3
2,-5,30:18.3
3,-5,30:18.3
4,-5,30:18.3
4,-4,30:18.3
3,-4,30:18.3
3,-3,30:18.3
2,-2,30:18.3
2,1,30:18.3
3,1,30:18.3
3,2,30:18.3
4,1,30:18.3
4,0,30:18.3
5,0,30:18.3
5,1,30:18.3
5,2,30:18.3
5,3,30:18.3
5,4,30:18.3
5,5,30:18.3
4,5,30:18.3
3,4,30:18.3
4,4,30:18.3
4,3,30:18.3
4,2,30:18.3
3,3,30:18.3
2,4,30:18.3
1,4,30:18.3
1,3,30:18.3
0,3,30:18.3
0,4,30:18.3
2,3,30:18.3
1,5,30:18.3
2,5,30:18.3
2,6,30:18.3
1,6,30:18.3
0,6,30:18.3
0,7,30:18.3
1,7,30:18.3
3,6,30:18.3
3,5,30:18.3
2,2,30:18.3
-1,2,30:18.3
-2,2,30:18.3
-2,1,30:18.3
-3,1,30:18.3
-3,2,30:18.3
-2,3,30:18.3
-1,3,30:18.3
-1,4,30:18.3
-2,4,30:18.3
-2,5,30:18.3
-3,5,30:18.3
-3,4,30:18.3
-3,3,30:18.3
-4,3,30:18.3
-4,4,30:18.3
-5,4,30:18.3
-5,3,30:18.3
-6,3,30:18.3
-6,4,30:18.3
-6,5,30:18.3
-5,5,30:18.3
-5,6,30:18.3
-4,6,30:18.3
-4,5,30:18.3
-1,-1,31:17.3
-1,0,31:17.3
-1,1,31:17.3
0,1,31:17.3
1,1,31:17.3
1,0,31:17.3
1,-1,31:17.3
0,-1,31:17.3
0,0,31:17.3
-1,-1,32:17.3
-1,0,32:17.3
-1,1,32:17.3
0,1,32:17.3
1,1,32:17.3
1,0,32:17.3
1,-1,32:17.3
0,-1,32:17.3
0,0,32:17.3
-1,-1,33:17.3
-1,0,33:17.3
-1,1,33:17.3
0,1,33:17.3
1,1,33:17.3
1,0,33:17.3
1,-1,33:17.3
0,-1,33:17.3
0,0,33:17.3
-1,-1,34:17.3
-1,0,34:17.3
-1,1,34:17.3
0,1,34:17.3
1,1,34:17.3
1,0,34:17.3
1,-1,34:17.3
0,-1,34:17.3
0,0,34:17.3
-1,-1,35:17.3
-1,0,35:17.3
-1,1,35:17.3
0,1,35:17.3
1,1,35:17.3
1,0,35:17.3
1,-1,35:17.3
0,-1,35:17.3
0,0,35:17.3
-2,-2,35:18.3
-3,-2,35:18.3
-3,-3,35:18.3
-4,-3,35:18.3
-4,-4,35:18.3
-5,-4,35:18.3
-5,-5,35:18.3
-2,1,35:18.3
-3,1,35:18.3
-4,1,35:18.3
-5,1,35:18.3
-6,1,35:18.3
-6,2,35:18.3
-6,3,35:18.3
-6,4,35:18.3
-5,4,35:18.3
-5,5,35:18.3
-4,4,35:18.3
-5,3,35:18.3
-5,2,35:18.3
-4,2,35:18.3
-4,3,35:18.3
-3,4,35:18.3
-3,3,35:18.3
-3,2,35:18.3
-2,2,35:18.3
2,2,35:18.3
1,2,35:18.3
0,3,35:18.3
0,4,35:18.3
-1,4,35:18.3
-1,5,35:18.3
-1,6,35:18.3
0,6,35:18.3
1,6,35:18.3
2,6,35:18.3
3,6,35:18.3
3,5,35:18.3
3,4,35:18.3
2,4,35:18.3
1,4,35:18.3
1,3,35:18.3
2,3,35:18.3
3,3,35:18.3
3,2,35:18.3
3,1,35:18.3
3,0,35:18.3
3,-1,35:18.3
3,-2,35:18.3
3,-3,35:18.3
2,-3,35:18.3
1,-3,35:18.3
0,-3,35:18.3
-1,-3,35:18.3
4,-1,35:18.3
5,-1,35:18.3
5,0,35:18.3
6,0,35:18.3
5,1,35:18.3
6,-1,35:18.3
6,-2,35:18.3
5,-2,35:18.3
5,-3,35:18.3
5,-4,35:18.3
4,-4,35:18.3
4,-5,35:18.3
4,-3,35:18.3
2,-2,35:18.3
1,-2,35:18.3
0,-2,35:18.3
0,-4,35:18.3
0,-5,35:18.3
-1,-5,35:18.3
-1,-4,35:18.3
-2,-4,35:18.3
-3,-4,35:18.3
-3,-5,35:18.3
-4,-5,35:18.3
-4,-6,35:18.3
-4,-7,35:18.3
-5,-7,35:18.3
-5,-6,35:18.3
-1,0,36:17.3
-2,0,36:17.3
-3,0,36:17.3
-4,0,36:17.3
-5,0,36:17.3
-5,1,36:17.3
-5,2,36:17.3
-1,1,36:17.3
0,1,36:17.3
1,1,36:17.3
1,0,36:17.3
1,-1,36:17.3
0,-1,36:17.3
0,0,36:17.3
-1,-1,36:17.3
0,-2,36:17.3
0,-3,36:17.3
0,-4,36:17.3
1,-4,36:17.3
1,-5,36:17.3
1,-6,36:17.3
2,1,36:17.3
3,1,36:17.3
4,1,36:17.3
4,0,36:17.3
5,0,36:17.3
5,-1,36:17.3
0,2,36:17.3
0,3,36:17.3
0,4,36:17.3
0,5,36:17.3
-1,5,36:17.3
-2,5,36:17.3
-2,6,36:17.3
-2,7,36:17.3
1,4,36:17.3
2,4,36:17.3
2,5,36:18.3
3,5,36:17.3
-6,2,36:17.3
-7,2,36:17.3
-4,2,36:17.3
-4,3,36:17.3
-3,-1,36:17.3
-3,-2,36:17.3
-4,-2,36:17.3
-5,-2,36:17.3
-5,-3,36:17.3
-5,-4,36:17.3
-1,-4,36:17.3
-1,-5,36:17.3
2,-4,36:17.3
3,-4,36:17.3
-6,-3,36:17.3
-7,-3,36:17.3
-1,3,36:17.3
3,2,36:17.3
4,2,36:17.3
5,2,36:17.3
5,3,36:17.3
5,4,36:17.3
5,5,36:17.3
-3,6,36:17.3
2,-2,36:18.3
2,-3,36:18.3
3,-3,36:18.3
1,-3,36:18.3
1,-2,36:18.3
4,-3,36:18.3
4,-4,36:18.3
4,-5,36:18.3
3,-5,36:18.3
2,-5,36:18.3
2,-6,36:18.3
2,-7,36:18.3
1,-7,36:18.3
0,-7,36:18.3
0,-6,36:18.3
-1,-6,36:18.3
-2,-6,36:18.3
-2,-5,36:18.3
-2,-4,36:18.3
-2,-3,36:18.3
-3,-3,36:18.3
-4,-3,36:18.3
-4,-4,36:18.3
-4,-5,36:18.3
-4,-6,36:18.3
-5,-6,36:18.3
-6,-6,36:18.3
-6,-5,36:18.3
-6,-4,36:18.3
-7,-4,36:18.3
-8,-4,36:18.3
-8,-3,36:18.3
-8,-2,36:18.3
-7,-2,36:18.3
-6,-2,36:18.3
-6,-1,36:18.3
-6,0,36:18.3
-7,0,36:18.3
-7,1,36:18.3
-8,0,36:18.3
-8,1,36:18.3
-8,2,36:18.3
-8,3,36:18.3
-7,3,36:18.3
-6,3,36:18.3
-6,4,36:18.3
-5,4,36:18.3
-5,5,36:18.3
-5,6,36:18.3
-5,7,36:18.3
-4,7,36:18.3
-3,7,36:18.3
-3,8,36:18.3
-4,6,36:18.3
-4,5,36:18.3
-3,5,36:18.3
-9,2,36:18.3
-9,1,36:18.3
-9,-3,36:18.3
-2,8,36:18.3
-1,8,36:18.3
-1,7,36:18.3
-1,6,36:18.3
0,6,36:18.3
1,6,36:18.3
2,6,36:18.3
1,5,36:18.3
1,7,36:18.3
2,7,36:18.3
3,7,36:18.3
3,6,36:18.3
4,6,36:18.3
4,7,36:18.3
4,5,36:18.3
4,4,36:18.3
4,3,36:18.3
3,3,36:18.3
5,6,36:18.3
6,6,36:18.3
6,5,36:18.3
6,4,36:18.3
6,3,36:18.3
6,2,36:18.3
6,1,36:18.3
5,1,36:18.3
7,3,36:18.3
7,4,36:18.3
7,5,36:18.3
6,0,36:18.3
7,0,36:18.3
7,-1,36:18.3
7,-2,36:18.3
6,-2,36:18.3
5,-2,36:18.3
4,-2,36:18.3
4,-1,36:18.3
3,-1,36:18.3
3,0,36:18.3
6,-1,36:18.3
-2,2,36:18.3
-2,1,36:18.3
-3,1,36:18.3
-4,1,36:18.3
-3,2,36:18.3
-3,3,36:18.3
-2,-2,36:18.3
1,2,36:18.3
1,3,36:18.3
2,3,36:18.3
-1,-1,37:17.3
-1,0,37:17.3
-1,1,37:17.3
0,1,37:17.3
1,1,37:17.3
1,0,37:17.3
1,-1,37:17.3
0,-1,37:17.3
0,0,37:17.3
-5,-4,37:18.3
-6,-4,37:18.3
-6,-3,37:18.3
-7,-3,37:18.3
-7,-2,37:18.3
-6,-2,37:18.3
-5,-2,37:18.3
-5,-5,37:18.3
-6,-5,37:18.3
-5,-3,37:18.3
-4,-2,37:18.3
-4,-1,37:18.3
-3,-1,37:18.3
-3,-2,37:18.3
-5,-1,37:18.3
-5,0,37:18.3
-6,0,37:18.3
-6,1,37:18.3
-6,2,37:18.3
-7,2,37:18.3
-5,2,37:18.3
-5,3,37:18.3
-5,1,37:18.3
-4,1,37:18.3
-4,0,37:18.3
-3,0,37:18.3
-3,1,37:18.3
-2,0,37:18.3
-2,2,37:18.3
-1,2,37:18.3
-1,3,37:18.3
0,3,37:18.3
0,4,37:18.3
-1,4,37:18.3
-1,5,37:18.3
-2,5,37:18.3
-3,5,37:18.3
-3,6,37:18.3
-3,7,37:18.3
-2,7,37:18.3
-2,6,37:18.3
-1,6,37:18.3
1,4,37:18.3
1,3,37:18.3
0,2,37:18.3
2,3,37:18.3
2,4,37:18.3
2,5,37:18.3
1,5,37:18.3
0,5,37:18.3
3,5,37:18.3
4,5,37:18.3
4,4,37:18.3
5,4,37:18.3
5,5,37:18.3
6,4,37:18.3
6,3,37:18.3
5,3,37:18.3
5,2,37:18.3
4,2,37:18.3
3,2,37:18.3
3,1,37:18.3
2,1,37:18.3
2,0,37:18.3
3,0,37:18.3
3,-1,37:18.3
4,-1,37:18.3
4,0,37:18.3
4,1,37:18.3
5,0,37:18.3
5,1,37:18.3
5,-1,37:18.3
5,-2,37:18.3
1,-3,37:18.3
0,-3,37:18.3
-1,-3,37:18.3
-1,-4,37:18.3
-1,-5,37:18.3
-1,-6,37:18.3
0,-6,37:18.3
0,-7,37:18.3
0,-5,37:18.3
0,-4,37:18.3
1,-4,37:18.3
2,-4,37:18.3
2,-3,37:18.3
2,-2,37:18.3
1,-2,37:18.3
0,-2,37:18.3
-1,-2,37:18.3
2,-5,37:18.3
2,-6,37:18.3
1,-6,37:18.3
3,-4,37:18.3
-4,2,37:18.3
-4,3,37:18.3
-4,4,37:18.3
-5,4,37:18.3
0,0,38:17.3
-1,-2,38:18.3
-1,-1,38:18.3
-2,-1,38:18.3
-2,0,38:18.3
-1,0,38:18.3
-1,1,38:18.3
-1,2,38:18.3
0,2,38:18.3
1,2,38:18.3
1,1,38:18.3
2,1,38:18.3
2,0,38:18.3
2,-1,38:18.3
1,-1,38:18.3
1,-2,38:18.3
0,-2,38:18.3
0,-1,38:18.3
1,0,38:18.3
0,1,38:18.3
0,0,39:17.3
-1,0,39:17.3
-2,0,39:17.3
-3,0,39:17.3
-3,-1,39:17.3
1,0,39:17.3
2,0,39:17.3
2,1,39:17.3
2,2,39:17.3
2,3,39:17.3
-1,1,39:17.3
-1,2,39:17.3
-2,2,39:17.3
0,-1,39:17.3
0,-2,39:17.3
0,-3,39:17.3
-1,-3,39:17.3
1,-2,39:17.3
2,-2,39:17.3
2,-3,39:17.3
2,-4,39:17.3
-4,-1,39:17.3
3,2,39:17.3
-2,3,39:17.3
-1,-4,39:18.3
-2,-4,39:18.3
-2,-3,39:18.3
-2,-2,39:18.3
-1,-2,39:18.3
-3,-2,39:18.3
-4,-2,39:18.3
-5,-2,39:18.3
-5,-1,39:18.3
-5,0,39:18.3
-4,0,39:18.3
-4,1,39:18.3
-3,1,39:18.3
-3,2,39:18.3
-3,3,39:18.3
-3,4,39:18.3
-2,4,39:18.3
-1,4,39:18.3
-1,3,39:18.3
0,3,39:18.3
1,3,39:18.3
1,2,39:18.3
1,4,39:18.3
2,4,39:18.3
3,4,39:18.3
3,3,39:18.3
4,3,39:18.3
5,3,39:18.3
5,2,39:18.3
4,2,39:18.3
4,1,39:18.3
3,1,39:18.3
3,0,39:18.3
3,-1,39:18.3
4,-1,39:18.3
4,-2,39:18.3
4,-3,39:18.3
3,-2,39:18.3
3,-3,39:18.3
3,-4,39:18.3
4,-4,39:18.3
4,-5,39:18.3
3,-5,39:18.3
2,-5,39:18.3
2,-6,39:18.3
1,-6,39:18.3
1,-5,39:18.3
1,-4,39:18.3
-1,-5,39:18.3
-2,-5,39:18.3
-3,-5,39:18.3
-3,-4,39:18.3
-4,-4,39:18.3
-4,-3,39:18.3
-5,-3,39:18.3
-6,-3,39:18.3
-6,-2,39:18.3
-6,-1,39:18.3
-6,0,39:18.3
-5,1,39:18.3
-5,2,39:18.3
-4,2,39:18.3
-4,3,39:18.3
-4,4,39:18.3
0,0,40:17.3
-3,-3,40:18.3
-4,-3,40:18.3
-4,-2,40:18.3
-4,-1,40:18.3
-5,-1,40:18.3
-4,0,40:18.3
-3,0,40:18.3
-3,-1,40:18.3
-2,-1,40:18.3
-2,0,40:18.3
-1,0,40:18.3
-1,1,40:18.3
-2,1,40:18.3
-2,2,40:18.3
-3,2,40:18.3
-3,3,40:18.3
-2,3,40:18.3
-1,3,40:18.3
-1,2,40:18.3
0,2,40:18.3
0,1,40:18.3
1,2,40:18.3
1,1,40:18.3
2,1,40:18.3
2,2,40:18.3
2,3,40:18.3
3,3,40:18.3
3,2,40:18.3
4,2,40:18.3
4,1,40:18.3
3,1,40:18.3
3,0,40:18.3
2,0,40:18.3
2,-1,40:18.3
2,-2,40:18.3
3,-2,40:18.3
2,-3,40:18.3
2,-4,40:18.3
1,-4,40:18.3
0,-4,40:18.3
-1,-4,40:18.3
-1,-3,40:18.3
0,-3,40:18.3
1,-3,40:18.3
1,-2,40:18.3
0,-2,40:18.3
0,-1,40:18.3
1,-1,40:18.3
1,0,40:18.3
0,0,41:17.3
-1,0,41:17.3
0,0,42:17.3
1,1,42:17.3
-1,-1,42:18.3
-2,-1,42:18.3
-2,0,42:18.3
-1,0,42:18.3
-1,1,42:18.3
-1,2,42:18.3
0,1,42:18.3
0,2,42:18.3
0,3,42:18.3
1,2,42:18.3
2,2,42:18.3
2,1,42:18.3
2,0,42:18.3
1,0,42:18.3
1,-1,42:18.3
0,-1,42:18.3
0,0,43:17.3
1,1,43:18.3
0,1,43:18.3
-1,1,43:18.3
-1,0,43:18.3
-1,-1,43:18.3
0,-1,43:18.3
1,-1,43:18.3
1,0,43:18.3
0,0,44:18.3
-2,-1,44:18.3
-2,0,44:18.3
-2,1,44:18.3
-1,1,44:18.3
0,1,44:18.3
0,2,44:18.3
1,2,44:18.3
2,2,44:18.3
2,1,44:18.3
2,0,44:18.3
2,-1,44:18.3
1,-2,44:18.3
0,-2,44:18.3
0,-1,44:18.3
-1,-1,44:18.3
