[META]
version=2.0
spawnOnBlockType=2
spawnSunlight=True
spawnDarkness=True
spawnWater=False
spawnLava=False
underFill=False
randomRotation=True
dig=True
tree=True
branch=False
needsFoundation=True
rarity=20
collisionPercentage=2
spawnElevationMin=0
spawnElevationMax=256
spawnInBiome=OttaForest
[DATA]
0,0,0:17.0
0,0,1:17.0
-1,0,2:18
0,0,2:17.0
0,1,2:18
-1,0,3:18
0,0,3:17.0
1,0,3:18
-1,1,3:18
0,1,3:18
1,1,3:18
0,0,4:17.0
1,-3,5:18
2,-3,5:18
0,-2,5:18
1,-2,5:17.4
2,-2,5:17.4
3,-2,5:18
-1,-1,5:18
0,-1,5:17.8
1,-1,5:17.4
2,-1,5:18
3,-1,5:18
-1,0,5:18
0,0,5:17.0
1,0,5:18
2,0,5:18
0,1,5:18
0,2,5:18
1,-4,6:18
1,-3,6:18
2,-3,6:18
3,-3,6:18
-1,-2,6:18
0,-2,6:18
1,-2,6:18
2,-2,6:17.4
3,-2,6:17.4
4,-2,6:18
-1,-1,6:18
0,-1,6:18
1,-1,6:18
2,-1,6:18
3,-1,6:18
4,-1,6:18
-1,0,6:18
0,0,6:17.0
1,0,6:18
2,0,6:18
3,0,6:18
-1,1,6:18
0,1,6:17.8
1,1,6:18
2,1,6:18
-3,2,6:18
-2,2,6:18
-1,2,6:17.4
0,2,6:17.8
1,2,6:18
-2,3,6:18
-1,3,6:18
0,3,6:18
1,-4,7:18
2,-4,7:18
-1,-3,7:18
0,-3,7:18
1,-3,7:18
2,-3,7:18
-2,-2,7:18
-1,-2,7:17.8
0,-2,7:18
1,-2,7:18
2,-2,7:18
3,-2,7:18
-2,-1,7:18
-1,-1,7:17.8
0,-1,7:17.8
1,-1,7:18
2,-1,7:18
3,-1,7:18
4,-1,7:18
-2,0,7:18
-1,0,7:18
0,0,7:17.0
1,0,7:18
2,0,7:18
3,0,7:18
-3,1,7:18
-2,1,7:18
-1,1,7:18
0,1,7:18
1,1,7:18
2,1,7:18
-3,2,7:18
-2,2,7:18
-1,2,7:17.8
0,2,7:18
1,2,7:18
-3,3,7:18
-2,3,7:17.4
-1,3,7:17.4
0,3,7:18
-2,4,7:18
-1,4,7:18
1,-3,8:18
-1,-2,8:18
0,-2,8:18
1,-2,8:18
2,-2,8:18
-1,-1,8:18
0,-1,8:18
1,-1,8:18
2,-1,8:18
-1,0,8:18
0,0,8:17.0
1,0,8:18
2,0,8:18
-2,1,8:18
-1,1,8:18
0,1,8:18
1,1,8:18
-3,2,8:18
-2,2,8:18
-1,2,8:18
0,2,8:18
-2,3,8:18
-1,3,8:18
0,-1,9:18
1,-1,9:18
0,0,9:18
1,0,9:18
