[META]
version=2.0
spawnOnBlockType=2
spawnSunlight=True
spawnDarkness=True
spawnWater=False
spawnLava=False
underFill=False
randomRotation=True
dig=False
tree=False
branch=False
needsFoundation=True
rarity=10
collisionPercentage=100
spawnElevationMin=0
spawnElevationMax=150
spawnInBiome=OttaJungle
[DATA]
3,-3,-6:17.3
3,-2,-6:17.3
-2,-1,-6:17.3
-20,0,-6:2.0
1,1,-6:1.5
0,4,-6:17.3
4,4,-6:17.3
-2,-2,-5:17.3
3,-2,-5:17.3
-2,-1,-5:17.3
2,-1,-5:17.3
1,0,-5:1.5
0,1,-5:1.5
1,1,-5:1.5
2,1,-5:1.5
0,2,-5:1.5
-1,4,-5:17.3
0,4,-5:17.3
1,4,-5:17.3
4,4,-5:17.3
2,-2,-4:17.3
-2,-1,-4:17.3
2,-1,-4:17.3
-2,0,-4:17.3
1,0,-4:1.5
2,0,-4:1.5
0,1,-4:3.5
1,1,-4:3.5
2,1,-4:1.5
3,1,-4:1.5
0,2,-4:1.5
1,2,-4:1.5
2,2,-4:1.5
3,2,-4:17.3
4,3,-4:17.3
-2,4,-4:17.3
-1,4,-4:17.3
4,4,-4:17.3
5,4,-4:17.3
2,-3,-3:17.3
-2,-2,-3:17.3
2,-2,-3:17.3
-3,-1,-3:17.3
-2,-1,-3:17.3
1,-1,-3:3.5
2,-1,-3:3.5
-2,0,-3:17.3
-1,0,-3:17.3
0,0,-3:1.5
1,0,-3:3.5
2,0,-3:3.5
3,0,-3:1.5
-1,1,-3:3.5
0,1,-3:3.5
1,1,-3:3.5
2,1,-3:3.5
3,1,-3:3.5
4,1,-3:17.3
-1,2,-3:3.5
0,2,-3:3.5
1,2,-3:3.5
2,2,-3:3.5
3,2,-3:3.5
-1,3,-3:17.3
0,3,-3:1.5
1,3,-3:17.3
2,3,-3:1.5
3,3,-3:17.3
4,3,-3:17.3
-1,4,-3:17.3
1,4,-3:17.3
1,-2,-2:3.5
2,-2,-2:17.3
0,-1,-2:3.5
1,-1,-2:3.5
2,-1,-2:17.3
3,-1,-2:2.0
-2,0,-2:17.3
-1,0,-2:17.3
0,0,-2:3.5
1,0,-2:17.3
2,0,-2:17.3
3,0,-2:3.5
-2,1,-2:3.5
-1,1,-2:3.5
0,1,-2:3.5
1,1,-2:17.3
2,1,-2:3.5
3,1,-2:3.5
-1,2,-2:3.5
0,2,-2:17.3
1,2,-2:17.3
2,2,-2:17.3
3,2,-2:17.3
4,2,-2:17.3
-1,3,-2:17.3
0,3,-2:17.3
1,3,-2:3.5
2,3,-2:3.5
3,3,-2:17.3
0,-2,-1:2.5
1,-2,-1:2.5
-1,-1,-1:2.5
0,-1,-1:3.0
1,-1,-1:3.5
2,-1,-1:2.5
-2,0,-1:2.5
-1,0,-1:17.3
0,0,-1:17.3
1,0,-1:17.3
2,0,-1:3.0
3,0,-1:2.0
-2,1,-1:2.5
-1,1,-1:3.5
0,1,-1:3.0
1,1,-1:17.3
2,1,-1:3.0
3,1,-1:3.0
4,1,-1:2.5
-2,2,-1:2.5
-1,2,-1:3.0
0,2,-1:3.0
1,2,-1:17.3
2,2,-1:17.3
3,2,-1:17.3
4,2,-1:2.5
-1,3,-1:17.3
0,3,-1:17.3
1,3,-1:17.3
2,3,-1:3.0
3,3,-1:2.5
0,4,-1:2.5
1,4,-1:2.5
2,4,-1:2.5
0,-1,0:17.3
1,-1,0:17.3
-1,0,0:17.3
0,0,0:17.3
1,0,0:17.3
2,0,0:17.3
-1,1,0:17.3
0,1,0:17.3
1,1,0:17.3
2,1,0:17.3
3,1,0:17.3
-1,2,0:17.3
0,2,0:17.3
1,2,0:17.3
2,2,0:17.3
3,2,0:17.3
1,3,0:17.3
2,3,0:17.3
0,-1,1:17.3
1,-1,1:17.3
-1,0,1:17.3
0,0,1:17.3
1,0,1:17.3
2,0,1:17.3
-1,1,1:17.3
0,1,1:17.3
1,1,1:17.3
2,1,1:17.3
3,1,1:17.3
-1,2,1:17.3
0,2,1:17.3
1,2,1:17.3
2,2,1:17.3
3,2,1:17.3
1,3,1:17.3
2,3,1:17.3
0,-1,2:17.3
-1,0,2:17.3
0,0,2:17.3
1,0,2:17.3
2,0,2:17.3
-1,1,2:17.3
0,1,2:17.3
1,1,2:17.3
2,1,2:17.3
3,1,2:17.3
0,2,2:17.3
1,2,2:17.3
2,2,2:17.3
3,2,2:17.3
1,3,2:17.3
2,3,2:17.3
0,-1,3:17.3
-1,0,3:17.3
0,0,3:17.3
1,0,3:17.3
2,0,3:17.3
0,1,3:17.3
1,1,3:17.3
2,1,3:17.3
3,1,3:17.3
0,2,3:17.3
1,2,3:17.3
2,2,3:17.3
3,2,3:17.3
1,3,3:17.3
2,3,3:17.3
0,-1,4:17.3
-1,0,4:17.3
0,0,4:17.3
1,0,4:17.3
2,0,4:17.3
0,1,4:17.3
1,1,4:17.3
2,1,4:17.3
3,1,4:17.3
0,2,4:17.3
1,2,4:17.3
2,2,4:17.3
3,2,4:17.3
1,3,4:17.3
2,3,4:17.3
0,-1,5:17.3
-1,0,5:17.3
0,0,5:17.3
1,0,5:17.3
2,0,5:17.3
0,1,5:17.3
1,1,5:17.3
2,1,5:17.3
3,1,5:17.3
0,2,5:17.3
1,2,5:17.3
2,2,5:17.3
3,2,5:17.3
1,3,5:17.3
2,3,5:17.3
-1,0,6:17.3
0,0,6:17.3
1,0,6:17.3
2,0,6:17.3
0,1,6:17.3
1,1,6:17.3
2,1,6:17.3
0,2,6:17.3
1,2,6:17.3
2,2,6:17.3
3,2,6:17.3
1,3,6:17.3
2,3,6:17.3
0,0,7:17.3
1,0,7:17.3
2,0,7:17.3
0,1,7:17.3
1,1,7:17.3
2,1,7:17.3
0,2,7:17.3
1,2,7:17.3
2,2,7:17.3
3,2,7:17.3
1,3,7:17.3
2,3,7:17.3
0,0,8:17.3
1,0,8:17.3
2,0,8:17.3
0,1,8:17.3
1,1,8:17.3
2,1,8:17.3
0,2,8:17.3
1,2,8:17.3
2,2,8:17.3
3,2,8:17.3
1,3,8:17.3
2,3,8:17.3
0,0,9:17.3
1,0,9:17.3
2,0,9:17.3
0,1,9:17.3
1,1,9:17.3
2,1,9:17.3
0,2,9:17.3
1,2,9:17.3
2,2,9:17.3
1,3,9:17.3
2,3,9:17.3
0,0,10:17.3
1,0,10:17.3
2,0,10:17.3
0,1,10:17.3
1,1,10:17.3
2,1,10:17.3
0,2,10:17.3
1,2,10:17.3
2,2,10:17.3
1,3,10:17.3
2,3,10:17.3
0,0,11:17.3
1,0,11:17.3
2,0,11:17.3
0,1,11:17.3
1,1,11:17.3
2,1,11:17.3
0,2,11:17.3
1,2,11:17.3
2,2,11:17.3
2,3,11:17.3
0,0,12:17.3
1,0,12:17.3
2,0,12:17.3
0,1,12:17.3
1,1,12:17.3
2,1,12:17.3
0,2,12:17.3
1,2,12:17.3
2,2,12:17.3
1,0,13:17.3
2,0,13:17.3
0,1,13:17.3
1,1,13:17.3
2,1,13:17.3
0,2,13:17.3
1,2,13:17.3
2,2,13:17.3
1,0,14:17.3
2,0,14:17.3
0,1,14:17.3
1,1,14:17.3
2,1,14:17.3
0,2,14:17.3
1,2,14:17.3
2,2,14:17.3
1,0,15:17.3
2,0,15:17.3
0,1,15:17.3
1,1,15:17.3
2,1,15:17.3
0,2,15:17.3
1,2,15:17.3
14,-11,16:18.4
1,0,16:17.3
2,0,16:17.3
0,1,16:17.3
1,1,16:17.3
2,1,16:17.3
0,2,16:17.3
1,2,16:17.3
10,-14,17:18.32
11,-14,17:18.32
12,-12,17:18.32
13,-12,17:18.32
14,-12,17:18.32
13,-11,17:18.32
14,-11,17:18.32
16,-8,17:18.32
1,-1,17:17.3
2,-1,17:17.3
1,0,17:17.3
2,0,17:17.3
0,1,17:17.3
1,1,17:17.3
0,2,17:17.3
1,2,17:17.3
9,-16,18:18.32
10,-16,18:18.4
9,-15,18:18.32
10,-15,18:18.32
8,-14,18:18.32
9,-14,18:18.32
10,-14,18:17.3
11,-14,18:18.32
12,-13,18:18.32
11,-12,18:18.32
12,-12,18:17.3
13,-12,18:18.32
14,-12,18:18.32
12,-11,18:17.3
13,-11,18:17.3
14,-11,18:18.32
13,-10,18:18.32
11,-9,18:18.32
12,-9,18:18.32
13,-9,18:18.32
15,-9,18:18.32
16,-9,18:18.32
12,-8,18:18.32
13,-8,18:18.32
15,-8,18:17.3
16,-8,18:18.32
17,-6,18:18.32
1,-2,18:17.3
2,-2,18:17.3
-17,-1,18:18.4
1,-1,18:17.3
2,-1,18:17.3
1,0,18:17.3
2,0,18:17.3
0,1,18:17.3
1,1,18:17.3
0,2,18:17.3
1,2,18:17.3
16,2,18:18.32
15,3,18:18.32
16,3,18:18.32
16,4,18:18.32
16,6,18:18.32
16,7,18:18.32
-13,9,18:18.32
-12,9,18:18.32
17,10,18:18.32
7,13,18:18.4
10,18,18:18.32
13,19,18:18.4
3,-18,19:18.32
4,-18,19:18.32
5,-17,19:18.32
0,-16,19:18.32
2,-16,19:18.32
3,-16,19:18.32
6,-15,19:18.32
10,-15,19:18.32
11,-15,19:18.32
9,-14,19:18.32
10,-14,19:17.3
11,-14,19:18.32
3,-13,19:18.32
8,-13,19:18.32
9,-13,19:18.32
10,-13,19:17.3
3,-12,19:18.32
4,-12,19:18.32
5,-12,19:18.32
10,-12,19:17.3
11,-12,19:18.32
12,-12,19:18.32
3,-11,19:18.32
6,-11,19:18.32
10,-11,19:17.3
11,-11,19:17.3
12,-11,19:17.3
13,-11,19:18.32
9,-10,19:18.32
11,-10,19:18.32
12,-10,19:18.32
9,-9,19:18.32
11,-9,19:18.32
12,-9,19:18.32
13,-9,19:18.32
14,-9,19:18.32
15,-9,19:18.32
16,-9,19:18.32
9,-8,19:18.32
10,-8,19:18.32
12,-8,19:18.32
13,-8,19:18.32
14,-8,19:18.32
15,-8,19:18.32
16,-8,19:18.32
13,-7,19:18.32
14,-7,19:18.32
15,-7,19:17.3
16,-7,19:17.3
-18,-6,19:18.32
14,-6,19:18.32
15,-6,19:17.3
16,-6,19:18.32
17,-6,19:18.32
18,-6,19:18.32
-18,-5,19:18.32
-17,-5,19:18.32
15,-5,19:17.3
16,-5,19:18.32
17,-5,19:18.32
-19,-4,19:18.32
1,-3,19:17.3
2,-3,19:17.3
-16,-2,19:18.32
1,-2,19:17.3
2,-2,19:17.3
19,-2,19:18.32
-17,-1,19:18.32
-16,-1,19:18.32
1,-1,19:17.3
2,-1,19:17.3
-17,0,19:18.32
-16,0,19:18.32
-16,1,19:18.32
0,1,19:17.3
1,1,19:17.3
16,1,19:18.32
0,2,19:17.3
1,2,19:17.3
15,2,19:17.3
16,2,19:17.3
17,2,19:18.4
18,2,19:18.32
13,3,19:18.32
15,3,19:18.32
16,3,19:18.32
17,3,19:18.32
16,4,19:18.32
-11,5,19:18.4
-11,6,19:18.32
14,6,19:18.32
15,6,19:18.32
16,6,19:18.32
-13,7,19:18.32
-12,7,19:18.32
15,7,19:18.32
16,7,19:18.32
-14,8,19:18.32
-13,8,19:18.32
15,8,19:18.32
16,8,19:18.32
17,8,19:18.32
-12,9,19:18.32
17,9,19:18.32
-12,10,19:18.32
-10,10,19:18.32
-6,10,19:18.32
17,10,19:18.32
-12,11,19:18.32
-10,11,19:18.32
-12,12,19:18.32
-11,12,19:18.32
-9,12,19:18.4
-11,13,19:18.32
6,13,19:18.32
7,13,19:18.32
8,13,19:18.32
-14,14,19:18.32
-13,14,19:18.32
-12,14,19:18.32
-11,14,19:18.32
-10,14,19:18.32
-9,14,19:18.32
-8,14,19:18.32
17,14,19:18.32
-13,15,19:18.32
-11,15,19:18.32
-6,15,19:18.32
2,15,19:18.32
17,15,19:18.32
-8,16,19:18.32
-6,16,19:18.32
17,16,19:18.32
-6,17,19:18.32
13,17,19:18.32
10,18,19:18.32
11,18,19:17.3
12,18,19:17.3
13,18,19:17.3
14,18,19:17.3
10,19,19:18.32
11,19,19:18.32
12,19,19:18.32
13,19,19:18.32
14,19,19:18.32
10,20,19:18.32
2,-19,20:18.32
3,-19,20:18.32
2,-18,20:18.32
3,-18,20:17.3
4,-18,20:18.32
1,-17,20:18.32
2,-17,20:18.32
3,-17,20:17.3
4,-17,20:18.32
5,-17,20:18.32
-8,-16,20:18.32
0,-16,20:18.32
1,-16,20:17.3
2,-16,20:17.3
3,-16,20:17.3
4,-16,20:18.32
5,-16,20:18.32
6,-16,20:18.32
-9,-15,20:18.32
3,-15,20:17.3
4,-15,20:17.3
5,-15,20:17.3
6,-15,20:18.32
-9,-14,20:18.4
-1,-14,20:18.32
3,-14,20:18.32
4,-14,20:18.32
5,-14,20:18.32
6,-14,20:18.32
8,-14,20:18.32
9,-14,20:18.32
10,-14,20:18.32
-2,-13,20:18.32
-1,-13,20:18.32
2,-13,20:18.32
3,-13,20:18.32
4,-13,20:18.32
5,-13,20:18.32
8,-13,20:18.32
9,-13,20:18.32
10,-13,20:18.32
2,-12,20:18.32
3,-12,20:18.32
4,-12,20:18.32
5,-12,20:18.32
6,-12,20:18.32
8,-12,20:18.32
9,-12,20:18.32
10,-12,20:18.32
11,-12,20:18.32
-15,-11,20:18.32
-14,-11,20:18.32
-13,-11,20:18.32
-12,-11,20:18.32
3,-11,20:18.32
4,-11,20:17.3
5,-11,20:18.32
6,-11,20:18.32
7,-11,20:18.32
8,-11,20:18.32
9,-11,20:18.32
10,-11,20:17.3
11,-11,20:18.32
12,-11,20:18.32
-18,-10,20:18.32
-17,-10,20:18.32
-16,-10,20:18.32
4,-10,20:17.3
5,-10,20:18.32
6,-10,20:18.32
8,-10,20:18.32
10,-10,20:17.3
11,-10,20:18.32
-18,-9,20:18.32
-17,-9,20:18.32
-16,-9,20:18.4
3,-9,20:18.32
4,-9,20:17.3
5,-9,20:18.32
6,-9,20:18.32
8,-9,20:18.32
10,-9,20:17.3
11,-9,20:18.32
12,-9,20:18.32
13,-9,20:18.32
6,-8,20:18.32
8,-8,20:18.32
9,-8,20:18.32
10,-8,20:17.3
11,-8,20:18.32
14,-8,20:18.32
16,-8,20:18.32
17,-8,20:18.32
-17,-7,20:18.32
9,-7,20:18.32
10,-7,20:17.3
15,-7,20:18.32
16,-7,20:18.32
17,-7,20:18.32
18,-7,20:18.32
-18,-6,20:18.32
-17,-6,20:18.32
10,-6,20:17.3
15,-6,20:18.32
18,-6,20:18.32
-19,-5,20:18.32
-18,-5,20:18.32
-17,-5,20:17.3
-16,-5,20:18.32
10,-5,20:17.3
15,-5,20:17.3
17,-5,20:18.32
-20,-4,20:18.32
-19,-4,20:18.32
-18,-4,20:18.32
-17,-4,20:18.32
-16,-4,20:18.32
1,-4,20:17.3
2,-4,20:17.3
15,-4,20:17.3
16,-4,20:18.32
17,-4,20:18.32
-19,-3,20:18.32
-18,-3,20:18.32
1,-3,20:17.3
2,-3,20:17.3
14,-3,20:18.32
15,-3,20:17.3
16,-3,20:18.32
19,-3,20:18.32
-16,-2,20:18.32
15,-2,20:17.3
17,-2,20:18.32
18,-2,20:18.32
19,-2,20:18.32
-17,-1,20:18.32
-16,-1,20:17.3
17,-1,20:18.32
19,-1,20:18.32
-18,0,20:18.32
-17,0,20:18.32
-16,0,20:18.32
-15,0,20:18.32
17,0,20:18.32
-17,1,20:18.32
-16,1,20:18.32
0,1,20:17.3
1,1,20:17.3
13,1,20:18.32
14,1,20:18.32
15,1,20:18.32
16,1,20:18.32
17,1,20:18.32
-15,2,20:18.32
-14,2,20:18.32
0,2,20:17.3
1,2,20:17.3
13,2,20:17.3
14,2,20:17.3
15,2,20:17.3
16,2,20:18.32
17,2,20:18.32
18,2,20:18.32
0,3,20:17.3
1,3,20:17.3
12,3,20:18.32
13,3,20:17.3
14,3,20:18.32
15,3,20:18.32
18,3,20:18.32
-14,4,20:18.32
-11,4,20:18.32
0,4,20:17.3
13,4,20:18.32
15,4,20:18.32
16,4,20:18.32
-14,5,20:18.32
-13,5,20:18.32
-12,5,20:18.32
-11,5,20:18.32
-10,5,20:18.32
15,5,20:18.32
-14,6,20:18.32
-13,6,20:18.32
-12,6,20:18.32
-11,6,20:17.3
-10,6,20:18.32
13,6,20:18.32
14,6,20:18.32
-13,7,20:18.32
-12,7,20:18.32
-11,7,20:17.3
-10,7,20:18.32
-9,7,20:18.32
14,7,20:18.32
15,7,20:18.32
-14,8,20:18.32
-13,8,20:18.32
-12,8,20:17.3
-11,8,20:17.3
-10,8,20:17.3
-9,8,20:18.32
-8,8,20:18.32
-7,8,20:18.32
3,8,20:18.32
14,8,20:18.32
15,8,20:18.32
16,8,20:18.32
17,8,20:18.32
18,8,20:18.32
-14,9,20:18.32
-13,9,20:18.32
-12,9,20:18.32
-11,9,20:18.32
-10,9,20:17.3
-9,9,20:17.3
-8,9,20:17.3
-7,9,20:18.32
-6,9,20:18.32
-5,9,20:18.32
3,9,20:18.32
13,9,20:18.32
15,9,20:17.3
16,9,20:18.32
17,9,20:18.32
18,9,20:18.32
-13,10,20:18.32
-12,10,20:18.32
-11,10,20:18.32
-10,10,20:17.3
-9,10,20:18.32
-8,10,20:17.3
16,10,20:18.32
17,10,20:18.32
-13,11,20:18.32
-12,11,20:17.3
-11,11,20:17.3
-10,11,20:17.3
-9,11,20:18.32
-8,11,20:18.32
-6,11,20:18.32
-4,11,20:18.32
0,11,20:18.32
-12,12,20:18.32
-11,12,20:18.32
-10,12,20:18.32
-9,12,20:18.32
-8,12,20:18.32
-7,12,20:18.32
-6,12,20:18.32
-5,12,20:17.3
-4,12,20:18.32
1,12,20:18.32
16,12,20:18.32
-13,13,20:18.32
-12,13,20:17.3
-10,13,20:18.32
-9,13,20:18.32
-5,13,20:17.3
-4,13,20:18.32
5,13,20:18.32
6,13,20:18.32
7,13,20:18.32
8,13,20:18.32
9,13,20:18.32
16,13,20:18.32
-13,14,20:18.32
-12,14,20:17.3
-11,14,20:18.32
-10,14,20:18.32
-9,14,20:18.32
-6,14,20:18.32
-5,14,20:18.32
1,14,20:18.32
2,14,20:18.32
5,14,20:18.32
8,14,20:18.32
9,14,20:18.32
16,14,20:18.32
17,14,20:18.32
-14,15,20:18.32
-13,15,20:17.3
-12,15,20:17.3
-11,15,20:18.32
-10,15,20:18.32
-9,15,20:18.32
-5,15,20:18.32
1,15,20:18.32
2,15,20:17.3
3,15,20:18.32
9,15,20:18.32
14,15,20:18.32
16,15,20:18.32
17,15,20:18.32
18,15,20:18.32
-14,16,20:18.32
-13,16,20:18.32
-12,16,20:18.32
-11,16,20:18.32
-10,16,20:18.32
-9,16,20:18.32
-8,16,20:18.32
-7,16,20:18.32
-6,16,20:18.32
1,16,20:18.32
2,16,20:18.32
8,16,20:18.32
9,16,20:18.32
17,16,20:18.32
-13,17,20:18.4
-11,17,20:18.32
-10,17,20:18.32
-9,17,20:18.32
-7,17,20:18.32
-6,17,20:18.32
-5,17,20:18.32
-1,17,20:18.32
0,17,20:18.32
12,17,20:18.4
13,17,20:18.32
14,17,20:18.32
-10,18,20:18.32
-9,18,20:18.4
-6,18,20:18.4
0,18,20:18.32
11,18,20:18.32
12,18,20:18.32
13,18,20:18.32
14,18,20:17.3
16,18,20:18.32
17,18,20:18.32
-10,19,20:18.32
10,19,20:18.32
11,19,20:18.32
12,19,20:18.32
13,19,20:18.32
14,19,20:18.32
15,19,20:18.32
16,19,20:18.32
17,19,20:18.32
9,20,20:18.32
11,20,20:18.32
12,20,20:18.32
13,20,20:18.32
-2,-20,21:18.32
-3,-19,21:18.32
-2,-19,21:18.32
3,-18,21:18.32
-6,-17,21:18.4
-5,-17,21:18.32
3,-17,21:18.32
-8,-16,21:18.32
-7,-16,21:18.32
-6,-16,21:18.32
-5,-16,21:18.32
1,-16,21:18.4
2,-16,21:18.32
3,-16,21:18.32
-9,-15,21:18.32
-8,-15,21:18.32
2,-15,21:18.32
3,-15,21:17.3
4,-15,21:18.32
5,-15,21:18.32
-9,-14,21:18.32
-2,-14,21:18.32
-1,-14,21:18.32
0,-14,21:18.32
2,-14,21:18.32
3,-14,21:17.3
4,-14,21:18.32
-10,-13,21:18.32
-3,-13,21:18.32
-2,-13,21:18.32
-1,-13,21:17.3
0,-13,21:17.3
1,-13,21:17.3
2,-13,21:17.3
3,-13,21:17.3
4,-13,21:18.32
-14,-12,21:18.32
-13,-12,21:18.32
-11,-12,21:18.32
1,-12,21:18.32
4,-12,21:18.32
-15,-11,21:18.32
-14,-11,21:18.32
-13,-11,21:18.32
-12,-11,21:18.32
3,-11,21:18.32
4,-11,21:18.32
5,-11,21:18.32
10,-11,21:18.32
-17,-10,21:18.32
-16,-10,21:18.32
-15,-10,21:18.32
-8,-10,21:18.32
3,-10,21:18.32
4,-10,21:18.32
5,-10,21:18.32
7,-10,21:18.32
10,-10,21:18.32
12,-10,21:18.32
-18,-9,21:18.32
-17,-9,21:18.32
-16,-9,21:17.3
-12,-9,21:18.32
-11,-9,21:18.32
-8,-9,21:18.32
-4,-9,21:18.32
2,-9,21:18.32
3,-9,21:18.32
4,-9,21:18.32
5,-9,21:18.32
6,-9,21:18.32
7,-9,21:17.3
8,-9,21:18.32
10,-9,21:18.32
11,-9,21:18.32
12,-9,21:18.32
-19,-8,21:18.32
-18,-8,21:18.32
-1,-8,21:18.32
4,-8,21:17.3
5,-8,21:18.32
6,-8,21:18.32
7,-8,21:17.3
8,-8,21:18.32
9,-8,21:18.32
10,-8,21:18.32
11,-8,21:18.32
12,-8,21:18.32
13,-8,21:18.32
-19,-7,21:18.32
-18,-7,21:18.32
0,-7,21:18.32
1,-7,21:17.3
2,-7,21:17.3
3,-7,21:18.32
5,-7,21:18.32
6,-7,21:18.32
7,-7,21:17.3
8,-7,21:18.32
9,-7,21:18.32
10,-7,21:18.32
11,-7,21:18.32
12,-7,21:18.32
13,-7,21:18.32
18,-7,21:18.32
-18,-6,21:18.32
-17,-6,21:18.32
1,-6,21:17.3
2,-6,21:17.3
5,-6,21:18.32
6,-6,21:18.32
7,-6,21:17.3
8,-6,21:18.32
10,-6,21:18.32
11,-6,21:18.32
12,-6,21:18.32
13,-6,21:18.32
18,-6,21:18.32
-19,-5,21:18.32
-18,-5,21:18.32
-17,-5,21:17.3
1,-5,21:17.3
2,-5,21:17.3
7,-5,21:17.3
8,-5,21:17.3
9,-5,21:17.3
10,-5,21:17.3
11,-5,21:17.3
12,-5,21:17.3
13,-5,21:18.32
15,-5,21:18.32
18,-5,21:18.32
-19,-4,21:18.32
-18,-4,21:18.32
-17,-4,21:18.4
-3,-4,21:18.32
1,-4,21:17.3
2,-4,21:17.3
5,-4,21:18.32
6,-4,21:18.32
9,-4,21:18.32
10,-4,21:18.32
11,-4,21:18.32
12,-4,21:17.3
13,-4,21:18.32
14,-4,21:18.32
15,-4,21:18.32
16,-4,21:18.32
17,-4,21:18.32
18,-4,21:18.32
19,-4,21:18.32
-19,-3,21:18.32
-18,-3,21:18.32
-17,-3,21:18.32
-16,-3,21:18.32
5,-3,21:18.32
10,-3,21:18.32
11,-3,21:18.32
12,-3,21:17.3
14,-3,21:18.32
15,-3,21:18.32
16,-3,21:18.32
17,-3,21:18.32
18,-3,21:18.32
-18,-2,21:18.32
-17,-2,21:18.32
-16,-2,21:18.32
10,-2,21:18.32
11,-2,21:18.32
12,-2,21:17.3
13,-2,21:17.3
14,-2,21:17.3
15,-2,21:17.3
16,-2,21:17.3
17,-2,21:17.3
18,-2,21:17.3
19,-2,21:18.32
-19,-1,21:18.32
-18,-1,21:18.32
-17,-1,21:18.32
-16,-1,21:17.3
11,-1,21:18.32
12,-1,21:18.32
13,-1,21:18.32
14,-1,21:18.32
16,-1,21:18.32
18,-1,21:18.32
-19,0,21:18.32
-18,0,21:18.32
-17,0,21:18.32
-16,0,21:18.32
-15,0,21:18.32
13,0,21:18.32
14,0,21:18.32
15,0,21:18.32
16,0,21:18.32
18,0,21:18.32
-18,1,21:18.32
-17,1,21:18.32
-15,1,21:18.32
0,1,21:17.3
1,1,21:17.3
13,1,21:18.32
15,1,21:18.32
-17,2,21:18.32
-15,2,21:18.32
-14,2,21:18.32
0,2,21:17.3
1,2,21:17.3
13,2,21:18.32
14,2,21:18.32
15,2,21:18.32
-14,3,21:18.32
-13,3,21:18.32
0,3,21:17.3
1,3,21:17.3
12,3,21:18.32
13,3,21:17.3
14,3,21:18.32
-14,4,21:18.32
-13,4,21:18.32
0,4,21:17.3
13,4,21:18.32
14,4,21:18.32
15,4,21:18.32
-13,5,21:18.32
0,5,21:17.3
13,5,21:18.32
14,5,21:18.32
15,5,21:18.32
-11,6,21:18.32
12,6,21:18.32
13,6,21:17.3
14,6,21:18.32
-12,7,21:18.32
-11,7,21:18.32
-10,7,21:18.32
12,7,21:18.32
13,7,21:17.3
14,7,21:18.32
15,7,21:18.32
-14,8,21:18.32
-13,8,21:18.32
-12,8,21:18.32
-11,8,21:18.32
-10,8,21:18.32
3,8,21:18.32
13,8,21:17.3
14,8,21:18.32
15,8,21:18.32
16,8,21:18.32
17,8,21:18.32
-10,9,21:18.32
-9,9,21:18.32
-8,9,21:18.32
-7,9,21:18.32
-5,9,21:18.32
-4,9,21:18.32
3,9,21:18.32
13,9,21:17.3
14,9,21:17.3
15,9,21:17.3
16,9,21:18.32
17,9,21:18.32
-12,10,21:18.32
-11,10,21:18.32
-10,10,21:18.32
-9,10,21:18.32
-8,10,21:18.32
-7,10,21:18.32
-6,10,21:18.32
-5,10,21:17.3
2,10,21:18.32
15,10,21:18.32
16,10,21:18.32
17,10,21:18.32
18,10,21:18.32
-12,11,21:18.32
-11,11,21:18.32
-10,11,21:18.32
-7,11,21:18.32
-6,11,21:18.32
-5,11,21:17.3
1,11,21:17.3
2,11,21:17.3
9,11,21:18.32
13,11,21:18.32
15,11,21:18.32
16,11,21:18.32
-7,12,21:18.32
-6,12,21:18.32
-5,12,21:18.32
-4,12,21:18.32
-3,12,21:18.32
-2,12,21:18.32
-1,12,21:18.32
0,12,21:18.32
1,12,21:17.3
2,12,21:18.32
5,12,21:18.32
6,12,21:18.32
7,12,21:18.32
9,12,21:18.32
10,12,21:18.32
13,12,21:18.32
15,12,21:18.32
16,12,21:18.32
-12,13,21:18.32
-6,13,21:18.32
-5,13,21:18.32
-4,13,21:18.32
-1,13,21:18.32
0,13,21:18.32
1,13,21:17.3
2,13,21:17.3
4,13,21:18.32
5,13,21:17.3
6,13,21:17.3
7,13,21:17.3
8,13,21:17.3
9,13,21:17.3
10,13,21:18.32
15,13,21:18.32
16,13,21:18.32
-13,14,21:18.32
-12,14,21:18.32
-10,14,21:18.32
-8,14,21:18.32
-5,14,21:18.32
1,14,21:18.32
2,14,21:17.3
5,14,21:17.3
6,14,21:18.32
7,14,21:18.32
8,14,21:18.32
9,14,21:17.3
10,14,21:18.32
14,14,21:18.32
15,14,21:18.32
16,14,21:18.32
-13,15,21:18.32
-12,15,21:17.3
-11,15,21:17.3
-10,15,21:17.3
-9,15,21:17.3
-8,15,21:17.3
-7,15,21:17.3
-6,15,21:18.32
0,15,21:18.32
1,15,21:18.32
2,15,21:17.3
3,15,21:18.32
5,15,21:18.32
7,15,21:18.32
8,15,21:18.32
9,15,21:17.3
10,15,21:18.32
14,15,21:17.3
15,15,21:17.3
16,15,21:17.3
17,15,21:18.32
18,15,21:18.32
-13,16,21:18.32
-12,16,21:18.32
-11,16,21:18.32
-10,16,21:17.3
-9,16,21:18.32
-8,16,21:18.32
-7,16,21:17.3
-6,16,21:18.32
0,16,21:18.32
1,16,21:18.32
2,16,21:18.32
8,16,21:18.32
9,16,21:17.3
10,16,21:18.32
13,16,21:18.32
14,16,21:17.3
15,16,21:18.32
17,16,21:18.32
18,16,21:18.32
-13,17,21:18.32
-12,17,21:17.3
-11,17,21:17.3
-10,17,21:17.3
-9,17,21:18.32
-8,17,21:18.32
-7,17,21:17.3
-6,17,21:18.32
-1,17,21:18.32
0,17,21:18.32
9,17,21:18.32
10,17,21:18.32
12,17,21:18.32
13,17,21:18.32
14,17,21:17.3
15,17,21:18.32
16,17,21:18.32
-12,18,21:18.32
-11,18,21:18.32
-10,18,21:17.3
-9,18,21:18.32
-8,18,21:18.32
-7,18,21:18.32
-6,18,21:18.32
1,18,21:18.32
12,18,21:18.32
13,18,21:18.32
14,18,21:17.3
15,18,21:18.32
16,18,21:18.32
-10,19,21:18.32
-9,19,21:18.32
-7,19,21:18.32
-6,19,21:18.32
10,19,21:18.32
11,19,21:18.32
12,19,21:18.32
14,19,21:18.32
15,19,21:18.32
-10,20,21:18.32
12,20,21:18.32
14,20,21:18.32
-3,-20,22:18.32
-4,-19,22:18.32
-3,-19,22:18.32
-2,-19,22:18.32
-1,-19,22:18.32
-5,-18,22:18.32
-4,-18,22:18.32
-3,-18,22:18.32
0,-18,22:18.32
-5,-17,22:18.32
-4,-17,22:18.32
0,-17,22:18.32
-7,-16,22:18.32
-6,-16,22:18.32
-5,-16,22:18.32
-9,-15,22:18.32
-8,-15,22:18.32
-7,-15,22:18.32
-6,-15,22:18.32
-5,-15,22:18.32
3,-15,22:18.32
-9,-14,22:18.32
-4,-14,22:18.32
0,-14,22:18.32
1,-14,22:18.32
3,-14,22:18.32
-10,-13,22:18.32
-4,-13,22:18.32
1,-13,22:17.3
2,-13,22:18.32
3,-13,22:18.32
-14,-12,22:18.32
-11,-12,22:18.32
-10,-12,22:18.32
-7,-12,22:18.32
-6,-12,22:18.32
-1,-12,22:18.32
0,-12,22:18.32
1,-12,22:17.3
4,-12,22:18.32
-14,-11,22:18.32
-11,-11,22:18.32
-10,-11,22:18.32
-9,-11,22:18.32
-5,-11,22:18.32
0,-11,22:18.32
1,-11,22:17.3
2,-11,22:18.4
3,-11,22:18.32
4,-11,22:18.32
-16,-10,22:18.4
-15,-10,22:18.32
-14,-10,22:17.3
-13,-10,22:18.32
-12,-10,22:18.32
-11,-10,22:18.32
-9,-10,22:18.32
-8,-10,22:18.32
-7,-10,22:18.32
-6,-10,22:18.32
-4,-10,22:18.32
-1,-10,22:18.32
1,-10,22:17.3
2,-10,22:18.32
3,-10,22:18.32
4,-10,22:18.32
10,-10,22:18.32
-18,-9,22:18.32
-17,-9,22:18.32
-16,-9,22:17.3
-15,-9,22:17.3
-14,-9,22:17.3
-13,-9,22:17.3
-12,-9,22:17.3
-11,-9,22:18.32
-8,-9,22:18.32
-7,-9,22:18.32
-4,-9,22:18.32
-2,-9,22:18.32
-1,-9,22:18.32
0,-9,22:18.32
1,-9,22:17.3
2,-9,22:18.32
3,-9,22:18.32
4,-9,22:18.32
5,-9,22:18.32
7,-9,22:18.32
-19,-8,22:18.32
-18,-8,22:18.32
-17,-8,22:18.32
-1,-8,22:18.32
1,-8,22:17.3
2,-8,22:17.3
3,-8,22:17.3
4,-8,22:17.3
5,-8,22:18.32
7,-8,22:18.32
9,-8,22:18.32
10,-8,22:18.32
-19,-7,22:18.32
-18,-7,22:18.32
-17,-7,22:18.32
1,-7,22:17.3
2,-7,22:17.3
4,-7,22:18.32
5,-7,22:18.32
6,-7,22:18.32
7,-7,22:18.32
-18,-6,22:18.32
-17,-6,22:18.32
-2,-6,22:18.32
1,-6,22:17.3
2,-6,22:17.3
3,-6,22:18.32
4,-6,22:18.32
5,-6,22:18.32
6,-6,22:18.32
7,-6,22:18.32
8,-6,22:18.32
9,-6,22:18.32
12,-6,22:18.32
-18,-5,22:18.32
-17,-5,22:17.3
-3,-5,22:18.32
-1,-5,22:18.32
1,-5,22:17.3
2,-5,22:17.3
5,-5,22:18.32
6,-5,22:18.32
7,-5,22:18.32
8,-5,22:17.3
9,-5,22:18.32
10,-5,22:18.32
11,-5,22:18.32
12,-5,22:18.32
13,-5,22:18.32
14,-5,22:18.32
-18,-4,22:18.32
-17,-4,22:18.32
-4,-4,22:18.32
-3,-4,22:17.3
-2,-4,22:18.32
0,-4,22:18.32
1,-4,22:18.32
2,-4,22:18.32
8,-4,22:17.3
12,-4,22:18.32
13,-4,22:18.32
-17,-3,22:18.32
-16,-3,22:18.32
-3,-3,22:18.32
6,-3,22:18.32
7,-3,22:18.32
8,-3,22:17.3
9,-3,22:18.32
12,-3,22:18.32
13,-3,22:18.32
14,-3,22:18.32
15,-3,22:18.32
18,-3,22:18.32
-17,-2,22:18.32
-16,-2,22:18.32
-15,-2,22:18.32
-14,-2,22:18.32
6,-2,22:18.32
7,-2,22:18.32
8,-2,22:17.3
11,-2,22:18.32
12,-2,22:18.32
13,-2,22:18.32
14,-2,22:18.32
15,-2,22:18.32
16,-2,22:18.32
17,-2,22:18.32
18,-2,22:18.32
19,-2,22:18.32
-17,-1,22:18.32
-16,-1,22:17.3
-15,-1,22:17.3
-14,-1,22:17.3
6,-1,22:18.32
7,-1,22:18.32
8,-1,22:17.3
9,-1,22:18.32
15,-1,22:18.32
16,-1,22:18.32
-16,0,22:18.32
-15,0,22:18.32
-14,0,22:17.3
8,0,22:17.3
9,0,22:18.32
18,0,22:18.32
-15,1,22:18.32
-14,1,22:17.3
-13,1,22:17.3
-12,1,22:17.3
-11,1,22:18.4
0,1,22:17.3
1,1,22:17.3
8,1,22:17.3
10,1,22:18.32
11,1,22:18.32
12,1,22:18.32
13,1,22:18.32
14,1,22:18.32
15,1,22:18.32
16,1,22:18.32
-15,2,22:18.32
-14,2,22:18.32
-13,2,22:18.32
-12,2,22:17.3
-11,2,22:18.32
0,2,22:17.3
1,2,22:17.3
7,2,22:18.32
8,2,22:17.3
9,2,22:18.32
10,2,22:18.32
11,2,22:18.32
12,2,22:18.32
13,2,22:18.32
14,2,22:18.32
15,2,22:18.32
-14,3,22:18.32
-13,3,22:18.32
-12,3,22:18.32
-11,3,22:18.32
0,3,22:17.3
1,3,22:17.3
6,3,22:18.32
7,3,22:18.32
8,3,22:17.3
9,3,22:17.3
10,3,22:17.3
11,3,22:17.3
12,3,22:17.3
13,3,22:17.3
14,3,22:18.32
15,3,22:18.32
-13,4,22:18.32
0,4,22:17.3
1,4,22:17.3
7,4,22:18.32
8,4,22:18.32
9,4,22:18.32
10,4,22:18.32
11,4,22:17.3
12,4,22:18.32
13,4,22:18.32
14,4,22:18.32
0,5,22:17.3
1,5,22:17.3
7,5,22:18.32
8,5,22:18.32
9,5,22:18.32
10,5,22:18.32
11,5,22:18.32
12,5,22:18.32
0,6,22:17.3
1,6,22:17.3
8,6,22:18.32
9,6,22:18.32
10,6,22:18.32
13,6,22:18.32
-10,7,22:18.32
0,7,22:17.3
1,7,22:17.3
12,7,22:18.32
13,7,22:18.32
16,7,22:18.32
-11,8,22:18.32
0,8,22:17.3
1,8,22:17.3
7,8,22:18.32
8,8,22:18.32
9,8,22:18.32
11,8,22:18.32
12,8,22:18.32
13,8,22:18.32
14,8,22:18.32
16,8,22:18.32
-4,9,22:18.4
-1,9,22:18.32
0,9,22:17.3
1,9,22:17.3
3,9,22:18.32
4,9,22:18.32
7,9,22:18.32
8,9,22:18.32
9,9,22:18.32
10,9,22:18.32
11,9,22:18.32
12,9,22:18.32
13,9,22:17.3
14,9,22:18.32
15,9,22:18.32
16,9,22:18.32
17,9,22:18.32
-10,10,22:18.32
-5,10,22:17.3
-4,10,22:17.3
-3,10,22:17.3
-2,10,22:17.3
-1,10,22:17.3
0,10,22:17.3
1,10,22:17.3
2,10,22:17.3
3,10,22:17.3
4,10,22:17.3
7,10,22:18.32
8,10,22:18.32
9,10,22:18.32
10,10,22:18.32
11,10,22:18.32
12,10,22:18.32
13,10,22:17.3
14,10,22:18.32
15,10,22:18.32
16,10,22:18.32
-6,11,22:18.32
-5,11,22:17.3
-4,11,22:17.3
-3,11,22:17.3
-2,11,22:17.3
-1,11,22:17.3
0,11,22:17.3
1,11,22:17.3
2,11,22:17.3
3,11,22:17.3
4,11,22:17.3
5,11,22:17.3
6,11,22:17.3
7,11,22:17.3
8,11,22:17.3
9,11,22:17.3
10,11,22:17.3
11,11,22:17.3
12,11,22:17.3
13,11,22:17.3
14,11,22:18.32
15,11,22:18.32
-7,12,22:18.32
-6,12,22:18.32
-5,12,22:17.3
-4,12,22:18.32
-3,12,22:18.32
-2,12,22:18.32
-1,12,22:18.32
1,12,22:18.32
3,12,22:18.32
5,12,22:18.32
6,12,22:18.32
7,12,22:18.32
8,12,22:17.3
9,12,22:18.32
10,12,22:18.32
11,12,22:18.32
12,12,22:18.32
13,12,22:17.3
14,12,22:17.3
15,12,22:18.32
16,12,22:18.32
-8,13,22:18.32
-7,13,22:17.3
-6,13,22:17.3
-5,13,22:17.3
-4,13,22:18.32
0,13,22:18.32
1,13,22:18.32
2,13,22:18.32
3,13,22:18.32
4,13,22:18.32
5,13,22:18.32
6,13,22:18.32
7,13,22:18.32
8,13,22:17.3
9,13,22:17.3
11,13,22:18.32
12,13,22:18.32
13,13,22:18.32
14,13,22:17.3
15,13,22:18.32
16,13,22:18.32
-8,14,22:18.32
-7,14,22:17.3
-6,14,22:18.32
-5,14,22:18.32
0,14,22:18.32
2,14,22:18.32
3,14,22:18.32
4,14,22:18.32
5,14,22:18.32
6,14,22:18.32
7,14,22:18.32
8,14,22:18.32
9,14,22:18.32
10,14,22:18.32
11,14,22:18.32
12,14,22:18.32
13,14,22:18.32
14,14,22:17.3
15,14,22:18.32
16,14,22:18.32
-12,15,22:18.32
-11,15,22:18.32
-10,15,22:18.32
-9,15,22:18.32
-8,15,22:18.32
-7,15,22:17.3
-6,15,22:18.32
2,15,22:18.32
3,15,22:18.32
4,15,22:18.32
5,15,22:18.32
6,15,22:18.32
7,15,22:18.32
8,15,22:18.32
9,15,22:18.32
10,15,22:18.32
11,15,22:18.32
12,15,22:18.32
13,15,22:18.32
14,15,22:17.3
15,15,22:18.32
16,15,22:18.32
-11,16,22:18.32
-10,16,22:18.32
-8,16,22:18.32
-7,16,22:18.32
0,16,22:18.32
1,16,22:18.32
2,16,22:18.32
4,16,22:18.32
5,16,22:18.32
6,16,22:18.32
7,16,22:18.32
8,16,22:18.32
9,16,22:18.32
10,16,22:18.32
11,16,22:18.32
12,16,22:18.32
13,16,22:18.32
14,16,22:18.32
15,16,22:18.32
16,16,22:18.32
17,16,22:18.32
-12,17,22:18.32
-11,17,22:18.32
-10,17,22:18.32
-9,17,22:18.32
-7,17,22:18.32
0,17,22:18.32
1,17,22:18.32
5,17,22:18.32
6,17,22:18.32
7,17,22:18.32
8,17,22:18.32
9,17,22:18.32
10,17,22:18.32
11,17,22:18.32
12,17,22:18.32
13,17,22:18.32
14,17,22:18.32
15,17,22:18.32
-10,18,22:18.32
1,18,22:18.32
7,18,22:18.32
8,18,22:18.32
9,18,22:18.32
10,18,22:18.32
11,18,22:18.32
13,18,22:18.32
14,18,22:18.32
15,18,22:18.32
7,19,22:18.32
8,19,22:18.32
10,19,22:18.32
11,19,22:18.32
-4,-19,23:18.32
-3,-19,23:18.32
-2,-19,23:18.32
-1,-19,23:18.32
-4,-18,23:18.32
-3,-18,23:18.32
-2,-18,23:17.3
-1,-18,23:18.32
0,-18,23:18.32
-5,-17,23:18.32
-4,-17,23:18.32
-3,-17,23:18.32
-2,-17,23:17.3
-1,-17,23:18.32
0,-17,23:18.32
-5,-16,23:18.32
-4,-16,23:17.3
-3,-16,23:17.3
-2,-16,23:17.3
-1,-16,23:18.32
0,-16,23:18.32
-8,-15,23:18.32
-7,-15,23:18.32
-5,-15,23:18.32
-4,-15,23:18.32
-1,-15,23:18.32
3,-15,23:18.32
-9,-14,23:18.32
-8,-14,23:18.32
-7,-14,23:18.32
-6,-14,23:18.32
-5,-14,23:18.32
-4,-14,23:18.32
1,-14,23:18.32
2,-14,23:18.32
-10,-13,23:18.32
-9,-13,23:18.32
-8,-13,23:18.32
-7,-13,23:18.32
-6,-13,23:18.32
-5,-13,23:18.32
-4,-13,23:18.32
2,-13,23:18.32
3,-13,23:18.32
-11,-12,23:18.32
-10,-12,23:18.32
-9,-12,23:17.3
-8,-12,23:17.3
-7,-12,23:18.32
-6,-12,23:18.32
-5,-12,23:18.32
-4,-12,23:18.32
0,-12,23:18.32
1,-12,23:18.32
-14,-11,23:18.32
-11,-11,23:18.32
-10,-11,23:18.32
-9,-11,23:18.32
-8,-11,23:17.3
-7,-11,23:18.32
-6,-11,23:18.32
-5,-11,23:18.32
-4,-11,23:18.32
-1,-11,23:18.32
0,-11,23:18.32
1,-11,23:18.32
-15,-10,23:18.32
-14,-10,23:18.32
-13,-10,23:18.32
-10,-10,23:18.32
-9,-10,23:18.32
-8,-10,23:17.3
-7,-10,23:17.3
-6,-10,23:18.32
-5,-10,23:18.32
-4,-10,23:18.32
-1,-10,23:18.32
0,-10,23:18.32
1,-10,23:18.32
3,-10,23:18.32
-17,-9,23:18.32
-16,-9,23:18.32
-15,-9,23:18.32
-14,-9,23:17.3
-13,-9,23:18.32
-12,-9,23:18.32
-11,-9,23:18.32
-8,-9,23:18.32
-6,-9,23:18.32
-2,-9,23:18.32
-1,-9,23:18.32
0,-9,23:18.32
1,-9,23:18.32
4,-9,23:18.32
-16,-8,23:18.32
-15,-8,23:18.32
-14,-8,23:17.3
-13,-8,23:18.32
-12,-8,23:18.32
-7,-8,23:18.32
-4,-8,23:18.32
-3,-8,23:17.3
-2,-8,23:18.32
-1,-8,23:18.32
0,-8,23:18.32
1,-8,23:18.32
2,-8,23:18.32
3,-8,23:18.32
4,-8,23:18.32
-15,-7,23:18.32
-14,-7,23:17.3
-13,-7,23:18.32
-12,-7,23:18.32
-11,-7,23:18.32
-3,-7,23:17.3
-1,-7,23:18.32
0,-7,23:18.32
1,-7,23:18.32
2,-7,23:18.32
5,-7,23:18.32
-17,-6,23:18.32
-16,-6,23:18.32
-15,-6,23:18.32
-14,-6,23:17.3
-13,-6,23:18.32
-12,-6,23:18.32
-11,-6,23:18.32
-4,-6,23:18.32
-3,-6,23:17.3
-2,-6,23:18.32
1,-6,23:18.32
2,-6,23:18.32
6,-6,23:18.32
7,-6,23:18.32
9,-6,23:18.32
-18,-5,23:18.32
-17,-5,23:17.3
-16,-5,23:17.3
-15,-5,23:17.3
-14,-5,23:17.3
-13,-5,23:17.3
-12,-5,23:17.3
-4,-5,23:18.32
-3,-5,23:17.3
-1,-5,23:18.32
1,-5,23:18.32
2,-5,23:18.32
6,-5,23:18.32
7,-5,23:18.32
8,-5,23:18.32
9,-5,23:18.32
-17,-4,23:18.32
-16,-4,23:18.32
-15,-4,23:18.32
-14,-4,23:18.32
-12,-4,23:17.3
-4,-4,23:18.32
-3,-4,23:17.3
-1,-4,23:18.32
0,-4,23:18.32
1,-4,23:18.32
2,-4,23:18.32
6,-4,23:18.32
7,-4,23:18.32
8,-4,23:17.3
9,-4,23:18.32
-15,-3,23:18.32
-14,-3,23:18.32
-13,-3,23:18.32
-12,-3,23:17.3
-3,-3,23:18.32
-1,-3,23:18.32
0,-3,23:18.32
2,-3,23:17.3
3,-3,23:18.32
6,-3,23:18.32
7,-3,23:18.32
8,-3,23:17.3
9,-3,23:18.32
13,-3,23:18.32
14,-3,23:18.32
17,-3,23:18.32
18,-3,23:18.32
-14,-2,23:18.32
-13,-2,23:18.32
-12,-2,23:17.3
1,-2,23:17.3
2,-2,23:17.3
4,-2,23:18.32
7,-2,23:18.32
8,-2,23:17.3
9,-2,23:18.32
13,-2,23:18.32
14,-2,23:18.32
15,-2,23:18.32
16,-2,23:18.32
17,-2,23:18.32
18,-2,23:18.32
-17,-1,23:18.32
-16,-1,23:18.32
-15,-1,23:18.32
-14,-1,23:17.3
-13,-1,23:17.3
-12,-1,23:17.3
-11,-1,23:18.32
2,-1,23:17.3
3,-1,23:18.32
4,-1,23:18.32
6,-1,23:18.32
7,-1,23:18.32
8,-1,23:17.3
9,-1,23:18.32
10,-1,23:18.32
14,-1,23:18.32
15,-1,23:18.32
16,-1,23:18.32
-14,0,23:18.32
-13,0,23:18.32
-12,0,23:18.32
-11,0,23:18.32
0,0,23:18.32
1,0,23:17.3
2,0,23:17.3
3,0,23:17.3
4,0,23:17.3
5,0,23:17.3
6,0,23:17.3
7,0,23:17.3
8,0,23:17.3
10,0,23:18.32
11,0,23:18.32
12,0,23:18.32
13,0,23:18.32
-14,1,23:18.32
-13,1,23:18.32
-12,1,23:18.32
0,1,23:17.3
1,1,23:17.3
2,1,23:17.3
3,1,23:17.3
4,1,23:17.3
5,1,23:17.3
6,1,23:17.3
7,1,23:17.3
8,1,23:17.3
9,1,23:18.32
10,1,23:18.32
11,1,23:18.32
-15,2,23:18.32
-14,2,23:18.32
-13,2,23:18.32
-12,2,23:18.32
-11,2,23:18.32
0,2,23:17.3
1,2,23:18.32
8,2,23:18.32
11,2,23:18.32
13,2,23:18.32
14,2,23:18.32
-12,3,23:18.32
-11,3,23:18.32
0,3,23:18.32
1,3,23:18.32
6,3,23:18.32
7,3,23:18.32
8,3,23:18.32
9,3,23:18.32
10,3,23:18.32
11,3,23:18.32
12,3,23:18.32
13,3,23:18.32
-12,4,23:18.32
-11,4,23:18.32
-1,4,23:18.32
0,4,23:17.3
1,4,23:17.3
2,4,23:18.32
9,4,23:18.32
10,4,23:18.32
11,4,23:18.32
12,4,23:18.32
-12,5,23:18.32
-11,5,23:18.32
-5,5,23:18.32
-4,5,23:18.32
-3,5,23:18.32
-2,5,23:18.32
-1,5,23:18.32
0,5,23:17.3
1,5,23:17.3
2,5,23:18.32
-6,6,23:18.32
-5,6,23:18.32
-4,6,23:18.32
-3,6,23:17.3
-2,6,23:17.3
-1,6,23:17.3
0,6,23:17.3
1,6,23:17.3
2,6,23:18.32
-8,7,23:18.32
-4,7,23:18.32
-3,7,23:18.32
-2,7,23:18.32
-1,7,23:18.32
0,7,23:17.3
1,7,23:17.3
2,7,23:18.32
13,7,23:18.32
-3,8,23:18.32
-2,8,23:18.32
-1,8,23:18.32
0,8,23:17.3
1,8,23:17.3
2,8,23:18.32
6,8,23:18.32
11,8,23:18.32
12,8,23:18.32
-1,9,23:18.32
0,9,23:17.3
1,9,23:17.3
2,9,23:18.32
6,9,23:18.32
7,9,23:18.32
8,9,23:18.32
10,9,23:18.32
13,9,23:18.32
15,9,23:18.32
-7,10,23:18.32
-6,10,23:18.32
-3,10,23:18.32
-2,10,23:18.4
-1,10,23:18.32
0,10,23:17.3
1,10,23:17.3
2,10,23:17.3
3,10,23:17.3
4,10,23:18.32
5,10,23:18.32
6,10,23:18.32
7,10,23:18.32
8,10,23:18.32
9,10,23:18.32
10,10,23:18.32
12,10,23:18.32
13,10,23:18.32
14,10,23:18.32
-6,11,23:18.32
-5,11,23:18.32
-4,11,23:18.32
-1,11,23:18.32
0,11,23:18.32
1,11,23:18.32
2,11,23:18.32
3,11,23:17.3
4,11,23:17.3
5,11,23:17.3
6,11,23:17.3
7,11,23:17.3
8,11,23:18.32
9,11,23:18.32
10,11,23:18.32
11,11,23:18.32
12,11,23:18.32
13,11,23:18.32
14,11,23:18.32
15,11,23:18.32
16,11,23:18.32
-6,12,23:18.32
-5,12,23:18.4
-3,12,23:18.4
-2,12,23:18.32
-1,12,23:18.32
0,12,23:18.32
3,12,23:18.32
4,12,23:18.32
5,12,23:18.32
6,12,23:18.32
7,12,23:18.32
8,12,23:18.32
9,12,23:18.32
10,12,23:18.32
12,12,23:18.32
13,12,23:18.32
14,12,23:18.32
15,12,23:18.32
16,12,23:18.32
-8,13,23:18.32
-7,13,23:18.32
-6,13,23:18.32
-5,13,23:18.32
-4,13,23:18.32
-1,13,23:18.32
0,13,23:18.32
3,13,23:18.32
5,13,23:18.32
8,13,23:18.32
9,13,23:18.32
12,13,23:18.32
13,13,23:18.32
14,13,23:18.32
15,13,23:18.32
-7,14,23:18.32
-5,14,23:18.32
-4,14,23:18.32
-1,14,23:18.32
0,14,23:18.32
2,14,23:18.32
3,14,23:18.32
7,14,23:18.32
11,14,23:18.32
14,14,23:18.32
15,14,23:18.32
-10,15,23:18.32
-9,15,23:18.32
-7,15,23:18.32
2,15,23:18.32
3,15,23:18.32
5,15,23:18.32
7,15,23:18.32
14,15,23:18.32
-10,16,23:18.4
1,16,23:18.32
2,16,23:18.32
8,16,23:18.32
9,16,23:18.32
10,16,23:18.32
12,16,23:18.32
2,17,23:18.32
6,17,23:18.32
10,17,23:18.32
-2,-18,24:18.32
-2,-17,24:18.32
-5,-16,24:18.32
-4,-16,24:18.32
-3,-16,24:18.32
-2,-16,24:17.3
-1,-16,24:18.32
1,-16,24:18.32
-4,-15,24:18.32
-3,-15,24:18.32
-2,-15,24:17.3
-1,-15,24:18.32
0,-15,24:18.32
1,-15,24:18.32
2,-15,24:18.32
3,-15,24:18.32
-4,-14,24:18.32
-3,-14,24:18.32
-2,-14,24:17.3
-1,-14,24:18.32
0,-14,24:18.32
1,-14,24:18.32
2,-14,24:18.32
3,-14,24:18.32
-8,-13,24:18.32
-7,-13,24:18.32
-4,-13,24:18.32
-3,-13,24:17.3
-2,-13,24:17.3
-1,-13,24:17.3
0,-13,24:17.3
1,-13,24:17.3
2,-13,24:18.32
3,-13,24:18.32
4,-13,24:18.32
-9,-12,24:18.4
-8,-12,24:18.32
-7,-12,24:17.3
-6,-12,24:18.32
-5,-12,24:18.32
-4,-12,24:18.32
-3,-12,24:17.3
-1,-12,24:18.32
0,-12,24:18.32
1,-12,24:18.32
2,-12,24:18.32
-8,-11,24:18.32
-7,-11,24:17.3
-6,-11,24:18.32
-4,-11,24:18.32
-3,-11,24:17.3
-2,-11,24:18.32
-1,-11,24:18.32
-9,-10,24:18.32
-8,-10,24:18.32
-7,-10,24:17.3
-6,-10,24:18.32
-4,-10,24:18.32
-3,-10,24:17.3
-2,-10,24:18.32
-1,-10,24:18.32
7,-10,24:18.32
-14,-9,24:18.32
-8,-9,24:18.32
-7,-9,24:17.3
-5,-9,24:18.32
-4,-9,24:18.32
-3,-9,24:17.3
-2,-9,24:17.3
-1,-9,24:18.32
0,-9,24:18.32
6,-9,24:18.32
7,-9,24:18.32
-15,-8,24:18.32
-14,-8,24:18.32
-13,-8,24:18.32
-8,-8,24:18.32
-7,-8,24:17.3
-6,-8,24:17.3
-5,-8,24:17.3
-4,-8,24:17.3
-3,-8,24:17.3
-2,-8,24:18.32
-1,-8,24:18.32
0,-8,24:18.32
2,-8,24:18.32
5,-8,24:18.4
6,-8,24:18.32
-14,-7,24:18.32
-9,-7,24:18.32
-8,-7,24:18.32
-7,-7,24:18.32
-5,-7,24:18.32
-4,-7,24:18.32
-3,-7,24:18.32
-2,-7,24:18.32
-1,-7,24:18.32
0,-7,24:18.32
6,-7,24:18.32
-14,-6,24:18.32
-13,-6,24:18.32
-11,-6,24:18.32
-10,-6,24:18.32
-9,-6,24:18.32
-6,-6,24:18.32
-5,-6,24:18.32
-4,-6,24:18.32
-3,-6,24:18.32
-2,-6,24:18.32
-1,-6,24:18.32
0,-6,24:18.32
-17,-5,24:18.32
-16,-5,24:18.32
-15,-5,24:18.32
-14,-5,24:18.32
-13,-5,24:18.32
-12,-5,24:18.32
-11,-5,24:18.32
-10,-5,24:18.32
-9,-5,24:17.3
-6,-5,24:18.32
-5,-5,24:18.32
-4,-5,24:18.32
-3,-5,24:18.32
-2,-5,24:18.32
-1,-5,24:18.32
1,-5,24:18.32
-14,-4,24:18.32
-13,-4,24:18.32
-12,-4,24:17.3
-11,-4,24:17.3
-10,-4,24:17.3
-9,-4,24:17.3
-4,-4,24:18.32
-3,-4,24:18.32
-2,-4,24:18.32
1,-4,24:18.32
2,-4,24:18.32
4,-4,24:18.32
8,-4,24:18.32
-13,-3,24:18.32
-12,-3,24:18.32
-11,-3,24:18.32
-10,-3,24:18.32
-3,-3,24:18.32
-2,-3,24:18.32
-1,-3,24:18.32
0,-3,24:18.32
1,-3,24:18.32
2,-3,24:18.32
3,-3,24:18.32
4,-3,24:18.32
5,-3,24:18.32
8,-3,24:18.32
9,-3,24:18.32
13,-3,24:18.32
-13,-2,24:18.32
-12,-2,24:18.32
-11,-2,24:18.32
-3,-2,24:18.32
-2,-2,24:18.32
-1,-2,24:18.32
0,-2,24:18.32
1,-2,24:18.32
2,-2,24:18.32
3,-2,24:18.32
4,-2,24:18.32
5,-2,24:18.32
8,-2,24:18.32
9,-2,24:18.32
13,-2,24:18.32
-14,-1,24:18.32
-13,-1,24:18.32
-12,-1,24:18.32
-1,-1,24:18.32
0,-1,24:18.32
1,-1,24:18.32
2,-1,24:18.32
3,-1,24:18.32
4,-1,24:18.32
5,-1,24:18.32
6,-1,24:18.32
7,-1,24:18.32
8,-1,24:18.32
9,-1,24:18.32
14,-1,24:18.32
15,-1,24:18.32
-13,0,24:18.32
-9,0,24:18.32
0,0,24:18.32
1,0,24:18.32
2,0,24:17.3
3,0,24:17.3
4,0,24:17.3
5,0,24:17.3
6,0,24:17.3
7,0,24:17.3
8,0,24:18.32
-10,1,24:18.32
-9,1,24:17.3
-8,1,24:17.3
-7,1,24:17.3
0,1,24:17.3
1,1,24:18.32
2,1,24:17.3
3,1,24:18.32
5,1,24:17.3
7,1,24:18.32
8,1,24:18.32
-10,2,24:18.32
-9,2,24:18.32
0,2,24:17.3
1,2,24:18.32
2,2,24:18.32
7,2,24:18.32
-12,3,24:18.32
-9,3,24:18.32
-2,3,24:18.32
-1,3,24:18.32
0,3,24:18.32
1,3,24:18.32
2,3,24:18.32
-9,4,24:18.32
0,4,24:18.32
1,4,24:18.32
-1,5,24:18.32
0,5,24:18.32
1,5,24:18.32
-7,6,24:18.32
-4,6,24:18.32
-3,6,24:18.32
-2,6,24:18.32
-1,6,24:18.32
0,6,24:18.32
1,6,24:18.32
-8,7,24:18.32
-7,7,24:18.32
-4,7,24:18.32
0,7,24:18.32
1,7,24:18.32
-8,8,24:18.32
-7,8,24:18.32
0,8,24:18.32
1,8,24:18.32
2,8,24:18.32
0,9,24:18.32
1,9,24:18.32
2,9,24:18.32
3,9,24:18.32
6,9,24:18.32
-8,10,24:18.32
-7,10,24:18.32
-6,10,24:18.32
-5,10,24:18.32
-1,10,24:18.32
0,10,24:18.32
1,10,24:18.32
2,10,24:18.32
3,10,24:18.32
4,10,24:18.32
5,10,24:18.32
7,10,24:18.32
8,10,24:18.32
-8,11,24:18.32
-7,11,24:18.32
-6,11,24:18.32
-5,11,24:18.32
-4,11,24:18.32
-3,11,24:18.32
-2,11,24:18.32
0,11,24:18.32
1,11,24:18.32
2,11,24:18.32
3,11,24:18.32
4,11,24:18.32
5,11,24:18.32
6,11,24:18.32
7,11,24:18.32
8,11,24:18.32
-7,12,24:18.32
-1,12,24:18.32
0,12,24:18.32
1,12,24:18.32
2,12,24:18.32
3,12,24:18.32
4,12,24:18.32
5,12,24:18.32
10,12,24:18.32
0,13,24:18.32
1,13,24:18.32
2,13,24:18.32
3,13,24:18.32
14,14,24:18.32
14,15,24:18.32
-3,-17,25:18.32
-3,-16,25:18.32
-2,-16,25:18.32
-3,-15,25:18.32
-2,-15,25:18.32
-2,-14,25:18.32
-1,-14,25:18.32
-3,-13,25:18.32
-2,-13,25:18.32
-1,-13,25:18.32
0,-13,25:18.32
1,-13,25:18.32
2,-13,25:18.32
-7,-12,25:18.32
-4,-12,25:18.32
-3,-12,25:18.32
-1,-12,25:18.32
-7,-11,25:18.32
-3,-11,25:18.32
7,-11,25:18.32
8,-11,25:18.32
-7,-10,25:18.32
-3,-10,25:18.32
7,-10,25:18.32
8,-10,25:18.32
-9,-9,25:18.32
-8,-9,25:18.32
-7,-9,25:18.32
-6,-9,25:18.32
-5,-9,25:18.32
-4,-9,25:18.32
-3,-9,25:18.32
-2,-9,25:18.32
5,-9,25:18.32
6,-9,25:18.32
7,-9,25:17.3
8,-9,25:18.32
-9,-8,25:18.32
-8,-8,25:18.32
-7,-8,25:17.3
-6,-8,25:18.32
-5,-8,25:18.32
-4,-8,25:18.32
-3,-8,25:18.32
5,-8,25:18.32
6,-8,25:18.32
7,-8,25:18.32
8,-8,25:18.32
-8,-7,25:18.32
-7,-7,25:17.3
-3,-7,25:18.32
-2,-7,25:18.32
5,-7,25:18.32
6,-7,25:18.32
7,-7,25:18.32
9,-7,25:18.32
-13,-6,25:18.32
-11,-6,25:18.32
-8,-6,25:18.32
-7,-6,25:17.3
-6,-6,25:18.32
3,-6,25:18.32
4,-6,25:18.32
9,-6,25:18.32
-13,-5,25:18.32
-9,-5,25:18.32
-8,-5,25:18.32
-7,-5,25:17.3
-6,-5,25:18.32
6,-5,25:18.32
-12,-4,25:18.32
-11,-4,25:18.32
-10,-4,25:18.32
-9,-4,25:17.3
-8,-4,25:17.3
-7,-4,25:17.3
-6,-4,25:18.32
-5,-4,25:18.32
-11,-3,25:18.32
-9,-3,25:18.32
-8,-3,25:18.32
-7,-3,25:17.3
-6,-3,25:18.32
-5,-3,25:18.32
-4,-3,25:18.32
-9,-2,25:18.32
-8,-2,25:18.32
-7,-2,25:17.3
-6,-2,25:18.32
-5,-2,25:18.32
-4,-2,25:18.32
0,-2,25:18.32
1,-2,25:18.32
5,-2,25:18.32
-9,-1,25:18.32
-8,-1,25:18.32
-7,-1,25:17.3
-6,-1,25:18.32
-4,-1,25:18.32
2,-1,25:18.32
3,-1,25:18.32
5,-1,25:18.32
7,-1,25:18.32
-10,0,25:18.32
-9,0,25:18.32
-8,0,25:18.32
-7,0,25:17.3
2,0,25:18.32
3,0,25:18.32
4,0,25:18.32
5,0,25:17.3
6,0,25:18.32
7,0,25:18.32
8,0,25:18.32
9,0,25:18.32
-10,1,25:18.32
-9,1,25:18.32
-8,1,25:18.32
-7,1,25:17.3
0,1,25:17.3
2,1,25:18.32
4,1,25:18.32
5,1,25:17.3
6,1,25:18.32
-10,2,25:18.32
-9,2,25:18.32
-8,2,25:18.32
-7,2,25:18.32
0,2,25:17.3
2,2,25:18.32
3,2,25:18.32
4,2,25:18.32
5,2,25:17.3
6,2,25:18.32
-10,3,25:18.32
-9,3,25:18.32
-8,3,25:18.32
-7,3,25:18.32
0,3,25:18.32
3,3,25:18.32
4,3,25:17.3
5,3,25:17.3
6,3,25:18.32
7,3,25:18.32
-9,4,25:18.32
-8,4,25:18.32
0,4,25:18.32
1,4,25:18.32
3,4,25:18.32
4,4,25:17.3
5,4,25:18.32
6,4,25:18.32
7,4,25:18.32
-9,5,25:18.32
-8,5,25:18.32
-6,5,25:18.32
-1,5,25:18.32
3,5,25:18.32
4,5,25:17.3
5,5,25:18.32
6,5,25:18.32
7,5,25:18.32
8,5,25:18.32
-8,6,25:18.32
-7,6,25:18.32
-6,6,25:18.32
-5,6,25:18.32
-4,6,25:18.32
3,6,25:18.32
4,6,25:17.3
5,6,25:17.3
6,6,25:17.3
7,6,25:18.32
8,6,25:18.32
9,6,25:18.32
-7,7,25:18.32
-6,7,25:18.32
1,7,25:18.32
3,7,25:18.32
4,7,25:18.32
5,7,25:18.32
6,7,25:17.3
7,7,25:18.32
8,7,25:18.32
9,7,25:18.32
-7,8,25:18.32
-1,8,25:18.32
3,8,25:18.32
4,8,25:18.32
5,8,25:18.32
6,8,25:18.32
7,8,25:18.32
8,8,25:18.4
-7,9,25:18.32
-1,9,25:18.32
6,9,25:18.32
-8,10,25:18.32
-7,10,25:18.32
-6,10,25:18.32
-5,10,25:18.32
-4,10,25:18.32
-1,10,25:18.32
-5,11,25:18.32
-4,11,25:18.32
-3,11,25:18.32
-2,11,25:18.32
-1,11,25:18.32
0,11,25:18.32
5,11,25:18.32
8,11,25:18.32
-5,12,25:18.32
-4,12,25:18.32
1,12,25:18.32
2,12,25:18.32
7,-10,26:18.32
8,-10,26:18.32
-4,-9,26:18.32
6,-9,26:18.32
7,-9,26:17.3
8,-9,26:18.32
-7,-8,26:18.32
6,-8,26:18.32
7,-8,26:17.3
8,-8,26:18.32
9,-8,26:18.32
10,-8,26:18.32
-7,-7,26:18.32
6,-7,26:18.32
7,-7,26:17.3
8,-7,26:17.3
9,-7,26:17.3
10,-7,26:18.32
-8,-6,26:18.32
-7,-6,26:18.32
3,-6,26:18.32
5,-6,26:18.4
6,-6,26:18.32
7,-6,26:18.32
9,-6,26:18.32
-8,-5,26:18.32
-7,-5,26:18.32
3,-5,26:18.32
4,-5,26:18.32
6,-5,26:18.32
7,-5,26:18.32
8,-5,26:18.32
9,-5,26:18.4
-9,-4,26:18.32
-8,-4,26:18.32
-7,-4,26:18.32
1,-4,26:18.4
2,-4,26:18.32
5,-4,26:18.32
7,-4,26:18.32
10,-4,26:18.32
-9,-3,26:18.32
-8,-3,26:18.32
-7,-3,26:17.3
-6,-3,26:18.32
-5,-3,26:18.32
4,-3,26:18.32
5,-3,26:18.4
8,-3,26:18.32
-8,-2,26:18.32
-7,-2,26:17.3
-6,-2,26:18.32
0,-2,26:18.32
1,-2,26:18.4
3,-2,26:18.32
4,-2,26:18.32
5,-2,26:18.32
-8,-1,26:18.32
-7,-1,26:17.3
-6,-1,26:18.32
-5,-1,26:18.32
-4,-1,26:18.32
-3,-1,26:18.32
-2,-1,26:18.32
3,-1,26:18.32
4,-1,26:18.32
-9,0,26:18.32
-8,0,26:18.32
-7,0,26:17.3
-6,0,26:18.32
-4,0,26:18.32
-3,0,26:18.32
-2,0,26:18.32
-1,0,26:18.32
0,0,26:18.32
2,0,26:17.3
5,0,26:18.32
6,0,26:18.32
7,0,26:18.32
-8,1,26:18.32
-7,1,26:17.3
-6,1,26:17.3
-5,1,26:17.3
-4,1,26:17.3
-3,1,26:17.3
-2,1,26:17.3
-1,1,26:17.3
0,1,26:17.3
1,1,26:17.3
2,1,26:17.3
4,1,26:18.32
5,1,26:18.32
-8,2,26:18.32
-7,2,26:18.32
-4,2,26:17.3
-3,2,26:17.3
-2,2,26:17.3
-1,2,26:17.3
0,2,26:17.3
1,2,26:18.32
2,2,26:18.32
5,2,26:18.32
-8,3,26:18.32
-7,3,26:18.32
-3,3,26:18.32
-2,3,26:18.32
-1,3,26:18.32
0,3,26:18.32
3,3,26:18.32
4,3,26:18.32
5,3,26:18.32
6,3,26:18.32
-3,4,26:18.32
-2,4,26:18.32
3,4,26:18.32
4,4,26:18.32
5,4,26:18.32
-7,5,26:18.32
-6,5,26:18.32
-3,5,26:18.32
-2,5,26:18.32
4,5,26:18.32
6,5,26:18.32
-7,6,26:18.32
-3,6,26:18.32
-2,6,26:18.32
-1,6,26:18.32
4,6,26:18.32
5,6,26:18.32
6,6,26:18.32
7,6,26:18.32
-7,7,26:18.32
-6,7,26:18.32
-4,7,26:18.32
-2,7,26:18.32
-1,7,26:18.32
4,7,26:18.32
6,7,26:18.32
7,7,26:18.32
8,7,26:18.32
-7,8,26:18.32
-6,8,26:17.3
-5,8,26:17.3
-4,8,26:17.3
-3,8,26:17.3
-2,8,26:17.3
-1,8,26:18.32
6,8,26:18.4
-7,9,26:18.32
-6,9,26:18.32
-5,9,26:17.3
-4,9,26:18.32
-3,9,26:18.32
-2,9,26:17.3
-1,9,26:18.32
-6,10,26:18.32
-5,10,26:17.3
-4,10,26:18.32
-3,10,26:18.32
-2,10,26:18.32
-1,10,26:18.32
-5,11,26:18.32
-4,11,26:18.32
-3,11,26:18.32
-2,11,26:18.32
-4,12,26:18.32
7,-9,27:18.32
8,-9,27:18.32
7,-8,27:18.32
8,-8,27:18.32
6,-7,27:18.32
7,-7,27:17.3
8,-7,27:18.32
9,-7,27:18.32
3,-6,27:18.32
4,-6,27:18.32
6,-6,27:18.32
7,-6,27:17.3
8,-6,27:18.32
9,-6,27:18.32
1,-5,27:18.32
2,-5,27:18.32
3,-5,27:18.32
4,-5,27:18.32
5,-5,27:18.32
6,-5,27:18.32
7,-5,27:17.3
8,-5,27:18.32
9,-5,27:18.32
10,-5,27:18.32
0,-4,27:18.32
1,-4,27:18.32
2,-4,27:17.3
3,-4,27:17.3
4,-4,27:17.3
5,-4,27:17.3
6,-4,27:17.3
7,-4,27:17.3
8,-4,27:17.3
9,-4,27:18.32
10,-4,27:18.32
11,-4,27:18.32
-8,-3,27:18.32
-7,-3,27:18.32
1,-3,27:18.32
2,-3,27:17.3
3,-3,27:18.32
4,-3,27:18.32
5,-3,27:18.32
6,-3,27:18.32
7,-3,27:18.32
8,-3,27:18.32
9,-3,27:18.32
-8,-2,27:18.32
-7,-2,27:18.32
0,-2,27:18.32
1,-2,27:18.32
2,-2,27:17.3
3,-2,27:18.32
4,-2,27:18.32
8,-2,27:18.32
-8,-1,27:18.32
-7,-1,27:18.32
-6,-1,27:18.32
-3,-1,27:18.32
2,-1,27:17.3
3,-1,27:18.32
-7,0,27:18.32
-6,0,27:18.32
-5,0,27:18.32
-4,0,27:18.32
-3,0,27:18.32
-2,0,27:18.32
-1,0,27:18.32
1,0,27:18.4
2,0,27:17.3
3,0,27:18.32
6,0,27:18.32
-7,1,27:18.32
-6,1,27:17.3
-5,1,27:17.3
-4,1,27:17.3
-3,1,27:17.3
-2,1,27:17.3
-1,1,27:17.3
0,1,27:18.32
1,1,27:18.32
2,1,27:17.3
3,1,27:18.32
-7,2,27:18.32
-6,2,27:18.32
-5,2,27:18.32
-4,2,27:17.3
-3,2,27:18.32
-2,2,27:18.32
-1,2,27:18.32
0,2,27:18.32
2,2,27:18.32
-6,3,27:18.32
-5,3,27:18.32
-4,3,27:17.3
-3,3,27:18.32
-2,3,27:18.32
-1,3,27:18.32
-7,4,27:18.32
-6,4,27:18.32
-5,4,27:18.32
-4,4,27:17.3
-3,4,27:18.32
-5,5,27:18.32
-4,5,27:17.3
-3,5,27:18.32
-6,6,27:18.32
-5,6,27:18.32
-4,6,27:17.3
-3,6,27:18.32
-6,7,27:18.32
-5,7,27:18.32
-4,7,27:17.3
-3,7,27:18.32
4,7,27:18.32
-6,8,27:18.32
-5,8,27:18.32
-4,8,27:17.3
-3,8,27:18.32
-2,8,27:18.32
-5,9,27:18.32
-4,9,27:18.32
-3,9,27:18.32
-2,9,27:18.32
-5,10,27:18.32
7,-7,28:18.4
7,-6,28:18.32
2,-5,28:18.32
5,-5,28:18.32
7,-5,28:18.32
9,-5,28:18.32
1,-4,28:18.4
2,-4,28:18.32
3,-4,28:18.32
4,-4,28:18.32
5,-4,28:18.32
6,-4,28:18.32
7,-4,28:18.32
8,-4,28:18.32
2,-3,28:18.32
3,-3,28:18.32
4,-3,28:18.32
5,-3,28:18.32
6,-3,28:18.32
8,-3,28:18.32
2,-2,28:18.32
8,-2,28:18.32
2,-1,28:18.32
3,-1,28:18.32
-6,0,28:18.32
-4,0,28:18.32
-2,0,28:18.32
-1,0,28:18.32
2,0,28:18.32
-7,1,28:18.32
-6,1,28:18.32
-5,1,28:18.32
-4,1,28:18.32
-3,1,28:18.32
-2,1,28:18.32
-1,1,28:18.32
2,1,28:18.32
-4,2,28:18.32
-2,2,28:18.4
-4,3,28:18.32
-4,4,28:18.32
-4,5,28:18.32
-3,5,28:18.32
-4,6,28:18.32
-3,6,28:18.4
-5,7,28:18.32
-4,7,28:18.32
-5,8,28:18.4
-4,8,28:18.32
1,4,0:31.2
4,2,0:31.1
4,1,0:37.0
-2,0,0:31.1
2,-1,0:31.2
-1,-1,0:31.2
1,-2,0:31.1
0,-2,0:31.1
