[META]
version=2.0
spawnOnBlockType=2
spawnSunlight=True
spawnDarkness=True
spawnWater=False
spawnLava=False
underFill=False
randomRotation=True
dig=True
tree=True
branch=False
needsFoundation=True
rarity=100
collisionPercentage=30
spawnElevationMin=0
spawnElevationMax=128
spawnInBiome=OttaJungle
[DATA]
-3,-4,0:18.3
-2,-4,0:18.3
-1,-4,0:18.3
2,-4,0:18.3
3,-4,0:18.3
-3,-3,0:18.3
-2,-3,0:17.3
-1,-3,0:18.3
2,-3,0:18.3
3,-3,0:18.3
-5,-2,0:2
-4,-2,0:2
-3,-2,0:2
-2,-2,0:3
-1,-2,0:2
2,-2,0:17.3
3,-2,0:17.3
-5,-1,0:2
-4,-1,0:3
-3,-1,0:2
-2,-1,0:3
-1,-1,0:2
2,-1,0:17.3
3,-1,0:17.3
-5,0,0:2
-4,0,0:3
-3,0,0:17.3
-2,0,0:17.3
-1,0,0:17.3
0,0,0:2
1,0,0:2
-6,1,0:17.3
-5,1,0:17.3
-4,1,0:3
-3,1,0:17.3
-2,1,0:17.3
-1,1,0:17.3
0,1,0:2
1,1,0:2
-5,2,0:2
-4,2,0:3
-3,2,0:17.3
-2,2,0:17.3
-1,2,0:17.3
0,2,0:3
1,2,0:2
-5,3,0:2
-4,3,0:3
-3,3,0:3
-2,3,0:3
-1,3,0:2
0,3,0:2
-5,4,0:2
-4,4,0:2
-3,4,0:3
-2,4,0:3
-1,4,0:2
-5,5,0:2
-4,5,0:2
-3,5,0:17.3
-2,5,0:2
-4,6,0:18.3
-3,6,0:17.3
-2,6,0:18.3
-4,7,0:18.3
-3,7,0:17.3
-2,7,0:18.3
-3,8,0:18.3
2,9,0:31
-3,9,0:106.4
-2,8,0:106.4
-1,7,0:31.1
-5,7,0:106.8
-1,6,0:106.2
-5,6,0:106.8
-1,5,0:31.1
3,4,0:106.4
1,4,0:106.4
4,3,0:106.2
4,2,0:106.2
-6,2,0:106.4
-7,2,0:31.1
4,1,0:106.2
-7,1,0:106.8
-8,1,0:31
-6,0,0:106.1
-7,0,0:31.1
-6,-1,0:31.1
-7,-1,0:31.1
5,-2,0:106.2
1,-3,0:31.1
0,-3,0:106.2
-4,-3,0:106.8
-6,-3,0:31.2
0,-4,0:106.2
-4,-4,0:31.1
2,-5,0:31
-1,-5,0:106.1
-2,-5,0:106.1
-3,-5,0:31.2
-4,-5,0:31.1
-5,-5,0:31
-3,-7,0:106.1
-3,-4,1:18.3
-2,-4,1:18.3
-3,-3,1:18.3
-2,-3,1:17.3
-1,-3,1:18.3
3,-3,1:18.3
-3,-2,1:18.3
-2,-2,1:17.3
2,-2,1:18.3
3,-2,1:17.3
4,-2,1:18.3
-4,-1,1:2
-3,-1,1:18.3
-2,-1,1:17.3
2,-1,1:18.3
3,-1,1:17.3
4,-1,1:18.3
-4,0,1:2
-3,0,1:17.3
-2,0,1:17.3
-1,0,1:17.3
1,0,1:18.3
2,0,1:17.3
3,0,1:17.3
4,0,1:18.3
-6,1,1:18.3
-5,1,1:17.3
-4,1,1:17.3
-3,1,1:17.3
-2,1,1:17.3
2,1,1:18.3
3,1,1:18.3
-4,2,1:2
-3,2,1:17.3
-2,2,1:17.3
-1,2,1:17.3
0,2,1:2
2,2,1:18.3
3,2,1:18.3
-4,3,1:2
-3,3,1:2
-2,3,1:17.3
3,3,1:18.3
-4,4,1:18.3
-3,4,1:17.3
-2,4,1:17.3
-4,5,1:18.3
-3,5,1:17.3
-2,5,1:18.3
-4,6,1:18.3
-3,6,1:17.3
-2,6,1:18.3
-3,7,1:18.3
-1,6,1:106.2
-5,6,1:106.8
1,5,1:106.2
-5,5,1:31.1
4,4,1:106.2
3,4,1:106.4
1,4,1:106.4
-1,4,1:106.2
-5,4,1:106.8
4,3,1:106.2
-1,3,1:106.2
-5,3,1:31.1
-7,3,1:106.4
5,2,1:106.2
4,2,1:106.2
-5,2,1:106.4
-6,2,1:106.4
-8,2,1:106.8
4,1,1:106.2
-8,1,1:106.8
5,0,1:106.2
0,0,1:106.2
-5,0,1:106.1
-6,0,1:106.1
-1,-1,1:31.2
-5,-1,1:31.1
5,-2,1:106.2
-1,-2,1:106.2
-4,-2,1:106.8
-5,-2,1:31.1
4,-3,1:106.2
0,-3,1:106.2
-4,-3,1:106.8
-4,-4,1:106.8
2,-5,1:106.2
-2,-5,1:106.1
-3,-5,1:106.1
1,-6,1:106.2
-4,-6,1:106.8
0,-7,1:106.1
-1,-7,1:106.1
-2,-7,1:106.1
-3,-7,1:106.1
-3,-4,2:18.3
-4,-3,2:18.3
-2,-3,2:18.3
-3,-2,2:18.3
-2,-2,2:17.3
3,-2,2:18.3
-3,-1,2:18.3
-2,-1,2:17.3
3,-1,2:18.3
-3,0,2:17.3
-2,0,2:17.3
-1,0,2:17.3
1,0,2:18.3
2,0,2:17.3
3,0,2:17.3
4,0,2:18.3
-5,1,2:18.3
-4,1,2:18.3
-3,1,2:17.3
2,1,2:17.3
3,1,2:17.3
4,1,2:18.3
-3,2,2:17.3
-2,2,2:17.3
-1,2,2:17.3
2,2,2:17.3
3,2,2:17.3
4,2,2:18.3
-2,3,2:18.3
1,3,2:18.3
2,3,2:18.3
3,3,2:18.3
-3,4,2:17.3
-2,4,2:17.3
-3,5,2:18.3
-2,6,2:18.3
-2,7,2:18.3
-1,8,2:106.4
-2,8,2:106.4
0,7,2:106.2
0,6,2:106.4
3,5,2:106.4
1,5,2:106.2
4,4,2:106.2
2,4,2:106.4
1,4,2:106.4
-1,4,2:106.2
-5,4,2:106.4
-6,4,2:106.4
4,3,2:106.2
-1,3,2:106.2
-3,3,2:106.8
-7,3,2:106.4
5,2,2:106.2
0,2,2:106.2
-4,2,2:31.1
-5,2,2:106.4
-8,2,2:106.8
5,1,2:106.2
-8,1,2:106.8
5,0,2:106.2
0,0,2:106.2
-4,0,2:106.1
-5,0,2:106.1
4,-1,2:106.2
-4,-1,2:31.1
4,-2,2:106.2
-1,-2,2:106.2
-4,-2,2:106.8
-3,-3,2:106.1
-2,-4,2:106.1
-4,-4,2:106.8
2,-5,2:106.2
-3,-5,2:106.1
1,-6,2:106.2
-4,-6,2:106.8
0,-7,2:106.1
-1,-7,2:106.1
-2,-7,2:106.1
-3,-7,2:106.1
-3,-4,3:18.3
-4,-3,3:18.3
-3,-3,3:18.3
-2,-2,3:18.3
-2,-1,3:18.3
-3,0,3:17.3
-2,0,3:17.3
-1,0,3:17.3
1,0,3:18.3
2,0,3:18.3
3,0,3:18.3
4,0,3:18.3
-3,1,3:17.3
1,1,3:17.3
2,1,3:17.3
3,1,3:18.3
-3,2,3:17.3
-1,2,3:17.3
1,2,3:17.3
2,2,3:17.3
3,2,3:18.3
1,3,3:18.3
2,3,3:18.3
-3,4,3:18.3
-2,4,3:18.3
-3,7,3:18.3
-1,8,3:106.4
-2,8,3:106.4
-3,8,3:106.4
0,7,3:106.2
-4,7,3:106.8
0,6,3:106.4
3,5,3:106.4
1,5,3:106.2
4,4,3:106.2
2,4,3:106.4
1,4,3:106.4
-5,4,3:106.4
-6,4,3:106.4
3,3,3:106.2
-7,3,3:106.4
0,2,3:106.2
-8,2,3:106.8
-8,1,3:106.8
0,0,3:106.2
5,-1,3:106.2
4,-2,3:106.1
3,-2,3:106.1
-1,-2,3:106.2
-7,-2,3:106.8
-7,-3,3:106.8
-4,-4,3:106.8
-5,-4,3:106.1
2,-5,3:106.2
-3,-5,3:106.1
1,-6,3:106.2
-4,-6,3:106.8
0,-7,3:106.1
-1,-7,3:106.1
-2,-7,3:106.1
-3,-7,3:106.1
-3,-4,4:18.3
-4,-3,4:17.3
-3,-3,4:18.3
-4,-2,4:18.3
-3,-2,4:18.3
-2,-2,4:18.3
-3,0,4:17.3
-2,0,4:17.3
-1,0,4:17.3
1,0,4:18.3
-3,1,4:17.3
-1,1,4:17.3
0,1,4:17.3
1,1,4:17.3
2,1,4:18.3
-3,2,4:17.3
-1,2,4:17.3
0,2,4:17.3
1,2,4:17.3
2,2,4:18.3
1,3,4:18.3
3,3,4:18.3
-1,8,4:106.4
-2,8,4:106.4
-3,8,4:106.4
0,7,4:106.2
-4,7,4:106.8
0,6,4:106.4
-4,6,4:106.8
3,5,4:106.4
2,5,4:106.4
1,5,4:106.2
-4,5,4:106.8
4,4,4:106.2
1,4,4:106.4
-5,4,4:106.4
-6,4,4:106.4
4,3,4:106.2
-7,3,4:106.4
-8,2,4:106.8
-8,1,4:106.8
5,0,4:106.2
0,0,4:106.2
5,-1,4:106.2
4,-2,4:106.1
3,-2,4:106.1
-7,-2,4:106.8
-7,-3,4:106.8
-4,-4,4:106.8
-5,-4,4:106.1
2,-5,4:106.2
-3,-5,4:106.1
1,-6,4:106.2
-4,-6,4:106.8
0,-7,4:106.1
-1,-7,4:106.1
-2,-7,4:106.1
-3,-7,4:106.1
-3,-4,5:18.3
-4,-3,5:17.3
-3,-3,5:17.3
-4,-2,5:17.3
-3,-2,5:17.3
-2,-2,5:17.3
-3,-1,5:18.3
-2,-1,5:18.3
-3,0,5:17.3
-2,0,5:17.3
-1,0,5:17.3
1,0,5:18.3
-3,1,5:17.3
-2,1,5:17.3
-1,1,5:17.3
0,1,5:18.3
1,1,5:18.3
-6,2,5:18.3
-3,2,5:17.3
-2,2,5:17.3
-1,2,5:17.3
0,2,5:17.3
1,2,5:18.3
3,3,5:18.3
-1,8,5:106.4
-2,8,5:106.4
-3,8,5:106.4
0,7,5:106.2
-4,7,5:106.8
0,6,5:106.4
-4,6,5:106.8
3,5,5:106.4
2,5,5:106.4
1,5,5:106.2
-4,5,5:106.8
4,4,5:106.2
-5,4,5:106.4
-6,4,5:106.4
4,3,5:106.2
0,3,5:106.4
-7,3,5:106.4
-8,2,5:106.8
-8,1,5:106.8
5,0,5:106.2
0,0,5:106.2
5,-1,5:106.2
1,-1,5:106.1
4,-2,5:106.1
3,-2,5:106.1
-1,-2,5:106.2
-5,-2,5:106.8
-7,-2,5:106.8
-7,-3,5:106.8
-4,-4,5:106.8
-5,-4,5:106.1
-6,-4,5:106.1
2,-5,5:106.2
-3,-5,5:106.1
1,-6,5:106.2
-4,-6,5:106.8
0,-7,5:106.1
-1,-7,5:106.1
-2,-7,5:106.1
-3,-7,5:106.1
-2,-5,6:18.3
-3,-4,6:18.3
-4,-3,6:18.3
-3,-3,6:17.3
-4,-2,6:17.3
-3,-2,6:17.3
-2,-2,6:17.3
-3,-1,6:17.3
-2,-1,6:17.3
-3,0,6:17.3
-2,0,6:17.3
-1,0,6:17.3
0,0,6:18.3
1,0,6:18.3
-7,1,6:18.3
-6,1,6:18.3
-5,1,6:18.3
-3,1,6:17.3
-2,1,6:17.3
-1,1,6:17.3
0,1,6:18.3
-7,2,6:18.3
-6,2,6:18.3
-5,2,6:18.3
-3,2,6:17.3
-2,2,6:17.3
-1,2,6:17.3
0,2,6:18.3
-6,3,6:18.3
-5,3,6:18.3
3,3,6:18.3
-1,8,6:106.4
-2,8,6:106.4
-3,8,6:106.4
0,7,6:106.2
-4,7,6:106.8
0,6,6:106.4
-4,6,6:106.8
3,5,6:106.4
2,5,6:106.4
1,5,6:106.2
-4,5,6:106.8
4,4,6:106.2
-5,4,6:106.4
-6,4,6:106.4
4,3,6:106.2
0,3,6:106.4
-2,3,6:106.4
-7,3,6:106.4
-8,2,6:106.8
-8,1,6:106.8
5,0,6:106.2
5,-1,6:106.2
1,-1,6:106.1
-1,-1,6:106.2
4,-2,6:106.1
3,-2,6:106.1
-1,-2,6:106.2
-5,-2,6:106.8
-7,-2,6:106.8
-2,-3,6:106.2
-7,-3,6:106.8
-4,-4,6:106.8
-5,-4,6:106.1
-6,-4,6:106.1
2,-5,6:106.2
-3,-5,6:106.1
1,-6,6:106.2
-4,-6,6:106.8
0,-7,6:106.1
-1,-7,6:106.1
-2,-7,6:106.1
-3,-7,6:106.1
-1,-6,7:18.3
-2,-5,7:18.3
-3,-4,7:18.3
-3,-3,7:18.3
-4,-2,7:18.3
-3,-2,7:18.3
-2,-2,7:18.3
-3,-1,7:17.3
-2,-1,7:17.3
-6,0,7:18.3
-5,0,7:18.3
-3,0,7:17.3
-2,0,7:17.3
-1,0,7:17.3
0,0,7:18.3
1,0,7:18.3
-7,1,7:18.3
-6,1,7:17.3
-5,1,7:17.3
-4,1,7:18.3
-3,1,7:17.3
-1,1,7:17.3
0,1,7:18.3
-7,2,7:18.3
-6,2,7:17.3
-5,2,7:17.3
-4,2,7:18.3
-3,2,7:17.3
-2,2,7:17.3
-1,2,7:17.3
0,2,7:18.3
-6,3,7:18.3
-5,3,7:18.3
3,3,7:18.3
-2,5,7:18.3
-1,8,7:106.4
-2,8,7:106.4
-3,8,7:106.4
0,7,7:106.2
-4,7,7:106.8
0,6,7:106.4
-4,6,7:106.8
3,5,7:106.4
2,5,7:106.4
1,5,7:106.2
-4,5,7:106.8
4,4,7:106.2
-5,4,7:106.4
-6,4,7:106.4
4,3,7:106.2
-2,3,7:106.4
-3,3,7:106.4
-7,3,7:106.4
-8,2,7:106.8
-8,1,7:106.8
5,0,7:106.2
5,-1,7:106.2
1,-1,7:106.1
0,-1,7:106.1
-1,-1,7:106.2
-6,-1,7:106.1
4,-2,7:106.1
3,-2,7:106.1
-1,-2,7:106.2
-5,-2,7:106.8
-7,-2,7:106.8
-7,-3,7:106.8
-4,-4,7:106.8
-5,-4,7:106.1
-6,-4,7:106.1
2,-5,7:106.2
-3,-5,7:106.1
1,-6,7:106.2
-4,-6,7:106.8
0,-7,7:106.1
-1,-7,7:106.1
-2,-7,7:106.1
-3,-7,7:106.1
-3,-6,8:18.3
-2,-6,8:18.3
-1,-6,8:18.3
0,-6,8:18.3
-3,-5,8:18.3
-2,-5,8:18.3
-1,-5,8:18.3
0,-5,8:18.3
1,-5,8:18.3
-3,-4,8:18.3
-1,-4,8:18.3
1,-4,8:18.3
-6,-3,8:18.3
-5,-3,8:18.3
-6,-2,8:18.3
-5,-2,8:18.3
1,-2,8:18.3
-3,-1,8:18.3
-2,-1,8:18.3
0,-1,8:18.3
2,-1,8:18.3
3,-1,8:18.3
4,-1,8:18.3
-6,0,8:18.3
-5,0,8:18.3
-4,0,8:18.3
-3,0,8:17.3
-2,0,8:17.3
-1,0,8:17.3
2,0,8:18.3
3,0,8:18.3
4,0,8:18.3
-7,1,8:18.3
-6,1,8:17.3
-5,1,8:17.3
-4,1,8:17.3
-3,1,8:17.3
-1,1,8:17.3
1,1,8:18.3
3,1,8:18.3
4,1,8:18.3
-7,2,8:18.3
-6,2,8:17.3
-5,2,8:17.3
-4,2,8:17.3
-3,2,8:17.3
-2,2,8:17.3
-1,2,8:17.3
-6,3,8:18.3
-5,3,8:18.3
-4,3,8:18.3
2,3,8:18.3
3,3,8:18.3
-2,5,8:18.3
-1,8,8:106.4
-2,8,8:106.4
-3,8,8:106.4
0,7,8:106.2
-2,7,8:106
-4,7,8:106.8
0,6,8:106.4
-2,6,8:106
-4,6,8:106.8
3,5,8:106.4
2,5,8:106.4
1,5,8:106.2
-4,5,8:106.8
4,4,8:106.2
-4,4,8:106.4
-5,4,8:106.4
-6,4,8:106.4
4,3,8:106.2
-1,3,8:106.4
-2,3,8:106.4
-3,3,8:106.4
-7,3,8:106.4
-8,2,8:106.8
-8,1,8:106.8
5,0,8:106.2
-7,0,8:106.8
5,-1,8:106.2
-1,-1,8:106.2
-4,-1,8:106.1
-5,-1,8:106.1
-6,-1,8:106.1
4,-2,8:106.1
3,-2,8:106.1
2,-2,8:106.2
-7,-2,8:106.8
-7,-3,8:106.8
-4,-4,8:106.8
-5,-4,8:106.1
-6,-4,8:106.1
2,-5,8:106.2
1,-6,8:106.2
-4,-6,8:106.8
0,-7,8:106.1
-1,-7,8:106.1
-2,-7,8:106.1
-3,-7,8:106.1
-3,-6,9:18.3
-2,-6,9:18.3
-1,-6,9:18.3
0,-6,9:18.3
-3,-5,9:18.3
-2,-5,9:18.3
-1,-5,9:18.3
0,-5,9:18.3
1,-5,9:18.3
-3,-4,9:18.3
-2,-4,9:18.3
-1,-4,9:18.3
0,-4,9:18.3
1,-4,9:18.3
-6,-3,9:18.3
-5,-3,9:18.3
-3,-3,9:18.3
-2,-3,9:18.3
-6,-2,9:18.3
-5,-2,9:18.3
1,-2,9:18.3
-6,-1,9:18.3
0,-1,9:18.3
1,-1,9:18.3
2,-1,9:18.3
3,-1,9:18.3
4,-1,9:18.3
-4,0,9:18.3
-3,0,9:17.3
-2,0,9:17.3
-1,0,9:17.3
0,0,9:18.3
1,0,9:18.3
2,0,9:18.3
3,0,9:18.3
4,0,9:18.3
-6,1,9:18.3
-5,1,9:18.3
-4,1,9:17.3
-3,1,9:17.3
-1,1,9:17.3
0,1,9:18.3
1,1,9:18.3
2,1,9:18.3
3,1,9:18.3
4,1,9:18.3
-6,2,9:18.3
-5,2,9:18.3
-4,2,9:17.3
-3,2,9:17.3
-2,2,9:17.3
-1,2,9:17.3
0,2,9:18.3
1,2,9:18.3
2,2,9:18.3
3,2,9:18.3
-5,3,9:18.3
-4,3,9:18.3
1,3,9:18.3
2,3,9:17.3
3,3,9:18.3
-5,4,9:18.3
-2,4,9:18.3
-1,4,9:18.3
0,4,9:18.3
2,4,9:18.3
3,4,9:18.3
-3,5,9:18.3
-2,5,9:18.3
-1,5,9:18.3
0,5,9:18.3
-3,6,9:18.3
-2,6,9:18.3
-1,6,9:18.3
-3,7,9:18.3
-2,7,9:18.3
-1,7,9:18.3
-1,8,9:106.4
-2,8,9:106.4
-3,8,9:106.4
0,7,9:106.2
-4,7,9:106.8
0,6,9:106.4
-4,6,9:106.8
3,5,9:106.4
2,5,9:106.4
1,5,9:106.2
-4,5,9:106.8
-5,5,9:106.4
4,4,9:106.2
-4,4,9:106.4
-6,4,9:106.8
4,3,9:106.2
4,2,9:106.2
5,0,9:106.2
5,-1,9:106.2
-4,-1,9:106.1
-7,-1,9:106.8
4,-2,9:106.1
3,-2,9:106.1
2,-2,9:106.2
-7,-2,9:106.8
-7,-3,9:106.8
-5,-4,9:106.1
-6,-4,9:106.1
2,-5,9:106.2
1,-6,9:106.2
-4,-6,9:106.8
0,-7,9:106.1
-1,-7,9:106.1
-2,-7,9:106.1
-3,-7,9:106.1
-3,-5,10:18.3
-2,-5,10:18.3
-1,-5,10:18.3
0,-5,10:18.3
-3,-4,10:18.3
-2,-4,10:18.3
-1,-4,10:18.3
0,-4,10:18.3
1,-4,10:18.3
-6,-3,10:18.3
-5,-3,10:18.3
-4,-3,10:18.3
-3,-3,10:17.3
-2,-3,10:17.3
-1,-3,10:18.3
0,-3,10:18.3
1,-3,10:18.3
-6,-2,10:18.3
-5,-2,10:18.3
-4,-2,10:18.3
-3,-2,10:18.3
-2,-2,10:18.3
-1,-2,10:18.3
0,-2,10:18.3
1,-2,10:18.3
-6,-1,10:18.3
-5,-1,10:18.3
-4,-1,10:18.3
-2,-1,10:18.3
-1,-1,10:18.3
0,-1,10:18.3
1,-1,10:18.3
2,-1,10:18.3
3,-1,10:18.3
4,-1,10:18.3
-6,0,10:18.3
-5,0,10:18.3
-4,0,10:18.3
-3,0,10:17.3
-2,0,10:17.3
-1,0,10:17.3
0,0,10:18.3
1,0,10:18.3
2,0,10:18.3
3,0,10:18.3
4,0,10:18.3
-5,1,10:18.3
-4,1,10:18.3
-3,1,10:17.3
-1,1,10:17.3
0,1,10:18.3
1,1,10:17.3
2,1,10:18.3
3,1,10:18.3
4,1,10:18.3
-5,2,10:18.3
-4,2,10:18.3
-3,2,10:17.3
-2,2,10:17.3
-1,2,10:17.3
0,2,10:18.3
1,2,10:17.3
2,2,10:17.3
3,2,10:18.3
-5,3,10:18.3
-2,3,10:18.3
-1,3,10:18.3
0,3,10:18.3
1,3,10:17.3
2,3,10:17.3
3,3,10:18.3
-5,4,10:18.3
-4,4,10:18.3
-2,4,10:18.3
-1,4,10:18.3
0,4,10:18.3
1,4,10:18.3
2,4,10:18.3
3,4,10:18.3
-3,5,10:18.3
-2,5,10:18.3
-1,5,10:18.3
0,5,10:18.3
-3,6,10:18.3
-2,6,10:18.3
-1,6,10:18.3
0,6,10:106.4
-4,6,10:106.8
3,5,10:106.4
2,5,10:106.4
1,5,10:106.2
-4,5,10:106.8
-5,5,10:106.4
4,4,10:106.2
-6,4,10:106.8
4,3,10:106.2
-4,3,10:106.4
4,2,10:106.2
5,0,10:106.2
-7,0,10:106.8
5,-1,10:106.2
-7,-1,10:106.8
4,-2,10:106.1
3,-2,10:106.1
2,-2,10:106.2
-7,-2,10:106.8
2,-3,10:106.2
-7,-3,10:106.8
-4,-4,10:106.1
-5,-4,10:106.1
-6,-4,10:106.1
-3,-4,11:18.3
-2,-4,11:18.3
-1,-4,11:18.3
0,-4,11:18.3
1,-4,11:18.3
-4,-3,11:18.3
-3,-3,11:17.3
-2,-3,11:17.3
-1,-3,11:18.3
0,-3,11:18.3
1,-3,11:18.3
-6,-2,11:18.3
-5,-2,11:18.3
-4,-2,11:18.3
-3,-2,11:17.3
-2,-2,11:17.3
-1,-2,11:18.3
0,-2,11:18.3
1,-2,11:18.3
-6,-1,11:18.3
-5,-1,11:18.3
-4,-1,11:18.3
-3,-1,11:18.3
-2,-1,11:17.3
-1,-1,11:17.3
0,-1,11:18.3
1,-1,11:18.3
2,-1,11:18.3
-6,0,11:18.3
-5,0,11:18.3
-4,0,11:18.3
-3,0,11:17.3
-2,0,11:17.3
-1,0,11:17.3
0,0,11:18.3.0
1,0,11:17.3
2,0,11:18.3
3,0,11:18.3
-4,1,11:18.3
-3,1,11:17.3
-1,1,11:17.3
0,1,11:18.3.0
1,1,11:17.3
2,1,11:17.3
3,1,11:18.3
-4,2,11:18.3
-3,2,11:17.3
-2,2,11:17.3
-1,2,11:17.3
0,2,11:17.3
1,2,11:17.3
2,2,11:18.3
-5,3,11:18.3
-4,3,11:18.3
-3,3,11:18.3
-2,3,11:17.3
-1,3,11:17.3
0,3,11:18.3
1,3,11:18.3
2,3,11:18.3
-5,4,11:18.3
-4,4,11:18.3
-3,4,11:18.3
-2,4,11:18.3
-1,4,11:18.3
0,4,11:18.3
-3,5,11:18.3
-2,5,11:18.3
-1,5,11:18.3
-3,6,11:106.4
-4,5,11:106.8
-5,5,11:106.4
-6,4,11:106.8
-7,0,11:106.8
-7,-1,11:106.8
2,-2,11:106.2
-7,-2,11:106.8
2,-4,11:106.2
-3,-3,12:18.3
-2,-3,12:18.3
-1,-3,12:18.3
0,-3,12:18.3
-3,-2,12:18.3
-2,-2,12:17.3
-1,-2,12:17.3
0,-2,12:18.3
-2,-1,12:18.3
-1,-1,12:17.3
0,-1,12:18.3
-3,0,12:18.3
-2,0,12:17.3
-1,0,12:18.3
0,0,12:18.3
1,0,12:18.3
-3,1,12:18.3
-2,1,12:17.3
-1,1,12:17.3
0,1,12:18.3
1,1,12:18.3
-3,2,12:18.3
-2,2,12:17.3
-1,2,12:17.3
0,2,12:17.3
1,2,12:18.3
-3,3,12:18.3
-2,3,12:17.3
-1,3,12:17.3
0,3,12:18.3
-2,4,12:18.3
-1,4,12:18.3
-1,5,12:106.4
-2,5,12:106.4
-2,-2,13:18.3
-1,-2,13:18.3
-2,-1,13:18.3
-1,-1,13:18.3
0,-1,13:18.3
-2,0,13:18.3
-1,0,13:18.3
-2,1,13:18.3
-1,1,13:18.3
0,1,13:18.3
-2,2,13:18.3
-1,2,13:18.3
0,2,13:18.3
1,2,13:18.3
-2,3,13:18.3
-1,3,13:18.3
-1,4,13:106.4
-2,4,13:106.4
-4,1,-1:17.3
-5,1,-1:17.3
-3,0,-1:17.3
-3,2,-1:17.3
-1,2,-1:17.3
-1,0,-1:17.3
2,-2,-1:17.3
3,-1,-1:17.3
-3,-3,-1:17.3
-2,-4,-1:17.3
-4,7,-1:17.3
-2,7,-1:17.3
0,-1,-1:17.3
0,3,-1:17.3
-3,3,-1:17.3
-2,5,-1:17.3
-3,5,-1:17.3
-2,1,-1:3
-4,0,-1:3
-2,3,-1:3
-1,4,-1:3
-3,4,-1:3
-3,6,-1:3
-4,3,-1:3
-3,-2,-1:3
-1,-2,-1:3
-2,-1,-1:3
0,1,-1:3
1,-1,-1:3
1,2,-1:3
1,4,-1:3
0,5,-1:3
