[META]
version=2.0
spawnOnBlockType=2,1
spawnSunlight=True
spawnDarkness=False
spawnWater=False
spawnLava=False
underFill=True
randomRotation=True
dig=True
tree=True
branch=False
needsFoundation=True
rarity=10
collisionPercentage=2
spawnElevationMin=0
spawnElevationMax=128
spawnInBiome=OttaWildlands
[DATA]
-2,0,0:17.3
-1,0,0:17.3
0,0,0:17.3
-2,1,0:17.3
-1,1,0:17.3
0,1,0:17.3
-1,2,0:17.3
0,2,0:17.3
-2,0,1:17.3
-1,0,1:17.3
0,0,1:17.3
-2,1,1:17.3
-1,1,1:17.3
0,1,1:17.3
-1,2,1:17.3
0,2,1:17.3
-2,0,2:17.3
-1,0,2:17.3
0,0,2:17.3
-2,1,2:17.3
-1,1,2:17.3
0,1,2:17.3
-1,2,2:17.3
0,2,2:17.3
-2,0,3:17.3
-1,0,3:17.3
0,0,3:17.3
-2,1,3:17.3
-1,1,3:17.3
0,1,3:17.3
-1,2,3:17.3
-2,0,4:17.3
-1,0,4:17.3
0,0,4:17.3
-2,1,4:17.3
-1,1,4:17.3
0,1,4:17.3
-2,0,5:17.3
-1,0,5:17.3
-1,1,5:17.3
0,1,5:17.3
-2,0,6:17.3
-1,0,6:17.3
-1,1,6:17.3
-1,0,7:17.3
-1,1,7:17.3
-1,1,8:17.3
-1,1,9:17.3
-1,1,10:17.3
-1,1,11:17.3
-1,1,12:17.3
-1,1,13:17.3
-1,1,14:17.3
-1,1,15:17.3
-1,1,16:17.3
-1,1,17:17.3
-1,1,18:17.3
-1,1,19:17.3
-1,1,20:17.3
-1,1,21:17.3
-1,1,22:17.3
-1,1,23:17.3
-1,1,24:17.3
-1,1,25:17.3
-1,-1,26:103
-1,1,26:17.3
-1,-1,27:85
-1,1,27:17.3
-3,2,27:103
-1,-1,28:85
-1,1,28:17.3
-3,2,28:85
2,2,28:103
-1,-1,29:17
-1,0,29:17
-1,1,29:17.3
-3,2,29:85
2,2,29:85
-1,-2,30:17
-1,-1,30:17.3
-2,1,30:17
-1,1,30:17.3
0,1,30:17
1,1,30:17
-3,2,30:85
-2,2,30:17
1,2,30:17
2,2,30:85
-3,-4,31:18
-2,-4,31:18
-1,-4,31:18
0,-4,31:18
1,-4,31:18
2,-4,31:18
-4,-3,31:18
-3,-3,31:18
-2,-3,31:17
-1,-3,31:18
0,-3,31:18
1,-3,31:18
2,-3,31:18
-5,-2,31:18
-4,-2,31:18
-3,-2,31:18
-2,-2,31:17
-1,-2,31:17.3
0,-2,31:17
1,-2,31:18
2,-2,31:18
3,-2,31:18
-5,-1,31:18
-4,-1,31:18
-3,-1,31:18
-2,-1,31:18
-1,-1,31:18
0,-1,31:18
1,-1,31:18
2,-1,31:18
3,-1,31:18
4,-1,31:18
-5,0,31:18
-4,0,31:18
-3,0,31:18
-2,0,31:18
-1,0,31:18
0,0,31:18
1,0,31:18
2,0,31:18
3,0,31:18
4,0,31:18
-5,1,31:18
-4,1,31:18
-3,1,31:18
-2,1,31:18
-1,1,31:17.3
0,1,31:18
1,1,31:18
2,1,31:18
3,1,31:18
4,1,31:18
-5,2,31:18
-4,2,31:18
-3,2,31:17
-2,2,31:17.3
-1,2,31:18
0,2,31:18
1,2,31:17.3
2,2,31:17
3,2,31:18
4,2,31:18
-4,3,31:18
-3,3,31:18
-2,3,31:18
-1,3,31:18
0,3,31:18
1,3,31:18
2,3,31:17
3,3,31:18
4,3,31:18
-3,4,31:18
-2,4,31:18
-1,4,31:18
0,4,31:18
1,4,31:18
2,4,31:18
3,4,31:18
-2,5,31:18
-1,5,31:18
0,5,31:18
1,5,31:18
-2,-6,32:18
-1,-6,32:18
0,-6,32:18
1,-6,32:18
-4,-5,32:18
-3,-5,32:18
-2,-5,32:18
-1,-5,32:18
0,-5,32:18
1,-5,32:18
2,-5,32:18
3,-5,32:18
-5,-4,32:18
-4,-4,32:18
-3,-4,32:18
-2,-4,32:18
-1,-4,32:18
0,-4,32:18
1,-4,32:18
2,-4,32:18
3,-4,32:18
4,-4,32:18
-6,-3,32:18
-5,-3,32:18
-4,-3,32:18
-3,-3,32:18
-2,-3,32:18
-1,-3,32:18
0,-3,32:18
1,-3,32:18
2,-3,32:18
3,-3,32:18
4,-3,32:18
-6,-2,32:18
-5,-2,32:18
-4,-2,32:18
-3,-2,32:18
-2,-2,32:18
-1,-2,32:18
0,-2,32:17.3
1,-2,32:18
2,-2,32:18
3,-2,32:18
4,-2,32:18
-6,-1,32:18
-5,-1,32:18
-4,-1,32:18
-3,-1,32:18
-2,-1,32:18
-1,-1,32:18
0,-1,32:18
1,-1,32:18
2,-1,32:18
3,-1,32:18
4,-1,32:18
5,-1,32:18
-6,0,32:18
-5,0,32:18
-4,0,32:18
-3,0,32:18
-2,0,32:18
-1,0,32:18
0,0,32:18
1,0,32:18
2,0,32:18
3,0,32:18
4,0,32:18
5,0,32:18
-6,1,32:18
-5,1,32:18
-4,1,32:18
-3,1,32:18
-2,1,32:18
-1,1,32:17.3
0,1,32:18
1,1,32:18
2,1,32:18
3,1,32:18
4,1,32:18
5,1,32:18
-6,2,32:18
-5,2,32:18
-4,2,32:18
-3,2,32:17.3
-2,2,32:18
-1,2,32:18
0,2,32:18
1,2,32:18
2,2,32:18
3,2,32:18
4,2,32:18
5,2,32:18
-5,3,32:18
-4,3,32:18
-3,3,32:18
-2,3,32:18
-1,3,32:18
0,3,32:18
1,3,32:18
2,3,32:17.3
3,3,32:18
4,3,32:18
5,3,32:18
-4,4,32:18
-3,4,32:18
-2,4,32:18
-1,4,32:18
0,4,32:18
1,4,32:18
2,4,32:18
3,4,32:18
4,4,32:18
5,4,32:18
-4,5,32:18
-3,5,32:18
-2,5,32:18
-1,5,32:18
0,5,32:18
1,5,32:18
2,5,32:18
3,5,32:18
4,5,32:18
-3,6,32:18
-2,6,32:18
-1,6,32:18
0,6,32:18
1,6,32:18
2,6,32:18
3,6,32:18
-4,-7,33:18
-3,-7,33:18
-2,-7,33:18
-1,-7,33:18
0,-7,33:18
1,-7,33:18
2,-7,33:18
-5,-6,33:18
-4,-6,33:18
-3,-6,33:18
-2,-6,33:18
-1,-6,33:18
0,-6,33:18
1,-6,33:18
2,-6,33:18
-7,-5,33:18
-6,-5,33:18
-5,-5,33:18
-4,-5,33:18
-3,-5,33:18
-2,-5,33:18
-1,-5,33:18
0,-5,33:18
1,-5,33:18
2,-5,33:18
3,-5,33:18
-7,-4,33:18
-6,-4,33:18
-5,-4,33:18
-4,-4,33:18
-3,-4,33:18
-2,-4,33:18
-1,-4,33:18
0,-4,33:18
1,-4,33:18
2,-4,33:18
3,-4,33:18
-7,-3,33:18
-6,-3,33:18
-5,-3,33:18
-4,-3,33:18
-3,-3,33:18
-2,-3,33:18
-1,-3,33:18
0,-3,33:18
1,-3,33:18
2,-3,33:18
3,-3,33:18
4,-3,33:18
5,-3,33:18
-7,-2,33:18
-6,-2,33:18
-5,-2,33:18
-4,-2,33:18
-3,-2,33:18
-2,-2,33:18
-1,-2,33:18
0,-2,33:18
1,-2,33:18
2,-2,33:18
3,-2,33:18
4,-2,33:18
5,-2,33:18
6,-2,33:18
-7,-1,33:18
-6,-1,33:18
-5,-1,33:18
-4,-1,33:18
-3,-1,33:18
-2,-1,33:18
-1,-1,33:18
0,-1,33:18
1,-1,33:18
2,-1,33:18
3,-1,33:18
4,-1,33:18
5,-1,33:18
6,-1,33:18
-7,0,33:18
-6,0,33:18
-5,0,33:18
-4,0,33:18
-3,0,33:18
-2,0,33:18
-1,0,33:18
0,0,33:18
1,0,33:18
2,0,33:18
3,0,33:18
4,0,33:18
5,0,33:18
6,0,33:18
-7,1,33:18
-6,1,33:18
-5,1,33:18
-4,1,33:18
-3,1,33:18
-2,1,33:18
-1,1,33:18
0,1,33:18
1,1,33:18
2,1,33:18
3,1,33:18
4,1,33:18
5,1,33:18
6,1,33:18
-7,2,33:18
-6,2,33:18
-5,2,33:18
-4,2,33:18
-3,2,33:18
-2,2,33:18
-1,2,33:18
0,2,33:18
1,2,33:18
2,2,33:18
3,2,33:18
4,2,33:18
5,2,33:18
6,2,33:18
-7,3,33:18
-6,3,33:18
-5,3,33:18
-4,3,33:18
-3,3,33:18
-2,3,33:18
-1,3,33:18
0,3,33:18
1,3,33:18
2,3,33:17.3
3,3,33:18
4,3,33:18
5,3,33:18
6,3,33:18
-6,4,33:18
-5,4,33:18
-4,4,33:18
-3,4,33:18
-2,4,33:18
-1,4,33:18
0,4,33:18
1,4,33:18
2,4,33:18
3,4,33:18
4,4,33:18
5,4,33:18
6,4,33:18
-6,5,33:18
-5,5,33:18
-4,5,33:18
-3,5,33:18
-2,5,33:18
-1,5,33:18
0,5,33:18
1,5,33:18
2,5,33:18
3,5,33:18
4,5,33:18
5,5,33:18
6,5,33:18
-5,6,33:18
-4,6,33:18
-3,6,33:18
-2,6,33:18
-1,6,33:18
0,6,33:18
1,6,33:18
2,6,33:18
3,6,33:18
4,6,33:18
5,6,33:18
-4,7,33:18
-3,7,33:18
-2,7,33:18
-1,7,33:18
0,7,33:18
1,7,33:18
2,7,33:18
3,7,33:18
4,7,33:18
-3,-6,34:18
-2,-6,34:18
-1,-6,34:18
-3,-5,34:18
-2,-5,34:18
-1,-5,34:18
0,-5,34:18
1,-5,34:18
-5,-4,34:18
-4,-4,34:18
-3,-4,34:18
-2,-4,34:18
-1,-4,34:18
0,-4,34:18
1,-4,34:18
2,-4,34:18
-6,-3,34:18
-5,-3,34:18
-4,-3,34:18
-3,-3,34:18
-2,-3,34:18
-1,-3,34:18
0,-3,34:18
1,-3,34:18
2,-3,34:18
3,-3,34:18
-6,-2,34:18
-5,-2,34:18
-4,-2,34:18
-3,-2,34:18
-2,-2,34:18
-1,-2,34:18
0,-2,34:18
1,-2,34:18
2,-2,34:18
3,-2,34:18
4,-2,34:18
5,-2,34:18
-6,-1,34:18
-5,-1,34:18
-4,-1,34:18
-3,-1,34:18
-2,-1,34:18
-1,-1,34:18
0,-1,34:18
1,-1,34:18
2,-1,34:18
3,-1,34:18
4,-1,34:18
5,-1,34:18
-6,0,34:18
-5,0,34:18
-4,0,34:18
-3,0,34:18
-2,0,34:18
-1,0,34:18
0,0,34:18
1,0,34:18
2,0,34:18
3,0,34:18
4,0,34:18
5,0,34:18
-6,1,34:18
-5,1,34:18
-4,1,34:18
-3,1,34:18
-2,1,34:18
-1,1,34:18
0,1,34:18
1,1,34:18
2,1,34:18
3,1,34:18
4,1,34:18
5,1,34:18
-6,2,34:18
-5,2,34:18
-4,2,34:18
-3,2,34:18
-2,2,34:18
-1,2,34:18
0,2,34:18
1,2,34:18
2,2,34:18
3,2,34:18
4,2,34:18
5,2,34:18
-5,3,34:18
-4,3,34:18
-3,3,34:18
-2,3,34:18
-1,3,34:18
0,3,34:18
1,3,34:18
2,3,34:18
3,3,34:18
4,3,34:18
5,3,34:18
-5,4,34:18
-4,4,34:18
-3,4,34:18
-2,4,34:18
-1,4,34:18
0,4,34:18
1,4,34:18
2,4,34:18
3,4,34:18
4,4,34:18
5,4,34:18
-4,5,34:18
-3,5,34:18
-2,5,34:18
-1,5,34:18
0,5,34:18
1,5,34:18
2,5,34:18
3,5,34:18
4,5,34:18
-3,6,34:18
-2,6,34:18
-1,6,34:18
0,6,34:18
1,6,34:18
2,6,34:18
-2,-4,35:18
-1,-4,35:18
-4,-3,35:18
-3,-3,35:18
-2,-3,35:18
-1,-3,35:18
0,-3,35:18
1,-3,35:18
-5,-2,35:18
-4,-2,35:18
-3,-2,35:18
-2,-2,35:18
-1,-2,35:18
0,-2,35:18
1,-2,35:18
2,-2,35:18
-5,-1,35:18
-4,-1,35:18
-3,-1,35:18
-2,-1,35:18
-1,-1,35:18
0,-1,35:18
1,-1,35:18
2,-1,35:18
3,-1,35:18
-5,0,35:18
-4,0,35:18
-3,0,35:18
-2,0,35:18
-1,0,35:18
0,0,35:18
1,0,35:18
2,0,35:18
3,0,35:18
4,0,35:18
-5,1,35:18
-4,1,35:18
-3,1,35:18
-2,1,35:18
-1,1,35:18
0,1,35:18
1,1,35:18
2,1,35:18
3,1,35:18
4,1,35:18
-5,2,35:18
-4,2,35:18
-3,2,35:18
-2,2,35:18
-1,2,35:18
0,2,35:18
1,2,35:18
2,2,35:18
3,2,35:18
4,2,35:18
-4,3,35:18
-3,3,35:18
-2,3,35:18
-1,3,35:18
0,3,35:18
1,3,35:18
2,3,35:18
3,3,35:18
4,3,35:18
-4,4,35:18
-3,4,35:18
-2,4,35:18
-1,4,35:18
0,4,35:18
1,4,35:18
2,4,35:18
3,4,35:18
-3,5,35:18
-2,5,35:18
-1,5,35:18
0,5,35:18
1,5,35:18
2,5,35:18
