[META]
version=2.0
spawnOnBlockType=3,2,12
spawnSunlight=True
spawnDarkness=True
spawnWater=True
spawnLava=False
underFill=True
randomRotation=True
dig=True
tree=True
branch=False
needsFoundation=True
rarity=100
collisionPercentage=2
spawnElevationMin=0
spawnElevationMax=100
spawnInBiome=OttaDesertOasisBorder
[DATA]
0,0,0:17.0
0,0,-1:3
0,0,1:17.0
0,0,2:17.0
0,0,3:17.0
0,0,4:17.0
0,0,5:17.0
-3,0,5:18.0
3,0,5:18.0
2,2,5:18.0
0,3,5:18.0
-2,2,5:18.0
-2,-2,5:18.0
0,-3,5:18.0
2,-2,5:18.0
2,0,5:18.0
0,-2,5:18.0
-2,0,5:18.0
0,2,5:18.0
0,-2,6:18.0
-2,0,6:18.0
-1,1,6:18.0
0,2,6:18.0
2,0,6:18.0
0,0,6:18.0
2,-1,6:18.0
2,-2,6:18.0
1,2,6:18.0
2,2,6:18.0
-1,2,6:18.0
-2,2,6:18.0
-2,-1,6:18.0
-2,-2,6:18.0
0,-3,6:18.0
-3,0,6:18.0
0,3,6:18.0
3,0,6:18.0
0,-1,7:18.0
0,-2,7:18.0
1,0,7:18.0
2,0,7:18.0
-1,1,7:18.0
0,1,7:18.0
0,0,7:18.0
-2,0,7:18.0
-1,0,7:18.0
0,0,8:18.0
