[META]
version=2.0
spawnOnBlockType=12
spawnSunlight=True
spawnDarkness=False
spawnWater=True
spawnLava=False
underFill=True
randomRotation=True
dig=True
tree=False
branch=False
needsFoundation=True
rarity=5
collisionPercentage=2
spawnElevationMin=0
spawnElevationMax=128
spawnInBiome=OttaAtollBeach
[DATA]
-1,-6,0:1
0,-6,0:1
1,-6,0:1
-2,-5,0:1
-1,-5,0:1
-1,-4,0:1
0,-4,0:1
1,-4,0:1
1,-5,0:1
0,-5,0:1
2,-5,0:1
3,-5,0:1
3,-4,0:1
2,-4,0:1
-2,-4,0:1
-3,-4,0:1
-3,-3,0:1
-4,-3,0:1
-5,-3,0:1
-2,-3,0:1
-1,-3,0:1
0,-3,0:1
1,-3,0:1
2,-3,0:1
3,-3,0:1
4,-3,0:1
5,-3,0:1
4,-4,0:1
4,-2,0:1
5,-2,0:1
3,-2,0:1
2,-2,0:1
1,-2,0:1
0,-2,0:1
-1,-2,0:1
-2,-2,0:1
-3,-2,0:1
-4,-2,0:1
-5,-2,0:1
-6,-2,0:1
-6,-1,0:1
-5,-1,0:1
-4,-1,0:1
-3,-1,0:1
-2,-1,0:1
-1,-1,0:1
0,-1,0:1
1,-1,0:1
2,-1,0:1
3,-1,0:1
4,-1,0:1
5,-1,0:1
5,0,0:1
6,0,0:1
4,0,0:1
3,0,0:1
2,0,0:1
1,0,0:1
0,0,0:1
-1,0,0:1
-2,0,0:1
-3,0,0:1
-4,0,0:1
-5,0,0:1
-6,0,0:1
-5,1,0:1
-4,1,0:1
-3,1,0:1
-2,1,0:1
-1,1,0:1
0,1,0:1
1,1,0:1
2,1,0:1
3,1,0:1
4,1,0:1
5,1,0:1
6,1,0:1
5,2,0:1
4,2,0:1
3,2,0:1
2,2,0:1
1,2,0:1
0,2,0:1
-1,2,0:1
-2,2,0:1
-3,2,0:1
-4,2,0:1
-4,3,0:1
-3,3,0:1
-2,3,0:1
-1,3,0:1
0,3,0:1
1,3,0:1
2,3,0:1
3,3,0:1
4,3,0:1
4,4,0:1
3,4,0:1
2,4,0:1
1,4,0:1
0,4,0:1
-1,4,0:1
-2,4,0:1
-3,4,0:1
-3,5,0:1
-2,5,0:1
-1,5,0:1
0,5,0:1
1,5,0:1
2,5,0:1
3,5,0:1
1,6,0:1
0,6,0:1
-1,6,0:1
-2,6,0:1
6,-3,0:12
6,-2,0:12
6,-1,0:12
7,0,0:12
7,1,0:12
6,2,0:12
5,3,0:12
5,4,0:12
4,5,0:12
2,6,0:12
3,6,0:12
-1,7,0:12
-2,7,0:12
0,7,0:12
1,7,0:12
-3,6,0:12
-4,5,0:12
-4,4,0:12
-5,3,0:12
-5,2,0:12
-6,1,0:12
-7,0,0:12
-7,-1,0:12
-7,-2,0:12
-6,-3,0:12
-5,-4,0:12
-4,-4,0:12
-3,-5,0:12
-2,-6,0:12
-1,-7,0:12
0,-7,0:12
1,-7,0:12
2,-6,0:12
3,-6,0:12
4,-5,0:12
5,-4,0:12
-1,-6,-1:1
0,-6,-1:1
0,-5,-1:1
1,-5,-1:1
1,-6,-1:1
-1,-5,-1:1
-2,-5,-1:1
2,-5,-1:1
3,-5,-1:1
3,-4,-1:1
4,-4,-1:1
2,-4,-1:1
1,-4,-1:1
0,-4,-1:1
-1,-4,-1:1
-2,-4,-1:1
-3,-4,-1:1
-3,-3,-1:1
-4,-3,-1:1
-5,-3,-1:1
-4,-2,-1:1
-3,-2,-1:1
-2,-3,-1:1
-1,-3,-1:1
0,-3,-1:1
1,-3,-1:1
2,-3,-1:1
3,-3,-1:1
4,-3,-1:1
5,-3,-1:1
5,-2,-1:1
5,-1,-1:1
4,-1,-1:1
3,-1,-1:1
2,-1,-1:1
1,-1,-1:1
0,-1,-1:1
-1,-1,-1:1
-2,-1,-1:1
-3,-1,-1:1
-4,-1,-1:1
-5,-1,-1:1
-6,-1,-1:1
-6,-2,-1:1
-5,-2,-1:1
-2,-2,-1:1
-1,-2,-1:1
0,-2,-1:1
1,-2,-1:1
2,-2,-1:1
3,-2,-1:1
4,-2,-1:1
4,0,-1:1
5,0,-1:1
6,0,-1:1
6,1,-1:1
5,1,-1:1
4,1,-1:1
3,1,-1:1
2,1,-1:1
1,1,-1:1
0,1,-1:1
-1,1,-1:1
-2,1,-1:1
-3,1,-1:1
-4,1,-1:1
-5,1,-1:1
-5,0,-1:1
-6,0,-1:1
-4,0,-1:1
-1,0,-1:1
-2,0,-1:1
-3,0,-1:1
0,0,-1:1
1,0,-1:1
2,0,-1:1
3,0,-1:1
5,2,-1:1
4,2,-1:1
3,2,-1:1
2,2,-1:1
1,2,-1:1
0,2,-1:1
-1,2,-1:1
-2,2,-1:1
-3,2,-1:1
-4,2,-1:1
-4,3,-1:1
-3,3,-1:1
-2,3,-1:1
-1,3,-1:1
0,3,-1:1
1,3,-1:1
2,3,-1:1
3,3,-1:1
4,3,-1:1
4,4,-1:1
3,4,-1:1
2,4,-1:1
1,4,-1:1
0,4,-1:1
-1,4,-1:1
-2,4,-1:1
-3,4,-1:1
-3,5,-1:1
-2,5,-1:1
-1,5,-1:1
0,5,-1:1
1,5,-1:1
2,5,-1:1
3,5,-1:1
1,6,-1:1
0,6,-1:1
-1,6,-1:1
-2,6,-1:1
7,0,-1:12
7,1,-1:12
6,2,-1:12
5,3,-1:12
5,4,-1:12
4,5,-1:12
3,6,-1:12
2,6,-1:12
1,7,-1:12
0,7,-1:12
-1,7,-1:12
-2,7,-1:12
-3,6,-1:12
-4,5,-1:12
-4,4,-1:12
-5,3,-1:12
-5,2,-1:12
-6,1,-1:12
-7,0,-1:12
-7,-1,-1:12
-7,-2,-1:12
-6,-3,-1:12
-5,-4,-1:12
-4,-4,-1:12
-3,-5,-1:12
-2,-6,-1:12
-1,-7,-1:12
0,-7,-1:12
1,-7,-1:12
2,-6,-1:12
3,-6,-1:12
4,-5,-1:12
5,-4,-1:12
6,-3,-1:12
6,-2,-1:12
6,-1,-1:12
-1,-6,-2:1
0,-6,-2:1
1,-6,-2:1
1,-5,-2:1
0,-5,-2:1
-1,-5,-2:1
-2,-5,-2:1
-1,-4,-2:1
0,-4,-2:1
1,-4,-2:1
2,-4,-2:1
2,-5,-2:1
3,-5,-2:1
3,-4,-2:1
4,-4,-2:1
-2,-4,-2:1
-3,-4,-2:1
-3,-3,-2:1
-3,-2,-2:1
-4,-3,-2:1
-5,-3,-2:1
-5,-2,-2:1
-5,-1,-2:1
-6,-1,-2:1
-6,0,-2:1
-6,-2,-2:1
-5,0,-2:1
-4,0,-2:1
-4,-1,-2:1
-3,-1,-2:1
-4,-2,-2:1
-3,0,-2:1
-3,1,-2:1
-4,1,-2:1
-2,-1,-2:1
-2,-2,-2:1
-1,-2,-2:1
-2,-3,-2:1
-1,-3,-2:1
0,-3,-2:1
1,-3,-2:1
2,-3,-2:1
3,-3,-2:1
4,-3,-2:1
4,-2,-2:1
5,-2,-2:1
5,-3,-2:1
5,-1,-2:1
4,-1,-2:1
3,-1,-2:1
2,-1,-2:1
1,-1,-2:1
0,-1,-2:1
-1,-1,-2:1
0,-2,-2:1
1,-2,-2:1
2,-2,-2:1
3,-2,-2:1
4,0,-2:1
5,0,-2:1
6,0,-2:1
6,1,-2:1
5,1,-2:1
4,1,-2:1
3,1,-2:1
2,1,-2:1
1,1,-2:1
0,1,-2:1
-1,1,-2:1
-1,2,-2:1
-2,2,-2:1
-2,1,-2:1
-2,0,-2:1
-1,0,-2:1
0,0,-2:1
1,0,-2:1
2,0,-2:1
3,0,-2:1
3,2,-2:1
4,2,-2:1
5,2,-2:1
2,2,-2:1
1,2,-2:1
0,2,-2:1
-3,2,-2:1
-4,2,-2:1
-5,1,-2:1
-4,3,-2:1
-3,3,-2:1
-2,3,-2:1
-1,3,-2:1
0,3,-2:1
1,3,-2:1
2,3,-2:1
3,3,-2:1
4,3,-2:1
4,4,-2:1
3,4,-2:1
2,4,-2:1
1,4,-2:1
0,4,-2:1
-1,4,-2:1
-2,4,-2:1
-3,4,-2:1
-2,5,-2:1
-3,5,-2:1
-1,5,-2:1
0,5,-2:1
1,5,-2:1
2,5,-2:1
3,5,-2:1
1,6,-2:1
0,6,-2:1
-1,6,-2:1
-2,6,-2:1
6,-3,-2:12
6,-2,-2:12
6,-1,-2:12
7,0,-2:12
7,1,-2:12
6,2,-2:12
5,3,-2:12
5,4,-2:12
4,5,-2:12
2,6,-2:12
3,6,-2:12
-2,7,-2:12
-1,7,-2:12
0,7,-2:12
1,7,-2:12
-3,6,-2:12
-4,5,-2:12
-4,4,-2:12
-5,3,-2:12
-5,2,-2:12
-6,1,-2:12
-7,0,-2:12
-7,-1,-2:12
-7,-2,-2:12
-6,-3,-2:12
-5,-4,-2:12
-4,-4,-2:12
-3,-5,-2:12
-2,-6,-2:12
-1,-7,-2:12
0,-7,-2:12
1,-7,-2:12
2,-6,-2:12
3,-6,-2:12
4,-5,-2:12
5,-4,-2:12
0,-6,-3:1
-1,-6,-3:1
1,-6,-3:1
2,-5,-3:1
3,-5,-3:1
4,-4,-3:1
5,-3,-3:1
5,-2,-3:1
5,-1,-3:1
6,0,-3:1
6,1,-3:1
5,2,-3:1
4,3,-3:1
4,4,-3:1
3,5,-3:1
2,5,-3:1
1,6,-3:1
0,6,-3:1
-1,6,-3:1
-2,6,-3:1
-3,5,-3:1
-3,4,-3:1
-4,3,-3:1
-4,2,-3:1
-5,1,-3:1
-6,0,-3:1
-6,-1,-3:1
-6,-2,-3:1
-5,-3,-3:1
-4,-3,-3:1
-3,-4,-3:1
-2,-5,-3:1
-1,-1,-3:1
-1,0,-3:1
0,0,-3:1
0,1,-3:1
0,2,-3:1
1,1,-3:1
1,0,-3:1
1,-1,-3:1
1,-2,-3:1
1,-3,-3:1
0,-2,-3:1
0,-1,-3:1
-1,2,-3:1
0,3,-3:1
-1,3,-3:1
-1,4,-3:1
0,4,-3:1
0,5,-3:1
-1,5,-3:1
-2,5,-3:1
-2,4,-3:1
-2,3,-3:1
-2,2,-3:1
-3,3,-3:1
-3,2,-3:1
-3,1,-3:1
-4,1,-3:1
-4,0,-3:1
-5,0,-3:1
-5,-1,-3:1
-5,-2,-3:1
-4,-2,-3:1
-3,-2,-3:1
-2,-2,-3:1
-1,-2,-3:1
0,-3,-3:1
-1,-3,-3:1
-2,-1,-3:1
-3,-1,-3:1
-3,0,-3:1
-2,0,-3:1
-2,1,-3:1
-1,1,-3:1
-4,-1,-3:1
-2,-3,-3:1
-3,-3,-3:1
-1,-4,-3:1
-2,-4,-3:1
0,-4,-3:1
-1,-5,-3:1
0,-5,-3:1
1,-5,-3:1
1,-4,-3:1
2,-4,-3:1
3,-4,-3:1
3,-3,-3:1
3,-2,-3:1
2,-2,-3:1
2,-1,-3:1
2,0,-3:1
2,1,-3:1
2,2,-3:1
2,3,-3:1
2,4,-3:1
1,4,-3:1
1,5,-3:1
1,3,-3:1
1,2,-3:1
3,4,-3:1
3,3,-3:1
3,2,-3:1
3,1,-3:1
3,0,-3:1
3,-1,-3:1
2,-3,-3:1
4,-3,-3:1
4,-2,-3:1
4,-1,-3:1
4,0,-3:1
4,1,-3:1
4,2,-3:1
5,0,-3:1
5,1,-3:1
7,0,-3:12
7,1,-3:12
6,-1,-3:12
6,-2,-3:12
6,-3,-3:12
5,-4,-3:12
4,-5,-3:12
2,-6,-3:12
3,-6,-3:12
-1,-7,-3:12
0,-7,-3:12
1,-7,-3:12
-2,-6,-3:12
-3,-5,-3:12
-4,-4,-3:12
-5,-4,-3:12
-6,-3,-3:12
-7,-2,-3:12
-7,-1,-3:12
-7,0,-3:12
-6,1,-3:12
-5,2,-3:12
-5,3,-3:12
-4,4,-3:12
-4,5,-3:12
-3,6,-3:12
-2,7,-3:12
-1,7,-3:12
0,7,-3:12
1,7,-3:12
2,6,-3:12
3,6,-3:12
4,5,-3:12
5,4,-3:12
5,3,-3:12
6,2,-3:12
0,-6,1:1
-2,-5,1:1
-1,-5,1:1
-1,-4,1:1
0,-4,1:1
1,-4,1:1
1,-5,1:1
2,-5,1:1
0,-5,1:1
2,-4,1:1
3,-4,1:1
3,-3,1:1
4,-3,1:1
4,-2,1:1
4,-1,1:1
5,-1,1:1
5,0,1:1
5,1,1:1
4,1,1:1
4,2,1:1
4,3,1:1
3,3,1:1
3,4,1:1
2,4,1:1
2,5,1:1
1,5,1:1
0,5,1:1
-1,5,1:1
-2,5,1:1
-2,4,1:1
-3,4,1:1
-3,3,1:1
-3,2,1:1
-4,2,1:1
-4,1,1:1
-4,0,1:1
-5,0,1:1
-5,-1,1:1
-5,-2,1:1
-4,-2,1:1
-4,-3,1:1
-3,-3,1:1
-2,-3,1:1
-2,-4,1:1
-6,-1,1:1
-1,6,1:1
0,6,1:1
0,4,1:1
1,4,1:1
1,3,1:1
1,2,1:1
2,2,1:1
2,1,1:1
3,1,1:1
4,0,1:1
3,0,1:1
3,2,1:1
2,3,1:1
2,0,1:1
2,-1,1:1
3,-1,1:1
3,-2,1:1
2,-2,1:1
2,-3,1:1
1,-3,1:1
0,-3,1:1
-1,-3,1:1
-1,-2,1:1
-1,-1,1:1
0,-1,1:1
0,-2,1:1
1,-2,1:1
0,2,1:1
0,1,1:1
0,0,1:1
1,0,1:1
1,-1,1:1
1,1,1:1
0,3,1:1
-1,3,1:1
-1,4,1:1
-1,2,1:1
-1,1,1:1
-2,1,1:1
-1,0,1:1
-2,2,1:1
-2,3,1:1
-2,0,1:1
-2,-1,1:1
-2,-2,1:1
-3,-2,1:1
-3,-1,1:1
-3,0,1:1
-3,1,1:1
-4,-1,1:1
-3,-5,1:12
-2,-6,1:12
6,-1,1:12
6,0,1:12
-4,4,1:12
-4,3,1:12
-5,2,1:12
2,6,1:12
5,3,1:12
5,4,1:12
-1,-5,2:1
0,-5,2:1
0,-4,2:1
1,-4,2:1
1,-5,2:1
2,-4,2:1
-1,-4,2:1
-2,-4,2:1
-2,-3,2:1
-3,-3,2:1
-3,-2,2:1
-4,-2,2:1
-4,-1,2:1
-5,-1,2:1
-4,0,2:1
-4,1,2:1
-3,1,2:1
-3,2,2:1
-3,3,2:1
-2,3,2:1
-2,4,2:1
-1,4,2:1
-1,5,2:1
0,5,2:1
0,4,2:1
1,4,2:1
1,5,2:1
2,4,2:1
-1,6,2:1
2,3,2:1
1,3,2:1
0,3,2:1
-1,3,2:1
3,3,2:1
3,2,2:1
4,2,2:1
4,1,2:1
3,1,2:1
4,0,2:1
4,-1,2:1
5,0,2:1
3,-2,2:1
3,-3,2:1
2,-3,2:1
2,-2,2:1
3,-1,2:1
3,0,2:1
2,0,2:1
1,0,2:1
1,-1,2:1
1,-2,2:1
1,-3,2:1
2,-1,2:1
0,-2,2:1
0,-3,2:1
-1,-3,2:1
-1,-2,2:1
-2,-2,2:1
-2,-1,2:1
-3,-1,2:1
-3,0,2:1
-2,0,2:1
-2,1,2:1
-2,2,2:1
-1,2,2:1
0,2,2:1
1,2,2:1
2,2,2:1
2,1,2:1
1,1,2:1
-1,1,2:1
-1,0,2:1
0,0,2:1
0,1,2:1
0,-1,2:1
-1,-1,2:1
0,-5,3:1
-1,-4,3:1
0,-4,3:1
0,-3,3:1
1,-4,3:1
1,-3,3:1
2,-3,3:1
-1,-3,3:1
-1,-2,3:1
-2,-2,3:1
-3,-2,3:1
-2,-3,3:1
0,-2,3:1
1,-2,3:1
2,-2,3:1
2,-1,3:1
3,-1,3:1
3,0,3:1
4,0,3:1
3,1,3:1
3,2,3:1
2,2,3:1
2,3,3:1
1,3,3:1
1,4,3:1
0,4,3:1
-1,4,3:1
-1,3,3:1
-2,3,3:1
-2,2,3:1
-1,5,3:1
-2,1,3:1
-3,2,3:1
-3,1,3:1
-3,0,3:1
-4,0,3:1
-4,-1,3:1
-3,-1,3:1
-2,0,3:1
-1,-1,3:1
0,-1,3:1
0,0,3:1
1,0,3:1
1,1,3:1
2,0,3:1
2,1,3:1
1,-1,3:1
-1,0,3:1
-1,1,3:1
0,1,3:1
0,2,3:1
0,3,3:1
-1,2,3:1
1,2,3:1
-2,-1,3:1
0,-4,4:1
-1,-3,4:1
0,-3,4:1
0,-2,4:1
1,-2,4:1
1,-3,4:1
-1,-2,4:1
-2,-2,4:1
-2,-1,4:1
-3,-1,4:1
-3,0,4:1
-2,0,4:1
-2,1,4:1
-2,2,4:1
-1,2,4:1
-1,3,4:1
0,3,4:1
1,3,4:1
1,2,4:1
0,2,4:1
2,2,4:1
2,1,4:1
3,1,4:1
3,0,4:1
2,0,4:1
2,-1,4:1
1,0,4:1
0,0,4:1
0,1,4:1
-1,1,4:1
-1,0,4:1
1,-1,4:1
0,-1,4:1
-1,-1,4:1
1,1,4:1
-1,-2,5:1
0,-2,5:1
0,-3,5:1
0,-1,5:1
1,-1,5:1
1,0,5:1
2,0,5:1
2,1,5:1
1,1,5:1
1,2,5:1
0,2,5:1
-1,2,5:1
-1,1,5:1
0,1,5:1
0,0,5:1
-1,0,5:1
-2,0,5:1
-2,-1,5:1
-1,-1,5:1
-1,-1,6:1
0,-1,6:1
0,0,6:1
-1,0,6:1
1,0,6:1
1,1,6:1
0,1,6:1
