[META]
version=2.0
spawnOnBlockType=2
spawnSunlight=True
spawnDarkness=False
spawnWater=False
spawnLava=False
underFill=True
randomRotation=True
dig=True
tree=True
branch=False
needsFoundation=True
rarity=10
collisionPercentage=2
spawnElevationMin=0
spawnElevationMax=128
spawnInBiome=OttaToskana,OttaToskanaHill
[DATA]
-1,0,0:17
0,1,0:17
-1,0,1:17
0,1,1:17
-1,0,2:17
0,1,2:17.0
1,1,2:17
-1,-1,3:17
-1,0,3:17.0
-1,1,3:17
1,1,3:17.0
-1,-1,4:17.0
-1,1,4:17.0
1,1,4:17.0
-1,2,4:17
-2,-2,5:17
-2,-1,5:17
-1,-1,5:17.0
0,-1,5:17
1,1,5:17.0
2,1,5:17
-1,2,5:17.0
2,2,5:17
3,2,5:17
-2,-2,6:17
0,-1,6:17
-1,2,6:17.0
3,2,6:17.0
-2,3,6:17
-1,3,6:17
3,3,6:17
-1,-6,7:18
0,-6,7:18
0,-5,7:18
-2,-4,7:18
0,-4,7:18
0,-3,7:18
1,-3,7:18
-2,-2,7:17
-1,-2,7:18
0,-2,7:18
1,-2,7:18
-1,-1,7:18
0,-1,7:17
1,-1,7:18
-4,0,7:18
-3,0,7:18
-1,0,7:18
0,0,7:18
1,0,7:18
3,0,7:18
-2,1,7:18
0,1,7:18
1,1,7:18
-3,2,7:18
0,2,7:18
4,2,7:18
-3,3,7:17
-2,3,7:17
3,3,7:17
3,4,7:17
4,4,7:17
-2,-6,8:18
-1,-6,8:18
0,-6,8:18
-5,-5,8:18
-4,-5,8:18
-2,-5,8:18
-1,-5,8:18
0,-5,8:18
1,-5,8:18
-5,-4,8:18
-4,-4,8:17
-3,-4,8:18
-2,-4,8:18
-1,-4,8:18
0,-4,8:18
1,-4,8:18
2,-4,8:18
3,-4,8:18
-5,-3,8:18
-4,-3,8:17
-3,-3,8:17
-2,-3,8:17
-1,-3,8:17
0,-3,8:17
1,-3,8:18
3,-3,8:18
-5,-2,8:18
-4,-2,8:18
-2,-2,8:17.0
-1,-2,8:18
0,-2,8:18
1,-2,8:18
2,-2,8:18
5,-2,8:18
-4,-1,8:18
-2,-1,8:18
-1,-1,8:18
1,-1,8:17
2,-1,8:18
3,-1,8:18
-6,0,8:18
-4,0,8:18
-2,0,8:18
-1,0,8:18
0,0,8:18
1,0,8:18
2,0,8:18
3,0,8:18
5,0,8:18
7,0,8:18
8,0,8:18
-5,1,8:18
-4,1,8:18
-2,1,8:18
-1,1,8:18
2,1,8:18
3,1,8:18
5,1,8:18
6,1,8:18
7,1,8:18
-2,2,8:18
0,2,8:18
1,2,8:18
2,2,8:18
3,2,8:17
4,2,8:18
7,2,8:18
8,2,8:18
-4,3,8:17
-3,3,8:17.0
-2,3,8:18
-1,3,8:18
1,3,8:18
4,3,8:18
5,3,8:18
7,3,8:18
-4,4,8:17
-3,4,8:18
-2,4,8:18
-1,4,8:18
0,4,8:18
1,4,8:18
4,4,8:17.0
-6,5,8:18
-4,5,8:18
-3,5,8:18
0,5,8:18
1,5,8:18
3,5,8:18
6,5,8:18
-4,6,8:18
4,6,8:18
5,6,8:18
6,6,8:18
3,7,8:18
-1,-7,9:18
-5,-6,9:18
-4,-6,9:18
-3,-6,9:18
-2,-6,9:18
-1,-6,9:18
0,-6,9:18
4,-6,9:18
-6,-5,9:18
-5,-5,9:17
-4,-5,9:18
-3,-5,9:18
-2,-5,9:18
-1,-5,9:18
0,-5,9:18
1,-5,9:18
2,-5,9:18
5,-5,9:18
-6,-4,9:18
-5,-4,9:17
-4,-4,9:17.0
-3,-4,9:18
-2,-4,9:18
-1,-4,9:18
0,-4,9:18
2,-4,9:18
3,-4,9:18
4,-4,9:18
5,-4,9:18
6,-4,9:18
-5,-3,9:18
-4,-3,9:18
-3,-3,9:18
-2,-3,9:18
0,-3,9:17.0
1,-3,9:18
2,-3,9:18
3,-3,9:18
4,-3,9:18
5,-3,9:18
6,-3,9:18
-5,-2,9:18
-4,-2,9:18
-3,-2,9:18
-2,-2,9:17.0
2,-2,9:18
3,-2,9:18
5,-2,9:18
6,-2,9:18
7,-2,9:18
-5,-1,9:18
-4,-1,9:18
-3,-1,9:18
-2,-1,9:18
-1,-1,9:18
1,-1,9:18
2,-1,9:17
3,-1,9:18
4,-1,9:18
5,-1,9:18
6,-1,9:18
7,-1,9:18
8,-1,9:18
-7,0,9:18
-6,0,9:18
-5,0,9:18
-4,0,9:18
-3,0,9:18
-2,0,9:18
-1,0,9:18
0,0,9:18
2,0,9:18
3,0,9:18
5,0,9:18
6,0,9:18
7,0,9:18
8,0,9:18
-8,1,9:18
-7,1,9:18
-6,1,9:18
-5,1,9:18
-4,1,9:18
-3,1,9:18
-2,1,9:18
-1,1,9:18
0,1,9:18
1,1,9:18
2,1,9:18
3,1,9:18
4,1,9:17
5,1,9:18
6,1,9:18
7,1,9:18
8,1,9:18
9,1,9:18
-8,2,9:18
-7,2,9:18
-6,2,9:18
-5,2,9:18
-4,2,9:18
-3,2,9:18
-2,2,9:18
0,2,9:18
1,2,9:18
2,2,9:18
3,2,9:18
4,2,9:18
5,2,9:18
6,2,9:18
7,2,9:18
8,2,9:18
-8,3,9:18
-7,3,9:18
-6,3,9:18
-5,3,9:18
-4,3,9:18
-3,3,9:18
-2,3,9:18
-1,3,9:18
1,3,9:18
2,3,9:18
4,3,9:18
5,3,9:18
6,3,9:18
7,3,9:18
-7,4,9:18
-6,4,9:18
-5,4,9:18
-4,4,9:17.0
-3,4,9:18
-2,4,9:18
-1,4,9:18
0,4,9:18
1,4,9:18
2,4,9:18
3,4,9:18
4,4,9:18
5,4,9:18
6,4,9:18
7,4,9:18
-6,5,9:18
-5,5,9:18
-4,5,9:18
-3,5,9:18
-2,5,9:18
-1,5,9:18
0,5,9:18
1,5,9:18
2,5,9:18
3,5,9:18
4,5,9:18
5,5,9:17
6,5,9:18
7,5,9:18
8,5,9:18
-6,6,9:18
-5,6,9:18
-4,6,9:18
-3,6,9:18
-2,6,9:18
-1,6,9:18
0,6,9:18
1,6,9:18
4,6,9:18
5,6,9:18
6,6,9:18
7,6,9:18
-5,7,9:18
-4,7,9:18
-3,7,9:18
-2,7,9:18
-1,7,9:18
1,7,9:18
2,7,9:18
3,7,9:18
4,7,9:18
5,7,9:18
6,7,9:18
-3,8,9:18
2,8,9:18
3,8,9:18
4,8,9:18
5,8,9:18
3,9,9:18
4,9,9:18
-4,-9,10:18
1,-9,10:18
-6,-8,10:18
-5,-8,10:18
-4,-8,10:18
-3,-8,10:18
0,-8,10:18
1,-8,10:18
4,-8,10:18
-8,-7,10:18
-7,-7,10:18
-6,-7,10:18
-5,-7,10:18
-4,-7,10:18
-3,-7,10:18
-2,-7,10:18
-1,-7,10:18
0,-7,10:18
1,-7,10:18
2,-7,10:18
3,-7,10:18
4,-7,10:18
5,-7,10:18
-8,-6,10:18
-7,-6,10:18
-6,-6,10:18
-5,-6,10:18
-4,-6,10:18
-3,-6,10:18
-2,-6,10:18
-1,-6,10:18
0,-6,10:18
1,-6,10:18
2,-6,10:18
3,-6,10:18
4,-6,10:18
5,-6,10:18
6,-6,10:18
-8,-5,10:18
-7,-5,10:18
-6,-5,10:18
-5,-5,10:18
-4,-5,10:18
-3,-5,10:18
-2,-5,10:18
-1,-5,10:18
0,-5,10:18
1,-5,10:18
2,-5,10:18
3,-5,10:18
4,-5,10:18
5,-5,10:18
6,-5,10:18
-9,-4,10:18
-8,-4,10:18
-7,-4,10:18
-6,-4,10:18
-5,-4,10:18
-4,-4,10:18
-3,-4,10:18
-2,-4,10:18
0,-4,10:18
1,-4,10:17
2,-4,10:18
3,-4,10:18
4,-4,10:18
5,-4,10:18
6,-4,10:18
-9,-3,10:18
-8,-3,10:18
-7,-3,10:18
-6,-3,10:18
-5,-3,10:18
-4,-3,10:18
-3,-3,10:18
-2,-3,10:18
1,-3,10:18
2,-3,10:18
3,-3,10:18
4,-3,10:18
5,-3,10:18
-8,-2,10:18
-7,-2,10:18
-6,-2,10:18
-5,-2,10:18
-4,-2,10:18
-3,-2,10:18
-2,-2,10:18
0,-2,10:18
4,-2,10:18
5,-2,10:18
-8,-1,10:18
-7,-1,10:18
-6,-1,10:18
-5,-1,10:18
-4,-1,10:18
-3,-1,10:18
-2,-1,10:18
-1,-1,10:18
2,-1,10:18
4,-1,10:18
5,-1,10:18
6,-1,10:18
-6,0,10:18
-5,0,10:18
-4,0,10:18
-3,0,10:18
-2,0,10:18
-1,0,10:18
0,0,10:18
1,0,10:18
2,0,10:18
4,0,10:18
5,0,10:18
6,0,10:18
7,0,10:18
-6,1,10:18
-5,1,10:18
-4,1,10:18
-3,1,10:18
-2,1,10:18
-1,1,10:18
0,1,10:18
1,1,10:18
2,1,10:18
4,1,10:18
5,1,10:18
6,1,10:18
7,1,10:18
8,1,10:18
-6,2,10:18
-5,2,10:18
-4,2,10:18
-2,2,10:18
-1,2,10:18
0,2,10:18
2,2,10:18
3,2,10:18
4,2,10:18
5,2,10:18
6,2,10:18
7,2,10:18
-6,3,10:18
-5,3,10:18
-4,3,10:18
-3,3,10:18
-2,3,10:18
-1,3,10:18
0,3,10:18
1,3,10:18
2,3,10:18
3,3,10:18
4,3,10:18
5,3,10:18
6,3,10:18
-5,4,10:18
-4,4,10:18
-3,4,10:18
-2,4,10:18
-1,4,10:18
0,4,10:18
1,4,10:18
2,4,10:18
3,4,10:18
4,4,10:18
5,4,10:18
6,4,10:18
-4,5,10:18
-3,5,10:18
-2,5,10:18
-1,5,10:18
0,5,10:18
2,5,10:18
3,5,10:18
4,5,10:18
5,5,10:18
6,5,10:18
7,5,10:18
-2,6,10:18
-1,6,10:18
0,6,10:18
1,6,10:18
2,6,10:18
3,6,10:18
4,6,10:18
5,6,10:18
6,6,10:18
2,7,10:18
3,7,10:18
4,7,10:18
5,7,10:18
3,8,10:18
-4,-6,11:18
1,-6,11:18
2,-6,11:18
-7,-5,11:18
-6,-5,11:18
-5,-5,11:18
-4,-5,11:18
-3,-5,11:18
1,-5,11:18
2,-5,11:18
-7,-4,11:18
-6,-4,11:18
-5,-4,11:18
-4,-4,11:18
-3,-4,11:18
-2,-4,11:18
-1,-4,11:18
0,-4,11:18
1,-4,11:18
2,-4,11:18
3,-4,11:18
-6,-3,11:18
-5,-3,11:18
-4,-3,11:18
-3,-3,11:18
-2,-3,11:18
-1,-3,11:18
0,-3,11:18
1,-3,11:18
2,-3,11:18
3,-3,11:18
4,-3,11:18
-5,-2,11:18
-4,-2,11:18
-3,-2,11:18
-2,-2,11:18
-1,-2,11:18
0,-2,11:18
1,-2,11:18
2,-2,11:18
3,-2,11:18
4,-2,11:18
-5,-1,11:18
-4,-1,11:18
-3,-1,11:18
-2,-1,11:18
-1,-1,11:18
0,-1,11:18
1,-1,11:18
2,-1,11:18
3,-1,11:18
4,-1,11:18
-5,0,11:18
-4,0,11:18
-3,0,11:18
-2,0,11:18
-1,0,11:18
0,0,11:18
1,0,11:18
2,0,11:18
3,0,11:18
4,0,11:18
5,0,11:18
-5,1,11:18
-4,1,11:18
-3,1,11:18
-2,1,11:18
-1,1,11:18
0,1,11:18
1,1,11:18
2,1,11:18
3,1,11:18
4,1,11:18
5,1,11:18
-4,2,11:18
-3,2,11:18
-2,2,11:18
-1,2,11:18
0,2,11:18
1,2,11:18
2,2,11:18
3,2,11:18
4,2,11:18
5,2,11:18
-3,3,11:18
-2,3,11:18
-1,3,11:18
0,3,11:18
1,3,11:18
2,3,11:18
3,3,11:18
4,3,11:18
5,3,11:18
-3,4,11:18
-2,4,11:18
-1,4,11:18
0,4,11:18
1,4,11:18
2,4,11:18
3,4,11:18
-2,5,11:18
-1,5,11:18
0,5,11:18
1,5,11:18
2,5,11:18
3,5,11:18
-1,6,11:18
0,6,11:18
1,-5,12:18
-5,-4,12:18
-4,-4,12:18
0,-4,12:18
1,-4,12:18
2,-4,12:18
-4,-3,12:18
-3,-3,12:18
0,-3,12:18
1,-3,12:18
2,-3,12:18
-4,-2,12:18
-3,-2,12:18
-2,-2,12:18
1,-2,12:18
2,-2,12:18
3,-2,12:18
-4,-1,12:18
-3,-1,12:18
2,-1,12:18
0,0,12:18
-1,1,12:18
0,1,12:18
1,1,12:18
0,2,12:18
1,2,12:18
2,2,12:18
0,3,12:18
1,3,12:18
2,3,12:18
1,4,12:18
1,-3,13:18
-4,-2,13:18
1,2,13:18
