[META]
version=2.0
spawnOnBlockType=2
spawnSunlight=True
spawnDarkness=True
spawnWater=False
spawnLava=False
underFill=False
randomRotation=True
dig=True
tree=True
branch=False
needsFoundation=True
rarity=10
collisionPercentage=2
spawnElevationMin=0
spawnElevationMax=256
spawnInBiome=OttaForest
[DATA]
0,0,0:17.1
0,0,1:17.1
0,0,2:17.1
0,0,3:17.1
0,0,4:17.1
0,0,5:17.1
0,0,6:17.1
0,1,6:18.1
-1,0,6:18.1
0,0,7:17.1
0,0,8:17.1
0,0,9:17.1
-1,1,9:18.1
0,1,9:18.1
0,2,9:18.1
-1,2,9:18.1
-1,0,9:18.1
1,1,9:18.1
1,0,9:18.1
1,2,9:18.1
0,-1,9:18.1
0,0,10:17.1
0,1,10:17.1
-1,0,10:18.1
-1,1,10:18.1
-1,2,10:18.1
0,2,10:18.1
1,2,10:18.1
1,1,10:18.1
1,0,10:18.1
1,-1,10:18.1
0,-1,10:18.1
0,0,11:17.1
0,-1,11:18.1
1,-1,11:18.1
1,0,11:18.1
1,1,11:18.1
0,1,11:18.1
0,0,12:17.1
0,1,12:18.1
0,2,12:18.1
0,3,12:18.1
0,0,13:17.1
0,1,13:17.1
0,2,13:17.1
-1,2,13:18.1
-1,3,13:18.1
0,3,13:18.1
1,3,13:18.1
1,2,13:18.1
1,1,13:18.1
2,1,13:18.1
2,0,13:18.1
1,0,13:18.1
1,-1,13:18.1
2,-1,13:18.1
-1,0,13:18.1
-1,1,13:18.1
-1,-1,13:18.1
0,-1,13:18.1
0,0,14:17.1
1,0,14:18.1
1,1,14:18.1
0,1,14:18.1
-1,1,14:18.1
-1,0,14:18.1
0,2,14:18.1
0,0,15:17.1
-1,0,15:17.1
0,1,15:18.1
1,1,15:18.1
1,0,15:18.1
0,-1,15:18.1
0,-2,15:18.1
-1,-2,15:18.1
-1,-1,15:18.1
-2,-1,15:18.1
-2,0,15:18.1
-2,1,15:18.1
-1,1,15:18.1
0,0,16:17.1
0,1,16:17.1
-1,0,16:18.1
-1,-1,16:18.1
0,-1,16:18.1
1,-1,16:18.1
1,0,16:18.1
1,1,16:18.1
1,2,16:18.1
0,2,16:18.1
-1,2,16:18.1
-1,1,16:18.1
0,0,17:17.1
0,1,17:18.1
0,2,17:18.1
-1,2,17:18.1
-1,1,17:18.1
-1,0,17:18.1
-1,-1,17:18.1
0,-1,17:18.1
1,-1,17:18.1
1,0,17:18.1
1,1,17:18.1
0,0,18:18.1
0,1,18:18.1
0,0,19:18.1
0,0,20:18.1
