[META]
version=2.0
spawnOnBlockType=2
spawnSunlight=True
spawnDarkness=True
spawnWater=False
spawnLava=False
underFill=False
randomRotation=True
dig=True
tree=False
branch=False
needsFoundation=True
rarity=800
collisionPercentage=2
spawnElevationMin=70
spawnElevationMax=120
spawnInBiome=MountainForest
spawnAboveGround=False
spawnUnderGround=False
collisionBlockType=All
groupId=
diggingBranch=false
branchLimit=6
groupFrequencyMin=1
groupFrequencyMax=5
groupSeperationMin=0
groupSeperationMax=5
[DATA]
0,0,-1:17.0
0,0,0:17.0
0,0,1:17.0
0,0,2:17.0
0,0,3:17.0
-2,-1,4:18
-1,-1,4:18
-3,0,4:18
-2,0,4:17.0
-1,0,4:17.0
0,0,4:17.0
-1,1,4:18
-2,0,5:18
-1,0,5:18
0,0,5:17.0
0,1,5:18
-3,-2,6:18
-2,-2,6:17.0
-1,-2,6:18
-1,-1,6:17.0
0,-1,6:18
0,0,6:17.0
-2,-2,7:18
-1,-1,7:18
0,0,7:17.0
1,0,7:18
0,0,8:17.0
-1,-1,9:18
-2,0,9:18
-1,0,9:17.0
0,0,9:17.0
-1,1,9:18
0,-1,10:18
-1,0,10:18
0,0,10:17.0
1,0,10:18
0,1,10:18
0,0,11:18
0,0,12:18
0,0,-2:3
