[META]
version=2.0
spawnOnBlockType=2
spawnSunlight=True
spawnDarkness=True
spawnWater=False
spawnLava=False
underFill=False
randomRotation=True
dig=True
tree=False
branch=False
needsFoundation=True
rarity=1000
collisionPercentage=2
spawnElevationMin=0
spawnElevationMax=128
spawnInBiome=MountainForest
spawnAboveGround=False
spawnUnderGround=False
collisionBlockType=All
groupId=
diggingBranch=false
branchLimit=6
groupFrequencyMin=1
groupFrequencyMax=5
groupSeperationMin=0
groupSeperationMax=5
[DATA]
0,0,0:17.1
0,0,-1:17.1
0,0,1:17.1
0,0,2:17.1
0,0,3:17.1
0,0,4:17.1
0,0,5:17.1
0,0,6:17.1
-1,0,6:18.1
0,-1,6:18.1
0,1,6:18.1
1,0,6:18.1
0,-2,6:18.1
2,0,6:18.1
0,2,6:18.1
-2,0,6:18.1
0,0,7:17.1
-1,0,7:18.1
0,1,7:18.1
0,-1,7:18.1
1,0,7:18.1
0,0,8:17.1
0,0,9:17.1
1,0,9:18.1
0,-1,9:18.1
0,-2,9:18.1
-1,0,9:18.1
0,1,9:18.1
0,2,9:18.1
0,0,10:17.1
-1,0,10:18.1
-2,0,10:18.1
1,0,10:18.1
0,-1,10:18.1
0,1,10:18.1
0,0,11:17.1
0,1,11:18.1
-1,0,11:18.1
0,0,12:18.1
-1,0,12:18.1
0,-1,12:18.1
0,1,12:18.1
1,0,12:18.1
0,0,13:18.1
0,0,14:18.1
