[META]
version=2.0
spawnOnBlockType=1,2,3,12
spawnSunlight=True
spawnDarkness=True
spawnWater=False
spawnLava=False
underFill=True
randomRotation=True
dig=True
tree=False
branch=False
needsFoundation=True
rarity=5
collisionPercentage=0
spawnElevationMin=0
spawnElevationMax=128
spawnInBiome=Jungle
spawnAboveGround=False
spawnUnderGround=False
collisionBlockType=All
groupId=
diggingBranch=false
branchLimit=6
groupFrequencyMin=1
groupFrequencyMax=5
groupSeperationMin=0
groupSeperationMax=5
[DATA]
-1,-1,0:109.2
0,-1,0:109.2
1,-1,0:109.2
0,0,0:98.0
1,0,0:98.0
2,0,0:109.1
-1,1,0:109.3
0,1,0:109.3
1,1,0:109.3
-2,0,0:109.0
-1,0,0:98.0
-2,1,0:2
-1,2,0:2
0,2,0:2
1,2,0:2
2,1,0:2
2,-1,0:2
1,-2,0:2
0,-2,0:2
-1,-2,0:2
-2,-1,0:2
-1,0,1:98.0
1,0,1:98.0
0,0,1:98.0
-2,-1,1:40
2,1,1:40
0,2,1:40
-1,2,1:40
1,-2,1:31.0
2,-1,1:40
-2,1,1:31.0
-1,-2,1:39
0,-2,1:39
1,2,1:39
-1,0,2:109.0
1,0,2:109.1
0,0,2:22
0,0,3:44.5
-2,0,-1:3
-1,0,-1:3
0,0,-1:3
0,1,-1:3
1,1,-1:3
1,0,-1:3
2,0,-1:3
-1,-1,-1:3
0,-1,-1:3
1,-1,-1:3
-1,1,-1:3
-1,0,-2:3
0,0,-2:3
0,-1,-2:3
0,1,-2:3
1,0,-2:3
0,0,-3:3
