[META]
version=2.0
spawnOnBlockType=1,2,3,12
spawnSunlight=True
spawnDarkness=True
spawnWater=False
spawnLava=False
underFill=True
randomRotation=True
dig=True
tree=False
branch=False
needsFoundation=True
rarity=5
collisionPercentage=0
spawnElevationMin=0
spawnElevationMax=128
spawnInBiome=Jungle
spawnAboveGround=False
spawnUnderGround=False
collisionBlockType=All
groupId=
diggingBranch=false
branchLimit=6
groupFrequencyMin=1
groupFrequencyMax=5
groupSeperationMin=0
groupSeperationMax=5
[DATA]
0,-1,0:109.2
0,0,0:98.0
1,0,0:109.1
0,1,0:44.5
-1,-1,-2:3
0,-1,-2:3
1,-1,-2:3
-1,0,-2:3
0,0,-2:3
1,0,-2:3
0,1,-2:3
1,1,-2:3
-1,-1,-1:43.0
0,-1,-1:98.0
1,-1,-1:43.0
-1,0,-1:2
0,0,-1:3
1,0,-1:98.0
0,1,-1:98.0
1,1,-1:43.0
0,0,1:98.0
0,1,1:106.4
-1,0,1:106.8
0,-1,1:106.1
0,0,2:98.2
0,1,2:106.4
-1,0,2:106.8
0,-1,2:106.1
0,0,3:98.0
0,1,3:106.4
1,0,3:106.2
0,-1,3:106.1
0,0,4:98.0
1,0,4:106.2
-1,0,4:106.8
0,-1,4:106.1
0,-1,5:98.0
-1,0,5:98.0
0,0,5:98.0
1,0,5:98.0
0,1,5:98.0
