[META]
version=2.0
spawnOnBlockType=3,2
spawnSunlight=True
spawnDarkness=True
spawnWater=False
spawnLava=False
underFill=False
randomRotation=False
dig=True
tree=False
branch=False
needsFoundation=True
rarity=10
collisionPercentage=20
spawnElevationMin=0
spawnElevationMax=240
spawnInBiome=Mystic,MushroomIsland
spawnAboveGround=False
spawnUnderGround=False
collisionBlockType=All
groupId=
diggingBranch=false
branchLimit=6
groupFrequencyMin=1
groupFrequencyMax=5
groupSeperationMin=0
groupSeperationMax=5
[DATA]
-1,-2,-4:1.0
0,-2,-4:1.0
1,-2,-4:1.0
-2,-1,-4:1.0
-1,-1,-4:1.0
0,-1,-4:1.0
1,-1,-4:1.0
-1,0,-4:1.0
0,0,-4:1.0
1,0,-4:1.0
-1,1,-4:1.0
0,1,-4:1.0
1,1,-4:1.0
-2,-3,-3:3.0
-1,-3,-3:3.0
0,-3,-3:1.5
1,-3,-3:1.5
2,-3,-3:3.0
-3,-2,-3:3.0
-2,-2,-3:1.0
-1,-2,-3:1.0
0,-2,-3:1.0
1,-2,-3:1.0
2,-2,-3:1.5
-3,-1,-3:3.0
-2,-1,-3:1.0
-1,-1,-3:1.0
0,-1,-3:1.0
1,-1,-3:1.0
2,-1,-3:3.0
-3,0,-3:3.0
-2,0,-3:1.0
-1,0,-3:1.0
0,0,-3:1.0
1,0,-3:1.0
2,0,-3:3.0
-2,1,-3:3.0
-1,1,-3:1.5
0,1,-3:1.5
1,1,-3:3.0
2,1,-3:3.0
-1,2,-3:3.0
0,2,-3:3.0
-2,-4,-2:3.0
-1,-4,-2:3.0
0,-4,-2:1.5
1,-4,-2:1.5
2,-4,-2:3.0
-3,-3,-2:3.0
-2,-3,-2:1.0
-1,-3,-2:1.0
0,-3,-2:11.0
1,-3,-2:11.0
2,-3,-2:1.5
3,-3,-2:3.0
-4,-2,-2:3.0
-3,-2,-2:1.0
-2,-2,-2:1.0
-1,-2,-2:11.0
0,-2,-2:11.0
1,-2,-2:11.0
2,-2,-2:11.0
3,-2,-2:1.5
-4,-1,-2:3.0
-3,-1,-2:1.0
-2,-1,-2:11.0
-1,-1,-2:11.0
0,-1,-2:11.0
1,-1,-2:11.0
2,-1,-2:1.0
3,-1,-2:3.0
-4,0,-2:3.0
-3,0,-2:1.0
-2,0,-2:11.0
-1,0,-2:11.0
0,0,-2:11.0
1,0,-2:11.0
2,0,-2:1.0
3,0,-2:3.0
-4,1,-2:3.0
-3,1,-2:1.5
-2,1,-2:1.5
-1,1,-2:11.0
0,1,-2:11.0
1,1,-2:1.0
2,1,-2:1.0
3,1,-2:3.0
-4,2,-2:3.0
-3,2,-2:3.0
-2,2,-2:3.0
-1,2,-2:1.5
0,2,-2:1.5
1,2,-2:3.0
2,2,-2:3.0
-3,3,-2:3.0
-2,3,-2:3.0
-1,3,-2:3.0
0,3,-2:3.0
1,3,-2:3.0
-2,-5,-1:110.0
-1,-5,-1:110.0
0,-5,-1:110.0
1,-5,-1:110.0
2,-5,-1:110.0
-3,-4,-1:110.0
-2,-4,-1:110.0
-1,-4,-1:110.0
1,-4,-1:99.10
2,-4,-1:3.0
3,-4,-1:110.0
-4,-3,-1:110.0
-3,-3,-1:110.0
-2,-3,-1:110.0
2,-3,-1:99.10
3,-3,-1:110.0
4,-3,-1:110.0
-4,-2,-1:110.0
-3,-2,-1:110.0
4,-2,-1:110.0
-5,-1,-1:110.0
-4,-1,-1:110.0
3,-1,-1:110.0
4,-1,-1:110.0
-5,0,-1:110.0
-4,0,-1:110.0
3,0,-1:110.0
4,0,-1:110.0
-4,1,-1:110.0
-3,1,-1:99.10
2,1,-1:110.0
3,1,-1:110.0
4,1,-1:110.0
-5,2,-1:110.0
-4,2,-1:110.0
-3,2,-1:3.0
-2,2,-1:99.10
1,2,-1:110.0
2,2,-1:110.0
3,2,-1:110.0
-4,3,-1:110.0
-3,3,-1:3.0
-2,3,-1:110.0
-1,3,-1:110.0
0,3,-1:110.0
1,3,-1:110.0
2,3,-1:110.0
-3,4,-1:110.0
-2,4,-1:110.0
-1,4,-1:110.0
0,4,-1:110.0
1,4,-1:110.0
2,-4,0:99.10
2,-3,0:99.10
-3,2,0:99.10
-2,2,0:99.10
-3,3,0:99.10
2,-3,1:99.10
-3,2,1:99.10
1,-5,2:100.1
2,-5,2:100.1
3,-5,2:100.3
0,-4,2:100.1
1,-4,2:100.1
3,-4,2:100.3
4,-4,2:100.3
0,-3,2:100.1
2,-3,2:99.10
4,-3,2:100.3
0,-2,2:100.7
1,-2,2:100.7
3,-2,2:100.9
4,-2,2:100.9
1,-1,2:100.7
2,-1,2:100.7
3,-1,2:100.9
-3,2,2:99.10
-2,2,2:99.10
1,-4,3:100.1
2,-4,3:100.1
3,-4,3:100.3
1,-3,3:100.1
2,-3,3:100.7
3,-3,3:100.9
1,-2,3:100.7
2,-2,3:100.7
3,-2,3:100.9
-2,2,3:99.10
-4,0,4:99.1
-3,0,4:99.1
-2,0,4:99.1
-1,0,4:99.3
0,0,4:99.3
-4,1,4:99.1
-3,1,4:99.1
-1,1,4:99.3
0,1,4:99.9
-4,2,4:99.1
-2,2,4:99.10
0,2,4:99.9
-4,3,4:99.1
-3,3,4:99.7
-1,3,4:99.9
0,3,4:99.9
-4,4,4:99.7
-3,4,4:99.7
-2,4,4:99.7
-1,4,4:99.7
0,4,4:99.9
-3,1,5:99.1
-2,1,5:99.3
-1,1,5:99.3
-3,2,5:99.7
-2,2,5:99.7
-1,2,5:99.9
-3,3,5:99.7
-2,3,5:99.7
-1,3,5:99.9
-3,2,3:39.5
-2,2,1:39.5
1,3,0:39.5
-3,-2,0:40.0
3,-3,0:40.5
-2,-3,0:40.5
