[META]
version=2.0
spawnOnBlockType=3,2
spawnSunlight=True
spawnDarkness=True
spawnWater=False
spawnLava=False
underFill=False
randomRotation=False
dig=True
tree=False
branch=False
needsFoundation=True
rarity=10
collisionPercentage=20
spawnElevationMin=0
spawnElevationMax=240
spawnInBiome=Mystic,MushroomIsland
spawnAboveGround=False
spawnUnderGround=False
collisionBlockType=All
groupId=
diggingBranch=false
branchLimit=6
groupFrequencyMin=1
groupFrequencyMax=5
groupSeperationMin=0
groupSeperationMax=5
[DATA]
-2,-2,0:1.5
-1,-2,0:1.5
0,-2,0:1.5
-3,-1,0:1.5
-2,-1,0:1.5
-1,-1,0:1.5
0,-1,0:1.5
-2,0,0:1.5
-1,0,0:1.5
0,0,0:1.5
-2,1,0:1.5
-1,1,0:1.5
0,1,0:1.5
-1,2,0:1.5
-3,-3,1:3.0
-2,-3,1:3.0
-1,-3,1:3.0
0,-3,1:3.0
-4,-2,1:3.0
-3,-2,1:1.5
-2,-2,1:1.5
-1,-2,1:1.5
0,-2,1:1.5
-4,-1,1:3.0
-3,-1,1:1.5
-2,-1,1:1.5
-1,-1,1:1.5
0,-1,1:1.5
1,-1,1:3.0
-4,0,1:3.0
-3,0,1:1.5
-2,0,1:1.5
-1,0,1:1.5
0,0,1:1.5
1,0,1:3.0
-3,1,1:3.0
-2,1,1:3.0
-1,1,1:3.0
0,1,1:3.0
1,1,1:3.0
-3,2,1:3.0
-2,2,1:3.0
-1,2,1:3.0
0,2,1:3.0
-2,3,1:3.0
-1,3,1:3.0
0,3,1:3.0
-1,4,1:3.0
-2,-4,2:3.0
-1,-4,2:3.0
0,-4,2:3.0
-3,-3,2:1.5
-2,-3,2:1.5
-1,-3,2:1.5
0,-3,2:1.5
1,-3,2:1.5
-4,-2,2:1.5
-3,-2,2:1.5
-2,-2,2:11.0
-1,-2,2:11.0
0,-2,2:88.0
1,-2,2:1.5
-5,-1,2:3.0
-4,-1,2:1.5
-3,-1,2:11.0
-2,-1,2:11.0
-1,-1,2:11.0
0,-1,2:11.0
1,-1,2:1.5
2,-1,2:3.0
-5,0,2:3.0
-4,0,2:1.5
-3,0,2:88.0
-2,0,2:11.0
-1,0,2:11.0
0,0,2:11.0
1,0,2:1.5
2,0,2:3.0
-4,1,2:3.0
-3,1,2:1.5
-2,1,2:1.5
-1,1,2:1.5
0,1,2:1.5
1,1,2:1.5
2,1,2:3.0
-3,2,2:3.0
-2,2,2:3.0
-1,2,2:3.0
0,2,2:3.0
1,2,2:3.0
-3,3,2:3.0
-2,3,2:3.0
-1,3,2:3.0
0,3,2:3.0
1,3,2:3.0
-2,4,2:3.0
-1,4,2:3.0
0,4,2:3.0
-1,5,2:3.0
-2,-5,3:110.0
-1,-5,3:110.0
0,-5,3:110.0
-3,-4,3:110.0
-2,-4,3:110.0
-1,-4,3:110.0
0,-4,3:110.0
1,-4,3:110.0
-4,-3,3:110.0
-3,-3,3:110.0
0,-3,3:110.0
1,-3,3:110.0
2,-3,3:110.0
-5,-2,3:110.0
-4,-2,3:110.0
1,-2,3:110.0
2,-2,3:110.0
-6,-1,3:110.0
-5,-1,3:110.0
2,-1,3:110.0
3,-1,3:110.0
-6,0,3:110.0
-5,0,3:110.0
-4,0,3:110.0
2,0,3:110.0
3,0,3:110.0
-5,1,3:110.0
-4,1,3:110.0
-3,1,3:110.0
-2,1,3:88.0
1,1,3:110.0
2,1,3:110.0
3,1,3:110.0
-4,2,3:110.0
-3,2,3:110.0
-2,2,3:110.0
-1,2,3:3.0
0,2,3:110.0
1,2,3:88.0
2,2,3:110.0
-4,3,3:110.0
-3,3,3:110.0
-2,3,3:3.0
-1,3,3:3.0
0,3,3:3.0
1,3,3:110.0
-3,4,3:110.0
-2,4,3:110.0
-1,4,3:3.0
0,4,3:110.0
1,4,3:110.0
-2,5,3:110.0
-1,5,3:3.0
0,5,3:110.0
-1,6,3:110.0
-1,2,4:99.10
-2,3,4:99.10
-1,3,4:99.10
0,3,4:99.10
-1,4,4:99.10
-1,5,4:99.10
-1,3,5:99.10
-1,4,5:99.10
-1,3,6:99.10
-1,2,7:99.10
-1,3,7:99.10
-1,2,8:99.10
-3,-3,9:100.1
-2,-3,9:100.1
-1,-3,9:100.1
0,-3,9:100.1
1,-3,9:100.3
-4,-2,9:100.1
-3,-2,9:100.1
1,-2,9:100.3
2,-2,9:100.3
-4,-1,9:100.7
2,-1,9:100.3
-4,0,9:100.7
2,0,9:100.3
-4,1,9:100.7
-1,1,9:99.10
2,1,9:100.3
-4,2,9:100.7
-3,2,9:100.7
-1,2,9:99.10
1,2,9:100.9
2,2,9:100.9
-3,3,9:100.7
-2,3,9:100.9
-1,3,9:100.9
0,3,9:100.9
1,3,9:100.9
-3,-3,10:100.1
-2,-3,10:100.1
-1,-3,10:100.1
0,-3,10:100.1
1,-3,10:100.3
-4,-2,10:100.1
-3,-2,10:100.1
1,-2,10:100.3
2,-2,10:100.3
-4,-1,10:100.1
2,-1,10:100.3
-4,0,10:100.1
-1,0,10:99.10
2,0,10:100.3
-4,1,10:100.1
-1,1,10:99.10
2,1,10:100.3
-4,2,10:100.7
-3,2,10:100.7
1,2,10:100.9
2,2,10:100.9
-3,3,10:100.7
-2,3,10:100.7
-1,3,10:100.7
0,3,10:100.7
1,3,10:100.9
-3,-3,11:100.1
-2,-3,11:100.3
-1,-3,11:100.3
0,-3,11:100.3
1,-3,11:100.3
-4,-2,11:100.1
-3,-2,11:100.1
1,-2,11:100.3
2,-2,11:100.3
-4,-1,11:100.1
2,-1,11:100.9
-4,0,11:100.1
-1,0,11:99.10
2,0,11:100.9
-4,1,11:100.7
2,1,11:100.9
-4,2,11:100.7
-3,2,11:100.7
1,2,11:100.9
2,2,11:100.9
-3,3,11:100.7
-2,3,11:100.7
-1,3,11:100.7
0,3,11:100.7
1,3,11:100.9
-3,-2,12:100.1
-2,-2,12:100.1
-1,-2,12:100.1
0,-2,12:100.1
1,-2,12:100.3
-3,-1,12:100.7
-1,-1,12:99.10
1,-1,12:100.3
-3,0,12:100.7
-2,0,12:99.10
-1,0,12:99.10
0,0,12:99.10
1,0,12:100.3
-3,1,12:100.7
-1,1,12:99.10
1,1,12:100.3
-3,2,12:100.7
-2,2,12:100.7
-1,2,12:100.8
0,2,12:100.9
1,2,12:100.9
-2,-1,13:100.1
-1,-1,13:100.1
0,-1,13:100.3
-2,0,13:100.1
-1,0,13:100.1
0,0,13:100.3
-2,1,13:100.7
-1,1,13:100.8
0,1,13:100.9
-1,4,6:40.5
-1,2,5:40.5
-4,3,4:39.5
-3,2,4:39.0
1,1,4:40.5
-2,1,4:39.0
-3,1,4:39.5
-4,0,4:39.5
-6,0,4:40.5
2,-1,4:40.5
-4,-3,4:40.5
-1,-4,4:39.5
0,-5,4:39.5
-1,-5,4:39.0
-2,-5,4:40.0
