[META]
version=2.0
spawnOnBlockType=3,2
spawnSunlight=True
spawnDarkness=True
spawnWater=False
spawnLava=False
underFill=False
randomRotation=False
dig=True
tree=False
branch=False
needsFoundation=True
rarity=100
collisionPercentage=10
spawnElevationMin=0
spawnElevationMax=240
spawnInBiome=Mystic,MushroomIsland
spawnAboveGround=False
spawnUnderGround=False
collisionBlockType=All
groupId=
diggingBranch=false
branchLimit=6
groupFrequencyMin=1
groupFrequencyMax=5
groupSeperationMin=0
groupSeperationMax=5
[DATA]
-1,0,-3:1.0
-2,1,-3:1.0
-1,1,-3:1.0
0,1,-3:1.0
-1,0,-2:3.0
-2,1,-2:88.0
-1,1,-2:88.0
0,1,-2:88.0
-1,2,-2:88.0
0,2,-2:3.0
-2,0,-1:110.0
-1,0,-1:110.0
-2,1,-1:88.0
-1,1,-1:3.0
0,1,-1:110.0
-1,2,-1:110.0
0,2,-1:88.0
-1,1,0:99.10
-1,1,1:99.10
-1,0,2:99.10
-1,1,2:99.10
-1,0,3:99.10
-1,-1,4:99.10
-1,0,4:99.10
-1,-1,5:99.10
-1,-1,6:99.10
-1,0,6:99.10
-1,0,7:99.10
-2,-3,8:99.1
-1,-3,8:99.2
0,-3,8:99.3
-3,-2,8:99.1
1,-2,8:99.3
-4,-1,8:99.1
2,-1,8:99.3
-4,0,8:99.4
-1,0,8:99.10
2,0,8:99.6
-4,1,8:99.7
2,1,8:99.9
-3,2,8:99.7
1,2,8:99.9
-2,3,8:99.7
-1,3,8:99.8
0,3,8:99.9
-2,-2,9:99.1
-1,-2,9:99.2
0,-2,9:99.3
-3,-1,9:99.1
1,-1,9:99.3
-3,0,9:99.4
-1,0,9:99.10
1,0,9:99.6
-3,1,9:99.7
1,1,9:99.9
-2,2,9:99.7
-1,2,9:99.8
0,2,9:99.9
-2,-1,10:99.1
-1,-1,10:99.2
0,-1,10:99.3
-2,0,10:99.4
-1,0,10:99.5
0,0,10:99.6
-2,1,10:99.7
-1,1,10:99.8
0,1,10:99.9
0,1,0:39.0
