[META]
version=2.0
spawnOnBlockType=3,2
spawnSunlight=True
spawnDarkness=True
spawnWater=False
spawnLava=False
underFill=False
randomRotation=False
dig=True
tree=False
branch=False
needsFoundation=True
rarity=40
collisionPercentage=10
spawnElevationMin=0
spawnElevationMax=240
spawnInBiome=Mystic,MushroomIsland
spawnAboveGround=False
spawnUnderGround=False
collisionBlockType=All
groupId=
diggingBranch=false
branchLimit=6
groupFrequencyMin=1
groupFrequencyMax=5
groupSeperationMin=0
groupSeperationMax=5
[DATA]
-1,-1,-4:1.0
0,-1,-4:1.0
-2,-2,-3:1.0
-1,-2,-3:88.0
0,-2,-3:1.0
-2,-1,-3:88.0
-1,-1,-3:1.0
0,-1,-3:1.0
1,-1,-3:1.0
-1,0,-3:1.0
0,0,-3:1.0
0,-3,-2:88.0
-2,-2,-2:1.0
-1,-2,-2:88.0
0,-2,-2:3.0
1,-2,-2:1.0
-2,-1,-2:3.0
-1,-1,-2:88.0
0,-1,-2:3.0
1,-1,-2:88.0
-2,0,-2:88.0
-1,0,-2:3.0
0,0,-2:88.0
1,0,-2:88.0
-1,1,-2:1.0
0,1,-2:3.0
-1,-3,-1:110.0
0,-3,-1:110.0
-2,-2,-1:110.0
-1,-2,-1:3.0
0,-2,-1:3.0
1,-2,-1:110.0
-3,-1,-1:110.0
-2,-1,-1:3.0
-1,-1,-1:3.0
0,-1,-1:3.0
1,-1,-1:3.0
2,-1,-1:110.0
-3,0,-1:110.0
-2,0,-1:3.0
-1,0,-1:3.0
0,0,-1:3.0
1,0,-1:3.0
2,0,-1:110.0
-2,1,-1:110.0
-1,1,-1:3.0
0,1,-1:3.0
0,2,-1:110.0
-1,-2,0:99.10
0,-2,0:99.10
-2,-1,0:99.10
-1,-1,0:99.10
0,-1,0:99.10
1,-1,0:99.10
-2,0,0:99.10
-1,0,0:99.10
0,0,0:99.10
1,0,0:99.10
-1,1,0:99.10
0,1,0:99.10
-1,-2,1:99.10
0,-2,1:99.10
-2,-1,1:99.10
-1,-1,1:99.10
0,-1,1:99.10
1,-1,1:99.10
-2,0,1:99.10
-1,0,1:99.10
0,0,1:99.10
1,0,1:99.10
-1,1,1:99.10
0,1,1:99.10
-1,-2,2:99.10
0,-2,2:99.10
-2,-1,2:99.10
-1,-1,2:99.10
0,-1,2:99.10
1,-1,2:99.10
-2,0,2:99.10
-1,0,2:99.10
0,0,2:99.10
1,0,2:99.10
-1,1,2:99.10
0,1,2:99.10
-1,-2,3:99.10
0,-2,3:99.10
-2,-1,3:99.10
-1,-1,3:99.10
0,-1,3:99.10
1,-1,3:99.10
-2,0,3:99.10
-1,0,3:99.10
0,0,3:99.10
1,0,3:99.10
-1,1,3:99.10
0,1,3:99.10
-1,-2,4:99.10
0,-2,4:99.10
-2,-1,4:99.10
-1,-1,4:99.10
0,-1,4:99.10
1,-1,4:99.10
-2,0,4:99.10
-1,0,4:99.10
0,0,4:99.10
1,0,4:99.10
-1,1,4:99.10
0,1,4:99.10
-2,-5,5:99.10
-1,-5,5:100.2
0,-5,5:100.2
1,-5,5:99.10
-3,-4,5:100.1
-2,-4,5:99.10
-1,-4,5:99.10
0,-4,5:99.10
1,-4,5:99.10
2,-4,5:99.10
-4,-3,5:100.1
-3,-3,5:99.10
-2,-3,5:99.10
-1,-3,5:99.10
0,-3,5:99.10
1,-3,5:99.10
2,-3,5:99.10
3,-3,5:99.10
-5,-2,5:99.10
-4,-2,5:99.10
-3,-2,5:99.10
-2,-2,5:99.10
-1,-2,5:99.10
0,-2,5:99.10
1,-2,5:99.10
2,-2,5:99.10
3,-2,5:99.10
4,-2,5:99.10
-5,-1,5:99.10
-4,-1,5:99.10
-3,-1,5:99.10
-2,-1,5:99.10
-1,-1,5:99.10
0,-1,5:99.10
1,-1,5:99.10
2,-1,5:99.10
3,-1,5:99.10
4,-1,5:100.6
-5,0,5:99.10
-4,0,5:99.10
-3,0,5:99.10
-2,0,5:99.10
-1,0,5:99.10
0,0,5:99.10
1,0,5:99.10
2,0,5:99.10
3,0,5:99.10
4,0,5:100.6
-5,1,5:99.10
-4,1,5:99.10
-3,1,5:99.10
-2,1,5:99.10
-1,1,5:99.10
0,1,5:99.10
1,1,5:99.10
2,1,5:99.10
3,1,5:99.10
4,1,5:99.10
-4,2,5:100.7
-3,2,5:99.10
-2,2,5:99.10
-1,2,5:99.10
0,2,5:99.10
1,2,5:99.10
2,2,5:99.10
3,2,5:99.10
-3,3,5:100.7
-2,3,5:99.10
-1,3,5:99.10
0,3,5:99.10
1,3,5:99.10
2,3,5:100.9
-2,4,5:100.7
-1,4,5:100.8
0,4,5:100.8
1,4,5:100.9
-2,-6,6:99.10
-1,-6,6:99.10
0,-6,6:100.2
1,-6,6:100.3
-3,-5,6:99.10
-2,-5,6:99.10
-1,-5,6:99.10
0,-5,6:99.10
1,-5,6:99.10
2,-5,6:99.10
-4,-4,6:100.1
-3,-4,6:99.10
-2,-4,6:99.10
-1,-4,6:99.10
0,-4,6:99.10
1,-4,6:99.10
2,-4,6:99.10
3,-4,6:99.10
-5,-3,6:100.1
-4,-3,6:99.10
-3,-3,6:99.10
-2,-3,6:99.10
-1,-3,6:99.10
0,-3,6:99.10
1,-3,6:99.10
2,-3,6:99.10
3,-3,6:99.10
4,-3,6:99.10
-6,-2,6:99.10
-5,-2,6:99.10
-4,-2,6:99.10
-3,-2,6:99.10
-2,-2,6:99.10
-1,-2,6:99.10
0,-2,6:99.10
1,-2,6:99.10
2,-2,6:99.10
3,-2,6:99.10
4,-2,6:99.10
5,-2,6:100.3
-6,-1,6:99.10
-5,-1,6:99.10
-4,-1,6:99.10
-3,-1,6:99.10
-2,-1,6:99.10
-1,-1,6:99.10
0,-1,6:99.10
1,-1,6:99.10
2,-1,6:99.10
3,-1,6:99.10
4,-1,6:99.10
5,-1,6:100.6
-6,0,6:99.10
-5,0,6:99.10
-4,0,6:99.10
-3,0,6:99.10
-2,0,6:99.10
-1,0,6:99.10
0,0,6:99.10
1,0,6:99.10
2,0,6:99.10
3,0,6:99.10
4,0,6:99.10
5,0,6:99.10
-6,1,6:99.10
-5,1,6:99.10
-4,1,6:99.10
-3,1,6:99.10
-2,1,6:99.10
-1,1,6:99.10
0,1,6:99.10
1,1,6:99.10
2,1,6:99.10
3,1,6:99.10
4,1,6:99.10
5,1,6:99.10
-5,2,6:100.7
-4,2,6:99.10
-3,2,6:99.10
-2,2,6:99.10
-1,2,6:99.10
0,2,6:99.10
1,2,6:99.10
2,2,6:99.10
3,2,6:99.10
4,2,6:99.10
-4,3,6:100.7
-3,3,6:99.10
-2,3,6:99.10
-1,3,6:99.10
0,3,6:99.10
1,3,6:99.10
2,3,6:99.10
3,3,6:99.10
-3,4,6:100.7
-2,4,6:99.10
-1,4,6:99.10
0,4,6:99.10
1,4,6:99.10
2,4,6:100.9
-2,5,6:100.7
-1,5,6:100.8
0,5,6:100.8
1,5,6:100.9
-2,-6,7:99.10
-1,-6,7:99.10
0,-6,7:99.10
1,-6,7:100.3
-3,-5,7:99.10
-2,-5,7:99.10
-1,-5,7:99.10
0,-5,7:99.10
1,-5,7:99.10
2,-5,7:100.3
-4,-4,7:99.10
-3,-4,7:99.10
-2,-4,7:99.10
-1,-4,7:99.10
0,-4,7:99.10
1,-4,7:99.10
2,-4,7:99.10
3,-4,7:100.3
-5,-3,7:100.1
-4,-3,7:99.10
-3,-3,7:99.10
-2,-3,7:99.10
-1,-3,7:99.10
0,-3,7:99.10
1,-3,7:99.10
2,-3,7:99.10
3,-3,7:99.10
4,-3,7:100.3
-6,-2,7:100.1
-5,-2,7:99.10
-4,-2,7:99.10
-3,-2,7:99.10
-2,-2,7:99.10
-1,-2,7:99.10
0,-2,7:99.10
1,-2,7:99.10
2,-2,7:99.10
3,-2,7:99.10
4,-2,7:99.10
5,-2,7:100.3
-6,-1,7:99.10
-5,-1,7:99.10
-4,-1,7:99.10
-3,-1,7:99.10
-2,-1,7:99.10
-1,-1,7:99.10
0,-1,7:99.10
1,-1,7:99.10
2,-1,7:99.10
3,-1,7:99.10
4,-1,7:99.10
5,-1,7:100.6
-6,0,7:99.10
-5,0,7:99.10
-4,0,7:99.10
-3,0,7:99.10
-2,0,7:99.10
-1,0,7:99.10
0,0,7:99.10
1,0,7:99.10
2,0,7:99.10
3,0,7:99.10
4,0,7:99.10
5,0,7:99.10
-6,1,7:100.7
-5,1,7:99.10
-4,1,7:99.10
-3,1,7:99.10
-2,1,7:99.10
-1,1,7:99.10
0,1,7:99.10
1,1,7:99.10
2,1,7:99.10
3,1,7:99.10
4,1,7:99.10
5,1,7:99.10
-5,2,7:100.7
-4,2,7:99.10
-3,2,7:99.10
-2,2,7:99.10
-1,2,7:99.10
0,2,7:99.10
1,2,7:99.10
2,2,7:99.10
3,2,7:99.10
4,2,7:99.10
-4,3,7:100.7
-3,3,7:99.10
-2,3,7:99.10
-1,3,7:99.10
0,3,7:99.10
1,3,7:99.10
2,3,7:99.10
3,3,7:99.10
-3,4,7:99.10
-2,4,7:99.10
-1,4,7:99.10
0,4,7:99.10
1,4,7:99.10
2,4,7:100.9
-2,5,7:99.10
-1,5,7:100.8
0,5,7:100.8
1,5,7:100.9
-2,-6,8:99.10
-1,-6,8:99.10
0,-6,8:100.2
1,-6,8:100.3
-3,-5,8:99.10
-2,-5,8:99.10
-1,-5,8:99.10
0,-5,8:99.10
1,-5,8:99.10
2,-5,8:100.3
-4,-4,8:100.1
-3,-4,8:99.10
-2,-4,8:99.10
-1,-4,8:99.10
0,-4,8:99.10
1,-4,8:99.10
2,-4,8:99.10
3,-4,8:100.3
-5,-3,8:100.1
-4,-3,8:99.10
-3,-3,8:99.10
-2,-3,8:99.10
-1,-3,8:99.10
0,-3,8:99.10
1,-3,8:99.10
2,-3,8:99.10
3,-3,8:99.10
4,-3,8:100.3
-6,-2,8:100.1
-5,-2,8:99.10
-4,-2,8:99.10
-3,-2,8:99.10
-2,-2,8:99.10
-1,-2,8:99.10
0,-2,8:99.10
1,-2,8:99.10
2,-2,8:99.10
3,-2,8:99.10
4,-2,8:99.10
5,-2,8:100.3
-6,-1,8:100.4
-5,-1,8:99.10
-4,-1,8:99.10
-3,-1,8:99.10
-2,-1,8:99.10
-1,-1,8:99.10
0,-1,8:99.10
1,-1,8:99.10
2,-1,8:99.10
3,-1,8:99.10
4,-1,8:99.10
5,-1,8:100.6
-6,0,8:100.4
-5,0,8:99.10
-4,0,8:99.10
-3,0,8:99.10
-2,0,8:99.10
-1,0,8:99.10
0,0,8:99.10
1,0,8:99.10
2,0,8:99.10
3,0,8:99.10
4,0,8:99.10
5,0,8:100.6
-6,1,8:100.7
-5,1,8:99.10
-4,1,8:99.10
-3,1,8:99.10
-2,1,8:99.10
-1,1,8:99.10
0,1,8:99.10
1,1,8:99.10
2,1,8:99.10
3,1,8:99.10
4,1,8:99.10
5,1,8:99.10
-5,2,8:100.7
-4,2,8:99.10
-3,2,8:99.10
-2,2,8:99.10
-1,2,8:99.10
0,2,8:99.10
1,2,8:99.10
2,2,8:99.10
3,2,8:99.10
4,2,8:99.10
-4,3,8:99.10
-3,3,8:99.10
-2,3,8:99.10
-1,3,8:99.10
0,3,8:99.10
1,3,8:99.10
2,3,8:99.10
3,3,8:100.9
-3,4,8:99.10
-2,4,8:99.10
-1,4,8:99.10
0,4,8:99.10
1,4,8:99.10
2,4,8:100.9
-2,5,8:99.10
-1,5,8:99.10
0,5,8:100.8
1,5,8:100.9
-2,-6,9:99.10
-1,-6,9:100.2
0,-6,9:100.2
1,-6,9:100.3
-3,-5,9:100.1
-2,-5,9:99.10
-1,-5,9:99.10
0,-5,9:99.10
1,-5,9:99.10
2,-5,9:99.10
-4,-4,9:100.1
-3,-4,9:99.10
-2,-4,9:99.10
-1,-4,9:99.10
0,-4,9:99.10
1,-4,9:99.10
2,-4,9:99.10
3,-4,9:99.10
-5,-3,9:100.1
-4,-3,9:99.10
-3,-3,9:99.10
-2,-3,9:99.10
-1,-3,9:99.10
0,-3,9:99.10
1,-3,9:99.10
2,-3,9:99.10
3,-3,9:99.10
4,-3,9:100.3
-6,-2,9:100.1
-5,-2,9:99.10
-4,-2,9:99.10
-3,-2,9:99.10
-2,-2,9:99.10
-1,-2,9:99.10
0,-2,9:99.10
1,-2,9:99.10
2,-2,9:99.10
3,-2,9:99.10
4,-2,9:99.10
5,-2,9:100.3
-6,-1,9:100.4
-5,-1,9:99.10
-4,-1,9:99.10
-3,-1,9:99.10
-2,-1,9:99.10
-1,-1,9:99.10
0,-1,9:99.10
1,-1,9:99.10
2,-1,9:99.10
3,-1,9:99.10
4,-1,9:99.10
5,-1,9:100.6
-6,0,9:100.4
-5,0,9:99.10
-4,0,9:99.10
-3,0,9:99.10
-2,0,9:99.10
-1,0,9:99.10
0,0,9:99.10
1,0,9:99.10
2,0,9:99.10
3,0,9:99.10
4,0,9:99.10
5,0,9:100.6
-6,1,9:100.7
-5,1,9:99.10
-4,1,9:99.10
-3,1,9:99.10
-2,1,9:99.10
-1,1,9:99.10
0,1,9:99.10
1,1,9:99.10
2,1,9:99.10
3,1,9:99.10
4,1,9:99.10
5,1,9:100.9
-5,2,9:100.7
-4,2,9:99.10
-3,2,9:99.10
-2,2,9:99.10
-1,2,9:99.10
0,2,9:99.10
1,2,9:99.10
2,2,9:99.10
3,2,9:99.10
4,2,9:100.9
-4,3,9:99.10
-3,3,9:99.10
-2,3,9:99.10
-1,3,9:99.10
0,3,9:99.10
1,3,9:99.10
2,3,9:99.10
3,3,9:100.9
-3,4,9:99.10
-2,4,9:99.10
-1,4,9:99.10
0,4,9:99.10
1,4,9:99.10
2,4,9:100.9
-2,5,9:99.10
-1,5,9:99.10
0,5,9:100.8
1,5,9:100.9
-2,-5,10:100.1
-1,-5,10:100.2
0,-5,10:100.2
1,-5,10:99.10
-3,-4,10:99.10
-2,-4,10:99.10
-1,-4,10:99.10
0,-4,10:99.10
1,-4,10:99.10
2,-4,10:99.10
-4,-3,10:99.10
-3,-3,10:99.10
-2,-3,10:99.10
-1,-3,10:99.10
0,-3,10:99.10
1,-3,10:99.10
2,-3,10:99.10
3,-3,10:99.10
-5,-2,10:100.1
-4,-2,10:99.10
-3,-2,10:99.10
-2,-2,10:99.10
-1,-2,10:99.10
0,-2,10:99.10
1,-2,10:99.10
2,-2,10:99.10
3,-2,10:99.10
4,-2,10:100.3
-5,-1,10:100.4
-4,-1,10:99.10
-3,-1,10:99.10
-2,-1,10:99.10
-1,-1,10:99.10
0,-1,10:99.10
1,-1,10:99.10
2,-1,10:99.10
3,-1,10:99.10
4,-1,10:100.6
-5,0,10:100.4
-4,0,10:99.10
-3,0,10:99.10
-2,0,10:99.10
-1,0,10:99.10
0,0,10:99.10
1,0,10:99.10
2,0,10:99.10
3,0,10:99.10
4,0,10:100.6
-5,1,10:100.7
-4,1,10:99.10
-3,1,10:99.10
-2,1,10:99.10
-1,1,10:99.10
0,1,10:99.10
1,1,10:99.10
2,1,10:99.10
3,1,10:99.10
4,1,10:100.9
-4,2,10:100.7
-3,2,10:99.10
-2,2,10:99.10
-1,2,10:99.10
0,2,10:99.10
1,2,10:99.10
2,2,10:99.10
3,2,10:100.9
-3,3,10:99.10
-2,3,10:99.10
-1,3,10:99.10
0,3,10:99.10
1,3,10:99.10
2,3,10:100.9
-2,4,10:99.10
-1,4,10:99.10
0,4,10:100.8
1,4,10:100.9
-2,-4,11:99.10
-1,-4,11:100.2
0,-4,11:100.2
1,-4,11:99.10
-3,-3,11:99.10
-2,-3,11:99.10
-1,-3,11:99.10
0,-3,11:99.10
1,-3,11:99.10
2,-3,11:99.10
-4,-2,11:99.10
-3,-2,11:99.10
-2,-2,11:99.10
-1,-2,11:99.10
0,-2,11:99.10
1,-2,11:99.10
2,-2,11:99.10
3,-2,11:100.3
-4,-1,11:100.4
-3,-1,11:99.10
-2,-1,11:99.10
-1,-1,11:99.10
0,-1,11:99.10
1,-1,11:99.10
2,-1,11:99.10
3,-1,11:99.10
-4,0,11:100.4
-3,0,11:99.10
-2,0,11:99.10
-1,0,11:99.10
0,0,11:99.10
1,0,11:99.10
2,0,11:99.10
3,0,11:99.10
-4,1,11:100.7
-3,1,11:99.10
-2,1,11:99.10
-1,1,11:99.10
0,1,11:99.10
1,1,11:99.10
2,1,11:99.10
3,1,11:99.10
-3,2,11:100.7
-2,2,11:99.10
-1,2,11:99.10
0,2,11:99.10
1,2,11:99.10
2,2,11:99.10
-2,3,11:99.10
-1,3,11:100.8
0,3,11:100.8
1,3,11:100.9
-2,-4,12:99.10
-1,-4,12:99.10
0,-4,12:100.2
1,-4,12:100.3
-3,-3,12:99.10
-2,-3,12:99.10
-1,-3,12:99.10
0,-3,12:99.10
1,-3,12:99.10
2,-3,12:100.3
-4,-2,12:99.10
-3,-2,12:99.10
-2,-2,12:99.10
-1,-2,12:99.10
0,-2,12:99.10
1,-2,12:99.10
2,-2,12:99.10
3,-2,12:100.3
-4,-1,12:99.10
-3,-1,12:99.10
-2,-1,12:99.10
-1,-1,12:99.10
0,-1,12:99.10
1,-1,12:99.10
2,-1,12:99.10
3,-1,12:99.10
-4,0,12:100.4
-3,0,12:99.10
-2,0,12:99.10
-1,0,12:99.10
0,0,12:99.10
1,0,12:99.10
2,0,12:99.10
3,0,12:99.10
-4,1,12:100.7
-3,1,12:99.10
-2,1,12:99.10
-1,1,12:99.10
0,1,12:99.10
1,1,12:99.10
2,1,12:99.10
3,1,12:99.10
-3,2,12:100.7
-2,2,12:99.10
-1,2,12:99.10
0,2,12:99.10
1,2,12:99.10
2,2,12:99.10
-2,3,12:100.7
-1,3,12:100.8
0,3,12:100.8
1,3,12:100.9
-2,-3,13:99.10
-1,-3,13:99.10
0,-3,13:100.2
1,-3,13:100.3
-3,-2,13:99.10
-2,-2,13:99.10
-1,-2,13:99.10
0,-2,13:99.10
1,-2,13:99.10
2,-2,13:100.3
-3,-1,13:99.10
-2,-1,13:99.10
-1,-1,13:99.10
0,-1,13:99.10
1,-1,13:99.10
2,-1,13:100.6
-3,0,13:100.4
-2,0,13:99.10
-1,0,13:99.10
0,0,13:99.10
1,0,13:99.10
2,0,13:99.10
-3,1,13:100.7
-2,1,13:99.10
-1,1,13:99.10
0,1,13:99.10
1,1,13:99.10
2,1,13:99.10
-2,2,13:100.7
-1,2,13:100.8
0,2,13:100.8
1,2,13:100.9
-2,-2,14:99.10
-1,-2,14:100.2
0,-2,14:100.2
1,-2,14:100.3
-2,-1,14:100.4
-1,-1,14:99.10
0,-1,14:99.10
1,-1,14:100.6
-2,0,14:100.4
-1,0,14:99.10
0,0,14:99.10
1,0,14:100.6
-2,1,14:100.7
-1,1,14:100.8
0,1,14:100.8
1,1,14:100.9
-1,-1,15:100.1
0,-1,15:100.3
-1,0,15:100.7
0,0,15:100.9
2,0,0:40.0
-3,0,0:40.0
2,-1,0:40.0
-3,-1,0:40.0
0,-3,0:40.0
-1,-3,0:40.0
