[META]
version=2.0
spawnOnBlockType=3,2
spawnSunlight=True
spawnDarkness=True
spawnWater=False
spawnLava=False
underFill=False
randomRotation=False
dig=True
tree=False
branch=False
needsFoundation=True
rarity=50
collisionPercentage=10
spawnElevationMin=0
spawnElevationMax=240
spawnInBiome=Mystic,MushroomIsland
spawnAboveGround=False
spawnUnderGround=False
collisionBlockType=All
groupId=
diggingBranch=false
branchLimit=6
groupFrequencyMin=1
groupFrequencyMax=5
groupSeperationMin=0
groupSeperationMax=5
[DATA]
0,-2,-6:1.0
1,-2,-6:1.0
1,-1,-6:1.0
0,-2,-5:88.0
1,-2,-5:1.0
0,-1,-5:88.0
1,-1,-5:1.0
0,-3,-4:88.0
1,-3,-4:88.0
-1,-2,-4:88.0
0,-2,-4:1.0
1,-2,-4:1.0
2,-2,-4:88.0
-1,-1,-4:88.0
0,-1,-4:1.0
1,-1,-4:88.0
2,-1,-4:88.0
0,0,-4:88.0
1,0,-4:88.0
0,-3,-3:3.0
1,-3,-3:3.0
-1,-2,-3:1.0
0,-2,-3:1.0
1,-2,-3:3.0
2,-2,-3:88.0
-1,-1,-3:3.0
0,-1,-3:1.0
1,-1,-3:3.0
2,-1,-3:88.0
0,0,-3:88.0
1,0,-3:88.0
0,-4,-2:88.0
1,-4,-2:88.0
-1,-3,-2:88.0
0,-3,-2:3.0
1,-3,-2:88.0
2,-3,-2:88.0
-2,-2,-2:88.0
-1,-2,-2:88.0
0,-2,-2:88.0
1,-2,-2:88.0
2,-2,-2:88.0
3,-2,-2:88.0
-2,-1,-2:88.0
-1,-1,-2:88.0
0,-1,-2:88.0
1,-1,-2:88.0
2,-1,-2:88.0
3,-1,-2:88.0
-1,0,-2:88.0
0,0,-2:88.0
1,0,-2:88.0
2,0,-2:88.0
0,1,-2:88.0
1,1,-2:88.0
0,-4,-1:110.0
1,-4,-1:110.0
-1,-3,-1:110.0
0,-3,-1:3.0
1,-3,-1:3.0
2,-3,-1:110.0
-2,-2,-1:110.0
-1,-2,-1:3.0
0,-2,-1:3.0
1,-2,-1:3.0
2,-2,-1:3.0
3,-2,-1:110.0
-2,-1,-1:110.0
-1,-1,-1:3.0
0,-1,-1:3.0
1,-1,-1:3.0
2,-1,-1:3.0
3,-1,-1:110.0
-1,0,-1:110.0
0,0,-1:3.0
1,0,-1:3.0
2,0,-1:110.0
0,1,-1:110.0
1,1,-1:110.0
0,-3,0:99.10
1,-3,0:99.10
-1,-2,0:99.10
0,-2,0:99.10
1,-2,0:99.10
2,-2,0:99.10
-1,-1,0:99.10
0,-1,0:99.10
1,-1,0:99.10
2,-1,0:99.10
0,0,0:99.10
1,0,0:99.10
0,-3,1:99.10
1,-3,1:99.10
-1,-2,1:99.10
0,-2,1:99.10
1,-2,1:99.10
2,-2,1:99.10
-1,-1,1:99.10
0,-1,1:99.10
1,-1,1:99.10
2,-1,1:99.10
0,0,1:99.10
1,0,1:99.10
0,-3,2:99.10
1,-3,2:99.10
-1,-2,2:99.10
0,-2,2:99.10
1,-2,2:99.10
2,-2,2:99.10
-1,-1,2:99.10
0,-1,2:99.10
1,-1,2:99.10
2,-1,2:99.10
0,0,2:99.10
1,0,2:99.10
0,-3,3:99.10
1,-3,3:99.10
-1,-2,3:99.10
0,-2,3:99.10
1,-2,3:99.10
2,-2,3:99.10
-1,-1,3:99.10
0,-1,3:99.10
1,-1,3:99.10
2,-1,3:99.10
0,0,3:99.10
1,0,3:99.10
0,-3,4:99.10
1,-3,4:99.10
-1,-2,4:99.10
0,-2,4:99.10
1,-2,4:99.10
2,-2,4:99.10
-1,-1,4:99.10
0,-1,4:99.10
1,-1,4:99.10
2,-1,4:99.10
0,0,4:99.10
1,0,4:99.10
-1,-5,5:99.10
0,-5,5:99.10
1,-5,5:99.10
2,-5,5:99.10
-2,-4,5:99.10
-1,-4,5:99.10
0,-4,5:99.10
1,-4,5:99.10
2,-4,5:99.10
3,-4,5:99.10
-3,-3,5:99.10
-2,-3,5:99.10
-1,-3,5:99.10
0,-3,5:99.10
1,-3,5:99.10
2,-3,5:99.10
3,-3,5:99.10
4,-3,5:99.10
-3,-2,5:99.10
-2,-2,5:99.10
-1,-2,5:99.10
0,-2,5:99.10
1,-2,5:99.10
2,-2,5:99.10
3,-2,5:99.10
4,-2,5:99.10
-3,-1,5:99.10
-2,-1,5:99.10
-1,-1,5:99.10
0,-1,5:99.10
1,-1,5:99.10
2,-1,5:99.10
3,-1,5:99.10
4,-1,5:99.10
-3,0,5:99.10
-2,0,5:99.10
-1,0,5:99.10
0,0,5:99.10
1,0,5:99.10
2,0,5:99.10
3,0,5:99.10
-2,1,5:99.10
-1,1,5:99.10
0,1,5:99.10
1,1,5:99.10
2,1,5:99.10
-1,2,5:99.10
0,2,5:99.10
1,2,5:99.10
2,2,5:99.10
-1,-6,6:99.10
0,-6,6:99.10
1,-6,6:99.10
2,-6,6:99.10
-2,-5,6:99.10
-1,-5,6:99.10
0,-5,6:99.10
1,-5,6:99.10
2,-5,6:99.10
3,-5,6:99.10
-3,-4,6:99.10
-2,-4,6:99.10
-1,-4,6:99.10
0,-4,6:99.10
1,-4,6:99.10
2,-4,6:99.10
3,-4,6:99.10
4,-4,6:99.10
-4,-3,6:99.10
-3,-3,6:99.10
-2,-3,6:99.10
-1,-3,6:99.10
0,-3,6:99.10
1,-3,6:99.10
2,-3,6:99.10
3,-3,6:99.10
4,-3,6:99.10
5,-3,6:99.10
-4,-2,6:99.10
-3,-2,6:99.10
-2,-2,6:99.10
-1,-2,6:99.10
0,-2,6:99.10
1,-2,6:99.10
2,-2,6:99.10
3,-2,6:99.10
4,-2,6:99.10
5,-2,6:99.10
-4,-1,6:99.10
-3,-1,6:99.10
-2,-1,6:99.10
-1,-1,6:99.10
0,-1,6:99.10
1,-1,6:99.10
2,-1,6:99.10
3,-1,6:99.10
4,-1,6:99.10
5,-1,6:99.10
-4,0,6:99.10
-3,0,6:99.10
-2,0,6:99.10
-1,0,6:99.10
0,0,6:99.10
1,0,6:99.10
2,0,6:99.10
3,0,6:99.10
4,0,6:99.10
5,0,6:99.10
-3,1,6:99.10
-2,1,6:99.10
-1,1,6:99.10
0,1,6:99.10
1,1,6:99.10
2,1,6:99.10
3,1,6:99.10
4,1,6:99.10
-2,2,6:99.10
-1,2,6:99.10
0,2,6:99.10
1,2,6:99.10
2,2,6:99.10
3,2,6:99.10
-1,3,6:99.10
0,3,6:99.10
1,3,6:99.10
2,3,6:99.10
-1,-6,7:99.10
0,-6,7:99.10
1,-6,7:99.10
2,-6,7:99.10
-2,-5,7:99.10
-1,-5,7:99.10
0,-5,7:99.10
1,-5,7:99.10
2,-5,7:99.10
3,-5,7:99.10
-3,-4,7:99.10
-2,-4,7:99.10
-1,-4,7:99.10
0,-4,7:99.10
1,-4,7:99.10
2,-4,7:99.10
3,-4,7:99.10
4,-4,7:99.10
-4,-3,7:99.10
-3,-3,7:99.10
-2,-3,7:99.10
-1,-3,7:99.10
0,-3,7:99.10
1,-3,7:99.10
2,-3,7:99.10
3,-3,7:99.10
4,-3,7:99.10
5,-3,7:99.10
-4,-2,7:99.10
-3,-2,7:99.10
-2,-2,7:99.10
-1,-2,7:99.10
0,-2,7:99.10
1,-2,7:99.10
2,-2,7:99.10
3,-2,7:99.10
4,-2,7:99.10
5,-2,7:99.10
-4,-1,7:99.10
-3,-1,7:99.10
-2,-1,7:99.10
-1,-1,7:99.10
0,-1,7:99.10
1,-1,7:99.10
2,-1,7:99.10
3,-1,7:99.10
4,-1,7:99.10
5,-1,7:99.10
-4,0,7:99.10
-3,0,7:99.10
-2,0,7:99.10
-1,0,7:99.10
0,0,7:99.10
1,0,7:99.10
2,0,7:99.10
3,0,7:99.10
4,0,7:99.10
5,0,7:99.10
-3,1,7:99.10
-2,1,7:99.10
-1,1,7:99.10
0,1,7:99.10
1,1,7:99.10
2,1,7:99.10
3,1,7:99.10
4,1,7:99.10
-2,2,7:99.10
-1,2,7:99.10
0,2,7:99.10
1,2,7:99.10
2,2,7:99.10
3,2,7:99.10
-1,3,7:99.10
0,3,7:99.10
1,3,7:99.10
2,3,7:99.10
-1,-6,8:99.10
0,-6,8:99.10
1,-6,8:99.10
2,-6,8:99.10
-2,-5,8:99.10
-1,-5,8:99.10
0,-5,8:99.10
1,-5,8:99.10
2,-5,8:99.10
3,-5,8:99.10
-3,-4,8:99.10
-2,-4,8:99.10
-1,-4,8:99.10
0,-4,8:99.10
1,-4,8:99.10
2,-4,8:99.10
3,-4,8:99.10
4,-4,8:99.10
-4,-3,8:99.10
-3,-3,8:99.10
-2,-3,8:99.10
-1,-3,8:99.10
0,-3,8:99.10
1,-3,8:99.10
2,-3,8:99.10
3,-3,8:99.10
4,-3,8:99.10
5,-3,8:99.10
-4,-2,8:99.10
-3,-2,8:99.10
-2,-2,8:99.10
-1,-2,8:99.10
0,-2,8:99.10
1,-2,8:99.10
2,-2,8:99.10
3,-2,8:99.10
4,-2,8:99.10
5,-2,8:99.10
-4,-1,8:99.10
-3,-1,8:99.10
-2,-1,8:99.10
-1,-1,8:99.10
0,-1,8:99.10
1,-1,8:99.10
2,-1,8:99.10
3,-1,8:99.10
4,-1,8:99.10
5,-1,8:99.10
-4,0,8:99.10
-3,0,8:99.10
-2,0,8:99.10
-1,0,8:99.10
0,0,8:99.10
1,0,8:99.10
2,0,8:99.10
3,0,8:99.10
4,0,8:99.10
5,0,8:99.10
-3,1,8:99.10
-2,1,8:99.10
-1,1,8:99.10
0,1,8:99.10
1,1,8:99.10
2,1,8:99.10
3,1,8:99.10
4,1,8:99.10
-2,2,8:99.10
-1,2,8:99.10
0,2,8:99.10
1,2,8:99.10
2,2,8:99.10
3,2,8:99.10
-1,3,8:99.10
0,3,8:99.10
1,3,8:99.10
2,3,8:99.10
-1,-5,9:99.10
0,-5,9:99.10
1,-5,9:99.10
2,-5,9:99.10
-2,-4,9:99.10
-1,-4,9:99.10
0,-4,9:99.10
1,-4,9:99.10
2,-4,9:99.10
3,-4,9:99.10
-3,-3,9:99.10
-2,-3,9:99.10
-1,-3,9:99.10
0,-3,9:99.10
1,-3,9:99.10
2,-3,9:99.10
3,-3,9:99.10
4,-3,9:99.10
-3,-2,9:99.10
-2,-2,9:99.10
-1,-2,9:99.10
0,-2,9:99.10
1,-2,9:99.10
2,-2,9:99.10
3,-2,9:99.10
4,-2,9:99.10
-3,-1,9:99.10
-2,-1,9:99.10
-1,-1,9:99.10
0,-1,9:99.10
1,-1,9:99.10
2,-1,9:99.10
3,-1,9:99.10
4,-1,9:99.10
-3,0,9:99.10
-2,0,9:99.10
-1,0,9:99.10
0,0,9:99.10
1,0,9:99.10
2,0,9:99.10
3,0,9:99.10
4,0,9:99.10
-2,1,9:99.10
-1,1,9:99.10
0,1,9:99.10
1,1,9:99.10
2,1,9:99.10
3,1,9:99.10
-1,2,9:99.10
0,2,9:99.10
1,2,9:99.10
2,2,9:99.10
-1,-5,10:99.10
0,-5,10:99.10
1,-5,10:99.10
2,-5,10:99.10
-2,-4,10:99.10
-1,-4,10:99.10
0,-4,10:99.10
1,-4,10:99.10
2,-4,10:99.10
3,-4,10:99.10
-3,-3,10:99.10
-2,-3,10:99.10
-1,-3,10:99.10
0,-3,10:99.10
1,-3,10:99.10
2,-3,10:99.10
3,-3,10:99.10
4,-3,10:99.10
-3,-2,10:99.10
-2,-2,10:99.10
-1,-2,10:99.10
0,-2,10:99.10
1,-2,10:99.10
2,-2,10:99.10
3,-2,10:99.10
4,-2,10:99.10
-3,-1,10:99.10
-2,-1,10:99.10
-1,-1,10:99.10
0,-1,10:99.10
1,-1,10:99.10
2,-1,10:99.10
3,-1,10:99.10
4,-1,10:99.10
-3,0,10:99.10
-2,0,10:99.10
-1,0,10:99.10
0,0,10:99.10
1,0,10:99.10
2,0,10:99.10
3,0,10:99.10
4,0,10:99.10
-2,1,10:99.10
-1,1,10:99.10
0,1,10:99.10
1,1,10:99.10
2,1,10:99.10
3,1,10:99.10
-1,2,10:99.10
0,2,10:99.10
1,2,10:99.10
2,2,10:99.10
-1,-4,11:99.10
0,-4,11:99.10
1,-4,11:99.10
2,-4,11:99.10
-2,-3,11:99.10
-1,-3,11:99.10
0,-3,11:99.10
1,-3,11:99.10
2,-3,11:99.10
3,-3,11:99.10
-2,-2,11:99.10
-1,-2,11:99.10
0,-2,11:99.10
1,-2,11:99.10
2,-2,11:99.10
3,-2,11:99.10
-2,-1,11:99.10
-1,-1,11:99.10
0,-1,11:99.10
1,-1,11:99.10
2,-1,11:99.10
3,-1,11:99.10
-2,0,11:99.10
-1,0,11:99.10
0,0,11:99.10
1,0,11:99.10
2,0,11:99.10
3,0,11:99.10
-1,1,11:99.10
0,1,11:99.10
1,1,11:99.10
2,1,11:99.10
-1,-3,12:99.10
0,-3,12:99.10
1,-3,12:99.10
2,-3,12:99.10
-1,-2,12:99.10
0,-2,12:99.10
1,-2,12:99.10
2,-2,12:99.10
-1,-1,12:99.10
0,-1,12:99.10
1,-1,12:99.10
2,-1,12:99.10
-1,0,12:99.10
0,0,12:99.10
1,0,12:99.10
2,0,12:99.10
0,-2,13:99.10
1,-2,13:99.10
0,-1,13:99.10
1,-1,13:99.10
1,1,0:40.0
2,0,0:40.0
3,-2,0:40.0
-1,-3,0:40.0
1,-4,0:40.0
0,-4,0:40.0
