[META]
version=2.0
spawnOnBlockType=3,2
spawnSunlight=True
spawnDarkness=True
spawnWater=False
spawnLava=False
underFill=False
randomRotation=False
dig=True
tree=False
branch=False
needsFoundation=True
rarity=30
collisionPercentage=20
spawnElevationMin=0
spawnElevationMax=240
spawnInBiome=Mystic,MushroomIsland
spawnAboveGround=False
spawnUnderGround=False
collisionBlockType=All
groupId=
diggingBranch=false
branchLimit=6
groupFrequencyMin=1
groupFrequencyMax=5
groupSeperationMin=0
groupSeperationMax=5
[DATA]
-1,-1,-3:3.0
0,-1,-3:99.10
-1,0,-3:3.0
0,0,-3:3.0
-2,-2,-2:3.0
-1,-2,-2:3.0
0,-2,-2:3.0
-2,-1,-2:3.0
-1,-1,-2:3.0
0,-1,-2:99.10
1,-1,-2:3.0
-2,0,-2:3.0
-1,0,-2:3.0
0,0,-2:3.0
1,0,-2:3.0
-1,1,-2:3.0
0,1,-2:3.0
1,1,-2:3.0
-2,-3,-1:110.0
-1,-3,-1:110.0
0,-3,-1:110.0
-3,-2,-1:110.0
-2,-2,-1:110.0
-1,-2,-1:3.0
0,-2,-1:3.0
1,-2,-1:110.0
2,-2,-1:110.0
-3,-1,-1:110.0
-2,-1,-1:3.0
-1,-1,-1:99.10
0,-1,-1:99.10
1,-1,-1:110.0
-3,0,-1:110.0
-2,0,-1:3.0
-1,0,-1:3.0
0,0,-1:99.10
1,0,-1:3.0
2,0,-1:2.5
-2,1,-1:110.0
-1,1,-1:3.0
0,1,-1:3.0
1,1,-1:110.0
-1,2,-1:110.0
0,2,-1:110.0
-1,-2,0:99.10
0,-2,0:99.10
-2,-1,0:99.10
-1,-1,0:99.10
0,-1,0:99.10
-2,0,0:99.10
-1,0,0:99.10
0,0,0:99.10
1,0,0:99.10
-1,1,0:99.10
0,1,0:99.10
-1,-2,1:99.10
-1,-1,1:99.10
0,-1,1:99.10
-2,0,1:99.10
-1,0,1:99.10
0,0,1:99.10
1,0,1:99.10
0,1,1:99.10
-1,-1,2:99.10
0,-1,2:99.10
-2,0,2:99.10
-1,0,2:99.10
0,0,2:99.10
-2,-3,3:100.1
-1,-3,3:100.3
0,-3,3:100.3
1,-3,3:100.3
-3,-2,3:100.1
2,-2,3:100.3
-3,-1,3:100.1
-1,-1,3:99.10
0,-1,3:99.10
2,-1,3:100.9
-3,0,3:100.1
-1,0,3:99.10
0,0,3:99.10
2,0,3:100.9
-3,1,3:100.7
2,1,3:100.9
-2,2,3:100.7
-1,2,3:100.7
0,2,3:100.7
1,2,3:100.9
-2,-3,4:100.1
-1,-3,4:100.3
0,-3,4:100.3
1,-3,4:100.3
-3,-2,4:100.1
2,-2,4:100.3
-3,-1,4:100.1
-1,-1,4:99.10
0,-1,4:99.10
2,-1,4:100.9
-3,0,4:100.1
-1,0,4:99.10
0,0,4:99.10
2,0,4:100.9
-3,1,4:100.7
2,1,4:100.9
-2,2,4:100.7
-1,2,4:100.7
0,2,4:100.7
1,2,4:100.9
-2,-3,5:100.1
-1,-3,5:100.1
0,-3,5:100.1
1,-3,5:100.3
-3,-2,5:100.1
-2,-2,5:100.1
-1,-2,5:89.0
0,-2,5:89.0
1,-2,5:100.3
2,-2,5:100.3
-3,-1,5:100.7
-2,-1,5:89.0
-1,-1,5:99.10
0,-1,5:99.10
1,-1,5:89.0
2,-1,5:100.3
-3,0,5:100.7
-2,0,5:89.0
-1,0,5:99.10
0,0,5:99.10
1,0,5:89.0
2,0,5:100.3
-3,1,5:100.7
-2,1,5:100.7
-1,1,5:89.0
0,1,5:89.0
1,1,5:100.9
2,1,5:100.9
-2,2,5:100.7
-1,2,5:100.9
0,2,5:100.9
1,2,5:100.9
-2,-2,6:100.1
-1,-2,6:100.3
0,-2,6:100.3
1,-2,6:100.3
-2,-1,6:100.1
-1,-1,6:100.1
0,-1,6:100.3
1,-1,6:100.9
-2,0,6:100.1
-1,0,6:100.7
0,0,6:100.9
1,0,6:100.9
-2,1,6:100.7
-1,1,6:100.7
0,1,6:100.7
1,1,6:100.9
-1,-1,7:100.1
0,-1,7:100.3
-1,0,7:100.7
0,0,7:100.9
