[META]
version=2.0
spawnOnBlockType=3,2
spawnSunlight=True
spawnDarkness=True
spawnWater=False
spawnLava=False
underFill=False
randomRotation=False
dig=True
tree=False
branch=False
needsFoundation=True
rarity=100
collisionPercentage=20
spawnElevationMin=0
spawnElevationMax=240
spawnInBiome=Mystic,MushroomIsland
spawnAboveGround=False
spawnUnderGround=False
collisionBlockType=All
groupId=
diggingBranch=false
branchLimit=6
groupFrequencyMin=1
groupFrequencyMax=5
groupSeperationMin=0
groupSeperationMax=5
[DATA]
-1,-1,-1:88.0
0,0,-1:88.0
1,1,-1:88.0
-1,-1,0:110.0
0,-1,0:110.0
-1,0,0:110.0
0,0,0:3.0
1,0,0:110.0
0,1,0:110.0
1,1,0:110.0
0,0,1:99.10
0,0,2:99.10
0,0,3:99.10
0,0,4:99.10
-1,-1,5:99.1
0,-1,5:99.2
1,-1,5:99.3
-1,0,5:99.4
0,0,5:99.10
1,0,5:99.6
-1,1,5:99.7
0,1,5:99.8
1,1,5:99.9
0,0,6:99.10
-1,-2,7:99.1
0,-2,7:99.2
1,-2,7:99.3
-2,-1,7:99.1
2,-1,7:99.3
-2,0,7:99.4
0,0,7:99.10
2,0,7:99.6
-2,1,7:99.7
2,1,7:99.9
-1,2,7:99.7
0,2,7:99.8
1,2,7:99.9
-1,-1,8:99.1
0,-1,8:99.2
1,-1,8:99.3
-1,0,8:99.4
0,0,8:99.5
1,0,8:99.6
-1,1,8:99.7
0,1,8:99.8
1,1,8:99.9
1,0,1:39.5
