[META]
version=2.0
spawnOnBlockType=3,2
spawnSunlight=True
spawnDarkness=True
spawnWater=False
spawnLava=False
underFill=False
randomRotation=False
dig=True
tree=False
branch=False
needsFoundation=True
rarity=50
collisionPercentage=10
spawnElevationMin=0
spawnElevationMax=240
spawnInBiome=Mystic,MushroomIsland
spawnAboveGround=False
spawnUnderGround=False
collisionBlockType=All
groupId=
diggingBranch=false
branchLimit=6
groupFrequencyMin=1
groupFrequencyMax=5
groupSeperationMin=0
groupSeperationMax=5
[DATA]
-3,-1,-3:88.5
-2,-1,-3:88.5
-3,0,-3:88.5
-2,0,-3:3.0
-3,-2,-2:88.5
-2,-2,-2:88.5
-4,-1,-2:88.5
-3,-1,-2:88.5
-2,-1,-2:88.5
-1,-1,-2:88.5
-4,0,-2:88.5
-3,0,-2:88.5
-2,0,-2:88.5
-1,0,-2:88.5
-3,1,-2:88.5
-2,1,-2:88.5
-3,-2,-1:110.5
-2,-2,-1:110.5
-4,-1,-1:110.5
-3,-1,-1:3.0
-2,-1,-1:3.0
-1,-1,-1:110.5
-4,0,-1:110.5
-3,0,-1:3.0
-2,0,-1:3.0
-1,0,-1:110.5
-3,1,-1:110.5
-2,1,-1:110.5
-3,-1,0:99.10
-2,-1,0:99.10
-3,0,0:99.10
-2,0,0:99.10
-3,-1,1:99.10
-2,-1,1:99.10
-3,0,1:99.10
-2,0,1:99.10
-3,-1,2:99.10
-2,-1,2:99.10
-3,0,2:99.10
-2,0,2:99.10
-3,-1,3:99.10
-2,-1,3:99.10
-3,0,3:99.10
-2,0,3:99.10
-3,-1,4:99.10
-2,-1,4:99.10
-3,0,4:99.10
-2,0,4:99.10
-3,-1,5:99.10
-2,-1,5:99.10
-3,0,5:99.10
-2,0,5:99.10
-3,-1,6:99.10
-2,-1,6:99.10
-3,0,6:99.10
-2,0,6:99.10
-3,-1,7:99.10
-2,-1,7:99.10
-3,0,7:99.10
-2,0,7:99.10
-2,-1,8:99.10
-1,-1,8:99.10
-2,0,8:99.10
-1,0,8:99.10
-2,-1,9:99.10
-1,-1,9:99.10
-2,0,9:99.10
-1,0,9:99.10
-1,-1,10:99.10
0,-1,10:99.10
-1,0,10:99.10
0,0,10:99.10
-2,-7,11:99.1
-1,-7,11:99.1
0,-7,11:99.1
1,-7,11:99.1
2,-7,11:99.3
-4,-6,11:99.1
-3,-6,11:99.1
-2,-6,11:99.1
2,-6,11:99.5
3,-6,11:99.3
4,-6,11:99.3
-5,-5,11:99.1
-4,-5,11:99.1
4,-5,11:99.6
5,-5,11:99.3
-6,-4,11:99.1
-5,-4,11:99.1
5,-4,11:99.6
6,-4,11:99.3
-6,-3,11:99.1
6,-3,11:99.3
-7,-2,11:99.1
-6,-2,11:99.1
6,-2,11:99.6
7,-2,11:99.3
-7,-1,11:99.1
-1,-1,11:99.10
0,-1,11:99.10
7,-1,11:99.3
-7,0,11:99.7
-1,0,11:99.10
0,0,11:99.10
7,0,11:99.9
-7,1,11:99.7
7,1,11:99.9
-7,2,11:99.7
-6,2,11:99.7
6,2,11:99.6
7,2,11:99.9
-6,3,11:99.7
6,3,11:99.9
-6,4,11:99.7
-5,4,11:99.7
5,4,11:99.6
6,4,11:99.9
-5,5,11:99.7
-4,5,11:99.7
4,5,11:99.6
5,5,11:99.9
-4,6,11:99.7
-3,6,11:99.7
-2,6,11:99.7
2,6,11:99.6
3,6,11:99.9
4,6,11:99.9
-2,7,11:99.7
-1,7,11:99.7
0,7,11:99.7
1,7,11:99.9
2,7,11:99.9
-2,-7,12:99.1
-1,-7,12:99.3
0,-7,12:99.3
1,-7,12:99.3
2,-7,12:99.3
-4,-6,12:99.1
-3,-6,12:99.1
-2,-6,12:99.1
-1,-6,12:99.1
0,-6,12:99.3
1,-6,12:99.3
2,-6,12:99.3
3,-6,12:99.3
4,-6,12:99.3
-5,-5,12:99.1
-4,-5,12:99.1
-3,-5,12:99.1
-2,-5,12:99.1
-1,-5,12:99.10
0,-5,12:99.10
1,-5,12:99.10
2,-5,12:99.3
3,-5,12:99.3
4,-5,12:99.3
5,-5,12:99.3
-6,-4,12:99.1
-5,-4,12:99.1
-4,-4,12:99.1
-3,-4,12:99.1
-2,-4,12:99.10
-1,-4,12:99.10
0,-4,12:99.10
1,-4,12:99.10
2,-4,12:99.10
3,-4,12:99.3
4,-4,12:99.3
5,-4,12:99.3
6,-4,12:99.3
-6,-3,12:99.1
-5,-3,12:99.1
-4,-3,12:99.1
-3,-3,12:99.10
-2,-3,12:99.10
-1,-3,12:99.10
0,-3,12:99.10
1,-3,12:99.10
2,-3,12:99.10
3,-3,12:99.10
4,-3,12:99.3
5,-3,12:99.3
6,-3,12:99.3
-7,-2,12:99.1
-6,-2,12:99.1
-5,-2,12:99.1
-4,-2,12:99.10
-3,-2,12:99.10
-2,-2,12:99.10
-1,-2,12:99.10
0,-2,12:99.10
1,-2,12:99.10
2,-2,12:99.10
3,-2,12:99.10
4,-2,12:99.10
5,-2,12:99.3
6,-2,12:99.3
7,-2,12:99.3
-7,-1,12:99.1
-6,-1,12:99.1
-5,-1,12:99.10
-4,-1,12:99.10
-3,-1,12:99.10
-2,-1,12:99.10
-1,-1,12:99.10
0,-1,12:99.10
1,-1,12:99.10
2,-1,12:99.10
3,-1,12:99.10
4,-1,12:99.10
5,-1,12:99.10
6,-1,12:99.3
7,-1,12:99.3
-7,0,12:99.7
-6,0,12:99.7
-5,0,12:99.10
-4,0,12:99.10
-3,0,12:99.10
-2,0,12:99.10
-1,0,12:99.10
0,0,12:99.10
1,0,12:99.10
2,0,12:99.10
3,0,12:99.10
4,0,12:99.10
5,0,12:99.10
6,0,12:99.3
7,0,12:99.9
-7,1,12:99.7
-6,1,12:99.7
-5,1,12:99.10
-4,1,12:99.10
-3,1,12:99.10
-2,1,12:99.10
-1,1,12:99.10
0,1,12:99.10
1,1,12:99.10
2,1,12:99.10
3,1,12:99.10
4,1,12:99.10
5,1,12:99.10
6,1,12:99.9
7,1,12:99.9
-7,2,12:99.7
-6,2,12:99.7
-5,2,12:99.7
-4,2,12:99.10
-3,2,12:99.10
-2,2,12:99.10
-1,2,12:99.10
0,2,12:99.10
1,2,12:99.10
2,2,12:99.10
3,2,12:99.10
4,2,12:99.10
5,2,12:99.9
6,2,12:99.9
7,2,12:99.9
-6,3,12:99.7
-5,3,12:99.7
-4,3,12:99.7
-3,3,12:99.10
-2,3,12:99.10
-1,3,12:99.10
0,3,12:99.10
1,3,12:99.10
2,3,12:99.10
3,3,12:99.10
4,3,12:99.9
5,3,12:99.9
6,3,12:99.9
-6,4,12:99.7
-5,4,12:99.7
-4,4,12:99.7
-3,4,12:99.7
-2,4,12:99.10
-1,4,12:99.10
0,4,12:99.10
1,4,12:99.10
2,4,12:99.10
3,4,12:99.9
4,4,12:99.9
5,4,12:99.9
6,4,12:99.9
-5,5,12:99.7
-4,5,12:99.7
-3,5,12:99.7
-2,5,12:99.7
-1,5,12:99.10
0,5,12:99.10
1,5,12:99.10
2,5,12:99.9
3,5,12:99.9
4,5,12:99.9
5,5,12:99.9
-4,6,12:99.7
-3,6,12:99.7
-2,6,12:99.7
-1,6,12:99.7
0,6,12:99.7
1,6,12:99.9
2,6,12:99.9
3,6,12:99.9
4,6,12:99.9
-2,7,12:99.7
-1,7,12:99.7
0,7,12:99.9
1,7,12:99.9
2,7,12:99.9
-1,-5,13:99.1
0,-5,13:99.3
1,-5,13:99.3
-2,-4,13:99.1
-1,-4,13:99.1
0,-4,13:99.1
1,-4,13:99.3
2,-4,13:99.3
-3,-3,13:99.1
-2,-3,13:99.1
-1,-3,13:99.1
0,-3,13:99.9
1,-3,13:99.3
2,-3,13:99.3
3,-3,13:99.3
-4,-2,13:99.1
-3,-2,13:99.1
-2,-2,13:99.1
-1,-2,13:99.10
0,-2,13:99.10
1,-2,13:99.10
2,-2,13:99.3
3,-2,13:99.3
4,-2,13:99.3
-5,-1,13:99.1
-4,-1,13:99.1
-3,-1,13:99.1
-2,-1,13:99.10
-1,-1,13:99.10
0,-1,13:99.10
1,-1,13:99.10
2,-1,13:99.10
3,-1,13:99.3
4,-1,13:99.3
5,-1,13:99.3
-5,0,13:99.7
-4,0,13:99.1
-3,0,13:99.10
-2,0,13:99.10
-1,0,13:99.10
0,0,13:99.10
1,0,13:99.10
2,0,13:99.10
3,0,13:99.10
4,0,13:99.3
5,0,13:99.3
-5,1,13:99.7
-4,1,13:99.7
-3,1,13:99.7
-2,1,13:99.10
-1,1,13:99.10
0,1,13:99.10
1,1,13:99.10
2,1,13:99.10
3,1,13:99.9
4,1,13:99.9
5,1,13:99.9
-4,2,13:99.7
-3,2,13:99.7
-2,2,13:99.7
-1,2,13:99.10
0,2,13:99.10
1,2,13:99.10
2,2,13:99.9
3,2,13:99.9
4,2,13:99.9
-3,3,13:99.7
-2,3,13:99.7
-1,3,13:99.7
0,3,13:99.10
1,3,13:99.9
2,3,13:99.9
3,3,13:99.9
-2,4,13:99.7
-1,4,13:99.7
0,4,13:99.7
1,4,13:99.9
2,4,13:99.9
-1,5,13:99.7
0,5,13:99.7
1,5,13:99.9
-1,-2,14:99.1
0,-2,14:99.1
1,-2,14:99.3
-2,-1,14:99.1
-1,-1,14:99.1
0,-1,14:99.1
1,-1,14:99.3
2,-1,14:99.3
-3,0,14:99.1
-2,0,14:99.1
-1,0,14:99.1
0,0,14:99.1
1,0,14:99.3
2,0,14:99.3
3,0,14:99.3
-3,1,14:99.7
-2,1,14:99.7
-1,1,14:99.7
0,1,14:99.9
1,1,14:99.9
2,1,14:99.9
3,1,14:99.9
-2,2,14:99.7
-1,2,14:99.7
0,2,14:99.9
1,2,14:99.9
2,2,14:99.9
-1,3,14:99.7
0,3,14:99.9
1,3,14:99.9
-1,0,0:39.5
-1,-1,0:39.0
-4,-1,0:39.5
-2,-2,0:39.0
-3,-2,0:39.5
