[META]
version=2.0
spawnOnBlockType=9
spawnSunlight=True
spawnDarkness=True
spawnWater=True
spawnLava=False
underFill=True
randomRotation=True
dig=True
tree=False
branch=False
needsFoundation=True
rarity=999
collisionPercentage=15
spawnElevationMin=55
spawnElevationMax=68
spawnInBiome=TropicalOcean
spawnAboveGround=False
spawnUnderGround=False
collisionBlockType=All
groupId=
diggingBranch=false
branchLimit=6
groupFrequencyMin=1
groupFrequencyMax=5
groupSeperationMin=0
groupSeperationMax=5
[DATA]
-3,-1,-29:12
-1,-1,-29:12
-2,0,-29:12
0,0,-29:12
1,0,-29:12
-1,-2,-29:12
0,-3,-29:12
1,-1,-29:106.1
-2,-1,-29:106.1
0,-4,-29:106.1
-3,-2,-29:106.1
-1,0,-29:106.4
-3,0,-29:106.4
0,-2,-29:12
0,-1,-29:12
1,-2,-29:106.2
2,0,-29:106.2
1,1,-29:106.2
1,-3,-29:106.2
-1,2,-29:106.4
-3,-1,-30:12
-2,-1,-30:12
-1,-1,-30:12
0,-1,-30:12
-2,0,-30:12
-1,0,-30:12
0,0,-30:12
1,0,-30:12
-1,-2,-30:12
0,-2,-30:12
-1,1,-30:12
1,-1,-30:12
0,1,-30:12
0,-3,-30:12
-2,1,-30:12
1,-2,-30:106.1
-3,-2,-30:106.1
0,-4,-30:106.1
-3,0,-30:106.4
2,0,-30:106.2
1,1,-30:106.2
1,-3,-30:106.2
-1,2,-30:106.4
1,-3,-27:106.2
1,-2,-27:106.2
2,0,-27:106.2
1,1,-27:106.2
-1,0,-27:106.4
-1,2,-27:106.4
-3,0,-27:106.4
-3,-2,-27:106.1
-2,-1,-27:106.1
0,-4,-27:106.1
1,-1,-27:106.1
1,-2,-28:106.2
2,0,-28:106.2
0,-4,-28:106.1
-1,0,-28:106.4
-3,0,-28:106.4
1,-1,-28:106.1
-3,-2,-28:106.1
-2,-1,-28:106.1
-1,2,-28:106.4
1,1,-28:106.2
1,-3,-28:106.2
