[META]
version=2.0
spawnOnBlockType=9
spawnSunlight=True
spawnDarkness=True
spawnWater=True
spawnLava=False
underFill=True
randomRotation=True
dig=True
tree=False
branch=False
needsFoundation=True
rarity=999
collisionPercentage=15
spawnElevationMin=59
spawnElevationMax=66
spawnInBiome=TropicalOcean2
spawnAboveGround=False
spawnUnderGround=False
collisionBlockType=All
groupId=
diggingBranch=false
branchLimit=6
groupFrequencyMin=1
groupFrequencyMax=5
groupSeperationMin=0
groupSeperationMax=5
[DATA]
0,-2,-6:83
-2,-1,-6:83
0,0,-6:83
1,1,-6:83
2,-1,-6:83
-2,-1,-7:83
0,-2,-7:83
0,0,-7:83
1,1,-7:83
2,-1,-7:83
0,-2,-8:12
0,-1,-8:12
0,0,-8:12
-2,-1,-8:12
-1,-1,-8:12
1,-1,-8:12
2,-1,-8:12
1,1,-8:12
-3,-1,-9:12
-2,-1,-9:12
-1,-1,-9:12
0,-1,-9:12
1,-1,-9:12
2,-1,-9:12
-2,-2,-9:12
-1,-2,-9:12
0,-2,-9:12
1,-2,-9:12
-2,0,-9:12
-1,0,-9:12
0,0,-9:12
1,0,-9:12
2,-2,-9:12
3,-2,-9:12
3,-1,-9:12
3,0,-9:12
2,0,-9:12
-1,1,-9:12
0,1,-9:12
1,1,-9:12
2,1,-9:12
1,2,-9:12
0,-3,-9:12
1,-3,-9:12
-1,-3,-9:12
0,-4,-10:12
1,-3,-10:12
2,-3,-10:12
3,-3,-10:12
3,-2,-10:12
3,-1,-10:12
4,-1,-10:12
4,0,-10:12
-4,-1,-10:12
-2,-3,-10:12
-1,-3,-10:12
-2,-2,-10:12
-2,-1,-10:12
-3,-1,-10:12
-3,0,-10:12
-3,-2,-10:12
-1,-2,-10:12
-1,-1,-10:12
-1,0,-10:12
-1,1,-10:12
-1,2,-10:12
0,2,-10:12
1,2,-10:12
2,2,-10:12
2,1,-10:12
3,1,-10:12
3,0,-10:12
2,-1,-10:12
2,-2,-10:12
0,-3,-10:12
0,-2,-10:12
0,-1,-10:12
1,-1,-10:12
1,0,-10:12
0,0,-10:12
0,1,-10:12
1,-2,-10:12
2,0,-10:12
1,1,-10:12
-2,1,-10:12
-2,0,-10:12
1,3,-10:12
