[META]
version=2.0
spawnOnBlockType=2
spawnSunlight=True
spawnDarkness=False
spawnWater=False
spawnLava=False
underFill=True
randomRotation=True
dig=True
tree=False
branch=False
needsFoundation=True
rarity=10
collisionPercentage=2
spawnElevationMin=0
spawnElevationMax=128
spawnInBiome=All
[DATA]
-4,0,0:17
-3,0,0:17
-4,1,0:17
-3,1,0:17
-4,0,1:17
-3,0,1:17
-4,1,1:17
-3,1,1:17
-3,0,2:17
-4,1,2:17
-2,2,2:17
-8,-6,3:18
-7,-5,3:18
-3,0,3:17
-4,1,3:17
-2,2,3:17
-6,-10,4:18
-6,-9,4:18
-8,-8,4:18
-6,-8,4:18
-2,-8,4:18
-8,-7,4:18
-6,-7,4:17
-5,-7,4:18
-3,-7,4:18
-9,-6,4:18
-6,-6,4:18
-5,-6,4:18
-2,-6,4:18
-9,-5,4:18
-4,-5,4:18
-9,-4,4:18
-5,-4,4:18
-4,0,4:17
-3,0,4:17
-4,1,4:17
-2,2,4:17
-7,-10,5:18
-2,-9,5:18
-8,-8,5:18
-7,-8,5:18
-2,-8,5:18
-5,-7,5:18
-3,-7,5:18
-1,-7,5:18
-7,-6,5:18
-6,-6,5:17
0,-6,5:18
-6,-5,5:17
-11,-4,5:18
-10,-4,5:18
-5,-2,5:17
-5,-1,5:17
-3,0,5:17
2,0,5:18
-5,1,5:17
3,1,5:18
-2,3,5:17
-2,4,5:17
-2,5,5:17
-6,9,5:18
-4,10,5:18
0,11,5:18
-5,12,5:18
-4,12,5:18
-2,12,5:18
2,12,5:18
-1,13,5:18
-4,14,5:18
0,-9,6:18
-6,-8,6:18
-3,-8,6:18
-2,-8,6:18
-1,-7,6:18
0,-7,6:18
-6,-6,6:18
-4,-6,6:18
-9,-5,6:18
-7,-5,6:18
-6,-5,6:18
-6,-4,6:17
-3,-4,6:18
-2,-4,6:18
-6,-3,6:17
2,-3,6:18
3,-3,6:18
-9,-2,6:18
-10,-1,6:18
-3,-1,6:17
-10,0,6:18
2,0,6:18
-11,1,6:18
-5,1,6:17
-2,2,6:17
3,2,6:18
-2,3,6:17
-8,6,6:18
-7,6,6:18
-2,6,6:17
-7,7,6:18
-2,7,6:17
-7,8,6:18
-5,8,6:18
-7,10,6:18
1,10,6:18
-4,11,6:18
-1,11,6:18
2,11,6:18
-6,12,6:18
-4,12,6:18
-3,12,6:18
-3,13,6:18
-2,13,6:18
-6,14,6:18
-4,14,6:18
-3,15,6:18
-1,-10,7:18
-4,-9,7:18
-3,-9,7:18
0,-9,7:18
-7,-8,7:18
-4,-8,7:18
-2,-8,7:18
0,-8,7:18
-6,-7,7:18
-5,-7,7:18
-4,-7,7:18
-3,-7,7:18
-1,-7,7:18
0,-7,7:18
-10,-6,7:18
-9,-6,7:18
-5,-6,7:18
-1,-6,7:18
-10,-5,7:18
-9,-5,7:18
-4,-5,7:18
-3,-5,7:18
-1,-5,7:18
-11,-4,7:18
-10,-4,7:18
-8,-4,7:18
-6,-4,7:18
-9,-3,7:18
-6,-3,7:18
4,-3,7:18
5,-3,7:18
2,-2,7:18
5,-2,7:18
6,-2,7:18
-11,-1,7:18
-3,-1,7:17
2,-1,7:18
3,-1,7:18
-9,0,7:18
1,0,7:18
2,0,7:18
3,0,7:17
4,0,7:17
-5,1,7:17
-1,1,7:17
0,1,7:17
1,1,7:18
2,1,7:18
-8,2,7:18
4,2,7:18
-10,3,7:18
-2,3,7:17
-8,6,7:18
-3,8,7:17
-7,9,7:18
-5,9,7:18
-3,9,7:17
-4,10,7:17
-3,10,7:18
-6,11,7:18
-5,11,7:18
-4,11,7:17
-1,11,7:18
0,11,7:18
3,11,7:18
-7,12,7:18
-5,12,7:18
-4,12,7:17
-2,12,7:18
0,12,7:18
-7,13,7:18
-5,13,7:18
0,13,7:18
-6,14,7:18
-3,14,7:18
-1,14,7:18
1,14,7:18
-2,15,7:18
-1,-9,8:18
0,-8,8:18
-2,-7,8:18
-1,-7,8:18
1,-7,8:18
-6,-6,8:18
-4,-6,8:18
-3,-5,8:18
-1,-5,8:18
-6,-4,8:18
-4,-4,8:18
0,-4,8:18
2,-4,8:18
4,-4,8:18
-12,-3,8:18
-10,-3,8:18
2,-3,8:18
3,-3,8:18
4,-3,8:18
2,-2,8:18
3,-2,8:18
4,-2,8:18
-10,-1,8:18
-8,-1,8:18
-3,-1,8:17
4,-1,8:18
1,0,8:17
2,0,8:17
4,0,8:18
-7,1,8:18
-6,1,8:17
-2,3,8:17
4,3,8:18
5,5,8:18
-8,6,8:18
-7,6,8:18
4,7,8:18
-10,8,8:18
-9,8,8:18
-8,8,8:18
-7,8,8:18
-6,8,8:18
-5,8,8:18
1,8,8:18
4,8,8:18
-6,9,8:18
1,9,8:18
-6,10,8:18
-5,10,8:18
-2,10,8:18
-3,11,8:18
-1,11,8:18
1,11,8:18
3,11,8:18
4,11,8:18
-5,12,8:18
-1,12,8:18
-3,13,8:18
-2,13,8:18
-1,13,8:18
0,13,8:18
1,13,8:18
-4,14,8:18
1,14,8:18
-3,15,8:18
-4,-9,9:18
0,-9,9:18
-4,-8,9:18
-9,-6,9:18
-6,-6,9:18
-2,-6,9:18
0,-6,9:18
-6,-5,9:18
0,-5,9:18
-6,-4,9:18
2,-4,9:18
3,-4,9:18
-9,-3,9:18
-7,-3,9:18
-1,-3,9:18
2,-3,9:18
-10,-2,9:18
-9,-2,9:18
4,-2,9:18
-10,-1,9:18
-9,-1,9:18
-3,-1,9:17
3,-1,9:18
-13,0,9:18
-11,0,9:18
4,0,9:18
-13,1,9:18
-11,1,9:18
-10,1,9:18
-6,1,9:17
-9,2,9:18
-7,2,9:18
4,2,9:18
-11,3,9:18
-10,3,9:18
-1,3,9:17
-10,4,9:18
4,4,9:18
-11,5,9:18
-11,6,9:18
-10,6,9:18
1,6,9:18
-9,7,9:18
-5,7,9:18
-10,8,9:18
-9,8,9:18
-8,8,9:18
-7,8,9:18
-5,8,9:18
-4,8,9:18
-2,8,9:18
1,8,9:18
-2,9,9:18
-1,9,9:18
-7,10,9:18
-3,10,9:18
-1,10,9:18
4,11,9:18
-6,12,9:18
-3,12,9:18
-4,13,9:18
-4,14,9:18
1,14,9:18
-2,-8,10:18
-7,-7,10:18
-6,-6,10:18
-9,-5,10:18
-4,-5,10:18
-9,-4,10:18
-6,-4,10:18
-5,-4,10:18
-4,-4,10:18
-9,-3,10:18
-7,-3,10:18
-6,-3,10:18
2,-3,10:18
-11,-2,10:18
-10,-2,10:18
-9,-2,10:18
-8,-2,10:18
-6,-2,10:18
-5,-2,10:18
-3,-2,10:17
1,-2,10:18
-10,-1,10:18
-5,-1,10:18
-13,0,10:18
1,0,10:18
4,0,10:18
5,0,10:18
-12,1,10:18
-11,1,10:18
-7,1,10:18
-6,1,10:17
3,1,10:18
-1,3,10:17
-10,4,10:18
-8,4,10:18
4,5,10:18
5,5,10:18
-10,8,10:18
-7,8,10:18
4,8,10:18
-2,9,10:18
1,9,10:18
2,9,10:18
5,9,10:18
1,10,10:18
2,10,10:18
3,10,10:18
-5,11,10:18
-3,11,10:18
-2,11,10:18
-4,12,10:18
1,12,10:18
-3,13,10:18
-8,-6,11:18
0,-6,11:18
-2,-5,11:18
-1,-5,11:18
-9,-4,11:18
-6,-4,11:18
-4,-3,11:18
-3,-3,11:18
2,-3,11:18
3,-3,11:18
-6,-2,11:18
-3,-2,11:17
3,-2,11:18
-11,0,11:18
0,0,11:18
2,0,11:18
-12,1,11:18
-8,1,11:18
-7,1,11:17
-1,1,11:18
2,1,11:18
-10,2,11:18
3,2,11:18
-12,3,11:18
-10,3,11:18
-1,3,11:17
3,3,11:18
-11,4,11:18
-11,6,11:18
-7,6,11:18
-2,6,11:18
-10,7,11:18
-11,8,11:18
-10,8,11:18
-5,8,11:18
0,8,11:18
5,8,11:18
-10,9,11:18
-8,9,11:18
-2,9,11:18
1,9,11:18
-3,10,11:18
-1,10,11:18
1,11,11:18
-7,-6,12:18
-6,-6,12:18
-2,-5,12:18
-4,-4,12:18
1,-3,12:18
2,-3,12:18
-8,-2,12:18
-3,-2,12:17
0,-2,12:18
1,-2,12:18
3,-2,12:18
2,-1,12:18
5,-1,12:18
0,0,12:18
1,0,12:18
-10,1,12:18
-9,1,12:18
-7,1,12:17
5,1,12:18
-10,2,12:18
2,2,12:18
3,2,12:18
4,2,12:18
-1,3,12:17
2,3,12:18
-11,5,12:18
-10,6,12:18
-2,6,12:18
-8,7,12:18
-7,7,12:18
4,7,12:18
-8,8,12:18
-1,8,12:18
5,8,12:18
-10,9,12:18
-2,9,12:18
0,9,12:18
-5,10,12:18
-2,10,12:18
-1,10,12:18
0,10,12:18
-3,11,12:18
-2,11,12:18
-3,12,12:18
-3,-6,13:18
-6,-5,13:18
-3,-5,13:18
-1,-5,13:18
0,-5,13:18
-7,-4,13:18
-3,-4,13:18
2,-4,13:18
3,-3,13:18
-3,-2,13:17
-2,-2,13:18
2,-2,13:18
4,-2,13:18
2,-1,13:18
2,0,13:18
3,0,13:18
5,0,13:18
-12,1,13:18
-11,1,13:18
-8,1,13:18
-7,1,13:17
-12,2,13:18
-7,2,13:18
1,2,13:18
3,2,13:18
-10,3,13:18
-1,4,13:17
-11,5,13:18
-10,5,13:18
-9,6,13:18
-8,6,13:18
4,6,13:18
-10,7,13:18
-4,7,13:18
-1,7,13:18
-10,8,13:18
-8,8,13:18
1,8,13:18
-4,9,13:18
-1,9,13:18
0,-8,14:18
-2,-6,14:18
0,-5,14:18
1,-5,14:18
2,-5,14:18
-9,-4,14:18
-5,-4,14:18
-3,-4,14:18
-2,-4,14:18
-1,-4,14:18
1,-4,14:18
-3,-3,14:17
1,-3,14:18
-7,-2,14:18
-3,-2,14:18
-1,-2,14:18
-10,0,14:18
-6,0,14:18
3,0,14:18
-8,1,14:17
0,1,14:18
2,1,14:18
-13,2,14:18
-10,2,14:18
1,2,14:18
-13,3,14:18
-11,3,14:18
-10,3,14:18
-7,3,14:18
-12,4,14:18
-10,4,14:18
-9,4,14:18
-7,4,14:18
-1,4,14:17
-10,5,14:18
-9,5,14:18
-11,6,14:18
-10,6,14:18
-11,7,14:18
-9,7,14:18
-4,7,14:18
0,7,14:18
-9,8,14:18
-2,8,14:18
-7,9,14:18
-3,9,14:18
0,9,14:18
-8,10,14:18
-7,10,14:18
-2,11,14:18
-2,-8,15:18
-4,-6,15:18
2,-6,15:18
-7,-5,15:18
-5,-5,15:18
2,-5,15:18
-3,-4,15:18
2,-4,15:18
-3,-3,15:17
0,-3,15:18
-10,-2,15:18
-8,-2,15:18
-7,-2,15:18
-5,-2,15:18
-7,-1,15:18
-5,-1,15:18
-1,-1,15:18
2,-1,15:18
3,-1,15:18
-8,0,15:18
-7,0,15:18
2,0,15:18
-8,1,15:17
2,2,15:18
4,2,15:18
-10,3,15:18
-7,3,15:18
-1,4,15:17
0,4,15:18
3,4,15:18
-8,5,15:18
-6,5,15:18
0,5,15:18
4,5,15:18
-8,6,15:18
-11,7,15:18
-10,7,15:18
-8,7,15:18
-7,7,15:18
-6,7,15:18
-10,8,15:18
-10,9,15:18
-8,10,15:18
-7,10,15:18
-3,-8,16:18
1,-7,16:18
-7,-5,16:18
-8,-4,16:18
-5,-4,16:18
0,-4,16:18
-8,-3,16:18
-3,-3,16:17
-2,-3,16:18
-9,-2,16:18
-8,-2,16:18
-7,-2,16:18
-4,-2,16:18
0,-2,16:18
-11,-1,16:18
-5,-1,16:18
-2,-1,16:18
-6,0,16:18
-5,0,16:18
-8,1,16:17
-12,2,16:18
-9,2,16:18
2,2,16:18
4,2,16:18
-8,3,16:18
-10,4,16:18
-1,4,16:17
1,4,16:18
2,4,16:18
-6,5,16:18
-1,5,16:18
3,5,16:18
-9,7,16:18
-6,7,16:18
2,7,16:18
-10,8,16:18
-8,9,16:18
-3,-7,17:18
-3,-6,17:18
-2,-6,17:18
0,-6,17:18
-7,-5,17:18
-6,-5,17:18
-5,-5,17:18
-4,-5,17:18
-3,-5,17:18
-1,-5,17:18
-5,-4,17:18
-4,-4,17:18
-2,-4,17:18
-1,-4,17:18
0,-4,17:18
-8,-3,17:18
-7,-3,17:18
-6,-3,17:18
-5,-3,17:18
-4,-3,17:18
-3,-3,17:17
-1,-3,17:18
-10,-2,17:18
-9,-2,17:18
-8,-2,17:18
-2,-2,17:18
0,-2,17:18
-9,-1,17:18
-7,-1,17:18
-5,-1,17:18
-3,-1,17:18
-2,-1,17:18
-10,0,17:18
-9,0,17:18
-7,0,17:18
-6,0,17:18
-5,0,17:18
-11,1,17:18
-9,1,17:17
0,2,17:18
1,2,17:18
-11,3,17:18
-10,3,17:18
-9,3,17:18
-1,3,17:18
1,3,17:18
2,3,17:18
-1,4,17:18
0,4,17:17
4,4,17:18
-6,5,17:18
1,5,17:18
2,5,17:18
-8,6,17:18
0,6,17:18
1,6,17:18
3,6,17:18
-8,7,17:18
-7,7,17:18
-5,7,17:18
-4,7,17:18
-3,9,17:18
-3,-7,18:18
-1,-7,18:18
-4,-6,18:18
-3,-5,18:18
-1,-5,18:18
0,-4,18:18
-9,-3,18:18
-5,-3,18:18
-3,-3,18:18
-9,-2,18:18
-5,-2,18:18
-4,-2,18:18
-1,-2,18:18
-5,-1,18:18
-3,-1,18:18
-12,0,18:18
-11,0,18:18
-9,0,18:18
-8,0,18:18
-7,0,18:18
-6,0,18:18
-5,0,18:18
-4,0,18:18
-9,1,18:17
-7,1,18:18
-6,1,18:18
-11,2,18:18
-10,2,18:18
1,2,18:18
-5,3,18:18
-4,3,18:18
0,3,18:18
1,3,18:18
4,3,18:18
-4,4,18:18
-2,4,18:18
-1,4,18:18
0,4,18:17
5,4,18:18
-6,5,18:18
2,5,18:18
4,5,18:18
-6,6,18:18
-4,6,18:18
-1,6,18:18
0,6,18:18
2,6,18:18
-9,7,18:18
-5,7,18:18
2,7,18:18
3,7,18:18
-8,8,18:18
-5,8,18:18
-2,8,18:18
-4,9,18:18
-3,9,18:18
-4,-6,19:18
-5,-5,19:18
-3,-5,19:18
-3,-4,19:18
-10,-3,19:18
-7,-3,19:18
-2,-3,19:18
-1,-3,19:18
-9,-2,19:18
-1,-2,19:18
-3,-1,19:18
-12,0,19:18
-9,0,19:18
-8,0,19:18
-7,0,19:18
-12,1,19:18
-9,1,19:17
-8,1,19:18
-7,1,19:18
-4,1,19:18
-1,1,19:18
-10,3,19:18
-3,3,19:18
3,3,19:18
-8,4,19:18
-5,4,19:18
-4,4,19:18
-2,4,19:18
0,4,19:17
1,4,19:18
3,4,19:18
-7,5,19:18
-2,5,19:18
-1,5,19:18
3,5,19:18
-6,6,19:18
-5,6,19:18
3,6,19:18
-5,7,19:18
-4,7,19:18
-4,9,19:18
-4,-5,20:18
-4,-4,20:18
-2,-4,20:18
-7,-1,20:18
-9,0,20:18
-7,0,20:18
-10,1,20:18
-8,1,20:18
-1,1,20:18
-6,2,20:18
-2,2,20:18
1,2,20:18
-8,3,20:18
-7,3,20:18
-1,3,20:18
-2,4,20:18
0,4,20:17
2,4,20:18
-2,5,20:18
-1,5,20:18
1,5,20:18
2,5,20:18
4,5,20:18
-8,6,20:18
0,6,20:18
1,7,20:18
-6,8,20:18
-3,9,20:18
-9,0,21:18
-4,0,21:18
-10,1,21:18
-8,1,21:18
-7,1,21:18
-4,1,21:18
-10,2,21:18
-7,2,21:18
-6,2,21:18
-4,2,21:18
-3,2,21:18
-10,3,21:18
-7,3,21:18
-6,3,21:18
-5,3,21:18
-4,3,21:18
-3,3,21:18
0,3,21:18
-3,4,21:18
-2,4,21:18
0,4,21:18
2,4,21:18
-6,5,21:18
3,5,21:18
-4,6,21:18
-8,0,22:18
-9,2,22:18
-8,2,22:18
-3,2,22:18
-2,2,22:18
-4,3,22:18
0,3,22:18
-7,4,22:18
-4,4,22:18
0,4,22:18
-4,5,22:18
0,5,22:18
-5,6,22:18
-6,7,22:18
-5,7,22:18
-5,8,22:18
-4,2,23:18
-4,3,23:18
-3,3,23:18
-2,4,23:18
-4,2,24:18
