[META]
version=2.0
spawnOnBlockType=2
spawnSunlight=True
spawnDarkness=False
spawnWater=False
spawnLava=False
underFill=True
randomRotation=True
dig=True
tree=False
branch=False
needsFoundation=True
rarity=10
collisionPercentage=2
spawnElevationMin=0
spawnElevationMax=128
spawnInBiome=All
[DATA]
0,-2,0:17.2
-1,-4,1:18
0,-3,1:85
1,-3,1:18
0,-2,1:17.2
1,-2,1:18
0,-4,2:18
2,-4,2:18
-2,-3,2:85
0,-3,2:18
2,-3,2:18
-2,-2,2:85
-1,-2,2:85
0,-2,2:17.2
1,-2,2:18
2,-2,2:85
-1,-1,2:18
0,-1,2:85
1,-1,2:18
-1,0,2:18
0,0,2:85
1,0,2:18
2,0,2:18
-1,-5,3:18
1,-5,3:85
-3,-4,3:18
-2,-4,3:18
-1,-4,3:18
0,-4,3:85
1,-4,3:18
2,-4,3:85
0,-3,3:18
1,-3,3:18
3,-3,3:18
-2,-2,3:18
0,-2,3:17.2
1,-2,3:18
2,-2,3:18
3,-2,3:18
0,-1,3:18
2,-1,3:18
3,-1,3:85
-4,0,3:18
-3,0,3:18
-2,0,3:18
-1,0,3:85
0,0,3:85
0,1,3:18
1,1,3:85
-2,2,3:18
0,2,3:18
-1,-6,4:18
1,-6,4:18
0,-5,4:85
-3,-4,4:18
-2,-4,4:85
-1,-4,4:18
0,-4,4:85
2,-4,4:18
3,-4,4:18
0,-3,4:85
1,-3,4:18
3,-3,4:18
-3,-2,4:18
-1,-2,4:18
0,-2,4:17.2
1,-2,4:18
3,-2,4:85
-3,-1,4:85
-2,-1,4:85
-1,-1,4:18
0,-1,4:18
3,-1,4:85
-4,0,4:18
-2,0,4:18
-1,0,4:85
0,0,4:85
2,0,4:85
0,1,4:85
1,1,4:18
1,2,4:18
-2,3,4:18
0,-6,5:18
-2,-5,5:18
0,-5,5:85
-2,-4,5:18
0,-4,5:18
1,-4,5:85
3,-4,5:18
-3,-3,5:18
-2,-3,5:18
-1,-3,5:85
0,-3,5:85
1,-3,5:85
3,-3,5:18
-2,-2,5:18
0,-2,5:17.2
1,-2,5:85
2,-2,5:85
-4,-1,5:18
-2,-1,5:18
-1,-1,5:18
0,-1,5:18
1,-1,5:85
2,-1,5:18
3,-1,5:85
-2,0,5:18
-1,0,5:18
0,0,5:18
-4,1,5:18
-1,1,5:85
0,1,5:85
0,2,5:18
1,2,5:18
0,3,5:18
0,-5,6:18
1,-5,6:18
-3,-4,6:18
-1,-4,6:85
0,-4,6:85
2,-4,6:18
-3,-3,6:18
-2,-3,6:18
0,-3,6:85
1,-3,6:18
2,-3,6:18
-2,-2,6:18
-1,-2,6:18
0,-2,6:17.2
1,-2,6:85
2,-2,6:85
-2,-1,6:18
0,-1,6:18
1,-1,6:18
2,-1,6:85
-3,0,6:18
-2,0,6:85
-1,0,6:18
0,0,6:18
1,0,6:18
-3,1,6:18
-1,1,6:18
-2,2,6:18
-1,2,6:18
0,-6,7:18
1,-6,7:18
0,-5,7:85
-2,-4,7:18
-1,-4,7:18
0,-4,7:18
2,-4,7:18
3,-4,7:18
-2,-3,7:18
-1,-3,7:18
0,-3,7:85
1,-3,7:18
2,-3,7:85
3,-3,7:18
-2,-2,7:18
0,-2,7:17.2
1,-2,7:18
2,-2,7:18
3,-2,7:18
-3,-1,7:18
0,-1,7:18
1,-1,7:18
2,-1,7:85
-2,0,7:18
-1,0,7:18
0,0,7:85
1,0,7:85
-3,1,7:18
-2,1,7:18
-1,1,7:18
0,1,7:18
-2,2,7:18
-1,2,7:18
-3,-6,8:18
-1,-6,8:18
1,-6,8:18
-1,-5,8:85
0,-5,8:18
-3,-4,8:18
-2,-4,8:18
-1,-4,8:18
1,-4,8:85
2,-4,8:85
-2,-3,8:18
-1,-3,8:18
0,-3,8:85
1,-3,8:85
2,-3,8:18
3,-3,8:18
-1,-2,8:18
0,-2,8:17.2
1,-2,8:18
3,-2,8:85
-3,-1,8:85
-2,-1,8:85
1,-1,8:18
-3,0,8:18
-1,0,8:18
0,0,8:85
-4,1,8:18
0,1,8:85
1,1,8:85
2,1,8:18
-1,2,8:18
0,2,8:18
-1,3,8:18
-1,-7,9:18
0,-6,9:18
-1,-5,9:18
0,-5,9:85
2,-5,9:18
-4,-4,9:18
0,-4,9:85
-1,-3,9:18
0,-3,9:85
1,-3,9:18
2,-3,9:85
3,-3,9:18
-3,-2,9:18
-2,-2,9:18
-1,-2,9:18
0,-2,9:17.2
1,-2,9:18
3,-2,9:18
-3,-1,9:85
-1,-1,9:18
0,-1,9:18
-2,0,9:18
-1,0,9:85
0,0,9:18
1,0,9:18
2,0,9:18
-1,1,9:18
0,1,9:18
1,1,9:85
2,1,9:18
-3,2,9:18
-2,2,9:18
-1,2,9:18
-2,3,9:18
-2,-7,10:18
-1,-7,10:18
-3,-5,10:18
-4,-4,10:18
-1,-4,10:18
0,-4,10:85
1,-4,10:85
2,-4,10:18
-2,-3,10:18
-1,-3,10:18
0,-3,10:85
1,-3,10:18
-3,-2,10:18
-1,-2,10:18
0,-2,10:17.2
1,-2,10:85
2,-2,10:18
3,-2,10:18
-2,-1,10:18
-1,-1,10:85
0,-1,10:18
1,-1,10:18
-3,0,10:18
-2,0,10:18
-1,0,10:18
0,0,10:18
-1,1,10:18
0,1,10:18
1,1,10:18
-1,2,10:18
1,2,10:18
0,3,10:18
-1,-5,11:18
0,-5,11:18
1,-5,11:18
0,-4,11:85
1,-4,11:85
2,-4,11:18
-2,-3,11:18
-1,-3,11:85
0,-3,11:85
2,-3,11:85
3,-3,11:18
-3,-2,11:18
-1,-2,11:85
0,-2,11:17.2
1,-2,11:85
-3,-1,11:18
-2,-1,11:18
-1,-1,11:85
0,-1,11:85
2,-1,11:18
-1,0,11:18
1,0,11:85
2,0,11:18
-2,1,11:18
-1,1,11:18
-1,2,11:18
1,2,11:18
1,-6,12:18
0,-5,12:18
1,-5,12:18
-3,-4,12:18
-1,-4,12:18
0,-4,12:18
1,-4,12:85
2,-4,12:18
-3,-3,12:18
-2,-3,12:18
0,-3,12:18
-3,-2,12:18
-2,-2,12:18
0,-2,12:17.2
1,-2,12:18
-2,-1,12:18
-1,-1,12:85
0,-1,12:85
-2,0,12:18
-1,0,12:18
1,0,12:18
-1,-5,13:18
-2,-4,13:18
0,-4,13:18
-2,-3,13:18
3,-3,13:18
-3,-2,13:18
-2,-2,13:18
-1,-2,13:18
0,-2,13:17.2
1,-2,13:18
3,-2,13:18
-1,-1,13:85
0,-1,13:85
1,-1,13:85
-2,0,13:18
-1,0,13:18
0,0,13:18
0,-5,14:18
-1,-4,14:18
0,-4,14:18
1,-4,14:18
-1,-3,14:18
0,-3,14:18
1,-3,14:18
2,-3,14:85
-3,-2,14:18
-2,-2,14:18
0,-2,14:17.2
-4,-1,14:18
-2,-1,14:18
0,-1,14:18
0,0,14:85
0,1,14:18
-2,-5,15:18
0,-5,15:18
2,-5,15:18
-2,-4,15:18
-1,-4,15:18
0,-4,15:85
1,-4,15:18
-4,-3,15:18
1,-3,15:18
2,-3,15:18
-2,-2,15:85
-1,-2,15:85
0,-2,15:17.2
0,-1,15:18
2,-1,15:85
-3,0,15:18
-2,0,15:18
-1,0,15:18
0,0,15:85
2,0,15:18
-2,-5,16:18
-3,-4,16:18
-2,-4,16:18
-3,-2,16:18
-2,-2,16:85
0,-2,16:17.2
1,-2,16:85
2,-2,16:85
0,-1,16:18
2,-1,16:18
-2,0,16:18
0,0,16:18
1,0,16:85
-2,1,16:18
0,-6,17:18
-3,-4,17:18
-2,-4,17:18
0,-4,17:18
-3,-3,17:18
-2,-3,17:18
-1,-3,17:85
0,-3,17:85
1,-3,17:18
2,-3,17:18
3,-3,17:18
-2,-2,17:18
0,-2,17:17.2
1,-2,17:18
-1,-1,17:18
0,-1,17:85
2,-1,17:18
-1,0,17:18
1,0,17:18
0,-4,18:18
2,-4,18:18
-3,-3,18:18
0,-3,18:85
-1,-2,18:18
1,-2,18:85
3,-2,18:18
0,-1,18:85
2,-1,18:18
-2,0,18:18
0,-4,19:18
-2,-3,19:18
-1,-3,19:18
0,-3,19:18
1,-3,19:18
2,-3,19:18
-1,-2,19:18
1,-2,19:18
0,-1,19:18
0,-3,20:18
