[META]
version=2.0
spawnOnBlockType=2
spawnSunlight=True
spawnDarkness=False
spawnWater=False
spawnLava=False
underFill=True
randomRotation=True
dig=True
tree=False
branch=False
needsFoundation=True
rarity=10
collisionPercentage=2
spawnElevationMin=0
spawnElevationMax=128
spawnInBiome=All
[DATA]
-6,-4,0:17
-6,-3,0:17
-4,-3,0:17
-5,-2,0:17
-5,-1,0:17
-4,-1,0:17
-2,-1,0:17
-6,0,0:17
-5,0,0:17
-4,0,0:17
-3,0,0:17
-5,1,0:17
-5,-1,1:17
-4,-1,1:17
-5,0,1:17
-4,0,1:17
-5,-1,2:17
-4,-1,2:17
-5,0,2:17
-4,0,2:17
-8,-2,3:18
-6,-1,3:18
-5,-1,3:17
-4,-1,3:17
-5,0,3:17
-4,0,3:17
-4,1,3:17
-6,5,3:18
-12,-8,4:18
-11,-6,4:18
-10,-6,4:18
-9,-5,4:18
-7,-5,4:18
-7,-4,4:18
-7,-2,4:18
-5,-2,4:17
-4,-2,4:17
-5,-1,4:17
-4,-1,4:17
-7,0,4:18
-6,0,4:17
-5,0,4:17
-4,0,4:17
-3,0,4:17
-4,1,4:17
-3,1,4:17
-6,4,4:18
-5,4,4:18
-7,5,4:18
-6,6,4:18
-6,7,4:18
-7,8,4:18
-7,-7,5:18
-9,-6,5:18
-8,-6,5:18
-12,-5,5:18
-11,-3,5:18
-9,-3,5:18
-8,-3,5:18
-6,-3,5:18
-9,-2,5:18
-8,-2,5:18
-6,-2,5:17
-5,-2,5:17
-4,-2,5:17
-6,-1,5:17
-5,-1,5:17
-4,-1,5:17
-9,0,5:18
-5,0,5:17
-4,0,5:17
-4,1,5:17
-3,1,5:17
-3,2,5:17
-6,4,5:18
-6,5,5:18
-3,6,5:18
-9,7,5:18
-6,7,5:18
-7,8,5:18
-3,-10,6:18
-11,-9,6:18
-10,-9,6:18
-2,-9,6:18
-12,-6,6:18
-9,-4,6:18
-5,-4,6:18
-8,-3,6:18
-6,-3,6:17
-5,-3,6:17
-6,-2,6:17
-5,-2,6:17
-5,-1,6:17
6,-1,6:18
5,0,6:18
-3,1,6:17
-4,2,6:17
-3,2,6:17
-7,3,6:18
-3,3,6:17
-2,3,6:17
-7,4,6:18
-4,4,6:18
-2,4,6:17
-7,6,6:18
-6,6,6:18
-5,6,6:18
-3,6,6:18
-9,7,6:18
-3,7,6:18
-6,8,6:18
-7,9,6:18
-7,12,6:18
-5,12,6:18
5,-11,7:18
-8,-8,7:18
-2,-8,7:18
-10,-7,7:18
-8,-7,7:18
-10,-6,7:18
-8,-6,7:18
-9,-3,7:18
-6,-3,7:17
-5,-3,7:17
-6,-2,7:17
-5,-2,7:17
-3,1,7:18
6,1,7:18
-1,2,7:18
6,2,7:18
7,2,7:18
-2,3,7:17
6,3,7:18
-4,4,7:18
-3,4,7:17
-2,4,7:17
-3,5,7:17
-2,5,7:17
0,5,7:18
1,5,7:18
-8,6,7:18
-3,6,7:17
-2,6,7:17
-5,7,7:18
-2,7,7:17
-7,9,7:18
-5,9,7:18
-6,10,7:18
-4,10,7:18
-3,13,7:18
-3,14,7:18
-2,-13,8:18
-4,-12,8:18
-3,-12,8:18
5,-12,8:18
3,-11,8:18
3,-10,8:18
7,-9,8:18
-11,-5,8:18
-10,-5,8:18
-6,-3,8:17
-5,-3,8:17
6,-3,8:18
-6,-2,8:17
7,-2,8:18
8,-2,8:18
5,-1,8:18
8,-1,8:18
-1,0,8:18
8,0,8:18
1,1,8:18
6,1,8:18
0,2,8:18
-2,3,8:18
-1,3,8:17
2,3,8:18
6,3,8:18
-8,4,8:18
-7,5,8:18
-6,5,8:18
-2,5,8:17
1,5,8:18
-7,6,8:18
-6,6,8:18
-4,6,8:18
-2,6,8:17
-7,7,8:18
-3,7,8:17
-2,7,8:17
-1,7,8:17
3,7,8:18
-7,8,8:18
-2,8,8:17
-5,9,8:18
-9,10,8:18
-7,10,8:18
-6,10,8:18
-5,10,8:18
-3,11,8:18
-8,12,8:18
-5,12,8:18
-2,12,8:18
-7,13,8:18
-5,13,8:18
-4,14,8:18
6,-13,9:18
6,-12,9:18
1,-11,9:18
5,-11,9:18
-2,-10,9:18
1,-10,9:18
6,-10,9:18
7,-10,9:18
8,-10,9:18
-4,-9,9:18
-2,-9,9:18
0,-8,9:18
3,-8,9:18
-11,-7,9:18
-2,-7,9:18
-5,-6,9:18
-10,-4,9:18
-6,-4,9:17
-4,-4,9:18
-7,-3,9:17
-6,-3,9:17
-5,-3,9:17
-4,-3,9:17
6,-3,9:18
9,-3,9:18
-6,-2,9:17
8,-2,9:18
-8,-1,9:18
8,-1,9:18
5,0,9:18
6,0,9:18
-2,1,9:18
6,1,9:18
7,1,9:18
-3,2,9:18
6,2,9:18
-4,3,9:18
-1,3,9:17
1,3,9:18
-4,4,9:18
2,4,9:18
2,5,9:18
6,5,9:18
-7,6,9:18
-1,6,9:18
-8,7,9:18
-7,7,9:18
-6,7,9:18
0,7,9:17
-3,8,9:17
-2,8,9:17
0,8,9:17
-7,9,9:18
-2,9,9:17
-8,10,9:18
-5,10,9:18
-4,10,9:18
-6,11,9:18
-4,11,9:18
-2,11,9:18
-9,12,9:18
-7,12,9:18
-6,12,9:18
-5,12,9:18
-3,12,9:18
-5,13,9:18
0,13,9:18
-7,14,9:18
-3,14,9:18
-2,14,9:18
-1,14,9:18
5,-13,10:18
6,-13,10:18
-6,-12,10:18
-2,-12,10:18
7,-12,10:18
-6,-11,10:18
7,-11,10:18
-6,-10,10:18
3,-10,10:18
6,-10,10:18
4,-9,10:18
7,-9,10:18
8,-9,10:18
-1,-8,10:18
1,-8,10:18
-11,-7,10:18
-6,-7,10:18
4,-7,10:18
5,-7,10:18
-6,-6,10:18
1,-6,10:18
6,-6,10:18
-13,-5,10:18
-7,-5,10:18
-6,-5,10:18
-7,-4,10:17
-6,-4,10:17
2,-4,10:18
8,-4,10:18
10,-4,10:18
-11,-3,10:18
-8,-3,10:18
-5,-3,10:17
-4,-3,10:17
-9,-2,10:18
6,-2,10:18
-9,-1,10:18
8,-1,10:18
0,0,10:18
8,0,10:18
-4,3,10:18
-2,3,10:18
0,3,10:18
2,3,10:18
-1,4,10:18
5,4,10:18
-1,5,10:18
-6,8,10:18
-5,8,10:18
1,8,10:18
-8,9,10:18
-2,9,10:17
1,9,10:17
4,9,10:18
-8,10,10:18
-6,10,10:18
1,10,10:17
-4,11,10:18
-3,11,10:18
-1,11,10:18
1,11,10:17
0,12,10:18
-3,13,10:18
1,13,10:18
3,13,10:18
4,13,10:18
-1,14,10:18
-3,15,10:18
-1,15,10:18
4,15,10:18
-5,-13,11:18
-6,-12,11:18
5,-12,11:18
-6,-11,11:18
6,-11,11:18
-2,-10,11:18
-1,-10,11:18
-6,-9,11:18
5,-9,11:18
-2,-8,11:18
0,-8,11:18
2,-8,11:18
-11,-7,11:18
5,-7,11:18
7,-7,11:18
-13,-6,11:18
-11,-6,11:18
-9,-6,11:18
-2,-6,11:18
-12,-5,11:18
-11,-5,11:18
-9,-5,11:18
-8,-5,11:17
-7,-5,11:17
-5,-5,11:18
-1,-5,11:18
10,-5,11:18
-14,-4,11:18
-11,-4,11:18
-10,-4,11:18
-8,-4,11:17
11,-4,11:18
-10,-3,11:18
-9,-3,11:18
-7,-3,11:18
-3,-3,11:17
7,-3,11:18
11,-3,11:18
-5,-2,11:18
-11,-1,11:18
-6,-1,11:18
3,-1,11:18
-9,0,11:18
2,0,11:18
-2,2,11:18
-3,3,11:18
-1,3,11:18
0,4,11:18
4,4,11:18
-8,5,11:18
4,5,11:18
4,6,11:18
-7,7,11:18
-6,7,11:18
-4,7,11:18
4,7,11:18
-5,8,11:18
-4,8,11:18
2,8,11:18
4,8,11:18
-2,9,11:17
3,9,11:18
5,9,11:18
-2,10,11:18
1,10,11:18
4,10,11:18
0,11,11:18
2,11,11:17
2,12,11:17
-7,13,11:18
-4,13,11:18
0,13,11:18
5,13,11:18
-3,14,11:18
2,14,11:18
-4,-13,12:18
-7,-12,12:18
-6,-11,12:18
-6,-10,12:18
-2,-10,12:18
5,-10,12:18
-7,-9,12:18
1,-9,12:18
7,-9,12:18
-11,-8,12:18
-7,-8,12:18
-5,-8,12:18
-1,-8,12:18
1,-8,12:18
7,-8,12:18
-3,-7,12:18
-2,-7,12:18
4,-7,12:18
9,-7,12:18
-13,-6,12:18
-7,-6,12:17
-6,-6,12:18
1,-6,12:18
4,-6,12:18
8,-6,12:18
-9,-5,12:17
-8,-5,12:18
-6,-5,12:18
-3,-5,12:18
-2,-5,12:18
4,-5,12:18
5,-5,12:18
7,-5,12:18
8,-5,12:18
-14,-4,12:18
1,-4,12:18
8,-4,12:18
9,-4,12:18
10,-4,12:18
-11,-3,12:18
-9,-3,12:18
-5,-3,12:18
-2,-3,12:17
1,-3,12:18
2,-3,12:18
9,-3,12:18
10,-3,12:18
-12,-2,12:18
-11,-2,12:18
-7,-2,12:18
-6,-2,12:18
6,-2,12:18
7,-2,12:18
8,-2,12:18
-12,-1,12:18
-7,-1,12:18
3,0,12:18
5,0,12:18
4,1,12:18
5,1,12:18
-1,2,12:18
-1,3,12:18
-6,4,12:18
4,4,12:18
-7,6,12:18
-6,6,12:18
-9,7,12:18
-6,7,12:18
4,7,12:18
-7,8,12:18
-3,8,12:18
4,8,12:18
-9,9,12:18
-8,9,12:18
-2,9,12:17
-5,10,12:18
-1,10,12:17
3,10,12:18
-7,11,12:18
-3,11,12:18
2,11,12:18
0,12,12:18
3,12,12:18
-5,13,12:18
-1,13,12:18
0,13,12:18
2,13,12:17
5,13,12:18
1,15,12:18
2,15,12:18
-8,-12,13:18
-6,-12,13:18
-4,-12,13:18
-3,-12,13:18
4,-12,13:18
-9,-11,13:18
-8,-11,13:18
-6,-11,13:18
-5,-11,13:18
-4,-11,13:18
2,-11,13:18
3,-11,13:18
6,-11,13:18
-8,-10,13:18
-7,-10,13:18
-3,-10,13:18
5,-10,13:18
6,-10,13:18
-6,-9,13:18
6,-8,13:18
-12,-7,13:18
-7,-7,13:18
-6,-7,13:18
8,-7,13:18
9,-7,13:18
-13,-6,13:18
-12,-6,13:18
-11,-6,13:18
-7,-6,13:17
-5,-6,13:18
-2,-6,13:18
0,-6,13:18
3,-6,13:18
-12,-5,13:18
-11,-5,13:18
-10,-5,13:18
-9,-5,13:17
-6,-5,13:18
-5,-5,13:18
-4,-5,13:18
7,-5,13:18
-9,-4,13:18
5,-4,13:18
6,-4,13:18
7,-4,13:18
10,-4,13:18
11,-4,13:18
-10,-3,13:18
-1,-3,13:17
0,-3,13:17
1,-3,13:17
3,-3,13:18
4,-3,13:18
2,-2,13:18
3,-2,13:18
7,-2,13:18
3,-1,13:18
2,0,13:18
6,0,13:18
-10,1,13:18
-7,2,13:18
2,2,13:18
-7,4,13:18
-6,4,13:18
-5,4,13:18
-4,4,13:18
-6,5,13:18
-5,5,13:18
5,5,13:18
-8,6,13:18
-4,6,13:18
1,6,13:18
-9,7,13:18
-5,7,13:18
-2,7,13:18
2,7,13:18
4,7,13:18
5,7,13:18
-3,8,13:18
0,8,13:18
3,8,13:18
-7,9,13:18
-6,9,13:18
-3,9,13:17
0,9,13:18
2,9,13:18
4,9,13:18
-1,10,13:17
1,10,13:18
2,10,13:18
-3,11,13:18
-2,11,13:18
2,11,13:18
-3,12,13:18
0,12,13:18
2,12,13:18
-3,13,13:18
0,13,13:18
2,13,13:18
3,13,13:18
-1,14,13:18
1,14,13:18
2,15,13:18
4,15,13:18
5,-12,14:18
-6,-11,14:18
-9,-10,14:18
3,-10,14:18
4,-10,14:18
5,-10,14:18
-9,-9,14:18
-2,-8,14:18
-1,-8,14:18
2,-8,14:18
6,-8,14:18
-7,-7,14:18
-6,-7,14:17
0,-7,14:18
1,-7,14:18
-13,-6,14:18
-10,-6,14:17
-8,-6,14:18
0,-6,14:18
-12,-5,14:18
-10,-5,14:17
-7,-5,14:18
-6,-5,14:18
-5,-5,14:18
-12,-4,14:18
-1,-4,14:18
-10,-3,14:18
2,-3,14:17
3,-3,14:17
4,-3,14:17
6,-3,14:18
-11,-2,14:18
-1,-2,14:18
-11,-1,14:18
-10,-1,14:18
-9,-1,14:18
0,-1,14:18
2,-1,14:18
3,-1,14:18
6,-1,14:18
-9,0,14:18
0,0,14:18
3,0,14:18
-11,1,14:18
-8,1,14:18
-7,1,14:18
-6,1,14:18
-4,2,14:18
2,3,14:18
-6,4,14:18
2,4,14:18
-7,5,14:18
-3,6,14:18
-2,6,14:18
-9,7,14:18
-8,7,14:18
-5,7,14:18
-8,8,14:18
-7,8,14:18
-6,8,14:18
-5,8,14:18
-4,8,14:18
-3,8,14:18
-1,8,14:18
0,8,14:18
-6,9,14:18
-3,9,14:17
-2,9,14:18
-1,9,14:18
-6,10,14:18
-4,10,14:18
-3,10,14:18
-2,10,14:18
-5,11,14:18
0,11,14:17
1,11,14:18
2,11,14:18
-2,12,14:18
3,12,14:18
-2,13,14:18
1,13,14:18
2,13,14:18
4,15,14:18
-6,-13,15:18
3,-13,15:18
4,-13,15:18
5,-12,15:18
-4,-11,15:18
1,-11,15:18
2,-11,15:18
6,-11,15:18
7,-11,15:18
-6,-10,15:18
1,-10,15:18
5,-10,15:18
-9,-9,15:18
-3,-9,15:18
-2,-9,15:18
1,-9,15:18
-10,-8,15:18
-8,-8,15:18
3,-8,15:18
4,-8,15:18
-7,-7,15:18
-6,-7,15:17
-13,-6,15:18
-10,-6,15:17
-8,-6,15:18
1,-6,15:18
5,-6,15:18
-12,-5,15:18
2,-5,15:18
-5,-4,15:18
5,-4,15:17
8,-4,15:18
9,-4,15:18
-1,-3,15:18
-8,-2,15:18
-6,-2,15:18
-1,-2,15:18
-7,-1,15:18
-2,-1,15:18
-1,-1,15:18
4,-1,15:18
5,-1,15:18
-9,0,15:18
-3,0,15:18
0,0,15:18
4,0,15:18
-6,1,15:18
-3,1,15:18
4,1,15:18
-8,2,15:18
-6,2,15:18
-5,2,15:18
-5,3,15:18
-4,3,15:18
1,3,15:18
3,3,15:18
4,3,15:18
-9,4,15:18
-7,4,15:18
-5,4,15:18
-3,4,15:18
2,4,15:18
-4,5,15:18
-5,6,15:18
-3,6,15:18
-2,6,15:18
1,6,15:18
2,6,15:18
-8,7,15:18
-6,7,15:18
-5,7,15:18
2,7,15:18
-3,8,15:18
-1,9,15:18
0,9,15:18
-1,10,15:18
-4,11,15:18
-2,11,15:18
-1,11,15:18
-1,12,15:18
0,12,15:18
2,14,15:18
3,-12,16:18
2,-10,16:18
2,-9,16:18
-8,-8,16:18
1,-8,16:18
2,-8,16:18
5,-8,16:18
-13,-7,16:18
-10,-7,16:18
-2,-7,16:18
4,-7,16:18
-10,-6,16:18
-8,-6,16:18
-7,-5,16:18
-6,-5,16:18
-10,-4,16:18
-8,-4,16:18
-5,-4,16:18
-2,-4,16:18
0,-4,16:18
6,-4,16:17
-7,-3,16:18
3,-3,16:18
-5,-2,16:18
2,-2,16:18
5,-2,16:18
6,-2,16:18
2,-1,16:18
-4,0,16:18
2,0,16:18
4,0,16:18
-5,1,16:18
-2,1,16:18
3,2,16:18
4,2,16:18
-8,3,16:18
-5,3,16:18
-8,4,16:18
-6,4,16:18
-5,4,16:18
0,4,16:18
-8,5,16:18
0,5,16:18
-2,6,16:18
2,6,16:18
3,6,16:18
4,6,16:18
-2,7,16:18
-1,7,16:18
1,7,16:18
-5,8,16:18
0,8,16:18
-2,9,16:18
1,9,16:18
2,9,16:18
-4,10,16:18
-3,10,16:18
-2,10,16:18
1,10,16:18
-5,11,16:18
-4,11,16:18
0,11,16:18
2,11,16:18
-5,12,16:18
-2,12,16:18
1,12,16:18
-2,-12,17:18
2,-11,17:18
4,-11,17:18
-2,-10,17:18
0,-10,17:18
1,-10,17:18
3,-10,17:18
4,-10,17:18
5,-10,17:18
-4,-9,17:18
-3,-9,17:18
0,-9,17:18
2,-9,17:18
-9,-8,17:18
-6,-8,17:18
-5,-8,17:18
-4,-8,17:18
3,-8,17:18
0,-7,17:18
6,-7,17:18
-9,-6,17:18
-8,-6,17:18
-7,-6,17:18
-5,-6,17:18
-2,-6,17:18
-1,-6,17:18
4,-6,17:18
6,-6,17:18
-9,-5,17:18
-8,-5,17:18
-3,-5,17:18
4,-5,17:18
9,-5,17:18
-8,-4,17:18
3,-4,17:18
6,-4,17:17
9,-4,17:18
-9,-3,17:18
-8,-3,17:18
-5,-3,17:18
-3,-3,17:18
-1,-3,17:18
1,-3,17:18
4,-3,17:18
6,-3,17:18
8,-3,17:18
-3,-2,17:18
-2,-2,17:18
-1,-2,17:18
6,-2,17:18
-9,-1,17:18
-8,-1,17:18
-3,-1,17:18
-1,-1,17:18
1,-1,17:18
2,-1,17:18
-8,0,17:18
-1,0,17:18
0,0,17:18
3,0,17:18
4,0,17:18
1,1,17:18
3,1,17:18
-8,2,17:18
-6,2,17:18
-4,2,17:18
0,2,17:18
2,3,17:18
5,3,17:18
-5,4,17:18
0,4,17:18
0,5,17:18
-1,6,17:18
0,6,17:18
1,6,17:18
2,6,17:18
-2,7,17:18
0,7,17:18
-4,8,17:18
-1,8,17:18
-3,9,17:18
-6,10,17:18
-1,11,17:18
0,11,17:18
1,11,17:18
2,11,17:18
3,11,17:18
-1,12,17:18
2,12,17:18
-3,-12,18:18
1,-10,18:18
4,-10,18:18
-6,-9,18:18
-2,-9,18:18
-1,-9,18:18
-6,-7,18:18
0,-7,18:18
-11,-6,18:18
-10,-6,18:18
-8,-6,18:18
-4,-6,18:18
2,-6,18:18
6,-6,18:18
-9,-5,18:18
-7,-5,18:18
-6,-5,18:18
-5,-5,18:18
1,-5,18:18
9,-5,18:18
-8,-4,18:18
0,-4,18:18
3,-4,18:18
4,-3,18:18
-7,-2,18:18
-2,-2,18:18
0,-2,18:18
0,-1,18:18
2,-1,18:18
7,-1,18:18
0,0,18:18
1,0,18:18
3,0,18:18
5,0,18:18
1,1,18:18
5,1,18:18
3,2,18:18
-6,4,18:18
0,4,18:18
2,4,18:18
3,4,18:18
-1,6,18:18
3,7,18:18
-5,9,18:18
-4,9,18:18
-4,10,18:18
1,10,18:18
-6,11,18:18
-3,11,18:18
-4,12,18:18
-3,13,18:18
0,13,18:18
1,14,18:18
-5,-9,19:18
-5,-7,19:18
-4,-7,19:18
-2,-6,19:18
7,-6,19:18
-8,-5,19:18
-3,-5,19:18
5,-5,19:18
8,-5,19:18
-8,-4,19:18
-5,-4,19:18
-1,-4,19:18
1,-4,19:18
2,-4,19:18
6,-4,19:18
-9,-3,19:18
-8,-3,19:18
-1,-3,19:18
1,-3,19:18
3,-3,19:18
-6,-1,19:18
0,-1,19:18
7,-1,19:18
1,0,19:18
4,0,19:18
0,5,19:18
1,5,19:18
0,6,19:18
1,6,19:18
-4,8,19:18
1,8,19:18
-1,9,19:18
0,9,19:18
1,9,19:18
-1,10,19:18
0,10,19:18
0,11,19:18
3,11,19:18
-3,12,19:18
-2,12,19:18
3,12,19:18
4,12,19:18
0,13,19:18
-2,-9,20:18
-3,-8,20:18
-6,-7,20:18
0,-7,20:18
1,-7,20:18
2,-6,20:18
-8,-5,20:18
-6,-5,20:18
2,-5,20:18
3,-5,20:18
-8,-4,20:18
3,-4,20:18
6,-4,20:18
2,-3,20:18
2,-2,20:18
2,0,20:18
3,2,20:18
-4,8,20:18
0,9,20:18
-4,10,20:18
-1,10,20:18
-5,11,20:18
-2,11,20:18
0,11,20:18
1,11,20:18
0,12,20:18
-6,-8,21:18
-4,-7,21:18
-3,-6,21:18
5,-6,21:18
-1,-5,21:18
1,-5,21:18
3,-4,21:18
-4,10,21:18
-5,-7,22:18
3,-7,22:18
2,-5,22:18
1,-4,22:18
4,-4,22:18
