[META]
version=2.0
spawnOnBlockType=2
spawnSunlight=True
spawnDarkness=False
spawnWater=False
spawnLava=False
underFill=True
randomRotation=True
dig=True
tree=False
branch=False
needsFoundation=True
rarity=10
collisionPercentage=2
spawnElevationMin=0
spawnElevationMax=128
spawnInBiome=All
[DATA]
0,-1,0:17
-2,0,0:17
-1,0,0:17
0,0,0:17
0,-1,1:17
-1,0,1:17
0,0,1:17
-1,0,2:17
0,0,2:17
1,1,2:17
2,2,2:18
3,2,2:18
1,3,2:18
2,3,2:18
4,3,2:18
3,6,2:18
0,0,3:17
5,0,3:18
0,1,3:18
1,1,3:17
1,2,3:18
6,4,3:18
3,5,3:18
6,5,3:18
3,6,3:18
4,6,3:18
0,-4,4:18
0,-3,4:18
-3,-1,4:18
0,-1,4:17
3,0,4:18
5,0,4:18
-5,1,4:18
-2,1,4:18
-1,1,4:17
-4,2,4:18
-3,2,4:18
2,2,4:17
5,2,4:18
6,2,4:18
2,3,4:18
6,3,4:18
-1,4,4:18
0,4,4:18
6,4,4:18
7,4,4:18
2,5,4:18
5,5,4:18
1,6,4:18
3,6,4:18
-1,-7,5:18
0,-7,5:18
1,-7,5:18
3,-5,5:18
0,-4,5:18
1,-4,5:18
-2,-3,5:18
3,-3,5:18
0,-2,5:17
1,-2,5:18
-3,-1,5:18
2,-1,5:18
3,-1,5:18
4,-1,5:18
1,0,5:18
3,0,5:18
6,0,5:18
-5,1,5:18
-1,1,5:17
1,1,5:18
2,1,5:18
3,1,5:18
4,1,5:18
5,1,5:18
7,1,5:18
0,2,5:18
1,2,5:18
3,2,5:18
-3,3,5:18
0,3,5:18
1,3,5:18
3,3,5:17
5,3,5:18
7,3,5:18
-4,4,5:18
-1,4,5:18
0,4,5:18
1,4,5:18
0,5,5:18
5,5,5:18
6,5,5:18
5,6,5:18
6,6,5:18
0,-6,6:18
-2,-5,6:18
-1,-5,6:18
2,-5,6:18
0,-4,6:18
1,-4,6:18
-2,-3,6:18
1,-3,6:18
-5,-2,6:18
0,-2,6:17
2,-2,6:18
-2,-1,6:18
0,-1,6:18
2,-1,6:18
4,-1,6:18
-2,0,6:18
1,0,6:18
2,0,6:18
4,0,6:18
-5,1,6:18
-4,1,6:18
-3,1,6:18
-2,1,6:18
-1,1,6:18
0,1,6:18
1,1,6:18
3,1,6:18
-2,2,6:17
0,2,6:18
1,2,6:18
3,2,6:18
4,2,6:18
-5,3,6:18
1,3,6:18
5,3,6:18
6,3,6:18
7,3,6:18
-3,4,6:18
2,4,6:18
3,4,6:18
1,5,6:18
6,5,6:18
6,6,6:18
0,-7,7:18
-1,-4,7:18
1,-4,7:18
4,-4,7:18
0,-3,7:17
1,-3,7:18
-2,-2,7:18
-1,-2,7:18
0,-1,7:18
1,-1,7:18
3,-1,7:18
4,-1,7:18
-6,0,7:18
-5,0,7:18
-3,0,7:18
-2,0,7:18
0,0,7:18
2,0,7:18
3,0,7:18
-3,1,7:18
-2,1,7:18
1,1,7:18
3,1,7:18
-2,2,7:17
-6,3,7:18
-3,3,7:18
2,3,7:18
4,3,7:18
6,3,7:18
-3,4,7:18
1,4,7:18
6,4,7:18
5,5,7:18
2,6,7:18
3,6,7:18
0,-8,8:18
-3,-7,8:18
-2,-7,8:18
-1,-7,8:18
0,-7,8:18
2,-7,8:18
3,-7,8:18
-4,-6,8:18
-2,-6,8:18
0,-6,8:18
-3,-5,8:18
0,-5,8:18
4,-5,8:18
-3,-4,8:18
-2,-4,8:18
0,-4,8:17
3,-4,8:18
4,-4,8:18
-5,-3,8:18
-4,-3,8:18
0,-3,8:18
1,-3,8:18
4,-3,8:18
-4,-2,8:18
0,-2,8:18
2,-2,8:18
4,-2,8:18
-2,-1,8:18
-1,-1,8:18
0,-1,8:18
1,-1,8:18
2,-1,8:18
3,-1,8:18
-7,0,8:18
-6,0,8:18
-2,0,8:18
-1,0,8:18
1,0,8:18
2,0,8:18
-6,1,8:18
-5,1,8:18
-3,1,8:17
3,1,8:18
-7,2,8:18
-5,2,8:18
-2,2,8:18
-1,2,8:18
3,2,8:18
-2,3,8:17
-1,3,8:18
1,3,8:18
3,3,8:18
-2,4,8:18
1,4,8:18
-1,5,8:18
1,5,8:18
4,5,8:18
5,5,8:18
-1,-8,9:18
0,-7,9:18
3,-7,9:18
-1,-4,9:18
0,-4,9:18
1,-4,9:18
3,-4,9:18
4,-4,9:18
-3,-3,9:18
-2,-3,9:18
0,-3,9:18
3,-3,9:18
4,-3,9:18
-5,-2,9:18
-3,-2,9:18
-2,-2,9:18
-1,-2,9:18
1,-2,9:18
4,-2,9:18
0,-1,9:18
1,-1,9:18
4,-1,9:18
-2,0,9:18
-1,0,9:18
0,0,9:18
1,0,9:18
2,0,9:18
4,0,9:18
5,0,9:18
-6,1,9:18
-5,1,9:18
-2,1,9:18
1,1,9:18
3,1,9:18
-3,2,9:18
-2,2,9:18
0,2,9:18
1,2,9:18
0,3,9:18
1,3,9:18
4,3,9:18
2,4,9:18
3,4,9:18
-2,-7,10:18
0,-7,10:18
-3,-6,10:18
0,-5,10:18
-2,-4,10:18
-1,-4,10:18
1,-4,10:18
4,-4,10:18
-2,-3,10:18
0,-3,10:18
4,-3,10:18
-2,-2,10:18
-3,-1,10:18
-2,-1,10:18
1,-1,10:18
2,-1,10:18
-2,0,10:18
-1,0,10:18
0,0,10:18
0,1,10:18
-3,2,10:18
0,3,10:18
-1,4,10:18
1,4,10:18
0,-7,11:18
1,-4,11:18
-3,-3,11:18
2,-3,11:18
3,-3,11:18
-1,-1,11:18
1,-1,11:18
-4,0,11:18
2,0,11:18
-1,1,11:18
4,1,11:18
1,2,11:18
1,4,11:18
0,-3,12:18
2,-1,12:18
-2,0,12:18
1,0,12:18
2,1,12:18
4,1,12:18
3,2,12:18
1,2,13:18
