[META]
version=2.0
spawnOnBlockType=2
spawnSunlight=True
spawnDarkness=False
spawnWater=False
spawnLava=False
underFill=True
randomRotation=True
dig=True
tree=False
branch=False
needsFoundation=True
rarity=10
collisionPercentage=2
spawnElevationMin=0
spawnElevationMax=128
spawnInBiome=All
[DATA]
-3,0,0:17
-5,1,0:17
-4,1,0:17
-3,1,0:17
-4,2,0:17
-3,2,0:17
-3,3,0:17
-4,1,1:17
-3,1,1:17
-4,2,1:17
-3,2,1:17
-7,-1,2:18
-5,-1,2:18
-4,1,2:17
-3,1,2:17
-4,2,2:17
-3,2,2:17
-6,3,2:18
0,3,2:18
-6,4,2:18
-5,5,2:18
-2,-3,3:18
-7,-2,3:18
-4,-2,3:18
0,-1,3:18
-8,0,3:18
0,0,3:18
-5,2,3:18
-4,2,3:17
-3,2,3:17
-1,2,3:18
-8,3,3:18
-2,3,3:18
0,3,3:18
-7,4,3:18
-1,8,3:18
-2,9,3:18
-4,-4,4:18
-2,-4,4:18
-3,-3,4:18
-7,-2,4:18
-6,-2,4:18
-5,-2,4:18
-3,-2,4:18
0,-2,4:18
1,-2,4:18
-3,-1,4:18
0,-1,4:18
2,-1,4:18
-7,0,4:18
-2,0,4:18
0,0,4:18
-6,1,4:18
-2,1,4:18
0,1,4:18
-3,2,4:17
-2,2,4:18
-8,3,4:18
-6,4,4:18
-3,4,4:18
0,4,4:18
-8,5,4:18
-5,5,4:18
-4,5,4:18
-4,6,4:18
-3,6,4:18
-2,6,4:18
-6,7,4:18
-2,7,4:18
-6,8,4:18
-3,8,4:18
0,8,4:18
-5,9,4:18
-2,9,4:18
-1,9,4:18
0,9,4:18
-2,-5,5:18
-8,-4,5:18
-5,-3,5:18
-3,-3,5:18
-1,-3,5:18
0,-3,5:18
-6,-2,5:18
-3,-2,5:18
-1,-2,5:18
0,-2,5:18
1,-2,5:18
2,-2,5:18
-6,-1,5:18
-5,-1,5:18
-4,-1,5:18
-3,-1,5:18
0,-1,5:18
-8,0,5:18
-1,0,5:18
1,0,5:18
2,0,5:18
-6,1,5:18
-1,1,5:18
0,1,5:18
-5,2,5:18
-4,2,5:18
-3,2,5:17
-1,2,5:18
-6,3,5:18
-4,3,5:18
-3,3,5:17
0,3,5:18
-7,4,5:18
-6,4,5:18
-3,4,5:18
1,4,5:18
-6,5,5:18
-5,5,5:18
-3,5,5:18
-2,5,5:18
-1,5,5:18
0,5,5:18
-8,6,5:18
-7,6,5:18
-6,6,5:18
-4,6,5:18
-2,6,5:18
-6,7,5:18
-5,7,5:18
-2,7,5:18
-6,8,5:18
-4,8,5:18
-3,8,5:18
-2,9,5:18
1,9,5:18
-5,10,5:18
-4,10,5:18
-3,10,5:18
-1,10,5:18
-7,-5,6:18
-1,-5,6:18
-5,-4,6:18
-9,-3,6:18
-6,-3,6:18
-4,-3,6:18
-3,-3,6:18
-9,-2,6:18
-8,-2,6:18
-1,-2,6:18
2,-2,6:18
-3,-1,6:18
-2,-1,6:18
-4,0,6:18
-3,0,6:18
-2,0,6:18
-3,1,6:18
-1,1,6:18
0,1,6:18
-5,2,6:18
-2,2,6:18
1,2,6:18
-6,3,6:18
-3,3,6:17
-2,3,6:18
-6,4,6:18
-3,4,6:18
-8,5,6:18
-6,5,6:18
-5,5,6:18
-3,5,6:18
-2,5,6:18
-1,5,6:18
-8,6,6:18
-4,6,6:18
-1,6,6:18
0,6,6:18
-7,7,6:18
-6,7,6:18
-5,7,6:18
-4,7,6:18
-3,7,6:18
-2,7,6:18
-1,7,6:18
1,7,6:18
-5,8,6:18
-4,8,6:18
-3,8,6:18
-2,8,6:18
1,8,6:18
-4,9,6:18
-2,9,6:18
0,9,6:18
1,9,6:18
-6,10,6:18
-3,10,6:18
-2,11,6:18
-3,-5,7:18
-5,-4,7:18
-5,-3,7:18
-1,-3,7:18
-7,-2,7:18
-2,-2,7:18
-1,-2,7:18
-6,-1,7:18
-3,-1,7:18
-1,-1,7:18
0,-1,7:18
-8,0,7:18
-6,0,7:18
-4,0,7:18
-3,0,7:18
-2,0,7:18
-7,2,7:18
-6,2,7:18
-4,2,7:18
-3,2,7:18
-2,2,7:18
-8,3,7:18
-5,3,7:18
-3,3,7:17
1,3,7:18
-7,4,7:18
-6,4,7:18
-3,4,7:18
-2,4,7:18
-7,5,7:18
-6,5,7:18
-5,5,7:18
-4,5,7:18
-3,5,7:18
-1,5,7:18
-6,6,7:18
-5,6,7:18
-4,6,7:18
-3,6,7:18
-8,7,7:18
-6,7,7:18
-5,7,7:18
-3,7,7:18
-2,7,7:18
-8,8,7:18
-6,8,7:18
-5,8,7:18
-4,8,7:18
-3,8,7:18
-2,8,7:18
-7,9,7:18
-5,9,7:18
-4,9,7:18
-3,9,7:18
-1,9,7:18
-4,10,7:18
-3,10,7:18
-2,11,7:18
-3,-5,8:18
-3,-4,8:18
-6,-3,8:18
-3,-3,8:18
-7,-2,8:18
-5,-2,8:18
-4,-2,8:18
-7,-1,8:18
-1,-1,8:18
-6,0,8:18
-5,0,8:18
-4,0,8:18
-3,0,8:18
-5,1,8:18
-4,1,8:18
-2,1,8:18
-7,2,8:18
-6,2,8:18
-5,2,8:18
-3,2,8:18
-5,3,8:18
-4,3,8:17
-3,3,8:17
-5,4,8:18
-4,4,8:18
-3,4,8:18
0,5,8:18
-7,6,8:18
0,7,8:18
-4,8,8:18
-3,8,8:18
-2,8,8:18
-1,8,8:18
-5,9,8:18
-3,9,8:18
-2,9,8:18
-1,9,8:18
0,9,8:18
-2,10,8:18
-3,-4,9:18
-4,-3,9:18
-6,-2,9:18
-6,-1,9:18
-3,-1,9:18
-5,0,9:18
-4,1,9:18
-4,3,9:17
-4,4,9:17
-4,5,9:18
-6,6,9:18
-3,6,9:18
-1,6,9:18
-7,7,9:18
-5,7,9:18
-4,7,9:18
-3,7,9:18
-4,8,9:18
-2,8,9:18
-5,9,9:18
-3,9,9:18
-2,9,9:18
-5,10,9:18
-4,-2,10:18
-5,-1,10:18
-6,4,10:18
-4,4,10:17
-7,5,10:18
-4,5,10:18
-7,6,10:18
-6,6,10:18
-4,7,10:18
-2,7,10:18
-5,8,10:18
-4,8,10:18
-5,9,10:18
-4,1,11:18
-2,3,11:18
-6,4,11:18
-5,4,11:18
-4,4,11:17
-7,5,11:18
-5,5,11:18
-7,6,11:18
-6,6,11:18
-5,6,11:18
-5,7,11:18
-5,1,12:18
-6,2,12:18
-4,2,12:18
-3,2,12:18
-7,3,12:18
-6,3,12:18
-8,4,12:18
-5,4,12:18
-4,4,12:17
-3,4,12:18
-8,5,12:18
-6,5,12:18
-4,5,12:18
-3,5,12:18
-6,6,12:18
-5,6,12:18
-3,6,12:18
-4,7,12:18
-6,8,12:18
-4,8,12:18
-4,1,13:18
-7,2,13:18
-4,2,13:18
-8,3,13:18
-7,3,13:18
-6,3,13:18
-4,3,13:18
-3,3,13:18
-5,4,13:18
-4,4,13:18
-3,4,13:18
-7,5,13:18
-5,5,13:18
-3,5,13:18
-8,6,13:18
-7,6,13:18
-6,6,13:18
-4,6,13:18
-6,7,13:18
-6,9,13:18
-7,2,14:18
-6,3,14:18
-5,3,14:18
-3,3,14:18
-5,4,14:18
-5,5,14:18
-3,5,14:18
-2,5,14:18
-9,6,14:18
-8,6,14:18
-7,6,14:18
-3,6,14:18
-7,7,14:18
-6,7,14:18
-7,8,14:18
-4,8,14:18
-6,2,15:18
-5,3,15:18
-3,3,15:18
-3,4,15:18
-6,5,15:18
-6,6,15:18
-4,3,16:18
