[META]
version=2.0
spawnOnBlockType=2
spawnSunlight=True
spawnDarkness=False
spawnWater=False
spawnLava=False
underFill=True
randomRotation=True
dig=True
tree=False
branch=False
needsFoundation=True
rarity=10
collisionPercentage=2
spawnElevationMin=0
spawnElevationMax=128
spawnInBiome=All
[DATA]
0,0,0:17
-1,1,0:17
-1,2,0:17
-3,0,1:18
-1,1,1:17
0,1,1:18
-1,2,1:18
-1,3,1:18
-3,-2,2:18
-2,-2,2:18
-1,-2,2:18
-2,-1,2:18
0,-1,2:18
-4,0,2:18
-3,0,2:18
-2,0,2:18
-1,0,2:18
-4,1,2:18
-2,1,2:18
-1,1,2:17
1,1,2:18
-4,2,2:18
-3,2,2:18
0,2,2:18
-2,3,2:18
-2,4,2:18
-1,4,2:18
0,4,2:18
-5,-1,3:18
-4,-1,3:18
-2,-1,3:18
1,-1,3:18
-2,0,3:17
-1,0,3:18
0,0,3:18
-4,1,3:18
-3,1,3:18
0,1,3:18
1,1,3:18
2,1,3:18
-4,2,3:18
-3,2,3:18
-1,2,3:17
0,2,3:18
1,2,3:18
-2,3,3:18
-1,3,3:18
-2,4,3:18
-1,4,3:18
0,4,3:18
1,4,3:18
-2,-3,4:18
-2,-2,4:18
0,-2,4:18
-4,-1,4:18
-3,-1,4:18
-2,-1,4:18
-1,-1,4:18
0,-1,4:18
1,-1,4:18
-4,0,4:18
-2,0,4:17
0,0,4:18
1,0,4:18
2,0,4:18
-3,1,4:18
0,1,4:18
-4,2,4:18
-3,2,4:18
-2,2,4:18
-1,2,4:18
0,2,4:18
1,2,4:18
2,2,4:18
-4,3,4:18
-2,3,4:18
-1,3,4:17
0,3,4:18
2,3,4:18
-3,4,4:18
-2,4,4:18
-1,4,4:18
-2,5,4:18
-1,5,4:18
-3,-3,5:18
-3,-2,5:18
-2,-1,5:18
-1,0,5:18
1,0,5:18
-4,1,5:18
-2,1,5:18
-3,2,5:18
-2,3,5:18
-1,3,5:18
0,3,5:18
-3,4,5:18
0,4,5:18
-1,5,5:18
-1,0,6:18
0,0,6:18
-1,1,6:18
0,1,6:18
1,1,6:18
-2,2,6:18
-1,2,6:18
0,2,6:18
1,2,6:18
1,3,6:18
-3,4,6:18
1,4,6:18
-1,1,7:18
0,2,7:18
