[META]
version=2.0
spawnOnBlockType=2
spawnSunlight=True
spawnDarkness=False
spawnWater=False
spawnLava=False
underFill=True
randomRotation=True
dig=True
tree=False
branch=False
needsFoundation=True
rarity=10
collisionPercentage=2
spawnElevationMin=0
spawnElevationMax=128
spawnInBiome=All
[DATA]
-1,1,0:17.0
-1,1,1:17.0
-1,1,2:17.0
-1,1,3:17.0
-1,1,4:17.0
-1,1,5:17.0
-1,1,6:17.0
-1,1,7:17.0
-1,1,8:17.0
-1,1,9:17.0
-1,1,10:17.0
-1,1,11:17.0
-1,1,12:17.0
-1,1,13:17.0
-1,1,14:17.0
-1,-2,15:18
-1,1,15:17.0
-2,-3,16:18
-1,1,16:17.0
-2,-4,17:18
-3,-3,17:18
-2,-3,17:18
-1,-3,17:18
-2,-2,17:17
-4,-1,17:18
-2,-1,17:18
-1,-1,17:17
-2,0,17:18
-1,0,17:17
-1,1,17:17.0
-1,-4,18:18
-4,-3,18:18
-2,-3,18:18
-2,-2,18:18
-1,-2,18:18
-1,-1,18:18
-2,0,18:18
-1,1,18:17.0
0,1,18:18
-3,2,18:18
-2,2,18:18
-1,2,18:17
-2,3,18:18
-1,3,18:18
1,3,18:18
0,4,18:18
-2,5,18:18
-1,5,18:18
-2,-3,19:18
-2,-2,19:18
-2,-1,19:18
1,-1,19:18
-1,0,19:18
0,0,19:18
-2,1,19:18
-1,1,19:17.0
-2,2,19:18
-1,3,19:17
0,3,19:18
-3,4,19:18
-1,4,19:18
0,-2,20:18
-2,-1,20:18
0,-1,20:18
-1,0,20:18
0,0,20:17
1,0,20:18
2,0,20:18
-4,1,20:18
-1,1,20:17.0
0,1,20:18
1,2,20:18
-3,3,20:18
-1,3,20:18
0,3,20:18
-3,4,20:18
-2,4,20:18
1,4,20:18
-2,-1,21:18
-1,-1,21:18
0,-1,21:18
-2,1,21:17
-1,1,21:17.0
0,1,21:18
-3,2,21:18
-1,2,21:18
-1,3,21:18
-2,-2,22:18
0,-2,22:18
-3,-1,22:18
-2,-1,22:18
-1,-1,22:18
1,-1,22:18
-4,0,22:18
-3,0,22:18
-1,0,22:18
0,0,22:18
1,0,22:18
-3,1,22:18
-1,1,22:17.0
0,1,22:18
0,2,22:17
-2,3,22:18
0,-2,23:18
-2,-1,23:18
-1,-1,23:18
0,-1,23:18
-3,0,23:18
-1,0,23:17
0,0,23:18
-2,1,23:18
-1,1,23:17.0
-2,2,23:18
-1,2,23:18
-1,-2,24:18
0,-2,24:18
-1,0,24:18
-3,1,24:18
-1,1,24:17.0
0,1,24:18
-1,2,24:18
-1,-1,25:18
-2,0,25:18
1,0,25:18
-1,1,25:17.0
1,1,25:18
-1,2,25:18
0,2,25:18
-2,3,25:18
-2,-1,26:18
-1,-1,26:18
-1,0,26:18
-3,1,26:18
-1,1,26:17.0
0,1,26:18
1,1,26:18
-3,2,26:18
-2,2,26:18
-1,3,26:18
0,-1,27:18
-1,0,27:18
-2,1,27:18
0,2,27:18
-2,0,28:18
-2,1,28:18
-1,1,28:18
-1,2,28:18
