[META]
version=2.0
spawnOnBlockType=2
spawnSunlight=True
spawnDarkness=False
spawnWater=False
spawnLava=False
underFill=True
randomRotation=True
dig=True
tree=False
branch=False
needsFoundation=True
rarity=10
collisionPercentage=2
spawnElevationMin=0
spawnElevationMax=128
spawnInBiome=All
[DATA]
-2,3,0:17
-2,3,1:17
0,-2,2:18
-6,-1,2:18
-5,-1,2:18
-2,-1,2:18
0,-1,2:18
2,-1,2:18
1,0,2:18
4,0,2:18
-7,1,2:18
-6,1,2:18
-5,1,2:18
2,1,2:18
3,1,2:18
-3,2,2:18
-2,2,2:18
-1,2,2:18
0,2,2:18
1,2,2:18
-6,3,2:18
-2,3,2:17
-6,6,2:18
-5,6,2:18
-6,7,2:18
-1,7,2:18
-3,8,2:18
-3,9,2:18
-2,9,2:18
-1,-5,3:18
0,-5,3:18
-2,-4,3:18
1,-4,3:18
-2,-3,3:18
-4,-2,3:18
-3,-2,3:18
0,-2,3:18
3,-2,3:18
-3,-1,3:18
-6,0,3:18
-5,0,3:18
-4,0,3:18
-3,0,3:18
-2,0,3:18
3,0,3:18
-8,1,3:18
-3,1,3:18
-2,1,3:18
-1,1,3:18
0,1,3:18
1,1,3:18
-7,2,3:18
-4,2,3:18
-2,2,3:17
-1,2,3:18
0,2,3:18
1,2,3:18
3,2,3:18
4,2,3:18
-8,3,3:18
-4,3,3:18
-3,3,3:18
-2,3,3:17
-1,3,3:18
0,3,3:18
-4,4,3:18
-3,4,3:17
-1,4,3:18
0,4,3:18
-8,5,3:18
-4,5,3:18
-2,5,3:18
1,5,3:18
-7,6,3:18
-4,6,3:18
-3,6,3:18
2,6,3:18
-3,7,3:18
-4,8,3:18
-3,8,3:18
-1,8,3:18
0,8,3:18
-3,9,3:18
-2,9,3:18
1,-5,4:18
-4,-4,4:18
-3,-4,4:18
-2,-4,4:18
0,-4,4:18
-6,-3,4:18
-2,-3,4:18
-1,-3,4:18
3,-3,4:18
-7,-2,4:18
-3,-2,4:18
0,-2,4:18
1,-2,4:18
2,-2,4:18
-6,-1,4:18
-4,-1,4:18
-3,-1,4:18
-2,-1,4:18
2,-1,4:18
3,-1,4:18
-6,0,4:18
-4,0,4:18
-3,0,4:18
-2,0,4:18
-1,0,4:18
0,0,4:18
2,0,4:18
4,0,4:18
-6,1,4:18
-5,1,4:18
-3,1,4:18
-2,1,4:17
0,1,4:18
1,1,4:18
2,1,4:18
-8,2,4:18
-4,2,4:18
-2,2,4:18
1,2,4:18
2,2,4:18
4,2,4:18
-9,3,4:18
-8,3,4:18
-6,3,4:18
-3,3,4:18
-2,3,4:17
-1,3,4:18
1,3,4:18
5,3,4:18
-7,4,4:18
-4,4,4:18
-3,4,4:18
-2,4,4:18
-1,4,4:17
0,4,4:18
4,4,4:18
-6,5,4:18
-4,5,4:17
-3,5,4:18
-2,5,4:18
0,5,4:18
1,5,4:18
3,5,4:18
-7,6,4:18
-6,6,4:18
-5,6,4:18
-2,6,4:18
0,6,4:18
1,6,4:18
-7,7,4:18
-6,7,4:18
-5,7,4:18
-3,7,4:18
-5,8,4:18
-3,9,4:18
0,9,4:18
-3,10,4:18
-4,-4,5:18
0,-4,5:18
2,-4,5:18
-3,-3,5:18
-2,-3,5:18
0,-3,5:18
2,-3,5:18
-8,-2,5:18
-6,-2,5:18
-5,-2,5:18
-4,-2,5:18
-3,-2,5:18
-1,-2,5:18
-5,-1,5:18
-4,-1,5:18
-3,-1,5:18
-2,-1,5:18
-1,-1,5:18
-9,0,5:18
-8,0,5:18
-7,0,5:18
-6,0,5:18
-5,0,5:18
-3,0,5:17
-1,0,5:18
0,0,5:18
1,0,5:18
-8,1,5:18
-7,1,5:18
-5,1,5:18
-4,1,5:18
-3,1,5:18
-2,1,5:18
-1,1,5:18
0,1,5:18
1,1,5:18
5,1,5:18
-6,2,5:18
-5,2,5:18
-4,2,5:18
-2,2,5:18
-1,2,5:18
0,2,5:18
2,2,5:18
-9,3,5:18
-8,3,5:18
-7,3,5:18
-6,3,5:18
-5,3,5:18
-4,3,5:18
-3,3,5:18
-2,3,5:17
-1,3,5:18
0,3,5:18
1,3,5:18
2,3,5:18
-5,4,5:18
-4,4,5:18
-3,4,5:18
-2,4,5:18
-1,4,5:18
0,4,5:18
1,4,5:18
-8,5,5:18
-5,5,5:18
-4,5,5:18
-3,5,5:18
-2,5,5:18
0,5,5:17
1,5,5:18
-6,6,5:18
-5,6,5:17
-4,6,5:18
-3,6,5:18
-2,6,5:18
-1,6,5:18
0,6,5:18
1,6,5:18
3,6,5:18
-7,7,5:18
-5,7,5:18
-4,7,5:18
-3,7,5:18
-2,7,5:18
-1,7,5:18
1,7,5:18
-4,8,5:18
-3,8,5:18
-2,8,5:18
-1,8,5:18
0,8,5:18
1,8,5:18
2,8,5:18
3,8,5:18
-6,9,5:18
-5,9,5:18
-4,9,5:18
-1,9,5:18
1,9,5:18
-3,10,5:18
-2,10,5:18
-1,10,5:18
-3,11,5:18
-4,-4,6:18
-3,-4,6:18
-6,-3,6:18
-4,-3,6:18
-3,-3,6:18
-2,-3,6:18
0,-3,6:18
-6,-2,6:18
-1,-2,6:18
-9,-1,6:18
-8,-1,6:18
-7,-1,6:18
-6,-1,6:18
-5,-1,6:18
-4,-1,6:17
-3,-1,6:18
-2,-1,6:18
-1,-1,6:18
0,-1,6:18
-7,0,6:18
-6,0,6:18
-5,0,6:18
-4,0,6:18
-3,0,6:18
-2,0,6:18
-1,0,6:18
2,0,6:18
-7,1,6:18
-6,1,6:18
-5,1,6:18
-4,1,6:18
-3,1,6:18
-1,1,6:18
0,1,6:18
2,1,6:18
-6,2,6:18
-5,2,6:18
-4,2,6:18
-3,2,6:18
-2,2,6:18
-1,2,6:18
0,2,6:18
1,2,6:18
2,2,6:18
4,2,6:18
-5,3,6:18
-4,3,6:18
-3,3,6:18
-2,3,6:17
-1,3,6:18
0,3,6:18
1,3,6:18
2,3,6:18
-5,4,6:18
-4,4,6:18
-3,4,6:18
-2,4,6:18
-1,4,6:18
0,4,6:18
1,4,6:18
2,4,6:18
3,4,6:18
-6,5,6:18
-3,5,6:18
-2,5,6:18
-1,5,6:18
1,5,6:18
2,5,6:18
3,5,6:18
4,5,6:18
-7,6,6:18
-4,6,6:18
-3,6,6:18
-2,6,6:18
-1,6,6:18
0,6,6:18
1,6,6:17
3,6,6:18
-8,7,6:18
-7,7,6:18
-6,7,6:18
-5,7,6:18
-2,7,6:18
-1,7,6:18
1,7,6:18
2,7,6:18
-5,8,6:18
-1,8,6:18
0,8,6:18
-6,9,6:18
-4,9,6:18
0,9,6:18
2,9,6:18
-4,10,6:18
-4,-4,7:18
0,-3,7:18
-9,-2,7:18
-4,-2,7:18
-2,-2,7:18
-1,-2,7:18
-6,-1,7:18
-5,-1,7:18
-3,-1,7:18
-7,0,7:18
-6,0,7:18
-4,0,7:18
-2,0,7:18
-1,0,7:18
-8,1,7:18
-6,1,7:18
-5,1,7:18
-4,1,7:18
-3,1,7:18
-2,1,7:18
-1,1,7:18
0,1,7:18
-7,2,7:18
-6,2,7:18
-5,2,7:18
-3,2,7:18
-2,2,7:18
0,2,7:18
-5,3,7:18
-3,3,7:18
-2,3,7:18
-1,3,7:18
1,3,7:18
-7,4,7:18
-5,4,7:18
-4,4,7:18
-3,4,7:18
-2,4,7:18
-1,4,7:18
-6,5,7:18
-4,5,7:18
-3,5,7:18
-2,5,7:18
-1,5,7:18
1,5,7:18
-5,6,7:18
-4,6,7:18
-3,6,7:18
-2,6,7:18
-1,6,7:18
-5,7,7:18
-4,7,7:18
1,7,7:18
-5,8,7:18
-3,8,7:18
0,8,7:18
-4,9,7:18
-3,9,7:18
0,9,7:18
2,9,7:18
-6,-3,8:18
-3,-3,8:18
-6,-2,8:18
-4,-2,8:18
-3,-2,8:18
-2,-1,8:18
-6,0,8:18
-5,0,8:18
-4,0,8:18
-3,0,8:18
-8,1,8:18
-6,1,8:18
-5,1,8:18
-4,1,8:18
-3,1,8:18
-2,1,8:18
-1,1,8:18
1,1,8:18
-7,2,8:18
-6,2,8:18
-5,2,8:18
-4,2,8:18
-2,2,8:18
-1,2,8:18
0,2,8:18
-6,3,8:18
-5,3,8:18
-4,3,8:18
-3,3,8:18
-2,3,8:18
-1,3,8:18
0,3,8:18
-7,4,8:18
-5,4,8:18
-4,4,8:18
-3,4,8:18
-2,4,8:18
-1,4,8:18
-7,5,8:18
-5,5,8:18
-3,5,8:18
-2,5,8:18
-1,5,8:18
-6,6,8:18
-5,6,8:18
-4,6,8:18
-3,6,8:18
0,6,8:18
-5,7,8:18
1,7,8:18
-3,8,8:18
-2,8,8:18
-2,9,8:18
-4,-2,9:18
-3,-2,9:18
-2,0,9:18
-4,1,9:18
-3,1,9:18
-2,1,9:18
0,1,9:18
-5,2,9:18
-4,2,9:18
-2,2,9:18
1,2,9:18
-5,3,9:18
-4,3,9:18
-3,3,9:18
-2,3,9:18
-1,3,9:18
-7,4,9:18
-6,4,9:18
-5,4,9:18
-4,4,9:18
-3,4,9:18
-2,4,9:18
0,4,9:18
-8,5,9:18
-5,5,9:18
-3,5,9:18
-1,5,9:18
1,5,9:18
2,5,9:18
-3,6,9:18
1,6,9:18
2,6,9:18
-5,7,9:18
-4,7,9:18
1,7,9:18
-2,0,10:18
-5,1,10:18
-4,1,10:18
-3,1,10:18
-2,1,10:18
-7,2,10:18
-4,2,10:18
-7,3,10:18
-6,3,10:18
-5,3,10:18
-3,3,10:18
-2,3,10:18
1,3,10:18
-6,4,10:18
-5,4,10:18
-4,4,10:18
-2,5,10:18
-1,5,10:18
0,5,10:18
-2,6,10:18
-3,1,11:18
-2,1,11:18
-3,2,11:18
-2,2,11:18
-3,3,11:18
-4,4,11:18
-3,4,11:18
-1,4,11:18
-4,5,11:18
-2,5,11:18
-2,2,12:18
-4,3,12:18
-3,3,12:18
