[META]
version=2.0
spawnOnBlockType=2
spawnSunlight=True
spawnDarkness=False
spawnWater=False
spawnLava=False
underFill=True
randomRotation=True
dig=True
tree=False
branch=False
needsFoundation=True
rarity=10
collisionPercentage=2
spawnElevationMin=0
spawnElevationMax=128
spawnInBiome=All
[DATA]
-1,0,0:17.0
-1,0,1:17.0
-1,0,2:17
-5,-6,3:18
-2,-6,3:18
-6,-5,3:18
-5,-5,3:18
-2,-5,3:18
-7,-4,3:18
-6,-4,3:18
-5,-4,3:18
-4,-4,3:18
-3,-4,3:18
-2,-4,3:18
-1,-4,3:18
0,-4,3:18
1,-4,3:18
-7,-3,3:18
-6,-3,3:18
-5,-3,3:18
-4,-3,3:18
-3,-3,3:18
-2,-3,3:18
-1,-3,3:18
0,-3,3:18
1,-3,3:18
2,-3,3:18
-6,-2,3:18
-5,-2,3:18
-4,-2,3:18
-3,-2,3:18
-2,-2,3:18
-1,-2,3:17
0,-2,3:18
1,-2,3:18
2,-2,3:18
-5,-1,3:18
-4,-1,3:18
-3,-1,3:18
-2,-1,3:18
-1,-1,3:17
0,-1,3:18
1,-1,3:18
-6,0,3:18
-5,0,3:18
-4,0,3:18
-3,0,3:18
-2,0,3:18
-1,0,3:17
0,0,3:18
1,0,3:18
-4,1,3:18
-4,2,3:18
-4,-5,4:18
-6,-4,4:18
-4,-4,4:18
-3,-4,4:18
-2,-4,4:18
-5,-3,4:18
-4,-3,4:18
-3,-3,4:18
-2,-3,4:18
0,-3,4:18
-5,-2,4:18
-4,-2,4:18
-3,-2,4:18
-2,-2,4:18
-1,-2,4:18
-5,-1,4:18
-4,-1,4:18
-3,-1,4:18
-2,-1,4:18
-1,-1,4:18
0,-1,4:18
2,-1,4:18
-3,0,4:18
-2,0,4:18
-1,0,4:17
0,0,4:18
2,0,4:18
-3,1,4:18
-1,1,4:18
0,1,4:18
1,1,4:18
-2,2,4:18
0,-3,5:18
-1,-2,5:18
0,-2,5:18
1,-2,5:18
2,-2,5:18
0,-1,5:17
2,-1,5:18
-2,0,5:18
-1,0,5:17
0,0,5:18
1,0,5:18
-2,1,5:17
0,1,5:18
1,1,5:18
-4,2,5:18
-3,2,5:18
-2,2,5:18
0,2,5:18
1,2,5:18
2,2,5:18
3,2,5:18
4,2,5:18
-2,3,5:18
-1,3,5:18
0,3,5:18
1,3,5:18
2,3,5:18
5,3,5:18
0,4,5:18
1,4,5:18
2,4,5:18
3,4,5:18
4,4,5:18
5,4,5:18
1,5,5:18
2,5,5:18
3,5,5:18
1,6,5:18
2,6,5:18
3,-6,6:18
3,-5,6:18
4,-5,6:18
1,-4,6:18
2,-4,6:18
3,-4,6:18
4,-4,6:18
5,-4,6:18
-3,-3,6:18
0,-3,6:18
2,-3,6:18
3,-3,6:18
4,-3,6:18
5,-3,6:18
6,-3,6:18
7,-3,6:18
-4,-2,6:18
-3,-2,6:17
-2,-2,6:18
0,-2,6:18
1,-2,6:18
2,-2,6:18
3,-2,6:18
4,-2,6:18
5,-2,6:18
6,-2,6:18
7,-2,6:18
-3,-1,6:18
-2,-1,6:17
-1,-1,6:18
0,-1,6:18
1,-1,6:17
2,-1,6:18
3,-1,6:18
4,-1,6:18
5,-1,6:18
-3,0,6:18
-2,0,6:18
-1,0,6:17
0,0,6:17
1,0,6:18
2,0,6:18
3,0,6:18
4,0,6:18
5,0,6:18
-3,1,6:18
-1,1,6:18
0,1,6:18
1,1,6:18
2,1,6:18
3,1,6:18
-2,2,6:18
-1,2,6:18
2,2,6:18
1,3,6:18
2,3,6:18
0,4,6:18
2,5,6:18
3,5,6:18
-4,-4,7:18
-3,-3,7:18
-2,-3,7:18
-1,-3,7:18
0,-3,7:18
3,-3,7:18
-6,-2,7:18
-5,-2,7:18
-4,-2,7:18
-3,-2,7:18
-2,-2,7:18
-1,-2,7:18
0,-2,7:18
1,-2,7:18
2,-2,7:18
-5,-1,7:18
-4,-1,7:18
-3,-1,7:18
-2,-1,7:18
-1,-1,7:18
0,-1,7:18
1,-1,7:18
2,-1,7:18
3,-1,7:18
4,-1,7:18
5,-1,7:18
6,-1,7:18
-3,0,7:18
-2,0,7:18
-1,0,7:17
0,0,7:18
1,0,7:18
2,0,7:18
3,0,7:18
4,0,7:18
-3,1,7:18
-2,1,7:18
-1,1,7:18
0,1,7:18
1,1,7:18
2,1,7:18
3,1,7:18
5,1,7:18
-3,2,7:18
-2,2,7:18
-1,2,7:18
0,2,7:18
-4,3,7:18
-3,3,7:18
-2,3,7:18
-1,3,7:18
0,3,7:17
1,3,7:18
-5,4,7:18
-4,4,7:18
-3,4,7:18
-2,4,7:18
0,4,7:18
-5,5,7:18
-3,5,7:18
-2,5,7:18
-1,5,7:18
0,5,7:18
1,5,7:18
2,5,7:18
-3,6,7:18
-3,7,7:18
-1,-2,8:18
-1,-1,8:18
1,-1,8:18
-2,0,8:18
-1,0,8:17
1,0,8:18
-2,1,8:18
-1,1,8:17
0,1,8:18
1,1,8:18
2,1,8:18
-3,2,8:18
-2,2,8:18
-1,2,8:18
0,2,8:17
2,2,8:18
3,2,8:18
-2,3,8:18
0,3,8:18
1,3,8:18
2,3,8:18
-3,4,8:18
-2,4,8:18
-1,4,8:18
0,4,8:18
1,4,8:18
-1,5,8:18
0,5,8:18
-1,6,8:18
0,6,8:18
0,-6,9:18
0,-5,9:18
1,-5,9:18
2,-5,9:18
3,-5,9:18
4,-5,9:18
2,-4,9:18
3,-4,9:18
4,-4,9:18
0,-3,9:18
2,-3,9:17
3,-3,9:18
4,-3,9:18
-2,-2,9:18
0,-2,9:18
2,-2,9:18
3,-2,9:18
-2,-1,9:18
-1,-1,9:18
3,-1,9:18
-2,0,9:18
-1,0,9:17
0,0,9:18
1,0,9:18
-1,2,9:18
1,-4,10:18
2,-4,10:18
-1,-3,10:18
1,-3,10:18
-1,-2,10:18
1,-2,10:17
2,-2,10:18
-1,-1,10:18
0,-1,10:17
1,-1,10:18
2,-1,10:18
-1,0,10:17
0,0,10:18
1,0,10:18
2,0,10:18
3,0,10:18
-1,1,10:18
1,1,10:18
3,1,10:18
-4,-2,11:18
-6,0,11:18
-5,0,11:18
-4,0,11:17
-2,0,11:18
-1,0,11:17
-7,1,11:18
-6,1,11:18
-5,1,11:18
-4,1,11:18
-5,2,11:18
-4,2,11:18
-1,-4,12:18
0,-4,12:18
1,-4,12:18
-5,-3,12:18
-4,-3,12:18
-3,-3,12:18
-2,-3,12:18
0,-3,12:18
-3,-2,12:18
-2,-2,12:18
-1,-2,12:18
0,-2,12:18
2,-2,12:18
-6,-1,12:18
-4,-1,12:18
-3,-1,12:18
-2,-1,12:18
0,-1,12:18
1,-1,12:18
2,-1,12:18
-5,0,12:18
-4,0,12:18
-3,0,12:17
-2,0,12:17
-1,0,12:17
0,0,12:18
1,0,12:18
-4,1,12:18
-3,1,12:18
-2,1,12:18
-4,2,12:18
-2,2,12:18
-3,3,12:18
1,-4,13:18
-3,-3,13:18
-2,-2,13:18
-1,-2,13:18
0,-2,13:18
1,-2,13:18
2,-2,13:18
-2,-1,13:18
2,-1,13:18
-3,0,13:18
-2,0,13:18
-1,0,13:17
0,0,13:18
-2,1,13:18
-1,1,13:18
0,1,13:18
-2,2,13:18
2,-1,14:18
4,-1,14:18
-1,0,14:17
2,0,14:18
3,0,14:18
1,1,14:18
2,1,14:18
3,1,14:18
4,1,14:18
1,2,14:18
2,2,14:18
4,2,14:18
1,3,14:18
2,3,14:17
3,3,14:18
4,3,14:18
2,4,14:18
3,4,14:18
2,5,14:18
3,5,14:18
0,-1,15:18
-5,0,15:18
-4,0,15:18
-3,0,15:18
-2,0,15:18
-1,0,15:17
1,0,15:18
2,0,15:18
-3,1,15:18
-2,1,15:18
-1,1,15:18
0,1,15:17
1,1,15:18
-4,2,15:18
-3,2,15:18
-2,2,15:18
-1,2,15:18
0,2,15:18
1,2,15:17
2,2,15:18
-4,3,15:18
-2,3,15:18
-1,3,15:18
0,3,15:18
1,3,15:18
3,3,15:18
-3,4,15:18
1,4,15:18
-2,5,15:18
0,-6,16:18
2,-6,16:18
2,-5,16:18
3,-5,16:18
-1,-4,16:18
0,-4,16:18
1,-4,16:18
2,-4,16:18
0,-3,16:18
1,-3,16:18
3,-3,16:18
-1,-2,16:18
0,-2,16:18
1,-2,16:18
2,-2,16:18
3,-2,16:18
-2,-1,16:18
-1,-1,16:18
0,-1,16:18
1,-1,16:18
3,-1,16:18
-3,0,16:18
-2,0,16:18
-1,0,16:17
1,0,16:18
2,0,16:18
3,0,16:18
0,1,16:18
-2,2,16:18
0,2,16:18
1,2,16:18
2,2,16:18
1,-5,17:18
-1,-3,17:18
0,-3,17:18
1,-3,17:18
2,-3,17:18
-2,-2,17:18
-1,-2,17:18
-3,-1,17:18
-1,-1,17:17
0,-1,17:18
-3,0,17:18
-1,0,17:17
0,0,17:18
1,0,17:18
1,1,17:18
-1,-2,18:18
-1,-1,18:18
1,-1,18:18
-3,0,18:18
-2,0,18:18
-1,0,18:17
0,0,18:18
-1,1,18:18
-3,2,18:18
-1,2,18:18
1,2,18:18
-1,3,18:18
1,3,18:18
-1,4,18:18
-1,-4,19:18
-1,-3,19:18
-3,-2,19:18
-2,-2,19:18
-2,-1,19:18
-1,-1,19:18
0,-1,19:18
-3,0,19:18
-2,0,19:17
-1,0,19:17
-3,1,19:18
-2,1,19:18
0,1,19:18
-3,2,19:18
0,-3,20:18
0,-2,20:18
-1,-1,20:18
0,-1,20:17
-1,0,20:17
0,1,20:18
-2,-3,21:18
-1,-3,21:18
-4,-2,21:18
-1,-2,21:18
-4,-1,21:18
-3,-1,21:18
-2,-1,21:18
-1,-1,21:18
0,-1,21:18
-4,0,21:18
-3,0,21:18
-2,0,21:18
-1,0,21:17
0,0,21:18
-4,1,21:18
-3,1,21:18
-2,1,21:18
-1,1,21:17
0,1,21:18
1,1,21:18
-1,2,21:18
1,2,21:18
-2,-1,22:18
-1,-1,22:18
-2,0,22:18
-1,0,22:18
0,0,22:18
-1,1,22:18
0,1,22:18
-2,0,23:18
-1,0,23:18
0,0,23:18
-1,0,24:18
