[META]
version=2.0
spawnOnBlockType=2
spawnSunlight=True
spawnDarkness=False
spawnWater=False
spawnLava=False
underFill=True
randomRotation=True
dig=True
tree=False
branch=False
needsFoundation=True
rarity=10
collisionPercentage=2
spawnElevationMin=0
spawnElevationMax=128
spawnInBiome=All
[DATA]
0,-1,0:85
1,-1,0:85
0,0,0:85
1,0,0:85
1,-2,1:18
-1,-1,1:18
0,-1,1:85
1,-1,1:18
-1,0,1:85
0,0,1:18
1,0,1:85
-1,1,1:18
1,2,1:18
0,-3,2:18
1,-3,2:85
-1,-2,2:18
0,-2,2:85
2,-2,2:18
-1,-1,2:18
1,-1,2:18
-1,0,2:18
0,0,2:85
1,0,2:18
2,0,2:18
-2,1,2:18
0,1,2:85
1,1,2:18
3,1,2:18
1,2,2:18
2,2,2:85
0,3,2:18
1,3,2:85
0,-3,3:18
1,-3,3:18
-2,-2,3:18
-1,-2,3:18
0,-2,3:18
1,-2,3:18
2,-2,3:18
-1,-1,3:85
0,-1,3:18
2,-1,3:18
3,-1,3:18
-2,0,3:85
-1,0,3:85
1,0,3:18
2,0,3:18
3,0,3:18
-1,1,3:18
0,1,3:18
1,1,3:18
3,1,3:18
-2,2,3:85
0,2,3:85
2,2,3:18
1,3,3:85
2,3,3:18
1,-3,4:18
1,-2,4:18
3,-2,4:18
-2,-1,4:85
-1,-1,4:18
1,-1,4:18
2,-1,4:18
-2,0,4:18
-1,0,4:18
1,0,4:85
2,0,4:85
3,0,4:85
-1,1,4:85
-2,2,4:85
0,2,4:18
1,2,4:18
1,3,4:18
-2,-2,5:18
0,-2,5:18
2,-2,5:18
-2,-1,5:18
-1,-1,5:85
-1,0,5:18
0,0,5:18
1,0,5:18
2,0,5:85
3,0,5:18
-1,1,5:18
0,1,5:85
2,1,5:18
-2,2,5:18
-1,2,5:85
1,2,5:18
3,2,5:18
-1,3,5:18
-1,-1,6:18
0,-1,6:18
1,-1,6:85
-1,0,6:85
0,0,6:18
1,0,6:18
2,0,6:18
-1,1,6:18
0,1,6:85
-1,2,6:18
0,3,6:18
1,-1,7:18
-1,0,7:18
0,1,7:18
