[META]
version=2.0
spawnOnBlockType=2
spawnSunlight=True
spawnDarkness=False
spawnWater=False
spawnLava=False
underFill=True
randomRotation=True
dig=True
tree=False
branch=False
needsFoundation=True
rarity=10
collisionPercentage=2
spawnElevationMin=0
spawnElevationMax=128
spawnInBiome=All
[DATA]
-1,0,0:17
-3,1,0:17
-2,1,0:17
-1,1,0:17
-1,2,0:17
0,2,0:17
-1,3,0:17
-2,1,1:17
-1,1,1:17
-1,2,1:17
-4,4,1:18
-6,-2,2:18
-4,-2,2:18
-7,-1,2:18
-3,0,2:17
-4,1,2:18
-2,1,2:17
-1,1,2:17
-5,2,2:18
-1,2,2:17
-4,4,2:18
-3,-5,3:18
-3,-4,3:18
-2,-4,3:18
-4,-3,3:18
-1,-3,3:18
-6,-2,3:18
-5,-2,3:18
-4,-2,3:17
-2,-2,3:18
-6,-1,3:18
-4,-1,3:18
-3,-1,3:17
-1,-1,3:18
-2,0,3:18
-1,0,3:17
-3,1,3:18
-2,1,3:18
0,1,3:17
-2,2,3:17
0,2,3:18
-4,3,3:18
-2,3,3:17
-4,4,3:18
-4,5,3:18
-4,6,3:18
-2,7,3:18
-5,-4,4:18
-4,-4,4:18
-5,-2,4:18
-1,-1,4:18
-2,0,4:18
-1,0,4:17
0,0,4:18
-2,1,4:18
0,1,4:18
-1,2,4:18
0,2,4:17
1,2,4:18
-3,4,4:17
-2,4,4:18
-1,4,4:18
-1,6,4:18
-4,7,4:18
-3,7,4:18
-2,7,4:18
-4,-4,5:18
-2,-4,5:18
0,-2,5:18
-4,-1,5:18
1,-1,5:18
-6,0,5:18
-3,0,5:18
-1,0,5:17
1,0,5:18
2,0,5:18
-3,1,5:18
-2,1,5:18
0,2,5:17
3,2,5:18
-6,3,5:18
-5,3,5:18
-3,3,5:18
-1,3,5:18
-4,4,5:18
-5,5,5:18
-1,5,5:18
0,5,5:18
1,5,5:18
-4,6,5:18
-2,6,5:18
-3,7,5:18
3,-3,6:18
-5,-2,6:18
-4,-2,6:18
-3,-2,6:18
-1,-2,6:18
0,-2,6:18
3,-2,6:18
-2,-1,6:18
-1,-1,6:18
0,-1,6:17
-2,0,6:17
-1,0,6:18
0,0,6:18
1,0,6:18
-2,1,6:18
-1,1,6:18
0,1,6:18
1,1,6:18
-2,2,6:18
-1,2,6:18
0,2,6:17
1,2,6:18
2,2,6:18
3,2,6:18
-5,3,6:18
-3,3,6:18
-2,3,6:18
-1,3,6:18
3,3,6:18
-1,6,6:18
1,-4,7:18
-1,-3,7:18
-2,-2,7:18
0,-2,7:18
1,-2,7:18
4,-2,7:18
-1,-1,7:18
0,-1,7:17
1,-1,7:18
4,-1,7:18
-4,0,7:18
-2,0,7:17
-1,0,7:18
0,0,7:18
1,0,7:18
2,0,7:18
-5,1,7:18
-2,1,7:18
0,1,7:18
-3,2,7:18
1,2,7:17
2,2,7:18
-3,3,7:18
-2,3,7:18
-1,3,7:17
-3,4,7:18
1,5,7:18
-1,-3,8:18
-4,-2,8:18
-3,-2,8:18
-1,-2,8:18
1,-2,8:18
2,-2,8:18
3,-2,8:18
4,-2,8:18
-1,-1,8:18
0,-1,8:17
1,-1,8:18
4,-1,8:18
-5,0,8:18
-4,0,8:18
-2,0,8:17
-1,0,8:18
0,0,8:18
1,0,8:18
2,0,8:18
-5,1,8:18
-3,1,8:85
-2,1,8:85
-1,1,8:18
1,1,8:18
-4,2,8:18
-2,2,8:18
-1,2,8:18
0,2,8:18
1,2,8:17
-1,3,8:17
1,3,8:18
2,3,8:18
-4,4,8:18
-2,4,8:85
-1,4,8:85
0,4,8:18
1,4,8:18
-2,6,8:18
-4,-2,9:18
-2,-2,9:18
-3,-1,9:17
-2,-1,9:18
-1,-1,9:18
0,-1,9:18
1,-1,9:18
3,-1,9:18
-3,0,9:18
0,0,9:18
1,0,9:18
-3,1,9:85
-2,1,9:18
0,1,9:85
1,1,9:18
2,1,9:18
-3,2,9:18
0,2,9:85
1,2,9:17
2,2,9:85
3,2,9:18
4,2,9:18
-2,3,9:18
4,3,9:18
-2,4,9:85
2,4,9:18
1,5,9:18
0,6,9:18
-3,-3,10:18
-1,-3,10:18
1,-3,10:18
-4,-2,10:18
-2,-2,10:18
0,-2,10:18
2,-2,10:18
3,-2,10:18
-5,-1,10:18
-3,-1,10:17
0,-1,10:18
1,-1,10:18
2,-1,10:18
3,-1,10:18
-1,0,10:18
1,0,10:18
-5,1,10:18
-3,1,10:85
-1,1,10:18
0,1,10:85
1,1,10:18
2,1,10:18
-2,2,10:18
-1,2,10:18
0,2,10:18
2,2,10:85
4,2,10:18
-3,3,10:18
0,3,10:18
2,3,10:18
4,3,10:18
-5,4,10:18
-2,4,10:85
1,4,10:18
-3,5,10:18
-2,5,10:18
3,5,10:18
-1,6,10:18
0,6,10:18
-3,7,10:18
-3,-4,11:18
-3,-3,11:18
-1,-3,11:18
-4,-2,11:18
0,-2,11:18
-4,-1,11:18
-3,-1,11:85
-2,-1,11:18
-3,0,11:18
0,0,11:18
2,0,11:18
3,0,11:18
4,0,11:18
-3,1,11:18
2,1,11:18
4,1,11:18
-2,2,11:18
1,2,11:18
2,2,11:85
4,2,11:18
-1,3,11:18
1,3,11:18
-4,4,11:18
0,4,11:18
-4,6,11:18
-3,6,11:18
-4,-4,12:18
-2,-4,12:18
-5,-3,12:18
-3,-2,12:18
-3,-1,12:85
-1,-1,12:18
0,-1,12:18
2,-1,12:18
-5,0,12:18
-3,0,12:18
0,0,12:18
-5,1,12:18
-3,1,12:18
1,1,12:18
-4,2,12:18
-2,2,12:18
1,2,12:18
4,2,12:18
-4,3,12:18
-3,3,12:18
-2,3,12:18
5,3,12:18
-4,4,12:18
-1,4,12:18
1,4,12:18
2,5,12:18
3,5,12:18
-3,6,12:18
-2,6,12:18
-2,-4,13:18
-4,-3,13:18
-5,-2,13:18
-2,-2,13:18
-6,-1,13:18
-1,-1,13:18
0,-1,13:18
0,0,13:18
2,0,13:18
0,1,13:18
-3,2,13:18
3,2,13:18
0,3,13:18
-3,4,13:18
0,4,13:18
-4,-3,14:18
-1,-3,14:18
-4,-2,14:18
-3,-2,14:18
-3,-1,14:18
-3,0,14:18
2,2,14:18
-3,-2,15:18
