[META]
version=2.0
spawnOnBlockType=2
spawnSunlight=True
spawnDarkness=False
spawnWater=False
spawnLava=False
underFill=True
randomRotation=True
dig=True
tree=False
branch=False
needsFoundation=True
rarity=10
collisionPercentage=2
spawnElevationMin=0
spawnElevationMax=128
spawnInBiome=All
[DATA]
-3,3,0:17
-2,3,0:17
-2,4,0:17
-2,3,1:17
-2,2,2:17
-2,2,3:17
-2,1,4:17
-2,-1,5:18
-3,0,5:18
-2,1,5:17
-3,-1,6:18
-2,-1,6:18
-2,0,6:18
-2,1,6:17
-1,1,6:18
-4,-2,7:18
-3,-2,7:18
-3,-1,7:18
-2,-1,7:18
-4,0,7:18
-3,0,7:17
-1,0,7:18
-5,1,7:18
-4,1,7:18
-2,1,7:18
-4,2,7:18
-3,2,7:18
-1,2,7:17
-3,-3,8:18
-3,-2,8:18
-5,-1,8:18
-3,-1,8:17
-2,-1,8:18
-1,-1,8:18
-3,0,8:18
-2,0,8:18
-2,1,8:18
-4,2,8:18
-2,2,8:18
-1,2,8:17
-3,3,8:18
-2,3,8:18
-1,3,8:18
0,3,8:18
-3,-3,9:18
-4,-1,9:18
-3,-1,9:18
-1,-1,9:18
0,1,9:18
-1,3,9:17
-3,4,9:18
-1,4,9:18
-2,1,10:18
-1,1,10:18
0,1,10:18
-4,2,10:18
-3,2,10:18
-2,2,10:18
0,2,10:18
1,2,10:18
-3,3,10:18
-2,3,10:18
-1,3,10:17
0,3,10:18
1,3,10:18
-3,4,10:18
-1,4,10:18
0,4,10:18
-2,5,10:18
-1,5,10:18
0,5,10:18
-2,6,10:18
-1,6,10:18
-4,1,11:18
0,1,11:18
-2,2,11:18
-1,2,11:18
-3,3,11:18
-2,3,11:18
-1,3,11:18
0,3,11:17
-3,4,11:18
-2,4,11:17
-1,4,11:18
0,4,11:18
1,4,11:18
-4,5,11:18
-1,5,11:18
-2,1,12:18
-2,2,12:18
-2,3,12:18
-1,3,12:18
0,3,12:18
-3,4,12:18
-2,4,12:18
-1,4,12:18
-2,6,12:18
-3,3,13:18
-2,3,13:18
-3,4,13:18
-2,4,13:18
-1,4,13:18
-3,5,13:18
