[META]
version=2.0
spawnOnBlockType=2
spawnSunlight=True
spawnDarkness=False
spawnWater=False
spawnLava=False
underFill=True
randomRotation=True
dig=True
tree=False
branch=False
needsFoundation=True
rarity=10
collisionPercentage=2
spawnElevationMin=0
spawnElevationMax=128
spawnInBiome=All
[DATA]
-1,-2,0:17
0,-2,0:17
-2,-1,0:17
-1,-1,0:17
0,-1,0:17
-1,0,0:17
0,-2,1:17
-1,-1,1:17
0,-1,1:17
-1,-1,2:17
0,-1,2:17
-1,-1,3:17
0,-1,3:17
-1,-1,4:17
-1,-1,5:17
-1,-1,6:17
-1,-1,7:17
-1,0,8:17
-1,0,9:17
-1,0,10:17
-1,0,11:17
-1,0,12:17
-1,0,13:17
0,-1,14:17
-1,0,14:17
0,-1,15:17
0,-1,16:17
0,-1,17:17
2,-3,18:18
3,-3,18:18
2,-2,18:18
0,-1,18:17
-2,3,18:18
0,3,18:18
1,-5,19:18
4,-3,19:18
0,-2,19:18
1,-2,19:17
2,-2,19:18
4,-2,19:18
0,-1,19:17
1,-1,19:18
0,0,19:17
1,2,19:18
-2,4,19:18
-1,4,19:18
0,-4,20:18
2,-4,20:18
2,-3,20:17
1,-2,20:18
4,-2,20:18
0,-1,20:17
2,-1,20:18
-1,0,20:18
-1,1,20:17
-2,2,20:18
-1,2,20:17
-2,3,20:18
-1,3,20:18
2,-5,21:18
1,-3,21:18
4,-3,21:18
0,-2,21:18
2,-2,21:18
3,-2,21:18
0,-1,21:17
2,-1,21:18
-1,0,21:18
0,0,21:18
-1,2,21:18
0,2,21:18
-2,-4,22:18
0,-3,22:18
1,-3,22:18
2,-3,22:18
0,-2,22:17
1,-2,22:18
2,-2,22:18
-2,-1,22:18
0,-1,22:17
1,-1,22:18
-3,0,22:18
-2,1,22:18
0,1,22:18
2,1,22:18
3,1,22:18
-2,3,22:18
0,-4,23:18
2,-4,23:18
-2,-3,23:18
-1,-3,23:18
0,-3,23:17
1,-3,23:18
2,-3,23:18
-2,-2,23:18
-1,-2,23:18
0,-2,23:18
1,-2,23:18
2,-2,23:18
-3,-1,23:18
-2,-1,23:18
-1,-1,23:17
0,-1,23:17
1,-1,23:18
3,-1,23:18
-1,0,23:18
1,0,23:17
-1,1,23:18
1,1,23:18
2,1,23:18
1,2,23:18
2,2,23:18
0,-5,24:18
1,-5,24:18
-1,-4,24:18
2,-4,24:18
-3,-3,24:18
-2,-3,24:18
-1,-3,24:18
0,-3,24:18
1,-3,24:17
0,-2,24:18
2,-2,24:18
-2,-1,24:17
-1,-1,24:18
0,-1,24:17
2,-1,24:17
-2,0,24:18
-1,0,24:18
0,0,24:18
2,0,24:18
-3,1,24:18
-2,1,24:18
-1,1,24:18
1,1,24:17
1,-4,25:18
0,-3,25:18
1,-3,25:18
-4,-2,25:18
-1,-2,25:18
0,-2,25:18
1,-2,25:18
-2,-1,25:18
-1,-1,25:18
0,-1,25:17
1,-1,25:18
-2,0,25:18
-1,0,25:18
0,0,25:18
1,1,25:18
2,1,25:18
0,-3,26:18
1,-3,26:18
-1,-2,26:18
0,-2,26:18
-3,-1,26:18
1,-1,26:18
0,1,26:18
-1,-1,27:18
0,-1,27:18
1,-1,27:18
1,0,27:18
