[META]
version=2.0
spawnOnBlockType=2
spawnSunlight=True
spawnDarkness=False
spawnWater=False
spawnLava=False
underFill=True
randomRotation=True
dig=True
tree=False
branch=False
needsFoundation=True
rarity=10
collisionPercentage=2
spawnElevationMin=0
spawnElevationMax=128
spawnInBiome=All
[DATA]
-1,1,0:17.1
-1,-2,1:18
-1,0,1:18
0,0,1:18
-4,1,1:18
-1,1,1:17.1
1,1,1:18
2,1,1:18
-4,2,1:18
2,2,1:18
-3,3,1:18
-2,-2,2:18
-1,-2,2:18
0,-2,2:18
-3,-1,2:18
-4,0,2:18
-2,0,2:18
-1,0,2:18
-4,1,2:18
-3,1,2:18
-1,1,2:17.1
0,1,2:18
2,1,2:18
-1,2,2:18
1,2,2:18
2,2,2:18
-1,3,2:18
1,3,2:18
-2,4,2:18
0,4,2:18
-2,-1,3:18
-1,-1,3:18
-3,0,3:18
-1,0,3:18
0,0,3:18
1,0,3:18
-3,1,3:18
-1,1,3:17.1
0,1,3:18
-4,2,3:18
0,2,3:18
0,-1,4:18
-2,0,4:18
-1,0,4:18
0,0,4:18
1,0,4:18
-1,1,4:17.1
0,1,4:18
1,1,4:18
-2,2,4:18
-1,2,4:18
0,2,4:18
-3,3,4:18
-2,3,4:18
-1,3,4:18
0,3,4:18
-2,0,5:18
-1,0,5:18
-1,1,5:17.1
1,1,5:18
-1,2,5:18
0,2,5:18
-1,3,5:18
0,0,6:18
-2,1,6:18
-1,1,6:17.1
0,1,6:18
1,1,6:18
-3,2,6:18
-2,2,6:18
-1,2,6:18
0,2,6:18
-1,3,6:18
-1,1,7:18
0,1,7:18
-1,2,7:18
0,2,7:18
0,1,8:18
