[META]
version=2.0
spawnOnBlockType=2
spawnSunlight=True
spawnDarkness=False
spawnWater=False
spawnLava=False
underFill=True
randomRotation=True
dig=True
tree=False
branch=False
needsFoundation=True
rarity=10
collisionPercentage=2
spawnElevationMin=0
spawnElevationMax=128
spawnInBiome=All
[DATA]
-2,2,0:17.1
-3,-3,1:18
-2,-3,1:18
-2,-2,1:18
-6,-1,1:18
2,-1,1:18
-5,0,1:18
-4,0,1:18
-3,0,1:18
-2,0,1:18
2,0,1:18
-5,1,1:18
0,1,1:18
1,1,1:18
3,1,1:18
-7,2,1:18
-6,2,1:18
-2,2,1:17.1
-1,2,1:18
0,2,1:18
1,2,1:18
2,2,1:18
3,2,1:18
-4,3,1:18
-2,3,1:18
1,3,1:18
2,3,1:18
-7,4,1:18
-6,4,1:18
-5,5,1:18
-3,7,1:18
-2,7,1:18
-2,-3,2:18
-1,-3,2:18
-4,-2,2:18
-2,-2,2:18
-6,-1,2:18
-4,-1,2:18
0,-1,2:18
-5,0,2:18
-2,0,2:18
2,0,2:18
3,0,2:18
-7,1,2:18
-6,1,2:18
-4,1,2:18
3,1,2:18
-7,2,2:18
-5,2,2:18
-4,2,2:18
-2,2,2:17.1
0,2,2:18
-6,3,2:18
-5,3,2:18
-4,5,2:18
-1,5,2:18
2,5,2:18
-5,6,2:18
-2,6,2:18
1,6,2:18
-4,7,2:18
-3,-2,3:18
-2,-2,3:18
0,-2,3:18
-4,-1,3:18
-3,0,3:18
-3,2,3:18
-2,2,3:17.1
-1,2,3:18
0,2,3:18
2,2,3:18
-3,3,3:18
-1,3,3:18
2,3,3:18
-2,4,3:18
0,4,3:18
-3,5,3:18
-1,6,3:18
0,-2,4:18
-5,-1,4:18
-3,-1,4:18
-2,-1,4:18
-4,0,4:18
0,1,4:18
2,1,4:18
-4,2,4:18
-2,2,4:17.1
-1,2,4:18
1,2,4:18
-2,3,4:18
2,3,4:18
-6,4,4:18
-1,4,4:18
1,4,4:18
2,4,4:18
-2,5,4:18
1,5,4:18
-4,6,4:18
-2,6,4:18
-4,-2,5:18
-3,-2,5:18
-2,-2,5:18
-5,-1,5:18
-4,0,5:18
-3,0,5:18
-4,1,5:18
0,1,5:18
1,1,5:18
-4,2,5:18
-3,2,5:18
-2,2,5:17.1
-1,2,5:18
2,2,5:18
-5,3,5:18
-6,4,5:18
-5,4,5:18
1,4,5:18
-2,5,5:18
-1,5,5:18
-3,6,5:18
0,-2,6:18
-2,-1,6:18
-1,-1,6:18
0,-1,6:18
-5,1,6:18
-3,1,6:18
1,1,6:18
-6,2,6:18
-5,2,6:18
-4,2,6:18
-3,2,6:18
-2,2,6:17.1
2,2,6:18
-2,3,6:18
-1,3,6:18
-5,4,6:18
-4,4,6:18
1,4,6:18
-5,5,6:18
0,5,6:18
-4,6,6:18
-2,6,6:18
-4,0,7:18
0,0,7:18
-5,2,7:18
-3,2,7:18
-2,2,7:17.1
-1,2,7:18
0,2,7:18
1,2,7:18
-1,4,7:18
0,4,7:18
-2,5,7:18
-1,5,7:18
-3,-1,8:18
-2,0,8:18
-5,1,8:18
-2,1,8:18
-5,2,8:18
-3,2,8:18
-2,2,8:17.1
-1,2,8:18
0,2,8:18
-4,3,8:18
-3,3,8:18
0,3,8:18
1,3,8:18
0,4,8:18
-3,5,8:18
-3,-1,9:18
-3,0,9:18
-4,1,9:18
-3,1,9:18
-2,1,9:18
1,1,9:18
-4,2,9:18
-2,2,9:17.1
-2,5,9:18
-2,-1,10:18
-1,-1,10:18
-5,1,10:18
1,1,10:18
-5,2,10:18
-2,2,10:17.1
0,2,10:18
-4,4,10:18
-2,4,10:18
-2,5,10:18
-1,5,10:18
-1,-1,11:18
-3,1,11:18
-2,1,11:18
1,1,11:18
-5,2,11:18
-4,2,11:18
-3,2,11:18
-2,2,11:17.1
-1,2,11:18
0,2,11:18
-4,3,11:18
-3,3,11:18
-4,4,11:18
-2,4,11:18
-2,5,11:18
-3,-1,12:18
-1,0,12:18
-3,1,12:18
0,1,12:18
-5,2,12:18
-4,2,12:18
-2,2,12:17.1
-1,2,12:18
1,2,12:18
-2,3,12:18
0,3,12:18
-1,5,12:18
-2,0,13:18
-2,1,13:18
0,1,13:18
-4,2,13:18
-3,2,13:18
-2,2,13:17.1
0,2,13:18
-3,3,13:18
-1,1,14:18
-3,2,14:18
-2,2,14:17.1
-1,2,14:18
-3,0,15:18
-1,0,15:18
-3,1,15:18
-3,2,15:18
-2,2,15:17.1
-1,2,15:18
0,2,15:18
-2,3,15:18
-1,3,15:18
-1,1,16:18
-3,2,16:18
-2,2,16:17.1
-1,2,16:18
-4,3,16:18
-2,4,16:18
-2,1,17:18
-2,2,17:17.1
-1,2,17:18
-2,3,17:18
-2,1,18:18
-2,2,18:17.1
-1,2,18:18
-3,3,18:18
-2,2,19:18
