[META]
version=2.0
spawnOnBlockType=2
spawnSunlight=True
spawnDarkness=False
spawnWater=False
spawnLava=False
underFill=True
randomRotation=True
dig=True
tree=False
branch=False
needsFoundation=True
rarity=10
collisionPercentage=2
spawnElevationMin=0
spawnElevationMax=128
spawnInBiome=All
[DATA]
-2,4,0:17
-2,4,1:17
-2,1,2:18
-3,2,2:18
-1,2,2:18
-4,3,2:18
-3,3,2:17
-2,3,2:18
-5,4,2:18
-2,4,2:17
-4,1,3:18
-1,1,3:18
-5,2,3:18
-4,2,3:17
-3,2,3:18
-4,3,3:18
-1,3,3:18
-5,4,3:18
-4,4,3:18
-2,4,3:17
-1,4,3:17
1,4,3:18
-4,5,3:18
0,5,3:18
-3,6,3:18
-1,6,3:18
1,6,3:18
-2,7,3:18
0,7,3:18
-4,2,4:18
-1,2,4:18
-2,3,4:18
0,3,4:18
-2,4,4:17
-1,4,4:18
0,4,4:17
1,4,4:18
0,5,4:18
0,6,4:18
1,7,4:18
-1,3,5:18
-4,4,5:18
-2,4,5:17
0,4,5:18
-5,5,5:18
-3,5,5:17
0,5,5:18
-6,6,5:18
-3,7,5:18
-5,3,6:18
-4,3,6:18
-3,3,6:18
-5,4,6:18
-2,4,6:17
-5,5,6:18
-3,5,6:18
-6,6,6:18
-4,6,6:17
-3,6,6:18
-6,7,6:18
-4,7,6:18
-3,7,6:18
-2,7,6:18
-5,8,6:18
-4,8,6:18
-2,8,6:18
-2,1,7:18
-1,1,7:18
-2,2,7:18
-1,2,7:18
-2,4,7:17
-1,1,8:18
-3,2,8:18
-2,2,8:18
0,2,8:18
-2,3,8:18
-1,3,8:18
0,3,8:18
1,3,8:18
-4,4,8:18
-2,4,8:17
0,4,8:18
1,4,8:18
-4,5,8:18
-1,5,8:18
1,5,8:18
-3,6,8:18
-2,6,8:18
-1,6,8:18
-3,7,8:18
-2,7,8:18
-2,2,9:18
-3,3,9:18
-2,3,9:18
0,3,9:18
-2,4,9:17
0,4,9:18
1,4,9:18
-1,5,9:18
-3,6,9:18
-2,6,9:18
-2,7,9:18
-1,7,9:18
-2,3,10:18
-1,3,10:18
1,3,10:18
-3,4,10:18
-2,4,10:17
-1,4,10:18
0,4,10:18
-2,5,10:18
-1,5,10:18
1,5,10:18
-1,6,10:18
-2,4,11:18
