[META]
version=2.0
spawnOnBlockType=2
spawnSunlight=True
spawnDarkness=False
spawnWater=False
spawnLava=False
underFill=True
randomRotation=True
dig=True
tree=False
branch=False
needsFoundation=True
rarity=10
collisionPercentage=2
spawnElevationMin=0
spawnElevationMax=128
spawnInBiome=All
[DATA]
-1,1,0:17
-1,1,1:17
0,-9,2:18
0,-8,2:18
2,-8,2:18
-3,-7,2:18
2,-7,2:18
3,-7,2:18
-1,-6,2:18
0,-6,2:17
1,-6,2:18
0,-5,2:18
3,-5,2:18
-1,-4,2:18
0,-4,2:18
1,-3,2:18
-1,1,2:17
-3,-9,3:18
-4,-8,3:18
-3,-7,3:18
-2,-7,3:18
-5,-6,3:18
-2,-6,3:17
0,-6,3:18
-2,-5,3:18
-1,-5,3:17
0,-5,3:18
1,-5,3:18
-8,-4,3:18
-7,-4,3:18
-4,-4,3:18
-3,-4,3:18
-2,-4,3:18
-1,-4,3:17
0,-4,3:18
2,-4,3:18
-7,-3,3:18
-5,-3,3:18
-1,-3,3:18
2,-3,3:18
-9,-2,3:18
-8,-2,3:18
-5,-2,3:18
-3,-2,3:18
-2,-2,3:18
-1,-2,3:18
0,-2,3:18
-9,-1,3:18
-7,-1,3:17
-5,-1,3:18
-3,-1,3:18
-9,0,3:18
-7,0,3:18
-6,0,3:17
-5,0,3:17
-3,0,3:18
-1,0,3:17
-9,1,3:18
-8,1,3:18
-7,1,3:18
-2,1,3:17
-1,1,3:17
-8,2,3:18
-6,2,3:18
-2,4,3:18
-1,4,3:18
-1,5,3:18
-1,6,3:18
1,6,3:18
-4,7,3:18
-3,7,3:18
-2,7,3:18
-1,7,3:17
1,7,3:18
-3,8,3:18
0,8,3:18
1,8,3:18
2,8,3:18
1,9,3:18
-2,10,3:18
-1,-5,4:18
5,-5,4:18
2,-4,4:18
5,-4,4:18
6,-4,4:18
-3,-3,4:18
-2,-3,4:18
-1,-3,4:17
5,-3,4:17
6,-3,4:18
-5,-2,4:18
-3,-2,4:18
-2,-2,4:18
-1,-2,4:17
2,-2,4:18
4,-2,4:18
5,-2,4:18
-1,-1,4:17
6,-1,4:18
-5,0,4:18
-4,0,4:18
-2,0,4:18
-1,0,4:18
5,0,4:18
-6,1,4:18
-4,1,4:17
-3,1,4:17
-1,1,4:17
-6,2,4:18
-4,2,4:18
-3,2,4:18
-1,2,4:17
-6,3,4:18
-3,3,4:18
-1,3,4:18
0,3,4:18
-1,4,4:18
1,4,4:18
-4,5,4:18
-3,5,4:18
-1,5,4:17
0,5,4:18
-2,6,4:18
-1,6,4:17
1,6,4:18
2,6,4:18
1,7,4:18
-1,8,4:18
1,8,4:18
-2,9,4:18
-1,9,4:18
0,9,4:18
1,-3,5:18
2,-3,5:18
3,-3,5:18
4,-3,5:17
5,-3,5:18
1,-2,5:18
2,-1,5:18
-1,1,5:17
-3,2,5:18
-1,3,5:17
2,3,5:18
-3,4,5:18
-1,4,5:17
2,4,5:18
-4,5,5:18
0,5,5:18
2,5,5:18
-1,6,5:18
3,-5,6:18
1,-3,6:18
2,-3,6:18
4,-3,6:18
1,-2,6:18
3,-2,6:17
4,-2,6:18
5,-2,6:18
0,-1,6:18
6,-1,6:18
0,0,6:17
1,0,6:18
3,0,6:18
5,0,6:18
-1,1,6:17
1,-4,7:18
3,-2,7:18
1,-1,7:17
2,-1,7:17
4,-1,7:18
5,-1,7:18
2,0,7:18
3,0,7:18
5,0,7:18
-1,1,7:17
2,1,7:18
-1,1,8:17
-6,2,8:18
-7,4,8:18
-6,4,8:18
-8,5,8:18
-7,5,8:18
-6,5,8:17
-4,5,8:18
-5,6,8:18
-7,7,8:18
-6,7,8:18
-7,8,8:18
-6,8,8:18
-4,1,9:18
-1,1,9:17
-6,2,9:18
-5,2,9:18
-2,2,9:17
-8,4,9:18
-7,4,9:18
-5,4,9:17
-5,5,9:18
-4,6,9:18
-3,6,9:18
-3,-8,10:18
-2,-8,10:18
2,-8,10:18
2,-7,10:18
3,-7,10:18
-7,-6,10:18
-6,-6,10:18
-5,-6,10:18
-4,-6,10:17
-2,-6,10:18
1,-6,10:18
2,-6,10:18
3,-6,10:18
-2,-5,10:18
-1,-5,10:18
1,-5,10:17
2,-5,10:18
3,-5,10:18
-6,-4,10:18
-4,-4,10:18
-3,-4,10:18
-1,-4,10:18
0,-4,10:18
1,-4,10:17
3,-4,10:18
-5,-3,10:18
-3,-3,10:18
0,-3,10:17
1,-3,10:18
2,-3,10:18
0,-2,10:18
1,-2,10:18
-3,-1,10:18
-2,-1,10:18
-4,0,10:18
-3,0,10:18
-4,1,10:18
-3,1,10:18
-1,1,10:17
-5,2,10:18
-4,2,10:18
-3,2,10:17
0,2,10:18
-6,3,10:18
-5,3,10:18
-4,3,10:17
-3,3,10:18
0,3,10:18
-4,4,10:18
-3,4,10:18
-1,4,10:18
3,5,10:18
7,5,10:18
2,6,10:18
3,6,10:18
4,7,10:18
5,7,10:17
6,7,10:18
7,7,10:18
5,8,10:18
5,9,10:18
7,9,10:18
-1,-7,11:18
-5,-5,11:18
-3,-5,11:17
0,-5,11:18
-5,-4,11:18
-3,-4,11:18
-2,-4,11:17
-5,-3,11:18
-3,-3,11:18
-2,-3,11:18
-1,-3,11:17
0,-3,11:18
-3,-1,11:18
-1,-1,11:18
-1,0,11:17
-1,1,11:17
5,3,11:18
4,5,11:18
4,6,11:17
6,6,11:18
7,6,11:18
1,7,11:18
3,7,11:18
4,7,11:18
5,8,11:18
6,8,11:18
4,9,11:18
5,9,11:18
-1,-5,12:18
-3,-4,12:18
-1,-4,12:18
1,-4,12:18
-2,-3,12:18
2,-3,12:18
-4,-2,12:18
-3,-2,12:18
-2,-2,12:18
-1,-2,12:17
-2,-1,12:18
-1,-1,12:17
1,-1,12:18
2,-1,12:18
-1,0,12:18
-3,1,12:18
-1,1,12:17
1,1,12:18
-1,2,12:18
0,2,12:18
5,3,12:18
5,5,12:18
1,6,12:18
4,6,12:17
5,6,12:18
7,6,12:18
1,7,12:18
2,7,12:18
3,7,12:18
-1,-1,13:18
2,0,13:18
-4,1,13:18
-1,1,13:17
0,1,13:18
2,1,13:18
-3,2,13:18
-1,2,13:18
0,2,13:17
4,3,13:18
0,4,13:18
1,4,13:18
1,5,13:18
2,5,13:18
3,5,13:17
5,5,13:18
4,6,13:18
6,6,13:18
3,7,13:18
3,8,13:18
2,0,14:18
-1,1,14:17
1,1,14:18
2,1,14:18
3,1,14:18
-1,2,14:18
1,2,14:18
3,2,14:18
0,3,14:18
1,3,14:17
2,3,14:18
1,4,14:18
2,4,14:17
1,5,14:18
2,5,14:18
0,6,14:18
1,6,14:18
2,6,14:18
-1,1,15:17
-1,1,16:17
0,-3,17:18
-3,-1,17:18
-3,0,17:18
-2,0,17:18
-1,0,17:18
0,0,17:17
1,0,17:18
-2,1,17:18
-1,1,17:17
0,1,17:18
1,2,17:18
-1,3,17:18
1,3,17:18
1,-5,18:18
2,-5,18:18
2,-4,18:18
0,-3,18:18
3,-3,18:18
1,-2,18:18
2,-2,18:17
4,-2,18:18
0,-1,18:18
1,-1,18:17
3,-1,18:18
-1,1,18:17
3,1,18:18
-4,-6,19:18
-5,-5,19:18
-5,-4,19:18
-4,-4,19:18
-3,-4,19:18
-7,-3,19:18
-6,-3,19:18
-5,-3,19:17
-3,-3,19:18
-7,-2,19:18
-4,-2,19:18
-3,-2,19:18
-2,-2,19:18
-6,-1,19:18
-5,-1,19:18
1,-1,19:18
-6,0,19:18
-4,0,19:18
-2,0,19:17
1,0,19:18
-4,1,19:18
-2,1,19:18
-1,1,19:17
0,1,19:18
-4,2,19:18
-2,3,19:18
-5,-5,20:18
-5,-4,20:18
-4,-4,20:18
-3,-3,20:18
-2,-3,20:18
-1,-3,20:18
-4,-2,20:17
-2,-2,20:18
-6,-1,20:18
-3,-1,20:17
-1,1,20:17
0,3,20:18
-1,4,20:18
-3,5,20:18
-1,5,20:18
1,5,20:18
-1,6,20:17
1,6,20:18
2,6,20:18
-2,7,20:18
0,7,20:18
-1,8,20:18
-1,1,21:17
-2,2,21:18
-1,2,21:17
1,3,21:18
-1,4,21:18
1,4,21:18
-4,5,21:18
-1,5,21:17
1,5,21:18
2,5,21:18
-1,6,21:18
1,7,21:18
-1,0,22:18
-2,1,22:18
-1,1,22:17
-3,2,22:18
-3,3,22:18
-2,3,22:18
-1,3,22:17
0,3,22:18
1,3,22:18
2,3,22:18
-4,4,22:18
-1,4,22:17
-3,5,22:18
-1,5,22:18
-1,1,23:17
-1,1,24:17
-1,-6,25:18
-3,-5,25:18
1,-5,25:18
-2,-4,25:18
0,-4,25:18
-1,-3,25:17
1,-3,25:18
-1,-2,25:18
0,-2,25:18
0,-1,25:18
1,-1,25:18
-2,0,25:17
-1,0,25:18
0,0,25:18
-2,1,25:18
-1,1,25:17
1,1,25:18
1,2,25:18
-1,3,25:18
1,3,25:18
-1,4,25:18
-2,-4,26:18
-1,-4,26:18
-3,-3,26:18
-2,-3,26:18
-1,-3,26:18
-5,-2,26:18
-2,-2,26:17
-4,-1,26:18
-3,-1,26:18
-2,-1,26:17
-1,-1,26:18
-3,0,26:18
-2,0,26:18
-4,1,26:18
-3,1,26:18
-2,1,26:18
-1,1,26:17
1,1,26:18
2,1,26:18
-1,2,26:18
1,2,26:18
2,2,26:18
-1,3,26:18
-2,-2,27:18
-1,-2,27:18
-1,-1,27:18
-2,0,27:18
0,0,27:18
2,0,27:18
-4,1,27:18
-2,1,27:18
-1,1,27:17
0,1,27:18
2,1,27:18
-3,2,27:18
-2,2,27:18
2,2,27:18
-2,3,27:18
-1,4,27:18
