[META]
version=2.0
spawnOnBlockType=2
spawnSunlight=True
spawnDarkness=False
spawnWater=False
spawnLava=False
underFill=True
randomRotation=True
dig=True
tree=False
branch=False
needsFoundation=True
rarity=10
collisionPercentage=2
spawnElevationMin=0
spawnElevationMax=128
spawnInBiome=All
[DATA]
-2,-3,0:17
-1,-2,0:17
0,-2,0:17
-2,-1,0:17
-1,-1,0:17
-3,0,0:17
-2,0,0:17
-1,0,0:17
0,0,0:17
1,0,0:17
-1,1,0:17
-1,2,0:17
-2,3,0:17
-5,-7,1:18
-4,-7,1:18
-3,-4,1:18
-5,-3,1:18
-4,-3,1:18
-2,-1,1:17
-1,-1,1:17
-2,0,1:17
-1,0,1:17
0,0,1:17
-1,1,1:17
-1,6,1:18
-5,-10,2:18
-4,-10,2:18
-6,-7,2:18
-3,-7,2:18
-7,-6,2:18
-5,-6,2:18
-3,-6,2:18
-6,-4,2:18
-5,-4,2:18
-4,-4,2:18
-5,-3,2:18
-2,-2,2:18
-2,-1,2:17
-1,-1,2:17
-2,0,2:17
-1,0,2:17
-1,1,2:17
-1,2,2:17
-1,5,2:18
0,5,2:18
2,5,2:18
0,6,2:18
1,6,2:18
0,8,2:18
2,8,2:18
-7,-10,3:18
-3,-10,3:18
-7,-9,3:18
-7,-8,3:18
-5,-8,3:18
-4,-8,3:18
-8,-7,3:18
-5,-5,3:18
-4,-4,3:18
-5,-3,3:18
-3,-3,3:18
-5,-2,3:18
-3,-2,3:17
-2,-1,3:17
-1,-1,3:17
-4,0,3:18
-2,0,3:17
-1,0,3:17
-1,3,3:17
1,3,3:18
-2,4,3:18
-1,4,3:17
2,4,3:18
-1,6,3:18
0,6,3:18
1,6,3:18
2,7,3:18
3,7,3:18
0,8,3:18
-4,-11,4:18
-7,-10,4:18
-5,-10,4:18
-4,-10,4:18
-6,-9,4:18
-5,-8,4:17
-4,-8,4:18
-3,-8,4:18
-7,-7,4:18
-5,-7,4:17
-4,-6,4:18
-5,-5,4:18
-4,-5,4:18
-7,-4,4:18
-5,-4,4:18
-4,-4,4:17
-3,-4,4:18
-5,-3,4:18
-4,-3,4:17
-3,-3,4:18
-1,-3,4:18
-2,-2,4:18
-6,-1,4:18
-4,-1,4:18
-2,-1,4:17
-1,-1,4:17
-4,0,4:18
-3,0,4:18
-2,0,4:17
-1,0,4:17
0,0,4:17
-2,5,4:18
0,5,4:17
0,6,4:17
1,6,4:18
2,6,4:18
0,7,4:18
2,7,4:18
3,7,4:18
2,8,4:18
4,8,4:18
-6,9,4:18
0,9,4:18
-6,10,4:18
-4,-10,5:18
-5,-8,5:18
-1,-8,5:18
-7,-7,5:18
-6,-7,5:18
-1,-7,5:18
1,-7,5:18
-7,-6,5:18
-5,-6,5:17
-4,-6,5:18
-3,-6,5:18
-6,-5,5:18
-5,-5,5:17
-5,-4,5:18
-6,-3,5:18
-3,-3,5:18
-5,-2,5:18
4,-2,5:18
-1,-1,5:17
-7,0,5:18
-6,0,5:18
-5,0,5:18
-4,0,5:18
-3,0,5:18
-2,0,5:17
-1,0,5:17
0,0,5:17
-8,1,5:18
0,1,5:17
0,3,5:18
-2,6,5:18
1,6,5:18
3,6,5:18
-1,7,5:18
2,7,5:18
3,7,5:18
-4,8,5:18
1,8,5:18
2,8,5:18
4,8,5:18
5,8,5:18
-6,9,5:18
-3,9,5:18
5,9,5:18
-6,11,5:18
-5,11,5:18
-5,-10,6:18
-3,-9,6:18
1,-9,6:18
-7,-8,6:18
-4,-8,6:18
2,-8,6:18
1,-7,6:18
-7,-6,6:18
-3,-6,6:18
1,-6,6:18
-5,-5,6:18
-4,-5,6:18
-2,-5,6:18
-1,-5,6:18
-5,-4,6:18
-4,-4,6:18
-5,-3,6:18
-4,-3,6:18
-3,-2,6:18
3,-2,6:18
-3,-1,6:18
-1,-1,6:17
5,-1,6:18
-9,0,6:18
-2,0,6:17
-1,0,6:17
0,0,6:17
4,0,6:18
-1,1,6:17
0,1,6:17
7,1,6:18
-7,3,6:18
7,3,6:18
-1,4,6:18
2,5,6:18
-1,6,6:18
1,6,6:18
2,6,6:18
3,6,6:18
4,6,6:18
-5,7,6:18
-2,7,6:18
-1,7,6:18
3,7,6:18
4,7,6:18
6,7,6:18
-5,9,6:18
2,9,6:18
-7,10,6:18
-6,10,6:18
3,10,6:18
-5,11,6:18
-5,12,6:18
-2,-10,7:18
2,-10,7:18
-5,-9,7:18
1,-9,7:18
-6,-8,7:18
-2,-8,7:18
1,-8,7:18
2,-8,7:18
3,-8,7:18
-2,-7,7:18
-1,-7,7:18
0,-7,7:18
-3,-6,7:18
3,-6,7:18
-4,-5,7:18
1,-5,7:18
-3,-3,7:18
2,-3,7:18
6,-3,7:18
-3,-2,7:18
0,-2,7:17
2,-2,7:18
4,-2,7:18
5,-2,7:18
-9,-1,7:18
-7,-1,7:18
-5,-1,7:18
-10,0,7:18
-1,0,7:17
0,0,7:17
2,0,7:18
-7,1,7:18
-1,1,7:17
0,1,7:17
4,1,7:18
6,1,7:18
-7,2,7:18
-5,2,7:18
0,2,7:17
6,2,7:18
-8,3,7:18
-7,3,7:18
-1,3,7:17
6,3,7:18
7,3,7:18
7,4,7:18
3,5,7:18
-4,6,7:18
1,6,7:18
4,6,7:18
-3,7,7:18
0,7,7:18
1,7,7:18
-6,8,7:18
-5,8,7:17
-3,8,7:18
-2,8,7:18
0,8,7:18
2,8,7:18
3,8,7:17
4,8,7:18
-6,9,7:18
-5,9,7:17
-4,9,7:18
-3,9,7:18
-2,9,7:18
3,9,7:18
-8,10,7:18
-5,10,7:18
-4,10,7:18
-2,10,7:18
2,10,7:18
4,10,7:18
5,10,7:18
-3,11,7:18
3,11,7:18
2,-11,8:18
0,-10,8:18
1,-10,8:18
0,-9,8:18
3,-9,8:18
-4,-8,8:18
1,-8,8:17
2,-8,8:18
-5,-7,8:18
1,-6,8:18
-3,-5,8:18
-2,-5,8:18
0,-5,8:18
4,-5,8:18
-2,-4,8:18
1,-4,8:17
3,-4,8:18
5,-4,8:18
1,-3,8:17
3,-3,8:18
6,-3,8:18
-7,-2,8:18
3,-2,8:18
4,-2,8:17
7,-2,8:18
-8,-1,8:18
3,-1,8:18
4,-1,8:18
-7,0,8:18
-1,0,8:17
0,0,8:17
-5,1,8:18
-1,1,8:17
0,1,8:17
-9,3,8:18
-7,3,8:18
1,3,8:17
2,3,8:17
-10,4,8:18
-2,4,8:17
-3,5,8:17
6,5,8:18
-5,6,8:18
-4,6,8:17
-4,7,8:17
3,7,8:17
5,7,8:18
-3,8,8:18
-2,8,8:18
5,8,8:18
6,8,8:18
-7,9,8:18
-6,9,8:18
-7,10,8:18
-6,10,8:18
2,10,8:18
-6,11,8:18
-5,12,8:18
-3,12,8:18
-2,-9,9:18
-2,-8,9:18
1,-7,9:18
2,-7,9:17
2,-6,9:17
3,-6,9:18
-3,-5,9:18
-1,-5,9:18
2,-5,9:17
4,-5,9:18
2,-3,9:17
3,-3,9:17
5,-3,9:18
6,-3,9:18
2,-2,9:18
-1,-1,9:17
4,-1,9:18
5,-1,9:18
-10,0,9:18
-1,0,9:17
0,0,9:17
-10,1,9:18
-9,1,9:18
-1,1,9:17
0,1,9:17
5,1,9:18
7,1,9:18
5,2,9:18
7,2,9:18
3,3,9:18
-8,4,9:18
2,4,9:17
5,4,9:18
3,5,9:17
-9,6,9:18
3,6,9:17
5,6,9:18
-10,7,9:18
2,7,9:18
6,7,9:18
2,8,9:18
7,8,9:18
6,9,9:18
-7,10,9:18
-6,10,9:18
-5,10,9:18
1,10,9:18
-6,11,9:18
-3,11,9:18
-2,12,9:18
-4,13,9:18
3,-8,10:18
0,-7,10:18
-1,-6,10:18
1,-6,10:18
-4,-5,10:18
4,-5,10:18
5,-5,10:18
-6,-4,10:18
-2,-4,10:18
4,-4,10:18
7,-4,10:18
2,-3,10:18
3,-3,10:18
4,-3,10:18
5,-3,10:18
6,-3,10:18
7,-3,10:18
8,-3,10:18
2,-2,10:18
4,-2,10:18
-7,-1,10:18
-2,-1,10:17
-1,-1,10:17
0,-1,10:17
5,-1,10:18
6,-1,10:18
-1,0,10:17
0,0,10:17
5,0,10:18
6,0,10:18
7,0,10:18
-7,1,10:18
7,1,10:18
-9,2,10:18
-7,2,10:18
-10,3,10:18
4,3,10:18
5,3,10:18
-12,4,10:18
-10,4,10:18
-9,4,10:18
6,4,10:18
-10,6,10:18
-12,7,10:18
-5,7,10:18
8,7,10:18
-6,8,10:18
-4,8,10:18
3,8,10:18
-10,9,10:18
-6,9,10:18
-5,9,10:18
-4,9,10:18
-1,9,10:18
2,9,10:18
6,9,10:18
-6,10,10:18
-5,10,10:18
-4,10,10:18
-2,10,10:18
-1,10,10:18
-1,11,10:18
-6,12,10:18
-5,12,10:18
-2,12,10:18
-2,-8,11:18
0,-8,11:18
-3,-7,11:18
1,-7,11:18
5,-6,11:18
-4,-5,11:18
1,-5,11:18
7,-3,11:18
-2,-1,11:17
-1,-1,11:17
-7,0,11:18
-2,0,11:17
-1,0,11:17
3,2,11:18
4,2,11:18
5,2,11:18
-9,3,11:18
3,3,11:18
6,3,11:18
7,3,11:18
-12,4,11:18
-8,4,11:18
4,4,11:18
-7,5,11:18
5,5,11:18
-12,6,11:18
-10,6,11:18
3,6,11:18
6,6,11:18
-3,7,11:18
7,7,11:18
8,7,11:18
2,8,11:18
3,8,11:18
4,8,11:18
6,8,11:18
7,8,11:18
-10,9,11:18
-4,9,11:18
-1,9,11:18
3,9,11:18
5,9,11:18
6,9,11:18
8,9,11:18
-5,10,11:18
-3,10,11:18
-2,10,11:18
7,10,11:18
-3,11,11:18
-1,11,11:18
-2,12,11:18
-1,12,11:18
-5,-9,12:18
-3,-8,12:18
-2,-8,12:18
-4,-7,12:18
-2,-7,12:18
2,-7,12:18
4,-7,12:18
-6,-6,12:18
-1,-6,12:18
1,-6,12:18
-5,-5,12:18
-4,-5,12:18
-2,-5,12:18
1,-5,12:18
4,-5,12:18
-6,-4,12:18
-5,-4,12:18
-1,-4,12:18
-3,-3,12:18
5,-3,12:18
-2,-2,12:17
-2,-1,12:17
-1,-1,12:17
5,-1,12:18
-9,0,12:18
-2,0,12:17
-1,0,12:17
4,0,12:18
6,0,12:18
5,2,12:18
-8,3,12:18
4,3,12:18
5,3,12:18
6,3,12:18
6,4,12:18
-11,5,12:18
-7,5,12:18
6,5,12:18
-8,6,12:18
-7,6,12:18
6,6,12:18
3,7,12:18
6,7,12:18
7,7,12:18
-10,8,12:18
-2,8,12:18
7,8,12:18
-6,9,12:18
-5,9,12:18
1,9,12:18
-6,10,12:18
-3,10,12:18
7,10,12:18
-5,11,12:18
-4,11,12:18
-3,11,12:18
-4,-9,13:18
-4,-8,13:18
-5,-7,13:18
1,-6,13:18
3,-6,13:18
4,-6,13:18
-5,-5,13:18
-2,-5,13:18
-1,-5,13:18
0,-5,13:18
1,-5,13:18
-8,-4,13:18
-6,-4,13:18
-5,-4,13:18
-3,-4,13:18
0,-4,13:18
1,-4,13:18
3,-4,13:18
4,-4,13:18
5,-3,13:18
-3,-2,13:17
-2,-2,13:17
6,-2,13:18
-7,-1,13:18
-3,-1,13:17
-2,-1,13:17
7,-1,13:18
-1,0,13:17
0,1,13:17
3,2,13:18
-12,4,13:18
-9,4,13:18
-7,4,13:18
-5,4,13:18
4,4,13:18
5,4,13:18
-11,5,13:18
-10,5,13:18
-5,5,13:18
-12,6,13:18
-9,6,13:18
-4,6,13:18
4,6,13:18
5,6,13:18
-7,7,13:18
-6,7,13:18
-4,7,13:18
0,7,13:18
2,7,13:18
4,7,13:18
6,7,13:18
7,7,13:18
-10,8,13:18
3,8,13:18
6,8,13:18
-1,9,13:18
5,9,13:18
-4,10,13:18
-3,10,13:18
0,10,13:18
1,10,13:18
-3,11,13:18
-1,11,13:18
1,11,13:18
-4,-8,14:18
-3,-8,14:18
1,-8,14:18
-3,-7,14:18
-2,-7,14:18
-5,-6,14:18
-4,-6,14:18
0,-6,14:18
4,-6,14:18
-5,-5,14:18
-2,-5,14:18
0,-5,14:18
2,-5,14:18
-7,-4,14:18
-2,-4,14:18
0,-4,14:18
1,-4,14:18
2,-4,14:18
5,-4,14:18
-8,-3,14:18
-7,-3,14:18
-6,-3,14:18
-5,-3,14:18
-2,-3,14:17
-1,-3,14:17
1,-3,14:18
-8,-2,14:18
-3,-2,14:17
-2,-2,14:17
3,-2,14:18
-5,-1,14:18
4,-1,14:18
-8,0,14:18
-6,0,14:18
-4,0,14:18
4,0,14:18
-11,1,14:18
-9,1,14:18
-6,1,14:18
0,1,14:17
2,1,14:18
4,1,14:18
-6,2,14:18
0,2,14:18
-11,3,14:18
-7,3,14:18
-6,3,14:18
3,3,14:18
-10,4,14:18
-9,4,14:18
-6,4,14:18
-10,5,14:18
-7,5,14:18
-6,5,14:18
6,5,14:18
1,6,14:18
2,6,14:18
6,6,14:18
-9,7,14:18
-8,7,14:18
-7,7,14:18
-6,7,14:18
-3,7,14:18
2,7,14:18
-11,8,14:18
-8,8,14:18
-10,9,14:18
-9,9,14:18
-3,9,14:18
-1,9,14:18
2,9,14:18
-4,10,14:18
-3,10,14:18
1,10,14:18
4,10,14:18
-6,11,14:18
-3,11,14:18
0,11,14:18
2,11,14:18
-4,12,14:18
3,12,14:18
-4,-9,15:18
-5,-8,15:18
1,-8,15:18
3,-8,15:18
4,-8,15:18
-2,-7,15:18
3,-7,15:18
5,-6,15:18
-7,-5,15:18
-6,-5,15:18
-5,-5,15:18
-2,-5,15:18
-9,-4,15:18
-5,-4,15:18
-3,-4,15:18
0,-4,15:17
1,-4,15:18
3,-4,15:18
-8,-3,15:18
-6,-3,15:18
-5,-3,15:18
-2,-3,15:18
-1,-3,15:17
-4,-2,15:17
-6,-1,15:18
-5,-1,15:18
-5,0,15:18
0,0,15:18
2,0,15:18
4,0,15:18
-6,1,15:18
-4,1,15:18
4,1,15:18
-7,2,15:18
-6,2,15:18
1,2,15:17
5,2,15:18
-10,3,15:18
-8,3,15:18
-5,3,15:18
3,3,15:18
4,3,15:18
-10,4,15:18
-7,4,15:18
3,4,15:18
-9,5,15:18
-8,5,15:18
-6,5,15:18
-5,5,15:18
0,5,15:18
3,5,15:17
5,5,15:18
-11,6,15:18
-8,6,15:18
-4,6,15:18
3,6,15:17
4,6,15:18
6,6,15:18
-4,7,15:18
1,7,15:18
-8,8,15:18
-6,8,15:18
-2,8,15:18
0,8,15:18
1,8,15:18
2,8,15:18
3,8,15:18
4,8,15:18
-7,9,15:18
-4,9,15:18
-1,9,15:18
2,9,15:18
-6,10,15:18
-5,10,15:18
-4,10,15:18
-5,11,15:18
-1,11,15:18
1,11,15:18
4,11,15:18
0,12,15:18
-6,-7,16:18
-5,-7,16:18
-4,-7,16:18
3,-7,16:18
-4,-6,16:18
1,-6,16:18
-6,-5,16:18
-5,-5,16:18
-4,-5,16:18
-3,-5,16:18
-2,-5,16:18
-1,-5,16:18
1,-5,16:17
2,-5,16:18
-7,-4,16:18
-4,-4,16:18
0,-4,16:18
1,-4,16:18
3,-4,16:18
5,-4,16:18
-7,-3,16:18
-5,-3,16:18
-3,-3,16:18
2,-3,16:18
-7,-2,16:18
-6,-2,16:18
-4,-2,16:18
-6,-1,16:18
-5,-1,16:18
-4,-1,16:17
-3,-1,16:18
-2,-1,16:18
1,-1,16:18
2,-1,16:18
-5,0,16:18
-2,0,16:18
-1,0,16:18
0,0,16:18
2,0,16:18
-1,1,16:18
2,1,16:18
-9,2,16:18
-7,2,16:18
-6,2,16:18
-5,2,16:18
0,2,16:18
2,2,16:18
3,2,16:18
4,2,16:18
5,2,16:18
-9,3,16:18
-4,3,16:18
-3,3,16:18
1,3,16:18
2,3,16:17
3,3,16:18
-9,4,16:18
-8,4,16:18
2,4,16:17
-11,5,16:18
-9,5,16:18
-7,5,16:18
-6,5,16:18
-5,5,16:18
-4,5,16:18
-11,6,16:18
-9,6,16:18
-6,6,16:18
2,6,16:18
6,6,16:18
-5,7,16:18
-3,7,16:18
2,7,16:18
4,7,16:18
-10,8,16:18
-9,8,16:18
-6,8,16:18
-5,8,16:18
1,8,16:18
-4,9,16:18
-3,9,16:18
-2,9,16:18
-6,10,16:18
-4,10,16:18
-5,11,16:18
-4,11,16:18
-2,11,16:18
-5,12,16:18
-4,12,16:18
-3,12,16:18
1,-8,17:18
0,-7,17:18
3,-7,17:18
-5,-6,17:18
-2,-6,17:18
-4,-5,17:18
-2,-5,17:18
-1,-5,17:18
-6,-4,17:18
-1,-4,17:18
-7,-3,17:18
-5,-3,17:18
-4,-3,17:18
-2,-3,17:18
0,-3,17:18
-6,-2,17:18
-5,-2,17:18
1,-2,17:18
2,-2,17:18
-7,-1,17:18
-6,-1,17:18
-5,-1,17:17
-4,-1,17:18
-3,-1,17:18
-2,-1,17:18
-1,-1,17:18
0,-1,17:18
3,0,17:18
-4,1,17:18
-3,1,17:18
-2,1,17:18
5,1,17:18
-6,2,17:18
-4,2,17:18
4,2,17:18
5,2,17:18
-9,3,17:18
-7,3,17:18
-2,3,17:18
1,3,17:18
5,3,17:18
-7,4,17:18
-3,4,17:18
-2,4,17:18
5,4,17:18
-9,5,17:18
-6,5,17:18
-5,5,17:18
2,5,17:18
5,5,17:18
-5,6,17:18
1,6,17:18
3,6,17:18
-8,7,17:18
-6,7,17:18
-5,7,17:18
2,7,17:18
3,7,17:18
-5,8,17:18
-4,8,17:18
-3,8,17:18
1,8,17:18
4,8,17:18
-7,9,17:18
-6,9,17:18
-4,9,17:18
-2,9,17:18
-1,9,17:18
3,9,17:18
-5,10,17:18
-2,10,17:18
-4,11,17:18
-5,12,17:18
-1,-7,18:18
-1,-6,18:18
-5,-5,18:18
-4,-5,18:18
0,-5,18:18
-7,-4,18:18
-4,-4,18:18
-3,-4,18:18
3,-4,18:18
-5,-3,18:18
2,-3,18:18
-8,-2,18:18
-5,-2,18:18
-4,-2,18:18
-1,-2,18:18
-6,-1,18:18
-4,-1,18:18
-3,-1,18:18
-2,0,18:18
1,0,18:18
2,0,18:18
-4,1,18:18
-3,1,18:18
-1,1,18:18
-4,2,18:18
-1,2,18:18
-5,3,18:18
-4,3,18:18
-3,3,18:18
-2,3,18:18
0,4,18:18
-10,5,18:18
-8,5,18:18
-6,5,18:18
-5,5,18:18
-4,5,18:18
1,5,18:18
2,5,18:18
2,6,18:18
-10,7,18:18
4,7,18:18
-4,9,18:18
-7,10,18:18
-5,10,18:18
-1,10,18:18
-5,12,18:18
-3,-4,19:18
-2,-4,19:18
-5,-3,19:18
-3,-3,19:18
-2,-3,19:18
-6,-2,19:18
-4,-2,19:18
-2,-2,19:18
-5,-1,19:18
-2,-1,19:18
-1,-1,19:18
1,-1,19:18
-4,0,19:18
-3,0,19:18
-2,0,19:18
1,0,19:18
-3,1,19:18
-2,1,19:18
-1,1,19:18
2,1,19:18
-6,2,19:18
-5,2,19:18
-3,2,19:18
-2,2,19:18
-1,2,19:18
0,2,19:18
-4,3,19:18
-1,3,19:18
-6,4,19:18
-5,4,19:18
-1,4,19:18
0,4,19:18
-6,5,19:18
-4,5,19:18
-3,5,19:18
-6,6,19:18
-4,6,19:18
-3,6,19:18
-1,6,19:18
-3,7,19:18
-2,7,19:18
-5,9,19:18
-3,10,19:18
-2,10,19:18
-5,11,19:18
-4,11,19:18
-2,-4,20:18
-4,-1,20:18
-2,-1,20:18
-5,0,20:18
-4,1,20:18
-3,1,20:18
-2,1,20:18
-6,2,20:18
-5,2,20:18
-4,2,20:18
-3,2,20:18
-2,2,20:18
-1,2,20:18
-4,3,20:18
-5,4,20:18
-4,4,20:18
-2,4,20:18
-1,4,20:18
-4,5,20:18
-1,5,20:18
-4,8,20:18
-5,10,20:18
-2,-1,21:18
-1,-1,21:18
-2,0,21:18
-4,2,21:18
-2,2,21:18
0,2,21:18
-3,3,21:18
-2,3,21:18
-4,5,21:18
-3,5,21:18
