[META]
version=2.0
spawnOnBlockType=2
spawnSunlight=True
spawnDarkness=False
spawnWater=False
spawnLava=False
underFill=True
randomRotation=True
dig=True
tree=False
branch=False
needsFoundation=True
rarity=10
collisionPercentage=2
spawnElevationMin=0
spawnElevationMax=128
spawnInBiome=All
[DATA]
0,1,0:17
0,1,1:17
0,0,2:18
0,1,2:17
0,-1,3:18
-2,0,3:18
0,0,3:17
0,2,3:18
1,2,3:18
-2,-2,4:18
-3,-1,4:18
1,-1,4:18
3,-1,4:18
0,0,4:17
0,-3,5:18
0,-2,5:18
2,-2,5:18
-2,-1,5:18
-1,0,5:18
0,0,5:17
2,0,5:18
3,0,5:18
-1,1,5:17
1,2,5:18
2,-3,6:18
0,-2,6:18
-2,-1,6:18
2,-1,6:18
0,0,6:17
-6,1,6:18
-1,1,6:17
0,1,6:18
1,1,6:18
2,1,6:18
-6,2,6:18
-5,2,6:18
-4,3,6:18
-6,4,6:18
0,5,6:18
1,5,6:18
1,6,6:18
-1,-3,7:18
0,-3,7:18
-1,-2,7:18
0,-1,7:18
3,-1,7:18
-4,0,7:18
0,0,7:17
-7,1,7:18
-1,2,7:17
2,3,7:18
-2,4,7:18
1,4,7:18
3,6,7:18
2,-2,8:18
0,-1,8:17
-4,0,8:18
-1,0,8:18
0,0,8:17
-1,1,8:18
1,1,8:18
2,1,8:18
-6,2,8:18
-3,2,8:18
-1,2,8:17
2,4,8:18
3,4,8:18
-4,5,8:18
0,5,8:18
0,-3,9:18
-3,-2,9:18
3,-2,9:18
-3,-1,9:18
-1,-1,9:18
0,-1,9:17
1,-1,9:18
0,0,9:18
-2,1,9:18
0,1,9:18
1,1,9:17
-7,2,9:18
-6,2,9:18
-2,2,9:17
1,3,9:18
-3,5,9:18
0,-4,10:18
-2,-2,10:18
-1,-2,10:18
0,-2,10:18
-4,-1,10:18
-1,-1,10:18
0,-1,10:17
1,-1,10:18
-2,0,10:18
-2,1,10:18
1,1,10:17
-2,2,10:17
-1,2,10:17
-4,3,10:18
-3,3,10:18
-1,3,10:17
0,3,10:18
1,3,10:18
0,5,10:18
-2,6,10:18
0,6,10:18
-1,-4,11:18
-1,-3,11:18
2,-3,11:18
-4,-2,11:18
-3,-2,11:18
0,-2,11:17
1,-2,11:18
-1,-1,11:17
0,-1,11:17
1,-1,11:18
2,0,11:18
4,0,11:18
5,0,11:18
-5,1,11:18
-3,1,11:18
-2,1,11:18
1,1,11:18
-1,2,11:18
-4,3,11:18
-1,3,11:17
2,3,11:18
-4,4,11:18
-1,4,11:18
1,4,11:18
-1,6,11:18
-2,-4,12:18
-1,-4,12:18
-3,-3,12:18
-2,-3,12:18
0,-3,12:18
2,-3,12:18
3,-3,12:18
-6,-2,12:18
-1,-2,12:18
0,-2,12:17
1,-2,12:18
2,-2,12:18
-3,-1,12:18
-1,-1,12:17
0,-1,12:18
1,-1,12:18
-6,0,12:18
-1,0,12:18
2,0,12:18
3,0,12:18
-2,2,12:18
1,2,12:18
-2,3,12:17
-1,3,12:17
-1,4,12:17
-1,-4,13:18
0,-4,13:18
-1,-3,13:18
-5,-2,13:18
-2,-2,13:18
0,-2,13:17
1,-2,13:17
2,-2,13:18
-3,-1,13:18
-1,-1,13:17
0,-1,13:18
4,-1,13:18
1,0,13:18
-4,1,13:18
2,1,13:18
-2,2,13:18
-2,3,13:17
-1,3,13:18
-2,4,13:18
-1,4,13:17
0,4,13:18
1,4,13:18
-2,5,13:18
2,-4,14:18
-4,-3,14:18
1,-3,14:18
1,-2,14:17
2,-2,14:18
-4,-1,14:18
-1,-1,14:17
-6,0,14:18
-2,0,14:18
-8,1,14:18
2,1,14:18
-6,3,14:18
-2,3,14:17
-1,3,14:18
2,3,14:18
-2,4,14:18
-1,4,14:17
0,4,14:17
1,4,14:18
-1,5,14:18
0,-4,15:18
3,-4,15:18
0,-3,15:18
2,-3,15:18
-3,-2,15:18
-1,-2,15:17
0,-2,15:18
1,-2,15:17
2,-2,15:17
-1,-1,15:17
-6,1,15:18
0,1,15:18
-4,2,15:18
-2,2,15:18
1,2,15:18
5,2,15:18
-5,3,15:18
-2,3,15:17
-1,3,15:18
0,4,15:17
-1,5,15:18
0,5,15:18
-3,6,15:18
-2,6,15:18
1,7,15:18
0,-4,16:18
2,-3,16:18
-2,-2,16:18
-1,-2,16:17
0,-2,16:18
2,-2,16:17
4,-2,16:18
-7,-1,16:18
-1,-1,16:18
-7,0,16:18
-2,0,16:18
5,1,16:18
-7,2,16:18
-2,2,16:18
-1,2,16:18
2,3,16:18
0,4,16:17
2,4,16:18
-3,5,16:18
0,5,16:18
1,5,16:18
2,5,16:18
3,5,16:18
-2,6,16:18
2,6,16:18
-1,7,16:18
3,-5,17:18
1,-4,17:18
-2,-3,17:18
-1,-3,17:18
2,-3,17:17
-1,-2,17:17
2,-2,17:17
0,0,17:18
-4,2,17:18
-2,2,17:18
2,2,17:18
5,2,17:18
-4,3,17:18
-3,3,17:18
-2,3,17:18
3,3,17:18
-3,4,17:18
0,4,17:18
-2,-5,18:18
2,-5,18:18
4,-5,18:18
-3,-4,18:18
2,-4,18:18
-1,-3,18:18
0,-3,18:18
2,-3,18:85
3,-3,18:18
-3,-2,18:18
-2,-2,18:18
-1,-2,18:17
2,-2,18:18
5,-2,18:18
-3,-1,18:18
-3,0,18:18
0,0,18:18
1,0,18:18
-3,3,18:18
-2,3,18:18
-1,3,18:18
-3,4,18:18
-1,-4,19:18
-4,-3,19:18
-1,-3,19:18
2,-3,19:18
3,-2,19:18
4,-2,19:18
-4,-1,19:18
-2,-1,19:18
1,-1,19:18
3,0,19:18
2,1,19:18
3,-3,20:18
-3,-2,20:18
-3,-1,20:18
-2,-1,20:18
