[META]
version=2.0
spawnOnBlockType=2
spawnSunlight=True
spawnDarkness=False
spawnWater=False
spawnLava=False
underFill=True
randomRotation=True
dig=True
tree=False
branch=False
needsFoundation=True
rarity=10
collisionPercentage=2
spawnElevationMin=0
spawnElevationMax=128
spawnInBiome=All
[DATA]
0,0,0:17
0,0,1:17
1,0,1:18
-2,-4,2:18
-1,-4,2:18
-1,-3,2:18
0,-2,2:18
0,0,2:17
1,1,2:18
-1,2,2:18
-2,-2,3:18
-1,-2,3:18
-1,-1,3:18
0,-1,3:18
-2,0,3:18
0,0,3:17
2,0,3:18
-2,1,3:18
-1,1,3:17
1,1,3:18
-1,2,3:17
-1,3,3:18
1,3,3:18
-1,4,3:18
0,4,3:18
1,4,3:18
-1,-5,4:18
1,-5,4:18
-2,-4,4:18
-1,-3,4:18
1,-3,4:18
2,-3,4:18
-2,-2,4:18
-1,-2,4:18
0,-2,4:18
-1,-1,4:18
0,-1,4:18
1,-1,4:18
2,-1,4:18
0,0,4:17
-2,1,4:18
-1,1,4:18
1,1,4:18
0,2,4:18
1,2,4:18
2,2,4:18
-4,3,4:18
-2,4,4:18
-1,4,4:18
-3,-5,5:18
-2,-5,5:18
-1,-5,5:18
1,-4,5:18
-3,-3,5:18
-2,-3,5:18
-1,-3,5:17
1,-3,5:18
2,-3,5:18
-2,-2,5:18
-1,-2,5:17
0,-2,5:18
3,-2,5:18
4,-2,5:18
-3,-1,5:18
-1,-1,5:17
0,-1,5:18
3,-1,5:18
-1,0,5:18
0,0,5:17
2,0,5:18
3,0,5:18
-3,1,5:18
-1,1,5:18
0,1,5:18
-1,2,5:18
0,2,5:18
1,2,5:18
-1,3,5:18
2,3,5:18
3,3,5:18
-1,4,5:18
-2,-5,6:18
-1,-5,6:18
2,-4,6:18
1,-3,6:18
-3,-2,6:18
-2,-2,6:18
1,-2,6:18
3,-2,6:18
-1,-1,6:18
1,-1,6:18
0,0,6:17
1,0,6:17
2,0,6:17
3,0,6:18
5,0,6:18
-1,1,6:18
0,1,6:18
2,1,6:18
3,1,6:18
-2,2,6:18
1,2,6:18
3,2,6:18
-3,-5,7:18
-1,-5,7:18
-1,-4,7:18
0,-4,7:18
-3,-3,7:18
2,-2,7:18
-2,-1,7:18
3,-1,7:18
4,-1,7:18
-2,0,7:18
0,0,7:17
1,0,7:18
1,1,7:18
2,3,7:18
-1,-4,8:18
-2,-3,8:18
0,-2,8:18
2,-2,8:18
0,-1,8:18
0,0,8:17
0,1,8:18
1,1,8:18
0,2,8:18
-2,-2,9:18
-1,-1,9:18
-2,0,9:18
0,0,9:17
1,0,9:18
3,0,9:18
-1,1,9:18
2,1,9:18
0,2,9:18
-3,-1,10:18
-2,0,10:18
0,0,10:17
2,0,10:18
-3,1,10:18
0,1,10:18
1,1,10:18
2,1,10:18
0,2,10:18
1,2,10:18
-1,-3,11:18
0,-3,11:18
-1,-2,11:18
2,-2,11:18
-2,-1,11:18
0,-1,11:18
-3,0,11:18
-2,0,11:18
-1,0,11:18
0,0,11:17
3,1,11:18
-2,2,11:18
0,2,11:18
-1,3,11:18
0,3,11:18
1,3,11:18
0,-3,12:18
1,-3,12:18
-2,-2,12:18
-3,0,12:18
0,0,12:17
3,0,12:18
0,2,12:18
-2,-2,13:18
-1,-1,13:18
0,-1,13:18
-1,0,13:18
0,0,13:18
2,0,13:18
0,1,13:18
0,2,13:18
1,2,13:18
-1,0,14:18
0,0,14:18
0,1,14:18
