[META]
version=2.0
spawnOnBlockType=2
spawnSunlight=True
spawnDarkness=False
spawnWater=False
spawnLava=False
underFill=True
randomRotation=True
dig=True
tree=False
branch=False
needsFoundation=True
rarity=10
collisionPercentage=2
spawnElevationMin=0
spawnElevationMax=128
spawnInBiome=All
[DATA]
-1,-2,0:17
-1,-1,0:17
-3,0,0:17
-2,0,0:17
-1,0,0:17
0,0,0:17
1,0,0:17
-2,1,0:17
-1,1,0:17
1,1,0:17
-1,2,0:17
-1,-1,1:17
-2,0,1:17
-1,0,1:17
0,0,1:17
-1,1,1:17
2,-4,2:18
-2,0,2:17
-1,0,2:17
-1,1,2:17
-8,5,2:18
-6,5,2:18
-9,6,2:18
-7,7,2:18
-3,7,2:18
2,-8,3:18
4,-7,3:18
1,-6,3:18
1,-5,3:18
2,-2,3:18
3,-2,3:18
-1,0,3:17
-5,1,3:18
-4,1,3:18
-1,1,3:17
-7,2,3:18
-4,2,3:18
3,2,3:18
-6,3,3:18
-6,4,3:18
-5,4,3:18
-4,4,3:18
5,4,3:18
-7,5,3:18
-6,5,3:18
-4,5,3:18
-4,6,3:18
-2,6,3:18
-3,7,3:18
2,-9,4:18
4,-8,4:18
2,-7,4:18
-2,-5,4:18
3,-5,4:18
3,-4,4:18
4,-4,4:18
0,-3,4:17
2,-3,4:18
0,-2,4:17
-1,-1,4:17
-1,0,4:17
-1,1,4:17
-4,2,4:18
-5,3,4:18
6,3,4:18
-8,4,4:18
-5,4,4:18
-4,4,4:18
-3,4,4:18
0,4,4:18
3,4,4:18
5,4,4:18
-6,5,4:18
-4,5,4:18
5,5,4:18
6,5,4:18
-10,6,4:18
-8,6,4:18
-7,6,4:18
-6,6,4:17
-4,6,4:18
-2,6,4:18
5,6,4:18
-10,7,4:18
-8,7,4:18
3,7,4:18
-6,9,4:18
1,-7,5:18
-1,-4,5:18
1,-4,5:17
2,-3,5:18
2,-2,5:18
-4,0,5:18
-1,0,5:17
0,0,5:18
-1,1,5:17
-5,2,5:18
-4,2,5:18
-2,2,5:17
-1,2,5:18
2,2,5:18
-7,3,5:18
1,3,5:18
4,3,5:18
1,4,5:18
-5,5,5:17
-2,5,5:18
-8,6,5:18
-7,6,5:18
-10,7,5:18
4,7,5:18
5,7,5:18
-5,8,5:18
3,8,5:18
-5,9,5:18
4,-8,6:18
5,-8,6:18
1,-6,6:18
4,-6,6:18
0,-5,6:18
2,-5,6:17
6,-4,6:18
-1,-2,6:18
0,-2,6:18
2,-2,6:18
3,-2,6:18
0,-1,6:18
4,-1,6:18
-6,0,6:18
-1,0,6:17
0,0,6:18
-7,1,6:18
-2,1,6:18
-1,1,6:17
-4,2,6:18
3,2,6:18
-4,3,6:18
-3,3,6:17
3,3,6:18
-8,4,6:18
-6,4,6:18
-4,4,6:17
-3,4,6:18
-2,4,6:18
0,4,6:18
2,4,6:18
4,4,6:18
-1,5,6:18
1,5,6:18
6,5,6:18
-4,6,6:18
4,6,6:18
-6,7,6:18
-5,7,6:18
-8,8,6:18
-6,8,6:18
-5,8,6:18
-2,8,6:18
3,8,6:18
-6,9,6:18
2,-9,7:18
-1,-7,7:18
0,-6,7:18
6,-6,7:18
1,-5,7:18
3,-5,7:18
1,-3,7:18
2,-3,7:18
-3,0,7:18
-1,0,7:17
3,0,7:18
5,0,7:18
-2,1,7:18
0,1,7:18
1,1,7:18
2,1,7:18
4,1,7:18
-1,2,7:18
0,2,7:17
4,2,7:18
-8,3,7:18
-4,3,7:18
-1,3,7:18
1,3,7:18
3,3,7:18
-7,4,7:18
-6,4,7:18
-4,4,7:18
-1,4,7:18
0,4,7:18
2,4,7:18
3,4,7:17
5,4,7:18
7,4,7:18
-2,5,7:18
-1,5,7:18
3,5,7:18
-8,6,7:18
-7,6,7:18
-4,6,7:18
-2,6,7:18
-1,6,7:18
0,6,7:18
2,6,7:18
3,7,7:18
-7,9,7:18
2,-9,8:18
2,-8,8:18
1,-5,8:18
4,-5,8:18
-3,-4,8:18
1,-3,8:18
3,-2,8:18
2,-1,8:18
-2,0,8:18
-1,0,8:17
0,0,8:17
2,0,8:18
3,0,8:18
-4,1,8:18
-2,1,8:17
-3,2,8:18
1,2,8:18
3,2,8:18
-1,3,8:18
0,3,8:18
1,3,8:17
2,3,8:17
5,3,8:18
-8,4,8:18
-7,4,8:18
-5,4,8:18
6,4,8:18
2,6,8:18
3,6,8:18
4,6,8:18
-1,7,8:18
4,8,8:18
4,-7,9:18
0,-5,9:18
2,-5,9:18
3,-5,9:18
2,-3,9:18
-6,-2,9:18
-5,-2,9:18
-4,-2,9:18
-2,-1,9:17
-1,0,9:17
0,0,9:17
-4,1,9:18
-6,2,9:18
-3,2,9:18
-2,2,9:17
-1,2,9:18
-6,3,9:18
-4,3,9:18
-3,3,9:18
0,3,9:18
3,3,9:18
-4,4,9:18
-3,4,9:18
-2,4,9:18
0,4,9:18
2,4,9:18
0,5,9:18
1,5,9:18
-3,6,9:18
2,6,9:18
3,6,9:18
-4,7,9:18
3,8,9:18
-1,-5,10:18
3,-5,10:18
-6,-4,10:18
-4,-4,10:18
2,-3,10:18
-7,-2,10:18
-4,-2,10:18
-5,-1,10:18
-2,-1,10:17
1,-1,10:18
-1,0,10:17
1,0,10:17
-5,1,10:18
-4,1,10:18
2,1,10:18
-2,2,10:17
1,2,10:18
4,2,10:18
-5,3,10:18
-2,3,10:18
-1,3,10:18
2,3,10:18
5,3,10:18
6,3,10:18
-5,4,10:18
-4,4,10:18
0,4,10:18
3,4,10:18
5,4,10:18
-3,5,10:18
1,5,10:18
1,6,10:18
2,6,10:18
-4,-6,11:18
-1,-3,11:18
4,-3,11:18
-7,-2,11:18
-3,-2,11:17
0,-2,11:18
-6,-1,11:18
-3,-1,11:18
2,-1,11:18
4,-1,11:18
5,-1,11:18
-1,0,11:17
1,0,11:17
1,1,11:18
-3,2,11:17
-4,3,11:18
4,3,11:18
-5,4,11:18
-1,4,11:18
4,4,11:18
-5,5,11:18
-3,5,11:18
1,6,11:18
-3,-5,12:18
0,-5,12:18
-6,-4,12:18
-5,-4,12:18
1,-4,12:18
-7,-3,12:18
-6,-3,12:18
-3,-3,12:18
-3,-2,12:17
-1,-2,12:18
-6,-1,12:18
-2,-1,12:18
-1,-1,12:17
3,-1,12:18
-4,0,12:18
-3,0,12:18
-2,0,12:18
-1,0,12:17
0,0,12:18
2,0,12:17
6,0,12:18
-6,1,12:18
-5,1,12:18
-4,1,12:18
-1,1,12:18
2,1,12:18
-3,2,12:17
-2,2,12:18
2,2,12:18
3,2,12:18
4,2,12:18
-6,3,12:18
-4,3,12:18
-1,3,12:18
0,3,12:18
1,3,12:18
2,3,12:18
3,3,12:18
-2,5,12:18
-4,7,12:18
3,-4,13:18
5,-4,13:18
-5,-3,13:18
-4,-3,13:17
3,-3,13:18
5,-3,13:18
-7,-2,13:18
-5,-2,13:18
-3,-2,13:18
-1,-2,13:17
2,-2,13:18
3,-2,13:18
5,-1,13:18
-1,0,13:17
2,0,13:17
6,0,13:18
7,0,13:18
-6,1,13:18
-3,1,13:18
0,1,13:18
3,1,13:18
2,2,13:18
4,2,13:18
6,2,13:18
-5,3,13:18
-3,3,13:17
-6,4,13:18
-5,4,13:18
-1,4,13:18
-3,5,13:18
0,5,13:18
-6,6,13:18
-3,7,13:18
-1,7,13:18
-3,-5,14:18
-3,-4,14:18
4,-4,14:18
-4,-3,14:17
-1,-3,14:17
4,-3,14:18
-5,-2,14:18
-3,-2,14:18
0,-2,14:18
1,-2,14:18
2,-2,14:18
-5,-1,14:18
-4,-1,14:18
-3,-1,14:18
7,-1,14:18
8,-1,14:18
-1,0,14:17
3,0,14:17
7,0,14:18
-3,1,14:18
-3,2,14:18
-2,2,14:18
3,3,14:18
-4,4,14:17
1,4,14:18
2,-5,15:18
4,-5,15:18
5,-5,15:18
1,-4,15:18
4,-4,15:18
7,-4,15:18
-6,-3,15:18
-5,-3,15:18
-3,-3,15:18
-1,-3,15:17
0,-3,15:18
2,-3,15:18
4,-3,15:18
-4,-2,15:18
2,-2,15:18
8,-2,15:18
-4,-1,15:18
0,-1,15:17
3,-1,15:18
4,-1,15:17
-5,0,15:18
-2,0,15:18
-1,0,15:17
2,0,15:18
4,0,15:17
8,0,15:18
-4,1,15:18
5,1,15:17
-5,2,15:18
-3,2,15:18
1,2,15:18
4,2,15:18
6,2,15:18
7,2,15:18
-2,3,15:18
1,3,15:18
5,3,15:18
6,3,15:18
-6,4,15:18
-4,4,15:18
-3,4,15:18
-5,5,15:18
-3,-4,16:18
-1,-4,16:17
4,-4,16:18
-2,-3,16:18
-3,-2,16:18
-2,-2,16:18
0,-1,16:17
5,-1,16:18
-2,0,16:18
-1,0,16:17
3,0,16:18
-1,2,16:18
0,2,16:18
2,2,16:18
-6,3,16:18
-3,3,16:18
-2,3,16:18
-1,3,16:18
1,3,16:18
3,3,16:18
4,3,16:18
-2,4,16:18
1,4,16:18
-3,6,16:18
-2,-5,17:18
-3,-4,17:18
0,-4,17:18
3,-4,17:18
5,-4,17:18
-3,-3,17:18
-2,-2,17:18
0,-2,17:17
2,-2,17:18
-4,-1,17:18
0,-1,17:18
2,-1,17:18
4,-1,17:18
7,-1,17:18
-4,0,17:18
-1,0,17:17
3,0,17:18
5,0,17:18
6,0,17:18
-1,1,17:18
3,1,17:18
7,1,17:18
-4,2,17:18
-3,2,17:18
-2,2,17:18
-1,2,17:18
4,2,17:18
-2,4,17:18
2,4,17:18
-3,5,17:18
-2,5,17:18
-1,5,17:18
-2,-6,18:18
1,-4,18:18
1,-3,18:18
0,-2,18:17
1,-2,18:18
2,-2,18:18
-4,-1,18:18
-3,-1,18:18
-1,-1,18:18
0,0,18:18
4,0,18:18
5,0,18:18
-1,1,18:17
2,1,18:18
-5,2,18:18
-3,2,18:18
-2,2,18:18
-1,2,18:18
1,2,18:18
2,2,18:18
-2,4,18:18
1,4,18:18
2,4,18:18
-3,5,18:18
0,5,18:18
-2,6,18:18
-2,-5,19:18
0,-5,19:18
1,-5,19:18
-5,-4,19:18
-2,-4,19:18
1,-4,19:18
2,-3,19:18
-5,-2,19:18
-4,-2,19:18
-3,-2,19:18
-2,-2,19:18
-1,-2,19:85
0,-2,19:17
1,-2,19:85
2,-2,19:18
-5,-1,19:18
-4,-1,19:18
-2,-1,19:18
-1,-1,19:18
0,-1,19:18
-1,0,19:18
1,0,19:18
-1,1,19:17
0,1,19:17
1,1,19:85
4,1,19:18
-5,2,19:18
-4,2,19:18
0,2,19:18
4,5,19:18
-4,-6,20:18
-2,-5,20:18
0,-4,20:18
-2,-3,20:85
1,-3,20:18
2,-3,20:18
3,-3,20:18
-4,-2,20:18
-3,-2,20:18
-2,-2,20:85
-1,-2,20:85
0,-2,20:18
1,-2,20:85
-6,-1,20:18
-5,-1,20:18
-2,-1,20:18
-1,-1,20:18
2,-1,20:18
3,-1,20:18
4,-1,20:18
-6,0,20:18
-4,0,20:18
-2,0,20:18
-1,0,20:18
0,0,20:18
1,0,20:18
4,0,20:18
5,0,20:18
-5,1,20:18
-4,1,20:18
-2,1,20:18
-1,1,20:85
1,1,20:85
2,1,20:18
-5,2,20:18
-2,2,20:85
-1,2,20:85
0,2,20:18
1,2,20:85
2,2,20:18
4,2,20:18
-3,3,20:18
-1,3,20:18
0,3,20:18
1,3,20:18
3,3,20:18
4,3,20:18
-6,4,20:18
-3,4,20:18
-2,4,20:18
-1,4,20:18
0,4,20:18
1,4,20:18
3,4,20:18
-2,5,20:18
-1,5,20:18
-2,6,20:18
-1,-5,21:18
-4,-4,21:18
-3,-4,21:18
-2,-4,21:18
-2,-3,21:85
-1,-3,21:18
1,-3,21:85
-4,-2,21:18
-1,-2,21:18
1,-2,21:85
2,-2,21:18
3,-2,21:18
-3,-1,21:18
-2,-1,21:18
-1,-1,21:18
0,-1,21:18
-4,0,21:18
2,0,21:18
-4,1,21:18
-2,1,21:18
-1,1,21:18
0,1,21:18
-6,2,21:18
-5,2,21:18
-3,2,21:18
-2,2,21:85
-1,2,21:18
1,2,21:85
-2,3,21:18
1,3,21:18
-4,4,21:18
0,4,21:18
-3,5,21:18
-2,6,21:18
-1,6,21:18
-2,-5,22:18
-5,-4,22:18
-2,-4,22:18
1,-3,22:85
-2,-2,22:18
1,-2,22:18
-2,0,22:18
3,0,22:18
4,0,22:18
-3,1,22:18
-2,1,22:18
-2,2,22:85
0,2,22:18
1,2,22:18
2,2,22:18
4,2,22:18
-1,3,22:18
-2,4,22:18
-1,4,22:18
0,5,22:18
1,6,22:18
-1,-5,23:18
-3,-3,23:18
-2,-3,23:18
0,-3,23:18
1,-3,23:85
4,-3,23:18
-3,-2,23:18
-3,-1,23:18
-2,-1,23:18
0,-1,23:18
1,-1,23:18
-3,0,23:18
-2,0,23:18
4,0,23:18
1,1,23:18
4,1,23:18
0,2,23:18
2,2,23:18
2,3,23:18
0,-4,24:18
-2,-3,24:18
-1,-3,24:18
-3,-2,24:18
-2,-2,24:18
-2,-1,24:18
-2,0,24:18
2,1,24:18
0,2,24:18
1,2,24:18
-2,3,24:18
-2,4,24:18
1,4,24:18
1,-4,25:18
2,-3,25:18
-2,-2,25:18
2,-2,25:18
3,-1,25:18
1,-2,26:18
2,-2,26:18
3,-2,26:18
1,-1,26:18
