[META]
version=2.0
spawnOnBlockType=2
spawnSunlight=True
spawnDarkness=False
spawnWater=False
spawnLava=False
underFill=True
randomRotation=True
dig=True
tree=False
branch=False
needsFoundation=True
rarity=10
collisionPercentage=2
spawnElevationMin=0
spawnElevationMax=128
spawnInBiome=All
[DATA]
-6,-2,0:17
-2,-2,0:17
-5,-1,0:17
-4,-1,0:17
-3,-1,0:17
-3,0,0:17
-4,1,0:17
-2,1,0:17
1,-2,1:18
2,-2,1:18
-4,-1,1:17
-3,-1,1:17
2,-1,1:18
3,-1,1:18
-3,0,1:17
-7,5,1:18
-5,5,1:18
-4,6,1:18
-5,7,1:18
-8,-6,2:18
-6,-6,2:18
-7,-5,2:18
2,-4,2:18
1,-2,2:18
2,-2,2:18
-3,-1,2:17
2,-1,2:18
3,-1,2:18
-3,0,2:17
-7,5,2:18
-5,5,2:18
-7,6,2:18
-4,6,2:18
-5,7,2:18
-5,8,2:18
-7,-7,3:18
-6,-7,3:18
-8,-6,3:18
-7,-6,3:18
-6,-6,3:18
-8,-5,3:18
-7,-5,3:18
-6,-5,3:18
2,-4,3:18
1,-2,3:18
2,-2,3:18
-3,-1,3:17
2,-1,3:18
3,-1,3:18
-3,0,3:17
-6,4,3:18
-5,4,3:18
-7,5,3:18
-5,5,3:18
-7,6,3:18
-4,6,3:18
-5,7,3:18
-5,8,3:18
-7,-7,4:18
-6,-7,4:18
-8,-6,4:18
-7,-6,4:18
-6,-6,4:18
-8,-5,4:18
-7,-5,4:18
-6,-5,4:18
2,-4,4:18
-6,-3,4:18
-2,-2,4:17
1,-2,4:18
2,-2,4:18
4,-2,4:18
-3,-1,4:17
1,-1,4:18
2,-1,4:18
3,-1,4:18
4,-1,4:18
-4,0,4:17
-2,1,4:17
-6,4,4:18
-5,4,4:18
-7,5,4:18
-5,5,4:18
-7,6,4:18
-4,6,4:18
-3,6,4:18
-5,7,4:18
-5,8,4:18
-6,-7,5:18
-8,-6,5:18
-7,-6,5:18
-6,-6,5:18
-9,-5,5:18
-8,-5,5:18
-7,-5,5:17
-6,-5,5:18
-9,-4,5:18
2,-4,5:18
-7,-3,5:18
-6,-3,5:18
-4,-2,5:17
-2,-2,5:17
1,-2,5:18
4,-2,5:18
-8,-1,5:18
1,-1,5:18
2,-1,5:18
3,-1,5:18
4,-1,5:18
-9,0,5:18
-4,0,5:17
1,0,5:18
2,0,5:18
3,0,5:18
-9,1,5:18
-2,1,5:17
2,1,5:17
-3,2,5:17
-3,3,5:17
-5,4,5:18
-7,5,5:18
-5,5,5:18
-3,5,5:18
-7,6,5:18
-5,6,5:17
-3,6,5:18
-4,7,5:18
-5,8,5:18
-6,-7,6:18
-8,-6,6:18
-7,-6,6:18
-7,-5,6:18
-3,-5,6:18
-6,-4,6:17
2,-4,6:18
3,-4,6:18
-6,-3,6:18
-5,-3,6:17
-2,-2,6:17
-1,-2,6:17
1,-2,6:18
2,-2,6:17
3,-2,6:18
4,-2,6:18
-8,-1,6:18
2,-1,6:18
-9,0,6:18
-4,0,6:17
1,0,6:17
2,0,6:18
3,0,6:18
-9,1,6:18
-2,1,6:17
-8,2,6:18
-3,4,6:17
-5,5,6:18
-4,5,6:17
-3,5,6:18
-7,6,6:18
-5,6,6:18
-5,7,6:18
-5,8,6:18
-4,8,6:18
-6,-5,7:18
-5,-5,7:18
-3,-5,7:18
-6,-4,7:18
2,-4,7:18
3,-4,7:18
3,-3,7:18
-2,-2,7:17
1,-2,7:18
2,-2,7:18
3,-2,7:18
4,-2,7:18
-8,-1,7:18
0,-1,7:17
1,-1,7:17
2,-1,7:18
-9,0,7:18
-9,1,7:18
-8,1,7:18
-5,1,7:17
-8,2,7:18
-1,2,7:17
-7,3,7:18
-5,4,7:18
-5,5,7:18
-5,6,7:18
-3,-6,8:18
-5,-5,8:18
-3,-5,8:18
-1,-5,8:18
-5,-4,8:18
-2,-4,8:18
-6,-3,8:18
-4,-3,8:18
-3,-3,8:17
-1,-3,8:18
3,-3,8:18
1,-2,8:18
2,-2,8:18
-8,-1,8:18
-9,0,8:18
-8,0,8:18
-9,1,8:18
-8,1,8:18
-7,1,8:18
-5,1,8:17
-8,2,8:18
-1,2,8:17
0,2,8:18
-7,3,8:18
-2,3,8:18
0,3,8:18
1,3,8:18
-5,4,8:18
-1,4,8:18
1,4,8:18
-5,5,8:18
-3,-6,9:18
-5,-5,9:18
-3,-5,9:18
-1,-5,9:18
0,-5,9:18
-5,-4,9:18
-2,-4,9:18
-1,-4,9:18
-6,-3,9:18
-4,-3,9:18
-3,-3,9:17
-1,-3,9:18
-9,-2,9:18
-8,-1,9:18
-6,-1,9:18
-1,-1,9:18
-9,0,9:18
-8,0,9:18
-6,0,9:17
-9,1,9:18
-8,1,9:18
-7,1,9:18
-8,2,9:18
-5,2,9:17
-1,2,9:17
0,2,9:18
-7,3,9:18
-3,3,9:18
-2,3,9:18
0,3,9:18
1,3,9:18
-5,4,9:18
-1,4,9:18
1,4,9:18
-5,5,9:18
0,5,9:18
-1,6,9:18
-4,-6,10:18
-3,-6,10:18
-2,-6,10:18
-5,-5,10:18
-3,-5,10:18
-1,-5,10:18
0,-5,10:18
-5,-4,10:18
-3,-4,10:17
-2,-4,10:18
-1,-4,10:18
-6,-3,10:18
-4,-3,10:18
-3,-3,10:18
-2,-3,10:18
-1,-3,10:18
-9,-2,10:18
-8,-2,10:18
-5,-2,10:18
-8,-1,10:18
-6,-1,10:18
-1,-1,10:18
-9,0,10:18
-8,0,10:18
-6,0,10:17
-2,0,10:18
0,0,10:18
1,0,10:18
2,0,10:18
-9,1,10:18
-8,1,10:18
-7,1,10:18
-4,1,10:18
-3,1,10:18
-2,1,10:18
0,1,10:17
2,1,10:18
-8,2,10:18
-5,2,10:17
-1,2,10:18
0,2,10:18
-7,3,10:18
-3,3,10:18
-2,3,10:18
-1,3,10:17
0,3,10:18
1,3,10:18
-7,4,10:18
-5,4,10:18
-1,4,10:18
0,4,10:18
1,4,10:18
-7,5,10:18
-5,5,10:18
0,5,10:18
-1,6,10:18
0,6,10:18
-2,-7,11:18
-4,-6,11:18
-3,-6,11:18
-2,-6,11:18
-5,-5,11:18
-3,-5,11:18
-1,-5,11:18
0,-5,11:18
-5,-4,11:18
-3,-4,11:17
-2,-4,11:18
-1,-4,11:18
-6,-3,11:18
-5,-3,11:18
-4,-3,11:18
-3,-3,11:18
-2,-3,11:18
-1,-3,11:18
-9,-2,11:18
-8,-2,11:18
-5,-2,11:18
-8,-1,11:18
-7,-1,11:17
-6,-1,11:18
-3,-1,11:18
-1,-1,11:18
0,-1,11:18
-9,0,11:18
-8,0,11:18
-6,0,11:18
-2,0,11:18
0,0,11:18
1,0,11:18
2,0,11:18
-9,1,11:18
-8,1,11:18
-7,1,11:18
-6,1,11:18
-4,1,11:18
-3,1,11:18
-2,1,11:18
-1,1,11:18
0,1,11:17
2,1,11:18
-8,2,11:18
-6,2,11:18
-1,2,11:18
0,2,11:18
1,2,11:18
2,2,11:18
-7,3,11:18
-5,3,11:17
-3,3,11:18
-2,3,11:18
-1,3,11:17
0,3,11:18
1,3,11:18
-7,4,11:18
-5,4,11:18
-2,4,11:18
-1,4,11:18
0,4,11:18
1,4,11:18
-7,5,11:18
-5,5,11:18
0,5,11:18
-1,6,11:18
0,6,11:18
-2,-7,12:18
-4,-6,12:18
-3,-6,12:18
-2,-6,12:18
-5,-5,12:18
-3,-5,12:18
-1,-5,12:18
0,-5,12:18
-8,-4,12:18
-5,-4,12:18
-3,-4,12:17
-2,-4,12:18
-1,-4,12:18
-8,-3,12:18
-6,-3,12:18
-5,-3,12:18
-4,-3,12:18
-3,-3,12:18
-2,-3,12:18
-1,-3,12:18
-9,-2,12:18
-8,-2,12:18
-6,-2,12:18
-5,-2,12:18
-4,-2,12:18
-3,-2,12:18
-8,-1,12:18
-7,-1,12:17
-6,-1,12:18
-3,-1,12:18
-1,-1,12:18
0,-1,12:18
-9,0,12:18
-8,0,12:18
-6,0,12:18
-4,0,12:18
-2,0,12:18
0,0,12:18
1,0,12:18
2,0,12:18
-9,1,12:18
-8,1,12:18
-7,1,12:18
-6,1,12:18
-4,1,12:18
-3,1,12:18
-2,1,12:18
-1,1,12:18
0,1,12:17
2,1,12:18
-8,2,12:18
-6,2,12:18
-2,2,12:18
-1,2,12:18
0,2,12:18
1,2,12:18
2,2,12:18
-7,3,12:18
-5,3,12:17
-3,3,12:18
-2,3,12:18
-1,3,12:17
0,3,12:18
1,3,12:18
-7,4,12:18
-5,4,12:18
-2,4,12:18
-1,4,12:18
0,4,12:18
1,4,12:18
-7,5,12:18
-5,5,12:18
0,5,12:18
1,5,12:18
-6,6,12:18
-1,6,12:18
0,6,12:18
-2,-7,13:18
-4,-6,13:18
-3,-6,13:18
-2,-6,13:18
0,-6,13:18
-5,-5,13:18
-3,-5,13:18
-2,-5,13:17
-1,-5,13:18
0,-5,13:18
-8,-4,13:18
-7,-4,13:18
-5,-4,13:18
-4,-4,13:17
-3,-4,13:18
-2,-4,13:18
-1,-4,13:18
-8,-3,13:18
-7,-3,13:18
-6,-3,13:18
-5,-3,13:18
-4,-3,13:18
-3,-3,13:18
-2,-3,13:18
-1,-3,13:18
-9,-2,13:18
-8,-2,13:18
-7,-2,13:17
-6,-2,13:18
-5,-2,13:18
-4,-2,13:18
-3,-2,13:18
1,-2,13:18
2,-2,13:18
-8,-1,13:18
-7,-1,13:18
-6,-1,13:18
-5,-1,13:18
-3,-1,13:18
-1,-1,13:18
0,-1,13:18
-9,0,13:18
-8,0,13:17
-7,0,13:18
-6,0,13:18
-5,0,13:18
-4,0,13:18
-2,0,13:18
0,0,13:18
1,0,13:17
2,0,13:18
-10,1,13:18
-8,1,13:18
-7,1,13:18
-6,1,13:18
-4,1,13:18
-3,1,13:18
-2,1,13:18
-1,1,13:18
0,1,13:18
2,1,13:18
-8,2,13:18
-6,2,13:18
-5,2,13:18
-4,2,13:18
-2,2,13:18
-1,2,13:18
0,2,13:18
1,2,13:18
2,2,13:18
-7,3,13:18
-5,3,13:17
-3,3,13:18
-2,3,13:18
-1,3,13:18
0,3,13:18
1,3,13:18
-8,4,13:18
-7,4,13:18
-5,4,13:18
-2,4,13:18
-1,4,13:17
0,4,13:18
1,4,13:18
-7,5,13:18
-5,5,13:18
-4,5,13:18
0,5,13:18
1,5,13:18
-6,6,13:18
-1,6,13:18
0,6,13:18
-2,-7,14:18
-4,-6,14:18
-3,-6,14:18
-2,-6,14:18
-1,-6,14:18
0,-6,14:18
-5,-5,14:18
-3,-5,14:18
-2,-5,14:17
-1,-5,14:18
0,-5,14:18
-8,-4,14:18
-7,-4,14:18
-5,-4,14:18
-4,-4,14:17
-3,-4,14:18
-2,-4,14:18
-1,-4,14:18
-9,-3,14:18
-8,-3,14:18
-7,-3,14:18
-6,-3,14:18
-5,-3,14:18
-4,-3,14:18
-3,-3,14:18
-2,-3,14:18
-1,-3,14:18
-9,-2,14:18
-8,-2,14:18
-7,-2,14:17
-6,-2,14:18
-5,-2,14:18
-4,-2,14:18
-3,-2,14:18
1,-2,14:18
2,-2,14:18
-8,-1,14:18
-7,-1,14:18
-6,-1,14:18
-5,-1,14:18
-3,-1,14:18
0,-1,14:18
2,-1,14:18
3,-1,14:18
-8,0,14:17
-7,0,14:18
-6,0,14:18
-5,0,14:18
-4,0,14:18
-2,0,14:18
0,0,14:18
1,0,14:17
2,0,14:18
3,0,14:18
-10,1,14:18
-8,1,14:18
-7,1,14:18
-6,1,14:18
-4,1,14:18
-3,1,14:18
-2,1,14:18
-1,1,14:18
0,1,14:18
2,1,14:18
3,1,14:18
-8,2,14:18
-6,2,14:18
-5,2,14:18
-4,2,14:18
-2,2,14:18
-1,2,14:18
0,2,14:18
1,2,14:18
2,2,14:18
-7,3,14:18
-6,3,14:18
-5,3,14:18
-3,3,14:18
-2,3,14:18
-1,3,14:18
0,3,14:18
1,3,14:18
-8,4,14:18
-7,4,14:18
-6,4,14:17
-5,4,14:18
-2,4,14:18
-1,4,14:17
0,4,14:18
1,4,14:18
-7,5,14:18
-5,5,14:18
-4,5,14:18
0,5,14:18
1,5,14:18
-6,6,14:18
-1,6,14:18
-2,-7,15:18
-4,-6,15:18
-2,-6,15:18
-1,-6,15:18
-5,-5,15:18
-3,-5,15:18
-2,-5,15:18
-8,-4,15:18
-7,-4,15:18
-4,-4,15:17
-3,-4,15:18
-2,-4,15:18
-1,-4,15:18
-9,-3,15:18
-8,-3,15:18
-7,-3,15:18
-6,-3,15:18
-4,-3,15:18
-3,-3,15:18
-2,-3,15:18
-9,-2,15:18
-8,-2,15:18
-7,-2,15:17
-6,-2,15:18
-5,-2,15:18
-4,-2,15:18
-3,-2,15:18
1,-2,15:18
-8,-1,15:18
-7,-1,15:18
-5,-1,15:18
-3,-1,15:18
0,-1,15:18
2,-1,15:18
3,-1,15:18
-8,0,15:18
-7,0,15:18
-5,0,15:18
-3,0,15:18
-2,0,15:18
-1,0,15:18
1,0,15:18
2,0,15:18
3,0,15:18
-10,1,15:18
-4,1,15:18
-3,1,15:18
-2,1,15:18
0,1,15:18
3,1,15:18
-6,2,15:18
-5,2,15:18
-4,2,15:18
-2,2,15:18
-1,2,15:18
1,2,15:18
2,2,15:18
3,2,15:18
-7,3,15:18
-6,3,15:18
-5,3,15:18
-2,3,15:18
-1,3,15:18
0,3,15:18
1,3,15:18
3,3,15:18
-8,4,15:18
-7,4,15:18
-6,4,15:17
-5,4,15:18
-2,4,15:18
-1,4,15:18
0,4,15:18
1,4,15:18
-7,5,15:18
-5,5,15:18
-4,5,15:18
-1,5,15:18
0,5,15:18
1,5,15:18
-6,6,15:18
-1,-6,16:18
-3,-5,16:18
-2,-5,16:18
-4,-4,16:18
-1,-4,16:18
-4,-3,16:18
-3,-3,16:18
-2,-3,16:18
-7,-2,16:18
-5,-2,16:18
-4,-2,16:18
-3,-2,16:18
-8,-1,16:18
-5,-1,16:18
-3,-1,16:18
0,-1,16:18
2,-1,16:18
-8,0,16:18
-7,0,16:18
-5,0,16:18
-3,0,16:18
-2,0,16:18
-1,0,16:18
1,0,16:18
-4,1,16:18
-3,1,16:18
0,1,16:18
-6,2,16:18
-5,2,16:18
-4,2,16:18
-2,2,16:18
-1,2,16:18
1,2,16:18
3,2,16:18
-7,3,16:18
-6,3,16:18
-8,4,16:18
-7,4,16:18
-6,4,16:17
-5,4,16:18
-2,4,16:18
-1,4,16:18
-7,5,16:18
-4,5,16:18
-6,6,16:18
-7,-2,17:18
-8,-1,17:18
-3,-1,17:18
-3,0,17:18
-4,1,17:18
-3,1,17:18
1,2,17:18
2,2,17:18
-7,3,17:18
-6,3,17:18
2,3,17:18
-6,4,17:18
-6,5,17:18
-3,0,18:18
-6,5,18:18
